[2022-08-01T09:39:22.452] _slurm_rpc_submit_batch_job: JobId=46936 InitPrio=24994 usec=466
[2022-08-01T09:55:37.524] _slurm_rpc_submit_batch_job: JobId=46937 InitPrio=26334 usec=391
[2022-08-01T09:56:07.069] _slurm_rpc_kill_job: REQUEST_KILL_JOB JobId=46937 uid 548200003
[2022-08-01T09:56:26.353] _slurm_rpc_submit_batch_job: JobId=46938 InitPrio=26334 usec=421
[2022-08-01T10:02:30.933] _slurm_rpc_kill_job: REQUEST_KILL_JOB JobId=46938 uid 548200003
[2022-08-01T10:02:34.959] _slurm_rpc_submit_batch_job: JobId=46939 InitPrio=26334 usec=370
[2022-08-01T10:02:35.479] sched: Allocate JobId=46939 NodeList=gpu01 #CPUs=2 Partition=gpu-k10
[2022-08-01T10:05:58.559] _slurm_rpc_kill_job: REQUEST_KILL_JOB JobId=46939 uid 548200003
[2022-08-01T10:09:03.220] _slurm_rpc_submit_batch_job: JobId=46940 InitPrio=30047 usec=44395
[2022-08-01T10:09:04.237] sched: Allocate JobId=46940 NodeList=cpu07 #CPUs=1 Partition=cpu-opteron
[2022-08-01T10:11:03.527] _slurm_rpc_kill_job: REQUEST_KILL_JOB JobId=46940 uid 548200011
[2022-08-01T10:39:52.453] _slurm_rpc_kill_job: REQUEST_KILL_JOB JobId=46896 uid 548200052
[2022-08-01T10:39:54.446] _slurm_rpc_kill_job: REQUEST_KILL_JOB JobId=46897 uid 548200052
[2022-08-01T10:39:56.326] _slurm_rpc_kill_job: REQUEST_KILL_JOB JobId=46898 uid 548200052
[2022-08-01T10:39:58.303] _slurm_rpc_kill_job: REQUEST_KILL_JOB JobId=46899 uid 548200052
[2022-08-01T10:40:01.238] _slurm_rpc_kill_job: REQUEST_KILL_JOB JobId=46900 uid 548200052
[2022-08-01T10:40:03.390] _slurm_rpc_kill_job: REQUEST_KILL_JOB JobId=46901 uid 548200052
[2022-08-01T10:40:09.862] _slurm_rpc_kill_job: REQUEST_KILL_JOB JobId=46902 uid 548200052
[2022-08-01T10:46:45.348] _slurm_rpc_submit_batch_job: JobId=46941 InitPrio=21845 usec=440
[2022-08-01T10:46:48.140] _slurm_rpc_submit_batch_job: JobId=46942 InitPrio=21845 usec=466
[2022-08-01T10:46:51.507] _slurm_rpc_submit_batch_job: JobId=46943 InitPrio=21845 usec=436
[2022-08-01T10:46:54.180] _slurm_rpc_submit_batch_job: JobId=46944 InitPrio=21845 usec=479
[2022-08-01T10:51:34.919] _slurm_rpc_submit_batch_job: JobId=46945 InitPrio=21845 usec=455
[2022-08-01T10:51:37.903] _slurm_rpc_submit_batch_job: JobId=46946 InitPrio=21845 usec=408
[2022-08-01T10:51:40.854] _slurm_rpc_submit_batch_job: JobId=46947 InitPrio=21845 usec=516
[2022-08-01T10:51:43.726] _slurm_rpc_submit_batch_job: JobId=46948 InitPrio=21845 usec=456
[2022-08-01T10:57:40.235] _slurm_rpc_submit_batch_job: JobId=46949 InitPrio=26548 usec=481
[2022-08-01T11:07:27.453] Time limit exhausted for JobId=46490
[2022-08-01T11:11:57.936] Time limit exhausted for JobId=46492
[2022-08-01T11:17:14.971] _slurm_rpc_submit_batch_job: JobId=46950 InitPrio=26548 usec=478
[2022-08-01T11:17:15.487] sched: Allocate JobId=46950 NodeList=gpu01 #CPUs=8 Partition=gpu-k10
[2022-08-01T11:21:22.695] _slurm_rpc_submit_batch_job: JobId=46951 InitPrio=26548 usec=580
[2022-08-01T11:23:06.773] _job_complete: JobId=46950 WEXITSTATUS 0
[2022-08-01T11:23:06.773] _job_complete: JobId=46950 done
[2022-08-01T11:23:07.680] sched: Allocate JobId=46951 NodeList=gpu01 #CPUs=8 Partition=gpu-k10
[2022-08-01T11:29:42.752] _job_complete: JobId=46951 WEXITSTATUS 0
[2022-08-01T11:29:42.752] _job_complete: JobId=46951 done
[2022-08-01T11:32:39.026] _slurm_rpc_submit_batch_job: JobId=46952 InitPrio=21188 usec=359
[2022-08-01T11:35:20.559] _slurm_rpc_submit_batch_job: JobId=46953 InitPrio=26283 usec=517
[2022-08-01T11:36:53.223] _slurm_rpc_submit_batch_job: JobId=46954 InitPrio=26283 usec=438
[2022-08-01T11:37:48.425] _slurm_rpc_submit_batch_job: JobId=46955 InitPrio=26283 usec=450
[2022-08-01T11:37:48.724] sched: Allocate JobId=46955 NodeList=gpu02 #CPUs=8 Partition=gpu-titan
[2022-08-01T11:41:23.202] _slurm_rpc_submit_batch_job: JobId=46956 InitPrio=26283 usec=414
[2022-08-01T11:42:02.267] _slurm_rpc_submit_batch_job: JobId=46957 InitPrio=26283 usec=416
[2022-08-01T11:42:33.264] sched/backfill: _start_job: Started JobId=46957 in gpu-v100s on gpu05
[2022-08-01T11:42:47.156] _job_complete: JobId=46955 WEXITSTATUS 0
[2022-08-01T11:42:47.156] _job_complete: JobId=46955 done
[2022-08-01T11:42:47.569] sched: Allocate JobId=46956 NodeList=gpu02 #CPUs=8 Partition=gpu-titan
[2022-08-01T11:42:56.349] _slurm_rpc_submit_batch_job: JobId=46958 InitPrio=26283 usec=391
[2022-08-01T11:43:33.267] sched/backfill: _start_job: Started JobId=46958 in gpu-v100s on gpu05
[2022-08-01T11:46:59.036] _job_complete: JobId=46957 WEXITSTATUS 0
[2022-08-01T11:46:59.036] _job_complete: JobId=46957 done
[2022-08-01T11:47:53.010] _job_complete: JobId=46956 WEXITSTATUS 0
[2022-08-01T11:47:53.010] _job_complete: JobId=46956 done
[2022-08-01T11:49:21.539] _job_complete: JobId=46958 WEXITSTATUS 0
[2022-08-01T11:49:21.539] _job_complete: JobId=46958 done
[2022-08-01T11:50:24.955] _job_complete: JobId=46933 WEXITSTATUS 0
[2022-08-01T11:50:24.960] _job_complete: JobId=46933 done
[2022-08-01T11:50:27.865] sched: Allocate JobId=46949 NodeList=gpu04 #CPUs=8 Partition=gpu-k40c
[2022-08-01T11:57:49.472] _job_complete: JobId=46949 WEXITSTATUS 0
[2022-08-01T11:57:49.472] _job_complete: JobId=46949 done
[2022-08-01T11:57:50.389] sched: Allocate JobId=46953 NodeList=gpu04 #CPUs=8 Partition=gpu-k40c
[2022-08-01T12:03:37.008] _job_complete: JobId=46953 WEXITSTATUS 0
[2022-08-01T12:03:37.008] _job_complete: JobId=46953 done
[2022-08-01T12:03:37.411] sched: Allocate JobId=46954 NodeList=gpu04 #CPUs=8 Partition=gpu-k40c
[2022-08-01T12:10:02.014] _job_complete: JobId=46954 WEXITSTATUS 0
[2022-08-01T12:10:02.014] _job_complete: JobId=46954 done
[2022-08-01T12:10:02.409] sched: Allocate JobId=46952 NodeList=gpu04 #CPUs=16 Partition=gpu-k40c
[2022-08-01T12:44:15.670] _slurm_rpc_submit_batch_job: JobId=46959 InitPrio=26018 usec=577
[2022-08-01T12:44:16.135] sched: Allocate JobId=46959 NodeList=cpu07 #CPUs=8 Partition=cpu-opteron
[2022-08-01T12:47:32.499] _slurm_rpc_submit_batch_job: JobId=46960 InitPrio=26018 usec=445
[2022-08-01T12:47:33.353] sched/backfill: _start_job: Started JobId=46960 in cpu-opteron on cpu09
[2022-08-01T12:49:35.196] _slurm_rpc_submit_batch_job: JobId=46961 InitPrio=26018 usec=714
[2022-08-01T12:50:18.133] _slurm_rpc_submit_batch_job: JobId=46962 InitPrio=26018 usec=427
[2022-08-01T12:50:33.358] sched/backfill: _start_job: Started JobId=46961 in cpu-epyc on cpu15
[2022-08-01T12:50:33.359] sched/backfill: _start_job: Started JobId=46962 in cpu-epyc on cpu15
[2022-08-01T12:54:51.520] _job_complete: JobId=46961 WEXITSTATUS 0
[2022-08-01T12:54:51.520] _job_complete: JobId=46961 done
[2022-08-01T12:56:47.498] _job_complete: JobId=46962 WEXITSTATUS 0
[2022-08-01T12:56:47.498] _job_complete: JobId=46962 done
[2022-08-01T12:57:16.191] _job_complete: JobId=46959 WEXITSTATUS 0
[2022-08-01T12:57:16.191] _job_complete: JobId=46959 done
[2022-08-01T13:02:51.045] _job_complete: JobId=46960 WEXITSTATUS 0
[2022-08-01T13:02:51.045] _job_complete: JobId=46960 done
[2022-08-01T13:27:10.123] _slurm_rpc_submit_batch_job: JobId=46963 InitPrio=26018 usec=552
[2022-08-01T13:27:10.681] sched: Allocate JobId=46963 NodeList=cpu07 #CPUs=8 Partition=cpu-opteron
[2022-08-01T13:28:59.309] _slurm_rpc_submit_batch_job: JobId=46964 InitPrio=26018 usec=409
[2022-08-01T13:29:00.968] sched: Allocate JobId=46964 NodeList=cpu09 #CPUs=8 Partition=cpu-opteron
[2022-08-01T13:39:32.290] _slurm_rpc_submit_batch_job: JobId=46965 InitPrio=21306 usec=543
[2022-08-01T13:40:17.912] _slurm_rpc_kill_job: REQUEST_KILL_JOB JobId=46930 uid 548200023
[2022-08-01T13:42:27.004] _slurm_rpc_submit_batch_job: JobId=46966 InitPrio=21580 usec=462
[2022-08-01T13:42:33.449] sched/backfill: _start_job: Started JobId=46966 in cpu-opteron on cpu07
[2022-08-01T13:42:34.832] _job_complete: JobId=46963 WEXITSTATUS 0
[2022-08-01T13:42:34.832] _job_complete: JobId=46963 done
[2022-08-01T13:42:34.990] _job_complete: JobId=46964 WEXITSTATUS 0
[2022-08-01T13:42:34.990] _job_complete: JobId=46964 done
[2022-08-01T13:47:53.716] _slurm_rpc_submit_batch_job: JobId=46967 InitPrio=26018 usec=493
[2022-08-01T13:47:54.025] sched: Allocate JobId=46967 NodeList=cpu07 #CPUs=8 Partition=cpu-opteron
[2022-08-01T13:55:28.145] _slurm_rpc_submit_batch_job: JobId=46968 InitPrio=26018 usec=424
[2022-08-01T13:55:28.757] sched: Allocate JobId=46968 NodeList=cpu09 #CPUs=8 Partition=cpu-opteron
[2022-08-01T14:00:43.506] _job_complete: JobId=46967 WEXITSTATUS 0
[2022-08-01T14:00:43.506] _job_complete: JobId=46967 done
[2022-08-01T14:10:49.155] _slurm_rpc_kill_job: REQUEST_KILL_JOB JobId=46965 uid 548200023
[2022-08-01T14:11:16.287] _job_complete: JobId=46968 WEXITSTATUS 0
[2022-08-01T14:11:16.287] _job_complete: JobId=46968 done
[2022-08-01T14:57:17.877] _slurm_rpc_submit_batch_job: JobId=46969 InitPrio=21580 usec=449
[2022-08-01T16:10:35.664] _job_complete: JobId=46921 WEXITSTATUS 0
[2022-08-01T16:10:35.664] _job_complete: JobId=46921 done
[2022-08-01T16:11:33.693] sched/backfill: _start_job: Started JobId=46969 in cpu-opteron on cpu09
[2022-08-01T16:31:04.599] _slurm_rpc_submit_batch_job: JobId=46970 InitPrio=22775 usec=521
[2022-08-01T16:31:06.247] _slurm_rpc_submit_batch_job: JobId=46971 InitPrio=22775 usec=426
[2022-08-01T16:31:07.670] _slurm_rpc_submit_batch_job: JobId=46972 InitPrio=22775 usec=493
[2022-08-01T16:31:09.678] _slurm_rpc_submit_batch_job: JobId=46973 InitPrio=22775 usec=567
[2022-08-01T16:31:11.014] _slurm_rpc_submit_batch_job: JobId=46974 InitPrio=22775 usec=424
[2022-08-01T16:31:12.398] _slurm_rpc_submit_batch_job: JobId=46975 InitPrio=22775 usec=543
[2022-08-01T16:31:15.439] _slurm_rpc_submit_batch_job: JobId=46976 InitPrio=22775 usec=588
[2022-08-01T16:31:17.310] _slurm_rpc_submit_batch_job: JobId=46977 InitPrio=22775 usec=406
[2022-08-01T16:31:31.079] _slurm_rpc_submit_batch_job: JobId=46978 InitPrio=22775 usec=405
[2022-08-01T16:31:33.982] _slurm_rpc_submit_batch_job: JobId=46979 InitPrio=22775 usec=503
[2022-08-01T16:31:36.143] _slurm_rpc_submit_batch_job: JobId=46980 InitPrio=22775 usec=383
[2022-08-01T16:31:37.526] _slurm_rpc_submit_batch_job: JobId=46981 InitPrio=22775 usec=427
[2022-08-01T16:31:39.015] _slurm_rpc_submit_batch_job: JobId=46982 InitPrio=22775 usec=417
[2022-08-01T16:31:41.055] _slurm_rpc_submit_batch_job: JobId=46983 InitPrio=22775 usec=803
[2022-08-01T16:31:42.479] _slurm_rpc_submit_batch_job: JobId=46984 InitPrio=22775 usec=462
[2022-08-01T16:31:44.351] _slurm_rpc_submit_batch_job: JobId=46985 InitPrio=22775 usec=451
[2022-08-01T16:31:45.961] _slurm_rpc_submit_batch_job: JobId=46986 InitPrio=22775 usec=500
[2022-08-01T16:31:47.463] _slurm_rpc_submit_batch_job: JobId=46987 InitPrio=22775 usec=484
[2022-08-01T16:31:49.094] _slurm_rpc_submit_batch_job: JobId=46988 InitPrio=22775 usec=407
[2022-08-01T16:31:51.623] _slurm_rpc_submit_batch_job: JobId=46989 InitPrio=22775 usec=376
[2022-08-01T16:31:53.406] _slurm_rpc_submit_batch_job: JobId=46990 InitPrio=22775 usec=471
[2022-08-01T16:31:55.151] _slurm_rpc_submit_batch_job: JobId=46991 InitPrio=22775 usec=561
[2022-08-01T18:31:41.122] _slurm_rpc_kill_job: REQUEST_KILL_JOB JobId=46966 uid 548200023
[2022-08-01T18:31:45.441] _slurm_rpc_kill_job: REQUEST_KILL_JOB JobId=46932 uid 548200023
[2022-08-01T18:31:45.861] sched: Allocate JobId=46936 NodeList=cpu[03,11] #CPUs=128 Partition=cpu-opteron
[2022-08-01T18:31:45.877] sched: Allocate JobId=46970 NodeList=cpu07 #CPUs=16 Partition=cpu-opteron
[2022-08-01T18:31:45.877] sched: Allocate JobId=46971 NodeList=cpu07 #CPUs=16 Partition=cpu-opteron
[2022-08-01T18:35:05.923] _slurm_rpc_submit_batch_job: JobId=46992 InitPrio=21580 usec=439
[2022-08-01T18:37:33.746] _slurm_rpc_submit_batch_job: JobId=46993 InitPrio=21580 usec=529
[2022-08-01T18:58:20.860] _slurm_rpc_submit_batch_job: JobId=46994 InitPrio=21717 usec=504
[2022-08-01T19:28:55.081] _job_complete: JobId=46936 WEXITSTATUS 0
[2022-08-01T19:28:55.081] _job_complete: JobId=46936 done
[2022-08-01T19:28:55.497] sched: Allocate JobId=46972 NodeList=cpu03 #CPUs=16 Partition=cpu-opteron
[2022-08-01T19:28:55.497] sched: Allocate JobId=46973 NodeList=cpu03 #CPUs=16 Partition=cpu-opteron
[2022-08-01T19:28:55.498] sched: Allocate JobId=46974 NodeList=cpu03 #CPUs=16 Partition=cpu-opteron
[2022-08-01T19:28:55.499] sched: Allocate JobId=46975 NodeList=cpu03 #CPUs=16 Partition=cpu-opteron
[2022-08-01T19:28:55.500] sched: Allocate JobId=46976 NodeList=cpu11 #CPUs=16 Partition=cpu-opteron
[2022-08-01T19:28:55.501] sched: Allocate JobId=46977 NodeList=cpu11 #CPUs=16 Partition=cpu-opteron
[2022-08-01T19:28:55.502] sched: Allocate JobId=46978 NodeList=cpu11 #CPUs=16 Partition=cpu-opteron
[2022-08-01T19:28:55.502] sched: Allocate JobId=46979 NodeList=cpu11 #CPUs=16 Partition=cpu-opteron
[2022-08-01T20:04:46.184] _slurm_rpc_submit_batch_job: JobId=46995 InitPrio=21384 usec=489
[2022-08-01T21:03:24.963] _slurm_rpc_submit_batch_job: JobId=46996 InitPrio=20659 usec=453
[2022-08-02T01:05:18.685] _job_complete: JobId=46976 WEXITSTATUS 0
[2022-08-02T01:05:18.685] _job_complete: JobId=46976 done
[2022-08-02T01:05:19.140] sched: Allocate JobId=46980 NodeList=cpu11 #CPUs=16 Partition=cpu-opteron
[2022-08-02T01:29:01.853] _job_complete: JobId=46971 WEXITSTATUS 0
[2022-08-02T01:29:01.853] _job_complete: JobId=46971 done
[2022-08-02T01:29:02.430] sched: Allocate JobId=46981 NodeList=cpu07 #CPUs=16 Partition=cpu-opteron
[2022-08-02T02:13:05.824] _job_complete: JobId=46975 WEXITSTATUS 0
[2022-08-02T02:13:05.825] _job_complete: JobId=46975 done
[2022-08-02T02:13:06.505] sched: Allocate JobId=46982 NodeList=cpu03 #CPUs=16 Partition=cpu-opteron
[2022-08-02T02:15:06.722] _slurm_rpc_submit_batch_job: JobId=46997 InitPrio=23868 usec=493
[2022-08-02T02:15:33.820] _slurm_rpc_kill_job: REQUEST_KILL_JOB JobId=46997 uid 548200084
[2022-08-02T02:16:01.864] _slurm_rpc_submit_batch_job: JobId=46998 InitPrio=23868 usec=670
[2022-08-02T02:16:35.531] sched/backfill: _start_job: Started JobId=46998 in cpu-epyc on cpu15
[2022-08-02T02:16:52.850] _job_complete: JobId=46998 WEXITSTATUS 1
[2022-08-02T02:16:52.850] _job_complete: JobId=46998 done
[2022-08-02T02:25:16.805] _slurm_rpc_submit_batch_job: JobId=46999 InitPrio=23868 usec=478
[2022-08-02T02:25:35.555] sched/backfill: _start_job: Started JobId=46999 in cpu-epyc on cpu15
[2022-08-02T02:26:03.349] _job_complete: JobId=46999 WEXITSTATUS 1
[2022-08-02T02:26:03.349] _job_complete: JobId=46999 done
[2022-08-02T02:26:55.742] _job_complete: JobId=46978 WEXITSTATUS 0
[2022-08-02T02:26:55.742] _job_complete: JobId=46978 done
[2022-08-02T02:26:56.272] sched: Allocate JobId=46983 NodeList=cpu11 #CPUs=16 Partition=cpu-opteron
[2022-08-02T02:28:15.957] _slurm_rpc_submit_batch_job: JobId=47000 InitPrio=23868 usec=439
[2022-08-02T02:28:35.566] sched/backfill: _start_job: Started JobId=47000 in cpu-epyc on cpu15
[2022-08-02T02:28:38.718] _job_complete: JobId=47000 WEXITSTATUS 1
[2022-08-02T02:28:38.718] _job_complete: JobId=47000 done
[2022-08-02T02:37:03.713] _slurm_rpc_submit_batch_job: JobId=47001 InitPrio=23868 usec=478
[2022-08-02T02:37:35.588] sched/backfill: _start_job: Started JobId=47001 in cpu-epyc on cpu15
[2022-08-02T02:37:37.796] _job_complete: JobId=47001 WEXITSTATUS 1
[2022-08-02T02:37:37.796] _job_complete: JobId=47001 done
[2022-08-02T02:40:03.054] _job_complete: JobId=46970 WEXITSTATUS 0
[2022-08-02T02:40:03.054] _job_complete: JobId=46970 done
[2022-08-02T02:40:03.526] sched: Allocate JobId=46984 NodeList=cpu07 #CPUs=16 Partition=cpu-opteron
[2022-08-02T02:46:47.565] _job_complete: JobId=46972 WEXITSTATUS 0
[2022-08-02T02:46:47.565] _job_complete: JobId=46972 done
[2022-08-02T02:46:47.948] sched: Allocate JobId=46985 NodeList=cpu03 #CPUs=16 Partition=cpu-opteron
[2022-08-02T03:32:16.455] _job_complete: JobId=46973 WEXITSTATUS 0
[2022-08-02T03:32:16.455] _job_complete: JobId=46973 done
[2022-08-02T03:32:16.939] sched: Allocate JobId=46986 NodeList=cpu03 #CPUs=16 Partition=cpu-opteron
[2022-08-02T03:49:07.669] _job_complete: JobId=46977 WEXITSTATUS 0
[2022-08-02T03:49:07.670] _job_complete: JobId=46977 done
[2022-08-02T03:49:08.193] sched: Allocate JobId=46987 NodeList=cpu11 #CPUs=16 Partition=cpu-opteron
[2022-08-02T04:30:27.828] _job_complete: JobId=46974 WEXITSTATUS 0
[2022-08-02T04:30:27.828] _job_complete: JobId=46974 done
[2022-08-02T04:30:28.214] sched: Allocate JobId=46988 NodeList=cpu03 #CPUs=16 Partition=cpu-opteron
[2022-08-02T07:59:01.883] _job_complete: JobId=46980 WEXITSTATUS 0
[2022-08-02T07:59:01.883] _job_complete: JobId=46980 done
[2022-08-02T07:59:02.313] sched: Allocate JobId=46989 NodeList=cpu11 #CPUs=16 Partition=cpu-opteron
[2022-08-02T08:09:35.161] _job_complete: JobId=46982 WEXITSTATUS 0
[2022-08-02T08:09:35.161] _job_complete: JobId=46982 done
[2022-08-02T08:09:35.551] sched: Allocate JobId=46990 NodeList=cpu03 #CPUs=16 Partition=cpu-opteron
[2022-08-02T08:16:05.962] _job_complete: JobId=46981 WEXITSTATUS 0
[2022-08-02T08:16:05.962] _job_complete: JobId=46981 done
[2022-08-02T08:16:06.382] sched: Allocate JobId=46991 NodeList=cpu07 #CPUs=16 Partition=cpu-opteron
[2022-08-02T09:16:14.271] _job_complete: JobId=46983 WEXITSTATUS 0
[2022-08-02T09:16:14.271] _job_complete: JobId=46983 done
[2022-08-02T09:16:14.733] sched: Allocate JobId=46994 NodeList=cpu11 #CPUs=16 Partition=cpu-opteron
[2022-08-02T09:20:37.437] _job_complete: JobId=46994 WEXITSTATUS 1
[2022-08-02T09:20:37.438] _job_complete: JobId=46994 done
[2022-08-02T09:21:36.434] sched/backfill: _start_job: Started JobId=46996 in cpu-opteron on cpu11
[2022-08-02T09:21:50.999] _job_complete: JobId=46996 WEXITSTATUS 1
[2022-08-02T09:21:50.999] _job_complete: JobId=46996 done
[2022-08-02T09:52:22.076] _job_complete: JobId=46984 WEXITSTATUS 0
[2022-08-02T09:52:22.076] _job_complete: JobId=46984 done
[2022-08-02T09:52:36.500] sched/backfill: _start_job: Started JobId=46995 in cpu-opteron on cpu07
[2022-08-02T09:58:53.370] _slurm_rpc_submit_batch_job: JobId=47002 InitPrio=20923 usec=420
[2022-08-02T09:59:36.514] sched/backfill: _start_job: Started JobId=47002 in cpu-opteron on cpu11
[2022-08-02T10:18:25.977] _job_complete: JobId=46986 WEXITSTATUS 0
[2022-08-02T10:18:25.977] _job_complete: JobId=46986 done
[2022-08-02T10:30:28.017] _job_complete: JobId=46979 WEXITSTATUS 0
[2022-08-02T10:30:28.018] _job_complete: JobId=46979 done
[2022-08-02T10:33:24.793] _job_complete: JobId=46969 WEXITSTATUS 1
[2022-08-02T10:33:24.793] _job_complete: JobId=46969 done
[2022-08-02T10:33:25.847] sched: Allocate JobId=46992 NodeList=cpu09 #CPUs=32 Partition=cpu-opteron
[2022-08-02T10:33:43.589] _job_complete: JobId=46992 WEXITSTATUS 1
[2022-08-02T10:33:43.589] _job_complete: JobId=46992 done
[2022-08-02T10:33:44.028] sched: Allocate JobId=46993 NodeList=cpu09 #CPUs=32 Partition=cpu-opteron
[2022-08-02T10:37:43.872] _job_complete: JobId=46993 WEXITSTATUS 1
[2022-08-02T10:37:43.872] _job_complete: JobId=46993 done
[2022-08-02T11:15:23.628] _job_complete: JobId=46988 WEXITSTATUS 0
[2022-08-02T11:15:23.628] _job_complete: JobId=46988 done
[2022-08-02T11:50:38.713] _job_complete: JobId=46987 WEXITSTATUS 0
[2022-08-02T11:50:38.713] _job_complete: JobId=46987 done
[2022-08-02T13:04:30.941] _slurm_rpc_submit_batch_job: JobId=47003 InitPrio=21580 usec=522
[2022-08-02T13:04:31.587] sched: Allocate JobId=47003 NodeList=cpu03 #CPUs=32 Partition=cpu-opteron
[2022-08-02T13:04:49.926] _job_complete: JobId=47003 WEXITSTATUS 1
[2022-08-02T13:04:49.926] _job_complete: JobId=47003 done
[2022-08-02T14:09:50.121] _slurm_rpc_submit_batch_job: JobId=47004 InitPrio=25685 usec=488
[2022-08-02T14:10:36.825] sched/backfill: _start_job: Started JobId=47004 in cpu-epyc on cpu15
[2022-08-02T14:10:40.231] _slurm_rpc_kill_job: REQUEST_KILL_JOB JobId=47004 uid 548300543
[2022-08-02T14:11:16.602] _slurm_rpc_submit_batch_job: JobId=47005 InitPrio=25548 usec=490
[2022-08-02T14:11:16.786] sched: Allocate JobId=47005 NodeList=cpu03 #CPUs=32 Partition=cpu-opteron
[2022-08-02T14:12:15.848] _slurm_rpc_kill_job: REQUEST_KILL_JOB JobId=47005 uid 548300543
[2022-08-02T14:18:54.707] _slurm_rpc_submit_batch_job: JobId=47006 InitPrio=24748 usec=633
[2022-08-02T14:19:14.255] _slurm_rpc_kill_job: REQUEST_KILL_JOB JobId=47006 uid 548300543
[2022-08-02T14:19:27.539] _slurm_rpc_submit_batch_job: JobId=47007 InitPrio=24748 usec=590
[2022-08-02T14:19:27.685] sched: Allocate JobId=47007 NodeList=cpu[03,09] #CPUs=64 Partition=cpu-opteron
[2022-08-02T14:20:42.470] _slurm_rpc_submit_batch_job: JobId=47008 InitPrio=22246 usec=409
[2022-08-02T14:20:42.805] sched: Allocate JobId=47008 NodeList=cpu11 #CPUs=16 Partition=cpu-opteron
[2022-08-02T14:21:24.146] _slurm_rpc_kill_job: REQUEST_KILL_JOB JobId=47007 uid 548300543
[2022-08-02T14:22:01.610] _job_complete: JobId=46985 WEXITSTATUS 0
[2022-08-02T14:22:01.610] _job_complete: JobId=46985 done
[2022-08-02T14:22:35.534] _slurm_rpc_submit_batch_job: JobId=47009 InitPrio=24748 usec=471
[2022-08-02T14:22:36.056] sched: Allocate JobId=47009 NodeList=cpu[03,09] #CPUs=64 Partition=cpu-opteron
[2022-08-02T14:22:36.571] _job_complete: JobId=47009 WEXITSTATUS 127
[2022-08-02T14:22:36.571] _job_complete: JobId=47009 done
[2022-08-02T14:23:41.408] _slurm_rpc_submit_batch_job: JobId=47010 InitPrio=25685 usec=476
[2022-08-02T14:24:25.583] _slurm_rpc_kill_job: REQUEST_KILL_JOB JobId=47010 uid 548300543
[2022-08-02T14:25:20.186] _slurm_rpc_submit_batch_job: JobId=47011 InitPrio=24748 usec=420
[2022-08-02T14:25:20.331] sched: Allocate JobId=47011 NodeList=cpu[03,09] #CPUs=64 Partition=cpu-opteron
[2022-08-02T14:25:20.856] _job_complete: JobId=47011 WEXITSTATUS 127
[2022-08-02T14:25:20.856] _job_complete: JobId=47011 done
[2022-08-02T14:25:35.149] _job_complete: JobId=47008 WEXITSTATUS 0
[2022-08-02T14:25:35.149] _job_complete: JobId=47008 done
[2022-08-02T14:31:14.647] _slurm_rpc_submit_batch_job: JobId=47012 InitPrio=24748 usec=409
[2022-08-02T14:31:14.950] sched: Allocate JobId=47012 NodeList=cpu[03,09] #CPUs=64 Partition=cpu-opteron
[2022-08-02T14:31:40.114] _job_complete: JobId=47012 WEXITSTATUS 0
[2022-08-02T14:31:40.115] _job_complete: JobId=47012 done
[2022-08-02T14:35:05.372] _slurm_rpc_submit_batch_job: JobId=47013 InitPrio=24748 usec=432
[2022-08-02T14:35:05.389] sched: Allocate JobId=47013 NodeList=cpu[03,09] #CPUs=64 Partition=cpu-opteron
[2022-08-02T14:36:11.779] _slurm_rpc_submit_batch_job: JobId=47014 InitPrio=22246 usec=498
[2022-08-02T14:36:12.483] sched: Allocate JobId=47014 NodeList=cpu03 #CPUs=16 Partition=cpu-opteron
[2022-08-02T14:37:34.474] _slurm_rpc_kill_job: REQUEST_KILL_JOB JobId=47013 uid 548300543
[2022-08-02T14:50:20.911] _slurm_rpc_submit_batch_job: JobId=47015 InitPrio=25228 usec=683
[2022-08-02T14:50:20.994] sched: Allocate JobId=47015 NodeList=cpu[03,09] #CPUs=8 Partition=cpu-opteron
[2022-08-02T14:50:21.499] _job_complete: JobId=47015 WEXITSTATUS 127
[2022-08-02T14:50:21.500] _job_complete: JobId=47015 done
[2022-08-02T14:51:54.970] _slurm_rpc_submit_batch_job: JobId=47016 InitPrio=25228 usec=438
[2022-08-02T14:51:55.123] sched: Allocate JobId=47016 NodeList=cpu[03,09] #CPUs=8 Partition=cpu-opteron
[2022-08-02T14:51:55.644] _job_complete: JobId=47016 WEXITSTATUS 127
[2022-08-02T14:51:55.644] _job_complete: JobId=47016 done
[2022-08-02T14:53:05.600] _slurm_rpc_submit_batch_job: JobId=47017 InitPrio=25228 usec=404
[2022-08-02T14:53:06.347] sched: Allocate JobId=47017 NodeList=cpu[03,09] #CPUs=8 Partition=cpu-opteron
[2022-08-02T14:53:06.907] _job_complete: JobId=47017 WEXITSTATUS 127
[2022-08-02T14:53:06.908] _job_complete: JobId=47017 done
[2022-08-02T14:53:25.262] _slurm_rpc_submit_batch_job: JobId=47018 InitPrio=26021 usec=460
[2022-08-02T14:53:25.401] sched: Allocate JobId=47018 NodeList=cpu[03,09] #CPUs=8 Partition=cpu-opteron
[2022-08-02T14:53:25.888] _job_complete: JobId=47018 WEXITSTATUS 127
[2022-08-02T14:53:25.888] _job_complete: JobId=47018 done
[2022-08-02T14:54:07.696] _slurm_rpc_submit_batch_job: JobId=47019 InitPrio=25228 usec=534
[2022-08-02T14:54:08.431] sched: Allocate JobId=47019 NodeList=cpu[03,09] #CPUs=8 Partition=cpu-opteron
[2022-08-02T14:54:58.917] _slurm_rpc_submit_batch_job: JobId=47020 InitPrio=26021 usec=385
[2022-08-02T14:54:59.503] sched: Allocate JobId=47020 NodeList=cpu[03,09] #CPUs=8 Partition=cpu-opteron
[2022-08-02T14:55:06.529] _job_complete: JobId=47020 WEXITSTATUS 0
[2022-08-02T14:55:06.530] _job_complete: JobId=47020 done
[2022-08-02T15:01:41.337] _slurm_rpc_submit_batch_job: JobId=47021 InitPrio=22246 usec=459
[2022-08-02T15:01:42.209] sched: Allocate JobId=47021 NodeList=cpu03 #CPUs=16 Partition=cpu-opteron
[2022-08-02T15:01:43.158] _slurm_rpc_submit_batch_job: JobId=47022 InitPrio=22246 usec=449
[2022-08-02T15:01:45.211] sched: Allocate JobId=47022 NodeList=cpu09 #CPUs=16 Partition=cpu-opteron
[2022-08-02T15:02:34.197] _job_complete: JobId=47014 WEXITSTATUS 0
[2022-08-02T15:02:34.197] _job_complete: JobId=47014 done
[2022-08-02T15:07:55.409] _slurm_rpc_submit_batch_job: JobId=47023 InitPrio=26021 usec=636
[2022-08-02T15:07:55.943] sched: Allocate JobId=47023 NodeList=cpu[03,09] #CPUs=8 Partition=cpu-opteron
[2022-08-02T15:07:56.734] _job_complete: JobId=47023 WEXITSTATUS 127
[2022-08-02T15:07:56.734] _job_complete: JobId=47023 done
[2022-08-02T15:09:07.679] _slurm_rpc_submit_batch_job: JobId=47024 InitPrio=26021 usec=659
[2022-08-02T15:09:08.038] sched: Allocate JobId=47024 NodeList=cpu[03,09] #CPUs=8 Partition=cpu-opteron
[2022-08-02T15:09:08.739] _job_complete: JobId=47024 WEXITSTATUS 127
[2022-08-02T15:09:08.740] _job_complete: JobId=47024 done
[2022-08-02T15:09:52.090] _slurm_rpc_submit_batch_job: JobId=47025 InitPrio=26021 usec=416
[2022-08-02T15:09:52.099] sched: Allocate JobId=47025 NodeList=cpu[03,09] #CPUs=8 Partition=cpu-opteron
[2022-08-02T15:10:25.417] _slurm_rpc_submit_batch_job: JobId=47026 InitPrio=21306 usec=402
[2022-08-02T15:10:44.101] _slurm_rpc_kill_job: REQUEST_KILL_JOB JobId=47025 uid 548200003
[2022-08-02T15:10:53.338] _slurm_rpc_submit_batch_job: JobId=47027 InitPrio=21580 usec=451
[2022-08-02T15:10:54.209] sched: Allocate JobId=47027 NodeList=cpu11 #CPUs=32 Partition=cpu-opteron
[2022-08-02T15:11:06.619] _job_complete: JobId=47027 WEXITSTATUS 1
[2022-08-02T15:11:06.619] _job_complete: JobId=47027 done
[2022-08-02T15:11:43.767] _slurm_rpc_kill_job: REQUEST_KILL_JOB JobId=47019 uid 548300543
[2022-08-02T15:12:48.216] _slurm_rpc_submit_batch_job: JobId=47028 InitPrio=26021 usec=452
[2022-08-02T15:12:48.508] sched: Allocate JobId=47028 NodeList=cpu[03,09] #CPUs=8 Partition=cpu-opteron
[2022-08-02T15:13:14.761] _slurm_rpc_kill_job: REQUEST_KILL_JOB JobId=47028 uid 548200003
[2022-08-02T15:13:36.549] _slurm_rpc_submit_batch_job: JobId=47029 InitPrio=21580 usec=445
[2022-08-02T15:13:36.576] sched: Allocate JobId=47029 NodeList=cpu03 #CPUs=32 Partition=cpu-opteron
[2022-08-02T15:13:37.876] _slurm_rpc_submit_batch_job: JobId=47030 InitPrio=26021 usec=419
[2022-08-02T15:13:39.580] sched: Allocate JobId=47030 NodeList=cpu[09,11] #CPUs=8 Partition=cpu-opteron
[2022-08-02T15:13:54.789] _job_complete: JobId=47029 WEXITSTATUS 1
[2022-08-02T15:13:54.790] _job_complete: JobId=47029 done
[2022-08-02T15:17:21.640] _slurm_rpc_submit_batch_job: JobId=47031 InitPrio=21580 usec=437
[2022-08-02T15:17:21.891] sched: Allocate JobId=47031 NodeList=cpu03 #CPUs=32 Partition=cpu-opteron
[2022-08-02T15:18:05.974] _slurm_rpc_kill_job: REQUEST_KILL_JOB JobId=47026 uid 548200023
[2022-08-02T15:18:29.407] _job_complete: JobId=47031 WEXITSTATUS 1
[2022-08-02T15:18:29.407] _job_complete: JobId=47031 done
[2022-08-02T15:19:17.870] _slurm_rpc_kill_job: REQUEST_KILL_JOB JobId=47030 uid 548200003
[2022-08-02T15:20:04.905] _slurm_rpc_submit_batch_job: JobId=47032 InitPrio=26021 usec=419
[2022-08-02T15:20:05.260] sched: Allocate JobId=47032 NodeList=cpu[03,09] #CPUs=8 Partition=cpu-opteron
[2022-08-02T15:20:56.493] _slurm_rpc_kill_job: REQUEST_KILL_JOB JobId=47032 uid 548200003
[2022-08-02T15:21:04.481] _slurm_rpc_submit_batch_job: JobId=47033 InitPrio=26021 usec=385
[2022-08-02T15:21:05.332] sched: Allocate JobId=47033 NodeList=cpu[03,09] #CPUs=8 Partition=cpu-opteron
[2022-08-02T15:21:09.875] _job_complete: JobId=47033 WEXITSTATUS 137
[2022-08-02T15:21:09.875] _job_complete: JobId=47033 done
[2022-08-02T15:22:47.872] _slurm_rpc_submit_batch_job: JobId=47034 InitPrio=26021 usec=528
[2022-08-02T15:22:48.556] sched: Allocate JobId=47034 NodeList=cpu[03,09] #CPUs=8 Partition=cpu-opteron
[2022-08-02T15:23:22.310] _slurm_rpc_submit_batch_job: JobId=47035 InitPrio=21580 usec=498
[2022-08-02T15:23:22.606] sched: Allocate JobId=47035 NodeList=cpu11 #CPUs=32 Partition=cpu-opteron
[2022-08-02T15:23:34.786] _job_complete: JobId=47035 WEXITSTATUS 1
[2022-08-02T15:23:34.786] _job_complete: JobId=47035 done
[2022-08-02T15:24:40.142] _slurm_rpc_submit_batch_job: JobId=47036 InitPrio=21580 usec=426
[2022-08-02T15:24:40.707] sched: Allocate JobId=47036 NodeList=cpu11 #CPUs=32 Partition=cpu-opteron
[2022-08-02T15:24:49.717] _slurm_rpc_kill_job: REQUEST_KILL_JOB JobId=47034 uid 548200003
[2022-08-02T15:24:52.120] _job_complete: JobId=47036 WEXITSTATUS 1
[2022-08-02T15:24:52.121] _job_complete: JobId=47036 done
[2022-08-02T15:25:18.815] _slurm_rpc_submit_batch_job: JobId=47037 InitPrio=21580 usec=426
[2022-08-02T15:25:19.761] sched: Allocate JobId=47037 NodeList=cpu03 #CPUs=32 Partition=cpu-opteron
[2022-08-02T15:26:27.733] _job_complete: JobId=47037 WEXITSTATUS 1
[2022-08-02T15:26:27.733] _job_complete: JobId=47037 done
[2022-08-02T15:26:46.906] _slurm_rpc_submit_batch_job: JobId=47038 InitPrio=22246 usec=561
[2022-08-02T15:26:47.890] sched: Allocate JobId=47038 NodeList=cpu09 #CPUs=16 Partition=cpu-opteron
[2022-08-02T15:26:49.481] _slurm_rpc_submit_batch_job: JobId=47039 InitPrio=22246 usec=472
[2022-08-02T15:26:50.891] sched: Allocate JobId=47039 NodeList=cpu03 #CPUs=16 Partition=cpu-opteron
[2022-08-02T15:27:19.498] _slurm_rpc_submit_batch_job: JobId=47040 InitPrio=21580 usec=528
[2022-08-02T15:27:19.932] sched: Allocate JobId=47040 NodeList=cpu11 #CPUs=32 Partition=cpu-opteron
[2022-08-02T15:27:23.938] _job_complete: JobId=46991 WEXITSTATUS 0
[2022-08-02T15:27:23.938] _job_complete: JobId=46991 done
[2022-08-02T15:27:32.888] _job_complete: JobId=47040 WEXITSTATUS 1
[2022-08-02T15:27:32.889] _job_complete: JobId=47040 done
[2022-08-02T15:29:57.844] _slurm_rpc_submit_batch_job: JobId=47041 InitPrio=21580 usec=415
[2022-08-02T15:29:58.232] sched: Allocate JobId=47041 NodeList=cpu11 #CPUs=32 Partition=cpu-opteron
[2022-08-02T15:33:55.869] _job_complete: JobId=47041 WEXITSTATUS 1
[2022-08-02T15:33:55.870] _job_complete: JobId=47041 done
[2022-08-02T15:40:31.241] _slurm_rpc_submit_batch_job: JobId=47042 InitPrio=26021 usec=452
[2022-08-02T15:40:31.375] sched: Allocate JobId=47042 NodeList=cpu[03,07] #CPUs=8 Partition=cpu-opteron
[2022-08-02T15:41:17.024] _slurm_rpc_kill_job: REQUEST_KILL_JOB JobId=47042 uid 548200003
[2022-08-02T15:43:51.284] _slurm_rpc_submit_batch_job: JobId=47043 InitPrio=22246 usec=589
[2022-08-02T15:43:51.764] sched: Allocate JobId=47043 NodeList=cpu03 #CPUs=16 Partition=cpu-opteron
[2022-08-02T15:44:52.688] _slurm_rpc_submit_batch_job: JobId=47044 InitPrio=26021 usec=487
[2022-08-02T15:44:52.850] sched: Allocate JobId=47044 NodeList=cpu[07,11] #CPUs=8 Partition=cpu-opteron
[2022-08-02T15:46:13.668] _slurm_rpc_kill_job: REQUEST_KILL_JOB JobId=47044 uid 548200003
[2022-08-02T15:47:30.191] _slurm_rpc_submit_batch_job: JobId=47045 InitPrio=26021 usec=434
[2022-08-02T15:47:31.078] sched: Allocate JobId=47045 NodeList=cpu[07,11] #CPUs=8 Partition=cpu-opteron
[2022-08-02T15:47:36.341] _job_complete: JobId=47045 WEXITSTATUS 0
[2022-08-02T15:47:36.341] _job_complete: JobId=47045 done
[2022-08-02T15:48:29.895] _slurm_rpc_submit_batch_job: JobId=47046 InitPrio=26021 usec=545
[2022-08-02T15:48:30.253] sched: Allocate JobId=47046 NodeList=cpu[07,11] #CPUs=8 Partition=cpu-opteron
[2022-08-02T15:48:35.454] _job_complete: JobId=47046 WEXITSTATUS 0
[2022-08-02T15:48:35.455] _job_complete: JobId=47046 done
[2022-08-02T15:49:25.982] _slurm_rpc_submit_batch_job: JobId=47047 InitPrio=26021 usec=596
[2022-08-02T15:49:26.334] sched: Allocate JobId=47047 NodeList=cpu[07,11] #CPUs=8 Partition=cpu-opteron
[2022-08-02T15:50:53.324] _job_complete: JobId=47043 WEXITSTATUS 0
[2022-08-02T15:50:53.325] _job_complete: JobId=47043 done
[2022-08-02T15:51:21.870] _slurm_rpc_kill_job: REQUEST_KILL_JOB JobId=47047 uid 548200003
[2022-08-02T15:52:03.493] _slurm_rpc_submit_batch_job: JobId=47048 InitPrio=26021 usec=892
[2022-08-02T15:52:04.557] sched: Allocate JobId=47048 NodeList=cpu[03,07] #CPUs=8 Partition=cpu-opteron
[2022-08-02T15:52:40.393] _slurm_rpc_kill_job: REQUEST_KILL_JOB JobId=47048 uid 548200003
[2022-08-02T15:52:55.008] _slurm_rpc_submit_batch_job: JobId=47049 InitPrio=25757 usec=463
[2022-08-02T15:52:55.769] sched: Allocate JobId=47049 NodeList=cpu[03,07] #CPUs=8 Partition=cpu-opteron
[2022-08-02T15:53:58.510] _slurm_rpc_kill_job: REQUEST_KILL_JOB JobId=47049 uid 548200003
[2022-08-02T15:54:11.148] _slurm_rpc_submit_batch_job: JobId=47050 InitPrio=25757 usec=431
[2022-08-02T15:54:11.876] sched: Allocate JobId=47050 NodeList=cpu[03,07] #CPUs=8 Partition=cpu-opteron
[2022-08-02T15:54:48.771] _slurm_rpc_kill_job: REQUEST_KILL_JOB JobId=47050 uid 548200003
[2022-08-02T15:54:59.612] _slurm_rpc_submit_batch_job: JobId=47051 InitPrio=25757 usec=447
[2022-08-02T15:54:59.941] sched: Allocate JobId=47051 NodeList=cpu[03,07] #CPUs=8 Partition=cpu-opteron
[2022-08-02T15:55:27.817] _slurm_rpc_kill_job: REQUEST_KILL_JOB JobId=47051 uid 548200003
[2022-08-02T15:56:09.979] _slurm_rpc_submit_batch_job: JobId=47052 InitPrio=25757 usec=461
[2022-08-02T15:56:10.038] sched: Allocate JobId=47052 NodeList=cpu[03,07] #CPUs=8 Partition=cpu-opteron
[2022-08-02T15:56:48.205] _slurm_rpc_submit_batch_job: JobId=47053 InitPrio=21580 usec=359
[2022-08-02T15:56:49.094] sched: Allocate JobId=47053 NodeList=cpu11 #CPUs=32 Partition=cpu-opteron
[2022-08-02T15:57:01.041] _job_complete: JobId=47053 WEXITSTATUS 1
[2022-08-02T15:57:01.041] _job_complete: JobId=47053 done
[2022-08-02T15:57:25.044] _slurm_rpc_submit_batch_job: JobId=47054 InitPrio=21580 usec=516
[2022-08-02T15:57:25.141] sched: Allocate JobId=47054 NodeList=cpu11 #CPUs=32 Partition=cpu-opteron
[2022-08-02T15:58:39.907] _slurm_rpc_submit_batch_job: JobId=47055 InitPrio=26283 usec=481
[2022-08-02T15:58:40.344] sched: Allocate JobId=47055 NodeList=cpu03 #CPUs=8 Partition=cpu-opteron
[2022-08-02T15:59:03.435] _slurm_rpc_kill_job: REQUEST_KILL_JOB JobId=47052 uid 548200003
[2022-08-02T15:59:06.341] _slurm_rpc_kill_job: REQUEST_KILL_JOB JobId=47055 uid 548200003
[2022-08-02T15:59:35.481] _slurm_rpc_submit_batch_job: JobId=47056 InitPrio=22246 usec=472
[2022-08-02T15:59:36.430] sched: Allocate JobId=47056 NodeList=cpu03 #CPUs=16 Partition=cpu-opteron
[2022-08-02T15:59:46.947] _slurm_rpc_submit_batch_job: JobId=47057 InitPrio=26283 usec=430
[2022-08-02T15:59:47.440] sched: Allocate JobId=47057 NodeList=cpu07 #CPUs=8 Partition=cpu-opteron
[2022-08-02T16:01:14.152] _job_complete: JobId=47054 WEXITSTATUS 1
[2022-08-02T16:01:14.153] _job_complete: JobId=47054 done
[2022-08-02T16:01:40.644] _slurm_rpc_kill_job: REQUEST_KILL_JOB JobId=47057 uid 548200003
[2022-08-02T16:03:19.089] _slurm_rpc_submit_batch_job: JobId=47058 InitPrio=26215 usec=553
[2022-08-02T16:03:36.960] sched/backfill: _start_job: Started JobId=47058 in cpu-epyc on cpu15
[2022-08-02T16:04:14.844] _update_job: updating accounting
[2022-08-02T16:04:14.844] _slurm_rpc_update_job: complete JobId=47058 uid=548200003 usec=717
[2022-08-02T16:07:36.703] _job_complete: JobId=47058 WEXITSTATUS 0
[2022-08-02T16:07:36.703] _job_complete: JobId=47058 done
[2022-08-02T16:10:58.752] _slurm_rpc_submit_batch_job: JobId=47059 InitPrio=25757 usec=393
[2022-08-02T16:11:11.640] _update_job: updating accounting
[2022-08-02T16:11:11.641] _slurm_rpc_update_job: complete JobId=47059 uid=548200003 usec=1048
[2022-08-02T16:11:23.656] _update_job: updating accounting
[2022-08-02T16:11:23.656] _slurm_rpc_update_job: complete JobId=47059 uid=548200003 usec=719
[2022-08-02T16:11:23.664] sched: Allocate JobId=47059 NodeList=cpu[12-13] #CPUs=8 Partition=cpu-epyc
[2022-08-02T16:11:28.434] _job_complete: JobId=47059 WEXITSTATUS 16
[2022-08-02T16:11:28.435] _job_complete: JobId=47059 done
[2022-08-02T16:14:20.664] _slurm_rpc_submit_batch_job: JobId=47060 InitPrio=25757 usec=394
[2022-08-02T16:14:32.156] _update_job: updating accounting
[2022-08-02T16:14:32.157] _slurm_rpc_update_job: complete JobId=47060 uid=548200003 usec=751
[2022-08-02T16:14:33.071] sched: Allocate JobId=47060 NodeList=cpu[12-13] #CPUs=8 Partition=cpu-epyc
[2022-08-02T16:14:37.459] _job_complete: JobId=47060 WEXITSTATUS 16
[2022-08-02T16:14:37.460] _job_complete: JobId=47060 done
[2022-08-02T16:15:36.850] _slurm_rpc_submit_batch_job: JobId=47061 InitPrio=25757 usec=487
[2022-08-02T16:15:36.975] sched/backfill: _start_job: Started JobId=47061 in cpu-epyc on cpu[12-13]
[2022-08-02T16:15:41.137] _job_complete: JobId=47061 WEXITSTATUS 16
[2022-08-02T16:15:41.137] _job_complete: JobId=47061 done
[2022-08-02T16:15:41.798] _slurm_rpc_update_job: JobId=47061 uid=548200003: Job has already finished
[2022-08-02T16:16:31.375] _slurm_rpc_submit_batch_job: JobId=47062 InitPrio=25757 usec=540
[2022-08-02T16:16:36.976] sched/backfill: _start_job: Started JobId=47062 in cpu-epyc on cpu[12-13]
[2022-08-02T16:16:40.166] _update_job: updating accounting
[2022-08-02T16:16:40.166] _slurm_rpc_update_job: complete JobId=47062 uid=548200003 usec=749
[2022-08-02T16:17:51.318] _slurm_rpc_kill_job: REQUEST_KILL_JOB JobId=47062 uid 548200003
[2022-08-02T16:18:16.015] _slurm_rpc_submit_batch_job: JobId=47063 InitPrio=25757 usec=547
[2022-08-02T16:18:19.300] _update_job: updating accounting
[2022-08-02T16:18:19.301] _slurm_rpc_update_job: complete JobId=47063 uid=548200003 usec=1018
[2022-08-02T16:18:19.523] sched: Allocate JobId=47063 NodeList=cpu[12-13] #CPUs=8 Partition=cpu-epyc
[2022-08-02T16:18:24.365] _job_complete: JobId=47063 WEXITSTATUS 0
[2022-08-02T16:18:24.365] _job_complete: JobId=47063 done
[2022-08-02T16:19:12.257] _slurm_rpc_submit_batch_job: JobId=47064 InitPrio=25757 usec=451
[2022-08-02T16:19:14.065] _slurm_rpc_submit_batch_job: JobId=47065 InitPrio=22246 usec=441
[2022-08-02T16:19:15.604] sched: Allocate JobId=47065 NodeList=cpu07 #CPUs=16 Partition=cpu-opteron
[2022-08-02T16:19:15.674] _update_job: updating accounting
[2022-08-02T16:19:15.674] _slurm_rpc_update_job: complete JobId=47064 uid=548200003 usec=690
[2022-08-02T16:19:18.605] sched: Allocate JobId=47064 NodeList=cpu[12-13] #CPUs=8 Partition=cpu-epyc
[2022-08-02T16:19:30.350] _job_complete: JobId=47056 WEXITSTATUS 0
[2022-08-02T16:19:30.350] _job_complete: JobId=47056 done
[2022-08-02T16:21:02.309] _slurm_rpc_kill_job: REQUEST_KILL_JOB JobId=47064 uid 548200003
[2022-08-02T16:21:31.251] _slurm_rpc_submit_batch_job: JobId=47066 InitPrio=25757 usec=453
[2022-08-02T16:21:36.984] sched/backfill: _start_job: Started JobId=47066 in cpu-epyc on cpu[12-13]
[2022-08-02T16:21:37.304] _job_complete: JobId=47066 WEXITSTATUS 255
[2022-08-02T16:21:37.304] _job_complete: JobId=47066 done
[2022-08-02T16:24:08.390] _slurm_rpc_submit_batch_job: JobId=47067 InitPrio=25757 usec=570
[2022-08-02T16:24:28.503] _update_job: updating accounting
[2022-08-02T16:24:28.503] _slurm_rpc_update_job: complete JobId=47067 uid=548200003 usec=754
[2022-08-02T16:24:29.162] sched: Allocate JobId=47067 NodeList=cpu[12-13] #CPUs=8 Partition=cpu-epyc
[2022-08-02T16:24:33.567] _job_complete: JobId=47067 WEXITSTATUS 16
[2022-08-02T16:24:33.567] _job_complete: JobId=47067 done
[2022-08-02T16:25:34.451] _slurm_rpc_submit_batch_job: JobId=47068 InitPrio=25757 usec=516
[2022-08-02T16:25:36.993] sched/backfill: _start_job: Started JobId=47068 in cpu-epyc on cpu[12-13]
[2022-08-02T16:25:40.686] _job_complete: JobId=47068 WEXITSTATUS 137
[2022-08-02T16:25:40.686] _job_complete: JobId=47068 done
[2022-08-02T16:25:40.756] _slurm_rpc_update_job: JobId=47068 uid=548200003: Job has already finished
[2022-08-02T16:26:47.621] _slurm_rpc_submit_batch_job: JobId=47069 InitPrio=25757 usec=434
[2022-08-02T16:26:52.772] _update_job: updating accounting
[2022-08-02T16:26:52.773] _slurm_rpc_update_job: complete JobId=47069 uid=548200003 usec=775
[2022-08-02T16:26:53.359] sched: Allocate JobId=47069 NodeList=cpu[12-13] #CPUs=8 Partition=cpu-epyc
[2022-08-02T16:27:39.089] _slurm_rpc_kill_job: REQUEST_KILL_JOB JobId=47069 uid 548200003
[2022-08-02T16:28:07.075] _slurm_rpc_submit_batch_job: JobId=47070 InitPrio=25757 usec=421
[2022-08-02T16:28:14.623] _update_job: updating accounting
[2022-08-02T16:28:14.623] _slurm_rpc_update_job: complete JobId=47070 uid=548200003 usec=890
[2022-08-02T16:28:15.558] sched: Allocate JobId=47070 NodeList=cpu[12-13] #CPUs=8 Partition=cpu-epyc
[2022-08-02T16:30:18.304] _job_complete: JobId=46989 WEXITSTATUS 0
[2022-08-02T16:30:18.304] _job_complete: JobId=46989 done
[2022-08-02T16:32:56.496] _slurm_rpc_kill_job: REQUEST_KILL_JOB JobId=47070 uid 548200003
[2022-08-02T16:33:09.903] _slurm_rpc_submit_batch_job: JobId=47071 InitPrio=25757 usec=441
[2022-08-02T16:33:19.383] _update_job: updating accounting
[2022-08-02T16:33:19.383] _slurm_rpc_update_job: complete JobId=47071 uid=548200003 usec=911
[2022-08-02T16:33:20.174] sched: Allocate JobId=47071 NodeList=cpu[12-13] #CPUs=8 Partition=cpu-epyc
[2022-08-02T16:33:45.282] _job_complete: JobId=47065 WEXITSTATUS 0
[2022-08-02T16:33:45.283] _job_complete: JobId=47065 done
[2022-08-02T16:35:27.413] _job_complete: JobId=47071 WEXITSTATUS 0
[2022-08-02T16:35:27.413] _job_complete: JobId=47071 done
[2022-08-02T16:38:17.546] _job_complete: JobId=47022 WEXITSTATUS 0
[2022-08-02T16:38:17.546] _job_complete: JobId=47022 done
[2022-08-02T16:40:39.973] _slurm_rpc_submit_batch_job: JobId=47072 InitPrio=22246 usec=408
[2022-08-02T16:40:40.071] sched: Allocate JobId=47072 NodeList=cpu03 #CPUs=16 Partition=cpu-opteron
[2022-08-02T16:40:41.772] _slurm_rpc_submit_batch_job: JobId=47073 InitPrio=22246 usec=386
[2022-08-02T16:40:43.071] sched: Allocate JobId=47073 NodeList=cpu07 #CPUs=16 Partition=cpu-opteron
[2022-08-02T16:40:52.149] _slurm_rpc_submit_batch_job: JobId=47074 InitPrio=21580 usec=480
[2022-08-02T16:40:53.087] sched: Allocate JobId=47074 NodeList=cpu11 #CPUs=32 Partition=cpu-opteron
[2022-08-02T16:42:50.838] _job_complete: JobId=47021 WEXITSTATUS 0
[2022-08-02T16:42:50.838] _job_complete: JobId=47021 done
[2022-08-02T16:44:19.605] _slurm_rpc_submit_batch_job: JobId=47075 InitPrio=25757 usec=517
[2022-08-02T16:44:20.553] sched: Allocate JobId=47075 NodeList=cpu[03,09] #CPUs=8 Partition=cpu-opteron
[2022-08-02T16:44:21.260] _job_complete: JobId=47075 WEXITSTATUS 255
[2022-08-02T16:44:21.260] _job_complete: JobId=47075 done
[2022-08-02T16:44:42.720] _job_complete: JobId=47074 WEXITSTATUS 1
[2022-08-02T16:44:42.720] _job_complete: JobId=47074 done
[2022-08-02T16:44:58.479] _slurm_rpc_submit_batch_job: JobId=47076 InitPrio=25757 usec=383
[2022-08-02T16:44:58.599] sched: Allocate JobId=47076 NodeList=cpu[03,09] #CPUs=8 Partition=cpu-opteron
[2022-08-02T16:44:59.385] _job_complete: JobId=47076 WEXITSTATUS 255
[2022-08-02T16:44:59.385] _job_complete: JobId=47076 done
[2022-08-02T16:45:16.993] _slurm_rpc_submit_batch_job: JobId=47077 InitPrio=25757 usec=479
[2022-08-02T16:45:17.627] sched: Allocate JobId=47077 NodeList=cpu[03,09] #CPUs=8 Partition=cpu-opteron
[2022-08-02T16:45:18.281] _job_complete: JobId=47077 WEXITSTATUS 255
[2022-08-02T16:45:18.282] _job_complete: JobId=47077 done
[2022-08-02T16:45:28.181] _slurm_rpc_submit_batch_job: JobId=47078 InitPrio=25757 usec=428
[2022-08-02T16:45:28.641] sched: Allocate JobId=47078 NodeList=cpu[03,09] #CPUs=8 Partition=cpu-opteron
[2022-08-02T16:45:29.302] _job_complete: JobId=47078 WEXITSTATUS 255
[2022-08-02T16:45:29.302] _job_complete: JobId=47078 done
[2022-08-02T16:45:53.962] _slurm_rpc_submit_batch_job: JobId=47079 InitPrio=25757 usec=436
[2022-08-02T16:45:54.678] sched: Allocate JobId=47079 NodeList=cpu[03,09] #CPUs=8 Partition=cpu-opteron
[2022-08-02T16:50:14.302] _job_complete: JobId=47038 WEXITSTATUS 0
[2022-08-02T16:50:14.302] _job_complete: JobId=47038 done
[2022-08-02T16:51:15.457] _slurm_rpc_submit_batch_job: JobId=47080 InitPrio=21580 usec=543
[2022-08-02T16:51:16.285] sched: Allocate JobId=47080 NodeList=cpu11 #CPUs=32 Partition=cpu-opteron
[2022-08-02T16:52:39.943] _job_complete: JobId=47079 WEXITSTATUS 0
[2022-08-02T16:52:39.943] _job_complete: JobId=47079 done
[2022-08-02T16:53:35.350] _slurm_rpc_submit_batch_job: JobId=47081 InitPrio=22246 usec=419
[2022-08-02T16:53:35.557] sched: Allocate JobId=47081 NodeList=cpu03 #CPUs=16 Partition=cpu-opteron
[2022-08-02T16:53:37.027] _slurm_rpc_submit_batch_job: JobId=47082 InitPrio=22246 usec=494
[2022-08-02T16:53:38.538] _slurm_rpc_submit_batch_job: JobId=47083 InitPrio=22246 usec=434
[2022-08-02T16:53:38.558] sched: Allocate JobId=47082 NodeList=cpu11 #CPUs=16 Partition=cpu-opteron
[2022-08-02T16:53:38.559] sched: Allocate JobId=47083 NodeList=cpu09 #CPUs=16 Partition=cpu-opteron
[2022-08-02T16:55:01.098] _job_complete: JobId=47080 WEXITSTATUS 1
[2022-08-02T16:55:01.098] _job_complete: JobId=47080 done
[2022-08-02T17:04:52.746] _slurm_rpc_submit_batch_job: JobId=47084 InitPrio=25757 usec=542
[2022-08-02T17:05:26.481] _slurm_rpc_submit_batch_job: JobId=47085 InitPrio=22246 usec=584
[2022-08-02T17:05:26.748] sched: Allocate JobId=47085 NodeList=cpu09 #CPUs=16 Partition=cpu-opteron
[2022-08-02T17:05:28.564] _slurm_rpc_submit_batch_job: JobId=47086 InitPrio=22246 usec=414
[2022-08-02T17:05:29.749] sched: Allocate JobId=47086 NodeList=cpu11 #CPUs=16 Partition=cpu-opteron
[2022-08-02T17:05:30.144] _slurm_rpc_submit_batch_job: JobId=47087 InitPrio=22246 usec=519
[2022-08-02T17:05:31.679] _slurm_rpc_submit_batch_job: JobId=47088 InitPrio=22246 usec=543
[2022-08-02T17:05:32.753] sched: Allocate JobId=47087 NodeList=cpu11 #CPUs=16 Partition=cpu-opteron
[2022-08-02T17:05:33.527] _slurm_rpc_submit_batch_job: JobId=47089 InitPrio=22246 usec=443
[2022-08-02T17:05:37.045] sched/backfill: _start_job: Started JobId=47084 in cpu-epyc on cpu[12-13]
[2022-08-02T17:08:00.322] _job_complete: JobId=47084 WEXITSTATUS 0
[2022-08-02T17:08:00.322] _job_complete: JobId=47084 done
[2022-08-02T17:08:37.363] _slurm_rpc_submit_batch_job: JobId=47090 InitPrio=25757 usec=400
[2022-08-02T17:08:46.423] _slurm_rpc_submit_batch_job: JobId=47091 InitPrio=21580 usec=712
[2022-08-02T17:08:56.544] _update_job: updating accounting
[2022-08-02T17:08:56.544] _slurm_rpc_update_job: complete JobId=47090 uid=548200003 usec=850
[2022-08-02T17:08:57.231] sched: Allocate JobId=47090 NodeList=cpu[13,15] #CPUs=8 Partition=cpu-epyc
[2022-08-02T17:10:24.699] _slurm_rpc_kill_job: REQUEST_KILL_JOB JobId=47090 uid 548200003
[2022-08-02T17:10:44.399] _slurm_rpc_submit_batch_job: JobId=47092 InitPrio=25757 usec=452
[2022-08-02T17:10:49.532] _update_job: updating accounting
[2022-08-02T17:10:49.532] _slurm_rpc_update_job: complete JobId=47092 uid=548200003 usec=786
[2022-08-02T17:10:50.387] sched: Allocate JobId=47092 NodeList=cpu[12-13] #CPUs=8 Partition=cpu-epyc
[2022-08-02T17:12:29.942] _slurm_rpc_kill_job: REQUEST_KILL_JOB JobId=47092 uid 548200003
[2022-08-02T17:12:39.381] _slurm_rpc_submit_batch_job: JobId=47093 InitPrio=25757 usec=404
[2022-08-02T17:13:04.294] _update_job: updating accounting
[2022-08-02T17:13:04.294] _slurm_rpc_update_job: complete JobId=47093 uid=548200003 usec=1278
[2022-08-02T17:13:04.780] sched: Allocate JobId=47093 NodeList=cpu[12-13] #CPUs=8 Partition=cpu-epyc
[2022-08-02T17:13:49.499] _slurm_rpc_submit_batch_job: JobId=47094 InitPrio=21717 usec=470
[2022-08-02T17:14:03.272] _slurm_rpc_kill_job: REQUEST_KILL_JOB JobId=47091 uid 548200023
[2022-08-02T17:14:04.820] _slurm_rpc_submit_batch_job: JobId=47095 InitPrio=22246 usec=437
[2022-08-02T17:14:06.908] _slurm_rpc_submit_batch_job: JobId=47096 InitPrio=22246 usec=387
[2022-08-02T17:14:08.644] _slurm_rpc_submit_batch_job: JobId=47097 InitPrio=22246 usec=443
[2022-08-02T17:14:10.348] _slurm_rpc_submit_batch_job: JobId=47098 InitPrio=22246 usec=443
[2022-08-02T17:14:13.331] _slurm_rpc_submit_batch_job: JobId=47099 InitPrio=22246 usec=577
[2022-08-02T17:14:41.492] _slurm_rpc_submit_batch_job: JobId=47100 InitPrio=21580 usec=557
[2022-08-02T17:14:59.802] _slurm_rpc_kill_job: REQUEST_KILL_JOB JobId=47094 uid 548200023
[2022-08-02T17:15:58.860] _slurm_rpc_submit_batch_job: JobId=47101 InitPrio=21191 usec=426
[2022-08-02T17:16:01.300] _slurm_rpc_kill_job: REQUEST_KILL_JOB JobId=47093 uid 548200003
[2022-08-02T17:16:06.300] _slurm_rpc_submit_batch_job: JobId=47102 InitPrio=25757 usec=404
[2022-08-02T17:16:25.953] _update_job: updating accounting
[2022-08-02T17:16:25.953] _slurm_rpc_update_job: complete JobId=47102 uid=548200003 usec=796
[2022-08-02T17:16:26.070] sched: Allocate JobId=47102 NodeList=cpu[12-13] #CPUs=8 Partition=cpu-epyc
[2022-08-02T17:16:26.362] _job_complete: JobId=47102 WEXITSTATUS 255
[2022-08-02T17:16:26.362] _job_complete: JobId=47102 done
[2022-08-02T17:17:51.684] _job_complete: JobId=47039 WEXITSTATUS 0
[2022-08-02T17:17:51.684] _job_complete: JobId=47039 done
[2022-08-02T17:17:52.126] sched: Allocate JobId=47088 NodeList=cpu03 #CPUs=16 Partition=cpu-opteron
[2022-08-02T17:19:32.969] _slurm_rpc_submit_batch_job: JobId=47103 InitPrio=25757 usec=623
[2022-08-02T17:19:37.072] sched/backfill: _start_job: Started JobId=47103 in cpu-epyc on cpu[12-13]
[2022-08-02T17:19:39.793] _update_job: updating accounting
[2022-08-02T17:19:39.793] _slurm_rpc_update_job: complete JobId=47103 uid=548200003 usec=553
[2022-08-02T17:38:19.347] _slurm_rpc_submit_batch_job: JobId=47104 InitPrio=22246 usec=414
[2022-08-02T17:38:21.282] _slurm_rpc_submit_batch_job: JobId=47105 InitPrio=22246 usec=382
[2022-08-02T17:38:22.822] _slurm_rpc_submit_batch_job: JobId=47106 InitPrio=22246 usec=441
[2022-08-02T17:38:24.919] _slurm_rpc_submit_batch_job: JobId=47107 InitPrio=22246 usec=595
[2022-08-02T17:38:26.454] _slurm_rpc_submit_batch_job: JobId=47108 InitPrio=22246 usec=452
[2022-08-02T17:38:27.902] _slurm_rpc_submit_batch_job: JobId=47109 InitPrio=22246 usec=441
[2022-08-02T17:38:29.334] _slurm_rpc_submit_batch_job: JobId=47110 InitPrio=22246 usec=432
[2022-08-02T17:38:30.833] _slurm_rpc_submit_batch_job: JobId=47111 InitPrio=22246 usec=418
[2022-08-02T17:38:32.815] _slurm_rpc_submit_batch_job: JobId=47112 InitPrio=22246 usec=436
[2022-08-02T17:38:35.054] _slurm_rpc_submit_batch_job: JobId=47113 InitPrio=22246 usec=466
[2022-08-02T17:38:36.815] _slurm_rpc_submit_batch_job: JobId=47114 InitPrio=22246 usec=467
[2022-08-02T17:38:38.222] _slurm_rpc_submit_batch_job: JobId=47115 InitPrio=22246 usec=452
[2022-08-02T17:38:39.718] _slurm_rpc_submit_batch_job: JobId=47116 InitPrio=22246 usec=480
[2022-08-02T17:38:41.207] _slurm_rpc_submit_batch_job: JobId=47117 InitPrio=22246 usec=462
[2022-08-02T17:38:42.902] _slurm_rpc_submit_batch_job: JobId=47118 InitPrio=22246 usec=450
[2022-08-02T17:38:44.974] _slurm_rpc_submit_batch_job: JobId=47119 InitPrio=22246 usec=435
[2022-08-02T17:38:48.279] _slurm_rpc_submit_batch_job: JobId=47120 InitPrio=22246 usec=434
[2022-08-02T17:38:50.614] _slurm_rpc_submit_batch_job: JobId=47121 InitPrio=22246 usec=491
[2022-08-02T17:38:53.807] _slurm_rpc_submit_batch_job: JobId=47122 InitPrio=22246 usec=447
[2022-08-02T17:50:25.396] _job_complete: JobId=47083 WEXITSTATUS 0
[2022-08-02T17:50:25.396] _job_complete: JobId=47083 done
[2022-08-02T17:50:25.789] sched: Allocate JobId=47089 NodeList=cpu09 #CPUs=16 Partition=cpu-opteron
[2022-08-02T17:52:26.794] _job_complete: JobId=47081 WEXITSTATUS 0
[2022-08-02T17:52:26.794] _job_complete: JobId=47081 done
[2022-08-02T17:52:27.238] sched: Allocate JobId=47095 NodeList=cpu03 #CPUs=16 Partition=cpu-opteron
[2022-08-02T17:55:25.734] _job_complete: JobId=47082 WEXITSTATUS 0
[2022-08-02T17:55:25.735] _job_complete: JobId=47082 done
[2022-08-02T17:55:26.182] sched: Allocate JobId=47096 NodeList=cpu11 #CPUs=16 Partition=cpu-opteron
[2022-08-02T18:32:22.809] _job_complete: JobId=47073 WEXITSTATUS 0
[2022-08-02T18:32:22.809] _job_complete: JobId=47073 done
[2022-08-02T18:32:23.335] sched: Allocate JobId=47097 NodeList=cpu07 #CPUs=16 Partition=cpu-opteron
[2022-08-02T18:34:18.922] _job_complete: JobId=47072 WEXITSTATUS 0
[2022-08-02T18:34:18.922] _job_complete: JobId=47072 done
[2022-08-02T18:34:19.306] sched: Allocate JobId=47098 NodeList=cpu03 #CPUs=16 Partition=cpu-opteron
[2022-08-02T22:02:19.552] _job_complete: JobId=46990 WEXITSTATUS 0
[2022-08-02T22:02:19.552] _job_complete: JobId=46990 done
[2022-08-02T22:02:19.985] sched: Allocate JobId=47099 NodeList=cpu03 #CPUs=16 Partition=cpu-opteron
[2022-08-02T22:32:51.692] _job_complete: JobId=47086 WEXITSTATUS 0
[2022-08-02T22:32:51.692] _job_complete: JobId=47086 done
[2022-08-02T22:32:52.119] sched: Allocate JobId=47104 NodeList=cpu11 #CPUs=16 Partition=cpu-opteron
[2022-08-02T23:21:03.162] Time limit exhausted for JobId=46567
[2022-08-02T23:21:24.184] sched: Allocate JobId=47105 NodeList=cpu10 #CPUs=16 Partition=cpu-opteron
[2022-08-02T23:21:24.184] sched: Allocate JobId=47106 NodeList=cpu10 #CPUs=16 Partition=cpu-opteron
[2022-08-02T23:21:24.185] sched: Allocate JobId=47107 NodeList=cpu10 #CPUs=16 Partition=cpu-opteron
[2022-08-02T23:21:24.185] sched: Allocate JobId=47108 NodeList=cpu10 #CPUs=16 Partition=cpu-opteron
[2022-08-02T23:25:35.051] _job_complete: JobId=47087 WEXITSTATUS 0
[2022-08-02T23:25:35.052] _job_complete: JobId=47087 done
[2022-08-02T23:25:35.483] sched: Allocate JobId=47109 NodeList=cpu11 #CPUs=16 Partition=cpu-opteron
[2022-08-03T00:02:54.957] _job_complete: JobId=47085 WEXITSTATUS 0
[2022-08-03T00:02:54.957] _job_complete: JobId=47085 done
[2022-08-03T00:02:55.296] sched: Allocate JobId=47110 NodeList=cpu09 #CPUs=16 Partition=cpu-opteron
[2022-08-03T00:32:40.047] _job_complete: JobId=47088 WEXITSTATUS 0
[2022-08-03T00:32:40.048] _job_complete: JobId=47088 done
[2022-08-03T00:32:40.536] sched: Allocate JobId=47111 NodeList=cpu03 #CPUs=16 Partition=cpu-opteron
[2022-08-03T00:39:10.126] _job_complete: JobId=47095 WEXITSTATUS 0
[2022-08-03T00:39:10.127] _job_complete: JobId=47095 done
[2022-08-03T00:39:10.594] sched: Allocate JobId=47112 NodeList=cpu03 #CPUs=16 Partition=cpu-opteron
[2022-08-03T00:40:53.656] _slurm_rpc_submit_batch_job: JobId=47123 InitPrio=21384 usec=591
[2022-08-03T01:12:19.007] _job_complete: JobId=47089 WEXITSTATUS 0
[2022-08-03T01:12:19.007] _job_complete: JobId=47089 done
[2022-08-03T01:12:19.459] sched: Allocate JobId=47113 NodeList=cpu09 #CPUs=16 Partition=cpu-opteron
[2022-08-03T01:26:38.146] _job_complete: JobId=47096 WEXITSTATUS 0
[2022-08-03T01:26:38.147] _job_complete: JobId=47096 done
[2022-08-03T01:26:38.636] sched: Allocate JobId=47114 NodeList=cpu11 #CPUs=16 Partition=cpu-opteron
[2022-08-03T02:08:29.320] _job_complete: JobId=47098 WEXITSTATUS 0
[2022-08-03T02:08:29.320] _job_complete: JobId=47098 done
[2022-08-03T02:08:29.728] sched: Allocate JobId=47115 NodeList=cpu03 #CPUs=16 Partition=cpu-opteron
[2022-08-03T04:07:43.427] _job_complete: JobId=46893 WEXITSTATUS 0
[2022-08-03T04:07:43.428] _job_complete: JobId=46893 done
[2022-08-03T04:07:44.469] sched: Allocate JobId=47116 NodeList=cpu07 #CPUs=16 Partition=cpu-opteron
[2022-08-03T04:24:36.773] _job_complete: JobId=47097 WEXITSTATUS 0
[2022-08-03T04:24:36.773] _job_complete: JobId=47097 done
[2022-08-03T04:24:37.343] sched: Allocate JobId=47117 NodeList=cpu07 #CPUs=16 Partition=cpu-opteron
[2022-08-03T05:46:12.616] _job_complete: JobId=47104 WEXITSTATUS 0
[2022-08-03T05:46:12.617] _job_complete: JobId=47104 done
[2022-08-03T05:46:13.047] sched: Allocate JobId=47118 NodeList=cpu11 #CPUs=16 Partition=cpu-opteron
[2022-08-03T05:57:18.385] _job_complete: JobId=47106 WEXITSTATUS 0
[2022-08-03T05:57:18.385] _job_complete: JobId=47106 done
[2022-08-03T05:57:18.897] sched: Allocate JobId=47119 NodeList=cpu10 #CPUs=16 Partition=cpu-opteron
[2022-08-03T06:58:05.904] _job_complete: JobId=47108 WEXITSTATUS 0
[2022-08-03T06:58:05.904] _job_complete: JobId=47108 done
[2022-08-03T06:58:06.333] sched: Allocate JobId=47120 NodeList=cpu10 #CPUs=16 Partition=cpu-opteron
[2022-08-03T07:51:26.561] _job_complete: JobId=47109 WEXITSTATUS 0
[2022-08-03T07:51:26.561] _job_complete: JobId=47109 done
[2022-08-03T07:51:27.136] sched: Allocate JobId=47121 NodeList=cpu11 #CPUs=16 Partition=cpu-opteron
[2022-08-03T08:01:01.346] _job_complete: JobId=47099 WEXITSTATUS 0
[2022-08-03T08:01:01.347] _job_complete: JobId=47099 done
[2022-08-03T08:01:01.833] sched: Allocate JobId=47122 NodeList=cpu03 #CPUs=16 Partition=cpu-opteron
[2022-08-03T08:38:43.329] _slurm_rpc_kill_job: REQUEST_KILL_JOB JobId=46913 uid 548300543
[2022-08-03T08:39:02.550] sched: Allocate JobId=46935 NodeList=cpu12 #CPUs=32 Partition=cpu-epyc
[2022-08-03T08:42:35.558] _slurm_rpc_kill_job: REQUEST_KILL_JOB JobId=47103 uid 548200003
[2022-08-03T08:54:36.656] _slurm_rpc_submit_batch_job: JobId=47124 InitPrio=20915 usec=448
[2022-08-03T08:59:59.729] _slurm_rpc_submit_batch_job: JobId=47125 InitPrio=25984 usec=480
[2022-08-03T08:59:59.766] sched: Allocate JobId=47125 NodeList=cpu07 #CPUs=8 Partition=cpu-opteron
[2022-08-03T09:00:00.398] _job_complete: JobId=47125 WEXITSTATUS 0
[2022-08-03T09:00:00.398] _job_complete: JobId=47125 done
[2022-08-03T09:00:21.527] _job_complete: JobId=47115 WEXITSTATUS 0
[2022-08-03T09:00:21.527] _job_complete: JobId=47115 done
[2022-08-03T09:00:39.377] sched/backfill: _start_job: Started JobId=47101 in cpu-opteron on cpu[03,07]
[2022-08-03T09:00:39.403] _slurm_rpc_submit_batch_job: JobId=47126 InitPrio=25389 usec=388
[2022-08-03T09:02:09.447] _job_complete: JobId=47113 WEXITSTATUS 0
[2022-08-03T09:02:09.447] _job_complete: JobId=47113 done
[2022-08-03T09:02:58.422] Requeuing JobId=47101
[2022-08-03T09:02:58.423] sched: Allocate JobId=47126 NodeList=cpu[03,07] #CPUs=16 Partition=cpu-opteron
[2022-08-03T09:02:58.989] _job_complete: JobId=47126 WEXITSTATUS 0
[2022-08-03T09:02:58.989] _job_complete: JobId=47126 done
[2022-08-03T09:03:36.074] _job_complete: JobId=47107 WEXITSTATUS 0
[2022-08-03T09:03:36.074] _job_complete: JobId=47107 done
[2022-08-03T09:03:39.400] sched/backfill: _start_job: Started JobId=47124 in cpu-opteron on cpu03
[2022-08-03T09:16:25.913] _job_complete: JobId=47112 WEXITSTATUS 0
[2022-08-03T09:16:25.913] _job_complete: JobId=47112 done
[2022-08-03T09:40:53.180] _slurm_rpc_submit_batch_job: JobId=47127 InitPrio=24726 usec=454
[2022-08-03T09:40:53.566] sched: Allocate JobId=47127 NodeList=cpu[12-13] #CPUs=32 Partition=cpu-epyc
[2022-08-03T09:41:11.777] _job_complete: JobId=47105 WEXITSTATUS 0
[2022-08-03T09:41:11.777] _job_complete: JobId=47105 done
[2022-08-03T09:41:12.173] sched: Allocate JobId=47100 NodeList=cpu10 #CPUs=32 Partition=cpu-opteron
[2022-08-03T09:41:31.677] _slurm_rpc_kill_job: REQUEST_KILL_JOB JobId=47127 uid 548200003
[2022-08-03T09:41:48.452] _slurm_rpc_submit_batch_job: JobId=47128 InitPrio=24452 usec=478
[2022-08-03T09:41:48.618] sched: Allocate JobId=47128 NodeList=cpu[12-13] #CPUs=64 Partition=cpu-epyc
[2022-08-03T09:42:25.267] _slurm_rpc_kill_job: REQUEST_KILL_JOB JobId=47128 uid 548200003
[2022-08-03T09:42:49.336] _slurm_rpc_submit_batch_job: JobId=47129 InitPrio=24452 usec=365
[2022-08-03T09:42:49.928] sched: Allocate JobId=47129 NodeList=cpu[12-13] #CPUs=64 Partition=cpu-epyc
[2022-08-03T09:43:43.619] _slurm_rpc_kill_job: REQUEST_KILL_JOB JobId=47129 uid 548200003
[2022-08-03T09:44:36.442] _slurm_rpc_submit_batch_job: JobId=47130 InitPrio=24452 usec=486
[2022-08-03T09:44:37.080] sched: Allocate JobId=47130 NodeList=cpu[12-13] #CPUs=64 Partition=cpu-epyc
[2022-08-03T09:44:49.071] _job_complete: JobId=47130 WEXITSTATUS 0
[2022-08-03T09:44:49.071] _job_complete: JobId=47130 done
[2022-08-03T09:45:00.601] _job_complete: JobId=47100 WEXITSTATUS 1
[2022-08-03T09:45:00.602] _job_complete: JobId=47100 done
[2022-08-03T09:45:39.477] sched/backfill: _start_job: Started JobId=47123 in cpu-opteron on cpu10
[2022-08-03T09:46:22.471] _slurm_rpc_submit_batch_job: JobId=47131 InitPrio=24452 usec=576
[2022-08-03T09:46:23.231] sched: Allocate JobId=47131 NodeList=cpu[12-13] #CPUs=64 Partition=cpu-epyc
[2022-08-03T09:46:29.213] _job_complete: JobId=47131 WEXITSTATUS 0
[2022-08-03T09:46:29.213] _job_complete: JobId=47131 done
[2022-08-03T09:48:44.485] _slurm_rpc_submit_batch_job: JobId=47132 InitPrio=24452 usec=397
[2022-08-03T09:48:44.796] sched: Allocate JobId=47132 NodeList=cpu[12-13] #CPUs=64 Partition=cpu-epyc
[2022-08-03T09:48:48.638] _job_complete: JobId=47132 WEXITSTATUS 0
[2022-08-03T09:48:48.638] _job_complete: JobId=47132 done
[2022-08-03T09:50:00.380] _slurm_rpc_submit_batch_job: JobId=47133 InitPrio=24452 usec=536
[2022-08-03T09:50:00.904] sched: Allocate JobId=47133 NodeList=cpu[12-13] #CPUs=64 Partition=cpu-epyc
[2022-08-03T09:50:04.566] _job_complete: JobId=47133 WEXITSTATUS 0
[2022-08-03T09:50:04.566] _job_complete: JobId=47133 done
[2022-08-03T09:51:49.885] _slurm_rpc_submit_batch_job: JobId=47134 InitPrio=24452 usec=476
[2022-08-03T09:51:50.060] sched: Allocate JobId=47134 NodeList=cpu[12-13] #CPUs=64 Partition=cpu-epyc
[2022-08-03T09:51:56.432] _job_complete: JobId=47134 WEXITSTATUS 0
[2022-08-03T09:51:56.432] _job_complete: JobId=47134 done
[2022-08-03T09:52:40.290] _slurm_rpc_submit_batch_job: JobId=47135 InitPrio=24726 usec=499
[2022-08-03T09:52:40.365] sched: Allocate JobId=47135 NodeList=cpu[12-13] #CPUs=32 Partition=cpu-epyc
[2022-08-03T09:54:06.030] _slurm_rpc_kill_job: REQUEST_KILL_JOB JobId=47135 uid 548200003
[2022-08-03T09:54:08.494] _slurm_rpc_submit_batch_job: JobId=47136 InitPrio=24726 usec=418
[2022-08-03T09:54:08.531] sched: Allocate JobId=47136 NodeList=cpu[13,15] #CPUs=32 Partition=cpu-epyc
[2022-08-03T09:54:16.009] _job_complete: JobId=47136 WEXITSTATUS 0
[2022-08-03T09:54:16.009] _job_complete: JobId=47136 done
[2022-08-03T09:55:57.094] _slurm_rpc_submit_batch_job: JobId=47137 InitPrio=24726 usec=479
[2022-08-03T09:55:57.683] sched: Allocate JobId=47137 NodeList=cpu[12-13] #CPUs=32 Partition=cpu-epyc
[2022-08-03T09:56:02.836] _job_complete: JobId=47137 WEXITSTATUS 255
[2022-08-03T09:56:02.836] _job_complete: JobId=47137 done
[2022-08-03T09:57:39.523] _slurm_rpc_submit_batch_job: JobId=47138 InitPrio=24726 usec=409
[2022-08-03T09:57:40.000] sched: Allocate JobId=47138 NodeList=cpu[12-13] #CPUs=32 Partition=cpu-epyc
[2022-08-03T09:58:32.558] _slurm_rpc_kill_job: REQUEST_KILL_JOB JobId=47138 uid 548200003
[2022-08-03T09:58:48.760] _slurm_rpc_submit_batch_job: JobId=47139 InitPrio=24726 usec=407
[2022-08-03T09:58:49.138] sched: Allocate JobId=47139 NodeList=cpu[12,15] #CPUs=32 Partition=cpu-epyc
[2022-08-03T09:59:33.453] _slurm_rpc_kill_job: REQUEST_KILL_JOB JobId=47139 uid 548200003
[2022-08-03T10:00:00.493] _slurm_rpc_submit_batch_job: JobId=47140 InitPrio=24726 usec=408
[2022-08-03T10:00:01.235] sched: Allocate JobId=47140 NodeList=cpu[12-13] #CPUs=32 Partition=cpu-epyc
[2022-08-03T10:00:42.454] _slurm_rpc_kill_job: REQUEST_KILL_JOB JobId=47140 uid 548200003
[2022-08-03T10:01:27.399] _slurm_rpc_submit_batch_job: JobId=47141 InitPrio=24726 usec=417
[2022-08-03T10:01:28.357] sched: Allocate JobId=47141 NodeList=cpu[12-13] #CPUs=32 Partition=cpu-epyc
[2022-08-03T10:01:33.510] _job_complete: JobId=47141 WEXITSTATUS 0
[2022-08-03T10:01:33.510] _job_complete: JobId=47141 done
[2022-08-03T10:03:13.087] _slurm_rpc_submit_batch_job: JobId=47142 InitPrio=24726 usec=507
[2022-08-03T10:03:13.952] sched: Allocate JobId=47142 NodeList=cpu[12-13] #CPUs=32 Partition=cpu-epyc
[2022-08-03T10:03:17.179] _job_complete: JobId=47142 WEXITSTATUS 0
[2022-08-03T10:03:17.179] _job_complete: JobId=47142 done
[2022-08-03T10:04:29.621] _slurm_rpc_submit_batch_job: JobId=47143 InitPrio=24726 usec=479
[2022-08-03T10:04:30.052] sched: Allocate JobId=47143 NodeList=cpu[12-13] #CPUs=32 Partition=cpu-epyc
[2022-08-03T10:04:32.695] _job_complete: JobId=47143 WEXITSTATUS 0
[2022-08-03T10:04:32.695] _job_complete: JobId=47143 done
[2022-08-03T10:04:44.828] _slurm_rpc_submit_batch_job: JobId=47144 InitPrio=24931 usec=393
[2022-08-03T10:04:45.072] sched: Allocate JobId=47144 NodeList=cpu[12-13] #CPUs=8 Partition=cpu-epyc
[2022-08-03T10:04:48.001] _job_complete: JobId=47144 WEXITSTATUS 0
[2022-08-03T10:04:48.001] _job_complete: JobId=47144 done
[2022-08-03T10:05:04.277] _slurm_rpc_submit_batch_job: JobId=47145 InitPrio=24931 usec=397
[2022-08-03T10:05:05.098] sched: Allocate JobId=47145 NodeList=cpu[12-13] #CPUs=8 Partition=cpu-epyc
[2022-08-03T10:05:05.412] _job_complete: JobId=47145 WEXITSTATUS 255
[2022-08-03T10:05:05.412] _job_complete: JobId=47145 done
[2022-08-03T10:05:41.631] _slurm_rpc_submit_batch_job: JobId=47146 InitPrio=24931 usec=429
[2022-08-03T10:05:42.151] sched: Allocate JobId=47146 NodeList=cpu[12-13] #CPUs=8 Partition=cpu-epyc
[2022-08-03T10:05:44.946] _job_complete: JobId=47146 WEXITSTATUS 0
[2022-08-03T10:05:44.946] _job_complete: JobId=47146 done
[2022-08-03T10:06:22.772] _slurm_rpc_submit_batch_job: JobId=47147 InitPrio=24931 usec=540
[2022-08-03T10:06:23.207] sched: Allocate JobId=47147 NodeList=cpu[12-13] #CPUs=8 Partition=cpu-epyc
[2022-08-03T10:06:25.705] _job_complete: JobId=47147 WEXITSTATUS 0
[2022-08-03T10:06:25.705] _job_complete: JobId=47147 done
[2022-08-03T10:06:48.835] _slurm_rpc_submit_batch_job: JobId=47148 InitPrio=24931 usec=423
[2022-08-03T10:06:49.244] sched: Allocate JobId=47148 NodeList=cpu[12-13] #CPUs=8 Partition=cpu-epyc
[2022-08-03T10:06:51.896] _job_complete: JobId=47148 WEXITSTATUS 0
[2022-08-03T10:06:51.896] _job_complete: JobId=47148 done
[2022-08-03T10:07:12.799] _slurm_rpc_submit_batch_job: JobId=47149 InitPrio=24931 usec=394
[2022-08-03T10:07:13.278] sched: Allocate JobId=47149 NodeList=cpu[12-13] #CPUs=8 Partition=cpu-epyc
[2022-08-03T10:14:52.280] _job_complete: JobId=47149 WEXITSTATUS 0
[2022-08-03T10:14:52.280] _job_complete: JobId=47149 done
[2022-08-03T10:14:59.415] _job_complete: JobId=47111 WEXITSTATUS 0
[2022-08-03T10:14:59.415] _job_complete: JobId=47111 done
[2022-08-03T10:21:26.581] _slurm_rpc_submit_batch_job: JobId=47150 InitPrio=24062 usec=447
[2022-08-03T10:21:39.530] sched/backfill: _start_job: Started JobId=47150 in cpu-epyc on cpu[12-13,15]
[2022-08-03T10:21:47.290] _update_job: updating accounting
[2022-08-03T10:21:47.290] _slurm_rpc_update_job: complete JobId=47150 uid=548200003 usec=641
[2022-08-03T10:23:50.310] _slurm_rpc_kill_job: REQUEST_KILL_JOB JobId=47150 uid 548200003
[2022-08-03T10:25:54.869] _slurm_rpc_submit_batch_job: JobId=47151 InitPrio=24062 usec=383
[2022-08-03T10:26:08.716] _update_job: updating accounting
[2022-08-03T10:26:08.716] _slurm_rpc_update_job: complete JobId=47151 uid=548200003 usec=988
[2022-08-03T10:26:09.404] sched: Allocate JobId=47151 NodeList=cpu[12-13,15] #CPUs=48 Partition=cpu-epyc
[2022-08-03T10:26:56.794] _slurm_rpc_kill_job: REQUEST_KILL_JOB JobId=47151 uid 548200003
[2022-08-03T10:27:54.309] _slurm_rpc_submit_batch_job: JobId=47152 InitPrio=24062 usec=416
[2022-08-03T10:28:04.805] _update_job: updating accounting
[2022-08-03T10:28:04.805] _slurm_rpc_update_job: complete JobId=47152 uid=548200003 usec=724
[2022-08-03T10:28:05.674] sched: Allocate JobId=47152 NodeList=cpu[12-13,15] #CPUs=48 Partition=cpu-epyc
[2022-08-03T10:28:07.885] _job_complete: JobId=47152 WEXITSTATUS 0
[2022-08-03T10:28:07.885] _job_complete: JobId=47152 done
[2022-08-03T10:33:30.083] _slurm_rpc_submit_batch_job: JobId=47153 InitPrio=24062 usec=792
[2022-08-03T10:33:39.550] sched/backfill: _start_job: Started JobId=47153 in cpu-epyc on cpu[12-13,15]
[2022-08-03T10:33:46.525] _update_job: updating accounting
[2022-08-03T10:33:46.526] _slurm_rpc_update_job: complete JobId=47153 uid=548200003 usec=774
[2022-08-03T10:36:31.340] _slurm_rpc_kill_job: REQUEST_KILL_JOB JobId=47153 uid 548200003
[2022-08-03T10:36:48.587] _slurm_rpc_submit_batch_job: JobId=47154 InitPrio=24062 usec=443
[2022-08-03T10:37:02.310] _update_job: updating accounting
[2022-08-03T10:37:02.310] _slurm_rpc_update_job: complete JobId=47154 uid=548200003 usec=920
[2022-08-03T10:37:02.571] sched: Allocate JobId=47154 NodeList=cpu[12-13,15] #CPUs=48 Partition=cpu-epyc
[2022-08-03T10:37:07.062] _job_complete: JobId=47154 WEXITSTATUS 0
[2022-08-03T10:37:07.062] _job_complete: JobId=47154 done
[2022-08-03T10:38:11.637] _slurm_rpc_submit_batch_job: JobId=47155 InitPrio=24062 usec=437
[2022-08-03T10:38:18.396] _update_job: updating accounting
[2022-08-03T10:38:18.396] _slurm_rpc_update_job: complete JobId=47155 uid=548200003 usec=697
[2022-08-03T10:38:18.824] sched: Allocate JobId=47155 NodeList=cpu[12-13,15] #CPUs=48 Partition=cpu-epyc
[2022-08-03T10:38:23.586] _job_complete: JobId=47155 WEXITSTATUS 0
[2022-08-03T10:38:23.586] _job_complete: JobId=47155 done
[2022-08-03T10:39:04.597] _slurm_rpc_submit_batch_job: JobId=47156 InitPrio=24726 usec=374
[2022-08-03T10:39:05.888] sched: Allocate JobId=47156 NodeList=cpu[12-13] #CPUs=32 Partition=cpu-epyc
[2022-08-03T10:39:09.089] _update_job: updating accounting
[2022-08-03T10:39:09.089] _slurm_rpc_update_job: complete JobId=47156 uid=548200003 usec=756
[2022-08-03T10:39:28.461] _job_complete: JobId=47156 WEXITSTATUS 0
[2022-08-03T10:39:28.462] _job_complete: JobId=47156 done
[2022-08-03T10:40:50.003] _slurm_rpc_submit_batch_job: JobId=47157 InitPrio=24726 usec=462
[2022-08-03T10:40:50.031] sched: Allocate JobId=47157 NodeList=cpu[12-13] #CPUs=32 Partition=cpu-epyc
[2022-08-03T10:40:55.202] _update_job: updating accounting
[2022-08-03T10:40:55.202] _slurm_rpc_update_job: complete JobId=47157 uid=548200003 usec=804
[2022-08-03T10:40:55.535] _job_complete: JobId=47157 WEXITSTATUS 0
[2022-08-03T10:40:55.535] _job_complete: JobId=47157 done
[2022-08-03T10:42:19.608] _slurm_rpc_submit_batch_job: JobId=47158 InitPrio=24726 usec=416
[2022-08-03T10:42:20.153] sched: Allocate JobId=47158 NodeList=cpu[12-13] #CPUs=32 Partition=cpu-epyc
[2022-08-03T10:42:24.116] _job_complete: JobId=47158 WEXITSTATUS 0
[2022-08-03T10:42:24.116] _job_complete: JobId=47158 done
[2022-08-03T10:46:31.874] _slurm_rpc_submit_batch_job: JobId=47159 InitPrio=24726 usec=535
[2022-08-03T10:46:32.604] sched: Allocate JobId=47159 NodeList=cpu[12-13] #CPUs=32 Partition=cpu-epyc
[2022-08-03T10:46:37.415] _job_complete: JobId=47159 WEXITSTATUS 0
[2022-08-03T10:46:37.416] _job_complete: JobId=47159 done
[2022-08-03T10:54:15.816] _slurm_rpc_submit_batch_job: JobId=47160 InitPrio=24726 usec=514
[2022-08-03T10:54:16.533] sched: Allocate JobId=47160 NodeList=cpu[12-13] #CPUs=32 Partition=cpu-epyc
[2022-08-03T10:56:30.254] _slurm_rpc_kill_job: REQUEST_KILL_JOB JobId=47160 uid 548200003
[2022-08-03T10:58:12.789] _slurm_rpc_submit_batch_job: JobId=47161 InitPrio=24726 usec=705
[2022-08-03T10:58:13.033] sched: Allocate JobId=47161 NodeList=cpu[12-13] #CPUs=32 Partition=cpu-epyc
[2022-08-03T10:58:17.113] _job_complete: JobId=47161 WEXITSTATUS 0
[2022-08-03T10:58:17.113] _job_complete: JobId=47161 done
[2022-08-03T10:59:58.283] _slurm_rpc_submit_batch_job: JobId=47162 InitPrio=24726 usec=479
[2022-08-03T10:59:59.178] sched: Allocate JobId=47162 NodeList=cpu[12-13] #CPUs=32 Partition=cpu-epyc
[2022-08-03T11:00:03.820] _job_complete: JobId=47162 WEXITSTATUS 0
[2022-08-03T11:00:03.820] _job_complete: JobId=47162 done
[2022-08-03T11:00:53.221] _slurm_rpc_submit_batch_job: JobId=47163 InitPrio=24863 usec=456
[2022-08-03T11:00:53.253] sched: Allocate JobId=47163 NodeList=cpu[12-13] #CPUs=16 Partition=cpu-epyc
[2022-08-03T11:00:56.173] _job_complete: JobId=47163 WEXITSTATUS 0
[2022-08-03T11:00:56.173] _job_complete: JobId=47163 done
[2022-08-03T11:03:58.712] _slurm_rpc_submit_batch_job: JobId=47164 InitPrio=24863 usec=418
[2022-08-03T11:03:59.589] sched: Allocate JobId=47164 NodeList=cpu[12-13] #CPUs=16 Partition=cpu-epyc
[2022-08-03T11:04:03.323] _job_complete: JobId=47164 WEXITSTATUS 0
[2022-08-03T11:04:03.323] _job_complete: JobId=47164 done
[2022-08-03T11:04:35.614] _slurm_rpc_submit_batch_job: JobId=47165 InitPrio=24863 usec=472
[2022-08-03T11:04:35.640] sched: Allocate JobId=47165 NodeList=cpu[12-13] #CPUs=16 Partition=cpu-epyc
[2022-08-03T11:04:38.328] _job_complete: JobId=47165 WEXITSTATUS 0
[2022-08-03T11:04:38.329] _job_complete: JobId=47165 done
[2022-08-03T11:08:53.809] _slurm_rpc_submit_batch_job: JobId=47166 InitPrio=24863 usec=472
[2022-08-03T11:08:54.131] sched: Allocate JobId=47166 NodeList=cpu[12-13] #CPUs=16 Partition=cpu-epyc
[2022-08-03T11:08:57.988] _job_complete: JobId=47166 WEXITSTATUS 0
[2022-08-03T11:08:57.988] _job_complete: JobId=47166 done
[2022-08-03T11:10:46.680] _job_complete: JobId=47110 WEXITSTATUS 0
[2022-08-03T11:10:46.680] _job_complete: JobId=47110 done
[2022-08-03T11:12:15.510] _slurm_rpc_submit_batch_job: JobId=47167 InitPrio=21968 usec=528
[2022-08-03T11:12:26.775] _slurm_rpc_submit_batch_job: JobId=47168 InitPrio=21968 usec=463
[2022-08-03T11:12:32.089] _slurm_rpc_submit_batch_job: JobId=47169 InitPrio=21968 usec=411
[2022-08-03T11:12:36.703] _slurm_rpc_submit_batch_job: JobId=47170 InitPrio=21968 usec=448
[2022-08-03T11:12:39.615] sched/backfill: _start_job: Started JobId=47167 in cpu-epyc on cpu15
[2022-08-03T11:12:39.616] sched/backfill: _start_job: Started JobId=47168 in cpu-epyc on cpu12
[2022-08-03T11:12:39.617] sched/backfill: _start_job: Started JobId=47169 in cpu-epyc on cpu13
[2022-08-03T11:12:46.711] _slurm_rpc_submit_batch_job: JobId=47171 InitPrio=21968 usec=440
[2022-08-03T11:12:55.952] _slurm_rpc_submit_batch_job: JobId=47172 InitPrio=21968 usec=413
[2022-08-03T11:13:00.303] _slurm_rpc_submit_batch_job: JobId=47173 InitPrio=21968 usec=480
[2022-08-03T11:13:04.895] _slurm_rpc_submit_batch_job: JobId=47174 InitPrio=21968 usec=611
[2022-08-03T11:13:09.591] _slurm_rpc_submit_batch_job: JobId=47175 InitPrio=21968 usec=443
[2022-08-03T11:13:18.638] _slurm_rpc_submit_batch_job: JobId=47176 InitPrio=21968 usec=377
[2022-08-03T11:13:23.903] _slurm_rpc_submit_batch_job: JobId=47177 InitPrio=21968 usec=360
[2022-08-03T11:13:28.934] _slurm_rpc_submit_batch_job: JobId=47178 InitPrio=21968 usec=382
[2022-08-03T11:13:33.808] _slurm_rpc_submit_batch_job: JobId=47179 InitPrio=21968 usec=470
[2022-08-03T11:13:37.911] _slurm_rpc_submit_batch_job: JobId=47180 InitPrio=21968 usec=420
[2022-08-03T11:13:44.431] _slurm_rpc_submit_batch_job: JobId=47181 InitPrio=21968 usec=385
[2022-08-03T11:13:49.088] _slurm_rpc_submit_batch_job: JobId=47182 InitPrio=21968 usec=575
[2022-08-03T11:13:57.191] _slurm_rpc_submit_batch_job: JobId=47183 InitPrio=21968 usec=466
[2022-08-03T11:14:01.128] _slurm_rpc_submit_batch_job: JobId=47184 InitPrio=21968 usec=382
[2022-08-03T11:14:05.732] _slurm_rpc_submit_batch_job: JobId=47185 InitPrio=21968 usec=448
[2022-08-03T11:14:16.182] _slurm_rpc_submit_batch_job: JobId=47186 InitPrio=21968 usec=473
[2022-08-03T11:14:20.647] _slurm_rpc_submit_batch_job: JobId=47187 InitPrio=21968 usec=489
[2022-08-03T11:14:25.008] _slurm_rpc_submit_batch_job: JobId=47188 InitPrio=21968 usec=456
[2022-08-03T11:14:28.887] _slurm_rpc_submit_batch_job: JobId=47189 InitPrio=21968 usec=398
[2022-08-03T11:14:34.728] _slurm_rpc_submit_batch_job: JobId=47190 InitPrio=21968 usec=443
[2022-08-03T11:14:39.032] _slurm_rpc_submit_batch_job: JobId=47191 InitPrio=21968 usec=428
[2022-08-03T11:14:43.296] _slurm_rpc_submit_batch_job: JobId=47192 InitPrio=21968 usec=396
[2022-08-03T11:14:48.824] _slurm_rpc_submit_batch_job: JobId=47193 InitPrio=21968 usec=406
[2022-08-03T11:14:54.600] _slurm_rpc_submit_batch_job: JobId=47194 InitPrio=21968 usec=462
[2022-08-03T11:14:58.865] _slurm_rpc_submit_batch_job: JobId=47195 InitPrio=21968 usec=449
[2022-08-03T11:15:06.088] _slurm_rpc_submit_batch_job: JobId=47196 InitPrio=21968 usec=442
[2022-08-03T11:15:10.465] _slurm_rpc_submit_batch_job: JobId=47197 InitPrio=21968 usec=404
[2022-08-03T11:15:14.152] _slurm_rpc_submit_batch_job: JobId=47198 InitPrio=21968 usec=441
[2022-08-03T11:15:18.377] _slurm_rpc_submit_batch_job: JobId=47199 InitPrio=21968 usec=401
[2022-08-03T11:15:23.168] _slurm_rpc_submit_batch_job: JobId=47200 InitPrio=21968 usec=387
[2022-08-03T11:15:26.625] _slurm_rpc_submit_batch_job: JobId=47201 InitPrio=21968 usec=479
[2022-08-03T11:15:31.249] _slurm_rpc_submit_batch_job: JobId=47202 InitPrio=21968 usec=432
[2022-08-03T11:15:35.232] _slurm_rpc_submit_batch_job: JobId=47203 InitPrio=21968 usec=482
[2022-08-03T11:15:38.600] _slurm_rpc_submit_batch_job: JobId=47204 InitPrio=21968 usec=449
[2022-08-03T11:15:43.001] _slurm_rpc_submit_batch_job: JobId=47205 InitPrio=21968 usec=494
[2022-08-03T11:15:48.457] _slurm_rpc_submit_batch_job: JobId=47206 InitPrio=21968 usec=422
[2022-08-03T11:15:53.201] _slurm_rpc_submit_batch_job: JobId=47207 InitPrio=21968 usec=417
[2022-08-03T11:15:57.785] _slurm_rpc_submit_batch_job: JobId=47208 InitPrio=21968 usec=451
[2022-08-03T11:16:01.822] _slurm_rpc_submit_batch_job: JobId=47209 InitPrio=21968 usec=496
[2022-08-03T11:16:48.756] _job_complete: JobId=47117 WEXITSTATUS 0
[2022-08-03T11:16:48.756] _job_complete: JobId=47117 done
[2022-08-03T11:17:32.308] _slurm_rpc_submit_batch_job: JobId=47210 InitPrio=24863 usec=457
[2022-08-03T11:18:02.986] _update_job: updating accounting
[2022-08-03T11:18:02.986] _slurm_rpc_update_job: complete JobId=47210 uid=548200003 usec=1023
[2022-08-03T11:20:31.631] _slurm_rpc_kill_job: REQUEST_KILL_JOB JobId=47210 uid 548200003
[2022-08-03T11:20:48.267] _slurm_rpc_submit_batch_job: JobId=47211 InitPrio=24863 usec=444
[2022-08-03T11:20:48.713] sched: Allocate JobId=47211 NodeList=cpu[09-10] #CPUs=16 Partition=cpu-opteron
[2022-08-03T11:20:53.098] _job_complete: JobId=47211 WEXITSTATUS 0
[2022-08-03T11:20:53.098] _job_complete: JobId=47211 done
[2022-08-03T11:33:20.116] _slurm_rpc_submit_batch_job: JobId=47212 InitPrio=24863 usec=480
[2022-08-03T11:33:20.141] sched: Allocate JobId=47212 NodeList=cpu[09-10] #CPUs=16 Partition=cpu-opteron
[2022-08-03T11:33:23.810] _job_complete: JobId=47212 WEXITSTATUS 0
[2022-08-03T11:33:23.810] _job_complete: JobId=47212 done
[2022-08-03T11:34:13.588] _slurm_rpc_submit_batch_job: JobId=47213 InitPrio=24863 usec=447
[2022-08-03T11:34:14.212] sched: Allocate JobId=47213 NodeList=cpu[09-10] #CPUs=16 Partition=cpu-opteron
[2022-08-03T11:34:14.747] _job_complete: JobId=47213 WEXITSTATUS 255
[2022-08-03T11:34:14.747] _job_complete: JobId=47213 done
[2022-08-03T11:34:57.102] _job_complete: JobId=47118 WEXITSTATUS 0
[2022-08-03T11:34:57.102] _job_complete: JobId=47118 done
[2022-08-03T11:38:19.615] _job_complete: JobId=47167 WEXITSTATUS 0
[2022-08-03T11:38:19.615] _job_complete: JobId=47167 done
[2022-08-03T11:38:39.701] sched/backfill: _start_job: Started JobId=47170 in cpu-epyc on cpu15
[2022-08-03T11:39:50.644] _job_complete: JobId=47169 WEXITSTATUS 0
[2022-08-03T11:39:50.644] _job_complete: JobId=47169 done
[2022-08-03T11:40:39.708] sched/backfill: _start_job: Started JobId=47171 in cpu-epyc on cpu13
[2022-08-03T11:44:39.226] _job_complete: JobId=47168 WEXITSTATUS 0
[2022-08-03T11:44:39.226] _job_complete: JobId=47168 done
[2022-08-03T11:44:39.722] sched/backfill: _start_job: Started JobId=47172 in cpu-epyc on cpu12
[2022-08-03T11:53:04.531] _slurm_rpc_submit_batch_job: JobId=47214 InitPrio=24863 usec=626
[2022-08-03T11:53:05.431] sched: Allocate JobId=47214 NodeList=cpu[09-10] #CPUs=16 Partition=cpu-opteron
[2022-08-03T11:53:06.361] _job_complete: JobId=47214 WEXITSTATUS 255
[2022-08-03T11:53:06.361] _job_complete: JobId=47214 done
[2022-08-03T11:54:45.200] _slurm_rpc_submit_batch_job: JobId=47215 InitPrio=24726 usec=449
[2022-08-03T11:54:45.572] sched: Allocate JobId=47215 NodeList=cpu[03,07] #CPUs=32 Partition=cpu-opteron
[2022-08-03T11:54:49.943] _job_complete: JobId=47215 WEXITSTATUS 0
[2022-08-03T11:54:49.943] _job_complete: JobId=47215 done
[2022-08-03T12:05:53.215] _job_complete: JobId=47170 WEXITSTATUS 0
[2022-08-03T12:05:53.215] _job_complete: JobId=47170 done
[2022-08-03T12:06:39.800] sched/backfill: _start_job: Started JobId=47173 in cpu-epyc on cpu15
[2022-08-03T12:09:11.406] _slurm_rpc_submit_batch_job: JobId=47216 InitPrio=24726 usec=429
[2022-08-03T12:09:12.074] sched: Allocate JobId=47216 NodeList=cpu[03,07] #CPUs=32 Partition=cpu-opteron
[2022-08-03T12:09:15.560] _job_complete: JobId=47216 WEXITSTATUS 0
[2022-08-03T12:09:15.560] _job_complete: JobId=47216 done
[2022-08-03T12:25:51.319] _job_complete: JobId=47171 WEXITSTATUS 0
[2022-08-03T12:25:51.319] _job_complete: JobId=47171 done
[2022-08-03T12:26:08.036] _job_complete: JobId=47172 WEXITSTATUS 0
[2022-08-03T12:26:08.036] _job_complete: JobId=47172 done
[2022-08-03T12:26:39.868] sched/backfill: _start_job: Started JobId=47174 in cpu-epyc on cpu12
[2022-08-03T12:26:39.869] sched/backfill: _start_job: Started JobId=47175 in cpu-epyc on cpu13
[2022-08-03T12:35:25.749] _job_complete: JobId=47173 WEXITSTATUS 0
[2022-08-03T12:35:25.749] _job_complete: JobId=47173 done
[2022-08-03T12:35:39.897] sched/backfill: _start_job: Started JobId=47176 in cpu-epyc on cpu15
[2022-08-03T12:54:55.856] _job_complete: JobId=47174 WEXITSTATUS 0
[2022-08-03T12:54:55.856] _job_complete: JobId=47174 done
[2022-08-03T12:55:39.962] sched/backfill: _start_job: Started JobId=47177 in cpu-epyc on cpu12
[2022-08-03T13:01:43.464] _job_complete: JobId=47175 WEXITSTATUS 0
[2022-08-03T13:01:43.464] _job_complete: JobId=47175 done
[2022-08-03T13:02:39.986] sched/backfill: _start_job: Started JobId=47178 in cpu-epyc on cpu13
[2022-08-03T13:08:00.243] _job_complete: JobId=47176 WEXITSTATUS 0
[2022-08-03T13:08:00.243] _job_complete: JobId=47176 done
[2022-08-03T13:08:12.680] _slurm_rpc_submit_batch_job: JobId=47217 InitPrio=24931 usec=443
[2022-08-03T13:08:13.555] sched: Allocate JobId=47217 NodeList=cpu[09-10] #CPUs=8 Partition=cpu-opteron
[2022-08-03T13:08:17.919] _job_complete: JobId=47217 WEXITSTATUS 0
[2022-08-03T13:08:17.919] _job_complete: JobId=47217 done
[2022-08-03T13:08:32.749] _slurm_rpc_submit_batch_job: JobId=47218 InitPrio=24931 usec=425
[2022-08-03T13:08:33.580] sched: Allocate JobId=47218 NodeList=cpu[09-10] #CPUs=8 Partition=cpu-opteron
[2022-08-03T13:08:36.844] _job_complete: JobId=47218 WEXITSTATUS 0
[2022-08-03T13:08:36.844] _job_complete: JobId=47218 done
[2022-08-03T13:08:40.008] sched/backfill: _start_job: Started JobId=47179 in cpu-epyc on cpu15
[2022-08-03T13:23:11.829] _slurm_rpc_submit_batch_job: JobId=47219 InitPrio=26044 usec=473
[2022-08-03T13:23:12.261] sched: Allocate JobId=47219 NodeList=cpu03 #CPUs=1 Partition=cpu-opteron
[2022-08-03T13:23:19.860] _slurm_rpc_submit_batch_job: JobId=47220 InitPrio=26044 usec=573
[2022-08-03T13:23:20.256] sched: Allocate JobId=47220 NodeList=cpu03 #CPUs=1 Partition=cpu-opteron
[2022-08-03T13:23:26.381] _slurm_rpc_submit_batch_job: JobId=47221 InitPrio=26044 usec=451
[2022-08-03T13:23:27.267] sched: Allocate JobId=47221 NodeList=cpu03 #CPUs=1 Partition=cpu-opteron
[2022-08-03T13:23:33.836] _slurm_rpc_submit_batch_job: JobId=47222 InitPrio=26044 usec=387
[2022-08-03T13:23:34.276] sched: Allocate JobId=47222 NodeList=cpu03 #CPUs=1 Partition=cpu-opteron
[2022-08-03T13:23:45.348] _slurm_rpc_submit_batch_job: JobId=47223 InitPrio=26044 usec=475
[2022-08-03T13:23:46.292] sched: Allocate JobId=47223 NodeList=cpu03 #CPUs=1 Partition=cpu-opteron
[2022-08-03T13:23:52.165] _slurm_rpc_submit_batch_job: JobId=47224 InitPrio=26044 usec=445
[2022-08-03T13:23:52.300] sched: Allocate JobId=47224 NodeList=cpu03 #CPUs=1 Partition=cpu-opteron
[2022-08-03T13:23:58.172] _slurm_rpc_submit_batch_job: JobId=47225 InitPrio=26044 usec=418
[2022-08-03T13:23:58.308] sched: Allocate JobId=47225 NodeList=cpu03 #CPUs=1 Partition=cpu-opteron
[2022-08-03T13:24:06.141] _slurm_rpc_submit_batch_job: JobId=47226 InitPrio=26044 usec=443
[2022-08-03T13:24:06.319] sched: Allocate JobId=47226 NodeList=cpu03 #CPUs=1 Partition=cpu-opteron
[2022-08-03T13:24:12.381] _slurm_rpc_submit_batch_job: JobId=47227 InitPrio=26044 usec=456
[2022-08-03T13:24:13.329] sched: Allocate JobId=47227 NodeList=cpu03 #CPUs=1 Partition=cpu-opteron
[2022-08-03T13:24:22.734] _slurm_rpc_submit_batch_job: JobId=47228 InitPrio=26044 usec=428
[2022-08-03T13:24:23.340] sched: Allocate JobId=47228 NodeList=cpu03 #CPUs=1 Partition=cpu-opteron
[2022-08-03T13:24:32.623] _slurm_rpc_submit_batch_job: JobId=47229 InitPrio=26044 usec=429
[2022-08-03T13:24:33.351] sched: Allocate JobId=47229 NodeList=cpu03 #CPUs=1 Partition=cpu-opteron
[2022-08-03T13:24:37.307] _job_complete: JobId=47229 WEXITSTATUS 0
[2022-08-03T13:24:37.307] _job_complete: JobId=47229 done
[2022-08-03T13:28:22.963] _job_complete: JobId=47177 WEXITSTATUS 0
[2022-08-03T13:28:22.963] _job_complete: JobId=47177 done
[2022-08-03T13:28:40.073] sched/backfill: _start_job: Started JobId=47180 in cpu-epyc on cpu12
[2022-08-03T13:28:53.698] _slurm_rpc_kill_job: REQUEST_KILL_JOB JobId=47228 uid 548300543
[2022-08-03T13:28:55.807] _slurm_rpc_kill_job: REQUEST_KILL_JOB JobId=47228 uid 548300543
[2022-08-03T13:28:57.917] _slurm_rpc_kill_job: REQUEST_KILL_JOB JobId=47227 uid 548300543
[2022-08-03T13:29:00.028] _slurm_rpc_kill_job: REQUEST_KILL_JOB JobId=47226 uid 548300543
[2022-08-03T13:29:02.137] _slurm_rpc_kill_job: REQUEST_KILL_JOB JobId=47224 uid 548300543
[2022-08-03T13:29:04.246] _slurm_rpc_kill_job: REQUEST_KILL_JOB JobId=47222 uid 548300543
[2022-08-03T13:29:06.355] _slurm_rpc_kill_job: REQUEST_KILL_JOB JobId=47220 uid 548300543
[2022-08-03T13:29:08.463] _slurm_rpc_kill_job: REQUEST_KILL_JOB JobId=47221 uid 548300543
[2022-08-03T13:29:10.572] _slurm_rpc_kill_job: REQUEST_KILL_JOB JobId=47219 uid 548300543
[2022-08-03T13:29:12.681] _slurm_rpc_kill_job: REQUEST_KILL_JOB JobId=46840 uid 548300543
[2022-08-03T13:29:28.502] _slurm_rpc_kill_job: REQUEST_KILL_JOB JobId=47225 uid 548300543
[2022-08-03T13:29:29.015] sched: Allocate JobId=46799 NodeList=gpu05 #CPUs=16 Partition=gpu-v100s
[2022-08-03T13:29:30.613] _slurm_rpc_kill_job: REQUEST_KILL_JOB JobId=47223 uid 548300543
[2022-08-03T13:29:53.942] _slurm_rpc_submit_batch_job: JobId=47230 InitPrio=25984 usec=407
[2022-08-03T13:30:30.789] _job_complete: JobId=46799 WEXITSTATUS 1
[2022-08-03T13:30:30.789] _job_complete: JobId=46799 done
[2022-08-03T13:30:33.708] sched: Allocate JobId=46801 NodeList=gpu05 #CPUs=16 Partition=gpu-v100s
[2022-08-03T13:32:38.001] _job_complete: JobId=47178 WEXITSTATUS 0
[2022-08-03T13:32:38.001] _job_complete: JobId=47178 done
[2022-08-03T13:32:40.086] sched/backfill: _start_job: Started JobId=47181 in cpu-epyc on cpu13
[2022-08-03T13:36:49.543] _slurm_rpc_submit_batch_job: JobId=47231 InitPrio=25457 usec=497
[2022-08-03T13:36:49.607] sched: Allocate JobId=47231 NodeList=cpu03 #CPUs=8 Partition=cpu-opteron
[2022-08-03T13:36:52.707] _job_complete: JobId=47231 WEXITSTATUS 0
[2022-08-03T13:36:52.707] _job_complete: JobId=47231 done
[2022-08-03T13:37:35.797] _slurm_rpc_submit_batch_job: JobId=47232 InitPrio=25457 usec=415
[2022-08-03T13:37:36.743] sched: Allocate JobId=47232 NodeList=cpu03 #CPUs=8 Partition=cpu-opteron
[2022-08-03T13:37:39.637] _job_complete: JobId=47232 WEXITSTATUS 0
[2022-08-03T13:37:39.637] _job_complete: JobId=47232 done
[2022-08-03T13:39:51.143] _job_complete: JobId=47179 WEXITSTATUS 0
[2022-08-03T13:39:51.143] _job_complete: JobId=47179 done
[2022-08-03T13:40:40.114] sched/backfill: _start_job: Started JobId=47182 in cpu-epyc on cpu15
[2022-08-03T13:57:06.818] _slurm_rpc_submit_batch_job: JobId=47233 InitPrio=25457 usec=528
[2022-08-03T13:57:07.821] sched: Allocate JobId=47233 NodeList=cpu03 #CPUs=8 Partition=cpu-opteron
[2022-08-03T13:57:10.807] _job_complete: JobId=47233 WEXITSTATUS 0
[2022-08-03T13:57:10.807] _job_complete: JobId=47233 done
[2022-08-03T14:01:45.208] _job_complete: JobId=47181 WEXITSTATUS 0
[2022-08-03T14:01:45.208] _job_complete: JobId=47181 done
[2022-08-03T14:02:40.182] sched/backfill: _start_job: Started JobId=47183 in cpu-epyc on cpu13
[2022-08-03T14:14:17.956] _job_complete: JobId=47180 WEXITSTATUS 0
[2022-08-03T14:14:17.956] _job_complete: JobId=47180 done
[2022-08-03T14:14:27.554] _job_complete: JobId=47182 WEXITSTATUS 0
[2022-08-03T14:14:27.554] _job_complete: JobId=47182 done
[2022-08-03T14:14:40.220] sched/backfill: _start_job: Started JobId=47184 in cpu-epyc on cpu12
[2022-08-03T14:14:40.221] sched/backfill: _start_job: Started JobId=47185 in cpu-epyc on cpu15
[2022-08-03T14:15:52.778] _slurm_rpc_submit_batch_job: JobId=47234 InitPrio=25457 usec=427
[2022-08-03T14:15:52.852] sched: Allocate JobId=47234 NodeList=cpu03 #CPUs=8 Partition=cpu-opteron
[2022-08-03T14:15:55.186] _job_complete: JobId=47234 WEXITSTATUS 0
[2022-08-03T14:15:55.186] _job_complete: JobId=47234 done
[2022-08-03T14:17:20.702] _slurm_rpc_submit_batch_job: JobId=47235 InitPrio=25457 usec=509
[2022-08-03T14:17:20.976] sched: Allocate JobId=47235 NodeList=cpu03 #CPUs=8 Partition=cpu-opteron
[2022-08-03T14:17:23.226] _job_complete: JobId=47235 WEXITSTATUS 0
[2022-08-03T14:17:23.226] _job_complete: JobId=47235 done
[2022-08-03T14:20:34.351] _job_complete: JobId=47121 WEXITSTATUS 0
[2022-08-03T14:20:34.351] _job_complete: JobId=47121 done
[2022-08-03T14:20:49.276] _slurm_rpc_submit_batch_job: JobId=47236 InitPrio=25457 usec=392
[2022-08-03T14:20:49.367] sched: Allocate JobId=47236 NodeList=cpu03 #CPUs=8 Partition=cpu-opteron
[2022-08-03T14:20:51.690] _job_complete: JobId=47236 WEXITSTATUS 0
[2022-08-03T14:20:51.691] _job_complete: JobId=47236 done
[2022-08-03T14:25:05.038] _slurm_rpc_submit_batch_job: JobId=47237 InitPrio=25984 usec=617
[2022-08-03T14:25:06.086] sched: Allocate JobId=47237 NodeList=cpu03 #CPUs=8 Partition=cpu-opteron
[2022-08-03T14:26:08.061] _slurm_rpc_kill_job: REQUEST_KILL_JOB JobId=47237 uid 548300543
[2022-08-03T14:31:33.382] _job_complete: JobId=47183 WEXITSTATUS 0
[2022-08-03T14:31:33.382] _job_complete: JobId=47183 done
[2022-08-03T14:31:40.271] sched/backfill: _start_job: Started JobId=47186 in cpu-epyc on cpu13
[2022-08-03T14:32:00.439] _slurm_rpc_submit_batch_job: JobId=47238 InitPrio=25984 usec=498
[2022-08-03T14:32:00.768] sched: Allocate JobId=47238 NodeList=cpu03 #CPUs=8 Partition=cpu-opteron
[2022-08-03T14:32:04.196] _job_complete: JobId=47238 WEXITSTATUS 0
[2022-08-03T14:32:04.196] _job_complete: JobId=47238 done
[2022-08-03T14:34:12.822] _slurm_rpc_submit_batch_job: JobId=47239 InitPrio=25984 usec=445
[2022-08-03T14:34:13.081] sched: Allocate JobId=47239 NodeList=cpu03 #CPUs=8 Partition=cpu-opteron
[2022-08-03T14:37:25.129] _slurm_rpc_submit_batch_job: JobId=47240 InitPrio=68878 usec=451
[2022-08-03T14:37:25.359] sched: Allocate JobId=47240 NodeList=cpu03 #CPUs=8 Partition=cpu-opteron
[2022-08-03T14:37:28.054] _job_complete: JobId=47240 WEXITSTATUS 0
[2022-08-03T14:37:28.054] _job_complete: JobId=47240 done
[2022-08-03T14:38:22.918] _slurm_rpc_submit_batch_job: JobId=47241 InitPrio=68878 usec=491
[2022-08-03T14:38:23.547] sched: Allocate JobId=47241 NodeList=cpu03 #CPUs=8 Partition=cpu-opteron
[2022-08-03T14:38:25.911] _job_complete: JobId=47241 WEXITSTATUS 0
[2022-08-03T14:38:25.911] _job_complete: JobId=47241 done
[2022-08-03T14:41:15.079] _job_complete: JobId=47185 WEXITSTATUS 0
[2022-08-03T14:41:15.079] _job_complete: JobId=47185 done
[2022-08-03T14:41:35.928] _slurm_rpc_submit_batch_job: JobId=47242 InitPrio=68878 usec=495
[2022-08-03T14:41:36.816] sched: Allocate JobId=47242 NodeList=cpu03 #CPUs=8 Partition=cpu-opteron
[2022-08-03T14:41:39.386] _job_complete: JobId=47242 WEXITSTATUS 0
[2022-08-03T14:41:39.386] _job_complete: JobId=47242 done
[2022-08-03T14:41:40.301] sched/backfill: _start_job: Started JobId=47187 in cpu-epyc on cpu15
[2022-08-03T14:41:53.041] _slurm_rpc_submit_batch_job: JobId=47243 InitPrio=68615 usec=511
[2022-08-03T14:41:53.853] sched: Allocate JobId=47243 NodeList=cpu03 #CPUs=8 Partition=cpu-opteron
[2022-08-03T14:41:56.466] _job_complete: JobId=47243 WEXITSTATUS 0
[2022-08-03T14:41:56.466] _job_complete: JobId=47243 done
[2022-08-03T14:45:46.006] _slurm_rpc_submit_batch_job: JobId=47244 InitPrio=22231 usec=516
[2022-08-03T14:45:46.310] sched: Allocate JobId=47244 NodeList=cpu03 #CPUs=16 Partition=cpu-opteron
[2022-08-03T14:45:49.179] _slurm_rpc_submit_batch_job: JobId=47245 InitPrio=22231 usec=460
[2022-08-03T14:45:49.301] sched: Allocate JobId=47245 NodeList=cpu07 #CPUs=16 Partition=cpu-opteron
[2022-08-03T14:46:47.115] _slurm_rpc_kill_job: REQUEST_KILL_JOB JobId=47239 uid 548300543
[2022-08-03T14:55:10.476] _slurm_rpc_submit_batch_job: JobId=47246 InitPrio=21373 usec=477
[2022-08-03T14:55:40.356] sched/backfill: _start_job: Started JobId=47246 in cpu-opteron on cpu09
[2022-08-03T14:55:59.146] _slurm_rpc_submit_batch_job: JobId=47247 InitPrio=21373 usec=782
[2022-08-03T14:56:40.360] sched/backfill: _start_job: Started JobId=47247 in cpu-opteron on cpu11
[2022-08-03T14:57:15.290] _slurm_rpc_submit_batch_job: JobId=47248 InitPrio=25457 usec=555
[2022-08-03T14:57:15.521] sched: Allocate JobId=47248 NodeList=cpu03 #CPUs=8 Partition=cpu-opteron
[2022-08-03T14:58:10.408] _slurm_rpc_submit_batch_job: JobId=47249 InitPrio=22231 usec=483
[2022-08-03T14:59:34.985] _slurm_rpc_kill_job: REQUEST_KILL_JOB JobId=47248 uid 548200003
[2022-08-03T14:59:37.085] sched: Allocate JobId=47249 NodeList=cpu03 #CPUs=16 Partition=cpu-opteron
[2022-08-03T14:59:47.248] _slurm_rpc_submit_batch_job: JobId=47250 InitPrio=25457 usec=416
[2022-08-03T14:59:47.847] sched: Allocate JobId=47250 NodeList=cpu07 #CPUs=8 Partition=cpu-opteron
[2022-08-03T15:01:32.295] _job_complete: JobId=47184 WEXITSTATUS 0
[2022-08-03T15:01:32.295] _job_complete: JobId=47184 done
[2022-08-03T15:01:40.377] sched/backfill: _start_job: Started JobId=47188 in cpu-epyc on cpu12
[2022-08-03T15:05:22.942] _job_complete: JobId=47186 WEXITSTATUS 0
[2022-08-03T15:05:22.942] _job_complete: JobId=47186 done
[2022-08-03T15:05:29.934] _job_complete: JobId=47187 WEXITSTATUS 0
[2022-08-03T15:05:29.934] _job_complete: JobId=47187 done
[2022-08-03T15:05:40.390] sched/backfill: _start_job: Started JobId=47189 in cpu-epyc on cpu13
[2022-08-03T15:05:40.390] sched/backfill: _start_job: Started JobId=47190 in cpu-epyc on cpu15
[2022-08-03T15:08:47.302] _slurm_rpc_submit_batch_job: JobId=47251 InitPrio=25984 usec=643
[2022-08-03T15:08:47.865] sched: Allocate JobId=47251 NodeList=cpu09 #CPUs=8 Partition=cpu-opteron
[2022-08-03T15:13:59.565] _slurm_rpc_kill_job: REQUEST_KILL_JOB JobId=47250 uid 0
[2022-08-03T15:14:13.023] _slurm_rpc_submit_batch_job: JobId=47252 InitPrio=22231 usec=416
[2022-08-03T15:15:23.425] _job_complete: JobId=47245 WEXITSTATUS 0
[2022-08-03T15:15:23.425] _job_complete: JobId=47245 done
[2022-08-03T15:15:24.028] sched: Allocate JobId=47252 NodeList=cpu07 #CPUs=16 Partition=cpu-opteron
[2022-08-03T15:16:04.382] _job_complete: JobId=47244 WEXITSTATUS 0
[2022-08-03T15:16:04.382] _job_complete: JobId=47244 done
[2022-08-03T15:16:13.285] _job_complete: JobId=47249 WEXITSTATUS 0
[2022-08-03T15:16:13.285] _job_complete: JobId=47249 done
[2022-08-03T15:20:38.391] _job_complete: JobId=47251 WEXITSTATUS 0
[2022-08-03T15:20:38.392] _job_complete: JobId=47251 done
[2022-08-03T15:21:05.645] _job_complete: JobId=47252 WEXITSTATUS 0
[2022-08-03T15:21:05.645] _job_complete: JobId=47252 done
[2022-08-03T15:21:26.576] _slurm_rpc_submit_batch_job: JobId=47253 InitPrio=24863 usec=8147
[2022-08-03T15:21:27.150] sched: Allocate JobId=47253 NodeList=cpu[09-10] #CPUs=16 Partition=cpu-opteron
[2022-08-03T15:22:04.484] _slurm_rpc_submit_batch_job: JobId=47254 InitPrio=22231 usec=456
[2022-08-03T15:22:06.200] sched: Allocate JobId=47254 NodeList=cpu07 #CPUs=16 Partition=cpu-opteron
[2022-08-03T15:22:19.624] _job_complete: JobId=47254 OOM failure
[2022-08-03T15:22:19.624] _job_complete: JobId=47254 done
[2022-08-03T15:23:48.991] _slurm_rpc_kill_job: REQUEST_KILL_JOB JobId=47253 uid 548200003
[2022-08-03T15:25:19.022] _slurm_rpc_submit_batch_job: JobId=47255 InitPrio=24863 usec=506
[2022-08-03T15:25:19.589] sched: Allocate JobId=47255 NodeList=cpu[09-10] #CPUs=16 Partition=cpu-opteron
[2022-08-03T15:25:24.979] _job_complete: JobId=47255 WEXITSTATUS 200
[2022-08-03T15:25:24.979] _job_complete: JobId=47255 done
[2022-08-03T15:27:24.260] _slurm_rpc_submit_batch_job: JobId=47256 InitPrio=24863 usec=505
[2022-08-03T15:27:24.761] sched: Allocate JobId=47256 NodeList=cpu[09-10] #CPUs=16 Partition=cpu-opteron
[2022-08-03T15:28:52.950] _slurm_rpc_submit_batch_job: JobId=47257 InitPrio=22231 usec=396
[2022-08-03T15:28:52.999] sched: Allocate JobId=47257 NodeList=cpu07 #CPUs=16 Partition=cpu-opteron
[2022-08-03T15:29:48.957] _slurm_rpc_kill_job: REQUEST_KILL_JOB JobId=47256 uid 548200003
[2022-08-03T15:30:57.965] _job_complete: JobId=47257 WEXITSTATUS 0
[2022-08-03T15:30:57.966] _job_complete: JobId=47257 done
[2022-08-03T15:30:59.684] _slurm_rpc_submit_batch_job: JobId=47258 InitPrio=24863 usec=438
[2022-08-03T15:31:00.174] sched: Allocate JobId=47258 NodeList=cpu[09-10] #CPUs=16 Partition=cpu-opteron
[2022-08-03T15:31:04.647] _job_complete: JobId=47258 WEXITSTATUS 137
[2022-08-03T15:31:04.647] _job_complete: JobId=47258 done
[2022-08-03T15:32:11.610] _job_complete: JobId=47120 WEXITSTATUS 0
[2022-08-03T15:32:11.610] _job_complete: JobId=47120 done
[2022-08-03T15:32:39.850] _slurm_rpc_submit_batch_job: JobId=47259 InitPrio=24863 usec=491
[2022-08-03T15:32:40.426] sched: Allocate JobId=47259 NodeList=cpu[09-10] #CPUs=16 Partition=cpu-opteron
[2022-08-03T15:32:44.625] _job_complete: JobId=47259 WEXITSTATUS 137
[2022-08-03T15:32:44.626] _job_complete: JobId=47259 done
[2022-08-03T15:32:46.916] _job_complete: JobId=47188 WEXITSTATUS 0
[2022-08-03T15:32:46.916] _job_complete: JobId=47188 done
[2022-08-03T15:33:40.468] sched/backfill: _start_job: Started JobId=47191 in cpu-epyc on cpu12
[2022-08-03T15:34:47.983] _slurm_rpc_submit_batch_job: JobId=47260 InitPrio=24863 usec=524
[2022-08-03T15:34:48.637] sched: Allocate JobId=47260 NodeList=cpu[09-10] #CPUs=16 Partition=cpu-opteron
[2022-08-03T15:34:49.298] _job_complete: JobId=47260 WEXITSTATUS 127
[2022-08-03T15:34:49.298] _job_complete: JobId=47260 done
[2022-08-03T15:35:06.561] _slurm_rpc_submit_batch_job: JobId=47261 InitPrio=24863 usec=465
[2022-08-03T15:35:06.663] sched: Allocate JobId=47261 NodeList=cpu[09-10] #CPUs=16 Partition=cpu-opteron
[2022-08-03T15:35:12.148] _job_complete: JobId=47261 WEXITSTATUS 200
[2022-08-03T15:35:12.148] _job_complete: JobId=47261 done
[2022-08-03T15:35:16.254] _job_complete: JobId=47190 WEXITSTATUS 0
[2022-08-03T15:35:16.254] _job_complete: JobId=47190 done
[2022-08-03T15:35:40.474] sched/backfill: _start_job: Started JobId=47192 in cpu-epyc on cpu15
[2022-08-03T15:39:05.617] _slurm_rpc_submit_batch_job: JobId=47262 InitPrio=25457 usec=578
[2022-08-03T15:39:06.090] sched: Allocate JobId=47262 NodeList=cpu03 #CPUs=8 Partition=cpu-opteron
[2022-08-03T15:39:06.604] _job_complete: JobId=47262 WEXITSTATUS 127
[2022-08-03T15:39:06.604] _job_complete: JobId=47262 done
[2022-08-03T15:39:21.871] _slurm_rpc_submit_batch_job: JobId=47263 InitPrio=25457 usec=537
[2022-08-03T15:39:22.113] sched: Allocate JobId=47263 NodeList=cpu03 #CPUs=8 Partition=cpu-opteron
[2022-08-03T15:39:28.924] _job_complete: JobId=47263 WEXITSTATUS 200
[2022-08-03T15:39:28.925] _job_complete: JobId=47263 done
[2022-08-03T15:42:16.682] _slurm_rpc_submit_batch_job: JobId=47264 InitPrio=25492 usec=477
[2022-08-03T15:42:17.353] sched: Allocate JobId=47264 NodeList=cpu03 #CPUs=4 Partition=cpu-opteron
[2022-08-03T15:42:23.555] _job_complete: JobId=47264 WEXITSTATUS 0
[2022-08-03T15:42:23.555] _job_complete: JobId=47264 done
[2022-08-03T15:42:24.428] _slurm_rpc_submit_batch_job: JobId=47265 InitPrio=22231 usec=499
[2022-08-03T15:42:24.758] _slurm_rpc_submit_batch_job: JobId=47266 InitPrio=25984 usec=458
[2022-08-03T15:42:25.367] sched: Allocate JobId=47266 NodeList=cpu03 #CPUs=8 Partition=cpu-opteron
[2022-08-03T15:42:25.371] sched: Allocate JobId=47265 NodeList=cpu03 #CPUs=16 Partition=cpu-opteron
[2022-08-03T15:42:27.069] _slurm_rpc_submit_batch_job: JobId=47267 InitPrio=22231 usec=454
[2022-08-03T15:42:28.369] sched: Allocate JobId=47267 NodeList=cpu07 #CPUs=16 Partition=cpu-opteron
[2022-08-03T15:42:30.277] _job_complete: JobId=47266 WEXITSTATUS 0
[2022-08-03T15:42:30.277] _job_complete: JobId=47266 done
[2022-08-03T15:43:40.579] _slurm_rpc_submit_batch_job: JobId=47268 InitPrio=25492 usec=445
[2022-08-03T15:43:41.579] sched: Allocate JobId=47268 NodeList=cpu03 #CPUs=4 Partition=cpu-opteron
[2022-08-03T15:43:46.260] _job_complete: JobId=47268 WEXITSTATUS 0
[2022-08-03T15:43:46.260] _job_complete: JobId=47268 done
[2022-08-03T15:44:55.724] _slurm_rpc_submit_batch_job: JobId=47269 InitPrio=24931 usec=405
[2022-08-03T15:44:56.682] sched: Allocate JobId=47269 NodeList=cpu[09-10] #CPUs=8 Partition=cpu-opteron
[2022-08-03T15:44:59.955] error: _find_node_record: lookup failure for node "cpu09.dicc.um.edu.my"
[2022-08-03T15:44:59.955] error: node_name2bitmap: invalid node specified: "cpu09.dicc.um.edu.my"
[2022-08-03T15:44:59.955] error: _find_node_record: lookup failure for node "cpu09.dicc.um.edu.my"
[2022-08-03T15:44:59.955] error: node_name2bitmap: invalid node specified: "cpu09.dicc.um.edu.my"
[2022-08-03T15:46:12.879] _slurm_rpc_kill_job: REQUEST_KILL_JOB JobId=47269 uid 548200003
[2022-08-03T15:46:31.075] _slurm_rpc_submit_batch_job: JobId=47270 InitPrio=24931 usec=557
[2022-08-03T15:46:31.813] sched: Allocate JobId=47270 NodeList=cpu[09-10] #CPUs=8 Partition=cpu-opteron
[2022-08-03T15:46:37.573] _job_complete: JobId=47270 WEXITSTATUS 0
[2022-08-03T15:46:37.573] _job_complete: JobId=47270 done
[2022-08-03T15:46:40.861] _slurm_rpc_submit_batch_job: JobId=47271 InitPrio=25984 usec=403
[2022-08-03T15:46:41.826] sched: Allocate JobId=47271 NodeList=cpu03 #CPUs=8 Partition=cpu-opteron
[2022-08-03T15:46:45.820] _job_complete: JobId=47271 WEXITSTATUS 0
[2022-08-03T15:46:45.820] _job_complete: JobId=47271 done
[2022-08-03T15:47:33.462] _slurm_rpc_submit_batch_job: JobId=47272 InitPrio=22494 usec=469
[2022-08-03T15:47:33.918] sched: Allocate JobId=47272 NodeList=cpu03 #CPUs=16 Partition=cpu-opteron
[2022-08-03T15:49:15.073] _slurm_rpc_submit_batch_job: JobId=47273 InitPrio=24863 usec=441
[2022-08-03T15:49:15.131] sched: Allocate JobId=47273 NodeList=cpu[09-10] #CPUs=16 Partition=cpu-opteron
[2022-08-03T15:49:51.158] _slurm_rpc_kill_job: REQUEST_KILL_JOB JobId=47273 uid 548200003
[2022-08-03T15:50:01.235] _slurm_rpc_submit_batch_job: JobId=47274 InitPrio=24863 usec=421
[2022-08-03T15:50:02.194] sched: Allocate JobId=47274 NodeList=cpu[09-10] #CPUs=16 Partition=cpu-opteron
[2022-08-03T15:50:56.385] _slurm_rpc_submit_batch_job: JobId=47275 InitPrio=25984 usec=521
[2022-08-03T15:50:57.270] sched: Allocate JobId=47275 NodeList=cpu07 #CPUs=8 Partition=cpu-opteron
[2022-08-03T15:51:01.494] _job_complete: JobId=47275 WEXITSTATUS 0
[2022-08-03T15:51:01.494] _job_complete: JobId=47275 done
[2022-08-03T15:51:07.365] _slurm_rpc_kill_job: REQUEST_KILL_JOB JobId=47274 uid 548200003
[2022-08-03T15:51:20.074] _slurm_rpc_submit_batch_job: JobId=47276 InitPrio=22231 usec=456
[2022-08-03T15:51:20.300] sched: Allocate JobId=47276 NodeList=cpu10 #CPUs=16 Partition=cpu-opteron
[2022-08-03T15:51:22.594] _slurm_rpc_submit_batch_job: JobId=47277 InitPrio=22231 usec=527
[2022-08-03T15:52:01.297] _slurm_rpc_submit_batch_job: JobId=47278 InitPrio=25984 usec=462
[2022-08-03T15:52:01.360] sched: Allocate JobId=47278 NodeList=cpu07 #CPUs=8 Partition=cpu-opteron
[2022-08-03T15:52:05.922] _job_complete: JobId=47278 WEXITSTATUS 0
[2022-08-03T15:52:05.922] _job_complete: JobId=47278 done
[2022-08-03T15:52:57.322] _slurm_rpc_submit_batch_job: JobId=47279 InitPrio=25984 usec=564
[2022-08-03T15:52:57.586] sched: Allocate JobId=47279 NodeList=cpu07 #CPUs=8 Partition=cpu-opteron
[2022-08-03T15:53:02.121] _job_complete: JobId=47279 WEXITSTATUS 0
[2022-08-03T15:53:02.122] _job_complete: JobId=47279 done
[2022-08-03T15:53:16.160] _slurm_rpc_submit_batch_job: JobId=47280 InitPrio=24863 usec=430
[2022-08-03T15:53:16.604] sched: Allocate JobId=47280 NodeList=cpu[09-10] #CPUs=16 Partition=cpu-opteron
[2022-08-03T15:53:43.613] _job_complete: JobId=47189 WEXITSTATUS 0
[2022-08-03T15:53:43.613] _job_complete: JobId=47189 done
[2022-08-03T15:53:45.033] _slurm_rpc_submit_batch_job: JobId=47281 InitPrio=22357 usec=362
[2022-08-03T15:54:25.468] _slurm_rpc_kill_job: REQUEST_KILL_JOB JobId=47280 uid 548200003
[2022-08-03T15:54:40.529] sched/backfill: _start_job: Started JobId=47193 in cpu-epyc on cpu13
[2022-08-03T15:55:17.997] _slurm_rpc_submit_batch_job: JobId=47282 InitPrio=24863 usec=427
[2022-08-03T15:55:18.775] sched: Allocate JobId=47282 NodeList=cpu[09-10] #CPUs=16 Partition=cpu-opteron
[2022-08-03T15:55:24.091] _job_complete: JobId=47282 WEXITSTATUS 200
[2022-08-03T15:55:24.092] _job_complete: JobId=47282 done
[2022-08-03T15:55:35.509] _slurm_rpc_submit_batch_job: JobId=47283 InitPrio=22357 usec=451
[2022-08-03T15:56:10.262] _job_complete: JobId=47122 WEXITSTATUS 0
[2022-08-03T15:56:10.262] _job_complete: JobId=47122 done
[2022-08-03T15:56:11.919] _slurm_rpc_submit_batch_job: JobId=47284 InitPrio=22357 usec=359
[2022-08-03T15:56:29.508] _slurm_rpc_submit_batch_job: JobId=47285 InitPrio=22231 usec=425
[2022-08-03T15:56:42.568] _job_complete: JobId=47272 WEXITSTATUS 0
[2022-08-03T15:56:42.569] _job_complete: JobId=47272 done
[2022-08-03T15:56:45.849] _slurm_rpc_submit_batch_job: JobId=47286 InitPrio=22357 usec=409
[2022-08-03T15:56:50.593] sched: Allocate JobId=47281 NodeList=cpu03 #CPUs=32 Partition=cpu-opteron
[2022-08-03T15:57:18.649] _slurm_rpc_submit_batch_job: JobId=47287 InitPrio=22357 usec=394
[2022-08-03T15:57:24.901] _job_complete: JobId=47281 WEXITSTATUS 0
[2022-08-03T15:57:24.902] _job_complete: JobId=47281 done
[2022-08-03T15:57:26.924] sched: Allocate JobId=47283 NodeList=cpu03 #CPUs=32 Partition=cpu-opteron
[2022-08-03T15:57:53.701] _slurm_rpc_submit_batch_job: JobId=47288 InitPrio=24863 usec=406
[2022-08-03T15:57:54.096] sched: Allocate JobId=47288 NodeList=cpu[09-10] #CPUs=16 Partition=cpu-opteron
[2022-08-03T15:57:57.161] error: _find_node_record: lookup failure for node "cpu09.dicc.um.edu.my"
[2022-08-03T15:57:57.161] error: node_name2bitmap: invalid node specified: "cpu09.dicc.um.edu.my"
[2022-08-03T15:57:58.054] error: _find_node_record: lookup failure for node "cpu10.dicc.um.edu.my"
[2022-08-03T15:57:58.054] error: node_name2bitmap: invalid node specified: "cpu10.dicc.um.edu.my"
[2022-08-03T15:58:00.237] _job_complete: JobId=47283 WEXITSTATUS 0
[2022-08-03T15:58:00.238] _job_complete: JobId=47283 done
[2022-08-03T15:58:01.272] sched: Allocate JobId=47284 NodeList=cpu03 #CPUs=32 Partition=cpu-opteron
[2022-08-03T15:58:14.405] _job_complete: JobId=47284 WEXITSTATUS 0
[2022-08-03T15:58:14.405] _job_complete: JobId=47284 done
[2022-08-03T15:58:14.836] sched: Allocate JobId=47286 NodeList=cpu03 #CPUs=32 Partition=cpu-opteron
[2022-08-03T15:58:19.492] _job_complete: JobId=47286 WEXITSTATUS 0
[2022-08-03T15:58:19.492] _job_complete: JobId=47286 done
[2022-08-03T15:58:19.892] sched: Allocate JobId=47287 NodeList=cpu03 #CPUs=32 Partition=cpu-opteron
[2022-08-03T15:58:35.256] _job_complete: JobId=47287 WEXITSTATUS 0
[2022-08-03T15:58:35.256] _job_complete: JobId=47287 done
[2022-08-03T15:58:35.687] sched: Allocate JobId=47277 NodeList=cpu03 #CPUs=16 Partition=cpu-opteron
[2022-08-03T15:58:35.687] sched: Allocate JobId=47285 NodeList=cpu03 #CPUs=16 Partition=cpu-opteron
[2022-08-03T15:58:56.198] _slurm_rpc_submit_batch_job: JobId=47289 InitPrio=22357 usec=441
[2022-08-03T15:59:00.809] _slurm_rpc_submit_batch_job: JobId=47290 InitPrio=22357 usec=412
[2022-08-03T15:59:53.633] _slurm_rpc_kill_job: REQUEST_KILL_JOB JobId=47288 uid 548200003
[2022-08-03T16:00:00.666] _slurm_rpc_submit_batch_job: JobId=47291 InitPrio=22357 usec=437
[2022-08-03T16:00:37.212] _slurm_rpc_submit_batch_job: JobId=47292 InitPrio=22357 usec=402
[2022-08-03T16:00:43.102] _slurm_rpc_submit_batch_job: JobId=47293 InitPrio=24863 usec=494
[2022-08-03T16:00:43.332] sched: Allocate JobId=47293 NodeList=cpu[09-10] #CPUs=16 Partition=cpu-opteron
[2022-08-03T16:00:44.015] _job_complete: JobId=47293 WEXITSTATUS 127
[2022-08-03T16:00:44.015] _job_complete: JobId=47293 done
[2022-08-03T16:00:57.415] _slurm_rpc_submit_batch_job: JobId=47294 InitPrio=24863 usec=427
[2022-08-03T16:00:58.355] sched: Allocate JobId=47294 NodeList=cpu[09-10] #CPUs=16 Partition=cpu-opteron
[2022-08-03T16:02:08.807] _slurm_rpc_submit_batch_job: JobId=47295 InitPrio=22231 usec=467
[2022-08-03T16:02:37.790] _slurm_rpc_submit_batch_job: JobId=47296 InitPrio=25984 usec=456
[2022-08-03T16:02:38.567] sched: Allocate JobId=47296 NodeList=cpu07 #CPUs=8 Partition=cpu-opteron
[2022-08-03T16:02:42.521] _job_complete: JobId=47296 WEXITSTATUS 0
[2022-08-03T16:02:42.521] _job_complete: JobId=47296 done
[2022-08-03T16:02:54.174] _job_complete: JobId=47192 WEXITSTATUS 0
[2022-08-03T16:02:54.174] _job_complete: JobId=47192 done
[2022-08-03T16:03:07.126] _job_complete: JobId=47191 WEXITSTATUS 0
[2022-08-03T16:03:07.126] _job_complete: JobId=47191 done
[2022-08-03T16:03:40.565] sched/backfill: _start_job: Started JobId=47194 in cpu-epyc on cpu12
[2022-08-03T16:03:40.566] sched/backfill: _start_job: Started JobId=47195 in cpu-epyc on cpu15
[2022-08-03T16:03:40.822] _slurm_rpc_submit_batch_job: JobId=47297 InitPrio=25984 usec=361
[2022-08-03T16:03:41.698] sched: Allocate JobId=47297 NodeList=cpu07 #CPUs=8 Partition=cpu-opteron
[2022-08-03T16:03:46.210] _job_complete: JobId=47297 WEXITSTATUS 0
[2022-08-03T16:03:46.210] _job_complete: JobId=47297 done
[2022-08-03T16:04:56.089] _job_complete: JobId=47267 WEXITSTATUS 0
[2022-08-03T16:04:56.089] _job_complete: JobId=47267 done
[2022-08-03T16:05:11.009] _job_complete: JobId=47285 WEXITSTATUS 0
[2022-08-03T16:05:11.009] _job_complete: JobId=47285 done
[2022-08-03T16:05:27.666] _slurm_rpc_submit_batch_job: JobId=47298 InitPrio=22231 usec=463
[2022-08-03T16:05:40.574] sched/backfill: _start_job: Started JobId=47295 in cpu-opteron on cpu07
[2022-08-03T16:05:57.278] _job_complete: JobId=47265 WEXITSTATUS 0
[2022-08-03T16:05:57.278] _job_complete: JobId=47265 done
[2022-08-03T16:05:57.719] sched: Allocate JobId=47289 NodeList=cpu03 #CPUs=32 Partition=cpu-opteron
[2022-08-03T16:06:44.147] _job_complete: JobId=47295 WEXITSTATUS 0
[2022-08-03T16:06:44.147] _job_complete: JobId=47295 done
[2022-08-03T16:07:10.475] _slurm_rpc_submit_batch_job: JobId=47299 InitPrio=25984 usec=453
[2022-08-03T16:07:10.995] sched: Allocate JobId=47299 NodeList=cpu07 #CPUs=8 Partition=cpu-opteron
[2022-08-03T16:07:19.634] _job_complete: JobId=47299 WEXITSTATUS 0
[2022-08-03T16:07:19.634] _job_complete: JobId=47299 done
[2022-08-03T16:07:40.583] sched/backfill: _start_job: Started JobId=47298 in cpu-opteron on cpu07
[2022-08-03T16:07:43.070] _job_complete: JobId=47289 WEXITSTATUS 0
[2022-08-03T16:07:43.070] _job_complete: JobId=47289 done
[2022-08-03T16:07:44.058] sched: Allocate JobId=47290 NodeList=cpu03 #CPUs=32 Partition=cpu-opteron
[2022-08-03T16:09:38.577] _job_complete: JobId=47290 WEXITSTATUS 0
[2022-08-03T16:09:38.577] _job_complete: JobId=47290 done
[2022-08-03T16:09:39.562] sched: Allocate JobId=47291 NodeList=cpu03 #CPUs=32 Partition=cpu-opteron
[2022-08-03T16:09:59.243] _job_complete: JobId=47291 WEXITSTATUS 0
[2022-08-03T16:09:59.244] _job_complete: JobId=47291 done
[2022-08-03T16:09:59.646] sched: Allocate JobId=47292 NodeList=cpu03 #CPUs=32 Partition=cpu-opteron
[2022-08-03T16:11:02.516] _slurm_rpc_submit_batch_job: JobId=47300 InitPrio=22231 usec=575
[2022-08-03T16:11:15.795] _job_complete: JobId=47292 WEXITSTATUS 0
[2022-08-03T16:11:15.796] _job_complete: JobId=47292 done
[2022-08-03T16:11:16.788] sched: Allocate JobId=47300 NodeList=cpu03 #CPUs=16 Partition=cpu-opteron
[2022-08-03T16:11:31.165] _job_complete: JobId=47298 WEXITSTATUS 0
[2022-08-03T16:11:31.165] _job_complete: JobId=47298 done
[2022-08-03T16:15:44.310] _slurm_rpc_submit_batch_job: JobId=47301 InitPrio=22231 usec=403
[2022-08-03T16:15:45.040] sched: Allocate JobId=47301 NodeList=cpu03 #CPUs=16 Partition=cpu-opteron
[2022-08-03T16:15:55.587] _slurm_rpc_submit_batch_job: JobId=47302 InitPrio=25984 usec=443
[2022-08-03T16:15:56.060] sched: Allocate JobId=47302 NodeList=cpu07 #CPUs=8 Partition=cpu-opteron
[2022-08-03T16:16:03.385] _job_complete: JobId=47302 WEXITSTATUS 0
[2022-08-03T16:16:03.385] _job_complete: JobId=47302 done
[2022-08-03T16:16:22.862] _job_complete: JobId=47301 WEXITSTATUS 0
[2022-08-03T16:16:22.862] _job_complete: JobId=47301 done
[2022-08-03T16:19:08.820] _job_complete: JobId=47276 WEXITSTATUS 0
[2022-08-03T16:19:08.820] _job_complete: JobId=47276 done
[2022-08-03T16:22:53.840] _job_complete: JobId=47193 WEXITSTATUS 0
[2022-08-03T16:22:53.840] _job_complete: JobId=47193 done
[2022-08-03T16:23:05.462] _slurm_rpc_submit_batch_job: JobId=47303 InitPrio=25984 usec=530
[2022-08-03T16:23:06.954] sched: Allocate JobId=47303 NodeList=cpu03 #CPUs=8 Partition=cpu-opteron
[2022-08-03T16:23:13.918] _job_complete: JobId=47303 WEXITSTATUS 0
[2022-08-03T16:23:13.918] _job_complete: JobId=47303 done
[2022-08-03T16:23:40.631] sched/backfill: _start_job: Started JobId=47196 in cpu-epyc on cpu13
[2022-08-03T16:29:28.039] _job_complete: JobId=47277 WEXITSTATUS 0
[2022-08-03T16:29:28.039] _job_complete: JobId=47277 done
[2022-08-03T16:29:45.307] _job_complete: JobId=47300 WEXITSTATUS 0
[2022-08-03T16:29:45.307] _job_complete: JobId=47300 done
[2022-08-03T16:33:35.816] _job_complete: JobId=47195 WEXITSTATUS 0
[2022-08-03T16:33:35.816] _job_complete: JobId=47195 done
[2022-08-03T16:33:40.660] sched/backfill: _start_job: Started JobId=47197 in cpu-epyc on cpu15
[2022-08-03T16:34:19.095] _slurm_rpc_submit_batch_job: JobId=47304 InitPrio=22231 usec=420
[2022-08-03T16:34:20.089] sched: Allocate JobId=47304 NodeList=cpu10 #CPUs=16 Partition=cpu-opteron
[2022-08-03T16:34:21.792] _slurm_rpc_submit_batch_job: JobId=47305 InitPrio=22231 usec=403
[2022-08-03T16:34:23.090] sched: Allocate JobId=47305 NodeList=cpu07 #CPUs=16 Partition=cpu-opteron
[2022-08-03T16:34:24.334] _slurm_rpc_submit_batch_job: JobId=47306 InitPrio=22231 usec=392
[2022-08-03T16:34:26.095] sched: Allocate JobId=47306 NodeList=cpu03 #CPUs=16 Partition=cpu-opteron
[2022-08-03T16:34:27.407] _slurm_rpc_submit_batch_job: JobId=47307 InitPrio=22231 usec=520
[2022-08-03T16:34:29.099] sched: Allocate JobId=47307 NodeList=cpu03 #CPUs=16 Partition=cpu-opteron
[2022-08-03T16:38:23.232] _slurm_rpc_submit_batch_job: JobId=47308 InitPrio=22231 usec=398
[2022-08-03T16:38:23.576] sched: Allocate JobId=47308 NodeList=cpu03 #CPUs=16 Partition=cpu-opteron
[2022-08-03T16:43:34.283] _slurm_rpc_submit_batch_job: JobId=47309 InitPrio=22357 usec=406
[2022-08-03T16:45:42.518] _job_complete: JobId=47308 WEXITSTATUS 0
[2022-08-03T16:45:42.518] _job_complete: JobId=47308 done
[2022-08-03T17:01:42.658] _job_complete: JobId=47197 WEXITSTATUS 0
[2022-08-03T17:01:42.658] _job_complete: JobId=47197 done
[2022-08-03T17:02:40.740] sched/backfill: _start_job: Started JobId=47198 in cpu-epyc on cpu15
[2022-08-03T17:15:47.780] _job_complete: JobId=47247 WEXITSTATUS 0
[2022-08-03T17:15:47.780] _job_complete: JobId=47247 done
[2022-08-03T17:15:49.825] sched: Allocate JobId=47309 NodeList=cpu11 #CPUs=32 Partition=cpu-opteron
[2022-08-03T17:17:33.686] _job_complete: JobId=47309 WEXITSTATUS 0
[2022-08-03T17:17:33.687] _job_complete: JobId=47309 done
[2022-08-03T17:27:09.535] _job_complete: JobId=47194 WEXITSTATUS 0
[2022-08-03T17:27:09.535] _job_complete: JobId=47194 done
[2022-08-03T17:27:40.810] sched/backfill: _start_job: Started JobId=47199 in cpu-epyc on cpu12
[2022-08-03T17:35:10.306] _job_complete: JobId=47198 WEXITSTATUS 0
[2022-08-03T17:35:10.306] _job_complete: JobId=47198 done
[2022-08-03T17:35:40.830] sched/backfill: _start_job: Started JobId=47200 in cpu-epyc on cpu15
[2022-08-03T17:37:13.766] _job_complete: JobId=47196 WEXITSTATUS 0
[2022-08-03T17:37:13.766] _job_complete: JobId=47196 done
[2022-08-03T17:37:40.839] sched/backfill: _start_job: Started JobId=47201 in cpu-epyc on cpu13
[2022-08-03T17:50:41.763] _slurm_rpc_submit_batch_job: JobId=47310 InitPrio=22494 usec=543
[2022-08-03T17:50:42.392] sched: Allocate JobId=47310 NodeList=cpu03 #CPUs=16 Partition=cpu-opteron
[2022-08-03T17:50:45.456] _job_complete: JobId=47310 WEXITSTATUS 1
[2022-08-03T17:50:45.456] _job_complete: JobId=47310 done
[2022-08-03T17:50:46.104] _slurm_rpc_submit_batch_job: JobId=47311 InitPrio=22494 usec=441
[2022-08-03T17:50:46.395] sched: Allocate JobId=47311 NodeList=cpu03 #CPUs=16 Partition=cpu-opteron
[2022-08-03T17:50:47.144] _job_complete: JobId=47311 WEXITSTATUS 1
[2022-08-03T17:50:47.144] _job_complete: JobId=47311 done
[2022-08-03T17:50:50.625] _slurm_rpc_submit_batch_job: JobId=47312 InitPrio=22494 usec=376
[2022-08-03T17:50:51.402] sched: Allocate JobId=47312 NodeList=cpu03 #CPUs=16 Partition=cpu-opteron
[2022-08-03T17:50:52.174] _job_complete: JobId=47312 WEXITSTATUS 1
[2022-08-03T17:50:52.174] _job_complete: JobId=47312 done
[2022-08-03T17:50:55.617] _slurm_rpc_submit_batch_job: JobId=47313 InitPrio=22494 usec=391
[2022-08-03T17:50:56.409] sched: Allocate JobId=47313 NodeList=cpu03 #CPUs=16 Partition=cpu-opteron
[2022-08-03T17:50:57.111] _job_complete: JobId=47313 WEXITSTATUS 1
[2022-08-03T17:50:57.111] _job_complete: JobId=47313 done
[2022-08-03T17:51:02.425] _slurm_rpc_submit_batch_job: JobId=47314 InitPrio=22494 usec=502
[2022-08-03T17:51:03.418] sched: Allocate JobId=47314 NodeList=cpu03 #CPUs=16 Partition=cpu-opteron
[2022-08-03T17:51:04.138] _job_complete: JobId=47314 WEXITSTATUS 1
[2022-08-03T17:51:04.138] _job_complete: JobId=47314 done
[2022-08-03T17:51:12.434] _slurm_rpc_submit_batch_job: JobId=47315 InitPrio=22494 usec=534
[2022-08-03T17:51:13.432] sched: Allocate JobId=47315 NodeList=cpu03 #CPUs=16 Partition=cpu-opteron
[2022-08-03T17:51:14.115] _job_complete: JobId=47315 WEXITSTATUS 1
[2022-08-03T17:51:14.115] _job_complete: JobId=47315 done
[2022-08-03T17:54:45.794] _slurm_rpc_submit_batch_job: JobId=47316 InitPrio=22494 usec=476
[2022-08-03T17:54:45.862] sched: Allocate JobId=47316 NodeList=cpu03 #CPUs=16 Partition=cpu-opteron
[2022-08-03T17:55:13.061] _slurm_rpc_submit_batch_job: JobId=47317 InitPrio=22494 usec=449
[2022-08-03T17:55:13.901] sched: Allocate JobId=47317 NodeList=cpu11 #CPUs=16 Partition=cpu-opteron
[2022-08-03T17:55:33.977] _slurm_rpc_submit_batch_job: JobId=47318 InitPrio=22494 usec=407
[2022-08-03T17:55:34.930] sched: Allocate JobId=47318 NodeList=cpu11 #CPUs=16 Partition=cpu-opteron
[2022-08-03T17:56:05.890] _slurm_rpc_submit_batch_job: JobId=47319 InitPrio=22494 usec=481
[2022-08-03T17:56:27.067] _slurm_rpc_submit_batch_job: JobId=47320 InitPrio=22494 usec=439
[2022-08-03T17:57:07.562] _slurm_rpc_submit_batch_job: JobId=47321 InitPrio=22494 usec=553
[2022-08-03T17:57:34.774] _slurm_rpc_kill_job: REQUEST_KILL_JOB JobId=47320 uid 548200029
[2022-08-03T17:57:37.386] _slurm_rpc_submit_batch_job: JobId=47322 InitPrio=22494 usec=581
[2022-08-03T17:57:46.187] _job_complete: JobId=47317 WEXITSTATUS 0
[2022-08-03T17:57:46.188] _job_complete: JobId=47317 done
[2022-08-03T17:57:46.613] sched: Allocate JobId=47319 NodeList=cpu11 #CPUs=16 Partition=cpu-opteron
[2022-08-03T17:57:47.395] _job_complete: JobId=47319 WEXITSTATUS 1
[2022-08-03T17:57:47.395] _job_complete: JobId=47319 done
[2022-08-03T17:57:47.945] sched: Allocate JobId=47321 NodeList=cpu11 #CPUs=16 Partition=cpu-opteron
[2022-08-03T17:58:56.327] _job_complete: JobId=47318 WEXITSTATUS 0
[2022-08-03T17:58:56.327] _job_complete: JobId=47318 done
[2022-08-03T17:58:56.729] sched: Allocate JobId=47322 NodeList=cpu11 #CPUs=16 Partition=cpu-opteron
[2022-08-03T18:01:28.012] _job_complete: JobId=47321 WEXITSTATUS 0
[2022-08-03T18:01:28.012] _job_complete: JobId=47321 done
[2022-08-03T18:01:39.697] _job_complete: JobId=47322 WEXITSTATUS 0
[2022-08-03T18:01:39.697] _job_complete: JobId=47322 done
[2022-08-03T18:06:13.896] _job_complete: JobId=47201 WEXITSTATUS 0
[2022-08-03T18:06:13.896] _job_complete: JobId=47201 done
[2022-08-03T18:06:40.913] sched/backfill: _start_job: Started JobId=47202 in cpu-epyc on cpu13
[2022-08-03T18:09:10.144] _job_complete: JobId=47199 WEXITSTATUS 0
[2022-08-03T18:09:10.144] _job_complete: JobId=47199 done
[2022-08-03T18:09:40.921] sched/backfill: _start_job: Started JobId=47203 in cpu-epyc on cpu12
[2022-08-03T18:13:56.340] _job_complete: JobId=47200 WEXITSTATUS 0
[2022-08-03T18:13:56.340] _job_complete: JobId=47200 done
[2022-08-03T18:14:40.933] sched/backfill: _start_job: Started JobId=47204 in cpu-epyc on cpu15
[2022-08-03T18:20:00.584] _job_complete: JobId=47316 WEXITSTATUS 0
[2022-08-03T18:20:00.584] _job_complete: JobId=47316 done
[2022-08-03T18:41:34.595] _job_complete: JobId=47203 WEXITSTATUS 0
[2022-08-03T18:41:34.596] _job_complete: JobId=47203 done
[2022-08-03T18:41:40.998] sched/backfill: _start_job: Started JobId=47205 in cpu-epyc on cpu12
[2022-08-03T18:45:28.785] _job_complete: JobId=47307 WEXITSTATUS 0
[2022-08-03T18:45:28.785] _job_complete: JobId=47307 done
[2022-08-03T18:46:29.522] _job_complete: JobId=47204 WEXITSTATUS 0
[2022-08-03T18:46:29.522] _job_complete: JobId=47204 done
[2022-08-03T18:46:41.011] sched/backfill: _start_job: Started JobId=47206 in cpu-epyc on cpu15
[2022-08-03T18:50:27.288] _job_complete: JobId=47305 WEXITSTATUS 0
[2022-08-03T18:50:27.288] _job_complete: JobId=47305 done
[2022-08-03T18:54:11.155] _job_complete: JobId=47116 WEXITSTATUS 0
[2022-08-03T18:54:11.155] _job_complete: JobId=47116 done
[2022-08-03T18:59:09.741] _job_complete: JobId=47306 WEXITSTATUS 0
[2022-08-03T18:59:09.742] _job_complete: JobId=47306 done
[2022-08-03T19:12:51.984] _job_complete: JobId=47205 WEXITSTATUS 0
[2022-08-03T19:12:51.984] _job_complete: JobId=47205 done
[2022-08-03T19:13:41.083] sched/backfill: _start_job: Started JobId=47207 in cpu-epyc on cpu12
[2022-08-03T19:14:23.696] _job_complete: JobId=47206 WEXITSTATUS 0
[2022-08-03T19:14:23.696] _job_complete: JobId=47206 done
[2022-08-03T19:14:41.085] sched/backfill: _start_job: Started JobId=47208 in cpu-epyc on cpu15
[2022-08-03T19:46:02.886] _job_complete: JobId=47208 WEXITSTATUS 0
[2022-08-03T19:46:02.886] _job_complete: JobId=47208 done
[2022-08-03T19:46:41.153] sched/backfill: _start_job: Started JobId=47209 in cpu-epyc on cpu15
[2022-08-03T19:52:53.967] _job_complete: JobId=47207 WEXITSTATUS 0
[2022-08-03T19:52:53.967] _job_complete: JobId=47207 done
[2022-08-03T20:19:43.603] _job_complete: JobId=47209 WEXITSTATUS 0
[2022-08-03T20:19:43.603] _job_complete: JobId=47209 done
[2022-08-03T20:26:18.810] _job_complete: JobId=47304 WEXITSTATUS 0
[2022-08-03T20:26:18.810] _job_complete: JobId=47304 done
[2022-08-03T22:04:53.872] _job_complete: JobId=47202 WEXITSTATUS 1
[2022-08-03T22:04:53.872] _job_complete: JobId=47202 done
[2022-08-03T22:24:44.587] _slurm_rpc_submit_batch_job: JobId=47323 InitPrio=21304 usec=490
[2022-08-03T22:25:41.430] sched/backfill: _start_job: Started JobId=47323 in cpu-opteron on cpu11
[2022-08-04T02:00:58.113] _slurm_rpc_submit_batch_job: JobId=47324 InitPrio=22357 usec=467
[2022-08-04T02:01:36.009] _slurm_rpc_submit_batch_job: JobId=47325 InitPrio=21373 usec=497
[2022-08-04T02:01:41.761] sched/backfill: _start_job: Started JobId=47324 in cpu-opteron on cpu07
[2022-08-04T02:01:41.774] sched/backfill: _start_job: Started JobId=47325 in cpu-opteron on cpu03
[2022-08-04T02:02:11.801] _job_complete: JobId=47324 WEXITSTATUS 0
[2022-08-04T02:02:11.801] _job_complete: JobId=47324 done
[2022-08-04T02:04:14.600] _slurm_rpc_submit_batch_job: JobId=47326 InitPrio=21373 usec=504
[2022-08-04T02:09:24.765] _slurm_rpc_submit_batch_job: JobId=47327 InitPrio=21373 usec=638
[2022-08-04T02:09:41.787] sched/backfill: _start_job: Started JobId=47327 in cpu-opteron on cpu03
[2022-08-04T02:14:33.993] _slurm_rpc_submit_batch_job: JobId=47328 InitPrio=21476 usec=494
[2022-08-04T02:14:41.798] sched/backfill: _start_job: Started JobId=47328 in cpu-opteron on cpu10
[2022-08-04T02:25:18.430] _slurm_rpc_submit_batch_job: JobId=47329 InitPrio=21476 usec=475
[2022-08-04T02:25:41.820] sched/backfill: _start_job: Started JobId=47329 in cpu-opteron on cpu07
[2022-08-04T03:46:44.181] _slurm_rpc_kill_job: REQUEST_KILL_JOB JobId=46935 uid 548300513
[2022-08-04T03:46:47.049] sched: Allocate JobId=46941 NodeList=cpu12 #CPUs=32 Partition=cpu-epyc
[2022-08-04T03:51:07.602] _job_complete: JobId=47328 WEXITSTATUS 0
[2022-08-04T03:51:07.602] _job_complete: JobId=47328 done
[2022-08-04T03:55:18.071] _job_complete: JobId=47329 WEXITSTATUS 0
[2022-08-04T03:55:18.071] _job_complete: JobId=47329 done
[2022-08-04T03:57:12.205] _job_complete: JobId=46995 WEXITSTATUS 0
[2022-08-04T03:57:12.205] _job_complete: JobId=46995 done
[2022-08-04T03:57:14.224] sched: Allocate JobId=46934 NodeList=cpu07 #CPUs=64 Partition=cpu-opteron
[2022-08-04T05:10:24.245] _slurm_rpc_kill_job: REQUEST_KILL_JOB JobId=46817 uid 548200045
[2022-08-04T05:13:34.480] _job_complete: JobId=46941 WEXITSTATUS 1
[2022-08-04T05:13:34.481] _job_complete: JobId=46941 done
[2022-08-04T05:13:35.302] sched: Allocate JobId=46942 NodeList=cpu12 #CPUs=32 Partition=cpu-epyc
[2022-08-04T07:26:45.171] _job_complete: JobId=47323 WEXITSTATUS 0
[2022-08-04T07:26:45.171] _job_complete: JobId=47323 done
[2022-08-04T08:55:16.339] _slurm_rpc_kill_job: REQUEST_KILL_JOB JobId=47294 uid 548200003
[2022-08-04T09:08:17.678] _slurm_rpc_submit_batch_job: JobId=47330 InitPrio=25194 usec=484
[2022-08-04T09:08:18.604] sched: Allocate JobId=47330 NodeList=cpu12 #CPUs=8 Partition=cpu-epyc
[2022-08-04T09:08:19.258] _job_complete: JobId=47330 WEXITSTATUS 255
[2022-08-04T09:08:19.259] _job_complete: JobId=47330 done
[2022-08-04T09:09:09.678] _slurm_rpc_submit_batch_job: JobId=47331 InitPrio=25194 usec=439
[2022-08-04T09:09:10.652] sched: Allocate JobId=47331 NodeList=cpu12 #CPUs=8 Partition=cpu-epyc
[2022-08-04T09:09:16.383] _job_complete: JobId=47331 WEXITSTATUS 0
[2022-08-04T09:09:16.383] _job_complete: JobId=47331 done
[2022-08-04T09:10:00.754] _slurm_rpc_submit_batch_job: JobId=47332 InitPrio=24599 usec=464
[2022-08-04T09:10:21.109] _update_job: updating accounting
[2022-08-04T09:10:21.109] _slurm_rpc_update_job: complete JobId=47332 uid=548200003 usec=976
[2022-08-04T09:10:21.751] sched: Allocate JobId=47332 NodeList=cpu[12-13] #CPUs=16 Partition=cpu-epyc
[2022-08-04T09:10:26.227] _job_complete: JobId=47332 WEXITSTATUS 0
[2022-08-04T09:10:26.227] _job_complete: JobId=47332 done
[2022-08-04T09:11:08.754] _slurm_rpc_submit_batch_job: JobId=47333 InitPrio=24599 usec=417
[2022-08-04T09:11:20.920] _update_job: updating accounting
[2022-08-04T09:11:20.920] _slurm_rpc_update_job: complete JobId=47333 uid=548200003 usec=773
[2022-08-04T09:11:21.834] sched: Allocate JobId=47333 NodeList=cpu[12-13] #CPUs=16 Partition=cpu-epyc
[2022-08-04T09:13:09.144] _slurm_rpc_kill_job: REQUEST_KILL_JOB JobId=47333 uid 548200003
[2022-08-04T09:14:01.031] _slurm_rpc_submit_batch_job: JobId=47334 InitPrio=24599 usec=471
[2022-08-04T09:14:11.031] _update_job: updating accounting
[2022-08-04T09:14:11.031] _slurm_rpc_update_job: complete JobId=47334 uid=548200003 usec=936
[2022-08-04T09:14:11.180] sched: Allocate JobId=47334 NodeList=cpu[12-13] #CPUs=16 Partition=cpu-epyc
[2022-08-04T09:14:54.263] _slurm_rpc_kill_job: REQUEST_KILL_JOB JobId=47334 uid 548200003
[2022-08-04T09:16:37.766] Core count for reservation node list is not consistent!
[2022-08-04T09:16:37.766] _slurm_rpc_resv_create reservation=biovia_test: Core count for reservation node list is not consistent!
[2022-08-04T09:16:44.637] Core count for reservation node list is not consistent!
[2022-08-04T09:16:44.637] _slurm_rpc_resv_create reservation=biovia_test: Core count for reservation node list is not consistent!
[2022-08-04T09:16:59.863] Core count for reservation node list is not consistent!
[2022-08-04T09:16:59.863] _slurm_rpc_resv_create reservation=biovia_test: Core count for reservation node list is not consistent!
[2022-08-04T09:17:08.922] Core count for reservation node list is not consistent!
[2022-08-04T09:17:08.922] _slurm_rpc_resv_create reservation=biovia_test: Core count for reservation node list is not consistent!
[2022-08-04T09:17:28.947] sched: Created reservation=biovia_test users=jitkang nodes=cpu[12-13] cores=32 licenses=(null) tres=cpu=64 watts=4294967294 start=2022-08-04T09:17:28 end=2023-08-04T09:17:28 MaxStartDelay=
[2022-08-04T09:18:04.348] Reservation biovia_test request overlaps jobs
[2022-08-04T09:18:04.348] _slurm_rpc_resv_update reservation=biovia_test: Requested nodes are busy
[2022-08-04T09:18:08.214] Reservation biovia_test request overlaps jobs
[2022-08-04T09:18:08.215] _slurm_rpc_resv_update reservation=biovia_test: Requested nodes are busy
[2022-08-04T09:18:44.694] _slurm_rpc_delete_reservation complete for biovia_test usec=55
[2022-08-04T09:18:54.073] sched: Created reservation=biovia_test users=jitkang nodes=cpu[12-13] cores=32 licenses=(null) tres=cpu=64 watts=4294967294 start=2022-08-04T09:18:54 end=2023-08-04T09:18:54 MaxStartDelay=
[2022-08-04T09:19:56.615] sched: Created reservation=biovia_test_opt users=jitkang nodes=cpu[10-11] cores=32 licenses=(null) tres=cpu=32 watts=4294967294 start=2022-08-04T09:19:56 end=2023-08-04T09:19:56 MaxStartDelay=
[2022-08-04T09:24:55.761] _slurm_rpc_submit_batch_job: JobId=47335 InitPrio=24599 usec=559
[2022-08-04T09:24:56.364] sched: Allocate JobId=47335 NodeList=cpu[12-13] #CPUs=16 Partition=cpu-epyc
[2022-08-04T09:25:24.726] _slurm_rpc_kill_job: REQUEST_KILL_JOB JobId=47335 uid 548200003
[2022-08-04T09:28:15.407] _slurm_rpc_submit_batch_job: JobId=47336 InitPrio=24599 usec=457
[2022-08-04T09:28:15.846] sched: Allocate JobId=47336 NodeList=cpu[10-11] #CPUs=16 Partition=cpu-opteron
[2022-08-04T09:29:09.849] _slurm_rpc_kill_job: REQUEST_KILL_JOB JobId=47336 uid 548200003
[2022-08-04T09:31:18.981] _slurm_rpc_submit_batch_job: JobId=47337 InitPrio=24599 usec=439
[2022-08-04T09:31:19.109] sched: Allocate JobId=47337 NodeList=cpu[12-13] #CPUs=16 Partition=cpu-epyc
[2022-08-04T09:31:22.982] _job_complete: JobId=47337 WEXITSTATUS 137
[2022-08-04T09:31:22.982] _job_complete: JobId=47337 done
[2022-08-04T09:32:54.987] _slurm_rpc_submit_batch_job: JobId=47338 InitPrio=24599 usec=523
[2022-08-04T09:32:55.381] sched: Allocate JobId=47338 NodeList=cpu[12-13] #CPUs=16 Partition=cpu-epyc
[2022-08-04T09:32:59.125] _job_complete: JobId=47338 WEXITSTATUS 0
[2022-08-04T09:32:59.125] _job_complete: JobId=47338 done
[2022-08-04T09:34:11.458] _slurm_rpc_submit_batch_job: JobId=47339 InitPrio=24599 usec=488
[2022-08-04T09:34:11.490] sched: Allocate JobId=47339 NodeList=cpu[12-13] #CPUs=16 Partition=cpu-epyc
[2022-08-04T09:35:09.197] _slurm_rpc_kill_job: REQUEST_KILL_JOB JobId=47339 uid 548200003
[2022-08-04T09:35:34.038] _slurm_rpc_submit_batch_job: JobId=47340 InitPrio=24599 usec=446
[2022-08-04T09:35:34.606] sched: Allocate JobId=47340 NodeList=cpu[12-13] #CPUs=16 Partition=cpu-epyc
[2022-08-04T09:35:37.956] _job_complete: JobId=47340 WEXITSTATUS 137
[2022-08-04T09:35:37.956] _job_complete: JobId=47340 done
[2022-08-04T09:36:44.145] _slurm_rpc_submit_batch_job: JobId=47341 InitPrio=24599 usec=493
[2022-08-04T09:36:44.705] sched: Allocate JobId=47341 NodeList=cpu[12-13] #CPUs=16 Partition=cpu-epyc
[2022-08-04T09:37:26.027] _slurm_rpc_kill_job: REQUEST_KILL_JOB JobId=47341 uid 548200003
[2022-08-04T09:38:38.375] _slurm_rpc_submit_batch_job: JobId=47342 InitPrio=24599 usec=487
[2022-08-04T09:38:39.043] sched: Allocate JobId=47342 NodeList=cpu[12-13] #CPUs=16 Partition=cpu-epyc
[2022-08-04T09:38:39.486] _job_complete: JobId=47342 WEXITSTATUS 2
[2022-08-04T09:38:39.486] _job_complete: JobId=47342 done
[2022-08-04T09:39:02.491] _slurm_rpc_submit_batch_job: JobId=47343 InitPrio=24599 usec=605
[2022-08-04T09:39:03.078] sched: Allocate JobId=47343 NodeList=cpu[12-13] #CPUs=16 Partition=cpu-epyc
[2022-08-04T09:39:03.540] _job_complete: JobId=47343 WEXITSTATUS 13
[2022-08-04T09:39:03.540] _job_complete: JobId=47343 done
[2022-08-04T09:39:21.839] _slurm_rpc_submit_batch_job: JobId=47344 InitPrio=24599 usec=461
[2022-08-04T09:39:22.104] sched: Allocate JobId=47344 NodeList=cpu[12-13] #CPUs=16 Partition=cpu-epyc
[2022-08-04T09:39:22.570] _job_complete: JobId=47344 WEXITSTATUS 8
[2022-08-04T09:39:22.570] _job_complete: JobId=47344 done
[2022-08-04T09:39:37.540] _slurm_rpc_submit_batch_job: JobId=47345 InitPrio=24599 usec=452
[2022-08-04T09:39:38.127] sched: Allocate JobId=47345 NodeList=cpu[12-13] #CPUs=16 Partition=cpu-epyc
[2022-08-04T09:39:56.843] _slurm_rpc_kill_job: REQUEST_KILL_JOB JobId=47345 uid 548200003
[2022-08-04T09:40:07.487] _slurm_rpc_submit_batch_job: JobId=47346 InitPrio=24599 usec=392
[2022-08-04T09:40:08.170] sched: Allocate JobId=47346 NodeList=cpu[12-13] #CPUs=16 Partition=cpu-epyc
[2022-08-04T09:40:44.334] _slurm_rpc_kill_job: REQUEST_KILL_JOB JobId=47346 uid 548200003
[2022-08-04T09:43:04.186] _slurm_rpc_submit_batch_job: JobId=47347 InitPrio=24599 usec=444
[2022-08-04T09:43:04.603] sched: Allocate JobId=47347 NodeList=cpu[12-13] #CPUs=16 Partition=cpu-epyc
[2022-08-04T09:43:23.136] _slurm_rpc_kill_job: REQUEST_KILL_JOB JobId=47347 uid 548200003
[2022-08-04T09:44:06.966] _slurm_rpc_submit_batch_job: JobId=47348 InitPrio=24599 usec=486
[2022-08-04T09:44:07.693] sched: Allocate JobId=47348 NodeList=cpu[12-13] #CPUs=16 Partition=cpu-epyc
[2022-08-04T09:44:38.360] _slurm_rpc_kill_job: REQUEST_KILL_JOB JobId=47348 uid 548200003
[2022-08-04T09:56:55.525] _slurm_rpc_submit_batch_job: JobId=47349 InitPrio=24599 usec=399
[2022-08-04T09:56:56.058] sched: Allocate JobId=47349 NodeList=cpu[12-13] #CPUs=16 Partition=cpu-epyc
[2022-08-04T09:56:56.416] _job_complete: JobId=47349 WEXITSTATUS 127
[2022-08-04T09:56:56.416] _job_complete: JobId=47349 done
[2022-08-04T09:57:39.523] _slurm_rpc_submit_batch_job: JobId=47350 InitPrio=24599 usec=461
[2022-08-04T09:57:40.218] sched: Allocate JobId=47350 NodeList=cpu[12-13] #CPUs=16 Partition=cpu-epyc
[2022-08-04T09:57:40.539] _job_complete: JobId=47350 WEXITSTATUS 255
[2022-08-04T09:57:40.539] _job_complete: JobId=47350 done
[2022-08-04T09:58:39.067] _slurm_rpc_submit_batch_job: JobId=47351 InitPrio=24462 usec=524
[2022-08-04T09:58:39.341] sched: Allocate JobId=47351 NodeList=cpu[12-13] #CPUs=32 Partition=cpu-epyc
[2022-08-04T09:58:39.695] _job_complete: JobId=47351 WEXITSTATUS 255
[2022-08-04T09:58:39.695] _job_complete: JobId=47351 done
[2022-08-04T09:59:07.173] _slurm_rpc_submit_batch_job: JobId=47352 InitPrio=24462 usec=435
[2022-08-04T09:59:07.380] sched: Allocate JobId=47352 NodeList=cpu[12-13] #CPUs=32 Partition=cpu-epyc
[2022-08-04T09:59:07.756] _job_complete: JobId=47352 WEXITSTATUS 255
[2022-08-04T09:59:07.756] _job_complete: JobId=47352 done
[2022-08-04T10:00:02.171] _slurm_rpc_submit_batch_job: JobId=47353 InitPrio=24462 usec=484
[2022-08-04T10:00:02.458] sched: Allocate JobId=47353 NodeList=cpu[12-13] #CPUs=32 Partition=cpu-epyc
[2022-08-04T10:00:06.211] _job_complete: JobId=47353 WEXITSTATUS 200
[2022-08-04T10:00:06.211] _job_complete: JobId=47353 done
[2022-08-04T10:01:33.296] _slurm_rpc_submit_batch_job: JobId=47354 InitPrio=24462 usec=433
[2022-08-04T10:01:33.588] sched: Allocate JobId=47354 NodeList=cpu[12-13] #CPUs=32 Partition=cpu-epyc
[2022-08-04T10:02:16.715] _slurm_rpc_kill_job: REQUEST_KILL_JOB JobId=47354 uid 548200003
[2022-08-04T10:02:34.711] _slurm_rpc_submit_batch_job: JobId=47355 InitPrio=20652 usec=449
[2022-08-04T10:02:39.588] _slurm_rpc_submit_batch_job: JobId=47356 InitPrio=24462 usec=419
[2022-08-04T10:02:39.748] sched: Allocate JobId=47356 NodeList=cpu[12-13] #CPUs=32 Partition=cpu-epyc
[2022-08-04T10:04:59.809] _slurm_rpc_kill_job: REQUEST_KILL_JOB JobId=47356 uid 548200003
[2022-08-04T10:06:28.842] _slurm_rpc_submit_batch_job: JobId=47357 InitPrio=24462 usec=594
[2022-08-04T10:06:29.111] sched: Allocate JobId=47357 NodeList=cpu[12-13] #CPUs=32 Partition=cpu-epyc
[2022-08-04T10:07:30.135] _slurm_rpc_kill_job: REQUEST_KILL_JOB JobId=47357 uid 548200003
[2022-08-04T10:07:42.155] _slurm_rpc_submit_batch_job: JobId=47358 InitPrio=24462 usec=395
[2022-08-04T10:07:42.277] sched: Allocate JobId=47358 NodeList=cpu[12-13] #CPUs=32 Partition=cpu-epyc
[2022-08-04T10:07:59.031] _slurm_rpc_kill_job: REQUEST_KILL_JOB JobId=47358 uid 548200003
[2022-08-04T10:08:37.126] _slurm_rpc_submit_batch_job: JobId=47359 InitPrio=24462 usec=475
[2022-08-04T10:08:37.395] sched: Allocate JobId=47359 NodeList=cpu[12-13] #CPUs=32 Partition=cpu-epyc
[2022-08-04T10:08:49.567] _slurm_rpc_kill_job: REQUEST_KILL_JOB JobId=47359 uid 548200003
[2022-08-04T10:09:08.757] _slurm_rpc_submit_batch_job: JobId=47360 InitPrio=24462 usec=532
[2022-08-04T10:09:09.439] sched: Allocate JobId=47360 NodeList=cpu[12-13] #CPUs=32 Partition=cpu-epyc
[2022-08-04T10:09:11.497] job_step_signal: JobId=47360 StepId=0 not found
[2022-08-04T10:09:11.501] job_step_signal: JobId=47360 StepId=0 not found
[2022-08-04T10:09:11.503] job_step_signal: JobId=47360 StepId=0 not found
[2022-08-04T10:09:11.514] job_step_signal: JobId=47360 StepId=0 not found
[2022-08-04T10:09:11.515] job_step_signal: JobId=47360 StepId=0 not found
[2022-08-04T10:09:11.515] job_step_signal: JobId=47360 StepId=0 not found
[2022-08-04T10:09:11.515] job_step_signal: JobId=47360 StepId=0 not found
[2022-08-04T10:09:11.515] job_step_signal: JobId=47360 StepId=0 not found
[2022-08-04T10:09:11.515] job_step_signal: JobId=47360 StepId=0 not found
[2022-08-04T10:09:11.515] job_step_signal: JobId=47360 StepId=0 not found
[2022-08-04T10:09:11.516] job_step_signal: JobId=47360 StepId=0 not found
[2022-08-04T10:09:11.517] job_step_signal: JobId=47360 StepId=0 not found
[2022-08-04T10:09:11.517] job_step_signal: JobId=47360 StepId=0 not found
[2022-08-04T10:09:11.518] job_step_signal: JobId=47360 StepId=0 not found
[2022-08-04T10:09:11.518] job_step_signal: JobId=47360 StepId=0 not found
[2022-08-04T10:09:11.519] job_step_signal: JobId=47360 StepId=0 not found
[2022-08-04T10:09:12.775] _job_complete: JobId=47360 WEXITSTATUS 0
[2022-08-04T10:09:12.775] _job_complete: JobId=47360 done
[2022-08-04T10:09:53.249] _slurm_rpc_submit_batch_job: JobId=47361 InitPrio=24462 usec=369
[2022-08-04T10:09:53.501] sched: Allocate JobId=47361 NodeList=cpu[12-13] #CPUs=32 Partition=cpu-epyc
[2022-08-04T10:10:22.838] _slurm_rpc_kill_job: REQUEST_KILL_JOB JobId=47361 uid 548200003
[2022-08-04T10:10:38.676] _slurm_rpc_submit_batch_job: JobId=47362 InitPrio=24462 usec=386
[2022-08-04T10:10:39.567] sched: Allocate JobId=47362 NodeList=cpu[12-13] #CPUs=32 Partition=cpu-epyc
[2022-08-04T10:10:54.324] _slurm_rpc_kill_job: REQUEST_KILL_JOB JobId=47362 uid 548200003
[2022-08-04T10:11:35.342] _slurm_rpc_submit_batch_job: JobId=47363 InitPrio=24462 usec=617
[2022-08-04T10:11:35.647] sched: Allocate JobId=47363 NodeList=cpu[12-13] #CPUs=32 Partition=cpu-epyc
[2022-08-04T10:11:38.841] _job_complete: JobId=47363 WEXITSTATUS 200
[2022-08-04T10:11:38.841] _job_complete: JobId=47363 done
[2022-08-04T10:11:59.512] _slurm_rpc_submit_batch_job: JobId=47364 InitPrio=24462 usec=400
[2022-08-04T10:11:59.680] sched: Allocate JobId=47364 NodeList=cpu[12-13] #CPUs=32 Partition=cpu-epyc
[2022-08-04T10:12:02.901] _job_complete: JobId=47364 WEXITSTATUS 200
[2022-08-04T10:12:02.901] _job_complete: JobId=47364 done
[2022-08-04T10:12:49.726] _slurm_rpc_submit_batch_job: JobId=47365 InitPrio=24462 usec=470
[2022-08-04T10:12:50.035] sched: Allocate JobId=47365 NodeList=cpu[12-13] #CPUs=32 Partition=cpu-epyc
[2022-08-04T10:12:53.210] _job_complete: JobId=47365 WEXITSTATUS 200
[2022-08-04T10:12:53.210] _job_complete: JobId=47365 done
[2022-08-04T10:13:31.680] _slurm_rpc_submit_batch_job: JobId=47366 InitPrio=24462 usec=422
[2022-08-04T10:13:32.094] sched: Allocate JobId=47366 NodeList=cpu[12-13] #CPUs=32 Partition=cpu-epyc
[2022-08-04T10:13:35.551] _job_complete: JobId=47366 WEXITSTATUS 200
[2022-08-04T10:13:35.551] _job_complete: JobId=47366 done
[2022-08-04T10:15:19.616] _slurm_rpc_submit_batch_job: JobId=47367 InitPrio=24462 usec=398
[2022-08-04T10:15:20.250] sched: Allocate JobId=47367 NodeList=cpu[12-13] #CPUs=32 Partition=cpu-epyc
[2022-08-04T10:15:24.223] _job_complete: JobId=47367 WEXITSTATUS 200
[2022-08-04T10:15:24.223] _job_complete: JobId=47367 done
[2022-08-04T10:16:08.358] _slurm_rpc_submit_batch_job: JobId=47368 InitPrio=24462 usec=379
[2022-08-04T10:16:09.317] sched: Allocate JobId=47368 NodeList=cpu[12-13] #CPUs=32 Partition=cpu-epyc
[2022-08-04T10:16:12.539] _job_complete: JobId=47368 WEXITSTATUS 200
[2022-08-04T10:16:12.539] _job_complete: JobId=47368 done
[2022-08-04T10:16:59.271] _slurm_rpc_submit_batch_job: JobId=47369 InitPrio=25126 usec=360
[2022-08-04T10:16:59.387] sched: Allocate JobId=47369 NodeList=cpu12 #CPUs=16 Partition=cpu-epyc
[2022-08-04T10:17:02.670] _job_complete: JobId=47369 WEXITSTATUS 200
[2022-08-04T10:17:02.670] _job_complete: JobId=47369 done
[2022-08-04T10:17:30.916] _slurm_rpc_submit_batch_job: JobId=47370 InitPrio=25126 usec=495
[2022-08-04T10:17:31.433] sched: Allocate JobId=47370 NodeList=cpu12 #CPUs=16 Partition=cpu-epyc
[2022-08-04T10:17:34.719] _job_complete: JobId=47370 WEXITSTATUS 200
[2022-08-04T10:17:34.719] _job_complete: JobId=47370 done
[2022-08-04T10:18:14.778] _slurm_rpc_submit_batch_job: JobId=47371 InitPrio=25126 usec=428
[2022-08-04T10:18:15.656] sched: Allocate JobId=47371 NodeList=cpu12 #CPUs=16 Partition=cpu-epyc
[2022-08-04T10:18:18.875] _job_complete: JobId=47371 WEXITSTATUS 200
[2022-08-04T10:18:18.875] _job_complete: JobId=47371 done
[2022-08-04T10:19:48.609] _slurm_rpc_submit_batch_job: JobId=47372 InitPrio=25126 usec=453
[2022-08-04T10:19:48.782] sched: Allocate JobId=47372 NodeList=cpu12 #CPUs=16 Partition=cpu-epyc
[2022-08-04T10:19:52.035] _job_complete: JobId=47372 WEXITSTATUS 200
[2022-08-04T10:19:52.035] _job_complete: JobId=47372 done
[2022-08-04T10:20:15.539] _slurm_rpc_submit_batch_job: JobId=47373 InitPrio=25126 usec=439
[2022-08-04T10:20:15.820] sched: Allocate JobId=47373 NodeList=cpu12 #CPUs=16 Partition=cpu-epyc
[2022-08-04T10:21:49.786] _slurm_rpc_kill_job: REQUEST_KILL_JOB JobId=47373 uid 548200003
[2022-08-04T10:22:01.550] _slurm_rpc_submit_batch_job: JobId=47374 InitPrio=22094 usec=479
[2022-08-04T10:22:21.855] _slurm_rpc_submit_batch_job: JobId=47375 InitPrio=24462 usec=812
[2022-08-04T10:22:21.996] sched: Allocate JobId=47375 NodeList=cpu[12-13] #CPUs=32 Partition=cpu-epyc
[2022-08-04T10:24:50.332] _job_complete: JobId=47375 WEXITSTATUS 0
[2022-08-04T10:24:50.332] _job_complete: JobId=47375 done
[2022-08-04T10:29:07.064] _slurm_rpc_submit_batch_job: JobId=47376 InitPrio=24462 usec=358
[2022-08-04T10:29:07.865] sched: Allocate JobId=47376 NodeList=cpu[12-13] #CPUs=32 Partition=cpu-epyc
[2022-08-04T10:29:57.278] _slurm_rpc_kill_job: REQUEST_KILL_JOB JobId=47376 uid 548200003
[2022-08-04T10:30:19.303] _slurm_rpc_submit_batch_job: JobId=47377 InitPrio=24462 usec=404
[2022-08-04T10:30:19.964] sched: Allocate JobId=47377 NodeList=cpu[12-13] #CPUs=32 Partition=cpu-epyc
[2022-08-04T10:30:33.136] _slurm_rpc_kill_job: REQUEST_KILL_JOB JobId=47377 uid 548200003
[2022-08-04T10:30:58.571] _slurm_rpc_submit_batch_job: JobId=47378 InitPrio=24462 usec=493
[2022-08-04T10:30:59.018] sched: Allocate JobId=47378 NodeList=cpu[12-13] #CPUs=32 Partition=cpu-epyc
[2022-08-04T10:32:40.731] _slurm_rpc_kill_job: REQUEST_KILL_JOB JobId=47378 uid 548200003
[2022-08-04T10:33:55.577] _slurm_rpc_submit_batch_job: JobId=47379 InitPrio=24462 usec=432
[2022-08-04T10:33:56.315] sched: Allocate JobId=47379 NodeList=cpu[12-13] #CPUs=32 Partition=cpu-epyc
[2022-08-04T10:34:19.159] _slurm_rpc_kill_job: REQUEST_KILL_JOB JobId=47379 uid 548200003
[2022-08-04T10:35:00.908] _slurm_rpc_submit_batch_job: JobId=47380 InitPrio=24462 usec=403
[2022-08-04T10:35:01.403] sched: Allocate JobId=47380 NodeList=cpu[12-13] #CPUs=32 Partition=cpu-epyc
[2022-08-04T10:35:05.251] _job_complete: JobId=47380 WEXITSTATUS 16
[2022-08-04T10:35:05.251] _job_complete: JobId=47380 done
[2022-08-04T10:36:58.796] _slurm_rpc_submit_batch_job: JobId=47381 InitPrio=24462 usec=474
[2022-08-04T10:36:59.567] sched: Allocate JobId=47381 NodeList=cpu[12-13] #CPUs=32 Partition=cpu-epyc
[2022-08-04T10:37:30.421] _slurm_rpc_kill_job: REQUEST_KILL_JOB JobId=47381 uid 548200003
[2022-08-04T10:38:19.440] _slurm_rpc_submit_batch_job: JobId=47382 InitPrio=24462 usec=473
[2022-08-04T10:38:19.751] sched: Allocate JobId=47382 NodeList=cpu[12-13] #CPUs=32 Partition=cpu-epyc
[2022-08-04T10:38:28.276] _job_complete: JobId=47382 WEXITSTATUS 0
[2022-08-04T10:38:28.276] _job_complete: JobId=47382 done
[2022-08-04T10:39:37.839] _slurm_rpc_submit_batch_job: JobId=47383 InitPrio=24462 usec=562
[2022-08-04T10:39:37.863] sched: Allocate JobId=47383 NodeList=cpu[12-13] #CPUs=32 Partition=cpu-epyc
[2022-08-04T10:40:29.174] _slurm_rpc_kill_job: REQUEST_KILL_JOB JobId=47383 uid 548200003
[2022-08-04T10:40:54.997] _slurm_rpc_submit_batch_job: JobId=47384 InitPrio=24462 usec=422
[2022-08-04T10:40:55.969] sched: Allocate JobId=47384 NodeList=cpu[12-13] #CPUs=32 Partition=cpu-epyc
[2022-08-04T10:41:51.731] _slurm_rpc_kill_job: REQUEST_KILL_JOB JobId=47384 uid 548200003
[2022-08-04T10:42:39.159] _slurm_rpc_submit_batch_job: JobId=47385 InitPrio=24462 usec=641
[2022-08-04T10:42:39.163] sched: Allocate JobId=47385 NodeList=cpu[12-13] #CPUs=32 Partition=cpu-epyc
[2022-08-04T10:43:29.503] _slurm_rpc_kill_job: REQUEST_KILL_JOB JobId=47385 uid 548200003
[2022-08-04T10:43:34.883] _slurm_rpc_submit_batch_job: JobId=47386 InitPrio=24462 usec=411
[2022-08-04T10:43:35.286] sched: Allocate JobId=47386 NodeList=cpu[12-13] #CPUs=32 Partition=cpu-epyc
[2022-08-04T10:43:39.017] _job_complete: JobId=47386 WEXITSTATUS 200
[2022-08-04T10:43:39.018] _job_complete: JobId=47386 done
[2022-08-04T10:45:14.410] _slurm_rpc_submit_batch_job: JobId=47387 InitPrio=24462 usec=476
[2022-08-04T10:45:14.426] sched: Allocate JobId=47387 NodeList=cpu[12-13] #CPUs=32 Partition=cpu-epyc
[2022-08-04T10:45:39.428] _slurm_rpc_kill_job: REQUEST_KILL_JOB JobId=47387 uid 548200003
[2022-08-04T10:46:14.775] _slurm_rpc_submit_batch_job: JobId=47388 InitPrio=24462 usec=420
[2022-08-04T10:46:15.510] sched: Allocate JobId=47388 NodeList=cpu[12-13] #CPUs=32 Partition=cpu-epyc
[2022-08-04T10:46:32.647] _slurm_rpc_kill_job: REQUEST_KILL_JOB JobId=47388 uid 548200003
[2022-08-04T10:51:09.187] _slurm_rpc_submit_batch_job: JobId=47389 InitPrio=25252 usec=473
[2022-08-04T10:51:10.088] sched: Allocate JobId=47389 NodeList=cpu[14-15] #CPUs=32 Partition=cpu-epyc
[2022-08-04T10:52:51.091] _slurm_rpc_submit_batch_job: JobId=47390 InitPrio=24462 usec=471
[2022-08-04T10:52:51.322] sched: Allocate JobId=47390 NodeList=cpu[12-13] #CPUs=32 Partition=cpu-epyc
[2022-08-04T10:53:08.939] _slurm_rpc_kill_job: REQUEST_KILL_JOB JobId=47390 uid 548200003
[2022-08-04T10:54:44.630] _slurm_rpc_submit_batch_job: JobId=47391 InitPrio=24462 usec=510
[2022-08-04T10:54:45.480] sched: Allocate JobId=47391 NodeList=cpu[12-13] #CPUs=32 Partition=cpu-epyc
[2022-08-04T10:55:00.342] _slurm_rpc_kill_job: REQUEST_KILL_JOB JobId=47391 uid 548200003
[2022-08-04T10:55:33.150] _slurm_rpc_submit_batch_job: JobId=47392 InitPrio=24462 usec=403
[2022-08-04T10:55:33.546] sched: Allocate JobId=47392 NodeList=cpu[12-13] #CPUs=32 Partition=cpu-epyc
[2022-08-04T10:55:57.174] _slurm_rpc_kill_job: REQUEST_KILL_JOB JobId=47392 uid 548200003
[2022-08-04T10:57:17.073] _slurm_rpc_submit_batch_job: JobId=47393 InitPrio=24462 usec=446
[2022-08-04T10:57:17.694] sched: Allocate JobId=47393 NodeList=cpu[12-13] #CPUs=32 Partition=cpu-epyc
[2022-08-04T10:57:18.038] _job_complete: JobId=47393 WEXITSTATUS 127
[2022-08-04T10:57:18.038] _job_complete: JobId=47393 done
[2022-08-04T10:57:22.278] _job_complete: JobId=46763 WEXITSTATUS 0
[2022-08-04T10:57:22.283] _job_complete: JobId=46763 done
[2022-08-04T10:57:24.194] sched: Allocate JobId=46830 NodeList=gpu05 #CPUs=16 Partition=gpu-v100s
[2022-08-04T10:59:34.101] _slurm_rpc_submit_batch_job: JobId=47394 InitPrio=24462 usec=521
[2022-08-04T10:59:35.066] sched: Allocate JobId=47394 NodeList=cpu[12-13] #CPUs=32 Partition=cpu-epyc
[2022-08-04T10:59:47.386] _slurm_rpc_kill_job: REQUEST_KILL_JOB JobId=47394 uid 548200003
[2022-08-04T11:01:06.991] _slurm_rpc_kill_job: REQUEST_KILL_JOB JobId=47394 uid 548200003
[2022-08-04T11:01:40.833] _slurm_rpc_submit_batch_job: JobId=47395 InitPrio=24599 usec=491
[2022-08-04T11:01:41.235] sched: Allocate JobId=47395 NodeList=cpu[12-13] #CPUs=16 Partition=cpu-epyc
[2022-08-04T11:01:45.321] _job_complete: JobId=47395 WEXITSTATUS 200
[2022-08-04T11:01:45.322] _job_complete: JobId=47395 done
[2022-08-04T11:02:09.475] _slurm_rpc_submit_batch_job: JobId=47396 InitPrio=24599 usec=462
[2022-08-04T11:02:10.277] sched: Allocate JobId=47396 NodeList=cpu[12-13] #CPUs=16 Partition=cpu-epyc
[2022-08-04T11:02:14.049] _job_complete: JobId=47396 WEXITSTATUS 200
[2022-08-04T11:02:14.049] _job_complete: JobId=47396 done
[2022-08-04T11:02:31.590] _slurm_rpc_submit_batch_job: JobId=47397 InitPrio=24599 usec=406
[2022-08-04T11:02:32.306] sched: Allocate JobId=47397 NodeList=cpu[12-13] #CPUs=16 Partition=cpu-epyc
[2022-08-04T11:02:57.005] _slurm_rpc_kill_job: REQUEST_KILL_JOB JobId=47397 uid 548200003
[2022-08-04T11:03:47.380] _slurm_rpc_submit_batch_job: JobId=47398 InitPrio=24599 usec=532
[2022-08-04T11:03:47.534] sched: Allocate JobId=47398 NodeList=cpu[12-13] #CPUs=16 Partition=cpu-epyc
[2022-08-04T11:04:00.000] _slurm_rpc_kill_job: REQUEST_KILL_JOB JobId=47398 uid 548200003
[2022-08-04T11:04:17.196] _slurm_rpc_submit_batch_job: JobId=47399 InitPrio=24599 usec=574
[2022-08-04T11:04:17.571] sched: Allocate JobId=47399 NodeList=cpu[12-13] #CPUs=16 Partition=cpu-epyc
[2022-08-04T11:04:55.701] _slurm_rpc_kill_job: REQUEST_KILL_JOB JobId=47399 uid 548200003
[2022-08-04T11:05:42.609] _slurm_rpc_submit_batch_job: JobId=47400 InitPrio=24599 usec=515
[2022-08-04T11:05:42.690] sched: Allocate JobId=47400 NodeList=cpu[12-13] #CPUs=16 Partition=cpu-epyc
[2022-08-04T11:06:11.325] _slurm_rpc_kill_job: REQUEST_KILL_JOB JobId=47400 uid 548200003
[2022-08-04T11:07:08.604] _slurm_rpc_submit_batch_job: JobId=47401 InitPrio=24599 usec=383
[2022-08-04T11:07:08.810] sched: Allocate JobId=47401 NodeList=cpu[12-13] #CPUs=16 Partition=cpu-epyc
[2022-08-04T11:07:28.298] _slurm_rpc_kill_job: REQUEST_KILL_JOB JobId=47401 uid 548200003
[2022-08-04T11:07:41.539] _slurm_rpc_submit_batch_job: JobId=47402 InitPrio=24599 usec=524
[2022-08-04T11:07:42.007] sched: Allocate JobId=47402 NodeList=cpu[12-13] #CPUs=16 Partition=cpu-epyc
[2022-08-04T11:07:46.115] _job_complete: JobId=47402 WEXITSTATUS 200
[2022-08-04T11:07:46.115] _job_complete: JobId=47402 done
[2022-08-04T11:08:05.335] _slurm_rpc_submit_batch_job: JobId=47403 InitPrio=24599 usec=607
[2022-08-04T11:08:07.082] sched: Allocate JobId=47403 NodeList=cpu[12-13] #CPUs=16 Partition=cpu-epyc
[2022-08-04T11:08:11.288] _job_complete: JobId=47403 WEXITSTATUS 200
[2022-08-04T11:08:11.288] _job_complete: JobId=47403 done
[2022-08-04T11:08:28.051] _slurm_rpc_submit_batch_job: JobId=47404 InitPrio=24599 usec=525
[2022-08-04T11:08:28.109] sched: Allocate JobId=47404 NodeList=cpu[12-13] #CPUs=16 Partition=cpu-epyc
[2022-08-04T11:08:57.288] _slurm_rpc_kill_job: REQUEST_KILL_JOB JobId=47404 uid 548200003
[2022-08-04T11:09:10.644] _slurm_rpc_submit_batch_job: JobId=47405 InitPrio=24599 usec=392
[2022-08-04T11:09:11.168] sched: Allocate JobId=47405 NodeList=cpu[12-13] #CPUs=16 Partition=cpu-epyc
[2022-08-04T11:09:16.816] _job_complete: JobId=47405 WEXITSTATUS 0
[2022-08-04T11:09:16.817] _job_complete: JobId=47405 done
[2022-08-04T11:10:53.809] _slurm_rpc_submit_batch_job: JobId=47406 InitPrio=21968 usec=415
[2022-08-04T11:10:54.321] sched: Allocate JobId=47406 NodeList=cpu11 #CPUs=16 Partition=cpu-opteron
[2022-08-04T11:10:56.378] _slurm_rpc_submit_batch_job: JobId=47407 InitPrio=21968 usec=476
[2022-08-04T11:10:59.009] _slurm_rpc_submit_batch_job: JobId=47408 InitPrio=21968 usec=371
[2022-08-04T11:11:01.681] _slurm_rpc_submit_batch_job: JobId=47409 InitPrio=21968 usec=497
[2022-08-04T11:11:04.933] _slurm_rpc_submit_batch_job: JobId=47410 InitPrio=24599 usec=420
[2022-08-04T11:11:07.327] sched: Allocate JobId=47410 NodeList=cpu[12-13] #CPUs=16 Partition=cpu-epyc
[2022-08-04T11:11:18.807] _slurm_rpc_kill_job: REQUEST_KILL_JOB JobId=47410 uid 548200003
[2022-08-04T11:12:06.005] _slurm_rpc_submit_batch_job: JobId=47411 InitPrio=24599 usec=411
[2022-08-04T11:12:07.409] sched: Allocate JobId=47411 NodeList=cpu[12-13] #CPUs=16 Partition=cpu-epyc
[2022-08-04T11:12:09.683] _job_complete: JobId=47411 WEXITSTATUS 0
[2022-08-04T11:12:09.684] _job_complete: JobId=47411 done
[2022-08-04T11:14:41.955] _slurm_rpc_submit_batch_job: JobId=47412 InitPrio=24462 usec=448
[2022-08-04T11:14:42.385] sched/backfill: _start_job: Started JobId=47412 in cpu-epyc on cpu[12-13]
[2022-08-04T11:14:58.434] _slurm_rpc_kill_job: REQUEST_KILL_JOB JobId=47412 uid 548200003
[2022-08-04T11:16:47.852] _slurm_rpc_submit_batch_job: JobId=47413 InitPrio=24462 usec=537
[2022-08-04T11:16:47.942] sched: Allocate JobId=47413 NodeList=cpu[12-13] #CPUs=32 Partition=cpu-epyc
[2022-08-04T11:17:19.784] _slurm_rpc_kill_job: REQUEST_KILL_JOB JobId=47413 uid 548200003
[2022-08-04T11:18:40.381] _slurm_rpc_submit_batch_job: JobId=47414 InitPrio=24668 usec=473
[2022-08-04T11:18:41.273] sched: Allocate JobId=47414 NodeList=cpu[12-13] #CPUs=8 Partition=cpu-epyc
[2022-08-04T11:19:02.990] _slurm_rpc_kill_job: REQUEST_KILL_JOB JobId=47414 uid 548200003
[2022-08-04T11:19:38.895] _slurm_rpc_submit_batch_job: JobId=47415 InitPrio=24668 usec=470
[2022-08-04T11:19:39.353] sched: Allocate JobId=47415 NodeList=cpu[12-13] #CPUs=8 Partition=cpu-epyc
[2022-08-04T11:19:42.926] _job_complete: JobId=47415 WEXITSTATUS 200
[2022-08-04T11:19:42.926] _job_complete: JobId=47415 done
[2022-08-04T11:23:31.549] _slurm_rpc_submit_batch_job: JobId=47416 InitPrio=24668 usec=497
[2022-08-04T11:23:31.807] sched: Allocate JobId=47416 NodeList=cpu[12-13] #CPUs=8 Partition=cpu-epyc
[2022-08-04T11:23:32.171] _job_complete: JobId=47416 WEXITSTATUS 255
[2022-08-04T11:23:32.171] _job_complete: JobId=47416 done
[2022-08-04T11:23:59.047] _slurm_rpc_submit_batch_job: JobId=47417 InitPrio=20057 usec=503
[2022-08-04T11:24:10.981] _slurm_rpc_submit_batch_job: JobId=47418 InitPrio=24668 usec=470
[2022-08-04T11:24:11.864] sched: Allocate JobId=47418 NodeList=cpu[12-13] #CPUs=8 Partition=cpu-epyc
[2022-08-04T11:24:12.193] error: _find_node_record: lookup failure for node "cpu03.dicc.um.edu.my"
[2022-08-04T11:24:12.193] error: node_name2bitmap: invalid node specified: "cpu03.dicc.um.edu.my"
[2022-08-04T11:24:55.632] _slurm_rpc_kill_job: REQUEST_KILL_JOB JobId=47418 uid 548200003
[2022-08-04T11:26:04.954] _slurm_rpc_submit_batch_job: JobId=47419 InitPrio=24668 usec=444
[2022-08-04T11:26:07.025] sched: Allocate JobId=47419 NodeList=cpu[12-13] #CPUs=8 Partition=cpu-epyc
[2022-08-04T11:26:07.386] error: _find_node_record: lookup failure for node "cpu12.dicc.um.edu.my"
[2022-08-04T11:26:07.386] error: node_name2bitmap: invalid node specified: "cpu12.dicc.um.edu.my"
[2022-08-04T11:26:07.386] error: _find_node_record: lookup failure for node "cpu13.dicc.um.edu.my"
[2022-08-04T11:26:07.386] error: node_name2bitmap: invalid node specified: "cpu13.dicc.um.edu.my"
[2022-08-04T11:26:30.334] _slurm_rpc_kill_job: REQUEST_KILL_JOB JobId=47419 uid 548200003
[2022-08-04T11:26:41.352] _slurm_rpc_submit_batch_job: JobId=47420 InitPrio=24668 usec=392
[2022-08-04T11:26:42.074] sched: Allocate JobId=47420 NodeList=cpu[12-13] #CPUs=8 Partition=cpu-epyc
[2022-08-04T11:26:42.373] error: _find_node_record: lookup failure for node "cpu12.dicc.um.edu.my"
[2022-08-04T11:26:42.373] error: node_name2bitmap: invalid node specified: "cpu12.dicc.um.edu.my"
[2022-08-04T11:26:42.373] error: _find_node_record: lookup failure for node "cpu13.dicc.um.edu.my"
[2022-08-04T11:26:42.373] error: node_name2bitmap: invalid node specified: "cpu13.dicc.um.edu.my"
[2022-08-04T11:26:44.921] _slurm_rpc_kill_job: REQUEST_KILL_JOB JobId=47417 uid 548200045
[2022-08-04T11:26:50.628] _slurm_rpc_kill_job: REQUEST_KILL_JOB JobId=47420 uid 548200003
[2022-08-04T11:26:56.780] _slurm_rpc_submit_batch_job: JobId=47421 InitPrio=20126 usec=419
[2022-08-04T11:26:58.837] _slurm_rpc_submit_batch_job: JobId=47422 InitPrio=24668 usec=372
[2022-08-04T11:27:00.097] sched: Allocate JobId=47422 NodeList=cpu[12-13] #CPUs=8 Partition=cpu-epyc
[2022-08-04T11:27:00.403] error: _find_node_record: lookup failure for node "cpu12.dicc.um.edu.my"
[2022-08-04T11:27:00.403] error: node_name2bitmap: invalid node specified: "cpu12.dicc.um.edu.my"
[2022-08-04T11:27:00.403] error: _find_node_record: lookup failure for node "cpu13.dicc.um.edu.my"
[2022-08-04T11:27:00.404] error: node_name2bitmap: invalid node specified: "cpu13.dicc.um.edu.my"
[2022-08-04T11:27:09.705] _slurm_rpc_kill_job: REQUEST_KILL_JOB JobId=47422 uid 548200003
[2022-08-04T11:27:43.780] _slurm_rpc_kill_job: REQUEST_KILL_JOB JobId=47421 uid 548200045
[2022-08-04T11:27:46.570] _slurm_rpc_submit_batch_job: JobId=47423 InitPrio=20126 usec=531
[2022-08-04T11:27:51.533] _slurm_rpc_submit_batch_job: JobId=47424 InitPrio=24668 usec=471
[2022-08-04T11:27:52.254] sched: Allocate JobId=47424 NodeList=cpu[12-13] #CPUs=8 Partition=cpu-epyc
[2022-08-04T11:27:52.552] error: _find_node_record: lookup failure for node "cpu12.dicc.um.edu.my"
[2022-08-04T11:27:52.552] error: node_name2bitmap: invalid node specified: "cpu12.dicc.um.edu.my"
[2022-08-04T11:27:59.966] _slurm_rpc_kill_job: REQUEST_KILL_JOB JobId=47424 uid 548200003
[2022-08-04T11:28:12.186] _slurm_rpc_kill_job: REQUEST_KILL_JOB JobId=47423 uid 548200045
[2022-08-04T11:28:29.351] _slurm_rpc_submit_batch_job: JobId=47425 InitPrio=24668 usec=525
[2022-08-04T11:28:30.307] sched: Allocate JobId=47425 NodeList=cpu[12-13] #CPUs=8 Partition=cpu-epyc
[2022-08-04T11:28:30.602] error: _find_node_record: lookup failure for node "cpu12.dicc.um.edu.my"
[2022-08-04T11:28:30.602] error: node_name2bitmap: invalid node specified: "cpu12.dicc.um.edu.my"
[2022-08-04T11:28:35.505] _slurm_rpc_submit_batch_job: JobId=47426 InitPrio=20057 usec=420
[2022-08-04T11:28:43.058] _slurm_rpc_kill_job: REQUEST_KILL_JOB JobId=47425 uid 548200003
[2022-08-04T11:28:58.286] _slurm_rpc_submit_batch_job: JobId=47427 InitPrio=24668 usec=397
[2022-08-04T11:28:58.347] sched: Allocate JobId=47427 NodeList=cpu[12-13] #CPUs=8 Partition=cpu-epyc
[2022-08-04T11:28:58.780] error: _find_node_record: lookup failure for node "cpu12.dicc.um.edu.my"
[2022-08-04T11:28:58.780] error: node_name2bitmap: invalid node specified: "cpu12.dicc.um.edu.my"
[2022-08-04T11:29:09.432] _slurm_rpc_kill_job: REQUEST_KILL_JOB JobId=47427 uid 548200003
[2022-08-04T11:29:16.166] _slurm_rpc_submit_batch_job: JobId=47428 InitPrio=24668 usec=395
[2022-08-04T11:29:16.373] sched: Allocate JobId=47428 NodeList=cpu[12-13] #CPUs=8 Partition=cpu-epyc
[2022-08-04T11:29:16.788] error: _find_node_record: lookup failure for node "cpu12.dicc.um.edu.my"
[2022-08-04T11:29:16.788] error: node_name2bitmap: invalid node specified: "cpu12.dicc.um.edu.my"
[2022-08-04T11:29:16.788] error: _find_node_record: lookup failure for node "cpu13.dicc.um.edu.my"
[2022-08-04T11:29:16.788] error: node_name2bitmap: invalid node specified: "cpu13.dicc.um.edu.my"
[2022-08-04T11:29:25.443] _slurm_rpc_kill_job: REQUEST_KILL_JOB JobId=47428 uid 548200003
[2022-08-04T11:29:49.978] _slurm_rpc_submit_batch_job: JobId=47429 InitPrio=24668 usec=440
[2022-08-04T11:29:50.420] sched: Allocate JobId=47429 NodeList=cpu[12-13] #CPUs=8 Partition=cpu-epyc
[2022-08-04T11:29:50.743] error: _find_node_record: lookup failure for node "cpu12.dicc.um.edu.my"
[2022-08-04T11:29:50.743] error: node_name2bitmap: invalid node specified: "cpu12.dicc.um.edu.my"
[2022-08-04T11:29:50.743] error: _find_node_record: lookup failure for node "cpu13.dicc.um.edu.my"
[2022-08-04T11:29:50.743] error: node_name2bitmap: invalid node specified: "cpu13.dicc.um.edu.my"
[2022-08-04T11:30:25.288] _slurm_rpc_kill_job: REQUEST_KILL_JOB JobId=47429 uid 548200003
[2022-08-04T11:31:09.625] _slurm_rpc_submit_batch_job: JobId=47430 InitPrio=24668 usec=10102
[2022-08-04T11:31:10.532] sched: Allocate JobId=47430 NodeList=cpu[12-13] #CPUs=8 Partition=cpu-epyc
[2022-08-04T11:31:10.872] error: _find_node_record: lookup failure for node "cpu12.dicc.um.edu.my"
[2022-08-04T11:31:10.872] error: node_name2bitmap: invalid node specified: "cpu12.dicc.um.edu.my"
[2022-08-04T11:31:10.872] error: _find_node_record: lookup failure for node "cpu13.dicc.um.edu.my"
[2022-08-04T11:31:10.872] error: node_name2bitmap: invalid node specified: "cpu13.dicc.um.edu.my"
[2022-08-04T11:31:37.198] _slurm_rpc_kill_job: REQUEST_KILL_JOB JobId=47430 uid 548200003
[2022-08-04T11:31:56.138] _slurm_rpc_submit_batch_job: JobId=47431 InitPrio=24668 usec=422
[2022-08-04T11:31:56.595] sched: Allocate JobId=47431 NodeList=cpu[12-13] #CPUs=8 Partition=cpu-epyc
[2022-08-04T11:32:00.570] _job_complete: JobId=47431 WEXITSTATUS 0
[2022-08-04T11:32:00.570] _job_complete: JobId=47431 done
[2022-08-04T11:32:52.131] _slurm_rpc_submit_batch_job: JobId=47432 InitPrio=25194 usec=469
[2022-08-04T11:32:52.846] sched: Allocate JobId=47432 NodeList=cpu10 #CPUs=8 Partition=cpu-opteron
[2022-08-04T11:34:06.209] _slurm_rpc_kill_job: REQUEST_KILL_JOB JobId=47432 uid 548200003
[2022-08-04T11:34:41.285] _slurm_rpc_submit_batch_job: JobId=47433 InitPrio=24462 usec=530
[2022-08-04T11:34:41.997] sched: Allocate JobId=47433 NodeList=cpu[10-11] #CPUs=32 Partition=cpu-opteron
[2022-08-04T11:35:31.543] _slurm_rpc_kill_job: REQUEST_KILL_JOB JobId=47433 uid 548200003
[2022-08-04T11:36:18.379] _slurm_rpc_submit_batch_job: JobId=47434 InitPrio=24462 usec=501
[2022-08-04T11:36:19.134] sched: Allocate JobId=47434 NodeList=cpu[10-11] #CPUs=32 Partition=cpu-opteron
[2022-08-04T11:36:39.292] _slurm_rpc_kill_job: REQUEST_KILL_JOB JobId=47434 uid 548200003
[2022-08-04T11:37:01.554] _slurm_rpc_submit_batch_job: JobId=47435 InitPrio=24462 usec=434
[2022-08-04T11:37:02.189] sched: Allocate JobId=47435 NodeList=cpu[12-13] #CPUs=32 Partition=cpu-epyc
[2022-08-04T11:37:27.524] _slurm_rpc_kill_job: REQUEST_KILL_JOB JobId=47435 uid 548200003
[2022-08-04T11:41:48.045] _slurm_rpc_submit_batch_job: JobId=47436 InitPrio=24462 usec=431
[2022-08-04T11:41:48.681] sched: Allocate JobId=47436 NodeList=cpu[12-13] #CPUs=32 Partition=cpu-epyc
[2022-08-04T11:45:51.672] _slurm_rpc_kill_job: REQUEST_KILL_JOB JobId=47436 uid 548200003
[2022-08-04T11:46:03.005] _slurm_rpc_submit_batch_job: JobId=47437 InitPrio=24462 usec=402
[2022-08-04T11:46:03.141] sched: Allocate JobId=47437 NodeList=cpu[12-13] #CPUs=32 Partition=cpu-epyc
[2022-08-04T11:50:21.793] _slurm_rpc_kill_job: REQUEST_KILL_JOB JobId=47437 uid 548200003
[2022-08-04T11:50:25.265] _slurm_rpc_submit_batch_job: JobId=47438 InitPrio=24462 usec=542
[2022-08-04T11:50:25.603] sched: Allocate JobId=47438 NodeList=cpu[12-13] #CPUs=32 Partition=cpu-epyc
[2022-08-04T11:50:45.745] _slurm_rpc_kill_job: REQUEST_KILL_JOB JobId=47438 uid 548200003
[2022-08-04T11:51:39.131] sched: _slurm_rpc_allocate_resources JobId=47439 NodeList=(null) usec=648
[2022-08-04T11:51:39.701] sched: Allocate JobId=47439 NodeList=cpu[10-11] #CPUs=8 Partition=cpu-opteron
[2022-08-04T11:52:14.766] _job_complete: JobId=47439 WEXITSTATUS 0
[2022-08-04T11:52:14.766] _job_complete: JobId=47439 done
[2022-08-04T11:52:20.599] sched: _slurm_rpc_allocate_resources JobId=47440 NodeList=(null) usec=802
[2022-08-04T11:52:20.759] sched: Allocate JobId=47440 NodeList=cpu[10-11] #CPUs=8 Partition=cpu-opteron
[2022-08-04T11:55:20.146] _slurm_rpc_submit_batch_job: JobId=47441 InitPrio=24462 usec=480
[2022-08-04T11:55:21.132] sched: Allocate JobId=47441 NodeList=cpu[12-13] #CPUs=32 Partition=cpu-epyc
[2022-08-04T11:55:39.676] _slurm_rpc_kill_job: REQUEST_KILL_JOB JobId=47441 uid 548200003
[2022-08-04T11:57:06.172] _job_complete: JobId=47440 WEXITSTATUS 130
[2022-08-04T11:57:06.172] _job_complete: JobId=47440 done
[2022-08-04T11:57:19.681] _slurm_rpc_submit_batch_job: JobId=47442 InitPrio=24989 usec=428
[2022-08-04T11:57:20.293] sched: Allocate JobId=47442 NodeList=cpu[12-13] #CPUs=32 Partition=cpu-epyc
[2022-08-04T11:57:34.750] _slurm_rpc_kill_job: REQUEST_KILL_JOB JobId=47442 uid 548200003
[2022-08-04T11:57:52.798] _slurm_rpc_submit_batch_job: JobId=47443 InitPrio=24989 usec=534
[2022-08-04T11:57:53.415] sched: Allocate JobId=47443 NodeList=cpu[12-13] #CPUs=32 Partition=cpu-epyc
[2022-08-04T12:00:19.061] _slurm_rpc_kill_job: REQUEST_KILL_JOB JobId=47443 uid 548200003
[2022-08-04T12:02:25.733] _slurm_rpc_submit_batch_job: JobId=47444 InitPrio=24989 usec=496
[2022-08-04T12:02:25.784] sched: Allocate JobId=47444 NodeList=cpu[12-13] #CPUs=32 Partition=cpu-epyc
[2022-08-04T12:02:34.308] _slurm_rpc_kill_job: REQUEST_KILL_JOB JobId=47444 uid 548200003
[2022-08-04T12:02:53.388] _slurm_rpc_submit_batch_job: JobId=47445 InitPrio=25006 usec=450
[2022-08-04T12:02:53.941] sched: Allocate JobId=47445 NodeList=cpu[12-13] #CPUs=30 Partition=cpu-epyc
[2022-08-04T12:03:01.550] _slurm_rpc_kill_job: REQUEST_KILL_JOB JobId=47445 uid 548200003
[2022-08-04T12:07:09.477] _slurm_rpc_submit_batch_job: JobId=47446 InitPrio=25006 usec=484
[2022-08-04T12:07:10.293] sched: Allocate JobId=47446 NodeList=cpu[12-13] #CPUs=30 Partition=cpu-epyc
[2022-08-04T12:07:22.424] _slurm_rpc_kill_job: REQUEST_KILL_JOB JobId=47446 uid 548200003
[2022-08-04T12:10:25.549] _slurm_rpc_submit_batch_job: JobId=47447 InitPrio=25006 usec=397
[2022-08-04T12:10:25.687] sched: Allocate JobId=47447 NodeList=cpu[12-13] #CPUs=30 Partition=cpu-epyc
[2022-08-04T12:10:39.572] _slurm_rpc_kill_job: REQUEST_KILL_JOB JobId=47447 uid 548200003
[2022-08-04T12:11:34.994] _slurm_rpc_submit_batch_job: JobId=47448 InitPrio=25006 usec=412
[2022-08-04T12:11:35.783] sched: Allocate JobId=47448 NodeList=cpu[12-13] #CPUs=30 Partition=cpu-epyc
[2022-08-04T12:11:42.473] _slurm_rpc_kill_job: REQUEST_KILL_JOB JobId=47448 uid 548200003
[2022-08-04T12:13:56.893] _slurm_rpc_submit_batch_job: JobId=47449 InitPrio=25006 usec=427
[2022-08-04T12:13:57.138] sched: Allocate JobId=47449 NodeList=cpu[12-13] #CPUs=30 Partition=cpu-epyc
[2022-08-04T12:14:29.338] _slurm_rpc_kill_job: REQUEST_KILL_JOB JobId=47449 uid 548200003
[2022-08-04T12:16:19.080] _slurm_rpc_kill_job: REQUEST_KILL_JOB JobId=47101 uid 548200023
[2022-08-04T12:18:16.947] _slurm_rpc_submit_batch_job: JobId=47450 InitPrio=25006 usec=514
[2022-08-04T12:18:17.648] sched: Allocate JobId=47450 NodeList=cpu[12-13] #CPUs=30 Partition=cpu-epyc
[2022-08-04T12:18:48.978] _slurm_rpc_kill_job: REQUEST_KILL_JOB JobId=47450 uid 548200003
[2022-08-04T12:19:19.489] _slurm_rpc_submit_batch_job: JobId=47451 InitPrio=25006 usec=428
[2022-08-04T12:19:19.731] sched: Allocate JobId=47451 NodeList=cpu[12-13] #CPUs=30 Partition=cpu-epyc
[2022-08-04T12:43:18.978] _slurm_rpc_submit_batch_job: JobId=47452 InitPrio=23547 usec=492
[2022-08-04T12:47:12.628] _slurm_rpc_submit_batch_job: JobId=47453 InitPrio=23547 usec=471
[2022-08-04T12:55:14.699] _slurm_rpc_submit_batch_job: JobId=47454 InitPrio=23547 usec=534
[2022-08-04T12:57:06.776] _slurm_rpc_submit_batch_job: JobId=47455 InitPrio=23547 usec=472
[2022-08-04T12:59:30.772] _slurm_rpc_kill_job: REQUEST_KILL_JOB JobId=47451 uid 548200003
[2022-08-04T13:08:27.787] _slurm_rpc_submit_batch_job: JobId=47456 InitPrio=24989 usec=483
[2022-08-04T13:08:27.979] sched: Allocate JobId=47456 NodeList=cpu12 #CPUs=32 Partition=cpu-epyc
[2022-08-04T13:08:41.429] _job_complete: JobId=47456 WEXITSTATUS 0
[2022-08-04T13:08:41.429] _job_complete: JobId=47456 done
[2022-08-04T13:10:49.754] _slurm_rpc_submit_batch_job: JobId=47457 InitPrio=24989 usec=505
[2022-08-04T13:10:50.167] sched: Allocate JobId=47457 NodeList=cpu12 #CPUs=32 Partition=cpu-epyc
[2022-08-04T13:11:02.312] _job_complete: JobId=47457 WEXITSTATUS 0
[2022-08-04T13:11:02.312] _job_complete: JobId=47457 done
[2022-08-04T13:11:53.408] _slurm_rpc_submit_batch_job: JobId=47458 InitPrio=24715 usec=478
[2022-08-04T13:12:57.799] _slurm_rpc_kill_job: REQUEST_KILL_JOB JobId=47458 uid 548200003
[2022-08-04T13:16:14.535] _slurm_rpc_submit_batch_job: JobId=47459 InitPrio=24989 usec=434
[2022-08-04T13:16:14.741] sched: Allocate JobId=47459 NodeList=cpu12 #CPUs=32 Partition=cpu-epyc
[2022-08-04T13:16:26.933] _job_complete: JobId=47459 WEXITSTATUS 0
[2022-08-04T13:16:26.933] _job_complete: JobId=47459 done
[2022-08-04T13:18:21.005] _slurm_rpc_kill_job: REQUEST_KILL_JOB JobId=47389 uid 548300543
[2022-08-04T13:20:35.600] _job_complete: JobId=47406 WEXITSTATUS 0
[2022-08-04T13:20:35.600] _job_complete: JobId=47406 done
[2022-08-04T13:20:36.109] sched: Allocate JobId=47452 NodeList=cpu11 #CPUs=16 Partition=cpu-opteron
[2022-08-04T13:21:18.248] _slurm_rpc_submit_batch_job: JobId=47460 InitPrio=25006 usec=391
[2022-08-04T13:21:18.268] sched: Allocate JobId=47460 NodeList=cpu[12-13] #CPUs=30 Partition=cpu-epyc
[2022-08-04T13:21:19.981] _slurm_rpc_submit_batch_job: JobId=47461 InitPrio=24989 usec=529
[2022-08-04T13:21:20.029] _job_complete: JobId=47460 WEXITSTATUS 0
[2022-08-04T13:21:20.029] _job_complete: JobId=47460 done
[2022-08-04T13:21:45.354] _slurm_rpc_kill_job: REQUEST_KILL_JOB JobId=47461 uid 548200003
[2022-08-04T13:22:00.265] _slurm_rpc_submit_batch_job: JobId=47462 InitPrio=25006 usec=434
[2022-08-04T13:22:00.324] sched: Allocate JobId=47462 NodeList=cpu[12-13] #CPUs=30 Partition=cpu-epyc
[2022-08-04T13:22:01.882] _slurm_rpc_submit_batch_job: JobId=47463 InitPrio=24989 usec=685
[2022-08-04T13:22:01.926] _job_complete: JobId=47462 WEXITSTATUS 0
[2022-08-04T13:22:01.926] _job_complete: JobId=47462 done
[2022-08-04T13:23:16.991] _slurm_rpc_kill_job: REQUEST_KILL_JOB JobId=47463 uid 548200003
[2022-08-04T13:23:20.596] _slurm_rpc_submit_batch_job: JobId=47464 InitPrio=25006 usec=488
[2022-08-04T13:23:21.551] sched: Allocate JobId=47464 NodeList=cpu[12-13] #CPUs=30 Partition=cpu-epyc
[2022-08-04T13:23:27.077] _job_complete: JobId=47464 WEXITSTATUS 0
[2022-08-04T13:23:27.077] _job_complete: JobId=47464 done
[2022-08-04T13:24:06.525] _slurm_rpc_submit_batch_job: JobId=47465 InitPrio=25006 usec=405
[2022-08-04T13:24:07.617] sched: Allocate JobId=47465 NodeList=cpu[12-13] #CPUs=30 Partition=cpu-epyc
[2022-08-04T13:26:06.061] _slurm_rpc_kill_job: REQUEST_KILL_JOB JobId=47465 uid 548200003
[2022-08-04T13:27:59.642] _slurm_rpc_submit_batch_job: JobId=47466 InitPrio=24743 usec=478
[2022-08-04T13:28:00.050] sched: Allocate JobId=47466 NodeList=cpu[12-13] #CPUs=30 Partition=cpu-epyc
[2022-08-04T13:28:57.606] _slurm_rpc_kill_job: REQUEST_KILL_JOB JobId=47466 uid 548200003
[2022-08-04T13:30:25.165] _slurm_rpc_submit_batch_job: JobId=47467 InitPrio=24383 usec=457
[2022-08-04T13:31:13.635] _slurm_rpc_kill_job: REQUEST_KILL_JOB JobId=47467 uid 548200003
[2022-08-04T13:31:15.764] _slurm_rpc_submit_batch_job: JobId=47468 InitPrio=22804 usec=490
[2022-08-04T13:31:28.757] update_job_str: invalid JobId=47469
[2022-08-04T13:31:28.757] _slurm_rpc_update_job: JobId=47469 uid=548200003: Invalid job id specified
[2022-08-04T13:31:36.441] _update_job: updating accounting
[2022-08-04T13:31:36.441] _slurm_rpc_update_job: complete JobId=47468 uid=548200003 usec=715
[2022-08-04T13:32:09.004] _pick_best_nodes: JobId=47469 never runnable in partition cpu-epyc
[2022-08-04T13:32:09.004] _slurm_rpc_submit_batch_job: Requested node configuration is not available
[2022-08-04T13:34:20.033] _slurm_rpc_kill_job: REQUEST_KILL_JOB JobId=47468 uid 548200003
[2022-08-04T13:34:28.908] _slurm_rpc_submit_batch_job: JobId=47470 InitPrio=22873 usec=419
[2022-08-04T13:34:39.724] _update_job: updating accounting
[2022-08-04T13:34:39.725] _slurm_rpc_update_job: complete JobId=47470 uid=548200003 usec=786
[2022-08-04T13:37:04.913] _slurm_rpc_delete_reservation complete for biovia_test usec=43
[2022-08-04T13:37:04.921] sched: Created reservation=biovia_test users=jitkang nodes=cpu[12-15] cores=64 licenses=(null) tres=cpu=128 watts=4294967294 start=2022-08-04T13:37:04 end=2023-08-04T13:37:04 MaxStartDelay=
[2022-08-04T13:37:07.900] sched: Allocate JobId=47470 NodeList=cpu[12-15] #CPUs=64 Partition=cpu-epyc
[2022-08-04T13:38:40.854] _slurm_rpc_kill_job: REQUEST_KILL_JOB JobId=47470 uid 548200003
[2022-08-04T13:42:45.843] _slurm_rpc_submit_batch_job: JobId=47471 InitPrio=22873 usec=440
[2022-08-04T13:42:46.635] sched: Allocate JobId=47471 NodeList=cpu[12-15] #CPUs=64 Partition=cpu-epyc
[2022-08-04T13:44:42.549] _slurm_rpc_kill_job: REQUEST_KILL_JOB JobId=47471 uid 548200003
[2022-08-04T13:45:26.834] _slurm_rpc_submit_batch_job: JobId=47472 InitPrio=22873 usec=469
[2022-08-04T13:45:26.860] sched: Allocate JobId=47472 NodeList=cpu[12-15] #CPUs=64 Partition=cpu-epyc
[2022-08-04T14:05:05.031] _job_complete: JobId=47452 WEXITSTATUS 0
[2022-08-04T14:05:05.032] _job_complete: JobId=47452 done
[2022-08-04T14:05:05.512] sched: Allocate JobId=47453 NodeList=cpu11 #CPUs=16 Partition=cpu-opteron
[2022-08-04T14:08:07.945] _slurm_rpc_kill_job: REQUEST_KILL_JOB JobId=47472 uid 548200003
[2022-08-04T14:08:23.131] _slurm_rpc_submit_batch_job: JobId=47473 InitPrio=22873 usec=643
[2022-08-04T14:08:23.386] sched: Allocate JobId=47473 NodeList=cpu[12-15] #CPUs=64 Partition=cpu-epyc
[2022-08-04T14:08:25.539] error: _find_node_record: lookup failure for node "cpu12.dicc.um.edu.my"
[2022-08-04T14:08:25.539] error: node_name2bitmap: invalid node specified: "cpu12.dicc.um.edu.my"
[2022-08-04T14:08:25.539] error: _find_node_record: lookup failure for node "cpu13.dicc.um.edu.my"
[2022-08-04T14:08:25.539] error: node_name2bitmap: invalid node specified: "cpu13.dicc.um.edu.my"
[2022-08-04T14:08:25.539] error: _find_node_record: lookup failure for node "cpu14.dicc.um.edu.my"
[2022-08-04T14:08:25.539] error: node_name2bitmap: invalid node specified: "cpu14.dicc.um.edu.my"
[2022-08-04T14:08:25.539] error: _find_node_record: lookup failure for node "cpu15.dicc.um.edu.my"
[2022-08-04T14:08:25.539] error: node_name2bitmap: invalid node specified: "cpu15.dicc.um.edu.my"
[2022-08-04T14:10:47.743] _slurm_rpc_kill_job: REQUEST_KILL_JOB JobId=47473 uid 548200003
[2022-08-04T14:11:27.300] _slurm_rpc_submit_batch_job: JobId=47474 InitPrio=22873 usec=415
[2022-08-04T14:11:27.628] sched: Allocate JobId=47474 NodeList=cpu[12-15] #CPUs=64 Partition=cpu-epyc
[2022-08-04T14:11:29.769] error: _find_node_record: lookup failure for node "cpu12.dicc.um.edu.my"
[2022-08-04T14:11:29.769] error: node_name2bitmap: invalid node specified: "cpu12.dicc.um.edu.my"
[2022-08-04T14:11:29.769] error: _find_node_record: lookup failure for node "cpu13.dicc.um.edu.my"
[2022-08-04T14:11:29.769] error: node_name2bitmap: invalid node specified: "cpu13.dicc.um.edu.my"
[2022-08-04T14:11:29.769] error: _find_node_record: lookup failure for node "cpu14.dicc.um.edu.my"
[2022-08-04T14:11:29.769] error: node_name2bitmap: invalid node specified: "cpu14.dicc.um.edu.my"
[2022-08-04T14:11:29.769] error: _find_node_record: lookup failure for node "cpu15.dicc.um.edu.my"
[2022-08-04T14:11:29.769] error: node_name2bitmap: invalid node specified: "cpu15.dicc.um.edu.my"
[2022-08-04T14:12:01.987] _slurm_rpc_kill_job: REQUEST_KILL_JOB JobId=47474 uid 548200003
[2022-08-04T14:13:26.670] _slurm_rpc_submit_batch_job: JobId=47475 InitPrio=22873 usec=388
[2022-08-04T14:13:26.956] sched: Allocate JobId=47475 NodeList=cpu[12-15] #CPUs=64 Partition=cpu-epyc
[2022-08-04T14:15:32.453] _slurm_rpc_kill_job: REQUEST_KILL_JOB JobId=47475 uid 548200003
[2022-08-04T14:15:35.355] _slurm_rpc_submit_batch_job: JobId=47476 InitPrio=22873 usec=581
[2022-08-04T14:15:36.132] sched: Allocate JobId=47476 NodeList=cpu[12-15] #CPUs=64 Partition=cpu-epyc
[2022-08-04T14:15:38.327] job_step_signal: JobId=47476 StepId=0 not found
[2022-08-04T14:15:38.328] job_step_signal: JobId=47476 StepId=0 not found
[2022-08-04T14:15:38.328] job_step_signal: JobId=47476 StepId=0 not found
[2022-08-04T14:15:38.328] job_step_signal: JobId=47476 StepId=0 not found
[2022-08-04T14:15:38.328] job_step_signal: JobId=47476 StepId=0 not found
[2022-08-04T14:15:38.328] job_step_signal: JobId=47476 StepId=0 not found
[2022-08-04T14:15:38.328] job_step_signal: JobId=47476 StepId=0 not found
[2022-08-04T14:15:38.329] job_step_signal: JobId=47476 StepId=0 not found
[2022-08-04T14:15:38.329] job_step_signal: JobId=47476 StepId=0 not found
[2022-08-04T14:15:38.329] job_step_signal: JobId=47476 StepId=0 not found
[2022-08-04T14:15:38.329] job_step_signal: JobId=47476 StepId=0 not found
[2022-08-04T14:15:38.329] job_step_signal: JobId=47476 StepId=0 not found
[2022-08-04T14:15:38.329] job_step_signal: JobId=47476 StepId=0 not found
[2022-08-04T14:15:38.329] job_step_signal: JobId=47476 StepId=0 not found
[2022-08-04T14:15:38.330] job_step_signal: JobId=47476 StepId=0 not found
[2022-08-04T14:15:38.330] job_step_signal: JobId=47476 StepId=0 not found
[2022-08-04T14:15:38.697] job_step_signal: JobId=47476 StepId=0 not found
[2022-08-04T14:15:38.697] job_step_signal: JobId=47476 StepId=0 not found
[2022-08-04T14:15:38.697] job_step_signal: JobId=47476 StepId=0 not found
[2022-08-04T14:15:38.697] job_step_signal: JobId=47476 StepId=0 not found
[2022-08-04T14:15:38.698] job_step_signal: JobId=47476 StepId=0 not found
[2022-08-04T14:15:38.698] job_step_signal: JobId=47476 StepId=0 not found
[2022-08-04T14:15:38.698] job_step_signal: JobId=47476 StepId=0 not found
[2022-08-04T14:15:38.699] job_step_signal: JobId=47476 StepId=0 not found
[2022-08-04T14:15:38.699] job_step_signal: JobId=47476 StepId=0 not found
[2022-08-04T14:15:38.699] job_step_signal: JobId=47476 StepId=0 not found
[2022-08-04T14:15:38.699] job_step_signal: JobId=47476 StepId=0 not found
[2022-08-04T14:15:38.699] job_step_signal: JobId=47476 StepId=0 not found
[2022-08-04T14:15:38.699] job_step_signal: JobId=47476 StepId=0 not found
[2022-08-04T14:15:38.700] job_step_signal: JobId=47476 StepId=0 not found
[2022-08-04T14:15:38.700] job_step_signal: JobId=47476 StepId=0 not found
[2022-08-04T14:15:38.703] job_step_signal: JobId=47476 StepId=0 not found
[2022-08-04T14:15:38.740] job_step_signal: JobId=47476 StepId=0 not found
[2022-08-04T14:15:38.741] job_step_signal: JobId=47476 StepId=0 not found
[2022-08-04T14:15:38.741] job_step_signal: JobId=47476 StepId=0 not found
[2022-08-04T14:15:38.741] job_step_signal: JobId=47476 StepId=0 not found
[2022-08-04T14:15:38.741] job_step_signal: JobId=47476 StepId=0 not found
[2022-08-04T14:15:38.742] job_step_signal: JobId=47476 StepId=0 not found
[2022-08-04T14:15:38.742] job_step_signal: JobId=47476 StepId=0 not found
[2022-08-04T14:15:38.742] job_step_signal: JobId=47476 StepId=0 not found
[2022-08-04T14:15:38.742] job_step_signal: JobId=47476 StepId=0 not found
[2022-08-04T14:15:38.742] job_step_signal: JobId=47476 StepId=0 not found
[2022-08-04T14:15:38.742] job_step_signal: JobId=47476 StepId=0 not found
[2022-08-04T14:15:38.742] job_step_signal: JobId=47476 StepId=0 not found
[2022-08-04T14:15:38.743] job_step_signal: JobId=47476 StepId=0 not found
[2022-08-04T14:15:38.743] job_step_signal: JobId=47476 StepId=0 not found
[2022-08-04T14:15:38.744] job_step_signal: JobId=47476 StepId=0 not found
[2022-08-04T14:15:38.744] job_step_signal: JobId=47476 StepId=0 not found
[2022-08-04T14:15:38.763] job_step_signal: JobId=47476 StepId=0 not found
[2022-08-04T14:15:38.763] job_step_signal: JobId=47476 StepId=0 not found
[2022-08-04T14:15:38.764] job_step_signal: JobId=47476 StepId=0 not found
[2022-08-04T14:15:38.764] job_step_signal: JobId=47476 StepId=0 not found
[2022-08-04T14:15:38.764] job_step_signal: JobId=47476 StepId=0 not found
[2022-08-04T14:15:38.764] job_step_signal: JobId=47476 StepId=0 not found
[2022-08-04T14:15:38.764] job_step_signal: JobId=47476 StepId=0 not found
[2022-08-04T14:15:38.764] job_step_signal: JobId=47476 StepId=0 not found
[2022-08-04T14:15:38.764] job_step_signal: JobId=47476 StepId=0 not found
[2022-08-04T14:15:38.765] job_step_signal: JobId=47476 StepId=0 not found
[2022-08-04T14:15:38.765] job_step_signal: JobId=47476 StepId=0 not found
[2022-08-04T14:15:38.765] job_step_signal: JobId=47476 StepId=0 not found
[2022-08-04T14:15:38.765] job_step_signal: JobId=47476 StepId=0 not found
[2022-08-04T14:15:38.765] job_step_signal: JobId=47476 StepId=0 not found
[2022-08-04T14:15:38.765] job_step_signal: JobId=47476 StepId=0 not found
[2022-08-04T14:15:38.766] job_step_signal: JobId=47476 StepId=0 not found
[2022-08-04T14:15:40.977] _job_complete: JobId=47476 WEXITSTATUS 0
[2022-08-04T14:15:40.977] _job_complete: JobId=47476 done
[2022-08-04T14:18:27.049] Reservation biovia_test request overlaps jobs
[2022-08-04T14:18:27.049] _slurm_rpc_resv_update reservation=biovia_test: Requested nodes are busy
[2022-08-04T14:18:31.092] Reservation biovia_test request overlaps jobs
[2022-08-04T14:18:31.092] _slurm_rpc_resv_update reservation=biovia_test: Requested nodes are busy
[2022-08-04T14:18:52.953] _slurm_rpc_delete_reservation complete for biovia_test usec=53
[2022-08-04T14:18:52.961] sched: Created reservation=biovia_test users=jitkang,testuser,yeehengteh nodes=cpu[12-15] cores=64 licenses=(null) tres=cpu=128 watts=4294967294 start=2022-08-04T14:18:52 end=2023-08-04T14:18:52 MaxStartDelay=
[2022-08-04T14:19:17.357] _slurm_rpc_submit_batch_job: JobId=47477 InitPrio=66820 usec=531
[2022-08-04T14:19:17.560] sched: Allocate JobId=47477 NodeList=cpu[12-15] #CPUs=64 Partition=cpu-epyc
[2022-08-04T14:19:38.163] _slurm_rpc_kill_job: REQUEST_KILL_JOB JobId=47326 uid 548200019
[2022-08-04T14:20:00.983] _slurm_rpc_submit_batch_job: JobId=47478 InitPrio=21110 usec=571
[2022-08-04T14:21:32.279] _slurm_rpc_kill_job: REQUEST_KILL_JOB JobId=47477 uid 548200005
[2022-08-04T14:22:16.451] _slurm_rpc_submit_batch_job: JobId=47479 InitPrio=66557 usec=435
[2022-08-04T14:22:16.794] sched: Allocate JobId=47479 NodeList=cpu[12-15] #CPUs=64 Partition=cpu-epyc
[2022-08-04T14:23:25.427] _slurm_rpc_kill_job: REQUEST_KILL_JOB JobId=47479 uid 548200005
[2022-08-04T14:23:59.612] _slurm_rpc_submit_batch_job: JobId=47480 InitPrio=66557 usec=477
[2022-08-04T14:24:00.050] sched: Allocate JobId=47480 NodeList=cpu[12-15] #CPUs=64 Partition=cpu-epyc
[2022-08-04T14:24:02.267] error: _find_node_record: lookup failure for node "cpu12.dicc.um.edu.my"
[2022-08-04T14:24:02.267] error: node_name2bitmap: invalid node specified: "cpu12.dicc.um.edu.my"
[2022-08-04T14:24:02.267] error: _find_node_record: lookup failure for node "cpu13.dicc.um.edu.my"
[2022-08-04T14:24:02.267] error: node_name2bitmap: invalid node specified: "cpu13.dicc.um.edu.my"
[2022-08-04T14:24:02.267] error: _find_node_record: lookup failure for node "cpu14.dicc.um.edu.my"
[2022-08-04T14:24:02.267] error: node_name2bitmap: invalid node specified: "cpu14.dicc.um.edu.my"
[2022-08-04T14:24:02.267] error: _find_node_record: lookup failure for node "cpu15.dicc.um.edu.my"
[2022-08-04T14:24:02.267] error: node_name2bitmap: invalid node specified: "cpu15.dicc.um.edu.my"
[2022-08-04T14:24:13.472] _slurm_rpc_kill_job: REQUEST_KILL_JOB JobId=47480 uid 548200005
[2022-08-04T14:25:32.549] _slurm_rpc_submit_batch_job: JobId=47481 InitPrio=66557 usec=593
[2022-08-04T14:25:33.178] sched: Allocate JobId=47481 NodeList=cpu[12-15] #CPUs=64 Partition=cpu-epyc
[2022-08-04T14:25:35.758] error: _find_node_record: lookup failure for node "cpu12.dicc.um.edu.my"
[2022-08-04T14:25:35.758] error: node_name2bitmap: invalid node specified: "cpu12.dicc.um.edu.my"
[2022-08-04T14:25:35.758] error: _find_node_record: lookup failure for node "cpu13.dicc.um.edu.my"
[2022-08-04T14:25:35.758] error: node_name2bitmap: invalid node specified: "cpu13.dicc.um.edu.my"
[2022-08-04T14:25:35.758] error: _find_node_record: lookup failure for node "cpu14.dicc.um.edu.my"
[2022-08-04T14:25:35.758] error: node_name2bitmap: invalid node specified: "cpu14.dicc.um.edu.my"
[2022-08-04T14:25:35.758] error: _find_node_record: lookup failure for node "cpu15.dicc.um.edu.my"
[2022-08-04T14:25:35.758] error: node_name2bitmap: invalid node specified: "cpu15.dicc.um.edu.my"
[2022-08-04T14:25:35.758] error: _find_node_record: lookup failure for node "cpu12.dicc.um.edu.my"
[2022-08-04T14:25:35.758] error: node_name2bitmap: invalid node specified: "cpu12.dicc.um.edu.my"
[2022-08-04T14:25:35.758] error: _find_node_record: lookup failure for node "cpu13.dicc.um.edu.my"
[2022-08-04T14:25:35.758] error: node_name2bitmap: invalid node specified: "cpu13.dicc.um.edu.my"
[2022-08-04T14:25:35.758] error: _find_node_record: lookup failure for node "cpu14.dicc.um.edu.my"
[2022-08-04T14:25:35.758] error: node_name2bitmap: invalid node specified: "cpu14.dicc.um.edu.my"
[2022-08-04T14:25:35.758] error: _find_node_record: lookup failure for node "cpu15.dicc.um.edu.my"
[2022-08-04T14:25:35.758] error: node_name2bitmap: invalid node specified: "cpu15.dicc.um.edu.my"
[2022-08-04T14:25:35.928] error: _find_node_record: lookup failure for node "cpu12.dicc.um.edu.my"
[2022-08-04T14:25:35.928] error: node_name2bitmap: invalid node specified: "cpu12.dicc.um.edu.my"
[2022-08-04T14:25:35.928] error: _find_node_record: lookup failure for node "cpu13.dicc.um.edu.my"
[2022-08-04T14:25:35.928] error: node_name2bitmap: invalid node specified: "cpu13.dicc.um.edu.my"
[2022-08-04T14:25:35.928] error: _find_node_record: lookup failure for node "cpu14.dicc.um.edu.my"
[2022-08-04T14:25:35.928] error: node_name2bitmap: invalid node specified: "cpu14.dicc.um.edu.my"
[2022-08-04T14:25:35.928] error: _find_node_record: lookup failure for node "cpu15.dicc.um.edu.my"
[2022-08-04T14:25:35.928] error: node_name2bitmap: invalid node specified: "cpu15.dicc.um.edu.my"
[2022-08-04T14:25:35.928] error: _find_node_record: lookup failure for node "cpu12.dicc.um.edu.my"
[2022-08-04T14:25:35.928] error: node_name2bitmap: invalid node specified: "cpu12.dicc.um.edu.my"
[2022-08-04T14:25:35.928] error: _find_node_record: lookup failure for node "cpu13.dicc.um.edu.my"
[2022-08-04T14:25:35.928] error: node_name2bitmap: invalid node specified: "cpu13.dicc.um.edu.my"
[2022-08-04T14:25:35.928] error: _find_node_record: lookup failure for node "cpu14.dicc.um.edu.my"
[2022-08-04T14:25:35.928] error: node_name2bitmap: invalid node specified: "cpu14.dicc.um.edu.my"
[2022-08-04T14:25:35.928] error: _find_node_record: lookup failure for node "cpu15.dicc.um.edu.my"
[2022-08-04T14:25:35.928] error: node_name2bitmap: invalid node specified: "cpu15.dicc.um.edu.my"
[2022-08-04T14:25:35.928] error: _find_node_record: lookup failure for node "cpu12.dicc.um.edu.my"
[2022-08-04T14:25:35.928] error: node_name2bitmap: invalid node specified: "cpu12.dicc.um.edu.my"
[2022-08-04T14:25:35.928] error: _find_node_record: lookup failure for node "cpu13.dicc.um.edu.my"
[2022-08-04T14:25:35.928] error: node_name2bitmap: invalid node specified: "cpu13.dicc.um.edu.my"
[2022-08-04T14:25:35.928] error: _find_node_record: lookup failure for node "cpu14.dicc.um.edu.my"
[2022-08-04T14:25:35.928] error: node_name2bitmap: invalid node specified: "cpu14.dicc.um.edu.my"
[2022-08-04T14:25:35.928] error: _find_node_record: lookup failure for node "cpu15.dicc.um.edu.my"
[2022-08-04T14:25:35.928] error: node_name2bitmap: invalid node specified: "cpu15.dicc.um.edu.my"
[2022-08-04T14:25:35.937] error: _find_node_record: lookup failure for node "cpu12.dicc.um.edu.my"
[2022-08-04T14:25:35.938] error: node_name2bitmap: invalid node specified: "cpu12.dicc.um.edu.my"
[2022-08-04T14:25:35.938] error: _find_node_record: lookup failure for node "cpu13.dicc.um.edu.my"
[2022-08-04T14:25:35.938] error: node_name2bitmap: invalid node specified: "cpu13.dicc.um.edu.my"
[2022-08-04T14:25:35.938] error: _find_node_record: lookup failure for node "cpu14.dicc.um.edu.my"
[2022-08-04T14:25:35.938] error: node_name2bitmap: invalid node specified: "cpu14.dicc.um.edu.my"
[2022-08-04T14:25:35.938] error: _find_node_record: lookup failure for node "cpu15.dicc.um.edu.my"
[2022-08-04T14:25:35.938] error: node_name2bitmap: invalid node specified: "cpu15.dicc.um.edu.my"
[2022-08-04T14:25:52.817] _slurm_rpc_kill_job: REQUEST_KILL_JOB JobId=47481 uid 548200005
[2022-08-04T14:26:27.044] _slurm_rpc_submit_batch_job: JobId=47482 InitPrio=66557 usec=388
[2022-08-04T14:26:27.254] sched: Allocate JobId=47482 NodeList=cpu[12-15] #CPUs=64 Partition=cpu-epyc
[2022-08-04T14:26:31.703] _job_complete: JobId=47482 WEXITSTATUS 0
[2022-08-04T14:26:31.704] _job_complete: JobId=47482 done
[2022-08-04T14:27:30.171] _slurm_rpc_submit_batch_job: JobId=47483 InitPrio=66557 usec=463
[2022-08-04T14:27:30.342] sched: Allocate JobId=47483 NodeList=cpu[12-15] #CPUs=64 Partition=cpu-epyc
[2022-08-04T14:28:13.455] _slurm_rpc_kill_job: REQUEST_KILL_JOB JobId=47483 uid 548200005
[2022-08-04T14:31:07.561] _slurm_rpc_submit_batch_job: JobId=47484 InitPrio=66557 usec=449
[2022-08-04T14:31:07.729] sched: Allocate JobId=47484 NodeList=cpu[12-15] #CPUs=64 Partition=cpu-epyc
[2022-08-04T14:31:12.227] _job_complete: JobId=47484 WEXITSTATUS 0
[2022-08-04T14:31:12.227] _job_complete: JobId=47484 done
[2022-08-04T14:54:24.303] _slurm_rpc_submit_batch_job: JobId=47485 InitPrio=66557 usec=565
[2022-08-04T14:54:25.116] sched: Allocate JobId=47485 NodeList=cpu[12-15] #CPUs=64 Partition=cpu-epyc
[2022-08-04T14:54:28.239] _job_complete: JobId=47485 WEXITSTATUS 0
[2022-08-04T14:54:28.239] _job_complete: JobId=47485 done
[2022-08-04T14:54:33.160] _slurm_rpc_submit_batch_job: JobId=47486 InitPrio=25720 usec=420
[2022-08-04T14:54:34.141] sched: Allocate JobId=47486 NodeList=cpu12 #CPUs=8 Partition=cpu-epyc
[2022-08-04T14:54:38.498] _job_complete: JobId=47486 WEXITSTATUS 0
[2022-08-04T14:54:38.498] _job_complete: JobId=47486 done
[2022-08-04T14:54:51.353] _slurm_rpc_submit_batch_job: JobId=47487 InitPrio=67346 usec=358
[2022-08-04T14:55:40.048] _slurm_rpc_submit_batch_job: JobId=47488 InitPrio=22873 usec=468
[2022-08-04T14:55:40.221] sched: Allocate JobId=47488 NodeList=cpu[12-15] #CPUs=64 Partition=cpu-epyc
[2022-08-04T14:55:52.897] _slurm_rpc_kill_job: REQUEST_KILL_JOB JobId=47487 uid 548200003
[2022-08-04T14:58:17.214] _slurm_rpc_submit_batch_job: JobId=47489 InitPrio=25720 usec=495
[2022-08-04T14:58:17.570] sched: Allocate JobId=47489 NodeList=cpu14 #CPUs=8 Partition=cpu-epyc
[2022-08-04T14:58:24.112] _job_complete: JobId=47489 WEXITSTATUS 0
[2022-08-04T14:58:24.112] _job_complete: JobId=47489 done
[2022-08-04T15:02:39.145] _job_complete: JobId=47453 WEXITSTATUS 0
[2022-08-04T15:02:39.145] _job_complete: JobId=47453 done
[2022-08-04T15:02:39.732] sched: Allocate JobId=47454 NodeList=cpu11 #CPUs=16 Partition=cpu-opteron
[2022-08-04T15:22:51.426] _job_complete: JobId=47454 WEXITSTATUS 1
[2022-08-04T15:22:51.426] _job_complete: JobId=47454 done
[2022-08-04T15:22:51.989] sched: Allocate JobId=47455 NodeList=cpu11 #CPUs=16 Partition=cpu-opteron
[2022-08-04T16:17:59.002] _slurm_rpc_submit_batch_job: JobId=47490 InitPrio=25720 usec=482
[2022-08-04T16:17:59.189] sched: Allocate JobId=47490 NodeList=cpu09 #CPUs=8 Partition=cpu-opteron
[2022-08-04T16:18:09.590] _job_complete: JobId=47490 WEXITSTATUS 0
[2022-08-04T16:18:09.590] _job_complete: JobId=47490 done
[2022-08-04T16:21:16.650] _slurm_rpc_submit_batch_job: JobId=47491 InitPrio=25720 usec=443
[2022-08-04T16:21:17.468] sched: Allocate JobId=47491 NodeList=cpu09 #CPUs=8 Partition=cpu-opteron
[2022-08-04T16:21:21.567] _job_complete: JobId=47491 WEXITSTATUS 0
[2022-08-04T16:21:21.567] _job_complete: JobId=47491 done
[2022-08-04T16:24:09.859] _slurm_rpc_submit_batch_job: JobId=47492 InitPrio=25720 usec=445
[2022-08-04T16:24:10.848] sched: Allocate JobId=47492 NodeList=cpu09 #CPUs=8 Partition=cpu-opteron
[2022-08-04T16:24:14.768] _job_complete: JobId=47492 WEXITSTATUS 0
[2022-08-04T16:24:14.768] _job_complete: JobId=47492 done
[2022-08-04T16:25:09.420] _slurm_rpc_submit_batch_job: JobId=47493 InitPrio=25720 usec=464
[2022-08-04T16:25:09.932] sched: Allocate JobId=47493 NodeList=cpu09 #CPUs=8 Partition=cpu-opteron
[2022-08-04T16:25:13.542] _job_complete: JobId=47493 WEXITSTATUS 0
[2022-08-04T16:25:13.542] _job_complete: JobId=47493 done
[2022-08-04T16:28:19.337] _slurm_rpc_submit_batch_job: JobId=47494 InitPrio=25720 usec=388
[2022-08-04T16:28:20.294] sched: Allocate JobId=47494 NodeList=cpu09 #CPUs=8 Partition=cpu-opteron
[2022-08-04T16:28:29.099] _job_complete: JobId=47494 WEXITSTATUS 0
[2022-08-04T16:28:29.099] _job_complete: JobId=47494 done
[2022-08-04T17:27:02.989] _slurm_rpc_submit_batch_job: JobId=47495 InitPrio=21824 usec=481
[2022-08-04T17:27:25.971] _slurm_rpc_kill_job: REQUEST_KILL_JOB JobId=47495 uid 548200023
[2022-08-04T17:29:12.727] _slurm_rpc_submit_batch_job: JobId=47496 InitPrio=21807 usec=519
[2022-08-04T17:29:13.106] sched: Allocate JobId=47496 NodeList=gpu01 #CPUs=4 Partition=gpu-k10
[2022-08-04T17:29:22.831] _job_complete: JobId=47496 WEXITSTATUS 21
[2022-08-04T17:29:22.831] _job_complete: JobId=47496 done
[2022-08-04T17:31:41.555] _slurm_rpc_submit_batch_job: JobId=47497 InitPrio=21807 usec=517
[2022-08-04T17:31:42.297] sched: Allocate JobId=47497 NodeList=gpu01 #CPUs=4 Partition=gpu-k10
[2022-08-04T17:31:55.372] _job_complete: JobId=47497 WEXITSTATUS 0
[2022-08-04T17:31:55.373] _job_complete: JobId=47497 done
[2022-08-04T17:34:44.291] _slurm_rpc_submit_batch_job: JobId=47498 InitPrio=21824 usec=498
[2022-08-04T17:34:44.641] sched: Allocate JobId=47498 NodeList=gpu02 #CPUs=2 Partition=gpu-titan
[2022-08-04T17:35:35.425] _job_complete: JobId=47498 WEXITSTATUS 0
[2022-08-04T17:35:35.425] _job_complete: JobId=47498 done
[2022-08-04T17:38:17.017] _slurm_rpc_submit_batch_job: JobId=47499 InitPrio=21807 usec=425
[2022-08-04T17:38:17.041] sched: Allocate JobId=47499 NodeList=gpu01 #CPUs=4 Partition=gpu-k10
[2022-08-04T17:38:19.780] _job_complete: JobId=47499 WEXITSTATUS 0
[2022-08-04T17:38:19.780] _job_complete: JobId=47499 done
[2022-08-04T17:42:50.314] _job_complete: JobId=46942 OOM failure
[2022-08-04T17:42:50.315] _job_complete: JobId=46942 done
[2022-08-04T17:42:50.564] sched: Allocate JobId=46943 NodeList=cpu12 #CPUs=32 Partition=cpu-epyc
[2022-08-04T17:46:37.931] _job_complete: JobId=47488 WEXITSTATUS 0
[2022-08-04T17:46:37.931] _job_complete: JobId=47488 done
[2022-08-04T17:56:21.289] _slurm_rpc_submit_batch_job: JobId=47500 InitPrio=21247 usec=465
[2022-08-04T17:56:43.406] sched/backfill: _start_job: Started JobId=47500 in cpu-opteron on cpu[09-10]
[2022-08-04T17:56:49.799] _slurm_rpc_kill_job: REQUEST_KILL_JOB JobId=47500 uid 548200023
[2022-08-04T17:57:54.352] _slurm_rpc_submit_batch_job: JobId=47501 InitPrio=21247 usec=506
[2022-08-04T17:58:43.411] sched/backfill: _start_job: Started JobId=47501 in cpu-opteron on cpu[09-10]
[2022-08-04T18:00:23.962] _job_complete: JobId=47501 WEXITSTATUS 1
[2022-08-04T18:00:23.962] _job_complete: JobId=47501 done
[2022-08-04T18:04:45.545] _slurm_rpc_submit_batch_job: JobId=47502 InitPrio=21178 usec=435
[2022-08-04T18:05:43.429] sched/backfill: _start_job: Started JobId=47502 in cpu-opteron on cpu[09-10]
[2022-08-04T18:09:47.689] _job_complete: JobId=47502 WEXITSTATUS 1
[2022-08-04T18:09:47.689] _job_complete: JobId=47502 done
[2022-08-04T18:11:31.221] _slurm_rpc_submit_batch_job: JobId=47503 InitPrio=21773 usec=402
[2022-08-04T18:11:43.447] sched/backfill: _start_job: Started JobId=47503 in cpu-opteron on cpu09
[2022-08-04T18:14:09.039] _job_complete: JobId=47503 WEXITSTATUS 1
[2022-08-04T18:14:09.039] _job_complete: JobId=47503 done
[2022-08-04T18:31:43.041] _slurm_rpc_submit_batch_job: JobId=47504 InitPrio=68284 usec=490
[2022-08-04T18:43:09.234] _slurm_rpc_submit_batch_job: JobId=47505 InitPrio=68284 usec=507
[2022-08-04T18:49:22.271] _slurm_rpc_submit_batch_job: JobId=47506 InitPrio=21705 usec=456
[2022-08-04T18:50:50.903] _slurm_rpc_kill_job: REQUEST_KILL_JOB JobId=47506 uid 548200023
[2022-08-04T18:51:13.529] _slurm_rpc_submit_batch_job: JobId=47507 InitPrio=21773 usec=454
[2022-08-04T18:51:43.553] sched/backfill: _start_job: Started JobId=47507 in cpu-opteron on cpu10
[2022-08-04T18:52:44.719] _job_complete: JobId=47507 WEXITSTATUS 1
[2022-08-04T18:52:44.719] _job_complete: JobId=47507 done
[2022-08-04T19:06:49.745] _job_complete: JobId=46943 WEXITSTATUS 1
[2022-08-04T19:06:49.745] _job_complete: JobId=46943 done
[2022-08-04T19:06:50.616] sched: Allocate JobId=46944 NodeList=cpu12 #CPUs=32 Partition=cpu-epyc
[2022-08-04T19:19:13.107] _slurm_rpc_submit_batch_job: JobId=47508 InitPrio=21247 usec=502
[2022-08-04T19:19:58.152] _slurm_rpc_kill_job: REQUEST_KILL_JOB JobId=47508 uid 548200023
[2022-08-04T19:20:45.876] _slurm_rpc_submit_batch_job: JobId=47509 InitPrio=21247 usec=524
[2022-08-04T19:21:43.639] sched/backfill: _start_job: Started JobId=47509 in cpu-opteron on cpu[09-10]
[2022-08-04T19:24:02.555] _job_complete: JobId=47509 WEXITSTATUS 1
[2022-08-04T19:24:02.555] _job_complete: JobId=47509 done
[2022-08-04T19:27:31.084] _slurm_rpc_submit_batch_job: JobId=47510 InitPrio=20904 usec=455
[2022-08-04T19:31:45.321] _slurm_rpc_submit_batch_job: JobId=47511 InitPrio=21247 usec=603
[2022-08-04T19:32:43.675] sched/backfill: _start_job: Started JobId=47511 in cpu-opteron on cpu[09-10]
[2022-08-04T19:34:11.317] _job_complete: JobId=47511 WEXITSTATUS 1
[2022-08-04T19:34:11.318] _job_complete: JobId=47511 done
[2022-08-04T19:59:35.291] _slurm_rpc_submit_batch_job: JobId=47512 InitPrio=21247 usec=534
[2022-08-04T19:59:43.762] sched/backfill: _start_job: Started JobId=47512 in cpu-opteron on cpu[09-10]
[2022-08-04T20:01:31.487] _job_complete: JobId=47512 WEXITSTATUS 1
[2022-08-04T20:01:31.487] _job_complete: JobId=47512 done
[2022-08-04T20:07:37.814] _job_complete: JobId=47246 WEXITSTATUS 0
[2022-08-04T20:07:37.814] _job_complete: JobId=47246 done
[2022-08-04T20:07:39.973] sched: Allocate JobId=47407 NodeList=cpu09 #CPUs=16 Partition=cpu-opteron
[2022-08-04T20:07:39.974] sched: Allocate JobId=47408 NodeList=cpu09 #CPUs=16 Partition=cpu-opteron
[2022-08-04T20:16:45.784] _slurm_rpc_submit_batch_job: JobId=47513 InitPrio=21247 usec=459
[2022-08-04T20:18:06.268] _slurm_rpc_kill_job: REQUEST_KILL_JOB JobId=47513 uid 548200023
[2022-08-04T20:18:26.423] _slurm_rpc_submit_batch_job: JobId=47514 InitPrio=21247 usec=424
[2022-08-04T22:29:48.839] _job_complete: JobId=47408 WEXITSTATUS 0
[2022-08-04T22:29:48.839] _job_complete: JobId=47408 done
[2022-08-04T22:29:49.379] sched: Allocate JobId=47409 NodeList=cpu09 #CPUs=16 Partition=cpu-opteron
[2022-08-04T22:37:57.174] _job_complete: JobId=47407 WEXITSTATUS 0
[2022-08-04T22:37:57.175] _job_complete: JobId=47407 done
[2022-08-04T23:22:32.284] _slurm_rpc_submit_batch_job: JobId=47515 InitPrio=21568 usec=544
[2022-08-05T00:05:40.145] _slurm_rpc_submit_batch_job: JobId=47516 InitPrio=21441 usec=451
[2022-08-05T00:22:45.944] _slurm_rpc_submit_batch_job: JobId=47517 InitPrio=20504 usec=436
[2022-08-05T00:25:38.687] _slurm_rpc_submit_batch_job: JobId=47518 InitPrio=20915 usec=435
[2022-08-05T00:39:58.755] _job_complete: JobId=47409 WEXITSTATUS 0
[2022-08-05T00:39:58.755] _job_complete: JobId=47409 done
[2022-08-05T00:39:59.208] sched: Allocate JobId=47515 NodeList=cpu09 #CPUs=32 Partition=cpu-opteron
[2022-08-05T00:41:10.457] _job_complete: JobId=47515 WEXITSTATUS 1
[2022-08-05T00:41:10.457] _job_complete: JobId=47515 done
[2022-08-05T00:41:10.910] sched: Allocate JobId=47478 NodeList=cpu09 #CPUs=24 Partition=cpu-opteron
[2022-08-05T00:41:10.911] sched: Allocate JobId=47514 NodeList=cpu[09-10] #CPUs=8 Partition=cpu-opteron
[2022-08-05T00:44:58.545] _job_complete: JobId=47514 WEXITSTATUS 1
[2022-08-05T00:44:58.546] _job_complete: JobId=47514 done
[2022-08-05T00:46:01.684] _slurm_rpc_submit_batch_job: JobId=47519 InitPrio=20984 usec=630
[2022-08-05T00:46:44.438] sched/backfill: _start_job: Started JobId=47519 in cpu-opteron on cpu09
[2022-08-05T00:46:48.962] _slurm_rpc_submit_batch_job: JobId=47520 InitPrio=20915 usec=471
[2022-08-05T00:47:00.705] _job_complete: JobId=47519 WEXITSTATUS 1
[2022-08-05T00:47:00.705] _job_complete: JobId=47519 done
[2022-08-05T00:47:48.001] _slurm_rpc_kill_job: REQUEST_KILL_JOB JobId=47520 uid 548200036
[2022-08-05T00:56:59.755] _slurm_rpc_submit_batch_job: JobId=47521 InitPrio=20984 usec=417
[2022-08-05T00:57:44.464] sched/backfill: _start_job: Started JobId=47521 in cpu-opteron on cpu09
[2022-08-05T01:05:32.879] _slurm_rpc_submit_batch_job: JobId=47522 InitPrio=20984 usec=485
[2022-08-05T01:05:44.480] sched/backfill: _start_job: Started JobId=47522 in cpu-opteron on cpu10
[2022-08-05T01:10:59.417] _slurm_rpc_submit_batch_job: JobId=47523 InitPrio=20984 usec=563
[2022-08-05T01:14:29.572] _slurm_rpc_submit_batch_job: JobId=47524 InitPrio=21294 usec=393
[2022-08-05T02:22:19.152] _job_complete: JobId=47455 WEXITSTATUS 0
[2022-08-05T02:22:19.153] _job_complete: JobId=47455 done
[2022-08-05T02:22:44.660] sched/backfill: _start_job: Started JobId=47523 in cpu-opteron on cpu11
[2022-08-05T02:23:15.469] _slurm_rpc_submit_batch_job: JobId=47525 InitPrio=22494 usec=517
[2022-08-05T02:23:26.552] _slurm_rpc_submit_batch_job: JobId=47526 InitPrio=22494 usec=523
[2022-08-05T02:23:35.527] _slurm_rpc_submit_batch_job: JobId=47527 InitPrio=22494 usec=427
[2022-08-05T02:24:02.787] _slurm_rpc_submit_batch_job: JobId=47528 InitPrio=22494 usec=476
[2022-08-05T02:24:15.774] _slurm_rpc_submit_batch_job: JobId=47529 InitPrio=22494 usec=500
[2022-08-05T02:24:26.797] _slurm_rpc_submit_batch_job: JobId=47530 InitPrio=22494 usec=419
[2022-08-05T04:05:48.851] _job_complete: JobId=46881 WEXITSTATUS 0
[2022-08-05T04:05:48.856] _job_complete: JobId=46881 done
[2022-08-05T04:05:51.741] sched: Allocate JobId=46945 NodeList=cpu13 #CPUs=32 Partition=cpu-epyc
[2022-08-05T06:21:37.735] _job_complete: JobId=46944 WEXITSTATUS 0
[2022-08-05T06:21:37.735] _job_complete: JobId=46944 done
[2022-08-05T06:21:37.984] sched: Allocate JobId=46946 NodeList=cpu12 #CPUs=32 Partition=cpu-epyc
[2022-08-05T07:06:09.729] _slurm_rpc_kill_job: REQUEST_KILL_JOB JobId=47510 uid 548200019
[2022-08-05T07:06:32.743] _slurm_rpc_submit_batch_job: JobId=47531 InitPrio=21110 usec=522
[2022-08-05T09:10:18.429] _job_complete: JobId=46952 WEXITSTATUS 0
[2022-08-05T09:10:18.435] _job_complete: JobId=46952 done
[2022-08-05T09:10:26.756] sched: Allocate JobId=47516 NodeList=gpu04 #CPUs=16 Partition=gpu-k40c
[2022-08-05T10:28:45.080] _slurm_rpc_submit_batch_job: JobId=47532 InitPrio=25126 usec=570
[2022-08-05T10:28:45.271] sched: Allocate JobId=47532 NodeList=cpu[12-13] #CPUs=16 Partition=cpu-epyc
[2022-08-05T10:28:46.066] _job_complete: JobId=47532 WEXITSTATUS 0
[2022-08-05T10:28:46.067] _job_complete: JobId=47532 done
[2022-08-05T10:42:24.932] _slurm_rpc_submit_batch_job: JobId=47533 InitPrio=25126 usec=629
[2022-08-05T10:42:25.611] sched: Allocate JobId=47533 NodeList=cpu[12-13] #CPUs=16 Partition=cpu-epyc
[2022-08-05T10:42:25.928] _job_complete: JobId=47533 WEXITSTATUS 0
[2022-08-05T10:42:25.928] _job_complete: JobId=47533 done
[2022-08-05T10:45:36.777] _slurm_rpc_submit_batch_job: JobId=47534 InitPrio=25126 usec=445
[2022-08-05T10:45:37.131] sched: Allocate JobId=47534 NodeList=cpu[12-13] #CPUs=16 Partition=cpu-epyc
[2022-08-05T10:45:37.454] _job_complete: JobId=47534 WEXITSTATUS 0
[2022-08-05T10:45:37.455] _job_complete: JobId=47534 done
[2022-08-05T10:46:30.504] _slurm_rpc_submit_batch_job: JobId=47535 InitPrio=25126 usec=420
[2022-08-05T10:46:31.208] sched: Allocate JobId=47535 NodeList=cpu[12-13] #CPUs=16 Partition=cpu-epyc
[2022-08-05T10:46:32.067] _job_complete: JobId=47535 WEXITSTATUS 0
[2022-08-05T10:46:32.067] _job_complete: JobId=47535 done
[2022-08-05T10:54:50.251] _slurm_rpc_submit_batch_job: JobId=47536 InitPrio=24989 usec=495
[2022-08-05T10:54:51.150] sched: Allocate JobId=47536 NodeList=cpu[12-13] #CPUs=32 Partition=cpu-epyc
[2022-08-05T10:56:01.655] _job_complete: JobId=47536 OOM failure
[2022-08-05T10:56:01.655] _job_complete: JobId=47536 done
[2022-08-05T10:56:07.271] _slurm_rpc_kill_job: REQUEST_KILL_JOB JobId=47536 uid 548300543
[2022-08-05T10:58:36.158] _slurm_rpc_submit_batch_job: JobId=47537 InitPrio=24989 usec=508
[2022-08-05T10:58:36.567] sched: Allocate JobId=47537 NodeList=cpu[12-13] #CPUs=32 Partition=cpu-epyc
[2022-08-05T10:59:55.659] _slurm_rpc_kill_job: REQUEST_KILL_JOB JobId=47537 uid 548300543
[2022-08-05T11:01:27.288] _slurm_rpc_submit_batch_job: JobId=47538 InitPrio=24989 usec=475
[2022-08-05T11:01:27.811] sched: Allocate JobId=47538 NodeList=cpu[12-13] #CPUs=32 Partition=cpu-epyc
[2022-08-05T11:16:22.941] _slurm_rpc_kill_job: REQUEST_KILL_JOB JobId=47538 uid 548300543
[2022-08-05T11:16:58.056] _slurm_rpc_submit_batch_job: JobId=47539 InitPrio=23662 usec=402
[2022-08-05T11:16:58.511] sched: Allocate JobId=47539 NodeList=cpu[12-15] #CPUs=64 Partition=cpu-epyc
[2022-08-05T11:19:18.258] _slurm_rpc_kill_job: REQUEST_KILL_JOB JobId=47539 uid 548300543
[2022-08-05T11:26:52.227] _slurm_rpc_submit_batch_job: JobId=47540 InitPrio=24005 usec=442
[2022-08-05T11:26:52.578] sched: Allocate JobId=47540 NodeList=cpu[12-15] #CPUs=24 Partition=cpu-epyc
[2022-08-05T11:27:19.736] _slurm_rpc_kill_job: REQUEST_KILL_JOB JobId=47540 uid 548300543
[2022-08-05T11:27:51.779] _slurm_rpc_submit_batch_job: JobId=47541 InitPrio=24005 usec=449
[2022-08-05T11:27:51.881] sched: Allocate JobId=47541 NodeList=cpu[12-15] #CPUs=24 Partition=cpu-epyc
[2022-08-05T11:28:29.040] _slurm_rpc_kill_job: REQUEST_KILL_JOB JobId=46917 uid 548200045
[2022-08-05T11:28:31.058] sched: Allocate JobId=47504 NodeList=gpu02 #CPUs=16 Partition=gpu-titan
[2022-08-05T11:28:33.462] _job_complete: JobId=47504 WEXITSTATUS 127
[2022-08-05T11:28:33.463] _job_complete: JobId=47504 done
[2022-08-05T11:28:33.773] sched: Allocate JobId=47505 NodeList=gpu02 #CPUs=16 Partition=gpu-titan
[2022-08-05T11:28:35.557] _job_complete: JobId=47505 WEXITSTATUS 127
[2022-08-05T11:28:35.558] _job_complete: JobId=47505 done
[2022-08-05T11:29:02.002] _slurm_rpc_submit_batch_job: JobId=47542 InitPrio=20194 usec=548
[2022-08-05T11:29:02.990] sched: Allocate JobId=47542 NodeList=gpu02 #CPUs=8 Partition=gpu-titan
[2022-08-05T11:30:44.055] create_resv: REPLACE or REPLACE_DOWN flags should be used with the NodeCnt reservation option; do not specify CoreCnt
[2022-08-05T11:30:44.055] _slurm_rpc_resv_create reservation=user_training: CPU count specification invalid
[2022-08-05T11:31:05.251] create_resv: REPLACE or REPLACE_DOWN flags should be used with the NodeCnt reservation option; do not specify CoreCnt
[2022-08-05T11:31:05.251] _slurm_rpc_resv_create reservation=user_training: CPU count specification invalid
[2022-08-05T11:35:16.439] create_resv: REPLACE or REPLACE_DOWN flags should be used with the NodeCnt reservation option; do not specify CoreCnt
[2022-08-05T11:35:16.439] _slurm_rpc_resv_create reservation=user_training: CPU count specification invalid
[2022-08-05T11:36:52.712] processed groups training_group
[2022-08-05T11:36:52.712] uid 548200003
[2022-08-05T11:36:52.712] sched: Created reservation=user_training groups=training_group nodes=cpu08 cores=64 licenses=(null) tres=cpu=64 watts=4294967294 start=2022-08-10T10:00:00 end=2022-08-10T18:00:00 MaxStartDelay=
[2022-08-05T11:38:27.758] _slurm_rpc_kill_job: REQUEST_KILL_JOB JobId=47541 uid 548200003
[2022-08-05T11:42:42.448] _slurm_rpc_submit_batch_job: JobId=47543 InitPrio=66899 usec=457
[2022-08-05T11:42:42.567] sched: Allocate JobId=47543 NodeList=cpu[12-15] #CPUs=24 Partition=cpu-epyc
[2022-08-05T11:44:33.087] _slurm_rpc_kill_job: REQUEST_KILL_JOB JobId=47543 uid 548200005
[2022-08-05T11:44:58.527] _slurm_rpc_submit_batch_job: JobId=47544 InitPrio=66899 usec=477
[2022-08-05T11:44:58.784] sched: Allocate JobId=47544 NodeList=cpu[12-15] #CPUs=24 Partition=cpu-epyc
[2022-08-05T11:46:22.337] _slurm_rpc_kill_job: REQUEST_KILL_JOB JobId=47544 uid 548200005
[2022-08-05T11:46:47.526] _slurm_rpc_submit_batch_job: JobId=47545 InitPrio=66899 usec=509
[2022-08-05T11:46:47.941] sched: Allocate JobId=47545 NodeList=cpu[12-15] #CPUs=24 Partition=cpu-epyc
[2022-08-05T11:47:23.475] _slurm_rpc_kill_job: REQUEST_KILL_JOB JobId=47545 uid 548200005
[2022-08-05T11:47:39.473] _slurm_rpc_submit_batch_job: JobId=47546 InitPrio=66899 usec=472
[2022-08-05T11:47:40.176] sched: Allocate JobId=47546 NodeList=cpu[12-15] #CPUs=24 Partition=cpu-epyc
[2022-08-05T11:49:04.293] _slurm_rpc_kill_job: REQUEST_KILL_JOB JobId=47546 uid 548200005
[2022-08-05T12:06:47.205] _slurm_rpc_submit_batch_job: JobId=47547 InitPrio=24005 usec=370
[2022-08-05T12:06:47.299] sched: Allocate JobId=47547 NodeList=cpu[12-15] #CPUs=24 Partition=cpu-epyc
[2022-08-05T12:06:47.654] _job_complete: JobId=47547 WEXITSTATUS 0
[2022-08-05T12:06:47.655] _job_complete: JobId=47547 done
[2022-08-05T12:11:23.942] _slurm_rpc_submit_batch_job: JobId=47548 InitPrio=66899 usec=497
[2022-08-05T12:11:24.839] sched: Allocate JobId=47548 NodeList=cpu[12-15] #CPUs=24 Partition=cpu-epyc
[2022-08-05T12:11:26.712] _job_complete: JobId=47548 WEXITSTATUS 0
[2022-08-05T12:11:26.712] _job_complete: JobId=47548 done
[2022-08-05T12:12:06.216] _slurm_rpc_submit_batch_job: JobId=47549 InitPrio=66899 usec=501
[2022-08-05T12:12:08.896] sched: Allocate JobId=47549 NodeList=cpu[12-15] #CPUs=24 Partition=cpu-epyc
[2022-08-05T12:12:10.620] _job_complete: JobId=47549 WEXITSTATUS 0
[2022-08-05T12:12:10.620] _job_complete: JobId=47549 done
[2022-08-05T12:13:34.765] _slurm_rpc_submit_batch_job: JobId=47550 InitPrio=66899 usec=451
[2022-08-05T12:13:35.120] sched: Allocate JobId=47550 NodeList=cpu[12-15] #CPUs=24 Partition=cpu-epyc
[2022-08-05T12:13:36.871] _job_complete: JobId=47550 WEXITSTATUS 0
[2022-08-05T12:13:36.871] _job_complete: JobId=47550 done
[2022-08-05T12:13:40.341] _slurm_rpc_submit_batch_job: JobId=47551 InitPrio=66899 usec=402
[2022-08-05T12:13:41.130] sched: Allocate JobId=47551 NodeList=cpu[12-15] #CPUs=24 Partition=cpu-epyc
[2022-08-05T12:13:42.874] _job_complete: JobId=47551 WEXITSTATUS 0
[2022-08-05T12:13:42.874] _job_complete: JobId=47551 done
[2022-08-05T12:14:24.478] _slurm_rpc_submit_batch_job: JobId=47552 InitPrio=24005 usec=497
[2022-08-05T12:14:25.190] sched: Allocate JobId=47552 NodeList=cpu[12-15] #CPUs=24 Partition=cpu-epyc
[2022-08-05T12:14:25.542] _job_complete: JobId=47552 WEXITSTATUS 0
[2022-08-05T12:14:25.543] _job_complete: JobId=47552 done
[2022-08-05T12:14:55.154] _slurm_rpc_submit_batch_job: JobId=47553 InitPrio=66899 usec=518
[2022-08-05T12:14:55.234] sched: Allocate JobId=47553 NodeList=cpu[12-15] #CPUs=24 Partition=cpu-epyc
[2022-08-05T12:14:57.014] _job_complete: JobId=47553 WEXITSTATUS 0
[2022-08-05T12:14:57.014] _job_complete: JobId=47553 done
[2022-08-05T12:15:30.950] _slurm_rpc_submit_batch_job: JobId=47554 InitPrio=66899 usec=581
[2022-08-05T12:15:31.282] sched: Allocate JobId=47554 NodeList=cpu[12-15] #CPUs=24 Partition=cpu-epyc
[2022-08-05T12:15:33.420] _job_complete: JobId=47554 WEXITSTATUS 0
[2022-08-05T12:15:33.420] _job_complete: JobId=47554 done
[2022-08-05T12:15:57.866] _slurm_rpc_submit_batch_job: JobId=47555 InitPrio=24005 usec=423
[2022-08-05T12:15:58.321] sched: Allocate JobId=47555 NodeList=cpu[12-15] #CPUs=24 Partition=cpu-epyc
[2022-08-05T12:15:58.756] _job_complete: JobId=47555 WEXITSTATUS 0
[2022-08-05T12:15:58.756] _job_complete: JobId=47555 done
[2022-08-05T12:16:13.159] _slurm_rpc_submit_batch_job: JobId=47556 InitPrio=66899 usec=417
[2022-08-05T12:16:13.342] sched: Allocate JobId=47556 NodeList=cpu[12-15] #CPUs=24 Partition=cpu-epyc
[2022-08-05T12:16:16.796] _job_complete: JobId=47556 WEXITSTATUS 0
[2022-08-05T12:16:16.796] _job_complete: JobId=47556 done
[2022-08-05T12:17:00.361] _slurm_rpc_submit_batch_job: JobId=47557 InitPrio=24005 usec=634
[2022-08-05T12:17:00.413] sched: Allocate JobId=47557 NodeList=cpu[12-15] #CPUs=24 Partition=cpu-epyc
[2022-08-05T12:17:00.800] _job_complete: JobId=47557 WEXITSTATUS 0
[2022-08-05T12:17:00.800] _job_complete: JobId=47557 done
[2022-08-05T12:17:45.889] _slurm_rpc_submit_batch_job: JobId=47558 InitPrio=24005 usec=441
[2022-08-05T12:17:46.652] sched: Allocate JobId=47558 NodeList=cpu[12-15] #CPUs=24 Partition=cpu-epyc
[2022-08-05T12:17:47.117] _job_complete: JobId=47558 WEXITSTATUS 0
[2022-08-05T12:17:47.117] _job_complete: JobId=47558 done
[2022-08-05T12:18:30.899] _slurm_rpc_submit_batch_job: JobId=47559 InitPrio=66899 usec=558
[2022-08-05T12:18:31.715] sched: Allocate JobId=47559 NodeList=cpu[12-15] #CPUs=24 Partition=cpu-epyc
[2022-08-05T12:18:35.245] _job_complete: JobId=47559 WEXITSTATUS 0
[2022-08-05T12:18:35.245] _job_complete: JobId=47559 done
[2022-08-05T12:18:49.898] _slurm_rpc_submit_batch_job: JobId=47560 InitPrio=24005 usec=429
[2022-08-05T12:18:50.741] sched: Allocate JobId=47560 NodeList=cpu[12-15] #CPUs=24 Partition=cpu-epyc
[2022-08-05T12:18:51.065] _job_complete: JobId=47560 WEXITSTATUS 0
[2022-08-05T12:18:51.065] _job_complete: JobId=47560 done
[2022-08-05T12:20:25.259] _slurm_rpc_submit_batch_job: JobId=47561 InitPrio=66899 usec=539
[2022-08-05T12:20:25.877] sched: Allocate JobId=47561 NodeList=cpu[12-15] #CPUs=24 Partition=cpu-epyc
[2022-08-05T12:20:29.437] _job_complete: JobId=47561 WEXITSTATUS 0
[2022-08-05T12:20:29.437] _job_complete: JobId=47561 done
[2022-08-05T12:20:46.383] _slurm_rpc_submit_batch_job: JobId=47562 InitPrio=66899 usec=486
[2022-08-05T12:20:46.906] sched: Allocate JobId=47562 NodeList=cpu[12-15] #CPUs=24 Partition=cpu-epyc
[2022-08-05T12:20:50.170] _job_complete: JobId=47562 WEXITSTATUS 0
[2022-08-05T12:20:50.170] _job_complete: JobId=47562 done
[2022-08-05T12:21:03.137] _slurm_rpc_submit_batch_job: JobId=47563 InitPrio=66899 usec=455
[2022-08-05T12:21:03.930] sched: Allocate JobId=47563 NodeList=cpu[12-15] #CPUs=24 Partition=cpu-epyc
[2022-08-05T12:21:07.154] _job_complete: JobId=47563 WEXITSTATUS 0
[2022-08-05T12:21:07.154] _job_complete: JobId=47563 done
[2022-08-05T12:21:09.648] _slurm_rpc_submit_batch_job: JobId=47564 InitPrio=66899 usec=470
[2022-08-05T12:21:09.939] sched: Allocate JobId=47564 NodeList=cpu[12-15] #CPUs=24 Partition=cpu-epyc
[2022-08-05T12:21:13.177] _job_complete: JobId=47564 WEXITSTATUS 0
[2022-08-05T12:21:13.177] _job_complete: JobId=47564 done
[2022-08-05T12:21:13.757] _slurm_rpc_submit_batch_job: JobId=47565 InitPrio=66899 usec=511
[2022-08-05T12:21:13.948] sched: Allocate JobId=47565 NodeList=cpu[12-15] #CPUs=24 Partition=cpu-epyc
[2022-08-05T12:21:14.800] _slurm_rpc_submit_batch_job: JobId=47566 InitPrio=66899 usec=420
[2022-08-05T12:21:17.161] _job_complete: JobId=47565 WEXITSTATUS 0
[2022-08-05T12:21:17.161] _job_complete: JobId=47565 done
[2022-08-05T12:21:17.426] sched: Allocate JobId=47566 NodeList=cpu[12-15] #CPUs=24 Partition=cpu-epyc
[2022-08-05T12:21:20.852] _job_complete: JobId=47566 WEXITSTATUS 0
[2022-08-05T12:21:20.853] _job_complete: JobId=47566 done
[2022-08-05T12:22:24.190] _slurm_rpc_submit_batch_job: JobId=47567 InitPrio=66899 usec=574
[2022-08-05T12:22:25.050] sched: Allocate JobId=47567 NodeList=cpu[12-15] #CPUs=24 Partition=cpu-epyc
[2022-08-05T12:22:28.289] _job_complete: JobId=47567 WEXITSTATUS 0
[2022-08-05T12:22:28.289] _job_complete: JobId=47567 done
[2022-08-05T12:22:31.915] _slurm_rpc_submit_batch_job: JobId=47568 InitPrio=66899 usec=548
[2022-08-05T12:22:32.056] sched: Allocate JobId=47568 NodeList=cpu[12-15] #CPUs=24 Partition=cpu-epyc
[2022-08-05T12:22:35.291] _job_complete: JobId=47568 WEXITSTATUS 0
[2022-08-05T12:22:35.292] _job_complete: JobId=47568 done
[2022-08-05T12:22:54.225] _slurm_rpc_submit_batch_job: JobId=47569 InitPrio=66899 usec=477
[2022-08-05T12:22:54.255] sched: Allocate JobId=47569 NodeList=cpu[12-15] #CPUs=24 Partition=cpu-epyc
[2022-08-05T12:22:57.487] _job_complete: JobId=47569 WEXITSTATUS 0
[2022-08-05T12:22:57.488] _job_complete: JobId=47569 done
[2022-08-05T12:22:59.136] _slurm_rpc_submit_batch_job: JobId=47570 InitPrio=66899 usec=467
[2022-08-05T12:22:59.262] sched: Allocate JobId=47570 NodeList=cpu[12-15] #CPUs=24 Partition=cpu-epyc
[2022-08-05T12:23:02.522] _job_complete: JobId=47570 WEXITSTATUS 0
[2022-08-05T12:23:02.522] _job_complete: JobId=47570 done
[2022-08-05T12:23:18.113] _slurm_rpc_submit_batch_job: JobId=47571 InitPrio=66899 usec=428
[2022-08-05T12:23:18.290] sched: Allocate JobId=47571 NodeList=cpu[12-15] #CPUs=24 Partition=cpu-epyc
[2022-08-05T12:23:21.514] _job_complete: JobId=47571 WEXITSTATUS 0
[2022-08-05T12:23:21.514] _job_complete: JobId=47571 done
[2022-08-05T12:23:22.162] _slurm_rpc_submit_batch_job: JobId=47572 InitPrio=66899 usec=527
[2022-08-05T12:23:22.295] sched: Allocate JobId=47572 NodeList=cpu[12-15] #CPUs=24 Partition=cpu-epyc
[2022-08-05T12:23:25.566] _job_complete: JobId=47572 WEXITSTATUS 0
[2022-08-05T12:23:25.566] _job_complete: JobId=47572 done
[2022-08-05T12:23:36.325] _slurm_rpc_submit_batch_job: JobId=47573 InitPrio=66899 usec=431
[2022-08-05T12:23:37.317] sched: Allocate JobId=47573 NodeList=cpu[12-15] #CPUs=24 Partition=cpu-epyc
[2022-08-05T12:23:40.594] _job_complete: JobId=47573 WEXITSTATUS 0
[2022-08-05T12:23:40.594] _job_complete: JobId=47573 done
[2022-08-05T12:23:45.448] _slurm_rpc_submit_batch_job: JobId=47574 InitPrio=24005 usec=410
[2022-08-05T12:23:46.333] sched: Allocate JobId=47574 NodeList=cpu[12-15] #CPUs=24 Partition=cpu-epyc
[2022-08-05T12:23:47.211] _job_complete: JobId=47574 WEXITSTATUS 0
[2022-08-05T12:23:47.211] _job_complete: JobId=47574 done
[2022-08-05T12:24:57.058] _slurm_rpc_submit_batch_job: JobId=47575 InitPrio=24005 usec=576
[2022-08-05T12:24:57.432] sched: Allocate JobId=47575 NodeList=cpu[12-15] #CPUs=24 Partition=cpu-epyc
[2022-08-05T12:24:58.218] _job_complete: JobId=47575 WEXITSTATUS 0
[2022-08-05T12:24:58.218] _job_complete: JobId=47575 done
[2022-08-05T12:25:32.245] _slurm_rpc_submit_batch_job: JobId=47576 InitPrio=66899 usec=461
[2022-08-05T12:25:32.481] sched: Allocate JobId=47576 NodeList=cpu[12-15] #CPUs=24 Partition=cpu-epyc
[2022-08-05T12:25:35.849] _job_complete: JobId=47576 WEXITSTATUS 0
[2022-08-05T12:25:35.849] _job_complete: JobId=47576 done
[2022-08-05T12:25:38.006] _slurm_rpc_submit_batch_job: JobId=47577 InitPrio=66899 usec=513
[2022-08-05T12:25:38.489] sched: Allocate JobId=47577 NodeList=cpu[12-15] #CPUs=24 Partition=cpu-epyc
[2022-08-05T12:25:41.764] _job_complete: JobId=47577 WEXITSTATUS 0
[2022-08-05T12:25:41.764] _job_complete: JobId=47577 done
[2022-08-05T12:26:17.819] _slurm_rpc_submit_batch_job: JobId=47578 InitPrio=66899 usec=460
[2022-08-05T12:26:18.544] sched: Allocate JobId=47578 NodeList=cpu[12-15] #CPUs=24 Partition=cpu-epyc
[2022-08-05T12:26:21.825] _job_complete: JobId=47578 WEXITSTATUS 0
[2022-08-05T12:26:21.825] _job_complete: JobId=47578 done
[2022-08-05T12:26:29.619] _slurm_rpc_submit_batch_job: JobId=47579 InitPrio=24005 usec=398
[2022-08-05T12:26:30.561] sched: Allocate JobId=47579 NodeList=cpu[12-15] #CPUs=24 Partition=cpu-epyc
[2022-08-05T12:26:35.471] _job_complete: JobId=47579 WEXITSTATUS 0
[2022-08-05T12:26:35.471] _job_complete: JobId=47579 done
[2022-08-05T12:26:36.856] _slurm_rpc_submit_batch_job: JobId=47580 InitPrio=66899 usec=450
[2022-08-05T12:26:37.571] sched: Allocate JobId=47580 NodeList=cpu[12-15] #CPUs=24 Partition=cpu-epyc
[2022-08-05T12:26:40.798] _job_complete: JobId=47580 WEXITSTATUS 0
[2022-08-05T12:26:40.798] _job_complete: JobId=47580 done
[2022-08-05T12:27:05.076] _slurm_rpc_submit_batch_job: JobId=47581 InitPrio=66899 usec=513
[2022-08-05T12:27:05.607] sched: Allocate JobId=47581 NodeList=cpu[12-15] #CPUs=24 Partition=cpu-epyc
[2022-08-05T12:27:09.217] _job_complete: JobId=47581 WEXITSTATUS 0
[2022-08-05T12:27:09.217] _job_complete: JobId=47581 done
[2022-08-05T12:27:15.909] _slurm_rpc_submit_batch_job: JobId=47582 InitPrio=66899 usec=662
[2022-08-05T12:27:16.623] sched: Allocate JobId=47582 NodeList=cpu[12-15] #CPUs=24 Partition=cpu-epyc
[2022-08-05T12:27:19.934] _job_complete: JobId=47582 WEXITSTATUS 0
[2022-08-05T12:27:19.934] _job_complete: JobId=47582 done
[2022-08-05T12:27:24.958] _slurm_rpc_submit_batch_job: JobId=47583 InitPrio=66899 usec=470
[2022-08-05T12:27:25.636] sched: Allocate JobId=47583 NodeList=cpu[12-15] #CPUs=24 Partition=cpu-epyc
[2022-08-05T12:27:28.995] _job_complete: JobId=47583 WEXITSTATUS 0
[2022-08-05T12:27:28.995] _job_complete: JobId=47583 done
[2022-08-05T12:28:58.485] _slurm_rpc_submit_batch_job: JobId=47584 InitPrio=66899 usec=510
[2022-08-05T12:28:59.030] sched: Allocate JobId=47584 NodeList=cpu[12-15] #CPUs=24 Partition=cpu-epyc
[2022-08-05T12:29:51.057] _slurm_rpc_submit_batch_job: JobId=47585 InitPrio=24005 usec=450
[2022-08-05T12:32:17.678] _job_complete: JobId=47584 WEXITSTATUS 0
[2022-08-05T12:32:17.678] _job_complete: JobId=47584 done
[2022-08-05T12:32:17.973] sched: Allocate JobId=47585 NodeList=cpu[12-15] #CPUs=24 Partition=cpu-epyc
[2022-08-05T12:32:18.818] _job_complete: JobId=47585 WEXITSTATUS 0
[2022-08-05T12:32:18.818] _job_complete: JobId=47585 done
[2022-08-05T12:56:13.815] _slurm_rpc_submit_batch_job: JobId=47586 InitPrio=66899 usec=445
[2022-08-05T12:56:14.272] sched: Allocate JobId=47586 NodeList=cpu[12-15] #CPUs=24 Partition=cpu-epyc
[2022-08-05T12:57:12.590] _slurm_rpc_kill_job: REQUEST_KILL_JOB JobId=47586 uid 548200005
[2022-08-05T12:57:36.380] _slurm_rpc_submit_batch_job: JobId=47587 InitPrio=66899 usec=479
[2022-08-05T12:57:36.385] sched: Allocate JobId=47587 NodeList=cpu[12-15] #CPUs=24 Partition=cpu-epyc
[2022-08-05T12:58:04.044] _slurm_rpc_kill_job: REQUEST_KILL_JOB JobId=47587 uid 548200005
[2022-08-05T12:58:15.042] _slurm_rpc_submit_batch_job: JobId=47588 InitPrio=66899 usec=467
[2022-08-05T12:58:15.636] sched: Allocate JobId=47588 NodeList=cpu[12-15] #CPUs=24 Partition=cpu-epyc
[2022-08-05T12:59:21.645] _slurm_rpc_kill_job: REQUEST_KILL_JOB JobId=47588 uid 548200005
[2022-08-05T13:06:29.306] _slurm_rpc_submit_batch_job: JobId=47589 InitPrio=66899 usec=429
[2022-08-05T13:06:29.442] sched: Allocate JobId=47589 NodeList=cpu[12-15] #CPUs=24 Partition=cpu-epyc
[2022-08-05T13:11:10.580] _slurm_rpc_kill_job: REQUEST_KILL_JOB JobId=47589 uid 548200005
[2022-08-05T13:11:12.591] _slurm_rpc_submit_batch_job: JobId=47590 InitPrio=66899 usec=487
[2022-08-05T13:11:13.018] sched: Allocate JobId=47590 NodeList=cpu[12-15] #CPUs=24 Partition=cpu-epyc
[2022-08-05T13:12:19.264] _slurm_rpc_kill_job: REQUEST_KILL_JOB JobId=47590 uid 548200005
[2022-08-05T13:12:45.664] _slurm_rpc_submit_batch_job: JobId=47591 InitPrio=66899 usec=505
[2022-08-05T13:12:46.484] sched: Allocate JobId=47591 NodeList=cpu[12-15] #CPUs=24 Partition=cpu-epyc
[2022-08-05T13:12:47.406] _job_complete: JobId=47591 WEXITSTATUS 0
[2022-08-05T13:12:47.407] _job_complete: JobId=47591 done
[2022-08-05T13:13:12.929] _slurm_rpc_submit_batch_job: JobId=47592 InitPrio=66899 usec=443
[2022-08-05T13:13:13.520] sched: Allocate JobId=47592 NodeList=cpu[12-15] #CPUs=24 Partition=cpu-epyc
[2022-08-05T13:13:14.357] _job_complete: JobId=47592 WEXITSTATUS 0
[2022-08-05T13:13:14.357] _job_complete: JobId=47592 done
[2022-08-05T13:15:55.188] _slurm_rpc_submit_batch_job: JobId=47593 InitPrio=66899 usec=505
[2022-08-05T13:15:55.746] sched: Allocate JobId=47593 NodeList=cpu[12-15] #CPUs=24 Partition=cpu-epyc
[2022-08-05T13:15:57.074] _job_complete: JobId=47593 WEXITSTATUS 0
[2022-08-05T13:15:57.074] _job_complete: JobId=47593 done
[2022-08-05T13:16:19.839] _slurm_rpc_submit_batch_job: JobId=47594 InitPrio=66899 usec=443
[2022-08-05T13:16:20.781] sched: Allocate JobId=47594 NodeList=cpu[12-15] #CPUs=24 Partition=cpu-epyc
[2022-08-05T13:16:22.080] _job_complete: JobId=47594 WEXITSTATUS 0
[2022-08-05T13:16:22.080] _job_complete: JobId=47594 done
[2022-08-05T13:17:10.243] _slurm_rpc_submit_batch_job: JobId=47595 InitPrio=66899 usec=444
[2022-08-05T13:17:10.853] sched: Allocate JobId=47595 NodeList=cpu[12-15] #CPUs=24 Partition=cpu-epyc
[2022-08-05T13:17:12.251] _job_complete: JobId=47595 WEXITSTATUS 0
[2022-08-05T13:17:12.251] _job_complete: JobId=47595 done
[2022-08-05T13:26:43.300] _slurm_rpc_submit_batch_job: JobId=47596 InitPrio=66899 usec=447
[2022-08-05T13:26:44.138] sched: Allocate JobId=47596 NodeList=cpu[12-15] #CPUs=24 Partition=cpu-epyc
[2022-08-05T13:26:45.473] _job_complete: JobId=47596 WEXITSTATUS 0
[2022-08-05T13:26:45.473] _job_complete: JobId=47596 done
[2022-08-05T13:27:31.565] _slurm_rpc_submit_batch_job: JobId=47597 InitPrio=66899 usec=576
[2022-08-05T13:27:32.210] sched: Allocate JobId=47597 NodeList=cpu[12-15] #CPUs=24 Partition=cpu-epyc
[2022-08-05T13:27:33.514] _job_complete: JobId=47597 WEXITSTATUS 0
[2022-08-05T13:27:33.514] _job_complete: JobId=47597 done
[2022-08-05T13:29:36.475] _slurm_rpc_submit_batch_job: JobId=47598 InitPrio=66899 usec=450
[2022-08-05T13:29:36.490] sched: Allocate JobId=47598 NodeList=cpu[12-15] #CPUs=24 Partition=cpu-epyc
[2022-08-05T13:29:37.810] _job_complete: JobId=47598 WEXITSTATUS 0
[2022-08-05T13:29:37.810] _job_complete: JobId=47598 done
[2022-08-05T13:29:59.000] sched: _slurm_rpc_allocate_resources JobId=47599 NodeList=(null) usec=975
[2022-08-05T13:30:24.240] _job_complete: JobId=47599 WTERMSIG 126
[2022-08-05T13:30:24.240] _job_complete: JobId=47599 cancelled by interactive user
[2022-08-05T13:30:24.240] _job_complete: JobId=47599 done
[2022-08-05T13:30:27.338] sched: _slurm_rpc_allocate_resources JobId=47600 NodeList=(null) usec=822
[2022-08-05T13:30:35.556] _job_complete: JobId=47600 WTERMSIG 126
[2022-08-05T13:30:35.556] _job_complete: JobId=47600 cancelled by interactive user
[2022-08-05T13:30:35.556] _job_complete: JobId=47600 done
[2022-08-05T13:30:45.086] _build_node_list: No nodes satisfy JobId=47601 requirements in partition cpu-opteron
[2022-08-05T13:30:45.086] _slurm_rpc_allocate_resources: Requested node configuration is not available 
[2022-08-05T13:30:56.117] _build_node_list: No nodes satisfy JobId=47602 requirements in partition cpu-opteron
[2022-08-05T13:30:56.117] _slurm_rpc_allocate_resources: Requested node configuration is not available 
[2022-08-05T13:30:59.872] sched: _slurm_rpc_allocate_resources JobId=47603 NodeList=(null) usec=1040
[2022-08-05T13:31:04.316] _job_complete: JobId=47603 WTERMSIG 126
[2022-08-05T13:31:04.316] _job_complete: JobId=47603 cancelled by interactive user
[2022-08-05T13:31:04.317] _job_complete: JobId=47603 done
[2022-08-05T13:31:07.123] sched: _slurm_rpc_allocate_resources JobId=47604 NodeList=(null) usec=782
[2022-08-05T13:31:18.583] _job_complete: JobId=47604 WTERMSIG 126
[2022-08-05T13:31:18.583] _job_complete: JobId=47604 cancelled by interactive user
[2022-08-05T13:31:18.583] _job_complete: JobId=47604 done
[2022-08-05T13:31:23.208] sched: _slurm_rpc_allocate_resources JobId=47605 NodeList=(null) usec=782
[2022-08-05T13:31:38.790] _job_complete: JobId=47605 WTERMSIG 126
[2022-08-05T13:31:38.790] _job_complete: JobId=47605 cancelled by interactive user
[2022-08-05T13:31:38.790] _job_complete: JobId=47605 done
[2022-08-05T13:31:40.618] sched: _slurm_rpc_allocate_resources JobId=47606 NodeList=(null) usec=1296
[2022-08-05T13:31:40.685] sched: Allocate JobId=47606 NodeList=cpu[10-11] #CPUs=2 Partition=cpu-opteron
[2022-08-05T13:31:54.868] _job_complete: JobId=47606 WEXITSTATUS 0
[2022-08-05T13:31:54.869] _job_complete: JobId=47606 done
[2022-08-05T13:32:04.734] sched: _slurm_rpc_allocate_resources JobId=47607 NodeList=(null) usec=1230
[2022-08-05T13:32:05.692] sched: Allocate JobId=47607 NodeList=cpu[12-15] #CPUs=24 Partition=cpu-epyc
[2022-08-05T13:41:52.382] _job_complete: JobId=47607 WEXITSTATUS 0
[2022-08-05T13:41:52.382] _job_complete: JobId=47607 done
[2022-08-05T13:42:11.207] _slurm_rpc_submit_batch_job: JobId=47608 InitPrio=66899 usec=463
[2022-08-05T13:42:11.788] sched: Allocate JobId=47608 NodeList=cpu[12-15] #CPUs=24 Partition=cpu-epyc
[2022-08-05T13:42:12.763] _job_complete: JobId=47608 WEXITSTATUS 0
[2022-08-05T13:42:12.764] _job_complete: JobId=47608 done
[2022-08-05T13:42:30.100] _slurm_rpc_submit_batch_job: JobId=47609 InitPrio=66899 usec=444
[2022-08-05T13:42:30.815] sched: Allocate JobId=47609 NodeList=cpu[12-15] #CPUs=24 Partition=cpu-epyc
[2022-08-05T13:42:31.740] _job_complete: JobId=47609 WEXITSTATUS 0
[2022-08-05T13:42:31.741] _job_complete: JobId=47609 done
[2022-08-05T13:42:38.323] _slurm_rpc_submit_batch_job: JobId=47610 InitPrio=66899 usec=441
[2022-08-05T13:42:38.926] sched: Allocate JobId=47610 NodeList=cpu[12-15] #CPUs=24 Partition=cpu-epyc
[2022-08-05T13:42:39.791] _job_complete: JobId=47610 WEXITSTATUS 0
[2022-08-05T13:42:39.791] _job_complete: JobId=47610 done
[2022-08-05T13:43:40.935] _slurm_rpc_submit_batch_job: JobId=47611 InitPrio=66899 usec=445
[2022-08-05T13:43:41.054] sched: Allocate JobId=47611 NodeList=cpu[12-15] #CPUs=24 Partition=cpu-epyc
[2022-08-05T13:43:42.888] _job_complete: JobId=47611 WEXITSTATUS 0
[2022-08-05T13:43:42.888] _job_complete: JobId=47611 done
[2022-08-05T13:45:17.597] _slurm_rpc_submit_batch_job: JobId=47612 InitPrio=66899 usec=470
[2022-08-05T13:45:18.187] sched: Allocate JobId=47612 NodeList=cpu[12-15] #CPUs=24 Partition=cpu-epyc
[2022-08-05T13:45:20.044] _job_complete: JobId=47612 WEXITSTATUS 0
[2022-08-05T13:45:20.044] _job_complete: JobId=47612 done
[2022-08-05T13:45:49.326] _slurm_rpc_submit_batch_job: JobId=47613 InitPrio=66899 usec=419
[2022-08-05T13:45:50.232] sched: Allocate JobId=47613 NodeList=cpu[12-15] #CPUs=24 Partition=cpu-epyc
[2022-08-05T13:45:52.069] _job_complete: JobId=47613 WEXITSTATUS 0
[2022-08-05T13:45:52.070] _job_complete: JobId=47613 done
[2022-08-05T13:46:30.233] _slurm_rpc_submit_batch_job: JobId=47614 InitPrio=66899 usec=518
[2022-08-05T13:46:30.285] sched: Allocate JobId=47614 NodeList=cpu[12-15] #CPUs=24 Partition=cpu-epyc
[2022-08-05T13:46:32.111] _job_complete: JobId=47614 WEXITSTATUS 0
[2022-08-05T13:46:32.111] _job_complete: JobId=47614 done
[2022-08-05T13:46:45.196] sched: _slurm_rpc_allocate_resources JobId=47615 NodeList=(null) usec=994
[2022-08-05T13:46:45.304] sched: Allocate JobId=47615 NodeList=cpu[12-15] #CPUs=24 Partition=cpu-epyc
[2022-08-05T13:52:19.936] _job_complete: JobId=47615 WEXITSTATUS 0
[2022-08-05T13:52:19.936] _job_complete: JobId=47615 done
[2022-08-05T13:52:27.159] sched: _slurm_rpc_allocate_resources JobId=47616 NodeList=(null) usec=774
[2022-08-05T13:52:27.953] sched: Allocate JobId=47616 NodeList=cpu[12-15] #CPUs=24 Partition=cpu-epyc
[2022-08-05T13:52:28.752] _job_complete: JobId=47616 WEXITSTATUS 0
[2022-08-05T13:52:28.752] _job_complete: JobId=47616 done
[2022-08-05T13:52:33.207] _slurm_rpc_submit_batch_job: JobId=47617 InitPrio=24005 usec=412
[2022-08-05T13:52:33.965] sched: Allocate JobId=47617 NodeList=cpu[12-15] #CPUs=24 Partition=cpu-epyc
[2022-08-05T13:52:34.928] _job_complete: JobId=47617 WEXITSTATUS 0
[2022-08-05T13:52:34.928] _job_complete: JobId=47617 done
[2022-08-05T13:52:46.456] sched: _slurm_rpc_allocate_resources JobId=47618 NodeList=(null) usec=793
[2022-08-05T13:52:47.073] sched: Allocate JobId=47618 NodeList=cpu[12-15] #CPUs=24 Partition=cpu-epyc
[2022-08-05T13:52:47.889] _job_complete: JobId=47618 WEXITSTATUS 0
[2022-08-05T13:52:47.889] _job_complete: JobId=47618 done
[2022-08-05T13:53:56.104] _slurm_rpc_submit_batch_job: JobId=47619 InitPrio=24005 usec=411
[2022-08-05T13:53:56.167] sched: Allocate JobId=47619 NodeList=cpu[12-15] #CPUs=24 Partition=cpu-epyc
[2022-08-05T13:53:57.140] _job_complete: JobId=47619 WEXITSTATUS 0
[2022-08-05T13:53:57.140] _job_complete: JobId=47619 done
[2022-08-05T13:55:39.414] _slurm_rpc_submit_batch_job: JobId=47620 InitPrio=66899 usec=510
[2022-08-05T13:55:40.309] sched: Allocate JobId=47620 NodeList=cpu[12-15] #CPUs=24 Partition=cpu-epyc
[2022-08-05T13:55:41.698] _job_complete: JobId=47620 WEXITSTATUS 0
[2022-08-05T13:55:41.698] _job_complete: JobId=47620 done
[2022-08-05T13:55:45.172] _slurm_rpc_submit_batch_job: JobId=47621 InitPrio=24005 usec=533
[2022-08-05T13:55:45.317] sched: Allocate JobId=47621 NodeList=cpu[12-15] #CPUs=24 Partition=cpu-epyc
[2022-08-05T13:55:46.166] _job_complete: JobId=47621 WEXITSTATUS 0
[2022-08-05T13:55:46.166] _job_complete: JobId=47621 done
[2022-08-05T13:55:47.256] sched: _slurm_rpc_allocate_resources JobId=47622 NodeList=(null) usec=1043
[2022-08-05T13:55:48.320] sched: Allocate JobId=47622 NodeList=cpu[12-15] #CPUs=24 Partition=cpu-epyc
[2022-08-05T13:58:29.354] _job_complete: JobId=47622 WEXITSTATUS 0
[2022-08-05T13:58:29.354] _job_complete: JobId=47622 done
[2022-08-05T14:00:19.606] _slurm_rpc_submit_batch_job: JobId=47623 InitPrio=24005 usec=454
[2022-08-05T14:00:19.820] sched: Allocate JobId=47623 NodeList=cpu[12-15] #CPUs=24 Partition=cpu-epyc
[2022-08-05T14:00:20.777] _job_complete: JobId=47623 WEXITSTATUS 0
[2022-08-05T14:00:20.777] _job_complete: JobId=47623 done
[2022-08-05T14:01:05.640] _slurm_rpc_submit_batch_job: JobId=47624 InitPrio=24005 usec=431
[2022-08-05T14:01:05.884] sched: Allocate JobId=47624 NodeList=cpu[12-15] #CPUs=24 Partition=cpu-epyc
[2022-08-05T14:01:06.847] _job_complete: JobId=47624 WEXITSTATUS 0
[2022-08-05T14:01:06.847] _job_complete: JobId=47624 done
[2022-08-05T14:01:50.720] _slurm_rpc_submit_batch_job: JobId=47625 InitPrio=24005 usec=407
[2022-08-05T14:01:50.945] sched: Allocate JobId=47625 NodeList=cpu[12-15] #CPUs=24 Partition=cpu-epyc
[2022-08-05T14:01:51.807] _job_complete: JobId=47625 WEXITSTATUS 0
[2022-08-05T14:01:51.807] _job_complete: JobId=47625 done
[2022-08-05T14:03:59.880] sched: _slurm_rpc_allocate_resources JobId=47626 NodeList=(null) usec=794
[2022-08-05T14:04:00.337] sched: Allocate JobId=47626 NodeList=cpu[12-15] #CPUs=24 Partition=cpu-epyc
[2022-08-05T14:04:05.475] _slurm_rpc_submit_batch_job: JobId=47627 InitPrio=24005 usec=536
[2022-08-05T14:06:09.179] _slurm_rpc_kill_job: REQUEST_KILL_JOB JobId=47627 uid 548300543
[2022-08-05T14:06:45.790] _slurm_rpc_submit_batch_job: JobId=47628 InitPrio=25057 usec=427
[2022-08-05T14:06:46.573] sched: Allocate JobId=47628 NodeList=cpu[14-15] #CPUs=24 Partition=cpu-epyc
[2022-08-05T14:06:47.660] _job_complete: JobId=47628 WEXITSTATUS 0
[2022-08-05T14:06:47.661] _job_complete: JobId=47628 done
[2022-08-05T14:08:12.567] _slurm_rpc_submit_batch_job: JobId=47629 InitPrio=25057 usec=498
[2022-08-05T14:08:12.843] sched: Allocate JobId=47629 NodeList=cpu[14-15] #CPUs=24 Partition=cpu-epyc
[2022-08-05T14:08:13.735] _job_complete: JobId=47629 WEXITSTATUS 0
[2022-08-05T14:08:13.735] _job_complete: JobId=47629 done
[2022-08-05T14:15:15.694] _job_complete: JobId=47626 WEXITSTATUS 0
[2022-08-05T14:15:15.694] _job_complete: JobId=47626 done
[2022-08-05T14:15:23.212] sched: _slurm_rpc_allocate_resources JobId=47630 NodeList=(null) usec=813
[2022-08-05T14:15:23.703] sched: Allocate JobId=47630 NodeList=cpu[12,14-15] #CPUs=24 Partition=cpu-epyc
[2022-08-05T14:20:57.691] _job_complete: JobId=47630 WEXITSTATUS 0
[2022-08-05T14:20:57.692] _job_complete: JobId=47630 done
[2022-08-05T14:21:03.083] sched: _slurm_rpc_allocate_resources JobId=47631 NodeList=(null) usec=1117
[2022-08-05T14:21:03.297] sched: Allocate JobId=47631 NodeList=cpu[12-15] #CPUs=24 Partition=cpu-epyc
[2022-08-05T14:24:22.235] _job_complete: JobId=47631 WEXITSTATUS 0
[2022-08-05T14:24:22.235] _job_complete: JobId=47631 done
[2022-08-05T14:24:25.654] sched: _slurm_rpc_allocate_resources JobId=47632 NodeList=(null) usec=1125
[2022-08-05T14:24:25.811] sched: Allocate JobId=47632 NodeList=cpu[12-13] #CPUs=24 Partition=cpu-epyc
[2022-08-05T14:24:47.487] _job_complete: JobId=47632 WEXITSTATUS 0
[2022-08-05T14:24:47.487] _job_complete: JobId=47632 done
[2022-08-05T14:24:52.825] sched: _slurm_rpc_allocate_resources JobId=47633 NodeList=(null) usec=1047
[2022-08-05T14:25:12.566] _update_job: updating accounting
[2022-08-05T14:25:12.567] _slurm_rpc_update_job: complete JobId=47633 uid=548200003 usec=663
[2022-08-05T14:25:55.103] _job_complete: JobId=47633 WTERMSIG 126
[2022-08-05T14:25:55.103] _job_complete: JobId=47633 cancelled by interactive user
[2022-08-05T14:25:55.103] _job_complete: JobId=47633 done
[2022-08-05T14:25:59.294] sched: _slurm_rpc_allocate_resources JobId=47634 NodeList=(null) usec=676
[2022-08-05T14:25:59.946] sched: Allocate JobId=47634 NodeList=cpu[12,14-15] #CPUs=24 Partition=cpu-epyc
[2022-08-05T14:29:00.724] _job_complete: JobId=47634 WEXITSTATUS 0
[2022-08-05T14:29:00.724] _job_complete: JobId=47634 done
[2022-08-05T14:29:03.398] _slurm_rpc_submit_batch_job: JobId=47635 InitPrio=66899 usec=521
[2022-08-05T14:29:04.372] sched: Allocate JobId=47635 NodeList=cpu[12-15] #CPUs=24 Partition=cpu-epyc
[2022-08-05T14:29:31.034] _slurm_rpc_kill_job: REQUEST_KILL_JOB JobId=47635 uid 548200005
[2022-08-05T14:37:13.789] _slurm_rpc_submit_batch_job: JobId=47636 InitPrio=25057 usec=477
[2022-08-05T14:37:14.194] sched: Allocate JobId=47636 NodeList=cpu[12-13] #CPUs=24 Partition=cpu-epyc
[2022-08-05T14:37:14.561] _job_complete: JobId=47636 WEXITSTATUS 127
[2022-08-05T14:37:14.562] _job_complete: JobId=47636 done
[2022-08-05T14:37:54.626] _slurm_rpc_submit_batch_job: JobId=47637 InitPrio=25057 usec=399
[2022-08-05T14:37:55.412] sched: Allocate JobId=47637 NodeList=cpu[12-13] #CPUs=24 Partition=cpu-epyc
[2022-08-05T14:37:55.866] _job_complete: JobId=47637 WEXITSTATUS 127
[2022-08-05T14:37:55.867] _job_complete: JobId=47637 done
[2022-08-05T14:38:37.043] _slurm_rpc_submit_batch_job: JobId=47638 InitPrio=25057 usec=438
[2022-08-05T14:38:37.468] sched: Allocate JobId=47638 NodeList=cpu[12-13] #CPUs=24 Partition=cpu-epyc
[2022-08-05T14:38:38.012] _job_complete: JobId=47638 WEXITSTATUS 0
[2022-08-05T14:38:38.013] _job_complete: JobId=47638 done
[2022-08-05T14:42:51.933] _slurm_rpc_submit_batch_job: JobId=47639 InitPrio=25057 usec=499
[2022-08-05T14:42:52.092] sched: Allocate JobId=47639 NodeList=cpu[12-13] #CPUs=24 Partition=cpu-epyc
[2022-08-05T14:56:35.818] _slurm_rpc_kill_job: REQUEST_KILL_JOB JobId=47639 uid 548300543
[2022-08-05T15:12:44.664] _slurm_rpc_kill_job: REQUEST_KILL_JOB JobId=47524 uid 548200023
[2022-08-05T15:13:29.812] _slurm_rpc_submit_batch_job: JobId=47640 InitPrio=21568 usec=569
[2022-08-05T16:16:20.111] _slurm_rpc_submit_batch_job: JobId=47641 InitPrio=21110 usec=479
[2022-08-05T16:16:49.322] _slurm_rpc_submit_batch_job: JobId=47642 InitPrio=21110 usec=510
[2022-08-05T16:25:49.927] _job_complete: JobId=47521 WEXITSTATUS 1
[2022-08-05T16:25:49.927] _job_complete: JobId=47521 done
[2022-08-05T17:00:42.502] _slurm_rpc_submit_batch_job: JobId=47643 InitPrio=21773 usec=589
[2022-08-05T17:01:12.108] _slurm_rpc_kill_job: REQUEST_KILL_JOB JobId=47643 uid 548200023
[2022-08-05T17:01:33.992] _slurm_rpc_submit_batch_job: JobId=47644 InitPrio=21773 usec=544
[2022-08-05T17:01:34.758] sched: Allocate JobId=47644 NodeList=gpu02 #CPUs=8 Partition=gpu-titan
[2022-08-05T17:01:43.735] _job_complete: JobId=47644 WEXITSTATUS 0
[2022-08-05T17:01:43.735] _job_complete: JobId=47644 done
[2022-08-05T18:21:21.750] _slurm_rpc_submit_batch_job: JobId=47645 InitPrio=21833 usec=512
[2022-08-05T18:21:22.403] sched: Allocate JobId=47645 NodeList=gpu02 #CPUs=1 Partition=gpu-titan
[2022-08-05T18:21:39.026] _job_complete: JobId=47645 WEXITSTATUS 0
[2022-08-05T18:21:39.026] _job_complete: JobId=47645 done
[2022-08-05T18:22:00.925] _slurm_rpc_submit_batch_job: JobId=47646 InitPrio=21807 usec=444
[2022-08-05T18:22:49.685] sched/backfill: _start_job: Started JobId=47646 in cpu-opteron on cpu09
[2022-08-05T18:22:52.171] _job_complete: JobId=47646 WEXITSTATUS 0
[2022-08-05T18:22:52.171] _job_complete: JobId=47646 done
[2022-08-05T18:23:06.420] _slurm_rpc_submit_batch_job: JobId=47647 InitPrio=21807 usec=416
[2022-08-05T18:23:06.654] sched: Allocate JobId=47647 NodeList=gpu01 #CPUs=4 Partition=gpu-k10
[2022-08-05T18:23:10.073] _job_complete: JobId=47647 WEXITSTATUS 0
[2022-08-05T18:23:10.073] _job_complete: JobId=47647 done
[2022-08-05T18:27:14.232] _slurm_rpc_submit_batch_job: JobId=47648 InitPrio=21773 usec=397
[2022-08-05T18:27:15.005] sched: Allocate JobId=47648 NodeList=gpu02 #CPUs=8 Partition=gpu-titan
[2022-08-05T18:27:23.835] _job_complete: JobId=47648 WEXITSTATUS 0
[2022-08-05T18:27:23.835] _job_complete: JobId=47648 done
[2022-08-05T18:30:26.108] _slurm_rpc_submit_batch_job: JobId=47649 InitPrio=21833 usec=514
[2022-08-05T18:30:26.354] sched: Allocate JobId=47649 NodeList=gpu02 #CPUs=1 Partition=gpu-titan
[2022-08-05T18:30:46.018] _job_complete: JobId=47649 WEXITSTATUS 0
[2022-08-05T18:30:46.018] _job_complete: JobId=47649 done
[2022-08-05T18:31:08.748] _slurm_rpc_submit_batch_job: JobId=47650 InitPrio=21807 usec=382
[2022-08-05T18:31:09.413] sched: Allocate JobId=47650 NodeList=gpu01 #CPUs=4 Partition=gpu-k10
[2022-08-05T18:31:11.071] _job_complete: JobId=47650 WEXITSTATUS 0
[2022-08-05T18:31:11.071] _job_complete: JobId=47650 done
[2022-08-05T19:26:23.757] _job_complete: JobId=47114 WEXITSTATUS 0
[2022-08-05T19:26:23.758] _job_complete: JobId=47114 done
[2022-08-05T19:26:24.396] sched: Allocate JobId=47525 NodeList=cpu11 #CPUs=16 Partition=cpu-opteron
[2022-08-05T19:35:44.095] _job_complete: JobId=47522 WEXITSTATUS 1
[2022-08-05T19:35:44.095] _job_complete: JobId=47522 done
[2022-08-05T19:41:20.764] _job_complete: JobId=46945 WEXITSTATUS 0
[2022-08-05T19:41:20.764] _job_complete: JobId=46945 done
[2022-08-05T19:41:21.028] sched: Allocate JobId=46947 NodeList=cpu13 #CPUs=32 Partition=cpu-epyc
[2022-08-05T19:42:20.655] _slurm_rpc_submit_batch_job: JobId=47651 InitPrio=19863 usec=438
[2022-08-05T19:42:46.999] _slurm_rpc_submit_batch_job: JobId=47652 InitPrio=19982 usec=428
[2022-08-05T19:42:50.056] sched/backfill: _start_job: Started JobId=47652 in cpu-opteron on cpu09
[2022-08-05T19:42:52.959] _job_complete: JobId=47652 WEXITSTATUS 0
[2022-08-05T19:42:52.959] _job_complete: JobId=47652 done
[2022-08-05T19:43:09.274] _slurm_rpc_kill_job: REQUEST_KILL_JOB JobId=47651 uid 548200021
[2022-08-05T19:43:16.971] _slurm_rpc_kill_job: REQUEST_KILL_JOB JobId=47652 uid 548200021
[2022-08-05T19:52:33.999] _slurm_rpc_submit_batch_job: JobId=47653 InitPrio=19863 usec=381
[2022-08-05T19:54:01.682] _slurm_rpc_kill_job: REQUEST_KILL_JOB JobId=47653 uid 548200021
[2022-08-05T19:54:18.669] _slurm_rpc_submit_batch_job: JobId=47654 InitPrio=19965 usec=378
[2022-08-05T19:54:50.101] sched/backfill: _start_job: Started JobId=47654 in cpu-opteron on cpu09
[2022-08-05T19:54:51.473] _job_complete: JobId=47654 WEXITSTATUS 1
[2022-08-05T19:54:51.473] _job_complete: JobId=47654 done
[2022-08-05T19:55:01.798] _slurm_rpc_submit_batch_job: JobId=47655 InitPrio=19965 usec=485
[2022-08-05T19:55:50.105] sched/backfill: _start_job: Started JobId=47655 in cpu-epyc on cpu14
[2022-08-05T19:55:51.611] _job_complete: JobId=47655 WEXITSTATUS 1
[2022-08-05T19:55:51.611] _job_complete: JobId=47655 done
[2022-08-05T19:58:19.458] _slurm_rpc_submit_batch_job: JobId=47656 InitPrio=19965 usec=459
[2022-08-05T19:58:50.116] sched/backfill: _start_job: Started JobId=47656 in cpu-epyc on cpu14
[2022-08-05T19:58:51.088] _job_complete: JobId=47656 WEXITSTATUS 1
[2022-08-05T19:58:51.088] _job_complete: JobId=47656 done
[2022-08-05T19:59:42.875] _slurm_rpc_submit_batch_job: JobId=47657 InitPrio=19965 usec=470
[2022-08-05T19:59:50.121] sched/backfill: _start_job: Started JobId=47657 in cpu-epyc on cpu14
[2022-08-05T19:59:51.211] _job_complete: JobId=47657 WEXITSTATUS 1
[2022-08-05T19:59:51.211] _job_complete: JobId=47657 done
[2022-08-05T20:00:42.339] _slurm_rpc_submit_batch_job: JobId=47658 InitPrio=19982 usec=555
[2022-08-05T20:00:50.125] sched/backfill: _start_job: Started JobId=47658 in cpu-opteron on cpu09
[2022-08-05T20:00:52.709] _job_complete: JobId=47658 WEXITSTATUS 0
[2022-08-05T20:00:52.709] _job_complete: JobId=47658 done
[2022-08-05T20:02:51.457] _slurm_rpc_submit_batch_job: JobId=47659 InitPrio=19965 usec=781
[2022-08-05T20:03:50.136] sched/backfill: _start_job: Started JobId=47659 in cpu-epyc on cpu14
[2022-08-05T20:03:51.380] _job_complete: JobId=47659 WEXITSTATUS 1
[2022-08-05T20:03:51.380] _job_complete: JobId=47659 done
[2022-08-05T20:05:04.391] _slurm_rpc_submit_batch_job: JobId=47660 InitPrio=19965 usec=428
[2022-08-05T20:05:50.146] sched/backfill: _start_job: Started JobId=47660 in cpu-epyc on cpu14
[2022-08-05T20:05:51.300] _job_complete: JobId=47660 WEXITSTATUS 1
[2022-08-05T20:05:51.300] _job_complete: JobId=47660 done
[2022-08-05T20:16:17.941] _job_complete: JobId=47525 WEXITSTATUS 0
[2022-08-05T20:16:17.941] _job_complete: JobId=47525 done
[2022-08-05T20:16:18.520] sched: Allocate JobId=47526 NodeList=cpu11 #CPUs=16 Partition=cpu-opteron
[2022-08-05T21:35:32.359] _job_complete: JobId=47526 WEXITSTATUS 0
[2022-08-05T21:35:32.359] _job_complete: JobId=47526 done
[2022-08-05T21:35:32.915] sched: Allocate JobId=47527 NodeList=cpu11 #CPUs=16 Partition=cpu-opteron
[2022-08-05T21:44:30.542] _job_complete: JobId=47124 WEXITSTATUS 1
[2022-08-05T21:44:30.542] _job_complete: JobId=47124 done
[2022-08-05T21:44:31.400] sched: Allocate JobId=47528 NodeList=cpu03 #CPUs=16 Partition=cpu-opteron
[2022-08-05T21:44:32.266] _job_complete: JobId=47528 WEXITSTATUS 1
[2022-08-05T21:44:32.266] _job_complete: JobId=47528 done
[2022-08-05T21:44:33.036] sched: Allocate JobId=47529 NodeList=cpu03 #CPUs=16 Partition=cpu-opteron
[2022-08-05T22:43:08.325] _job_complete: JobId=47527 WEXITSTATUS 0
[2022-08-05T22:43:08.325] _job_complete: JobId=47527 done
[2022-08-05T22:43:08.871] sched: Allocate JobId=47530 NodeList=cpu11 #CPUs=16 Partition=cpu-opteron
[2022-08-05T23:01:37.167] _job_complete: JobId=46876 WEXITSTATUS 0
[2022-08-05T23:01:37.172] _job_complete: JobId=46876 done
[2022-08-05T23:01:40.038] sched: Allocate JobId=46948 NodeList=cpu14 #CPUs=32 Partition=cpu-epyc
[2022-08-05T23:29:52.685] _job_complete: JobId=47529 WEXITSTATUS 0
[2022-08-05T23:29:52.685] _job_complete: JobId=47529 done
[2022-08-06T00:18:31.780] _job_complete: JobId=46946 WEXITSTATUS 0
[2022-08-06T00:18:31.780] _job_complete: JobId=46946 done
[2022-08-06T00:18:32.044] sched: Allocate JobId=46918 NodeList=cpu12 #CPUs=24 Partition=cpu-epyc
[2022-08-06T01:42:43.781] _job_complete: JobId=47119 WEXITSTATUS 0
[2022-08-06T01:42:43.782] _job_complete: JobId=47119 done
[2022-08-06T01:42:51.354] sched/backfill: _start_job: Started JobId=47531 in cpu-opteron on cpu10
[2022-08-06T01:47:12.977] _job_complete: JobId=47530 WEXITSTATUS 0
[2022-08-06T01:47:12.977] _job_complete: JobId=47530 done
[2022-08-06T01:47:51.371] sched/backfill: _start_job: Started JobId=47641 in cpu-opteron on cpu11
[2022-08-06T02:52:30.828] _slurm_rpc_submit_batch_job: JobId=47661 InitPrio=22494 usec=983
[2022-08-06T02:53:28.122] _slurm_rpc_kill_job: REQUEST_KILL_JOB JobId=47661 uid 548200029
[2022-08-06T02:55:26.999] _slurm_rpc_submit_batch_job: JobId=47662 InitPrio=22494 usec=1066
[2022-08-06T02:55:49.068] _slurm_rpc_kill_job: REQUEST_KILL_JOB JobId=47662 uid 548200029
[2022-08-06T02:56:12.373] _slurm_rpc_submit_batch_job: JobId=47663 InitPrio=22494 usec=986
[2022-08-06T09:02:54.079] _slurm_rpc_submit_batch_job: JobId=47664 InitPrio=19462 usec=468
[2022-08-06T09:06:33.577] _slurm_rpc_submit_batch_job: JobId=47665 InitPrio=19531 usec=402
[2022-08-06T09:49:53.045] _job_complete: JobId=46947 WEXITSTATUS 0
[2022-08-06T09:49:53.045] _job_complete: JobId=46947 done
[2022-08-06T09:49:53.292] sched: Allocate JobId=47374 NodeList=cpu13 #CPUs=32 Partition=cpu-epyc
[2022-08-06T12:04:51.409] _job_complete: JobId=46948 WEXITSTATUS 0
[2022-08-06T12:04:51.410] _job_complete: JobId=46948 done
[2022-08-06T12:04:51.668] sched: Allocate JobId=47518 NodeList=cpu14 #CPUs=16 Partition=cpu-epyc
[2022-08-06T12:04:56.971] _job_complete: JobId=47518 WEXITSTATUS 1
[2022-08-06T12:04:56.972] _job_complete: JobId=47518 done
[2022-08-06T12:04:57.247] sched: Allocate JobId=47426 NodeList=cpu14 #CPUs=24 Partition=cpu-epyc
[2022-08-06T12:25:50.791] _slurm_rpc_kill_job: REQUEST_KILL_JOB JobId=47426 uid 548200045
[2022-08-06T12:25:52.664] sched: Allocate JobId=47665 NodeList=cpu14 #CPUs=24 Partition=cpu-epyc
[2022-08-06T12:27:30.863] _slurm_rpc_submit_batch_job: JobId=47666 InitPrio=20320 usec=512
[2022-08-06T12:28:17.481] _slurm_rpc_kill_job: REQUEST_KILL_JOB JobId=47666 uid 548200045
[2022-08-06T12:28:28.644] _slurm_rpc_submit_batch_job: JobId=47667 InitPrio=20389 usec=427
[2022-08-06T12:28:42.063] _slurm_rpc_kill_job: REQUEST_KILL_JOB JobId=47667 uid 548200045
[2022-08-06T12:28:54.730] _slurm_rpc_submit_batch_job: JobId=47668 InitPrio=20320 usec=553
[2022-08-06T15:06:48.524] _slurm_rpc_submit_batch_job: JobId=47669 InitPrio=31178 usec=497
[2022-08-06T17:20:12.545] _slurm_rpc_kill_job: REQUEST_KILL_JOB JobId=47542 uid 548200045
[2022-08-06T17:20:14.467] sched: Allocate JobId=47669 NodeList=gpu02 #CPUs=16 Partition=gpu-titan
[2022-08-06T17:20:16.366] _job_complete: JobId=47669 WEXITSTATUS 127
[2022-08-06T17:20:16.367] _job_complete: JobId=47669 done
[2022-08-06T17:20:52.544] _slurm_rpc_submit_batch_job: JobId=47670 InitPrio=20457 usec=465
[2022-08-06T17:20:53.088] sched: Allocate JobId=47670 NodeList=gpu02 #CPUs=8 Partition=gpu-titan
[2022-08-06T18:30:36.209] _slurm_rpc_submit_batch_job: JobId=47671 InitPrio=19462 usec=410
[2022-08-06T19:17:02.815] _slurm_rpc_submit_batch_job: JobId=47672 InitPrio=30915 usec=479
[2022-08-06T20:01:08.012] _slurm_rpc_kill_job: REQUEST_KILL_JOB JobId=47670 uid 548200045
[2022-08-06T20:01:09.958] sched: Allocate JobId=47672 NodeList=gpu02 #CPUs=16 Partition=gpu-titan
[2022-08-06T20:01:12.019] _job_complete: JobId=47672 WEXITSTATUS 127
[2022-08-06T20:01:12.020] _job_complete: JobId=47672 done
[2022-08-06T20:01:44.586] _slurm_rpc_submit_batch_job: JobId=47673 InitPrio=20457 usec=461
[2022-08-06T20:01:45.585] sched: Allocate JobId=47673 NodeList=gpu02 #CPUs=8 Partition=gpu-titan
[2022-08-06T20:11:24.302] _job_complete: JobId=47325 WEXITSTATUS 0
[2022-08-06T20:11:24.302] _job_complete: JobId=47325 done
[2022-08-06T20:11:26.306] sched: Allocate JobId=47640 NodeList=cpu03 #CPUs=32 Partition=cpu-opteron
[2022-08-06T20:16:14.662] _job_complete: JobId=47640 WEXITSTATUS 1
[2022-08-06T20:16:14.662] _job_complete: JobId=47640 done
[2022-08-06T20:16:54.915] sched/backfill: _start_job: Started JobId=47642 in cpu-opteron on cpu03
[2022-08-07T01:02:01.507] _job_complete: JobId=47374 WEXITSTATUS 0
[2022-08-07T01:02:01.507] _job_complete: JobId=47374 done
[2022-08-07T01:02:01.755] sched: Allocate JobId=47668 NodeList=cpu13 #CPUs=24 Partition=cpu-epyc
[2022-08-07T10:09:35.796] _slurm_rpc_submit_batch_job: JobId=47674 InitPrio=22357 usec=447
[2022-08-07T10:12:40.660] _slurm_rpc_submit_batch_job: JobId=47675 InitPrio=22357 usec=469
[2022-08-07T10:15:14.793] _slurm_rpc_submit_batch_job: JobId=47676 InitPrio=22357 usec=447
[2022-08-07T10:17:35.940] _slurm_rpc_submit_batch_job: JobId=47677 InitPrio=22357 usec=410
[2022-08-07T14:49:41.132] _slurm_rpc_submit_batch_job: JobId=47678 InitPrio=20320 usec=432
[2022-08-07T14:52:30.642] _slurm_rpc_kill_job: REQUEST_KILL_JOB JobId=47678 uid 548200045
[2022-08-07T14:52:50.625] _slurm_rpc_submit_batch_job: JobId=47679 InitPrio=20457 usec=462
[2022-08-07T14:52:57.385] sched/backfill: _start_job: Started JobId=47679 in cpu-epyc on cpu12
[2022-08-07T14:53:08.295] _slurm_rpc_kill_job: REQUEST_KILL_JOB JobId=47679 uid 548200045
[2022-08-07T14:55:16.807] _job_complete: JobId=47641 WEXITSTATUS 0
[2022-08-07T14:55:16.807] _job_complete: JobId=47641 done
[2022-08-07T20:55:14.629] _job_complete: JobId=47531 WEXITSTATUS 0
[2022-08-07T20:55:14.629] _job_complete: JobId=47531 done
[2022-08-08T00:26:58.561] _slurm_rpc_submit_batch_job: JobId=47680 InitPrio=23878 usec=568
[2022-08-08T00:26:58.633] sched: Allocate JobId=47680 NodeList=cpu03 #CPUs=8 Partition=cpu-opteron
[2022-08-08T00:32:06.799] _job_complete: JobId=47680 WEXITSTATUS 0
[2022-08-08T00:32:06.799] _job_complete: JobId=47680 done
[2022-08-08T00:44:50.743] _slurm_rpc_submit_batch_job: JobId=47681 InitPrio=21773 usec=453
[2022-08-08T00:44:59.316] sched/backfill: _start_job: Started JobId=47681 in cpu-opteron on cpu03
[2022-08-08T00:47:49.218] _job_complete: JobId=47681 WEXITSTATUS 1
[2022-08-08T00:47:49.218] _job_complete: JobId=47681 done
[2022-08-08T10:21:13.401] sched: _slurm_rpc_allocate_resources JobId=47682 NodeList=(null) usec=965
[2022-08-08T10:21:13.871] sched: Allocate JobId=47682 NodeList=cpu03 #CPUs=1 Partition=cpu-opteron
[2022-08-08T10:21:18.917] _job_complete: JobId=47682 WEXITSTATUS 0
[2022-08-08T10:21:18.918] _job_complete: JobId=47682 done
[2022-08-08T10:39:09.698] _slurm_rpc_submit_batch_job: JobId=47683 InitPrio=21968 usec=512
[2022-08-08T10:40:01.250] sched/backfill: _start_job: Started JobId=47683 in cpu-opteron on cpu03
[2022-08-08T10:46:43.639] _slurm_rpc_submit_batch_job: JobId=47684 InitPrio=22094 usec=397
[2022-08-08T10:47:24.718] _slurm_rpc_submit_batch_job: JobId=47685 InitPrio=25583 usec=508
[2022-08-08T10:47:51.459] _slurm_rpc_kill_job: REQUEST_KILL_JOB JobId=47685 uid 548300543
[2022-08-08T10:48:12.702] _slurm_rpc_submit_batch_job: JobId=47686 InitPrio=25584 usec=468
[2022-08-08T10:48:28.803] _slurm_rpc_kill_job: REQUEST_KILL_JOB JobId=47686 uid 548300543
[2022-08-08T10:48:54.552] _slurm_rpc_submit_batch_job: JobId=47687 InitPrio=25652 usec=522
[2022-08-08T10:48:54.872] sched: Allocate JobId=47687 NodeList=cpu10 #CPUs=16 Partition=cpu-opteron
[2022-08-08T10:48:57.930] _job_complete: JobId=47687 WEXITSTATUS 0
[2022-08-08T10:48:57.930] _job_complete: JobId=47687 done
[2022-08-08T10:49:27.166] _slurm_rpc_submit_batch_job: JobId=47688 InitPrio=22094 usec=410
[2022-08-08T10:51:18.978] _slurm_rpc_submit_batch_job: JobId=47689 InitPrio=25652 usec=494
[2022-08-08T10:51:19.057] sched: Allocate JobId=47689 NodeList=cpu10 #CPUs=16 Partition=cpu-opteron
[2022-08-08T10:51:56.865] _job_complete: JobId=47689 WEXITSTATUS 0
[2022-08-08T10:51:56.866] _job_complete: JobId=47689 done
[2022-08-08T11:43:52.907] _slurm_rpc_submit_batch_job: JobId=47690 InitPrio=21773 usec=450
[2022-08-08T11:44:01.520] sched/backfill: _start_job: Started JobId=47690 in cpu-opteron on cpu10
[2022-08-08T12:51:00.213] _job_complete: JobId=47683 WEXITSTATUS 0
[2022-08-08T12:51:00.213] _job_complete: JobId=47683 done
[2022-08-08T13:12:05.683] _slurm_rpc_submit_batch_job: JobId=47691 InitPrio=25652 usec=494
[2022-08-08T13:12:06.506] sched: Allocate JobId=47691 NodeList=cpu03 #CPUs=16 Partition=cpu-opteron
[2022-08-08T13:12:10.723] _job_complete: JobId=47691 WEXITSTATUS 0
[2022-08-08T13:12:10.723] _job_complete: JobId=47691 done
[2022-08-08T13:13:07.579] _slurm_rpc_submit_batch_job: JobId=47692 InitPrio=25652 usec=405
[2022-08-08T13:13:07.659] sched: Allocate JobId=47692 NodeList=cpu03 #CPUs=16 Partition=cpu-opteron
[2022-08-08T13:13:11.702] _job_complete: JobId=47692 WEXITSTATUS 0
[2022-08-08T13:13:11.702] _job_complete: JobId=47692 done
[2022-08-08T13:27:30.585] _slurm_rpc_submit_batch_job: JobId=47693 InitPrio=25652 usec=494
[2022-08-08T13:27:31.016] sched: Allocate JobId=47693 NodeList=cpu03 #CPUs=16 Partition=cpu-opteron
[2022-08-08T13:27:35.641] _job_complete: JobId=47693 WEXITSTATUS 0
[2022-08-08T13:27:35.641] _job_complete: JobId=47693 done
[2022-08-08T13:37:42.740] _slurm_rpc_submit_batch_job: JobId=47694 InitPrio=25652 usec=420
[2022-08-08T13:37:43.109] sched: Allocate JobId=47694 NodeList=cpu03 #CPUs=16 Partition=cpu-opteron
[2022-08-08T13:37:47.280] _job_complete: JobId=47694 WEXITSTATUS 0
[2022-08-08T13:37:47.280] _job_complete: JobId=47694 done
[2022-08-08T13:55:36.410] _slurm_rpc_submit_batch_job: JobId=47695 InitPrio=21761 usec=478
[2022-08-08T13:56:02.047] sched/backfill: _start_job: Started JobId=47695 in cpu-opteron on cpu03
[2022-08-08T13:56:02.789] _job_complete: JobId=47695 WEXITSTATUS 1
[2022-08-08T13:56:02.789] _job_complete: JobId=47695 done
[2022-08-08T14:00:41.003] _slurm_rpc_submit_batch_job: JobId=47696 InitPrio=21761 usec=472
[2022-08-08T14:01:02.066] sched/backfill: _start_job: Started JobId=47696 in cpu-opteron on cpu03
[2022-08-08T14:01:02.838] _job_complete: JobId=47696 WEXITSTATUS 1
[2022-08-08T14:01:02.838] _job_complete: JobId=47696 done
[2022-08-08T14:01:24.197] _slurm_rpc_submit_batch_job: JobId=47697 InitPrio=21761 usec=497
[2022-08-08T14:02:02.070] sched/backfill: _start_job: Started JobId=47697 in cpu-opteron on cpu03
[2022-08-08T14:02:02.775] _job_complete: JobId=47697 WEXITSTATUS 1
[2022-08-08T14:02:02.775] _job_complete: JobId=47697 done
[2022-08-08T14:06:07.264] _slurm_rpc_submit_batch_job: JobId=47698 InitPrio=21748 usec=464
[2022-08-08T14:07:02.093] sched/backfill: _start_job: Started JobId=47698 in cpu-opteron on cpu03
[2022-08-08T14:07:17.460] _job_complete: JobId=47698 WEXITSTATUS 1
[2022-08-08T14:07:17.460] _job_complete: JobId=47698 done
[2022-08-08T14:07:56.371] _slurm_rpc_submit_batch_job: JobId=47699 InitPrio=21724 usec=418
[2022-08-08T14:08:02.097] sched/backfill: _start_job: Started JobId=47699 in cpu-opteron on cpu03
[2022-08-08T14:10:51.851] _job_complete: JobId=47699 WEXITSTATUS 1
[2022-08-08T14:10:51.851] _job_complete: JobId=47699 done
[2022-08-08T14:27:38.273] _slurm_rpc_submit_batch_job: JobId=47700 InitPrio=21712 usec=496
[2022-08-08T14:28:02.173] sched/backfill: _start_job: Started JobId=47700 in cpu-opteron on cpu03
[2022-08-08T14:28:15.999] _job_complete: JobId=47700 WEXITSTATUS 1
[2022-08-08T14:28:15.999] _job_complete: JobId=47700 done
[2022-08-08T14:29:17.067] _slurm_rpc_submit_batch_job: JobId=47701 InitPrio=21712 usec=462
[2022-08-08T14:30:02.181] sched/backfill: _start_job: Started JobId=47701 in cpu-opteron on cpu03
[2022-08-08T14:33:01.903] _job_complete: JobId=47701 WEXITSTATUS 1
[2022-08-08T14:33:01.903] _job_complete: JobId=47701 done
[2022-08-08T14:42:36.503] _slurm_rpc_submit_batch_job: JobId=47702 InitPrio=21712 usec=481
[2022-08-08T14:43:02.232] sched/backfill: _start_job: Started JobId=47702 in cpu-opteron on cpu03
[2022-08-08T14:46:03.249] _job_complete: JobId=47702 WEXITSTATUS 1
[2022-08-08T14:46:03.249] _job_complete: JobId=47702 done
[2022-08-08T15:24:08.747] _slurm_rpc_submit_batch_job: JobId=47703 InitPrio=20312 usec=413
[2022-08-08T15:38:19.708] _slurm_rpc_kill_job: REQUEST_KILL_JOB JobId=47703 uid 548200019
[2022-08-08T15:38:35.732] _slurm_rpc_submit_batch_job: JobId=47704 InitPrio=20312 usec=492
[2022-08-08T19:20:15.092] _job_complete: JobId=47690 WEXITSTATUS 0
[2022-08-08T19:20:15.092] _job_complete: JobId=47690 done
[2022-08-09T06:20:43.830] _job_complete: JobId=47516 WEXITSTATUS 0
[2022-08-09T06:20:43.836] _job_complete: JobId=47516 done
[2022-08-09T08:45:50.792] _slurm_rpc_submit_batch_job: JobId=47705 InitPrio=21336 usec=539
[2022-08-09T08:45:50.914] sched: Allocate JobId=47705 NodeList=gpu04 #CPUs=16 Partition=gpu-k40c
[2022-08-09T10:39:25.463] _slurm_rpc_submit_batch_job: JobId=47706 InitPrio=21949 usec=466
[2022-08-09T10:39:28.014] _slurm_rpc_submit_batch_job: JobId=47707 InitPrio=21949 usec=452
[2022-08-09T10:39:30.470] _slurm_rpc_submit_batch_job: JobId=47708 InitPrio=21949 usec=453
[2022-08-09T10:39:34.486] _slurm_rpc_submit_batch_job: JobId=47709 InitPrio=21949 usec=436
[2022-08-09T10:52:31.871] _slurm_rpc_submit_batch_job: JobId=47710 InitPrio=21936 usec=447
[2022-08-09T10:52:34.772] _slurm_rpc_submit_batch_job: JobId=47711 InitPrio=21936 usec=415
[2022-08-09T10:52:37.844] _slurm_rpc_submit_batch_job: JobId=47712 InitPrio=21936 usec=438
[2022-08-09T11:21:01.833] sched: _slurm_rpc_allocate_resources JobId=47713 NodeList=(null) usec=757
[2022-08-09T11:21:02.642] sched: Allocate JobId=47713 NodeList=cpu03 #CPUs=1 Partition=cpu-opteron
[2022-08-09T12:19:28.051] _slurm_rpc_submit_batch_job: JobId=47714 InitPrio=23452 usec=473
[2022-08-09T12:19:28.588] sched: Allocate JobId=47714 NodeList=cpu12 #CPUs=8 Partition=cpu-epyc
[2022-08-09T12:19:33.375] _job_complete: JobId=47714 WEXITSTATUS 0
[2022-08-09T12:19:33.375] _job_complete: JobId=47714 done
[2022-08-09T12:59:25.149] _job_complete: JobId=47713 WEXITSTATUS 0
[2022-08-09T12:59:25.149] _job_complete: JobId=47713 done
[2022-08-09T15:56:17.022] _pick_best_nodes: JobId=47715 never runnable in partition gpu-v100s
[2022-08-09T15:56:17.027] _slurm_rpc_submit_batch_job: Requested node configuration is not available
[2022-08-09T15:58:38.862] _pick_best_nodes: JobId=47716 never runnable in partition gpu-v100s
[2022-08-09T15:58:38.862] _slurm_rpc_submit_batch_job: Requested node configuration is not available
[2022-08-09T15:59:22.389] _pick_best_nodes: JobId=47717 never runnable in partition gpu-v100s
[2022-08-09T15:59:22.390] _slurm_rpc_submit_batch_job: Requested node configuration is not available
[2022-08-09T16:02:55.352] _slurm_rpc_submit_batch_job: JobId=47718 InitPrio=28687 usec=435
[2022-08-09T16:19:35.739] _slurm_rpc_submit_batch_job: JobId=47719 InitPrio=21205 usec=517
[2022-08-09T17:07:01.179] _slurm_rpc_submit_batch_job: JobId=47720 InitPrio=19812 usec=436
[2022-08-09T17:07:08.292] sched/backfill: _start_job: Started JobId=47720 in gpu-k10 on gpu01
[2022-08-09T17:40:22.795] _slurm_rpc_kill_job: REQUEST_KILL_JOB JobId=47720 uid 548200021
[2022-08-09T17:41:18.279] _slurm_rpc_submit_batch_job: JobId=47721 InitPrio=19812 usec=490
[2022-08-09T18:19:15.093] _slurm_rpc_submit_batch_job: JobId=47722 InitPrio=23452 usec=505
[2022-08-09T18:19:15.126] sched: Allocate JobId=47722 NodeList=cpu12 #CPUs=8 Partition=cpu-epyc
[2022-08-09T18:19:20.638] _job_complete: JobId=47722 WEXITSTATUS 0
[2022-08-09T18:19:20.638] _job_complete: JobId=47722 done
[2022-08-09T18:24:23.571] _slurm_rpc_kill_job: REQUEST_KILL_JOB JobId=47673 uid 548200045
[2022-08-09T18:31:01.410] _slurm_rpc_submit_batch_job: JobId=47723 InitPrio=23452 usec=453
[2022-08-09T18:31:02.282] sched: Allocate JobId=47723 NodeList=cpu12 #CPUs=8 Partition=cpu-epyc
[2022-08-09T18:31:07.801] _job_complete: JobId=47723 WEXITSTATUS 0
[2022-08-09T18:31:07.801] _job_complete: JobId=47723 done
[2022-08-09T18:50:32.161] _slurm_rpc_submit_batch_job: JobId=47724 InitPrio=23452 usec=451
[2022-08-09T18:50:32.380] sched: Allocate JobId=47724 NodeList=cpu12 #CPUs=8 Partition=cpu-epyc
[2022-08-09T18:50:35.888] _job_complete: JobId=47724 WEXITSTATUS 0
[2022-08-09T18:50:35.888] _job_complete: JobId=47724 done
[2022-08-09T19:18:22.449] _slurm_rpc_submit_batch_job: JobId=47725 InitPrio=20357 usec=454
[2022-08-09T19:18:23.390] sched: Allocate JobId=47725 NodeList=gpu02 #CPUs=8 Partition=gpu-titan
[2022-08-09T19:28:27.749] _slurm_rpc_submit_batch_job: JobId=47726 InitPrio=23452 usec=493
[2022-08-09T19:28:28.405] sched: Allocate JobId=47726 NodeList=cpu12 #CPUs=8 Partition=cpu-epyc
[2022-08-09T19:28:32.895] _job_complete: JobId=47726 WEXITSTATUS 0
[2022-08-09T19:28:32.895] _job_complete: JobId=47726 done
[2022-08-09T19:41:25.974] _slurm_rpc_submit_batch_job: JobId=47727 InitPrio=23452 usec=404
[2022-08-09T19:41:26.752] sched: Allocate JobId=47727 NodeList=cpu12 #CPUs=8 Partition=cpu-epyc
[2022-08-09T19:41:30.870] _job_complete: JobId=47727 WEXITSTATUS 0
[2022-08-09T19:41:30.870] _job_complete: JobId=47727 done
[2022-08-09T19:53:00.388] _slurm_rpc_submit_batch_job: JobId=47728 InitPrio=23452 usec=452
[2022-08-09T19:53:01.019] sched: Allocate JobId=47728 NodeList=cpu12 #CPUs=8 Partition=cpu-epyc
[2022-08-09T19:53:39.773] _job_complete: JobId=47728 WEXITSTATUS 0
[2022-08-09T19:53:39.773] _job_complete: JobId=47728 done
[2022-08-09T20:08:20.741] _slurm_rpc_submit_batch_job: JobId=47729 InitPrio=23452 usec=462
[2022-08-09T20:08:21.590] sched: Allocate JobId=47729 NodeList=cpu12 #CPUs=8 Partition=cpu-epyc
[2022-08-09T20:25:45.515] _slurm_rpc_submit_batch_job: JobId=47730 InitPrio=23452 usec=563
[2022-08-09T20:25:46.301] sched: Allocate JobId=47730 NodeList=cpu13 #CPUs=8 Partition=cpu-epyc
[2022-08-09T20:26:27.285] _job_complete: JobId=47730 WEXITSTATUS 0
[2022-08-09T20:26:27.285] _job_complete: JobId=47730 done
[2022-08-09T20:36:57.456] _slurm_rpc_submit_batch_job: JobId=47731 InitPrio=23452 usec=449
[2022-08-09T20:36:57.657] sched: Allocate JobId=47731 NodeList=cpu13 #CPUs=8 Partition=cpu-epyc
[2022-08-09T20:53:30.595] _slurm_rpc_submit_batch_job: JobId=47732 InitPrio=23452 usec=390
[2022-08-09T20:53:31.498] sched: Allocate JobId=47732 NodeList=cpu14 #CPUs=8 Partition=cpu-epyc
[2022-08-09T20:53:37.213] _job_complete: JobId=47732 WEXITSTATUS 0
[2022-08-09T20:53:37.213] _job_complete: JobId=47732 done
[2022-08-09T20:56:30.582] _job_complete: JobId=47729 WEXITSTATUS 0
[2022-08-09T20:56:30.582] _job_complete: JobId=47729 done
[2022-08-09T21:07:47.196] _slurm_rpc_submit_batch_job: JobId=47733 InitPrio=23452 usec=414
[2022-08-09T21:07:47.911] sched: Allocate JobId=47733 NodeList=cpu12 #CPUs=8 Partition=cpu-epyc
[2022-08-09T21:08:35.594] _job_complete: JobId=47733 WEXITSTATUS 0
[2022-08-09T21:08:35.594] _job_complete: JobId=47733 done
[2022-08-09T21:32:11.634] _job_complete: JobId=47731 WEXITSTATUS 0
[2022-08-09T21:32:11.634] _job_complete: JobId=47731 done
[2022-08-09T22:23:11.454] _slurm_rpc_submit_batch_job: JobId=47734 InitPrio=23452 usec=454
[2022-08-09T22:23:12.006] sched: Allocate JobId=47734 NodeList=cpu12 #CPUs=8 Partition=cpu-epyc
[2022-08-09T22:54:16.854] _slurm_rpc_submit_batch_job: JobId=47735 InitPrio=23452 usec=468
[2022-08-09T22:54:17.328] sched: Allocate JobId=47735 NodeList=cpu13 #CPUs=8 Partition=cpu-epyc
[2022-08-09T22:55:01.757] _job_complete: JobId=47735 WEXITSTATUS 0
[2022-08-09T22:55:01.757] _job_complete: JobId=47735 done
[2022-08-09T23:08:46.621] _job_complete: JobId=47734 WEXITSTATUS 0
[2022-08-09T23:08:46.621] _job_complete: JobId=47734 done
[2022-08-09T23:11:23.849] _slurm_rpc_submit_batch_job: JobId=47736 InitPrio=23452 usec=381
[2022-08-09T23:11:24.133] sched: Allocate JobId=47736 NodeList=cpu12 #CPUs=8 Partition=cpu-epyc
[2022-08-09T23:52:38.277] _slurm_rpc_submit_batch_job: JobId=47737 InitPrio=23452 usec=448
[2022-08-09T23:52:38.389] sched: Allocate JobId=47737 NodeList=cpu13 #CPUs=8 Partition=cpu-epyc
[2022-08-09T23:52:44.520] _job_complete: JobId=47737 WEXITSTATUS 0
[2022-08-09T23:52:44.520] _job_complete: JobId=47737 done
[2022-08-09T23:56:35.414] _job_complete: JobId=47736 WEXITSTATUS 0
[2022-08-09T23:56:35.414] _job_complete: JobId=47736 done
[2022-08-10T00:12:38.833] _slurm_rpc_submit_batch_job: JobId=47738 InitPrio=23452 usec=479
[2022-08-10T00:12:39.620] sched: Allocate JobId=47738 NodeList=cpu12 #CPUs=8 Partition=cpu-epyc
[2022-08-10T00:13:23.444] _job_complete: JobId=47738 WEXITSTATUS 0
[2022-08-10T00:13:23.444] _job_complete: JobId=47738 done
[2022-08-10T00:25:17.719] _slurm_rpc_submit_batch_job: JobId=47739 InitPrio=23452 usec=422
[2022-08-10T00:25:17.931] sched: Allocate JobId=47739 NodeList=cpu12 #CPUs=8 Partition=cpu-epyc
[2022-08-10T00:35:54.220] _slurm_rpc_submit_batch_job: JobId=47740 InitPrio=23452 usec=432
[2022-08-10T00:35:55.002] sched: Allocate JobId=47740 NodeList=cpu13 #CPUs=8 Partition=cpu-epyc
[2022-08-10T00:36:37.667] _job_complete: JobId=47740 WEXITSTATUS 0
[2022-08-10T00:36:37.667] _job_complete: JobId=47740 done
[2022-08-10T01:01:08.227] _slurm_rpc_submit_batch_job: JobId=47741 InitPrio=23452 usec=507
[2022-08-10T01:01:08.518] sched: Allocate JobId=47741 NodeList=cpu13 #CPUs=8 Partition=cpu-epyc
[2022-08-10T01:22:43.085] _job_complete: JobId=47739 WEXITSTATUS 0
[2022-08-10T01:22:43.085] _job_complete: JobId=47739 done
[2022-08-10T01:46:32.387] _job_complete: JobId=47741 WEXITSTATUS 0
[2022-08-10T01:46:32.387] _job_complete: JobId=47741 done
[2022-08-10T05:10:25.134] _job_complete: JobId=47642 WEXITSTATUS 0
[2022-08-10T05:10:25.134] _job_complete: JobId=47642 done
[2022-08-10T05:11:11.163] sched/backfill: _start_job: Started JobId=47674 in cpu-opteron on cpu03
[2022-08-10T05:11:14.119] _job_complete: JobId=47674 WEXITSTATUS 1
[2022-08-10T05:11:14.120] _job_complete: JobId=47674 done
[2022-08-10T05:12:11.169] sched/backfill: _start_job: Started JobId=47675 in cpu-opteron on cpu03
[2022-08-10T05:12:13.404] _job_complete: JobId=47675 WEXITSTATUS 1
[2022-08-10T05:12:13.405] _job_complete: JobId=47675 done
[2022-08-10T05:13:11.173] sched/backfill: _start_job: Started JobId=47676 in cpu-opteron on cpu03
[2022-08-10T05:13:13.800] _job_complete: JobId=47676 WEXITSTATUS 1
[2022-08-10T05:13:13.801] _job_complete: JobId=47676 done
[2022-08-10T05:14:11.178] sched/backfill: _start_job: Started JobId=47677 in cpu-opteron on cpu03
[2022-08-10T05:14:12.102] _job_complete: JobId=47677 WEXITSTATUS 1
[2022-08-10T05:14:12.102] _job_complete: JobId=47677 done
[2022-08-10T05:43:31.240] Time limit exhausted for JobId=46755
[2022-08-10T08:52:27.381] _slurm_rpc_delete_reservation complete for biovia_test_opt usec=58
[2022-08-10T08:52:28.936] _slurm_rpc_delete_reservation complete for biovia_test usec=50
[2022-08-10T08:53:49.061] Reservation requested both users and groups, these are mutually exclusive.  You can have one or the other, but not both.
[2022-08-10T08:53:49.061] _slurm_rpc_resv_update reservation=user_training: Reservations can't have users and groups specified, only one or the other
[2022-08-10T08:54:44.933] sched: Updated reservation=user_training users=jitkang,yeehengteh nodes=cpu04 cores=64 licenses=(null) tres=cpu=64 watts=4294967294 start=2022-08-10T10:00:00 end=2022-08-10T18:00:00 MaxStartDelay=
[2022-08-10T08:55:16.061] sched: Updated reservation=user_training users=jitkang,yeehengteh nodes=cpu08 cores=64 licenses=(null) tres=cpu=64 watts=4294967294 start=2022-08-10T10:00:00 end=2022-08-10T18:00:00 MaxStartDelay=
[2022-08-10T09:31:28.571] sched: _slurm_rpc_allocate_resources JobId=47742 NodeList=(null) usec=741
[2022-08-10T09:31:28.657] sched: Allocate JobId=47742 NodeList=cpu03 #CPUs=1 Partition=cpu-opteron
[2022-08-10T09:41:22.604] _slurm_rpc_kill_job: REQUEST_KILL_JOB JobId=47725 uid 548200045
[2022-08-10T09:44:11.538] _slurm_rpc_submit_batch_job: JobId=47743 InitPrio=20353 usec=539
[2022-08-10T09:44:11.780] sched/backfill: _start_job: Started JobId=47743 in gpu-titan on gpu02
[2022-08-10T09:45:58.486] _slurm_rpc_kill_job: REQUEST_KILL_JOB JobId=47743 uid 548200045
[2022-08-10T09:46:33.920] _slurm_rpc_submit_batch_job: JobId=47744 InitPrio=20353 usec=420
[2022-08-10T09:46:34.212] sched: Allocate JobId=47744 NodeList=gpu02 #CPUs=8 Partition=gpu-titan
[2022-08-10T10:17:49.389] _job_complete: JobId=47742 WEXITSTATUS 0
[2022-08-10T10:17:49.390] _job_complete: JobId=47742 done
[2022-08-10T10:47:24.433] error: This association 228(account='free', user='kurk', partition='(null)') does not have access to qos normal
[2022-08-10T10:47:24.433] _slurm_rpc_submit_batch_job: Invalid qos specification
[2022-08-10T13:15:04.856] _job_complete: JobId=47478 WEXITSTATUS 0
[2022-08-10T13:15:04.856] _job_complete: JobId=47478 done
[2022-08-10T13:15:24.511] _slurm_rpc_kill_job: REQUEST_KILL_JOB JobId=47744 uid 548200045
[2022-08-10T13:16:31.001] _slurm_rpc_submit_batch_job: JobId=47745 InitPrio=20275 usec=450
[2022-08-10T13:16:31.967] sched: Allocate JobId=47745 NodeList=gpu02 #CPUs=16 Partition=gpu-titan
[2022-08-10T14:36:14.943] _slurm_rpc_submit_batch_job: JobId=47746 InitPrio=21552 usec=449
[2022-08-10T14:36:39.719] _slurm_rpc_kill_job: REQUEST_KILL_JOB JobId=47746 uid 548200023
[2022-08-10T14:37:03.375] _slurm_rpc_submit_batch_job: JobId=47747 InitPrio=21552 usec=425
[2022-08-10T14:37:39.940] _slurm_rpc_kill_job: REQUEST_KILL_JOB JobId=47747 uid 548200023
[2022-08-10T14:38:07.749] _slurm_rpc_submit_batch_job: JobId=47748 InitPrio=21577 usec=492
[2022-08-10T14:39:55.227] _slurm_rpc_kill_job: REQUEST_KILL_JOB JobId=47748 uid 548200023
[2022-08-10T14:40:24.778] _slurm_rpc_submit_batch_job: JobId=47749 InitPrio=21577 usec=490
[2022-08-10T14:41:12.309] sched/backfill: _start_job: Started JobId=47749 in gpu-k10 on gpu01
[2022-08-10T14:41:14.054] _job_complete: JobId=47749 WEXITSTATUS 0
[2022-08-10T14:41:14.054] _job_complete: JobId=47749 done
[2022-08-10T14:45:30.033] sched: _slurm_rpc_allocate_resources JobId=47750 NodeList=(null) usec=828
[2022-08-10T14:45:30.730] sched: Allocate JobId=47750 NodeList=cpu03 #CPUs=1 Partition=cpu-opteron
[2022-08-10T14:50:33.164] Time limit exhausted for JobId=46785
[2022-08-10T14:50:56.603] error: This association 222(account='free', user='fairus', partition='(null)') does not have access to qos normal
[2022-08-10T14:50:56.603] _slurm_rpc_submit_batch_job: Invalid qos specification
[2022-08-10T14:51:23.441] _slurm_rpc_submit_batch_job: JobId=47751 InitPrio=24134 usec=358
[2022-08-10T14:51:24.262] sched: Allocate JobId=47751 NodeList=cpu04 #CPUs=4 Partition=cpu-opteron
[2022-08-10T14:51:27.474] error: This association 222(account='free', user='fairus', partition='(null)') does not have access to qos normal
[2022-08-10T14:51:27.474] _slurm_rpc_submit_batch_job: Invalid qos specification
[2022-08-10T14:51:28.777] error: This association 221(account='free', user='manoj', partition='(null)') does not have access to qos normal
[2022-08-10T14:51:28.777] _slurm_rpc_submit_batch_job: Invalid qos specification
[2022-08-10T14:51:46.260] error: This association 221(account='free', user='manoj', partition='(null)') does not have access to qos normal
[2022-08-10T14:51:46.260] _slurm_rpc_submit_batch_job: Invalid qos specification
[2022-08-10T14:51:48.256] error: This association 222(account='free', user='fairus', partition='(null)') does not have access to qos normal
[2022-08-10T14:51:48.256] _slurm_rpc_submit_batch_job: Invalid qos specification
[2022-08-10T14:51:59.043] _slurm_rpc_kill_job: REQUEST_KILL_JOB JobId=47751 uid 548200003
[2022-08-10T14:52:01.041] sched: Allocate JobId=47517 NodeList=cpu04 #CPUs=64 Partition=cpu-opteron
[2022-08-10T14:52:21.335] _job_complete: JobId=47517 WEXITSTATUS 1
[2022-08-10T14:52:21.335] _job_complete: JobId=47517 done
[2022-08-10T14:52:21.738] sched: Allocate JobId=47704 NodeList=cpu04 #CPUs=48 Partition=cpu-opteron
[2022-08-10T14:52:25.759] _job_complete: JobId=47704 WEXITSTATUS 1
[2022-08-10T14:52:25.759] _job_complete: JobId=47704 done
[2022-08-10T14:56:27.142] sched: _slurm_rpc_allocate_resources JobId=47752 NodeList=(null) usec=893
[2022-08-10T14:56:27.712] sched: Allocate JobId=47752 NodeList=cpu04 #CPUs=1 Partition=cpu-opteron
[2022-08-10T14:59:27.428] _slurm_rpc_submit_batch_job: JobId=47753 InitPrio=21577 usec=431
[2022-08-10T14:59:29.129] error: This association 221(account='free', user='manoj', partition='(null)') does not have access to qos normal
[2022-08-10T14:59:29.129] _slurm_rpc_submit_batch_job: Invalid qos specification
[2022-08-10T15:00:12.342] sched/backfill: _start_job: Started JobId=47753 in gpu-k10 on gpu01
[2022-08-10T15:00:37.118] _job_complete: JobId=47753 WEXITSTATUS 0
[2022-08-10T15:00:37.118] _job_complete: JobId=47753 done
[2022-08-10T15:04:33.984] _slurm_rpc_submit_batch_job: JobId=47754 InitPrio=21552 usec=435
[2022-08-10T15:05:40.656] _slurm_rpc_kill_job: REQUEST_KILL_JOB JobId=47754 uid 548200023
[2022-08-10T15:05:43.870] _slurm_rpc_submit_batch_job: JobId=47755 InitPrio=21569 usec=410
[2022-08-10T15:10:02.618] sched: _slurm_rpc_allocate_resources JobId=47756 NodeList=(null) usec=815
[2022-08-10T15:10:03.182] sched: Allocate JobId=47756 NodeList=cpu03 #CPUs=4 Partition=cpu-opteron
[2022-08-10T15:10:47.841] error: This association 221(account='free', user='manoj', partition='(null)') does not have access to qos normal
[2022-08-10T15:10:47.841] _slurm_rpc_submit_batch_job: Invalid qos specification
[2022-08-10T15:13:03.772] _job_complete: JobId=47756 WEXITSTATUS 1
[2022-08-10T15:13:03.772] _job_complete: JobId=47756 done
[2022-08-10T15:13:19.989] sched: _slurm_rpc_allocate_resources JobId=47757 NodeList=(null) usec=825
[2022-08-10T15:13:20.046] _job_complete: JobId=47752 WEXITSTATUS 1
[2022-08-10T15:13:20.046] _job_complete: JobId=47752 done
[2022-08-10T15:13:20.422] sched: Allocate JobId=47757 NodeList=cpu03 #CPUs=4 Partition=cpu-opteron
[2022-08-10T15:18:48.669] _slurm_rpc_kill_job: REQUEST_KILL_JOB JobId=47755 uid 548200023
[2022-08-10T15:19:29.187] _slurm_rpc_submit_batch_job: JobId=47758 InitPrio=21577 usec=523
[2022-08-10T15:20:12.369] sched/backfill: _start_job: Started JobId=47758 in gpu-k10 on gpu01
[2022-08-10T15:21:53.333] _job_complete: JobId=47758 WEXITSTATUS 0
[2022-08-10T15:21:53.333] _job_complete: JobId=47758 done
[2022-08-10T15:29:05.511] _slurm_rpc_submit_batch_job: JobId=47759 InitPrio=20236 usec=572
[2022-08-10T15:41:08.573] _slurm_rpc_submit_batch_job: JobId=47760 InitPrio=24970 usec=439
[2022-08-10T15:41:09.280] sched: Allocate JobId=47760 NodeList=cpu04 #CPUs=16 Partition=cpu-opteron
[2022-08-10T15:41:09.285] sched: Allocate JobId=47759 NodeList=cpu04 #CPUs=48 Partition=cpu-opteron
[2022-08-10T15:44:05.781] _slurm_rpc_submit_batch_job: JobId=47761 InitPrio=25038 usec=417
[2022-08-10T15:44:06.591] sched: Allocate JobId=47761 NodeList=cpu03 #CPUs=8 Partition=cpu-opteron
[2022-08-10T15:44:10.781] _job_complete: JobId=47761 WEXITSTATUS 0
[2022-08-10T15:44:10.781] _job_complete: JobId=47761 done
[2022-08-10T15:45:28.231] _job_complete: JobId=47757 WEXITSTATUS 130
[2022-08-10T15:45:28.231] _job_complete: JobId=47757 done
[2022-08-10T15:45:33.712] Time limit exhausted for JobId=47750
[2022-08-10T15:45:48.876] _job_create: exceeded association/QOS limit for user 548300600: AssocGrpCpuLimit
[2022-08-10T15:45:48.876] _slurm_rpc_allocate_resources: Job violates accounting/QOS policy (job submit limit, user's size and/or time limits) 
[2022-08-10T15:46:02.915] _job_create: exceeded association/QOS limit for user 548300600: AssocGrpCpuLimit
[2022-08-10T15:46:02.915] _slurm_rpc_allocate_resources: Job violates accounting/QOS policy (job submit limit, user's size and/or time limits) 
[2022-08-10T15:46:16.650] _job_create: exceeded association/QOS limit for user 548300600: AssocGrpCpuLimit
[2022-08-10T15:46:16.650] _slurm_rpc_allocate_resources: Job violates accounting/QOS policy (job submit limit, user's size and/or time limits) 
[2022-08-10T15:46:21.428] _job_create: exceeded association/QOS limit for user 548300600: AssocGrpCpuLimit
[2022-08-10T15:46:21.428] _slurm_rpc_allocate_resources: Job violates accounting/QOS policy (job submit limit, user's size and/or time limits) 
[2022-08-10T15:46:25.299] _job_create: exceeded association/QOS limit for user 548300600: AssocGrpCpuLimit
[2022-08-10T15:46:25.299] _slurm_rpc_allocate_resources: Job violates accounting/QOS policy (job submit limit, user's size and/or time limits) 
[2022-08-10T15:46:28.659] _job_create: exceeded association/QOS limit for user 548300600: AssocGrpMemLimit
[2022-08-10T15:46:28.659] _slurm_rpc_allocate_resources: Job violates accounting/QOS policy (job submit limit, user's size and/or time limits) 
[2022-08-10T15:46:43.579] _job_create: exceeded association/QOS limit for user 548300600: AssocGrpCpuLimit
[2022-08-10T15:46:43.579] _slurm_rpc_allocate_resources: Job violates accounting/QOS policy (job submit limit, user's size and/or time limits) 
[2022-08-10T15:46:47.919] sched: _slurm_rpc_allocate_resources JobId=47762 NodeList=(null) usec=808
[2022-08-10T15:46:48.821] sched: Allocate JobId=47762 NodeList=cpu03 #CPUs=4 Partition=cpu-opteron
[2022-08-10T15:47:37.580] sched: _slurm_rpc_allocate_resources JobId=47763 NodeList=(null) usec=1015
[2022-08-10T15:47:38.820] _job_complete: JobId=47763 WTERMSIG 126
[2022-08-10T15:47:38.820] _job_complete: JobId=47763 cancelled by interactive user
[2022-08-10T15:47:38.820] _job_complete: JobId=47763 done
[2022-08-10T15:47:42.257] sched: _slurm_rpc_allocate_resources JobId=47764 NodeList=(null) usec=748
[2022-08-10T15:48:55.475] _job_complete: JobId=47764 WTERMSIG 126
[2022-08-10T15:48:55.475] _job_complete: JobId=47764 cancelled by interactive user
[2022-08-10T15:48:55.475] _job_complete: JobId=47764 done
[2022-08-10T15:49:38.620] sched: _slurm_rpc_allocate_resources JobId=47765 NodeList=(null) usec=745
[2022-08-10T15:55:51.199] _job_complete: JobId=47765 WTERMSIG 126
[2022-08-10T15:55:51.199] _job_complete: JobId=47765 cancelled by interactive user
[2022-08-10T15:55:51.200] _job_complete: JobId=47765 done
[2022-08-10T15:55:54.529] _job_complete: JobId=47762 WEXITSTATUS 1
[2022-08-10T15:55:54.529] _job_complete: JobId=47762 done
[2022-08-10T15:56:22.768] _job_create: exceeded association/QOS limit for user 548300600: AssocGrpCpuLimit
[2022-08-10T15:56:22.768] _slurm_rpc_allocate_resources: Job violates accounting/QOS policy (job submit limit, user's size and/or time limits) 
[2022-08-10T15:56:39.270] _job_create: exceeded association/QOS limit for user 548300600: AssocGrpMemLimit
[2022-08-10T15:56:39.270] _slurm_rpc_allocate_resources: Job violates accounting/QOS policy (job submit limit, user's size and/or time limits) 
[2022-08-10T15:56:42.675] sched: _slurm_rpc_allocate_resources JobId=47766 NodeList=(null) usec=918
[2022-08-10T15:56:42.829] sched: Allocate JobId=47766 NodeList=cpu03 #CPUs=4 Partition=cpu-opteron
[2022-08-10T15:56:51.109] _job_complete: JobId=47766 WEXITSTATUS 0
[2022-08-10T15:56:51.109] _job_complete: JobId=47766 done
[2022-08-10T16:06:26.936] sched: _slurm_rpc_allocate_resources JobId=47767 NodeList=(null) usec=822
[2022-08-10T16:07:37.793] sched: _slurm_rpc_allocate_resources JobId=47768 NodeList=(null) usec=735
[2022-08-10T16:08:17.669] sched: _slurm_rpc_allocate_resources JobId=47769 NodeList=(null) usec=945
[2022-08-10T16:08:18.085] sched: Allocate JobId=47769 NodeList=gpu01 #CPUs=4 Partition=gpu-k10
[2022-08-10T16:08:20.253] _slurm_rpc_submit_batch_job: JobId=47770 InitPrio=21569 usec=389
[2022-08-10T16:08:35.557] _slurm_rpc_submit_batch_job: JobId=47771 InitPrio=24100 usec=492
[2022-08-10T16:08:36.100] sched: Allocate JobId=47771 NodeList=cpu03 #CPUs=8 Partition=cpu-opteron
[2022-08-10T16:08:39.261] _job_complete: JobId=47771 WEXITSTATUS 0
[2022-08-10T16:08:39.261] _job_complete: JobId=47771 done
[2022-08-10T16:09:12.434] sched/backfill: _start_job: Started JobId=47770 in gpu-k10 on gpu01
[2022-08-10T16:09:13.988] _job_complete: JobId=47770 WEXITSTATUS 0
[2022-08-10T16:09:13.988] _job_complete: JobId=47770 done
[2022-08-10T16:13:30.657] _job_complete: JobId=47769 WEXITSTATUS 1
[2022-08-10T16:13:30.658] _job_complete: JobId=47769 done
[2022-08-10T16:13:54.648] _job_complete: JobId=47768 WTERMSIG 126
[2022-08-10T16:13:54.648] _job_complete: JobId=47768 cancelled by interactive user
[2022-08-10T16:13:54.648] _job_complete: JobId=47768 done
[2022-08-10T16:13:54.648] _job_complete: JobId=47767 WTERMSIG 126
[2022-08-10T16:13:54.648] _job_complete: JobId=47767 cancelled by interactive user
[2022-08-10T16:13:54.648] _job_complete: JobId=47767 done
[2022-08-10T16:14:36.830] sched: _slurm_rpc_allocate_resources JobId=47772 NodeList=(null) usec=863
[2022-08-10T16:14:37.648] sched: Allocate JobId=47772 NodeList=gpu01 #CPUs=4 Partition=gpu-k10
[2022-08-10T16:26:52.039] _slurm_rpc_submit_batch_job: JobId=47773 InitPrio=21577 usec=424
[2022-08-10T16:27:12.459] sched/backfill: _start_job: Started JobId=47773 in gpu-k10 on gpu01
[2022-08-10T16:27:37.282] _job_complete: JobId=47773 WEXITSTATUS 0
[2022-08-10T16:27:37.282] _job_complete: JobId=47773 done
[2022-08-10T16:33:05.415] _slurm_rpc_submit_batch_job: JobId=47774 InitPrio=21500 usec=498
[2022-08-10T16:40:01.349] _slurm_rpc_kill_job: REQUEST_KILL_JOB JobId=47760 uid 548300543
[2022-08-10T17:02:04.667] _pick_best_nodes: JobId=47775 never runnable in partition gpu-v100s
[2022-08-10T17:02:04.672] _slurm_rpc_submit_batch_job: Requested node configuration is not available
[2022-08-10T17:02:32.295] _pick_best_nodes: JobId=47776 never runnable in partition gpu-v100s
[2022-08-10T17:02:32.295] _slurm_rpc_submit_batch_job: Requested node configuration is not available
[2022-08-10T17:02:57.232] _slurm_rpc_submit_batch_job: JobId=47777 InitPrio=27885 usec=386
[2022-08-10T17:03:40.195] _slurm_rpc_kill_job: REQUEST_KILL_JOB JobId=47718 uid 548300576
[2022-08-10T17:03:59.120] _job_complete: JobId=47772 WEXITSTATUS 1
[2022-08-10T17:03:59.121] _job_complete: JobId=47772 done
[2022-08-10T17:05:04.122] _slurm_rpc_kill_job: REQUEST_KILL_JOB JobId=47777 uid 548300576
[2022-08-10T17:05:15.662] _slurm_rpc_submit_batch_job: JobId=47778 InitPrio=27885 usec=363
[2022-08-10T17:16:58.072] _slurm_rpc_submit_batch_job: JobId=47779 InitPrio=30134 usec=537
[2022-08-10T17:16:58.462] sched: Allocate JobId=47779 NodeList=gpu01 #CPUs=16 Partition=gpu-k10
[2022-08-10T17:17:07.942] _job_complete: JobId=47779 WEXITSTATUS 255
[2022-08-10T17:17:07.942] _job_complete: JobId=47779 done
[2022-08-10T17:20:58.126] _slurm_rpc_submit_batch_job: JobId=47780 InitPrio=29900 usec=471
[2022-08-10T17:20:58.863] sched: Allocate JobId=47780 NodeList=gpu01 #CPUs=16 Partition=gpu-k10
[2022-08-10T17:21:02.284] _job_complete: JobId=47780 WEXITSTATUS 255
[2022-08-10T17:21:02.284] _job_complete: JobId=47780 done
[2022-08-10T17:21:02.909] _slurm_rpc_submit_batch_job: JobId=47781 InitPrio=29900 usec=424
[2022-08-10T17:21:03.870] sched: Allocate JobId=47781 NodeList=gpu01 #CPUs=16 Partition=gpu-k10
[2022-08-10T17:21:08.458] _job_complete: JobId=47781 WEXITSTATUS 255
[2022-08-10T17:21:08.458] _job_complete: JobId=47781 done
[2022-08-10T17:21:47.149] _slurm_rpc_submit_batch_job: JobId=47782 InitPrio=29900 usec=437
[2022-08-10T17:21:47.930] sched: Allocate JobId=47782 NodeList=gpu01 #CPUs=16 Partition=gpu-k10
[2022-08-10T17:21:52.232] _job_complete: JobId=47782 WEXITSTATUS 127
[2022-08-10T17:21:52.232] _job_complete: JobId=47782 done
[2022-08-10T17:22:25.772] _slurm_rpc_submit_batch_job: JobId=47783 InitPrio=29665 usec=486
[2022-08-10T17:22:25.981] sched: Allocate JobId=47783 NodeList=gpu01 #CPUs=16 Partition=gpu-k10
[2022-08-10T17:22:29.331] _job_complete: JobId=47783 WEXITSTATUS 127
[2022-08-10T17:22:29.331] _job_complete: JobId=47783 done
[2022-08-10T17:27:09.718] _slurm_rpc_submit_batch_job: JobId=47784 InitPrio=29665 usec=492
[2022-08-10T17:27:10.456] sched: Allocate JobId=47784 NodeList=gpu01 #CPUs=16 Partition=gpu-k10
[2022-08-10T17:27:12.325] _job_complete: JobId=47784 WEXITSTATUS 127
[2022-08-10T17:27:12.325] _job_complete: JobId=47784 done
[2022-08-10T17:27:38.455] _slurm_rpc_submit_batch_job: JobId=47785 InitPrio=25205 usec=464
[2022-08-10T17:28:12.596] sched/backfill: _start_job: Started JobId=47785 in gpu-k10 on gpu01
[2022-08-10T17:28:17.975] _job_complete: JobId=47785 WEXITSTATUS 255
[2022-08-10T17:28:17.975] _job_complete: JobId=47785 done
[2022-08-10T17:30:18.603] _slurm_rpc_submit_batch_job: JobId=47786 InitPrio=29665 usec=588
[2022-08-10T17:30:18.790] sched: Allocate JobId=47786 NodeList=gpu01 #CPUs=16 Partition=gpu-k10
[2022-08-10T17:30:20.677] _job_complete: JobId=47786 WEXITSTATUS 127
[2022-08-10T17:30:20.677] _job_complete: JobId=47786 done
[2022-08-10T17:30:28.128] _slurm_rpc_submit_batch_job: JobId=47787 InitPrio=25205 usec=518
[2022-08-10T17:31:12.600] sched/backfill: _start_job: Started JobId=47787 in gpu-k10 on gpu01
[2022-08-10T17:31:17.738] _job_complete: JobId=47787 WEXITSTATUS 255
[2022-08-10T17:31:17.738] _job_complete: JobId=47787 done
[2022-08-10T17:45:51.920] _slurm_rpc_submit_batch_job: JobId=47788 InitPrio=29665 usec=591
[2022-08-10T17:45:52.320] sched: Allocate JobId=47788 NodeList=gpu01 #CPUs=16 Partition=gpu-k10
[2022-08-10T17:45:54.743] _job_complete: JobId=47788 WEXITSTATUS 1
[2022-08-10T17:45:54.743] _job_complete: JobId=47788 done
[2022-08-10T17:46:14.700] _slurm_rpc_submit_batch_job: JobId=47789 InitPrio=29665 usec=434
[2022-08-10T17:46:15.348] sched: Allocate JobId=47789 NodeList=gpu01 #CPUs=16 Partition=gpu-k10
[2022-08-10T17:46:17.064] _job_complete: JobId=47789 WEXITSTATUS 1
[2022-08-10T17:46:17.064] _job_complete: JobId=47789 done
[2022-08-10T17:46:38.881] _slurm_rpc_submit_batch_job: JobId=47790 InitPrio=29665 usec=463
[2022-08-10T17:46:39.382] sched: Allocate JobId=47790 NodeList=gpu01 #CPUs=16 Partition=gpu-k10
[2022-08-10T17:46:41.371] _job_complete: JobId=47790 WEXITSTATUS 1
[2022-08-10T17:46:41.371] _job_complete: JobId=47790 done
[2022-08-10T17:47:15.370] _slurm_rpc_submit_batch_job: JobId=47791 InitPrio=29665 usec=505
[2022-08-10T17:47:15.432] sched: Allocate JobId=47791 NodeList=gpu01 #CPUs=16 Partition=gpu-k10
[2022-08-10T17:47:16.497] _job_complete: JobId=47791 WEXITSTATUS 1
[2022-08-10T17:47:16.497] _job_complete: JobId=47791 done
[2022-08-10T17:47:53.047] _slurm_rpc_submit_batch_job: JobId=47792 InitPrio=29665 usec=507
[2022-08-10T17:47:53.579] sched: Allocate JobId=47792 NodeList=gpu01 #CPUs=16 Partition=gpu-k10
[2022-08-10T17:47:55.271] _job_complete: JobId=47792 WEXITSTATUS 1
[2022-08-10T17:47:55.271] _job_complete: JobId=47792 done
[2022-08-10T17:49:17.590] _slurm_rpc_submit_batch_job: JobId=47793 InitPrio=29665 usec=438
[2022-08-10T17:49:17.695] sched: Allocate JobId=47793 NodeList=gpu01 #CPUs=16 Partition=gpu-k10
[2022-08-10T17:49:18.726] _job_complete: JobId=47793 WEXITSTATUS 1
[2022-08-10T17:49:18.726] _job_complete: JobId=47793 done
[2022-08-10T17:50:40.774] _slurm_rpc_submit_batch_job: JobId=47794 InitPrio=29665 usec=511
[2022-08-10T17:50:40.813] sched: Allocate JobId=47794 NodeList=gpu01 #CPUs=16 Partition=gpu-k10
[2022-08-10T17:50:41.714] _job_complete: JobId=47794 WEXITSTATUS 127
[2022-08-10T17:50:41.714] _job_complete: JobId=47794 done
[2022-08-10T17:51:51.749] _slurm_rpc_submit_batch_job: JobId=47795 InitPrio=29665 usec=519
[2022-08-10T17:51:51.909] sched: Allocate JobId=47795 NodeList=gpu01 #CPUs=16 Partition=gpu-k10
[2022-08-10T17:51:53.006] _job_complete: JobId=47795 WEXITSTATUS 127
[2022-08-10T17:51:53.007] _job_complete: JobId=47795 done
[2022-08-10T17:52:37.495] _slurm_rpc_submit_batch_job: JobId=47796 InitPrio=29665 usec=486
[2022-08-10T17:52:37.994] sched: Allocate JobId=47796 NodeList=gpu01 #CPUs=16 Partition=gpu-k10
[2022-08-10T17:52:38.813] _job_complete: JobId=47796 WEXITSTATUS 1
[2022-08-10T17:52:38.813] _job_complete: JobId=47796 done
[2022-08-10T17:53:09.223] _slurm_rpc_submit_batch_job: JobId=47797 InitPrio=29665 usec=438
[2022-08-10T17:53:10.081] sched: Allocate JobId=47797 NodeList=gpu01 #CPUs=16 Partition=gpu-k10
[2022-08-10T17:53:10.888] _job_complete: JobId=47797 WEXITSTATUS 1
[2022-08-10T17:53:10.889] _job_complete: JobId=47797 done
[2022-08-10T17:54:49.054] _slurm_rpc_submit_batch_job: JobId=47798 InitPrio=29665 usec=499
[2022-08-10T17:54:49.216] sched: Allocate JobId=47798 NodeList=gpu01 #CPUs=16 Partition=gpu-k10
[2022-08-10T17:54:50.269] _job_complete: JobId=47798 WEXITSTATUS 1
[2022-08-10T17:54:50.269] _job_complete: JobId=47798 done
[2022-08-10T18:12:29.229] _slurm_rpc_submit_batch_job: JobId=47799 InitPrio=20344 usec=560
[2022-08-10T18:12:52.844] _slurm_rpc_kill_job: REQUEST_KILL_JOB JobId=47799 uid 548200045
[2022-08-10T18:13:55.416] _slurm_rpc_submit_batch_job: JobId=47800 InitPrio=20344 usec=452
[2022-08-10T18:14:05.783] _slurm_rpc_kill_job: REQUEST_KILL_JOB JobId=47800 uid 548200045
[2022-08-10T21:52:34.930] Time limit exhausted for JobId=46766
[2022-08-10T22:16:04.408] Time limit exhausted for JobId=46798
[2022-08-10T22:16:25.380] sched: Allocate JobId=47663 NodeList=gpu03 #CPUs=16 Partition=gpu-k10
[2022-08-10T22:16:28.353] _job_complete: JobId=47663 WEXITSTATUS 127
[2022-08-10T22:16:28.354] _job_complete: JobId=47663 done
[2022-08-10T22:16:28.706] sched: Allocate JobId=47721 NodeList=gpu03 #CPUs=16 Partition=gpu-k10
[2022-08-10T22:17:34.901] _slurm_rpc_submit_batch_job: JobId=47801 InitPrio=19297 usec=416
[2022-08-10T22:17:35.550] sched: Allocate JobId=47801 NodeList=cpu08 #CPUs=48 Partition=cpu-opteron
[2022-08-10T22:20:20.402] _slurm_rpc_submit_batch_job: JobId=47802 InitPrio=19160 usec=424
[2022-08-10T23:09:34.464] Time limit exhausted for JobId=46804
[2022-08-10T23:09:35.552] sched: Allocate JobId=47802 NodeList=cpu05 #CPUs=64 Partition=cpu-opteron
[2022-08-11T04:13:56.538] _slurm_rpc_submit_batch_job: JobId=47803 InitPrio=22153 usec=974
[2022-08-11T04:22:03.933] _slurm_rpc_submit_batch_job: JobId=47804 InitPrio=22153 usec=955
[2022-08-11T04:22:13.340] sched/backfill: _start_job: Started JobId=47804 in gpu-k10 on gpu01
[2022-08-11T06:27:13.548] _job_complete: JobId=47721 WEXITSTATUS 0
[2022-08-11T06:27:13.548] _job_complete: JobId=47721 done
[2022-08-11T06:27:13.877] sched: Allocate JobId=47803 NodeList=gpu03 #CPUs=16 Partition=gpu-k10
[2022-08-11T06:51:35.320] _job_complete: JobId=47803 WEXITSTATUS 134
[2022-08-11T06:51:35.321] _job_complete: JobId=47803 done
[2022-08-11T07:45:30.264] _job_complete: JobId=47002 WEXITSTATUS 1
[2022-08-11T07:45:30.264] _job_complete: JobId=47002 done
[2022-08-11T09:29:29.087] _slurm_rpc_submit_batch_job: JobId=47805 InitPrio=25205 usec=542
[2022-08-11T09:29:29.850] sched: Allocate JobId=47805 NodeList=gpu03 #CPUs=16 Partition=gpu-k10
[2022-08-11T09:29:35.119] _job_complete: JobId=47805 WEXITSTATUS 1
[2022-08-11T09:29:35.120] _job_complete: JobId=47805 done
[2022-08-11T09:32:51.888] _slurm_rpc_submit_batch_job: JobId=47806 InitPrio=25307 usec=488
[2022-08-11T09:36:50.397] Requeuing JobId=47745
[2022-08-11T09:36:50.397] sched: Allocate JobId=47806 NodeList=gpu02 #CPUs=4 Partition=gpu-titan
[2022-08-11T09:36:54.849] _job_complete: JobId=47806 WEXITSTATUS 1
[2022-08-11T09:36:54.849] _job_complete: JobId=47806 done
[2022-08-11T09:37:56.754] _slurm_rpc_submit_batch_job: JobId=47807 InitPrio=25307 usec=474
[2022-08-11T09:37:57.677] sched: Allocate JobId=47807 NodeList=gpu02 #CPUs=4 Partition=gpu-titan
[2022-08-11T09:38:00.588] _job_complete: JobId=47807 WEXITSTATUS 1
[2022-08-11T09:38:00.588] _job_complete: JobId=47807 done
[2022-08-11T09:41:01.843] _slurm_rpc_submit_batch_job: JobId=47808 InitPrio=25307 usec=578
[2022-08-11T09:41:01.937] sched: Allocate JobId=47808 NodeList=gpu02 #CPUs=4 Partition=gpu-titan
[2022-08-11T09:41:05.315] _job_complete: JobId=47808 WEXITSTATUS 1
[2022-08-11T09:41:05.315] _job_complete: JobId=47808 done
[2022-08-11T09:59:39.102] _slurm_rpc_submit_batch_job: JobId=47809 InitPrio=25098 usec=460
[2022-08-11T09:59:40.029] sched: Allocate JobId=47809 NodeList=gpu02 #CPUs=1 Partition=gpu-titan
[2022-08-11T09:59:52.547] _job_complete: JobId=47809 WEXITSTATUS 2
[2022-08-11T09:59:52.547] _job_complete: JobId=47809 done
[2022-08-11T10:03:02.639] _slurm_rpc_submit_batch_job: JobId=47810 InitPrio=25098 usec=501
[2022-08-11T10:03:03.352] sched: Allocate JobId=47810 NodeList=gpu02 #CPUs=1 Partition=gpu-titan
[2022-08-11T10:03:10.304] _job_complete: JobId=47810 WEXITSTATUS 2
[2022-08-11T10:03:10.304] _job_complete: JobId=47810 done
[2022-08-11T10:04:37.198] _slurm_rpc_submit_batch_job: JobId=47811 InitPrio=25098 usec=430
[2022-08-11T10:04:37.480] sched: Allocate JobId=47811 NodeList=gpu02 #CPUs=1 Partition=gpu-titan
[2022-08-11T10:04:46.639] _job_complete: JobId=47811 WEXITSTATUS 2
[2022-08-11T10:04:46.639] _job_complete: JobId=47811 done
[2022-08-11T10:15:13.811] _slurm_rpc_submit_batch_job: JobId=47812 InitPrio=25098 usec=390
[2022-08-11T10:15:14.576] sched: Allocate JobId=47812 NodeList=gpu02 #CPUs=1 Partition=gpu-titan
[2022-08-11T10:24:53.529] _job_complete: JobId=47812 WEXITSTATUS 0
[2022-08-11T10:24:53.529] _job_complete: JobId=47812 done
[2022-08-11T10:34:11.767] _job_create: exceeded association/QOS limit for user 548300600: AssocGrpCpuLimit
[2022-08-11T10:34:11.767] _slurm_rpc_allocate_resources: Job violates accounting/QOS policy (job submit limit, user's size and/or time limits) 
[2022-08-11T10:34:16.830] sched: _slurm_rpc_allocate_resources JobId=47813 NodeList=(null) usec=965
[2022-08-11T10:34:17.596] sched: Allocate JobId=47813 NodeList=cpu04 #CPUs=4 Partition=cpu-opteron
[2022-08-11T10:35:01.655] _slurm_rpc_submit_batch_job: JobId=47814 InitPrio=25290 usec=495
[2022-08-11T10:35:02.650] sched: Allocate JobId=47814 NodeList=gpu02 #CPUs=6 Partition=gpu-titan
[2022-08-11T10:35:15.299] _job_complete: JobId=47814 WEXITSTATUS 0
[2022-08-11T10:35:15.299] _job_complete: JobId=47814 done
[2022-08-11T10:35:57.691] _job_complete: JobId=47813 WEXITSTATUS 0
[2022-08-11T10:35:57.692] _job_complete: JobId=47813 done
[2022-08-11T10:36:02.950] sched: _slurm_rpc_allocate_resources JobId=47815 NodeList=(null) usec=983
[2022-08-11T10:36:03.729] sched: Allocate JobId=47815 NodeList=cpu04 #CPUs=4 Partition=cpu-opteron
[2022-08-11T10:38:32.039] _job_complete: JobId=47815 WEXITSTATUS 0
[2022-08-11T10:38:32.039] _job_complete: JobId=47815 done
[2022-08-11T10:40:08.782] sched: _slurm_rpc_allocate_resources JobId=47816 NodeList=(null) usec=921
[2022-08-11T10:40:09.143] sched: Allocate JobId=47816 NodeList=cpu04 #CPUs=4 Partition=cpu-opteron
[2022-08-11T10:44:15.931] _slurm_rpc_submit_batch_job: JobId=47817 InitPrio=25290 usec=462
[2022-08-11T10:44:16.614] sched: Allocate JobId=47817 NodeList=gpu03 #CPUs=6 Partition=gpu-k10
[2022-08-11T10:44:30.283] _job_complete: JobId=47817 WEXITSTATUS 0
[2022-08-11T10:44:30.283] _job_complete: JobId=47817 done
[2022-08-11T10:50:42.747] _job_complete: JobId=47816 WEXITSTATUS 127
[2022-08-11T10:50:42.747] _job_complete: JobId=47816 done
[2022-08-11T10:51:45.270] _job_create: exceeded association/QOS limit for user 548300600: AssocGrpMemLimit
[2022-08-11T10:51:45.270] _slurm_rpc_allocate_resources: Job violates accounting/QOS policy (job submit limit, user's size and/or time limits) 
[2022-08-11T10:51:59.851] sched: _slurm_rpc_allocate_resources JobId=47818 NodeList=(null) usec=954
[2022-08-11T10:52:00.368] sched: Allocate JobId=47818 NodeList=cpu04 #CPUs=4 Partition=cpu-opteron
[2022-08-11T11:07:05.313] _job_complete: JobId=46830 WEXITSTATUS 0
[2022-08-11T11:07:05.318] _job_complete: JobId=46830 done
[2022-08-11T11:07:14.245] sched: Allocate JobId=46802 NodeList=gpu05 #CPUs=16 Partition=gpu-v100s
[2022-08-11T11:28:18.000] _slurm_rpc_submit_batch_job: JobId=47819 InitPrio=25038 usec=450
[2022-08-11T11:28:18.306] sched: Allocate JobId=47819 NodeList=cpu04 #CPUs=8 Partition=cpu-opteron
[2022-08-11T11:28:23.852] _job_complete: JobId=47819 WEXITSTATUS 0
[2022-08-11T11:28:23.852] _job_complete: JobId=47819 done
[2022-08-11T11:32:10.733] _slurm_rpc_submit_batch_job: JobId=47820 InitPrio=25038 usec=431
[2022-08-11T11:32:11.626] sched: Allocate JobId=47820 NodeList=cpu04 #CPUs=8 Partition=cpu-opteron
[2022-08-11T11:32:21.850] _job_complete: JobId=47820 WEXITSTATUS 0
[2022-08-11T11:32:21.851] _job_complete: JobId=47820 done
[2022-08-11T11:52:09.651] Time limit exhausted for JobId=47818
[2022-08-11T11:56:19.015] _slurm_rpc_submit_batch_job: JobId=47821 InitPrio=29750 usec=531
[2022-08-11T11:56:19.098] sched: Allocate JobId=47821 NodeList=gpu02 #CPUs=6 Partition=gpu-titan
[2022-08-11T11:56:22.560] _job_complete: JobId=47821 WEXITSTATUS 255
[2022-08-11T11:56:22.560] _job_complete: JobId=47821 done
[2022-08-11T11:57:10.987] _slurm_rpc_complete_job_allocation: JobId=47818 error Job/step already completing or completed
[2022-08-11T11:57:11.427] cleanup_completing: JobId=47818 completion process took 302 seconds
[2022-08-11T11:57:42.167] _slurm_rpc_submit_batch_job: JobId=47822 InitPrio=29750 usec=430
[2022-08-11T11:57:42.276] sched: Allocate JobId=47822 NodeList=gpu02 #CPUs=6 Partition=gpu-titan
[2022-08-11T11:57:43.035] _job_complete: JobId=47822 WEXITSTATUS 127
[2022-08-11T11:57:43.035] _job_complete: JobId=47822 done
[2022-08-11T12:00:33.630] _slurm_rpc_submit_batch_job: JobId=47823 InitPrio=29750 usec=437
[2022-08-11T12:00:34.550] sched: Allocate JobId=47823 NodeList=gpu02 #CPUs=6 Partition=gpu-titan
[2022-08-11T12:00:35.375] _job_complete: JobId=47823 WEXITSTATUS 127
[2022-08-11T12:00:35.375] _job_complete: JobId=47823 done
[2022-08-11T12:01:07.895] _slurm_rpc_submit_batch_job: JobId=47824 InitPrio=29750 usec=531
[2022-08-11T12:01:08.595] sched: Allocate JobId=47824 NodeList=gpu02 #CPUs=6 Partition=gpu-titan
[2022-08-11T12:01:09.363] _job_complete: JobId=47824 WEXITSTATUS 127
[2022-08-11T12:01:09.363] _job_complete: JobId=47824 done
[2022-08-11T12:01:54.333] _slurm_rpc_submit_batch_job: JobId=47825 InitPrio=29750 usec=491
[2022-08-11T12:01:54.656] sched: Allocate JobId=47825 NodeList=gpu02 #CPUs=6 Partition=gpu-titan
[2022-08-11T12:01:55.404] _job_complete: JobId=47825 WEXITSTATUS 127
[2022-08-11T12:01:55.404] _job_complete: JobId=47825 done
[2022-08-11T12:02:09.078] _slurm_rpc_submit_batch_job: JobId=47826 InitPrio=29750 usec=460
[2022-08-11T12:02:09.676] sched: Allocate JobId=47826 NodeList=gpu02 #CPUs=6 Partition=gpu-titan
[2022-08-11T12:02:10.406] _job_complete: JobId=47826 WEXITSTATUS 127
[2022-08-11T12:02:10.406] _job_complete: JobId=47826 done
[2022-08-11T12:05:12.326] _slurm_rpc_submit_batch_job: JobId=47827 InitPrio=29750 usec=430
[2022-08-11T12:05:13.013] sched: Allocate JobId=47827 NodeList=gpu02 #CPUs=6 Partition=gpu-titan
[2022-08-11T12:06:19.584] _job_complete: JobId=47827 OOM failure
[2022-08-11T12:06:19.584] _job_complete: JobId=47827 done
[2022-08-11T12:10:15.451] _slurm_rpc_submit_batch_job: JobId=47828 InitPrio=29750 usec=671
[2022-08-11T12:10:15.505] sched: Allocate JobId=47828 NodeList=gpu02 #CPUs=6 Partition=gpu-titan
[2022-08-11T12:10:28.945] _job_complete: JobId=47828 WEXITSTATUS 0
[2022-08-11T12:10:28.945] _job_complete: JobId=47828 done
[2022-08-11T12:11:53.284] _slurm_rpc_submit_batch_job: JobId=47829 InitPrio=29750 usec=435
[2022-08-11T12:11:53.642] sched: Allocate JobId=47829 NodeList=gpu02 #CPUs=6 Partition=gpu-titan
[2022-08-11T12:22:42.030] _slurm_rpc_kill_job: REQUEST_KILL_JOB JobId=47829 uid 548300580
[2022-08-11T12:22:56.181] _slurm_rpc_kill_job: REQUEST_KILL_JOB JobId=47829 uid 548300580
[2022-08-11T12:25:35.744] _slurm_rpc_submit_batch_job: JobId=47830 InitPrio=28342 usec=489
[2022-08-11T12:25:35.983] sched: Allocate JobId=47830 NodeList=gpu02 #CPUs=6 Partition=gpu-titan
[2022-08-11T13:20:21.774] _slurm_rpc_kill_job: REQUEST_KILL_JOB JobId=47830 uid 548300580
[2022-08-11T13:20:36.936] _slurm_rpc_submit_batch_job: JobId=47831 InitPrio=26613 usec=418
[2022-08-11T13:20:37.627] sched: Allocate JobId=47831 NodeList=gpu02 #CPUs=16 Partition=gpu-titan
[2022-08-11T14:04:23.366] _slurm_rpc_submit_batch_job: JobId=47832 InitPrio=22153 usec=1010
[2022-08-11T14:04:26.226] sched: Allocate JobId=47832 NodeList=gpu03 #CPUs=16 Partition=gpu-k10
[2022-08-11T14:07:11.692] _slurm_rpc_submit_batch_job: JobId=47833 InitPrio=22016 usec=382
[2022-08-11T14:07:12.437] sched: Allocate JobId=47833 NodeList=cpu03 #CPUs=32 Partition=cpu-opteron
[2022-08-11T14:07:17.505] _job_complete: JobId=47833 WEXITSTATUS 0
[2022-08-11T14:07:17.506] _job_complete: JobId=47833 done
[2022-08-11T14:07:55.655] _slurm_rpc_submit_batch_job: JobId=47834 InitPrio=26613 usec=459
[2022-08-11T14:08:07.783] _slurm_rpc_submit_batch_job: JobId=47835 InitPrio=22016 usec=396
[2022-08-11T14:08:08.622] sched: Allocate JobId=47835 NodeList=cpu03 #CPUs=32 Partition=cpu-opteron
[2022-08-11T14:08:09.223] _slurm_rpc_kill_job: REQUEST_KILL_JOB JobId=47831 uid 548300580
[2022-08-11T14:08:13.453] _job_complete: JobId=47835 WEXITSTATUS 0
[2022-08-11T14:08:13.454] _job_complete: JobId=47835 done
[2022-08-11T14:08:15.167] sched: Allocate JobId=47834 NodeList=gpu02 #CPUs=16 Partition=gpu-titan
[2022-08-11T14:08:22.191] _job_complete: JobId=47834 WEXITSTATUS 0
[2022-08-11T14:08:22.191] _job_complete: JobId=47834 done
[2022-08-11T14:08:50.129] _slurm_rpc_submit_batch_job: JobId=47836 InitPrio=20347 usec=511
[2022-08-11T14:09:02.547] _slurm_rpc_kill_job: REQUEST_KILL_JOB JobId=47836 uid 548200003
[2022-08-11T14:09:21.883] _slurm_rpc_submit_batch_job: JobId=47837 InitPrio=22016 usec=427
[2022-08-11T14:09:22.728] sched: Allocate JobId=47837 NodeList=cpu03 #CPUs=32 Partition=cpu-opteron
[2022-08-11T14:09:27.768] _job_complete: JobId=47837 WEXITSTATUS 0
[2022-08-11T14:09:27.769] _job_complete: JobId=47837 done
[2022-08-11T14:09:29.545] _slurm_rpc_submit_batch_job: JobId=47838 InitPrio=26613 usec=422
[2022-08-11T14:09:29.737] sched: Allocate JobId=47838 NodeList=gpu02 #CPUs=16 Partition=gpu-titan
[2022-08-11T14:09:59.657] _slurm_rpc_submit_batch_job: JobId=47839 InitPrio=22016 usec=391
[2022-08-11T14:09:59.777] sched: Allocate JobId=47839 NodeList=cpu03 #CPUs=32 Partition=cpu-opteron
[2022-08-11T14:10:03.353] _job_complete: JobId=47839 WEXITSTATUS 0
[2022-08-11T14:10:03.353] _job_complete: JobId=47839 done
[2022-08-11T14:10:11.410] _slurm_rpc_submit_batch_job: JobId=47840 InitPrio=23395 usec=529
[2022-08-11T14:10:13.984] sched/backfill: _start_job: Started JobId=47840 in cpu-epyc on cpu15
[2022-08-11T14:10:23.053] _slurm_rpc_kill_job: REQUEST_KILL_JOB JobId=47838 uid 548300580
[2022-08-11T14:10:29.866] _slurm_rpc_submit_batch_job: JobId=47841 InitPrio=26699 usec=410
[2022-08-11T14:10:30.817] sched: Allocate JobId=47841 NodeList=gpu02 #CPUs=6 Partition=gpu-titan
[2022-08-11T14:10:35.567] _job_complete: JobId=47840 WEXITSTATUS 0
[2022-08-11T14:10:35.567] _job_complete: JobId=47840 done
[2022-08-11T14:11:19.873] _slurm_rpc_submit_batch_job: JobId=47842 InitPrio=26699 usec=416
[2022-08-11T14:37:45.604] _slurm_rpc_submit_batch_job: JobId=47843 InitPrio=23894 usec=448
[2022-08-11T14:38:19.252] _slurm_rpc_submit_batch_job: JobId=47844 InitPrio=25039 usec=420
[2022-08-11T14:43:18.763] sched: _slurm_rpc_allocate_resources JobId=47845 NodeList=cpu15 usec=54819
[2022-08-11T14:53:39.514] Processing Reconfiguration Request
[2022-08-11T14:53:39.521] restoring original state of nodes
[2022-08-11T14:53:39.521] select/cons_tres: part_data_create_array: select/cons_tres: preparing for 6 partitions
[2022-08-11T14:53:39.522] read_slurm_conf: backup_controller not specified
[2022-08-11T14:53:39.522] select/cons_tres: select_p_reconfigure: select/cons_tres: reconfigure
[2022-08-11T14:53:39.522] select/cons_tres: part_data_create_array: select/cons_tres: preparing for 6 partitions
[2022-08-11T14:53:39.523] No parameter for mcs plugin, default values set
[2022-08-11T14:53:39.523] mcs: MCSParameters = (null). ondemand set.
[2022-08-11T14:53:39.523] _slurm_rpc_reconfigure_controller: completed usec=9144
[2022-08-11T14:53:40.177] SchedulerParameters=default_queue_depth=100,max_rpc_cnt=0,max_sched_time=2,partition_job_depth=0,sched_max_job_start=0,sched_min_interval=2
[2022-08-11T14:54:38.655] Processing Reconfiguration Request
[2022-08-11T14:54:38.662] restoring original state of nodes
[2022-08-11T14:54:38.662] select/cons_tres: part_data_create_array: select/cons_tres: preparing for 6 partitions
[2022-08-11T14:54:38.663] read_slurm_conf: backup_controller not specified
[2022-08-11T14:54:38.663] select/cons_tres: select_p_reconfigure: select/cons_tres: reconfigure
[2022-08-11T14:54:38.663] select/cons_tres: part_data_create_array: select/cons_tres: preparing for 6 partitions
[2022-08-11T14:54:38.663] No parameter for mcs plugin, default values set
[2022-08-11T14:54:38.663] mcs: MCSParameters = (null). ondemand set.
[2022-08-11T14:54:38.664] _slurm_rpc_reconfigure_controller: completed usec=8752
[2022-08-11T14:54:39.256] SchedulerParameters=default_queue_depth=100,max_rpc_cnt=0,max_sched_time=2,partition_job_depth=0,sched_max_job_start=0,sched_min_interval=2
[2022-08-11T14:55:37.987] _slurm_rpc_kill_job: REQUEST_KILL_JOB JobId=47844 uid 548300543
[2022-08-11T14:57:37.775] _job_complete: JobId=47832 WEXITSTATUS 1
[2022-08-11T14:57:37.776] _job_complete: JobId=47832 done
[2022-08-11T15:01:29.260] Processing Reconfiguration Request
[2022-08-11T15:01:29.267] restoring original state of nodes
[2022-08-11T15:01:29.267] select/cons_tres: part_data_create_array: select/cons_tres: preparing for 6 partitions
[2022-08-11T15:01:29.268] read_slurm_conf: backup_controller not specified
[2022-08-11T15:01:29.268] select/cons_tres: select_p_reconfigure: select/cons_tres: reconfigure
[2022-08-11T15:01:29.268] select/cons_tres: part_data_create_array: select/cons_tres: preparing for 6 partitions
[2022-08-11T15:01:29.268] No parameter for mcs plugin, default values set
[2022-08-11T15:01:29.268] mcs: MCSParameters = (null). ondemand set.
[2022-08-11T15:01:29.269] _slurm_rpc_reconfigure_controller: completed usec=9147
[2022-08-11T15:01:29.923] SchedulerParameters=default_queue_depth=100,max_rpc_cnt=0,max_sched_time=2,partition_job_depth=0,sched_max_job_start=0,sched_min_interval=2
[2022-08-11T15:03:17.743] Processing Reconfiguration Request
[2022-08-11T15:03:17.750] restoring original state of nodes
[2022-08-11T15:03:17.750] select/cons_tres: part_data_create_array: select/cons_tres: preparing for 6 partitions
[2022-08-11T15:03:17.751] read_slurm_conf: backup_controller not specified
[2022-08-11T15:03:17.751] select/cons_tres: select_p_reconfigure: select/cons_tres: reconfigure
[2022-08-11T15:03:17.751] select/cons_tres: part_data_create_array: select/cons_tres: preparing for 6 partitions
[2022-08-11T15:03:17.751] No parameter for mcs plugin, default values set
[2022-08-11T15:03:17.751] mcs: MCSParameters = (null). ondemand set.
[2022-08-11T15:03:17.752] _slurm_rpc_reconfigure_controller: completed usec=8704
[2022-08-11T15:03:18.169] SchedulerParameters=default_queue_depth=100,max_rpc_cnt=0,max_sched_time=2,partition_job_depth=0,sched_max_job_start=0,sched_min_interval=2
[2022-08-11T15:04:20.213] Processing Reconfiguration Request
[2022-08-11T15:04:20.219] restoring original state of nodes
[2022-08-11T15:04:20.219] select/cons_tres: part_data_create_array: select/cons_tres: preparing for 6 partitions
[2022-08-11T15:04:20.220] read_slurm_conf: backup_controller not specified
[2022-08-11T15:04:20.220] select/cons_tres: select_p_reconfigure: select/cons_tres: reconfigure
[2022-08-11T15:04:20.220] select/cons_tres: part_data_create_array: select/cons_tres: preparing for 6 partitions
[2022-08-11T15:04:20.220] No parameter for mcs plugin, default values set
[2022-08-11T15:04:20.220] mcs: MCSParameters = (null). ondemand set.
[2022-08-11T15:04:20.221] _slurm_rpc_reconfigure_controller: completed usec=8139
[2022-08-11T15:04:21.256] SchedulerParameters=default_queue_depth=100,max_rpc_cnt=0,max_sched_time=2,partition_job_depth=0,sched_max_job_start=0,sched_min_interval=2
[2022-08-11T15:04:33.926] _slurm_rpc_kill_job: REQUEST_KILL_JOB JobId=47843 uid 548200003
[2022-08-11T15:32:21.666] _slurm_rpc_requeue: Requeue of JobId=47842 returned an error: Job is pending execution
[2022-08-11T15:32:26.709] Requeuing JobId=47841
[2022-08-11T15:32:26.713] sched: Allocate JobId=47842 NodeList=gpu02 #CPUs=6 Partition=gpu-titan
[2022-08-11T15:32:37.498] Requeuing JobId=47842
[2022-08-11T15:41:10.938] Time limit exhausted for JobId=47759
[2022-08-11T15:43:40.254] Time limit exhausted for JobId=47845
[2022-08-11T15:45:40.785] _get_job_parts: invalid partition specified: =cpu-epyc
[2022-08-11T15:45:40.785] _slurm_rpc_allocate_resources: Invalid partition name specified 
[2022-08-11T15:45:53.681] sched: _slurm_rpc_allocate_resources JobId=47846 NodeList=(null) usec=623
[2022-08-11T15:45:54.455] sched: Allocate JobId=47846 NodeList=cpu12 #CPUs=4 Partition=cpu-epyc
[2022-08-11T15:48:40.575] cleanup_completing: JobId=47845 completion process took 300 seconds
[2022-08-11T15:49:40.873] job_time_limit: inactivity time limit reached for JobId=47846
[2022-08-11T15:53:29.590] _slurm_rpc_kill_job: REQUEST_KILL_JOB JobId=47842 uid 548300580
[2022-08-11T15:53:29.590] _slurm_rpc_kill_job: REQUEST_KILL_JOB JobId=47841 uid 548300580
[2022-08-11T15:54:43.398] cleanup_completing: JobId=47846 completion process took 303 seconds
[2022-08-11T15:54:48.795] _slurm_rpc_kill_job: REQUEST_KILL_JOB JobId=47846 uid 548300595
[2022-08-11T15:55:47.835] sched: _slurm_rpc_allocate_resources JobId=47847 NodeList=(null) usec=1134
[2022-08-11T15:55:48.454] sched: Allocate JobId=47847 NodeList=cpu15 #CPUs=4 Partition=cpu-epyc
[2022-08-11T16:26:47.143] _job_complete: JobId=47847 WEXITSTATUS 0
[2022-08-11T16:26:47.143] _job_complete: JobId=47847 done
[2022-08-11T16:27:07.070] _slurm_rpc_submit_batch_job: JobId=47848 InitPrio=9389 usec=402
[2022-08-11T16:27:07.799] sched: Allocate JobId=47848 NodeList=cpu15 #CPUs=1 Partition=cpu-epyc
[2022-08-11T16:27:08.268] _job_complete: JobId=47848 WEXITSTATUS 127
[2022-08-11T16:27:08.268] _job_complete: JobId=47848 done
[2022-08-11T16:29:13.988] _slurm_rpc_submit_batch_job: JobId=47849 InitPrio=9154 usec=377
[2022-08-11T16:29:14.022] sched: Allocate JobId=47849 NodeList=cpu15 #CPUs=1 Partition=cpu-epyc
[2022-08-11T16:42:31.664] _job_complete: JobId=47849 WEXITSTATUS 0
[2022-08-11T16:42:31.665] _job_complete: JobId=47849 done
[2022-08-11T17:16:56.074] sched: _slurm_rpc_allocate_resources JobId=47850 NodeList=(null) usec=1083
[2022-08-11T17:16:56.900] sched: Allocate JobId=47850 NodeList=cpu15 #CPUs=1 Partition=cpu-epyc
[2022-08-11T17:28:44.765] _job_complete: JobId=47850 WEXITSTATUS 0
[2022-08-11T17:28:44.766] _job_complete: JobId=47850 done
[2022-08-11T17:32:43.699] _slurm_rpc_submit_batch_job: JobId=47851 InitPrio=9154 usec=386
[2022-08-11T17:32:44.634] sched: Allocate JobId=47851 NodeList=cpu15 #CPUs=1 Partition=cpu-epyc
[2022-08-11T17:34:58.671] _slurm_rpc_kill_job: REQUEST_KILL_JOB JobId=47851 uid 548300595
[2022-08-11T17:35:59.826] _slurm_rpc_submit_batch_job: JobId=47852 InitPrio=9154 usec=443
[2022-08-11T17:35:59.941] sched: Allocate JobId=47852 NodeList=cpu15 #CPUs=1 Partition=cpu-epyc
[2022-08-11T17:38:51.990] _slurm_rpc_submit_batch_job: JobId=47853 InitPrio=3990 usec=440
[2022-08-11T17:39:12.376] _slurm_rpc_kill_job: REQUEST_KILL_JOB JobId=47852 uid 548300595
[2022-08-11T17:39:15.247] sched/backfill: _start_job: Started JobId=47853 in cpu-epyc on cpu12
[2022-08-11T17:39:18.614] _job_complete: JobId=47853 WEXITSTATUS 1
[2022-08-11T17:39:18.615] _job_complete: JobId=47853 done
[2022-08-11T17:39:27.662] _slurm_rpc_kill_job: REQUEST_KILL_JOB JobId=47853 uid 548200084
[2022-08-11T17:39:39.942] _slurm_rpc_submit_batch_job: JobId=47854 InitPrio=3990 usec=462
[2022-08-11T17:39:40.388] sched: Allocate JobId=47854 NodeList=cpu03 #CPUs=8 Partition=cpu-opteron
[2022-08-11T17:39:40.703] _slurm_rpc_submit_batch_job: JobId=47855 InitPrio=9154 usec=370
[2022-08-11T17:39:43.014] _job_complete: JobId=47854 WEXITSTATUS 1
[2022-08-11T17:39:43.014] _job_complete: JobId=47854 done
[2022-08-11T17:39:43.393] sched: Allocate JobId=47855 NodeList=cpu15 #CPUs=1 Partition=cpu-epyc
[2022-08-11T17:40:14.843] _slurm_rpc_kill_job: REQUEST_KILL_JOB JobId=47852 uid 548300595
[2022-08-11T17:41:48.015] _slurm_rpc_kill_job: REQUEST_KILL_JOB JobId=47855 uid 548300595
[2022-08-11T17:42:29.974] _slurm_rpc_submit_batch_job: JobId=47856 InitPrio=9154 usec=444
[2022-08-11T17:42:30.631] sched: Allocate JobId=47856 NodeList=cpu15 #CPUs=1 Partition=cpu-epyc
[2022-08-11T17:47:40.106] _job_complete: JobId=47856 WEXITSTATUS 0
[2022-08-11T17:47:40.107] _job_complete: JobId=47856 done
[2022-08-11T17:56:55.623] _slurm_rpc_submit_batch_job: JobId=47857 InitPrio=3990 usec=486
[2022-08-11T17:57:12.770] _slurm_rpc_kill_job: REQUEST_KILL_JOB JobId=47857 uid 548200084
[2022-08-11T17:57:24.610] _slurm_rpc_submit_batch_job: JobId=47858 InitPrio=3990 usec=410
[2022-08-11T17:57:26.158] sched: Allocate JobId=47858 NodeList=cpu03 #CPUs=8 Partition=cpu-opteron
[2022-08-11T17:57:31.216] _job_complete: JobId=47858 WEXITSTATUS 1
[2022-08-11T17:57:31.216] _job_complete: JobId=47858 done
[2022-08-11T20:14:17.551] error: SECURITY VIOLATION: Attempt to suspend job from user 548200045
[2022-08-11T20:14:17.551] _slurm_rpc_suspend(resume) for 47745 Access/permission denied
[2022-08-11T20:14:29.961] _slurm_rpc_kill_job: REQUEST_KILL_JOB JobId=47745 uid 548200045
[2022-08-11T20:15:24.789] _slurm_rpc_submit_batch_job: JobId=47859 InitPrio=938 usec=403
[2022-08-11T20:15:26.739] sched: Allocate JobId=47859 NodeList=gpu02 #CPUs=16 Partition=gpu-titan
[2022-08-11T20:16:05.766] _job_complete: JobId=47859 WEXITSTATUS 0
[2022-08-11T20:16:05.767] _job_complete: JobId=47859 done
[2022-08-11T20:18:52.300] _slurm_rpc_submit_batch_job: JobId=47860 InitPrio=938 usec=366
[2022-08-11T20:18:53.102] sched: Allocate JobId=47860 NodeList=gpu02 #CPUs=16 Partition=gpu-titan
[2022-08-11T20:23:17.552] _slurm_rpc_submit_batch_job: JobId=47861 InitPrio=2816 usec=905
[2022-08-11T20:23:17.612] sched: Allocate JobId=47861 NodeList=gpu03 #CPUs=16 Partition=gpu-k10
[2022-08-11T20:35:43.782] _slurm_rpc_submit_batch_job: JobId=47862 InitPrio=469 usec=492
[2022-08-11T20:46:21.680] _slurm_rpc_submit_batch_job: JobId=47863 InitPrio=469 usec=501
[2022-08-11T20:48:04.897] _slurm_rpc_kill_job: REQUEST_KILL_JOB JobId=47862 uid 548200021
[2022-08-11T20:48:13.234] _slurm_rpc_kill_job: REQUEST_KILL_JOB JobId=47863 uid 548200021
[2022-08-11T20:50:39.504] _slurm_rpc_submit_batch_job: JobId=47864 InitPrio=469 usec=526
[2022-08-11T21:36:11.870] _slurm_rpc_submit_batch_job: JobId=47865 InitPrio=2816 usec=420
[2022-08-11T21:36:12.212] sched: Allocate JobId=47865 NodeList=cpu03 #CPUs=32 Partition=cpu-opteron
[2022-08-11T21:36:14.439] _job_complete: JobId=47865 WEXITSTATUS 1
[2022-08-11T21:36:14.439] _job_complete: JobId=47865 done
[2022-08-11T22:30:06.660] _slurm_rpc_submit_batch_job: JobId=47866 InitPrio=1173 usec=469
[2022-08-11T22:30:07.032] sched: Allocate JobId=47866 NodeList=cpu11 #CPUs=48 Partition=cpu-opteron
[2022-08-11T22:32:31.149] _slurm_rpc_submit_batch_job: JobId=47867 InitPrio=1173 usec=437
[2022-08-11T22:32:31.216] sched: Allocate JobId=47867 NodeList=cpu08 #CPUs=16 Partition=cpu-opteron
[2022-08-11T23:26:24.781] _job_complete: JobId=47860 WEXITSTATUS 0
[2022-08-11T23:26:24.781] _job_complete: JobId=47860 done
[2022-08-11T23:45:41.928] Time limit exhausted for JobId=46868
[2022-08-11T23:46:13.803] _slurm_rpc_submit_batch_job: JobId=47868 InitPrio=1173 usec=549
[2022-08-11T23:46:13.981] sched: Allocate JobId=47868 NodeList=cpu09 #CPUs=24 Partition=cpu-opteron
[2022-08-11T23:46:16.449] _job_complete: JobId=47868 WEXITSTATUS 1
[2022-08-11T23:46:16.449] _job_complete: JobId=47868 done
[2022-08-11T23:47:02.558] _slurm_rpc_submit_batch_job: JobId=47869 InitPrio=1173 usec=472
[2022-08-11T23:47:03.049] sched: Allocate JobId=47869 NodeList=cpu09 #CPUs=24 Partition=cpu-opteron
[2022-08-11T23:49:14.277] _job_complete: JobId=47327 WEXITSTATUS 0
[2022-08-11T23:49:14.277] _job_complete: JobId=47327 done
[2022-08-12T00:18:36.919] _slurm_rpc_submit_batch_job: JobId=47870 InitPrio=938 usec=404
[2022-08-12T00:18:37.613] sched: Allocate JobId=47870 NodeList=gpu02 #CPUs=16 Partition=gpu-titan
[2022-08-12T00:18:41.474] _job_complete: JobId=47870 WEXITSTATUS 0
[2022-08-12T00:18:41.512] _job_complete: JobId=47870 done
[2022-08-12T00:44:36.973] _slurm_rpc_submit_batch_job: JobId=47871 InitPrio=938 usec=468
[2022-08-12T00:44:37.209] sched: Allocate JobId=47871 NodeList=gpu02 #CPUs=16 Partition=gpu-titan
[2022-08-12T01:20:22.073] _slurm_rpc_submit_batch_job: JobId=47872 InitPrio=938 usec=466
[2022-08-12T01:22:32.612] _slurm_rpc_submit_batch_job: JobId=47873 InitPrio=1173 usec=437
[2022-08-12T01:22:33.571] sched: Allocate JobId=47873 NodeList=cpu10 #CPUs=24 Partition=cpu-opteron
[2022-08-12T01:23:03.807] _slurm_rpc_submit_batch_job: JobId=47874 InitPrio=1173 usec=405
[2022-08-12T01:23:04.691] sched: Allocate JobId=47874 NodeList=cpu01 #CPUs=24 Partition=cpu-opteron
[2022-08-12T02:23:23.295] _slurm_rpc_submit_batch_job: JobId=47875 InitPrio=1173 usec=539
[2022-08-12T02:23:26.026] sched: Allocate JobId=47875 NodeList=cpu03 #CPUs=48 Partition=cpu-opteron
[2022-08-12T02:33:10.102] _slurm_rpc_submit_batch_job: JobId=47876 InitPrio=1173 usec=617
[2022-08-12T02:33:11.025] sched: Allocate JobId=47876 NodeList=cpu01 #CPUs=40 Partition=cpu-opteron
[2022-08-12T02:40:49.635] _slurm_rpc_submit_batch_job: JobId=47877 InitPrio=1173 usec=484
[2022-08-12T02:40:49.792] sched: Allocate JobId=47877 NodeList=cpu10 #CPUs=16 Partition=cpu-opteron
[2022-08-12T02:55:40.707] _slurm_rpc_submit_batch_job: JobId=47878 InitPrio=1173 usec=454
[2022-08-12T02:55:41.311] sched: Allocate JobId=47878 NodeList=cpu04 #CPUs=24 Partition=cpu-opteron
[2022-08-12T03:02:36.143] _slurm_rpc_submit_batch_job: JobId=47879 InitPrio=1173 usec=466
[2022-08-12T03:02:37.086] sched: Allocate JobId=47879 NodeList=cpu04 #CPUs=40 Partition=cpu-opteron
[2022-08-12T04:15:00.253] _job_complete: JobId=47871 WEXITSTATUS 0
[2022-08-12T04:15:00.258] _job_complete: JobId=47871 done
[2022-08-12T04:15:00.680] sched: Allocate JobId=47872 NodeList=gpu02 #CPUs=16 Partition=gpu-titan
[2022-08-12T08:06:37.858] _slurm_rpc_submit_batch_job: JobId=47880 InitPrio=234 usec=603
[2022-08-12T08:08:57.629] _slurm_rpc_submit_batch_job: JobId=47881 InitPrio=234 usec=457
[2022-08-12T09:33:37.986] _slurm_rpc_submit_batch_job: JobId=47882 InitPrio=2347 usec=626
[2022-08-12T09:33:43.838] _slurm_rpc_submit_batch_job: JobId=47883 InitPrio=2347 usec=455
[2022-08-12T09:33:48.237] _slurm_rpc_submit_batch_job: JobId=47884 InitPrio=2347 usec=491
[2022-08-12T09:33:54.254] _slurm_rpc_submit_batch_job: JobId=47885 InitPrio=2347 usec=416
[2022-08-12T09:33:58.670] _slurm_rpc_submit_batch_job: JobId=47886 InitPrio=2347 usec=431
[2022-08-12T09:34:03.118] _slurm_rpc_submit_batch_job: JobId=47887 InitPrio=2347 usec=495
[2022-08-12T09:34:07.086] _slurm_rpc_submit_batch_job: JobId=47888 InitPrio=2347 usec=441
[2022-08-12T09:34:16.484] sched/backfill: _start_job: Started JobId=47882 in cpu-epyc on cpu12
[2022-08-12T09:34:16.485] sched/backfill: _start_job: Started JobId=47883 in cpu-epyc on cpu13
[2022-08-12T09:34:16.486] sched/backfill: _start_job: Started JobId=47884 in cpu-epyc on cpu14
[2022-08-12T09:36:08.190] _slurm_rpc_submit_batch_job: JobId=47889 InitPrio=2347 usec=361
[2022-08-12T09:39:06.480] _slurm_rpc_submit_batch_job: JobId=47890 InitPrio=2347 usec=380
[2022-08-12T09:39:12.328] _slurm_rpc_submit_batch_job: JobId=47891 InitPrio=2347 usec=433
[2022-08-12T09:39:20.832] _slurm_rpc_submit_batch_job: JobId=47892 InitPrio=2347 usec=512
[2022-08-12T09:39:25.249] _slurm_rpc_submit_batch_job: JobId=47893 InitPrio=2347 usec=388
[2022-08-12T09:39:29.712] _slurm_rpc_submit_batch_job: JobId=47894 InitPrio=2347 usec=454
[2022-08-12T09:39:34.201] _slurm_rpc_submit_batch_job: JobId=47895 InitPrio=2347 usec=593
[2022-08-12T09:39:38.740] _slurm_rpc_submit_batch_job: JobId=47896 InitPrio=2347 usec=422
[2022-08-12T09:53:38.792] _job_complete: JobId=47883 WEXITSTATUS 0
[2022-08-12T09:53:38.793] _job_complete: JobId=47883 done
[2022-08-12T09:53:44.655] _job_complete: JobId=47882 WEXITSTATUS 0
[2022-08-12T09:53:44.655] _job_complete: JobId=47882 done
[2022-08-12T09:53:46.331] _job_complete: JobId=47884 WEXITSTATUS 0
[2022-08-12T09:53:46.331] _job_complete: JobId=47884 done
[2022-08-12T09:54:16.536] sched/backfill: _start_job: Started JobId=47885 in cpu-epyc on cpu12
[2022-08-12T09:54:16.537] sched/backfill: _start_job: Started JobId=47886 in cpu-epyc on cpu13
[2022-08-12T09:54:16.537] sched/backfill: _start_job: Started JobId=47887 in cpu-epyc on cpu14
[2022-08-12T10:03:20.647] Requeuing JobId=47872
[2022-08-12T10:04:29.377] sched: Created reservation=gpu02_pcp users=jitkang nodes=gpu02 cores=16 licenses=(null) tres=cpu=32 watts=4294967294 start=2022-08-12T10:04:29 end=2023-08-12T10:04:29 MaxStartDelay=
[2022-08-12T10:13:37.546] _job_complete: JobId=47886 WEXITSTATUS 0
[2022-08-12T10:13:37.546] _job_complete: JobId=47886 done
[2022-08-12T10:13:45.184] _job_complete: JobId=47885 WEXITSTATUS 0
[2022-08-12T10:13:45.185] _job_complete: JobId=47885 done
[2022-08-12T10:13:53.338] _job_complete: JobId=47887 WEXITSTATUS 0
[2022-08-12T10:13:53.338] _job_complete: JobId=47887 done
[2022-08-12T10:14:05.901] sched: Updated reservation=gpu02_pcp users=jitkang,yeehengteh nodes=gpu02 cores=16 licenses=(null) tres=cpu=32 watts=4294967294 start=2022-08-12T10:04:29 end=2023-08-12T10:04:29 MaxStartDelay=
[2022-08-12T10:14:16.587] sched/backfill: _start_job: Started JobId=47888 in cpu-epyc on cpu12
[2022-08-12T10:14:16.588] sched/backfill: _start_job: Started JobId=47889 in cpu-epyc on cpu13
[2022-08-12T10:14:16.588] sched/backfill: _start_job: Started JobId=47890 in cpu-epyc on cpu14
[2022-08-12T10:15:14.616] _slurm_rpc_submit_batch_job: JobId=47897 InitPrio=15633 usec=487
[2022-08-12T10:15:15.586] sched: Allocate JobId=47897 NodeList=gpu02 #CPUs=8 Partition=gpu-titan
[2022-08-12T10:20:50.853] _slurm_rpc_kill_job: REQUEST_KILL_JOB JobId=47897 uid 548300543
[2022-08-12T10:21:53.742] _slurm_rpc_submit_batch_job: JobId=47898 InitPrio=15633 usec=579
[2022-08-12T10:21:54.207] sched: Allocate JobId=47898 NodeList=gpu02 #CPUs=8 Partition=gpu-titan
[2022-08-12T10:24:55.555] _job_complete: JobId=47898 WEXITSTATUS 0
[2022-08-12T10:24:55.556] _job_complete: JobId=47898 done
[2022-08-12T10:29:01.720] _slurm_rpc_submit_batch_job: JobId=47899 InitPrio=15633 usec=474
[2022-08-12T10:29:01.991] sched: Allocate JobId=47899 NodeList=gpu02 #CPUs=8 Partition=gpu-titan
[2022-08-12T10:29:27.283] _slurm_rpc_submit_batch_job: JobId=47900 InitPrio=15633 usec=469
[2022-08-12T10:29:28.027] sched: Allocate JobId=47900 NodeList=gpu02 #CPUs=8 Partition=gpu-titan
[2022-08-12T10:29:58.480] _slurm_rpc_submit_batch_job: JobId=47901 InitPrio=15633 usec=548
[2022-08-12T10:30:21.545] _slurm_rpc_submit_batch_job: JobId=47902 InitPrio=15633 usec=450
[2022-08-12T10:30:59.450] _slurm_rpc_submit_batch_job: JobId=47903 InitPrio=15633 usec=503
[2022-08-12T10:32:29.407] _job_complete: JobId=47899 WEXITSTATUS 0
[2022-08-12T10:32:29.407] _job_complete: JobId=47899 done
[2022-08-12T10:32:29.914] sched: Allocate JobId=47901 NodeList=gpu02 #CPUs=8 Partition=gpu-titan
[2022-08-12T10:33:40.281] _job_complete: JobId=47889 WEXITSTATUS 0
[2022-08-12T10:33:40.282] _job_complete: JobId=47889 done
[2022-08-12T10:33:56.823] _job_complete: JobId=47890 WEXITSTATUS 0
[2022-08-12T10:33:56.823] _job_complete: JobId=47890 done
[2022-08-12T10:34:10.946] _job_complete: JobId=47888 WEXITSTATUS 0
[2022-08-12T10:34:10.946] _job_complete: JobId=47888 done
[2022-08-12T10:34:16.636] sched/backfill: _start_job: Started JobId=47891 in cpu-epyc on cpu12
[2022-08-12T10:34:16.637] sched/backfill: _start_job: Started JobId=47892 in cpu-epyc on cpu13
[2022-08-12T10:34:16.637] sched/backfill: _start_job: Started JobId=47893 in cpu-epyc on cpu14
[2022-08-12T10:36:34.316] _job_complete: JobId=47900 WEXITSTATUS 0
[2022-08-12T10:36:34.316] _job_complete: JobId=47900 done
[2022-08-12T10:37:16.644] sched/backfill: _start_job: Started JobId=47903 in gpu-titan on gpu02
[2022-08-12T10:40:00.889] _job_complete: JobId=47903 WEXITSTATUS 0
[2022-08-12T10:40:00.889] _job_complete: JobId=47903 done
[2022-08-12T10:40:51.202] _job_complete: JobId=47901 WEXITSTATUS 0
[2022-08-12T10:40:51.202] _job_complete: JobId=47901 done
[2022-08-12T10:40:52.230] sched: Allocate JobId=47902 NodeList=gpu02 #CPUs=8 Partition=gpu-titan
[2022-08-12T10:46:45.509] _job_complete: JobId=47902 WEXITSTATUS 0
[2022-08-12T10:46:45.509] _job_complete: JobId=47902 done
[2022-08-12T10:53:40.459] _job_complete: JobId=47893 WEXITSTATUS 0
[2022-08-12T10:53:40.459] _job_complete: JobId=47893 done
[2022-08-12T10:53:43.163] _job_complete: JobId=47891 WEXITSTATUS 0
[2022-08-12T10:53:43.163] _job_complete: JobId=47891 done
[2022-08-12T10:53:56.847] _job_complete: JobId=47892 WEXITSTATUS 0
[2022-08-12T10:53:56.847] _job_complete: JobId=47892 done
[2022-08-12T10:54:16.687] sched/backfill: _start_job: Started JobId=47894 in cpu-epyc on cpu12
[2022-08-12T10:54:16.687] sched/backfill: _start_job: Started JobId=47895 in cpu-epyc on cpu13
[2022-08-12T10:54:16.688] sched/backfill: _start_job: Started JobId=47896 in cpu-epyc on cpu14
[2022-08-12T11:13:58.501] _job_complete: JobId=47895 WEXITSTATUS 0
[2022-08-12T11:13:58.501] _job_complete: JobId=47895 done
[2022-08-12T11:14:03.039] _job_complete: JobId=47894 WEXITSTATUS 0
[2022-08-12T11:14:03.039] _job_complete: JobId=47894 done
[2022-08-12T11:14:06.244] _job_complete: JobId=47896 WEXITSTATUS 0
[2022-08-12T11:14:06.244] _job_complete: JobId=47896 done
[2022-08-12T11:18:41.367] _slurm_rpc_delete_reservation complete for gpu02_pcp usec=66
[2022-08-12T11:39:27.331] _slurm_rpc_submit_batch_job: JobId=47904 InitPrio=15633 usec=552
[2022-08-12T11:39:28.279] sched: Allocate JobId=47904 NodeList=gpu02 #CPUs=8 Partition=gpu-titan
[2022-08-12T11:39:51.878] _slurm_rpc_submit_batch_job: JobId=47905 InitPrio=15633 usec=469
[2022-08-12T11:39:52.309] sched: Allocate JobId=47905 NodeList=gpu02 #CPUs=8 Partition=gpu-titan
[2022-08-12T11:40:25.118] _slurm_rpc_submit_batch_job: JobId=47906 InitPrio=15633 usec=487
[2022-08-12T11:40:49.830] _slurm_rpc_submit_batch_job: JobId=47907 InitPrio=15633 usec=429
[2022-08-12T11:41:15.983] _slurm_rpc_submit_batch_job: JobId=47908 InitPrio=15633 usec=537
[2022-08-12T11:42:41.771] _job_complete: JobId=47904 WEXITSTATUS 0
[2022-08-12T11:42:41.772] _job_complete: JobId=47904 done
[2022-08-12T11:42:42.256] sched: Allocate JobId=47906 NodeList=gpu02 #CPUs=8 Partition=gpu-titan
[2022-08-12T11:46:42.911] _job_complete: JobId=47905 WEXITSTATUS 0
[2022-08-12T11:46:42.911] _job_complete: JobId=47905 done
[2022-08-12T11:50:36.601] _job_complete: JobId=47906 WEXITSTATUS 0
[2022-08-12T11:50:36.601] _job_complete: JobId=47906 done
[2022-08-12T11:50:37.645] sched: Allocate JobId=47907 NodeList=gpu02 #CPUs=8 Partition=gpu-titan
[2022-08-12T11:50:37.645] sched: Allocate JobId=47908 NodeList=gpu02 #CPUs=8 Partition=gpu-titan
[2022-08-12T11:53:33.379] _job_complete: JobId=47908 WEXITSTATUS 0
[2022-08-12T11:53:33.379] _job_complete: JobId=47908 done
[2022-08-12T11:57:41.357] _job_complete: JobId=47907 WEXITSTATUS 0
[2022-08-12T11:57:41.357] _job_complete: JobId=47907 done
[2022-08-12T12:08:30.999] _slurm_rpc_submit_batch_job: JobId=47909 InitPrio=5633 usec=408
[2022-08-12T12:08:31.255] sched: Allocate JobId=47909 NodeList=cpu03 #CPUs=16 Partition=cpu-opteron
[2022-08-12T12:08:53.056] _slurm_rpc_submit_batch_job: JobId=47910 InitPrio=5633 usec=435
[2022-08-12T12:09:16.826] sched/backfill: _start_job: Started JobId=47910 in cpu-epyc on cpu12
[2022-08-12T12:10:20.602] _job_complete: JobId=47910 WEXITSTATUS 0
[2022-08-12T12:10:20.602] _job_complete: JobId=47910 done
[2022-08-12T12:10:42.618] _job_complete: JobId=47909 WEXITSTATUS 0
[2022-08-12T12:10:42.619] _job_complete: JobId=47909 done
[2022-08-12T12:19:49.230] sched: _slurm_rpc_allocate_resources JobId=47911 NodeList=(null) usec=1298
[2022-08-12T12:19:49.363] sched: Allocate JobId=47911 NodeList=cpu15 #CPUs=4 Partition=cpu-epyc
[2022-08-12T12:31:16.326] _slurm_rpc_kill_job: REQUEST_KILL_JOB JobId=47872 uid 548200045
[2022-08-12T12:31:59.284] _slurm_rpc_submit_batch_job: JobId=47912 InitPrio=1173 usec=480
[2022-08-12T12:31:59.549] sched: Allocate JobId=47912 NodeList=gpu02 #CPUs=16 Partition=gpu-titan
[2022-08-12T12:38:41.145] _job_complete: JobId=47911 WEXITSTATUS 0
[2022-08-12T12:38:41.145] _job_complete: JobId=47911 done
[2022-08-12T12:46:16.261] _slurm_rpc_submit_batch_job: JobId=47913 InitPrio=18920 usec=477
[2022-08-12T12:46:16.885] sched: Allocate JobId=47913 NodeList=cpu15 #CPUs=1 Partition=cpu-epyc
[2022-08-12T12:46:30.274] _job_complete: JobId=47913 WEXITSTATUS 0
[2022-08-12T12:46:30.275] _job_complete: JobId=47913 done
[2022-08-12T12:50:39.600] _slurm_rpc_submit_batch_job: JobId=47914 InitPrio=18920 usec=484
[2022-08-12T12:50:40.266] sched: Allocate JobId=47914 NodeList=cpu15 #CPUs=1 Partition=cpu-epyc
[2022-08-12T12:51:17.133] _job_complete: JobId=47914 WEXITSTATUS 0
[2022-08-12T12:51:17.134] _job_complete: JobId=47914 done
[2022-08-12T13:48:30.443] _slurm_rpc_kill_job: REQUEST_KILL_JOB JobId=47867 uid 548200019
[2022-08-12T14:08:09.893] Requeuing JobId=47912
[2022-08-12T14:19:13.265] _slurm_rpc_submit_batch_job: JobId=47915 InitPrio=18920 usec=414
[2022-08-12T14:19:13.408] sched: Allocate JobId=47915 NodeList=cpu15 #CPUs=1 Partition=cpu-epyc
[2022-08-12T14:19:15.574] _job_complete: JobId=47915 WEXITSTATUS 1
[2022-08-12T14:19:15.575] _job_complete: JobId=47915 done
[2022-08-12T14:21:12.161] _slurm_rpc_submit_batch_job: JobId=47916 InitPrio=18920 usec=423
[2022-08-12T14:21:12.552] sched: Allocate JobId=47916 NodeList=cpu15 #CPUs=1 Partition=cpu-epyc
[2022-08-12T14:21:18.797] _job_complete: JobId=47916 WEXITSTATUS 0
[2022-08-12T14:21:18.798] _job_complete: JobId=47916 done
[2022-08-12T14:25:11.175] _slurm_rpc_submit_batch_job: JobId=47917 InitPrio=8920 usec=531
[2022-08-12T14:25:11.945] sched: Allocate JobId=47917 NodeList=cpu15 #CPUs=1 Partition=cpu-epyc
[2022-08-12T14:50:44.305] Time limit exhausted for JobId=46877
[2022-08-12T14:50:46.192] sched: Allocate JobId=47684 NodeList=cpu15 #CPUs=32 Partition=cpu-epyc
[2022-08-12T15:03:52.675] _slurm_rpc_submit_batch_job: JobId=47918 InitPrio=938 usec=538
[2022-08-12T15:03:53.480] sched: Allocate JobId=47918 NodeList=cpu03 #CPUs=16 Partition=cpu-opteron
[2022-08-12T15:26:18.216] _job_complete: JobId=47917 WEXITSTATUS 0
[2022-08-12T15:26:18.217] _job_complete: JobId=47917 done
[2022-08-12T15:43:13.170] _slurm_rpc_submit_batch_job: JobId=47919 InitPrio=8920 usec=449
[2022-08-12T15:43:14.014] sched: Allocate JobId=47919 NodeList=cpu15 #CPUs=4 Partition=cpu-epyc
[2022-08-12T15:43:14.627] _job_complete: JobId=47919 WEXITSTATUS 1
[2022-08-12T15:43:14.628] _job_complete: JobId=47919 done
[2022-08-12T15:43:47.280] _slurm_rpc_submit_batch_job: JobId=47920 InitPrio=8920 usec=389
[2022-08-12T15:43:48.052] sched: Allocate JobId=47920 NodeList=cpu15 #CPUs=4 Partition=cpu-epyc
[2022-08-12T15:43:48.501] _job_complete: JobId=47920 WEXITSTATUS 1
[2022-08-12T15:43:48.501] _job_complete: JobId=47920 done
[2022-08-12T15:44:14.743] _slurm_rpc_submit_batch_job: JobId=47921 InitPrio=8920 usec=410
[2022-08-12T15:44:15.083] sched: Allocate JobId=47921 NodeList=cpu15 #CPUs=4 Partition=cpu-epyc
[2022-08-12T15:57:34.598] _job_complete: JobId=47921 WEXITSTATUS 0
[2022-08-12T15:57:34.599] _job_complete: JobId=47921 done
[2022-08-12T16:19:16.617] _slurm_rpc_submit_batch_job: JobId=47922 InitPrio=2816 usec=370
[2022-08-12T16:24:32.156] _slurm_rpc_submit_batch_job: JobId=47923 InitPrio=2816 usec=373
[2022-08-12T16:28:31.579] _slurm_rpc_submit_batch_job: JobId=47924 InitPrio=2816 usec=398
[2022-08-12T16:32:03.371] _slurm_rpc_submit_batch_job: JobId=47925 InitPrio=2816 usec=457
[2022-08-12T16:36:55.258] _slurm_rpc_submit_batch_job: JobId=47926 InitPrio=2816 usec=423
[2022-08-12T16:40:34.350] _slurm_rpc_submit_batch_job: JobId=47927 InitPrio=2816 usec=366
[2022-08-12T16:44:10.869] _slurm_rpc_submit_batch_job: JobId=47928 InitPrio=2816 usec=381
[2022-08-12T17:18:06.705] _slurm_rpc_kill_job: REQUEST_KILL_JOB JobId=47912 uid 548200045
[2022-08-12T17:18:39.096] _slurm_rpc_submit_batch_job: JobId=47929 InitPrio=1173 usec=538
[2022-08-12T17:18:40.052] sched: Allocate JobId=47929 NodeList=gpu02 #CPUs=16 Partition=gpu-titan
[2022-08-12T17:28:45.264] _slurm_rpc_submit_batch_job: JobId=47930 InitPrio=8450 usec=387
[2022-08-12T17:28:45.328] sched: Allocate JobId=47930 NodeList=cpu11 #CPUs=1 Partition=cpu-opteron
[2022-08-12T17:28:50.989] _job_complete: JobId=47930 WEXITSTATUS 0
[2022-08-12T17:28:50.990] _job_complete: JobId=47930 done
[2022-08-12T17:32:06.765] _slurm_rpc_submit_batch_job: JobId=47931 InitPrio=8450 usec=442
[2022-08-12T17:32:07.553] sched: Allocate JobId=47931 NodeList=cpu11 #CPUs=1 Partition=cpu-opteron
[2022-08-12T17:35:28.618] error: slurm_receive_msg [10.11.132.14:59824]: Zero Bytes were transmitted or received
[2022-08-12T17:35:28.824] error: slurm_receive_msg [10.11.132.14:59828]: Zero Bytes were transmitted or received
[2022-08-12T17:35:58.854] _job_complete: JobId=47931 WEXITSTATUS 0
[2022-08-12T17:35:58.855] _job_complete: JobId=47931 done
[2022-08-12T17:38:51.193] error: slurm_receive_msg [10.11.132.18:60668]: Zero Bytes were transmitted or received
[2022-08-12T17:40:38.909] _slurm_rpc_submit_batch_job: JobId=47932 InitPrio=8450 usec=400
[2022-08-12T17:40:39.334] sched: Allocate JobId=47932 NodeList=cpu11 #CPUs=1 Partition=cpu-opteron
[2022-08-12T17:40:59.750] _slurm_rpc_kill_job: REQUEST_KILL_JOB JobId=47932 uid 548300595
[2022-08-12T17:42:46.536] error: slurm_receive_msg [10.11.132.21:49448]: Zero Bytes were transmitted or received
[2022-08-12T17:43:36.021] error: slurm_receive_msg [10.11.132.23:33480]: Zero Bytes were transmitted or received
[2022-08-12T17:44:43.851] _slurm_rpc_submit_batch_job: JobId=47933 InitPrio=8450 usec=636
[2022-08-12T17:44:44.762] sched: Allocate JobId=47933 NodeList=cpu11 #CPUs=1 Partition=cpu-opteron
[2022-08-12T18:25:40.825] _job_complete: JobId=47933 WEXITSTATUS 0
[2022-08-12T18:25:40.826] _job_complete: JobId=47933 done
[2022-08-12T22:12:14.241] _slurm_rpc_submit_batch_job: JobId=47934 InitPrio=17981 usec=406
[2022-08-12T22:12:14.824] sched: Allocate JobId=47934 NodeList=cpu15 #CPUs=1 Partition=cpu-epyc
[2022-08-12T22:12:41.771] _job_complete: JobId=47934 WEXITSTATUS 0
[2022-08-12T22:12:41.772] _job_complete: JobId=47934 done
[2022-08-12T22:16:23.972] _slurm_rpc_submit_batch_job: JobId=47935 InitPrio=17981 usec=343
[2022-08-12T22:16:26.211] sched: Allocate JobId=47935 NodeList=cpu15 #CPUs=1 Partition=cpu-epyc
[2022-08-12T22:16:27.392] _job_complete: JobId=47935 WEXITSTATUS 0
[2022-08-12T22:16:27.393] _job_complete: JobId=47935 done
[2022-08-12T22:17:36.947] _slurm_rpc_submit_batch_job: JobId=47936 InitPrio=17981 usec=404
[2022-08-12T22:17:37.330] sched: Allocate JobId=47936 NodeList=cpu15 #CPUs=1 Partition=cpu-epyc
[2022-08-12T22:21:56.508] _job_complete: JobId=47936 WEXITSTATUS 0
[2022-08-12T22:21:56.509] _job_complete: JobId=47936 done
[2022-08-12T22:31:44.100] _slurm_rpc_submit_batch_job: JobId=47937 InitPrio=17981 usec=481
[2022-08-12T22:31:44.577] sched: Allocate JobId=47937 NodeList=cpu15 #CPUs=1 Partition=cpu-epyc
[2022-08-12T23:03:19.313] _job_complete: JobId=47937 WEXITSTATUS 0
[2022-08-12T23:03:19.314] _job_complete: JobId=47937 done
[2022-08-12T23:08:23.661] _slurm_rpc_submit_batch_job: JobId=47938 InitPrio=17981 usec=384
[2022-08-12T23:08:23.709] sched: Allocate JobId=47938 NodeList=cpu15 #CPUs=1 Partition=cpu-epyc
[2022-08-12T23:11:55.042] _job_complete: JobId=47938 WEXITSTATUS 0
[2022-08-12T23:11:55.042] _job_complete: JobId=47938 done
[2022-08-12T23:12:13.963] _slurm_rpc_kill_job: REQUEST_KILL_JOB JobId=47938 uid 548300595
[2022-08-12T23:13:26.312] _slurm_rpc_submit_batch_job: JobId=47939 InitPrio=17981 usec=441
[2022-08-12T23:13:27.224] sched: Allocate JobId=47939 NodeList=cpu15 #CPUs=1 Partition=cpu-epyc
[2022-08-12T23:16:38.961] _job_complete: JobId=47939 WEXITSTATUS 0
[2022-08-12T23:16:38.962] _job_complete: JobId=47939 done
[2022-08-12T23:29:34.516] _slurm_rpc_submit_batch_job: JobId=47940 InitPrio=7981 usec=456
[2022-08-12T23:30:11.814] _slurm_rpc_kill_job: REQUEST_KILL_JOB JobId=47940 uid 548300595
[2022-08-12T23:30:33.714] _slurm_rpc_submit_batch_job: JobId=47941 InitPrio=7981 usec=446
[2022-08-12T23:30:33.775] sched: Allocate JobId=47941 NodeList=cpu15 #CPUs=16 Partition=cpu-epyc
[2022-08-12T23:31:22.565] _slurm_rpc_kill_job: REQUEST_KILL_JOB JobId=47941 uid 548300595
[2022-08-12T23:31:25.177] _slurm_rpc_submit_batch_job: JobId=47942 InitPrio=7981 usec=442
[2022-08-12T23:31:27.836] sched: Allocate JobId=47942 NodeList=cpu15 #CPUs=16 Partition=cpu-epyc
[2022-08-12T23:31:28.004] _slurm_rpc_kill_job: REQUEST_KILL_JOB JobId=47942 uid 548300595
[2022-08-12T23:31:49.112] _slurm_rpc_submit_batch_job: JobId=47943 InitPrio=7981 usec=458
[2022-08-12T23:31:49.863] sched: Allocate JobId=47943 NodeList=cpu15 #CPUs=16 Partition=cpu-epyc
[2022-08-12T23:33:39.099] _slurm_rpc_kill_job: REQUEST_KILL_JOB JobId=47943 uid 548300595
[2022-08-12T23:35:21.655] _slurm_rpc_submit_batch_job: JobId=47944 InitPrio=7981 usec=446
[2022-08-12T23:35:22.215] sched: Allocate JobId=47944 NodeList=cpu15 #CPUs=16 Partition=cpu-epyc
[2022-08-13T06:17:03.579] _job_complete: JobId=47705 WEXITSTATUS 0
[2022-08-13T06:17:03.584] _job_complete: JobId=47705 done
[2022-08-13T06:35:03.358] _job_complete: JobId=47684 WEXITSTATUS 0
[2022-08-13T06:35:03.359] _job_complete: JobId=47684 done
[2022-08-13T06:35:03.733] sched: Allocate JobId=47688 NodeList=cpu15 #CPUs=32 Partition=cpu-epyc
[2022-08-13T09:00:55.463] Requeuing JobId=47929
[2022-08-13T11:20:09.543] _slurm_rpc_kill_job: REQUEST_KILL_JOB JobId=47929 uid 548200045
[2022-08-13T11:21:39.385] _slurm_rpc_submit_batch_job: JobId=47945 InitPrio=1173 usec=594
[2022-08-13T11:21:40.155] sched: Allocate JobId=47945 NodeList=gpu02 #CPUs=16 Partition=gpu-titan
[2022-08-13T11:37:52.939] Requeuing JobId=47945
[2022-08-13T12:34:46.145] _slurm_rpc_kill_job: REQUEST_KILL_JOB JobId=47945 uid 548200045
[2022-08-13T12:34:50.902] _slurm_rpc_submit_batch_job: JobId=47946 InitPrio=1173 usec=486
[2022-08-13T12:34:51.353] sched: Allocate JobId=47946 NodeList=gpu02 #CPUs=16 Partition=gpu-titan
[2022-08-13T12:49:42.720] Requeuing JobId=47946
[2022-08-13T12:59:41.590] _slurm_rpc_kill_job: REQUEST_KILL_JOB JobId=47946 uid 548200045
[2022-08-13T13:00:08.545] _slurm_rpc_submit_batch_job: JobId=47947 InitPrio=1173 usec=423
[2022-08-13T13:00:08.738] sched: Allocate JobId=47947 NodeList=gpu02 #CPUs=16 Partition=gpu-titan
[2022-08-13T13:14:21.295] Requeuing JobId=47947
[2022-08-13T13:14:35.531] acct_policy_update_pending_job: exceeded association/qos's cpu, node, memory or time limit for JobId=47947
[2022-08-13T13:18:10.712] _slurm_rpc_kill_job: REQUEST_KILL_JOB JobId=47947 uid 548200045
[2022-08-13T14:29:54.530] error: This association 43(account='free', user='han', partition='(null)') does not have access to qos long
[2022-08-13T14:29:54.530] _slurm_rpc_submit_batch_job: Invalid qos specification
[2022-08-13T14:30:08.478] error: This association 43(account='free', user='han', partition='(null)') does not have access to qos normal
[2022-08-13T14:30:08.478] _slurm_rpc_submit_batch_job: Invalid qos specification
[2022-08-13T14:30:14.749] error: This association 43(account='free', user='han', partition='(null)') does not have access to qos normal
[2022-08-13T14:30:14.749] _slurm_rpc_submit_batch_job: Invalid qos specification
[2022-08-13T14:30:27.231] _job_create: exceeded association/QOS limit for user 548200045: AssocGrpCpuLimit
[2022-08-13T14:30:27.231] _slurm_rpc_submit_batch_job: Job violates accounting/QOS policy (job submit limit, user's size and/or time limits)
[2022-08-13T14:35:05.787] _job_create: exceeded association/QOS limit for user 548200045: AssocGrpCpuLimit
[2022-08-13T14:35:05.787] _slurm_rpc_submit_batch_job: Job violates accounting/QOS policy (job submit limit, user's size and/or time limits)
[2022-08-13T14:43:23.105] _slurm_rpc_kill_job: REQUEST_KILL_JOB JobId=47668 uid 548200045
[2022-08-13T14:43:25.387] sched: Allocate JobId=47664 NodeList=cpu13 #CPUs=32 Partition=cpu-epyc
[2022-08-13T14:43:47.940] _job_create: exceeded association/QOS limit for user 548200045: AssocGrpCpuLimit
[2022-08-13T14:43:47.940] _slurm_rpc_submit_batch_job: Job violates accounting/QOS policy (job submit limit, user's size and/or time limits)
[2022-08-13T14:44:59.131] error: This association 43(account='free', user='han', partition='(null)') does not have access to qos long
[2022-08-13T14:44:59.131] _slurm_rpc_submit_batch_job: Invalid qos specification
[2022-08-13T14:45:50.046] _job_create: exceeded association/QOS limit for user 548200045: AssocGrpCpuLimit
[2022-08-13T14:45:50.046] _slurm_rpc_submit_batch_job: Job violates accounting/QOS policy (job submit limit, user's size and/or time limits)
[2022-08-13T15:00:37.189] _job_complete: JobId=47874 WEXITSTATUS 0
[2022-08-13T15:00:37.189] _job_complete: JobId=47874 done
[2022-08-13T15:02:42.340] _job_complete: JobId=47873 WEXITSTATUS 0
[2022-08-13T15:02:42.340] _job_complete: JobId=47873 done
[2022-08-13T15:27:52.764] _job_complete: JobId=47665 WEXITSTATUS 0
[2022-08-13T15:27:52.765] _job_complete: JobId=47665 done
[2022-08-13T15:27:55.758] sched: Allocate JobId=47671 NodeList=cpu14 #CPUs=32 Partition=cpu-epyc
[2022-08-13T16:16:59.992] _job_complete: JobId=47523 WEXITSTATUS 1
[2022-08-13T16:16:59.992] _job_complete: JobId=47523 done
[2022-08-13T16:58:58.576] _slurm_rpc_submit_batch_job: JobId=47948 InitPrio=234 usec=409
[2022-08-13T17:00:53.266] _slurm_rpc_submit_batch_job: JobId=47949 InitPrio=234 usec=586
[2022-08-13T17:11:01.065] _job_create: exceeded association/QOS limit for user 548200045: AssocGrpCpuLimit
[2022-08-13T17:11:01.065] _slurm_rpc_submit_batch_job: Job violates accounting/QOS policy (job submit limit, user's size and/or time limits)
[2022-08-13T18:48:31.556] _slurm_rpc_submit_batch_job: JobId=47950 InitPrio=1408 usec=407
[2022-08-13T18:48:32.393] sched: Allocate JobId=47950 NodeList=gpu04 #CPUs=16 Partition=gpu-k40c
[2022-08-13T20:22:37.713] _job_complete: JobId=47688 WEXITSTATUS 0
[2022-08-13T20:22:37.713] _job_complete: JobId=47688 done
[2022-08-13T20:22:38.328] sched: Allocate JobId=47706 NodeList=cpu15 #CPUs=32 Partition=cpu-epyc
[2022-08-14T00:11:22.508] Time limit exhausted for JobId=46922
[2022-08-14T00:11:27.245] sched: Allocate JobId=47922 NodeList=cpu09 #CPUs=32 Partition=cpu-opteron
[2022-08-14T00:12:12.011] _job_complete: JobId=47922 WEXITSTATUS 0
[2022-08-14T00:12:12.012] _job_complete: JobId=47922 done
[2022-08-14T00:12:14.231] sched: Allocate JobId=47923 NodeList=cpu09 #CPUs=32 Partition=cpu-opteron
[2022-08-14T00:12:43.086] _job_complete: JobId=47923 WEXITSTATUS 0
[2022-08-14T00:12:43.087] _job_complete: JobId=47923 done
[2022-08-14T00:12:44.253] sched: Allocate JobId=47924 NodeList=cpu09 #CPUs=32 Partition=cpu-opteron
[2022-08-14T00:13:13.951] _job_complete: JobId=47924 WEXITSTATUS 0
[2022-08-14T00:13:13.951] _job_complete: JobId=47924 done
[2022-08-14T00:13:15.132] sched: Allocate JobId=47925 NodeList=cpu09 #CPUs=32 Partition=cpu-opteron
[2022-08-14T00:13:44.170] _job_complete: JobId=47925 WEXITSTATUS 0
[2022-08-14T00:13:44.170] _job_complete: JobId=47925 done
[2022-08-14T00:13:45.394] sched: Allocate JobId=47926 NodeList=cpu09 #CPUs=32 Partition=cpu-opteron
[2022-08-14T00:14:13.807] _job_complete: JobId=47926 WEXITSTATUS 0
[2022-08-14T00:14:13.807] _job_complete: JobId=47926 done
[2022-08-14T00:14:15.018] sched: Allocate JobId=47927 NodeList=cpu09 #CPUs=32 Partition=cpu-opteron
[2022-08-14T00:14:44.011] _job_complete: JobId=47927 WEXITSTATUS 0
[2022-08-14T00:14:44.012] _job_complete: JobId=47927 done
[2022-08-14T00:14:45.237] sched: Allocate JobId=47928 NodeList=cpu09 #CPUs=32 Partition=cpu-opteron
[2022-08-14T00:15:14.829] _job_complete: JobId=47928 WEXITSTATUS 0
[2022-08-14T00:15:14.830] _job_complete: JobId=47928 done
[2022-08-14T00:15:16.089] sched: Allocate JobId=47880 NodeList=cpu09 #CPUs=32 Partition=cpu-opteron
[2022-08-14T07:56:26.519] error: This association 43(account='free', user='han', partition='(null)') does not have access to qos normal
[2022-08-14T07:56:26.519] _slurm_rpc_submit_batch_job: Invalid qos specification
[2022-08-14T08:01:13.288] _job_create: exceeded association/QOS limit for user 548200045: AssocGrpCpuLimit
[2022-08-14T08:01:13.288] _slurm_rpc_submit_batch_job: Job violates accounting/QOS policy (job submit limit, user's size and/or time limits)
[2022-08-14T10:34:57.925] _job_complete: JobId=47706 WEXITSTATUS 0
[2022-08-14T10:34:57.926] _job_complete: JobId=47706 done
[2022-08-14T10:34:58.400] sched: Allocate JobId=47707 NodeList=cpu15 #CPUs=32 Partition=cpu-epyc
[2022-08-14T14:24:21.865] _job_complete: JobId=47804 WEXITSTATUS 0
[2022-08-14T14:24:21.870] _job_complete: JobId=47804 done
[2022-08-14T18:48:54.525] Time limit exhausted for JobId=47950
[2022-08-14T19:20:48.442] _slurm_rpc_submit_batch_job: JobId=47951 InitPrio=1408 usec=429
[2022-08-14T19:20:48.729] sched: Allocate JobId=47951 NodeList=gpu04 #CPUs=16 Partition=gpu-k40c
[2022-08-14T21:08:59.824] _job_complete: JobId=47944 WEXITSTATUS 1
[2022-08-14T21:08:59.830] _job_complete: JobId=47944 done
[2022-08-14T21:41:06.449] _slurm_rpc_submit_batch_job: JobId=47952 InitPrio=3990 usec=481
[2022-08-15T00:17:33.812] _slurm_rpc_submit_batch_job: JobId=47953 InitPrio=11173 usec=562
[2022-08-15T00:17:34.423] sched: Allocate JobId=47953 NodeList=gpu02 #CPUs=16 Partition=gpu-titan
[2022-08-15T00:17:43.002] _slurm_rpc_kill_job: REQUEST_KILL_JOB JobId=47953 uid 548200045
[2022-08-15T00:33:44.530] _job_complete: JobId=47866 WEXITSTATUS 0
[2022-08-15T00:33:44.530] _job_complete: JobId=47866 done
[2022-08-15T00:33:49.803] sched: Allocate JobId=47881 NodeList=cpu11 #CPUs=32 Partition=cpu-opteron
[2022-08-15T01:17:14.219] _slurm_rpc_kill_job: REQUEST_KILL_JOB JobId=47952 uid 548300595
[2022-08-15T01:17:45.039] _slurm_rpc_submit_batch_job: JobId=47954 InitPrio=3990 usec=440
[2022-08-15T03:49:17.954] _job_complete: JobId=47707 WEXITSTATUS 0
[2022-08-15T03:49:17.954] _job_complete: JobId=47707 done
[2022-08-15T03:49:18.265] sched: Allocate JobId=47708 NodeList=cpu15 #CPUs=32 Partition=cpu-epyc
[2022-08-15T05:13:41.846] _job_complete: JobId=46918 WEXITSTATUS 0
[2022-08-15T05:13:41.851] _job_complete: JobId=46918 done
[2022-08-15T05:13:43.768] sched: Allocate JobId=47709 NodeList=cpu12 #CPUs=32 Partition=cpu-epyc
[2022-08-15T05:21:44.390] _job_complete: JobId=47861 WEXITSTATUS 0
[2022-08-15T05:21:44.396] _job_complete: JobId=47861 done
[2022-08-15T05:21:46.402] sched: Allocate JobId=47864 NodeList=gpu03 #CPUs=16 Partition=gpu-k10
[2022-08-15T08:38:19.981] _slurm_rpc_submit_batch_job: JobId=47955 InitPrio=3990 usec=513
[2022-08-15T08:38:31.724] _slurm_rpc_kill_job: REQUEST_KILL_JOB JobId=47955 uid 548300595
[2022-08-15T08:39:17.056] error: Invalid qos (quick)
[2022-08-15T08:39:17.056] _slurm_rpc_submit_batch_job: Invalid qos specification
[2022-08-15T08:40:14.327] _slurm_rpc_submit_batch_job: JobId=47956 InitPrio=13990 usec=489
[2022-08-15T08:40:14.381] sched: Allocate JobId=47956 NodeList=cpu[12-15] #CPUs=16 Partition=cpu-epyc
[2022-08-15T08:44:25.260] _slurm_rpc_kill_job: REQUEST_KILL_JOB JobId=47954 uid 548300595
[2022-08-15T09:09:03.600] _job_complete: JobId=47956 WEXITSTATUS 0
[2022-08-15T09:09:03.601] _job_complete: JobId=47956 done
[2022-08-15T09:56:08.678] _slurm_rpc_submit_batch_job: JobId=47957 InitPrio=13990 usec=461
[2022-08-15T09:56:09.216] sched: Allocate JobId=47957 NodeList=cpu12 #CPUs=16 Partition=cpu-epyc
[2022-08-15T09:57:19.965] _slurm_rpc_kill_job: REQUEST_KILL_JOB JobId=47957 uid 548300595
[2022-08-15T09:57:44.199] _slurm_rpc_submit_batch_job: JobId=47958 InitPrio=13990 usec=428
[2022-08-15T09:57:44.410] sched: Allocate JobId=47958 NodeList=cpu12 #CPUs=16 Partition=cpu-epyc
[2022-08-15T10:28:55.074] sched: _slurm_rpc_allocate_resources JobId=47959 NodeList=(null) usec=826
[2022-08-15T10:28:55.565] sched: Allocate JobId=47959 NodeList=cpu08 #CPUs=16 Partition=cpu-opteron
[2022-08-15T10:30:27.588] _job_complete: JobId=47958 WEXITSTATUS 0
[2022-08-15T10:30:27.589] _job_complete: JobId=47958 done
[2022-08-15T10:44:07.533] _slurm_rpc_submit_batch_job: JobId=47960 InitPrio=15868 usec=497
[2022-08-15T10:44:08.333] sched: Allocate JobId=47960 NodeList=gpu02 #CPUs=15 Partition=gpu-titan
[2022-08-15T10:44:36.307] _slurm_rpc_submit_batch_job: JobId=47961 InitPrio=15868 usec=463
[2022-08-15T10:45:04.092] _slurm_rpc_submit_batch_job: JobId=47962 InitPrio=15868 usec=472
[2022-08-15T10:45:37.980] _slurm_rpc_submit_batch_job: JobId=47963 InitPrio=15868 usec=426
[2022-08-15T10:46:03.653] _slurm_rpc_submit_batch_job: JobId=47964 InitPrio=15868 usec=388
[2022-08-15T10:46:24.461] _slurm_rpc_submit_batch_job: JobId=47965 InitPrio=15868 usec=388
[2022-08-15T10:51:10.669] _job_complete: JobId=47960 WEXITSTATUS 0
[2022-08-15T10:51:10.669] _job_complete: JobId=47960 done
[2022-08-15T10:51:11.217] sched: Allocate JobId=47961 NodeList=gpu02 #CPUs=8 Partition=gpu-titan
[2022-08-15T10:51:11.218] sched: Allocate JobId=47962 NodeList=gpu02 #CPUs=8 Partition=gpu-titan
[2022-08-15T10:55:24.546] _job_complete: JobId=47961 WEXITSTATUS 0
[2022-08-15T10:55:24.546] _job_complete: JobId=47961 done
[2022-08-15T10:55:25.221] sched: Allocate JobId=47963 NodeList=gpu02 #CPUs=8 Partition=gpu-titan
[2022-08-15T10:58:52.647] _job_complete: JobId=47962 WEXITSTATUS 0
[2022-08-15T10:58:52.648] _job_complete: JobId=47962 done
[2022-08-15T11:02:19.590] _job_complete: JobId=47963 WEXITSTATUS 0
[2022-08-15T11:02:19.590] _job_complete: JobId=47963 done
[2022-08-15T11:02:20.658] sched: Allocate JobId=47964 NodeList=gpu02 #CPUs=8 Partition=gpu-titan
[2022-08-15T11:02:20.658] sched: Allocate JobId=47965 NodeList=gpu02 #CPUs=8 Partition=gpu-titan
[2022-08-15T11:05:15.938] _job_complete: JobId=47965 WEXITSTATUS 0
[2022-08-15T11:05:15.938] _job_complete: JobId=47965 done
[2022-08-15T11:09:44.655] _job_complete: JobId=47964 WEXITSTATUS 0
[2022-08-15T11:09:44.655] _job_complete: JobId=47964 done
[2022-08-15T12:15:07.885] _slurm_rpc_submit_batch_job: JobId=47966 InitPrio=234 usec=476
[2022-08-15T12:40:24.778] _slurm_rpc_submit_batch_job: JobId=47967 InitPrio=15633 usec=476
[2022-08-15T12:40:25.175] sched: Allocate JobId=47967 NodeList=gpu02 #CPUs=15 Partition=gpu-titan
[2022-08-15T12:40:47.168] _slurm_rpc_submit_batch_job: JobId=47968 InitPrio=15633 usec=395
[2022-08-15T12:41:07.281] _slurm_rpc_submit_batch_job: JobId=47969 InitPrio=15633 usec=467
[2022-08-15T12:41:28.210] _slurm_rpc_submit_batch_job: JobId=47970 InitPrio=15633 usec=442
[2022-08-15T12:41:53.010] _slurm_rpc_submit_batch_job: JobId=47971 InitPrio=15633 usec=449
[2022-08-15T12:42:20.922] _slurm_rpc_submit_batch_job: JobId=47972 InitPrio=15633 usec=467
[2022-08-15T12:47:05.420] _job_complete: JobId=47967 WEXITSTATUS 0
[2022-08-15T12:47:05.421] _job_complete: JobId=47967 done
[2022-08-15T12:47:05.969] sched: Allocate JobId=47968 NodeList=gpu02 #CPUs=8 Partition=gpu-titan
[2022-08-15T12:47:05.970] sched: Allocate JobId=47969 NodeList=gpu02 #CPUs=8 Partition=gpu-titan
[2022-08-15T12:47:17.397] _slurm_rpc_submit_batch_job: JobId=47973 InitPrio=7276 usec=437
[2022-08-15T12:48:03.081] _slurm_rpc_kill_job: REQUEST_KILL_JOB JobId=47973 uid 548300580
[2022-08-15T12:49:07.925] _build_node_list: No nodes satisfy JobId=47974 requirements in partition gpu-k40c
[2022-08-15T12:49:07.925] _slurm_rpc_submit_batch_job: Requested node configuration is not available
[2022-08-15T12:49:47.245] _slurm_rpc_submit_batch_job: JobId=47975 InitPrio=7276 usec=747
[2022-08-15T12:50:33.221] _job_complete: JobId=47968 WEXITSTATUS 0
[2022-08-15T12:50:33.221] _job_complete: JobId=47968 done
[2022-08-15T12:50:33.801] sched: Allocate JobId=47970 NodeList=gpu02 #CPUs=8 Partition=gpu-titan
[2022-08-15T12:53:07.172] _job_complete: JobId=47969 WEXITSTATUS 0
[2022-08-15T12:53:07.173] _job_complete: JobId=47969 done
[2022-08-15T12:59:07.405] _job_complete: JobId=47970 WEXITSTATUS 0
[2022-08-15T12:59:07.405] _job_complete: JobId=47970 done
[2022-08-15T12:59:08.485] sched: Allocate JobId=47971 NodeList=gpu02 #CPUs=8 Partition=gpu-titan
[2022-08-15T12:59:08.485] sched: Allocate JobId=47972 NodeList=gpu02 #CPUs=8 Partition=gpu-titan
[2022-08-15T13:01:37.754] _job_complete: JobId=47972 WEXITSTATUS 0
[2022-08-15T13:01:37.754] _job_complete: JobId=47972 done
[2022-08-15T13:05:54.130] _job_complete: JobId=47971 WEXITSTATUS 0
[2022-08-15T13:05:54.130] _job_complete: JobId=47971 done
[2022-08-15T13:06:53.627] _slurm_rpc_submit_batch_job: JobId=47976 InitPrio=4929 usec=371
[2022-08-15T13:07:03.715] _slurm_rpc_kill_job: REQUEST_KILL_JOB JobId=47976 uid 548200003
[2022-08-15T13:07:08.331] _slurm_rpc_submit_batch_job: JobId=47977 InitPrio=14929 usec=357
[2022-08-15T13:07:08.866] sched: Allocate JobId=47977 NodeList=cpu12 #CPUs=16 Partition=cpu-epyc
[2022-08-15T13:08:59.276] _slurm_rpc_kill_job: REQUEST_KILL_JOB JobId=47977 uid 548200003
[2022-08-15T13:42:54.840] _pick_best_nodes: JobId=47978 never runnable in partition cpu-opteron
[2022-08-15T13:42:54.840] _slurm_rpc_submit_batch_job: Requested node configuration is not available
[2022-08-15T13:43:01.595] _slurm_rpc_submit_batch_job: JobId=47979 InitPrio=15399 usec=422
[2022-08-15T13:43:01.716] sched: Allocate JobId=47979 NodeList=cpu[09-10] #CPUs=8 Partition=cpu-opteron
[2022-08-15T14:03:23.630] _slurm_rpc_submit_batch_job: JobId=47980 InitPrio=15399 usec=329
[2022-08-15T14:03:23.769] sched: Allocate JobId=47980 NodeList=cpu[12-13] #CPUs=32 Partition=cpu-epyc
[2022-08-15T14:09:10.207] _job_complete: JobId=47980 WEXITSTATUS 0
[2022-08-15T14:09:10.208] _job_complete: JobId=47980 done
[2022-08-15T14:12:01.175] _slurm_rpc_submit_batch_job: JobId=47981 InitPrio=15399 usec=377
[2022-08-15T14:12:01.652] sched: Allocate JobId=47981 NodeList=cpu[12-13] #CPUs=32 Partition=cpu-epyc
[2022-08-15T14:13:35.515] _slurm_rpc_kill_job: REQUEST_KILL_JOB JobId=47979 uid 548300543
[2022-08-15T14:19:05.983] _job_complete: JobId=47981 WEXITSTATUS 0
[2022-08-15T14:19:05.984] _job_complete: JobId=47981 done
[2022-08-15T14:58:15.324] _slurm_rpc_submit_batch_job: JobId=47982 InitPrio=13990 usec=416
[2022-08-15T14:58:15.525] sched: Allocate JobId=47982 NodeList=cpu01 #CPUs=16 Partition=cpu-opteron
[2022-08-15T15:00:35.402] _slurm_rpc_submit_batch_job: JobId=47983 InitPrio=13990 usec=367
[2022-08-15T15:00:35.707] sched: Allocate JobId=47983 NodeList=cpu[01,09-11] #CPUs=16 Partition=cpu-opteron
[2022-08-15T15:11:44.981] _pick_best_nodes: JobId=47984 never runnable in partition cpu-epyc
[2022-08-15T15:11:44.982] _slurm_rpc_submit_batch_job: Requested node configuration is not available
[2022-08-15T15:11:59.714] _slurm_rpc_submit_batch_job: JobId=47985 InitPrio=4929 usec=357
[2022-08-15T15:12:17.351] _slurm_rpc_kill_job: REQUEST_KILL_JOB JobId=47985 uid 548200003
[2022-08-15T15:12:30.427] _slurm_rpc_submit_batch_job: JobId=47986 InitPrio=14929 usec=446
[2022-08-15T15:12:30.872] sched: Allocate JobId=47986 NodeList=cpu[12-15] #CPUs=64 Partition=cpu-epyc
[2022-08-15T15:13:31.611] _job_complete: JobId=47986 WEXITSTATUS 0
[2022-08-15T15:13:31.612] _job_complete: JobId=47986 done
[2022-08-15T15:22:06.848] _slurm_rpc_submit_batch_job: JobId=47987 InitPrio=15399 usec=397
[2022-08-15T15:22:06.872] sched: Allocate JobId=47987 NodeList=cpu[12-13] #CPUs=32 Partition=cpu-epyc
[2022-08-15T15:30:16.699] _job_complete: JobId=47987 WEXITSTATUS 0
[2022-08-15T15:30:16.700] _job_complete: JobId=47987 done
[2022-08-15T15:32:51.633] _slurm_rpc_kill_job: REQUEST_KILL_JOB JobId=47959 uid 548300543
[2022-08-15T15:38:40.619] _slurm_rpc_submit_batch_job: JobId=47988 InitPrio=5399 usec=440
[2022-08-15T15:39:03.959] _slurm_rpc_kill_job: REQUEST_KILL_JOB JobId=47988 uid 548300543
[2022-08-15T15:39:54.059] _slurm_rpc_submit_batch_job: JobId=47989 InitPrio=5399 usec=471
[2022-08-15T15:39:54.754] sched: Allocate JobId=47989 NodeList=cpu08 #CPUs=16 Partition=cpu-opteron
[2022-08-15T15:53:07.967] _slurm_rpc_kill_job: REQUEST_KILL_JOB JobId=47989 uid 548300543
[2022-08-15T15:54:51.660] _slurm_rpc_submit_batch_job: JobId=47990 InitPrio=15399 usec=582
[2022-08-15T15:54:52.231] sched: Allocate JobId=47990 NodeList=cpu12 #CPUs=16 Partition=cpu-epyc
[2022-08-15T15:58:27.600] Time limit exhausted for JobId=47982
[2022-08-15T16:00:57.808] Time limit exhausted for JobId=47983
[2022-08-15T16:02:25.079] _slurm_rpc_kill_job: REQUEST_KILL_JOB JobId=47990 uid 548300543
[2022-08-15T16:03:31.268] _slurm_rpc_submit_batch_job: JobId=47991 InitPrio=15399 usec=401
[2022-08-15T16:03:32.128] sched: Allocate JobId=47991 NodeList=cpu12 #CPUs=16 Partition=cpu-epyc
[2022-08-15T16:04:39.962] _slurm_rpc_kill_job: REQUEST_KILL_JOB JobId=47991 uid 548300543
[2022-08-15T16:05:21.534] _slurm_rpc_submit_batch_job: JobId=47992 InitPrio=15399 usec=551
[2022-08-15T16:05:22.282] sched: Allocate JobId=47992 NodeList=cpu12 #CPUs=16 Partition=cpu-epyc
[2022-08-15T16:07:26.118] _slurm_rpc_kill_job: REQUEST_KILL_JOB JobId=47992 uid 548300543
[2022-08-15T16:09:11.796] _job_complete: JobId=47708 WEXITSTATUS 0
[2022-08-15T16:09:11.796] _job_complete: JobId=47708 done
[2022-08-15T16:09:12.059] sched: Allocate JobId=47710 NodeList=cpu15 #CPUs=32 Partition=cpu-epyc
[2022-08-15T16:10:16.327] _slurm_rpc_submit_batch_job: JobId=47993 InitPrio=3990 usec=381
[2022-08-15T16:10:16.783] sched: Allocate JobId=47993 NodeList=cpu[08-11] #CPUs=16 Partition=cpu-opteron
[2022-08-15T16:11:11.223] _slurm_rpc_submit_batch_job: JobId=47994 InitPrio=3990 usec=633
[2022-08-15T16:11:11.853] sched: Allocate JobId=47994 NodeList=cpu01 #CPUs=16 Partition=cpu-opteron
[2022-08-15T16:12:31.559] _slurm_rpc_submit_batch_job: JobId=47995 InitPrio=15399 usec=484
[2022-08-15T16:12:31.965] sched: Allocate JobId=47995 NodeList=cpu[12-13] #CPUs=32 Partition=cpu-epyc
[2022-08-15T16:13:33.856] _slurm_rpc_submit_batch_job: JobId=47996 InitPrio=15399 usec=389
[2022-08-15T16:13:34.149] sched: Allocate JobId=47996 NodeList=cpu14 #CPUs=16 Partition=cpu-epyc
[2022-08-15T16:22:14.167] _job_complete: JobId=47995 WEXITSTATUS 0
[2022-08-15T16:22:14.168] _job_complete: JobId=47995 done
[2022-08-15T16:38:17.507] _job_complete: JobId=47996 WEXITSTATUS 1
[2022-08-15T16:38:17.507] _job_complete: JobId=47996 done
[2022-08-15T16:43:23.795] _slurm_rpc_submit_batch_job: JobId=47997 InitPrio=15399 usec=406
[2022-08-15T16:43:24.195] sched: Allocate JobId=47997 NodeList=cpu12 #CPUs=16 Partition=cpu-epyc
[2022-08-15T16:43:37.964] _job_complete: JobId=47997 WEXITSTATUS 1
[2022-08-15T16:43:37.965] _job_complete: JobId=47997 done
[2022-08-15T16:44:21.297] _slurm_rpc_submit_batch_job: JobId=47998 InitPrio=15399 usec=540
[2022-08-15T16:44:22.274] sched: Allocate JobId=47998 NodeList=cpu12 #CPUs=16 Partition=cpu-epyc
[2022-08-15T16:44:33.131] _job_complete: JobId=47998 WEXITSTATUS 1
[2022-08-15T16:44:33.131] _job_complete: JobId=47998 done
[2022-08-15T16:55:59.479] _slurm_rpc_submit_batch_job: JobId=47999 InitPrio=15399 usec=526
[2022-08-15T16:56:00.438] sched: Allocate JobId=47999 NodeList=cpu12 #CPUs=16 Partition=cpu-epyc
[2022-08-15T16:56:12.202] _job_complete: JobId=47999 WEXITSTATUS 1
[2022-08-15T16:56:12.202] _job_complete: JobId=47999 done
[2022-08-15T19:02:09.463] _job_complete: JobId=47993 WEXITSTATUS 0
[2022-08-15T19:02:09.468] _job_complete: JobId=47993 done
[2022-08-15T19:10:45.886] _job_complete: JobId=47994 WEXITSTATUS 0
[2022-08-15T19:10:45.886] _job_complete: JobId=47994 done
[2022-08-15T20:20:20.087] _job_complete: JobId=47709 WEXITSTATUS 0
[2022-08-15T20:20:20.087] _job_complete: JobId=47709 done
[2022-08-15T20:20:20.406] sched: Allocate JobId=47711 NodeList=cpu12 #CPUs=32 Partition=cpu-epyc
[2022-08-15T20:23:53.960] _slurm_rpc_submit_batch_job: JobId=48000 InitPrio=3990 usec=405
[2022-08-15T20:59:36.621] _slurm_rpc_submit_batch_job: JobId=48001 InitPrio=2816 usec=917
[2022-08-15T20:59:37.608] sched: Allocate JobId=48001 NodeList=gpu01 #CPUs=16 Partition=gpu-k10
[2022-08-15T21:00:26.273] _slurm_rpc_submit_batch_job: JobId=48002 InitPrio=2816 usec=716
[2022-08-15T22:44:16.139] _slurm_rpc_submit_batch_job: JobId=48003 InitPrio=704 usec=504
[2022-08-15T22:55:38.894] _slurm_rpc_submit_batch_job: JobId=48004 InitPrio=2112 usec=425
[2022-08-15T23:42:28.726] _slurm_rpc_submit_batch_job: JobId=48005 InitPrio=11173 usec=420
[2022-08-15T23:42:29.377] sched/backfill: _start_job: Started JobId=48005 in gpu-titan on gpu02
[2022-08-15T23:44:35.856] sched: _slurm_rpc_allocate_resources JobId=48006 NodeList=cpu01 usec=84586
[2022-08-15T23:45:24.343] _job_complete: JobId=48006 WEXITSTATUS 0
[2022-08-15T23:45:24.344] _job_complete: JobId=48006 done
[2022-08-15T23:52:18.083] error: This association 222(account='free', user='fairus', partition='(null)') does not have access to qos normal
[2022-08-15T23:52:18.083] _slurm_rpc_submit_batch_job: Invalid qos specification
[2022-08-15T23:53:52.873] error: This association 222(account='free', user='fairus', partition='(null)') does not have access to qos normal
[2022-08-15T23:53:52.873] _slurm_rpc_submit_batch_job: Invalid qos specification
[2022-08-15T23:54:08.508] error: This association 222(account='free', user='fairus', partition='(null)') does not have access to qos normal
[2022-08-15T23:54:08.508] _slurm_rpc_submit_batch_job: Invalid qos specification
[2022-08-15T23:54:46.374] error: This association 222(account='free', user='fairus', partition='(null)') does not have access to qos normal
[2022-08-15T23:54:46.374] _slurm_rpc_submit_batch_job: Invalid qos specification
[2022-08-15T23:55:12.281] _slurm_rpc_submit_batch_job: JobId=48007 InitPrio=21267 usec=514
[2022-08-15T23:55:12.934] sched: Allocate JobId=48007 NodeList=cpu01 #CPUs=1 Partition=cpu-opteron
[2022-08-15T23:55:15.041] _job_complete: JobId=48007 WEXITSTATUS 127
[2022-08-15T23:55:15.041] _job_complete: JobId=48007 done
[2022-08-16T00:42:29.108] Time limit exhausted for JobId=48005
[2022-08-16T00:48:03.531] _slurm_rpc_submit_batch_job: JobId=48008 InitPrio=1173 usec=608
[2022-08-16T00:48:03.770] sched: Allocate JobId=48008 NodeList=gpu02 #CPUs=16 Partition=gpu-titan
[2022-08-16T06:19:10.769] _job_complete: JobId=47710 WEXITSTATUS 0
[2022-08-16T06:19:10.769] _job_complete: JobId=47710 done
[2022-08-16T06:19:11.078] sched: Allocate JobId=47712 NodeList=cpu15 #CPUs=32 Partition=cpu-epyc
[2022-08-16T07:48:34.538] _job_complete: JobId=47711 WEXITSTATUS 0
[2022-08-16T07:48:34.538] _job_complete: JobId=47711 done
[2022-08-16T07:48:34.869] sched: Allocate JobId=47719 NodeList=cpu12 #CPUs=48 Partition=cpu-epyc
[2022-08-16T07:49:19.410] _job_complete: JobId=47719 WEXITSTATUS 1
[2022-08-16T07:49:19.410] _job_complete: JobId=47719 done
[2022-08-16T07:49:19.773] sched: Allocate JobId=47949 NodeList=cpu12 #CPUs=32 Partition=cpu-epyc
[2022-08-16T08:02:06.281] _job_complete: JobId=47801 WEXITSTATUS 0
[2022-08-16T08:02:06.282] _job_complete: JobId=47801 done
[2022-08-16T08:02:13.510] sched: Allocate JobId=48000 NodeList=cpu08 #CPUs=64 Partition=cpu-opteron
[2022-08-16T08:02:25.003] _job_complete: JobId=48000 OOM failure
[2022-08-16T08:02:25.004] _job_complete: JobId=48000 done
[2022-08-16T08:02:25.644] sched: Allocate JobId=47948 NodeList=cpu08 #CPUs=64 Partition=cpu-opteron
[2022-08-16T08:43:59.225] Requeuing JobId=48008
[2022-08-16T08:44:08.825] acct_policy_update_pending_job: exceeded association/qos's cpu, node, memory or time limit for JobId=48008
[2022-08-16T08:49:25.790] _slurm_rpc_submit_batch_job: JobId=48009 InitPrio=15399 usec=436
[2022-08-16T08:49:26.193] sched: Allocate JobId=48009 NodeList=cpu12 #CPUs=16 Partition=cpu-epyc
[2022-08-16T08:49:40.255] _job_complete: JobId=48009 WEXITSTATUS 1
[2022-08-16T08:49:40.256] _job_complete: JobId=48009 done
[2022-08-16T08:55:47.582] _slurm_rpc_submit_batch_job: JobId=48010 InitPrio=15399 usec=434
[2022-08-16T08:55:47.900] sched: Allocate JobId=48010 NodeList=cpu12 #CPUs=16 Partition=cpu-epyc
[2022-08-16T08:56:00.494] _job_complete: JobId=48010 WEXITSTATUS 1
[2022-08-16T08:56:00.495] _job_complete: JobId=48010 done
[2022-08-16T09:06:56.554] sched: _slurm_rpc_allocate_resources JobId=48011 NodeList=(null) usec=808
[2022-08-16T09:06:57.111] sched: Allocate JobId=48011 NodeList=cpu12 #CPUs=16 Partition=cpu-epyc
[2022-08-16T09:10:30.815] _slurm_rpc_kill_job: REQUEST_KILL_JOB JobId=48011 uid 548300543
[2022-08-16T09:18:22.596] _slurm_rpc_submit_batch_job: JobId=48012 InitPrio=3990 usec=464
[2022-08-16T09:33:40.884] sched: _slurm_rpc_allocate_resources JobId=48013 NodeList=(null) usec=844
[2022-08-16T09:33:41.019] sched: Allocate JobId=48013 NodeList=cpu12 #CPUs=16 Partition=cpu-epyc
[2022-08-16T09:36:47.410] _slurm_rpc_kill_job: REQUEST_KILL_JOB JobId=48008 uid 548200045
[2022-08-16T09:41:05.826] _slurm_rpc_kill_job: REQUEST_KILL_JOB JobId=48013 uid 548300543
[2022-08-16T09:45:48.379] _slurm_rpc_submit_batch_job: JobId=48014 InitPrio=15399 usec=466
[2022-08-16T09:45:49.235] sched: Allocate JobId=48014 NodeList=cpu12 #CPUs=16 Partition=cpu-epyc
[2022-08-16T09:46:00.833] _job_complete: JobId=48014 WEXITSTATUS 1
[2022-08-16T09:46:00.833] _job_complete: JobId=48014 done
[2022-08-16T09:49:31.699] sched: _slurm_rpc_allocate_resources JobId=48015 NodeList=(null) usec=872
[2022-08-16T09:49:32.681] sched: Allocate JobId=48015 NodeList=cpu12 #CPUs=16 Partition=cpu-epyc
[2022-08-16T10:20:17.667] _slurm_rpc_kill_job: REQUEST_KILL_JOB JobId=48015 uid 548300543
[2022-08-16T10:30:03.993] _slurm_rpc_submit_batch_job: JobId=48016 InitPrio=15399 usec=495
[2022-08-16T10:30:04.829] sched: Allocate JobId=48016 NodeList=cpu12 #CPUs=16 Partition=cpu-epyc
[2022-08-16T10:51:53.804] _job_complete: JobId=48016 WEXITSTATUS 1
[2022-08-16T10:51:53.804] _job_complete: JobId=48016 done
[2022-08-16T10:58:24.950] _slurm_rpc_submit_batch_job: JobId=48017 InitPrio=15399 usec=529
[2022-08-16T10:58:25.879] sched: Allocate JobId=48017 NodeList=cpu12 #CPUs=16 Partition=cpu-epyc
[2022-08-16T11:32:41.759] _job_complete: JobId=48017 WEXITSTATUS 1
[2022-08-16T11:32:41.760] _job_complete: JobId=48017 done
[2022-08-16T12:19:40.286] _slurm_rpc_submit_batch_job: JobId=48018 InitPrio=15399 usec=484
[2022-08-16T12:19:40.337] sched: Allocate JobId=48018 NodeList=cpu12 #CPUs=16 Partition=cpu-epyc
[2022-08-16T12:21:21.667] _slurm_rpc_kill_job: REQUEST_KILL_JOB JobId=48018 uid 548300543
[2022-08-16T12:22:18.839] _slurm_rpc_submit_batch_job: JobId=48019 InitPrio=15399 usec=457
[2022-08-16T12:22:19.535] sched: Allocate JobId=48019 NodeList=cpu12 #CPUs=16 Partition=cpu-epyc
[2022-08-16T12:22:20.518] _job_complete: JobId=48019 WEXITSTATUS 1
[2022-08-16T12:22:20.518] _job_complete: JobId=48019 done
[2022-08-16T12:27:48.036] _slurm_rpc_submit_batch_job: JobId=48020 InitPrio=15399 usec=474
[2022-08-16T12:27:48.129] sched: Allocate JobId=48020 NodeList=cpu12 #CPUs=16 Partition=cpu-epyc
[2022-08-16T12:27:49.110] _job_complete: JobId=48020 WEXITSTATUS 1
[2022-08-16T12:27:49.110] _job_complete: JobId=48020 done
[2022-08-16T12:34:22.167] _slurm_rpc_submit_batch_job: JobId=48021 InitPrio=15399 usec=430
[2022-08-16T12:34:22.833] sched: Allocate JobId=48021 NodeList=cpu12 #CPUs=16 Partition=cpu-epyc
[2022-08-16T12:51:17.644] _job_complete: JobId=48021 WEXITSTATUS 1
[2022-08-16T12:51:17.645] _job_complete: JobId=48021 done
[2022-08-16T12:59:25.566] _slurm_rpc_submit_batch_job: JobId=48022 InitPrio=15399 usec=619
[2022-08-16T12:59:25.674] sched: Allocate JobId=48022 NodeList=cpu12 #CPUs=16 Partition=cpu-epyc
[2022-08-16T13:18:36.755] _job_complete: JobId=48022 WEXITSTATUS 0
[2022-08-16T13:18:36.755] _job_complete: JobId=48022 done
[2022-08-16T13:26:22.738] _slurm_rpc_submit_batch_job: JobId=48023 InitPrio=15164 usec=709
[2022-08-16T13:26:23.500] sched: Allocate JobId=48023 NodeList=cpu12 #CPUs=16 Partition=cpu-epyc
[2022-08-16T13:32:01.831] _job_complete: JobId=48023 WEXITSTATUS 2
[2022-08-16T13:32:01.831] _job_complete: JobId=48023 done
[2022-08-16T13:48:32.259] _slurm_rpc_submit_batch_job: JobId=48024 InitPrio=15164 usec=451
[2022-08-16T13:48:32.771] sched: Allocate JobId=48024 NodeList=cpu12 #CPUs=16 Partition=cpu-epyc
[2022-08-16T14:11:07.462] _job_complete: JobId=48024 WEXITSTATUS 0
[2022-08-16T14:11:07.462] _job_complete: JobId=48024 done
[2022-08-16T14:13:33.782] _slurm_rpc_submit_batch_job: JobId=48025 InitPrio=15164 usec=437
[2022-08-16T14:13:34.287] sched: Allocate JobId=48025 NodeList=cpu12 #CPUs=16 Partition=cpu-epyc
[2022-08-16T14:22:20.900] _job_complete: JobId=48025 WEXITSTATUS 0
[2022-08-16T14:22:20.900] _job_complete: JobId=48025 done
[2022-08-16T17:07:08.419] _slurm_rpc_submit_batch_job: JobId=48026 InitPrio=6046 usec=568
[2022-08-16T17:07:08.944] sched: Allocate JobId=48026 NodeList=cpu12 #CPUs=16 Partition=cpu-epyc
[2022-08-16T17:07:10.028] _job_complete: JobId=48026 WEXITSTATUS 0
[2022-08-16T17:07:10.028] _job_complete: JobId=48026 done
[2022-08-16T17:07:49.324] _job_complete: JobId=47712 WEXITSTATUS 0
[2022-08-16T17:07:49.324] _job_complete: JobId=47712 done
[2022-08-16T17:07:49.634] sched: Allocate JobId=48004 NodeList=cpu15 #CPUs=24 Partition=cpu-epyc
[2022-08-16T17:08:34.073] _job_complete: JobId=48004 WEXITSTATUS 1
[2022-08-16T17:08:34.073] _job_complete: JobId=48004 done
[2022-08-16T17:08:34.475] sched: Allocate JobId=47966 NodeList=cpu15 #CPUs=32 Partition=cpu-epyc
[2022-08-16T17:08:41.041] _slurm_rpc_submit_batch_job: JobId=48027 InitPrio=6046 usec=510
[2022-08-16T17:08:41.188] sched: Allocate JobId=48027 NodeList=cpu12 #CPUs=16 Partition=cpu-epyc
[2022-08-16T17:08:42.185] _job_complete: JobId=48027 WEXITSTATUS 0
[2022-08-16T17:08:42.185] _job_complete: JobId=48027 done
[2022-08-16T17:17:23.080] _slurm_rpc_submit_batch_job: JobId=48028 InitPrio=13953 usec=344
[2022-08-16T17:17:24.038] sched: Allocate JobId=48028 NodeList=cpu12 #CPUs=1 Partition=cpu-epyc
[2022-08-16T17:21:49.613] _slurm_rpc_submit_batch_job: JobId=48029 InitPrio=5116 usec=464
[2022-08-16T17:21:50.523] sched: Allocate JobId=48029 NodeList=cpu13 #CPUs=16 Partition=cpu-epyc
[2022-08-16T17:21:58.550] _job_complete: JobId=48029 WEXITSTATUS 0
[2022-08-16T17:21:58.550] _job_complete: JobId=48029 done
[2022-08-16T17:24:18.487] _slurm_rpc_submit_batch_job: JobId=48030 InitPrio=15116 usec=545
[2022-08-16T17:24:18.815] sched: Allocate JobId=48030 NodeList=cpu13 #CPUs=16 Partition=cpu-epyc
[2022-08-16T17:26:02.263] _job_complete: JobId=48030 OOM failure
[2022-08-16T17:26:02.264] _job_complete: JobId=48030 done
[2022-08-16T17:32:22.446] _job_complete: JobId=48028 WEXITSTATUS 0
[2022-08-16T17:32:22.447] _job_complete: JobId=48028 done
[2022-08-16T17:36:32.127] _slurm_rpc_submit_batch_job: JobId=48031 InitPrio=13953 usec=399
[2022-08-16T17:36:33.032] sched: Allocate JobId=48031 NodeList=cpu12 #CPUs=1 Partition=cpu-epyc
[2022-08-16T17:36:33.741] _job_complete: JobId=48031 WEXITSTATUS 1
[2022-08-16T17:36:33.742] _job_complete: JobId=48031 done
[2022-08-16T17:37:20.487] _slurm_rpc_submit_batch_job: JobId=48032 InitPrio=13953 usec=397
[2022-08-16T17:37:21.092] sched: Allocate JobId=48032 NodeList=cpu12 #CPUs=1 Partition=cpu-epyc
[2022-08-16T17:37:47.398] _job_complete: JobId=48032 WEXITSTATUS 0
[2022-08-16T17:37:47.399] _job_complete: JobId=48032 done
[2022-08-16T20:03:50.934] _slurm_rpc_submit_batch_job: JobId=48033 InitPrio=232 usec=370
[2022-08-16T20:06:38.985] _slurm_rpc_submit_batch_job: JobId=48034 InitPrio=232 usec=481
[2022-08-16T22:38:17.226] _job_complete: JobId=47864 WEXITSTATUS 0
[2022-08-16T22:38:17.226] _job_complete: JobId=47864 done
[2022-08-16T22:38:17.731] sched: Allocate JobId=48002 NodeList=gpu03 #CPUs=16 Partition=gpu-k10
[2022-08-16T23:55:08.709] _job_complete: JobId=48002 WEXITSTATUS 1
[2022-08-16T23:55:08.710] _job_complete: JobId=48002 done
[2022-08-17T09:45:59.591] Time limit exhausted for JobId=47123
[2022-08-17T09:46:32.811] sched/backfill: _start_job: Started JobId=48003 in cpu-opteron on cpu10
[2022-08-17T09:48:12.231] _slurm_rpc_submit_batch_job: JobId=48035 InitPrio=15116 usec=374
[2022-08-17T09:48:12.923] sched: Allocate JobId=48035 NodeList=cpu12 #CPUs=16 Partition=cpu-epyc
[2022-08-17T09:53:25.918] _slurm_rpc_submit_batch_job: JobId=48036 InitPrio=15116 usec=536
[2022-08-17T09:53:26.407] sched: Allocate JobId=48036 NodeList=cpu13 #CPUs=16 Partition=cpu-epyc
[2022-08-17T10:00:02.861] _slurm_rpc_kill_job: REQUEST_KILL_JOB JobId=48035 uid 548300543
[2022-08-17T10:00:38.569] _slurm_rpc_kill_job: REQUEST_KILL_JOB JobId=48036 uid 548300543
[2022-08-17T10:01:10.337] _slurm_rpc_submit_batch_job: JobId=48037 InitPrio=15116 usec=529
[2022-08-17T10:01:11.118] sched: Allocate JobId=48037 NodeList=cpu12 #CPUs=16 Partition=cpu-epyc
[2022-08-17T10:25:24.507] _slurm_rpc_kill_job: REQUEST_KILL_JOB JobId=48037 uid 548300543
[2022-08-17T10:26:34.085] _slurm_rpc_submit_batch_job: JobId=48038 InitPrio=15116 usec=481
[2022-08-17T10:26:34.826] sched: Allocate JobId=48038 NodeList=cpu12 #CPUs=16 Partition=cpu-epyc
[2022-08-17T10:28:06.682] _slurm_rpc_kill_job: REQUEST_KILL_JOB JobId=48038 uid 548300543
[2022-08-17T10:28:38.353] _slurm_rpc_submit_batch_job: JobId=48039 InitPrio=15116 usec=371
[2022-08-17T10:28:39.075] sched: Allocate JobId=48039 NodeList=cpu12 #CPUs=16 Partition=cpu-epyc
[2022-08-17T10:29:54.707] _slurm_rpc_kill_job: REQUEST_KILL_JOB JobId=48039 uid 548300543
[2022-08-17T10:30:18.483] _slurm_rpc_submit_batch_job: JobId=48040 InitPrio=15116 usec=394
[2022-08-17T10:30:19.203] sched: Allocate JobId=48040 NodeList=cpu12 #CPUs=16 Partition=cpu-epyc
[2022-08-17T10:39:12.148] _slurm_rpc_kill_job: REQUEST_KILL_JOB JobId=48040 uid 548300543
[2022-08-17T10:39:27.293] _slurm_rpc_submit_batch_job: JobId=48041 InitPrio=15116 usec=397
[2022-08-17T10:39:28.191] sched: Allocate JobId=48041 NodeList=cpu12 #CPUs=16 Partition=cpu-epyc
[2022-08-17T10:42:52.447] _slurm_rpc_kill_job: REQUEST_KILL_JOB JobId=48041 uid 548300543
[2022-08-17T10:49:25.872] _slurm_rpc_submit_batch_job: JobId=48042 InitPrio=15116 usec=462
[2022-08-17T10:49:26.205] sched: Allocate JobId=48042 NodeList=cpu12 #CPUs=16 Partition=cpu-epyc
[2022-08-17T10:49:45.368] _slurm_rpc_submit_batch_job: JobId=48043 InitPrio=15116 usec=410
[2022-08-17T10:49:46.236] sched: Allocate JobId=48043 NodeList=cpu13 #CPUs=16 Partition=cpu-epyc
[2022-08-17T10:50:01.142] _slurm_rpc_submit_batch_job: JobId=48044 InitPrio=15116 usec=417
[2022-08-17T10:50:01.253] sched: Allocate JobId=48044 NodeList=cpu14 #CPUs=16 Partition=cpu-epyc
[2022-08-17T10:50:02.655] _slurm_rpc_submit_batch_job: JobId=48045 InitPrio=2558 usec=464
[2022-08-17T10:50:04.274] sched: Allocate JobId=48045 NodeList=cpu15 #CPUs=16 Partition=cpu-epyc
[2022-08-17T10:50:18.024] _slurm_rpc_submit_batch_job: JobId=48046 InitPrio=15116 usec=492
[2022-08-17T10:50:45.722] _slurm_rpc_submit_batch_job: JobId=48047 InitPrio=15116 usec=428
[2022-08-17T11:01:13.559] _job_complete: JobId=48042 WEXITSTATUS 0
[2022-08-17T11:01:13.559] _job_complete: JobId=48042 done
[2022-08-17T11:01:13.981] sched: Allocate JobId=48046 NodeList=cpu12 #CPUs=16 Partition=cpu-epyc
[2022-08-17T11:02:32.229] _job_complete: JobId=48043 WEXITSTATUS 0
[2022-08-17T11:02:32.229] _job_complete: JobId=48043 done
[2022-08-17T11:02:32.702] sched: Allocate JobId=48047 NodeList=cpu13 #CPUs=16 Partition=cpu-epyc
[2022-08-17T11:02:35.840] _job_complete: JobId=48045 WEXITSTATUS 0
[2022-08-17T11:02:35.840] _job_complete: JobId=48045 done
[2022-08-17T11:03:43.119] _job_complete: JobId=48044 WEXITSTATUS 0
[2022-08-17T11:03:43.119] _job_complete: JobId=48044 done
[2022-08-17T11:16:29.110] _job_complete: JobId=48046 WEXITSTATUS 0
[2022-08-17T11:16:29.110] _job_complete: JobId=48046 done
[2022-08-17T11:29:18.653] _job_complete: JobId=48047 WEXITSTATUS 0
[2022-08-17T11:29:18.653] _job_complete: JobId=48047 done
[2022-08-17T11:40:00.775] _slurm_rpc_submit_batch_job: JobId=48048 InitPrio=14883 usec=448
[2022-08-17T11:40:01.386] sched: Allocate JobId=48048 NodeList=cpu12 #CPUs=1 Partition=cpu-epyc
[2022-08-17T11:41:10.067] _slurm_rpc_submit_batch_job: JobId=48049 InitPrio=2558 usec=459
[2022-08-17T11:41:10.483] sched: Allocate JobId=48049 NodeList=cpu13 #CPUs=16 Partition=cpu-epyc
[2022-08-17T11:41:37.988] _slurm_rpc_kill_job: REQUEST_KILL_JOB JobId=48048 uid 548300543
[2022-08-17T11:42:51.255] _slurm_rpc_submit_batch_job: JobId=48050 InitPrio=14883 usec=455
[2022-08-17T11:42:51.690] sched: Allocate JobId=48050 NodeList=cpu12 #CPUs=1 Partition=cpu-epyc
[2022-08-17T11:45:07.187] _slurm_rpc_kill_job: REQUEST_KILL_JOB JobId=48050 uid 548300543
[2022-08-17T11:49:38.337] _slurm_rpc_submit_batch_job: JobId=48051 InitPrio=2558 usec=451
[2022-08-17T11:49:38.361] sched: Allocate JobId=48051 NodeList=cpu12 #CPUs=16 Partition=cpu-epyc
[2022-08-17T11:53:11.601] _job_complete: JobId=48049 WEXITSTATUS 0
[2022-08-17T11:53:11.601] _job_complete: JobId=48049 done
[2022-08-17T11:55:27.049] _slurm_rpc_submit_batch_job: JobId=48052 InitPrio=14883 usec=351
[2022-08-17T11:55:27.931] sched: Allocate JobId=48052 NodeList=cpu13 #CPUs=16 Partition=cpu-epyc
[2022-08-17T11:56:16.379] _slurm_rpc_kill_job: REQUEST_KILL_JOB JobId=48052 uid 548300543
[2022-08-17T12:00:27.145] _slurm_rpc_submit_batch_job: JobId=48053 InitPrio=14883 usec=413
[2022-08-17T12:00:27.435] sched: Allocate JobId=48053 NodeList=cpu13 #CPUs=16 Partition=cpu-epyc
[2022-08-17T12:00:44.623] _slurm_rpc_kill_job: REQUEST_KILL_JOB JobId=48053 uid 548300543
[2022-08-17T12:20:12.104] _slurm_rpc_submit_batch_job: JobId=48054 InitPrio=2558 usec=515
[2022-08-17T12:20:12.578] sched: Allocate JobId=48054 NodeList=cpu13 #CPUs=16 Partition=cpu-epyc
[2022-08-17T12:33:20.677] _slurm_rpc_submit_batch_job: JobId=48055 InitPrio=2558 usec=416
[2022-08-17T12:33:20.941] sched: Allocate JobId=48055 NodeList=cpu14 #CPUs=16 Partition=cpu-epyc
[2022-08-17T12:33:29.037] _slurm_rpc_submit_batch_job: JobId=48056 InitPrio=2558 usec=412
[2022-08-17T12:33:29.950] sched: Allocate JobId=48056 NodeList=cpu15 #CPUs=16 Partition=cpu-epyc
[2022-08-17T12:33:34.869] _slurm_rpc_submit_batch_job: JobId=48057 InitPrio=2558 usec=421
[2022-08-17T12:33:41.500] _slurm_rpc_submit_batch_job: JobId=48058 InitPrio=2558 usec=547
[2022-08-17T12:33:47.197] _slurm_rpc_submit_batch_job: JobId=48059 InitPrio=2558 usec=414
[2022-08-17T12:33:53.188] _slurm_rpc_submit_batch_job: JobId=48060 InitPrio=2558 usec=531
[2022-08-17T12:33:58.012] _slurm_rpc_submit_batch_job: JobId=48061 InitPrio=2558 usec=482
[2022-08-17T12:34:04.196] _slurm_rpc_submit_batch_job: JobId=48062 InitPrio=2558 usec=445
[2022-08-17T12:34:24.109] _slurm_rpc_submit_batch_job: JobId=48063 InitPrio=2558 usec=424
[2022-08-17T12:46:04.041] _job_complete: JobId=48054 WEXITSTATUS 0
[2022-08-17T12:46:04.041] _job_complete: JobId=48054 done
[2022-08-17T12:46:04.504] sched: Allocate JobId=48057 NodeList=cpu13 #CPUs=16 Partition=cpu-epyc
[2022-08-17T13:30:00.695] Time limit exhausted for JobId=46801
[2022-08-17T13:55:09.724] _job_complete: JobId=48051 WEXITSTATUS 0
[2022-08-17T13:55:09.724] _job_complete: JobId=48051 done
[2022-08-17T13:55:10.180] sched: Allocate JobId=48058 NodeList=cpu12 #CPUs=16 Partition=cpu-epyc
[2022-08-17T14:06:18.782] _slurm_rpc_submit_batch_job: JobId=48064 InitPrio=3953 usec=390
[2022-08-17T14:06:33.188] sched/backfill: _start_job: Started JobId=48064 in cpu-opteron on cpu09
[2022-08-17T15:45:05.085] _job_complete: JobId=48055 WEXITSTATUS 0
[2022-08-17T15:45:05.085] _job_complete: JobId=48055 done
[2022-08-17T15:45:05.688] sched: Allocate JobId=48059 NodeList=cpu14 #CPUs=16 Partition=cpu-epyc
[2022-08-17T15:47:35.723] _job_complete: JobId=48056 WEXITSTATUS 0
[2022-08-17T15:47:35.723] _job_complete: JobId=48056 done
[2022-08-17T15:47:36.238] sched: Allocate JobId=48060 NodeList=cpu15 #CPUs=16 Partition=cpu-epyc
[2022-08-17T16:00:06.371] _job_complete: JobId=48057 WEXITSTATUS 0
[2022-08-17T16:00:06.372] _job_complete: JobId=48057 done
[2022-08-17T16:00:06.774] sched: Allocate JobId=48061 NodeList=cpu13 #CPUs=16 Partition=cpu-epyc
[2022-08-17T16:02:58.363] _slurm_rpc_submit_batch_job: JobId=48065 InitPrio=16046 usec=595
[2022-08-17T16:03:13.858] _slurm_rpc_kill_job: REQUEST_KILL_JOB JobId=48065 uid 548300534
[2022-08-17T16:03:33.826] _slurm_rpc_submit_batch_job: JobId=48066 InitPrio=16046 usec=625
[2022-08-17T16:03:34.393] sched: Allocate JobId=48066 NodeList=gpu02 #CPUs=1 Partition=gpu-titan
[2022-08-17T16:03:35.094] _job_complete: JobId=48066 WEXITSTATUS 0
[2022-08-17T16:03:35.094] _job_complete: JobId=48066 done
[2022-08-17T16:09:41.689] _job_complete: JobId=48064 WEXITSTATUS 0
[2022-08-17T16:09:41.694] _job_complete: JobId=48064 done
[2022-08-17T16:23:45.784] _slurm_rpc_submit_batch_job: JobId=48067 InitPrio=13953 usec=431
[2022-08-17T16:24:19.524] _slurm_rpc_submit_batch_job: JobId=48068 InitPrio=13953 usec=390
[2022-08-17T17:03:43.635] _job_complete: JobId=48058 WEXITSTATUS 0
[2022-08-17T17:03:43.635] _job_complete: JobId=48058 done
[2022-08-17T17:03:44.087] sched: Allocate JobId=48067 NodeList=cpu12 #CPUs=1 Partition=cpu-epyc
[2022-08-17T17:03:44.088] sched: Allocate JobId=48068 NodeList=cpu12 #CPUs=1 Partition=cpu-epyc
[2022-08-17T17:03:46.672] _job_complete: JobId=48068 WEXITSTATUS 0
[2022-08-17T17:03:46.672] _job_complete: JobId=48068 done
[2022-08-17T17:06:32.169] _slurm_rpc_submit_batch_job: JobId=48069 InitPrio=2790 usec=662
[2022-08-17T17:06:33.462] sched/backfill: _start_job: Started JobId=48069 in gpu-k10 on gpu03
[2022-08-17T17:30:24.363] _job_complete: JobId=48067 WEXITSTATUS 0
[2022-08-17T17:30:24.364] _job_complete: JobId=48067 done
[2022-08-17T17:30:26.337] sched: Allocate JobId=48062 NodeList=cpu12 #CPUs=16 Partition=cpu-epyc
[2022-08-17T17:32:51.517] _slurm_rpc_submit_batch_job: JobId=48070 InitPrio=13953 usec=428
[2022-08-17T17:47:43.159] _slurm_rpc_submit_batch_job: JobId=48071 InitPrio=2093 usec=422
[2022-08-17T18:56:29.142] _job_complete: JobId=48059 WEXITSTATUS 0
[2022-08-17T18:56:29.142] _job_complete: JobId=48059 done
[2022-08-17T18:56:29.580] sched: Allocate JobId=48070 NodeList=cpu14 #CPUs=1 Partition=cpu-epyc
[2022-08-17T18:56:31.019] _job_complete: JobId=48070 WEXITSTATUS 0
[2022-08-17T18:56:31.019] _job_complete: JobId=48070 done
[2022-08-17T18:56:31.358] sched: Allocate JobId=48063 NodeList=cpu14 #CPUs=16 Partition=cpu-epyc
[2022-08-17T19:01:27.912] _job_complete: JobId=48060 WEXITSTATUS 0
[2022-08-17T19:01:27.912] _job_complete: JobId=48060 done
[2022-08-17T19:17:23.284] _job_complete: JobId=48061 WEXITSTATUS 0
[2022-08-17T19:17:23.284] _job_complete: JobId=48061 done
[2022-08-17T20:24:06.078] _slurm_rpc_submit_batch_job: JobId=48072 InitPrio=697 usec=531
[2022-08-17T20:24:33.749] sched/backfill: _start_job: Started JobId=48072 in cpu-opteron on cpu01
[2022-08-17T20:33:08.250] sched: _slurm_rpc_allocate_resources JobId=48073 NodeList=(null) usec=1274
[2022-08-17T20:33:33.776] sched/backfill: _start_job: Started JobId=48073 in cpu-opteron on cpu01
[2022-08-17T20:43:07.343] _job_complete: JobId=48062 WEXITSTATUS 0
[2022-08-17T20:43:07.343] _job_complete: JobId=48062 done
[2022-08-17T20:50:37.111] _slurm_rpc_submit_batch_job: JobId=48074 InitPrio=465 usec=476
[2022-08-17T20:50:37.852] sched: Allocate JobId=48074 NodeList=gpu02 #CPUs=16 Partition=gpu-titan
[2022-08-17T21:10:12.848] _job_complete: JobId=48073 WEXITSTATUS 127
[2022-08-17T21:10:12.848] _job_complete: JobId=48073 done
[2022-08-17T21:11:07.632] sched: _slurm_rpc_allocate_resources JobId=48075 NodeList=(null) usec=1106
[2022-08-17T21:11:33.829] sched/backfill: _start_job: Started JobId=48075 in cpu-opteron on cpu01
[2022-08-17T21:23:59.829] _job_complete: JobId=48075 WEXITSTATUS 1
[2022-08-17T21:23:59.830] _job_complete: JobId=48075 done
[2022-08-17T21:24:50.787] sched: _slurm_rpc_allocate_resources JobId=48076 NodeList=(null) usec=1092
[2022-08-17T21:25:33.850] sched/backfill: _start_job: Started JobId=48076 in cpu-opteron on cpu01
[2022-08-17T21:30:38.996] _job_complete: JobId=48076 WEXITSTATUS 1
[2022-08-17T21:30:38.996] _job_complete: JobId=48076 done
[2022-08-17T21:31:01.365] _slurm_rpc_submit_batch_job: JobId=48077 InitPrio=465 usec=441
[2022-08-17T21:31:33.859] sched/backfill: _start_job: Started JobId=48077 in cpu-opteron on cpu01
[2022-08-17T21:31:36.902] _job_complete: JobId=48077 WEXITSTATUS 1
[2022-08-17T21:31:36.902] _job_complete: JobId=48077 done
[2022-08-17T21:33:37.488] _slurm_rpc_submit_batch_job: JobId=48078 InitPrio=2093 usec=535
[2022-08-17T21:33:40.241] _slurm_rpc_submit_batch_job: JobId=48079 InitPrio=465 usec=406
[2022-08-17T21:34:27.345] _slurm_rpc_kill_job: REQUEST_KILL_JOB JobId=48078 uid 548200023
[2022-08-17T21:34:33.864] sched/backfill: _start_job: Started JobId=48079 in cpu-opteron on cpu01
[2022-08-17T21:34:36.416] _job_complete: JobId=48079 WEXITSTATUS 1
[2022-08-17T21:34:36.416] _job_complete: JobId=48079 done
[2022-08-17T21:35:07.324] _slurm_rpc_submit_batch_job: JobId=48080 InitPrio=2093 usec=509
[2022-08-17T21:40:34.121] _job_complete: JobId=48074 WEXITSTATUS 1
[2022-08-17T21:40:34.121] _job_complete: JobId=48074 done
[2022-08-17T21:40:35.246] sched: Allocate JobId=48080 NodeList=gpu02 #CPUs=5 Partition=gpu-titan
[2022-08-17T21:47:36.652] _slurm_rpc_submit_batch_job: JobId=48081 InitPrio=465 usec=430
[2022-08-17T21:48:33.886] sched/backfill: _start_job: Started JobId=48081 in cpu-opteron on cpu01
[2022-08-17T21:48:36.472] _job_complete: JobId=48081 WEXITSTATUS 1
[2022-08-17T21:48:36.473] _job_complete: JobId=48081 done
[2022-08-17T21:50:20.632] _slurm_rpc_submit_batch_job: JobId=48082 InitPrio=465 usec=493
[2022-08-17T21:50:33.890] sched/backfill: _start_job: Started JobId=48082 in cpu-opteron on cpu01
[2022-08-17T21:50:36.387] _job_complete: JobId=48082 WEXITSTATUS 1
[2022-08-17T21:50:36.387] _job_complete: JobId=48082 done
[2022-08-17T21:51:16.834] _slurm_rpc_submit_batch_job: JobId=48083 InitPrio=465 usec=387
[2022-08-17T21:51:33.892] sched/backfill: _start_job: Started JobId=48083 in cpu-opteron on cpu01
[2022-08-17T21:51:36.460] _job_complete: JobId=48083 WEXITSTATUS 1
[2022-08-17T21:51:36.460] _job_complete: JobId=48083 done
[2022-08-17T21:53:51.905] sched: _slurm_rpc_allocate_resources JobId=48084 NodeList=(null) usec=885
[2022-08-17T21:54:33.897] sched/backfill: _start_job: Started JobId=48084 in cpu-opteron on cpu01
[2022-08-17T22:05:08.050] _job_complete: JobId=48084 WEXITSTATUS 0
[2022-08-17T22:05:08.050] _job_complete: JobId=48084 done
[2022-08-17T22:05:18.366] _slurm_rpc_submit_batch_job: JobId=48085 InitPrio=465 usec=486
[2022-08-17T22:05:33.915] sched/backfill: _start_job: Started JobId=48085 in cpu-opteron on cpu01
[2022-08-17T22:05:35.621] _job_complete: JobId=48085 WEXITSTATUS 127
[2022-08-17T22:05:35.621] _job_complete: JobId=48085 done
[2022-08-17T22:08:33.070] _job_complete: JobId=48063 WEXITSTATUS 0
[2022-08-17T22:08:33.070] _job_complete: JobId=48063 done
[2022-08-17T22:09:53.384] sched: _slurm_rpc_allocate_resources JobId=48086 NodeList=(null) usec=775
[2022-08-17T22:10:33.938] sched/backfill: _start_job: Started JobId=48086 in cpu-opteron on cpu01
[2022-08-17T22:11:12.499] _slurm_rpc_submit_batch_job: JobId=48087 InitPrio=930 usec=452
[2022-08-17T22:13:25.825] _slurm_rpc_kill_job: REQUEST_KILL_JOB JobId=48087 uid 548300547
[2022-08-17T22:15:01.319] _slurm_rpc_submit_batch_job: JobId=48088 InitPrio=930 usec=437
[2022-08-17T22:15:28.433] _job_complete: JobId=48086 WEXITSTATUS 130
[2022-08-17T22:15:28.433] _job_complete: JobId=48086 done
[2022-08-17T22:15:51.172] _slurm_rpc_submit_batch_job: JobId=48089 InitPrio=13953 usec=389
[2022-08-17T22:15:51.619] sched: Allocate JobId=48089 NodeList=cpu12 #CPUs=1 Partition=cpu-epyc
[2022-08-17T22:23:49.199] sched: _slurm_rpc_allocate_resources JobId=48090 NodeList=(null) usec=681
[2022-08-17T22:24:33.963] sched/backfill: _start_job: Started JobId=48090 in cpu-opteron on cpu01
[2022-08-17T22:32:01.431] _slurm_rpc_submit_batch_job: JobId=48091 InitPrio=465 usec=446
[2022-08-17T22:32:33.976] sched/backfill: _start_job: Started JobId=48091 in cpu-opteron on cpu01
[2022-08-17T22:32:37.686] _job_complete: JobId=48091 WEXITSTATUS 0
[2022-08-17T22:32:37.686] _job_complete: JobId=48091 done
[2022-08-17T22:32:39.845] _job_complete: JobId=47878 WEXITSTATUS 0
[2022-08-17T22:32:39.845] _job_complete: JobId=47878 done
[2022-08-17T22:36:11.302] _job_complete: JobId=48090 WEXITSTATUS 1
[2022-08-17T22:36:11.302] _job_complete: JobId=48090 done
[2022-08-17T22:40:20.125] sched: _slurm_rpc_allocate_resources JobId=48092 NodeList=(null) usec=557
[2022-08-17T22:40:33.993] sched/backfill: _start_job: Started JobId=48092 in cpu-opteron on cpu01
[2022-08-17T22:40:37.005] _job_complete: JobId=48092 WEXITSTATUS 1
[2022-08-17T22:40:37.005] _job_complete: JobId=48092 done
[2022-08-17T22:42:38.946] _job_complete: JobId=48089 WEXITSTATUS 0
[2022-08-17T22:42:38.947] _job_complete: JobId=48089 done
[2022-08-17T22:43:25.518] _get_job_parts: invalid partition specified: cpu=opteron
[2022-08-17T22:43:25.518] _slurm_rpc_allocate_resources: Invalid partition name specified 
[2022-08-17T22:44:26.431] sched: _slurm_rpc_allocate_resources JobId=48093 NodeList=(null) usec=634
[2022-08-17T22:44:33.999] sched/backfill: _start_job: Started JobId=48093 in cpu-opteron on cpu01
[2022-08-17T22:55:16.323] _slurm_rpc_submit_batch_job: JobId=48094 InitPrio=465 usec=504
[2022-08-17T22:55:34.019] sched/backfill: _start_job: Started JobId=48094 in cpu-opteron on cpu04
[2022-08-17T23:16:21.404] _slurm_rpc_submit_batch_job: JobId=48095 InitPrio=3953 usec=415
[2022-08-17T23:16:21.783] sched: Allocate JobId=48095 NodeList=cpu12 #CPUs=1 Partition=cpu-epyc
[2022-08-18T01:09:18.413] _job_complete: JobId=48093 WEXITSTATUS 0
[2022-08-18T01:09:18.414] _job_complete: JobId=48093 done
[2022-08-18T01:14:19.013] cleanup_completing: JobId=48093 completion process took 301 seconds
[2022-08-18T01:22:59.135] _job_complete: JobId=48094 WEXITSTATUS 0
[2022-08-18T01:22:59.135] _job_complete: JobId=48094 done
[2022-08-18T01:45:39.930] sched: _slurm_rpc_allocate_resources JobId=48096 NodeList=(null) usec=852
[2022-08-18T01:46:34.292] sched/backfill: _start_job: Started JobId=48096 in cpu-opteron on cpu01
[2022-08-18T02:26:09.479] _job_complete: JobId=48095 WEXITSTATUS 0
[2022-08-18T02:26:09.485] _job_complete: JobId=48095 done
[2022-08-18T03:28:34.604] _get_job_parts: invalid partition specified: cpu=epyc
[2022-08-18T03:28:34.604] _slurm_rpc_allocate_resources: Invalid partition name specified 
[2022-08-18T03:30:14.226] sched: _slurm_rpc_allocate_resources JobId=48097 NodeList=(null) usec=3583
[2022-08-18T03:30:34.459] sched/backfill: _start_job: Started JobId=48097 in cpu-epyc on cpu12
[2022-08-18T03:57:31.618] Time limit exhausted for JobId=46934
[2022-08-18T03:57:33.987] sched: Allocate JobId=48012 NodeList=cpu07 #CPUs=64 Partition=cpu-opteron
[2022-08-18T04:01:59.778] No nodes satisfy requirements for JobId=48098 in partition gpu-titan
[2022-08-18T04:01:59.778] _slurm_rpc_submit_batch_job: Requested node configuration is not available
[2022-08-18T04:02:36.070] _slurm_rpc_submit_batch_job: JobId=48099 InitPrio=465 usec=487
[2022-08-18T04:06:22.033] _job_complete: JobId=48096 WEXITSTATUS 0
[2022-08-18T04:06:22.034] _job_complete: JobId=48096 done
[2022-08-18T04:09:15.825] _slurm_rpc_kill_job: REQUEST_KILL_JOB JobId=48096 uid 548200021
[2022-08-18T04:11:24.388] cleanup_completing: JobId=48096 completion process took 302 seconds
[2022-08-18T04:14:01.705] sched: _slurm_rpc_allocate_resources JobId=48100 NodeList=(null) usec=841
[2022-08-18T04:14:34.519] sched/backfill: _start_job: Started JobId=48100 in cpu-epyc on cpu12
[2022-08-18T04:25:33.177] _job_complete: JobId=48097 WEXITSTATUS 0
[2022-08-18T04:25:33.177] _job_complete: JobId=48097 done
[2022-08-18T04:25:42.767] _job_complete: JobId=48100 WEXITSTATUS 0
[2022-08-18T04:25:42.768] _job_complete: JobId=48100 done
[2022-08-18T07:30:42.252] _slurm_rpc_submit_batch_job: JobId=48101 InitPrio=232 usec=413
[2022-08-18T07:31:02.457] _slurm_rpc_kill_job: REQUEST_KILL_JOB JobId=48101 uid 548200017
[2022-08-18T07:31:22.415] _slurm_rpc_submit_batch_job: JobId=48102 InitPrio=232 usec=374
[2022-08-18T07:34:06.077] _slurm_rpc_submit_batch_job: JobId=48103 InitPrio=232 usec=373
[2022-08-18T07:35:42.318] _slurm_rpc_submit_batch_job: JobId=48104 InitPrio=232 usec=423
[2022-08-18T07:36:03.580] _slurm_rpc_kill_job: REQUEST_KILL_JOB JobId=48104 uid 548200017
[2022-08-18T07:36:22.030] _slurm_rpc_submit_batch_job: JobId=48105 InitPrio=232 usec=558
[2022-08-18T07:36:34.773] sched/backfill: _start_job: Started JobId=48105 in cpu-epyc on cpu15
[2022-08-18T07:36:48.140] _job_complete: JobId=48105 WEXITSTATUS 1
[2022-08-18T07:36:48.141] _job_complete: JobId=48105 done
[2022-08-18T07:40:04.206] _slurm_rpc_submit_batch_job: JobId=48106 InitPrio=232 usec=467
[2022-08-18T07:40:34.782] sched/backfill: _start_job: Started JobId=48106 in cpu-epyc on cpu15
[2022-08-18T07:58:50.447] _slurm_rpc_submit_batch_job: JobId=48107 InitPrio=3720 usec=391
[2022-08-18T07:58:51.288] sched: Allocate JobId=48107 NodeList=cpu12 #CPUs=1 Partition=cpu-epyc
[2022-08-18T08:04:32.263] _slurm_rpc_kill_job: REQUEST_KILL_JOB JobId=48107 uid 548300595
[2022-08-18T08:05:55.495] _slurm_rpc_submit_batch_job: JobId=48108 InitPrio=3720 usec=379
[2022-08-18T08:05:55.953] sched: Allocate JobId=48108 NodeList=cpu12 #CPUs=1 Partition=cpu-epyc
[2022-08-18T09:40:10.129] _slurm_rpc_kill_job: REQUEST_KILL_JOB JobId=48088 uid 548300547
[2022-08-18T09:40:13.266] _slurm_rpc_submit_batch_job: JobId=48109 InitPrio=930 usec=461
[2022-08-18T09:42:52.365] _slurm_rpc_submit_batch_job: JobId=48110 InitPrio=930 usec=378
[2022-08-18T12:45:44.823] _slurm_rpc_submit_batch_job: JobId=48111 InitPrio=6046 usec=643
[2022-08-18T12:45:44.961] sched: Allocate JobId=48111 NodeList=cpu12 #CPUs=1 Partition=cpu-epyc
[2022-08-18T12:45:45.692] _job_complete: JobId=48111 WEXITSTATUS 0
[2022-08-18T12:45:45.692] _job_complete: JobId=48111 done
[2022-08-18T14:15:40.441] _slurm_rpc_submit_batch_job: JobId=48112 InitPrio=2777 usec=384
[2022-08-18T14:15:40.969] sched: Allocate JobId=48112 NodeList=cpu11 #CPUs=32 Partition=cpu-opteron
[2022-08-18T14:18:10.027] _job_complete: JobId=48112 WEXITSTATUS 0
[2022-08-18T14:18:10.028] _job_complete: JobId=48112 done
[2022-08-18T14:49:03.269] sched: _slurm_rpc_allocate_resources JobId=48113 NodeList=(null) usec=693
[2022-08-18T14:49:35.561] sched/backfill: _start_job: Started JobId=48113 in cpu-epyc on cpu12
[2022-08-18T16:13:08.362] _job_complete: JobId=48108 WEXITSTATUS 0
[2022-08-18T16:13:08.367] _job_complete: JobId=48108 done
[2022-08-18T16:27:13.631] _job_complete: JobId=48113 WEXITSTATUS 0
[2022-08-18T16:27:13.631] _job_complete: JobId=48113 done
[2022-08-18T16:32:15.309] cleanup_completing: JobId=48113 completion process took 302 seconds
[2022-08-18T16:57:25.885] _job_complete: JobId=47951 WEXITSTATUS 0
[2022-08-18T16:57:25.890] _job_complete: JobId=47951 done
[2022-08-18T16:57:33.161] sched: Allocate JobId=47975 NodeList=gpu04 #CPUs=8 Partition=gpu-k40c
[2022-08-18T17:00:14.691] sched: _slurm_rpc_allocate_resources JobId=48114 NodeList=(null) usec=830
[2022-08-18T17:00:14.745] sched: Allocate JobId=48114 NodeList=cpu12 #CPUs=1 Partition=cpu-epyc
[2022-08-18T17:08:04.412] _job_complete: JobId=48114 WEXITSTATUS 1
[2022-08-18T17:08:04.413] _job_complete: JobId=48114 done
[2022-08-18T17:08:22.954] sched: _slurm_rpc_allocate_resources JobId=48115 NodeList=(null) usec=698
[2022-08-18T17:08:23.779] sched: Allocate JobId=48115 NodeList=cpu12 #CPUs=1 Partition=cpu-epyc
[2022-08-18T17:10:17.981] _job_complete: JobId=48115 WEXITSTATUS 1
[2022-08-18T17:10:17.981] _job_complete: JobId=48115 done
[2022-08-18T17:10:40.700] sched: _slurm_rpc_allocate_resources JobId=48116 NodeList=(null) usec=1223
[2022-08-18T17:10:40.975] sched: Allocate JobId=48116 NodeList=cpu12 #CPUs=1 Partition=cpu-epyc
[2022-08-18T17:11:43.785] _job_complete: JobId=48116 WEXITSTATUS 1
[2022-08-18T17:11:43.786] _job_complete: JobId=48116 done
[2022-08-18T17:11:48.552] sched: _slurm_rpc_allocate_resources JobId=48117 NodeList=(null) usec=747
[2022-08-18T17:11:49.065] sched: Allocate JobId=48117 NodeList=cpu12 #CPUs=1 Partition=cpu-epyc
[2022-08-18T17:12:56.952] _job_complete: JobId=48117 WEXITSTATUS 1
[2022-08-18T17:12:56.952] _job_complete: JobId=48117 done
[2022-08-18T17:13:10.096] sched: _slurm_rpc_allocate_resources JobId=48118 NodeList=(null) usec=630
[2022-08-18T17:13:10.324] sched: Allocate JobId=48118 NodeList=cpu12 #CPUs=1 Partition=cpu-epyc
[2022-08-18T17:16:14.518] _job_complete: JobId=48118 WEXITSTATUS 1
[2022-08-18T17:16:14.518] _job_complete: JobId=48118 done
[2022-08-18T17:20:43.544] sched: _slurm_rpc_allocate_resources JobId=48119 NodeList=(null) usec=625
[2022-08-18T17:20:44.025] sched: Allocate JobId=48119 NodeList=cpu[12-13] #CPUs=4 Partition=cpu-epyc
[2022-08-18T17:21:47.620] _job_complete: JobId=48119 WEXITSTATUS 1
[2022-08-18T17:21:47.621] _job_complete: JobId=48119 done
[2022-08-18T17:25:39.863] _slurm_rpc_submit_batch_job: JobId=48120 InitPrio=3472 usec=361
[2022-08-18T17:29:12.362] _slurm_rpc_submit_batch_job: JobId=48121 InitPrio=694 usec=485
[2022-08-18T17:29:12.935] sched: Allocate JobId=48121 NodeList=cpu04 #CPUs=24 Partition=cpu-opteron
[2022-08-18T17:35:35.814] _slurm_rpc_kill_job: REQUEST_KILL_JOB JobId=48120 uid 548300595
[2022-08-18T19:16:16.165] _slurm_rpc_submit_batch_job: JobId=48122 InitPrio=16018 usec=630
[2022-08-18T19:16:16.767] sched: Allocate JobId=48122 NodeList=cpu12 #CPUs=16 Partition=cpu-epyc
[2022-08-18T19:39:58.582] _job_complete: JobId=48122 WEXITSTATUS 0
[2022-08-18T19:39:58.582] _job_complete: JobId=48122 done
[2022-08-18T20:35:01.848] _slurm_rpc_submit_batch_job: JobId=48123 InitPrio=16018 usec=909
[2022-08-18T20:35:02.064] sched: Allocate JobId=48123 NodeList=cpu12 #CPUs=16 Partition=cpu-epyc
[2022-08-18T20:44:18.376] _job_complete: JobId=48123 WEXITSTATUS 2
[2022-08-18T20:44:18.376] _job_complete: JobId=48123 done
[2022-08-18T20:52:11.950] _slurm_rpc_submit_batch_job: JobId=48124 InitPrio=6481 usec=516
[2022-08-18T20:53:14.027] _slurm_rpc_submit_batch_job: JobId=48125 InitPrio=6018 usec=806
[2022-08-18T20:53:14.910] sched: Allocate JobId=48125 NodeList=cpu12 #CPUs=16 Partition=cpu-epyc
[2022-08-18T21:01:55.208] _job_complete: JobId=48125 WEXITSTATUS 2
[2022-08-18T21:01:55.208] _job_complete: JobId=48125 done
[2022-08-18T21:03:09.949] sched: _slurm_rpc_allocate_resources JobId=48126 NodeList=(null) usec=845
[2022-08-18T21:03:36.294] sched/backfill: _start_job: Started JobId=48126 in cpu-epyc on cpu12
[2022-08-18T22:04:56.542] _slurm_rpc_kill_job: REQUEST_KILL_JOB JobId=48126 uid 548200021
[2022-08-18T22:05:19.472] sched: _slurm_rpc_allocate_resources JobId=48127 NodeList=(null) usec=801
[2022-08-18T22:08:44.767] _job_complete: JobId=48127 WTERMSIG 126
[2022-08-18T22:08:44.767] _job_complete: JobId=48127 cancelled by interactive user
[2022-08-18T22:08:44.767] _job_complete: JobId=48127 done
[2022-08-18T22:08:44.769] _slurm_rpc_complete_job_allocation: JobId=48127 error Job/step already completing or completed
[2022-08-18T22:09:43.517] sched: _slurm_rpc_allocate_resources JobId=48128 NodeList=(null) usec=884
[2022-08-18T22:09:58.287] cleanup_completing: JobId=48126 completion process took 302 seconds
[2022-08-18T22:10:35.291] sched: _slurm_rpc_allocate_resources JobId=48129 NodeList=(null) usec=1193
[2022-08-18T22:10:36.443] sched/backfill: _start_job: Started JobId=48128 in cpu-epyc on cpu12
[2022-08-18T22:10:36.444] sched/backfill: _start_job: Started JobId=48129 in cpu-opteron on cpu01
[2022-08-18T22:16:49.032] _job_complete: JobId=48129 WEXITSTATUS 0
[2022-08-18T22:16:49.033] _job_complete: JobId=48129 done
[2022-08-18T22:31:12.470] _job_complete: JobId=48128 WEXITSTATUS 1
[2022-08-18T22:31:12.470] _job_complete: JobId=48128 done
[2022-08-18T22:40:17.337] _slurm_rpc_kill_job: REQUEST_KILL_JOB JobId=47975 uid 548300580
[2022-08-18T22:40:24.459] sched: Allocate JobId=48124 NodeList=gpu04 #CPUs=8 Partition=gpu-k40c
[2022-08-19T00:10:33.607] _slurm_rpc_submit_batch_job: JobId=48130 InitPrio=1388 usec=444
[2022-08-19T06:51:50.830] _job_complete: JobId=48001 WEXITSTATUS 0
[2022-08-19T06:51:50.835] _job_complete: JobId=48001 done
[2022-08-19T07:50:31.738] _job_complete: JobId=48069 WEXITSTATUS 0
