[2022-12-01T00:56:52.045] _job_complete: JobId=53337 WEXITSTATUS 0
[2022-12-01T00:56:52.046] _job_complete: JobId=53337 done
[2022-12-01T01:01:55.001] cleanup_completing: JobId=53337 completion process took 303 seconds
[2022-12-01T07:19:45.842] _slurm_rpc_submit_batch_job: JobId=53338 InitPrio=2200 usec=576
[2022-12-01T07:19:45.969] sched: Allocate JobId=53338 NodeList=gpu04 #CPUs=16 Partition=gpu-k40c
[2022-12-01T07:40:47.268] Requeuing JobId=53209
[2022-12-01T08:10:25.296] _slurm_rpc_submit_batch_job: JobId=53339 InitPrio=2600 usec=581
[2022-12-01T08:10:25.477] sched: Allocate JobId=53339 NodeList=cpu07 #CPUs=32 Partition=cpu-opteron
[2022-12-01T08:20:26.483] Time limit exhausted for JobId=53115
[2022-12-01T08:20:27.837] sched: Allocate JobId=53322 NodeList=gpu02 #CPUs=8 Partition=gpu-titan
[2022-12-01T08:21:30.903] _job_complete: JobId=53201 WEXITSTATUS 0
[2022-12-01T08:21:30.909] _job_complete: JobId=53201 done
[2022-12-01T08:21:34.121] sched: Allocate JobId=53333 NodeList=cpu04 #CPUs=64 Partition=cpu-opteron
[2022-12-01T09:12:13.047] _slurm_rpc_submit_batch_job: JobId=53340 InitPrio=800 usec=546
[2022-12-01T09:12:19.534] sched/backfill: _start_job: Started JobId=53340 in cpu-opteron on cpu10
[2022-12-01T09:12:21.929] _job_complete: JobId=53340 WEXITSTATUS 1
[2022-12-01T09:12:21.929] _job_complete: JobId=53340 done
[2022-12-01T10:14:41.866] sched: _slurm_rpc_allocate_resources JobId=53341 NodeList=(null) usec=1276
[2022-12-01T10:15:19.609] sched/backfill: _start_job: Started JobId=53341 in cpu-opteron on cpu10
[2022-12-01T10:27:33.751] sched: _slurm_rpc_allocate_resources JobId=53342 NodeList=(null) usec=779
[2022-12-01T10:28:19.627] sched/backfill: _start_job: Started JobId=53342 in cpu-opteron on cpu10
[2022-12-01T10:33:52.382] _job_complete: JobId=53342 WEXITSTATUS 0
[2022-12-01T10:33:52.383] _job_complete: JobId=53342 done
[2022-12-01T10:35:11.342] _slurm_rpc_submit_batch_job: JobId=53343 InitPrio=800 usec=485
[2022-12-01T10:35:19.637] sched/backfill: _start_job: Started JobId=53343 in cpu-opteron on cpu10
[2022-12-01T10:35:22.852] _job_complete: JobId=53343 WEXITSTATUS 1
[2022-12-01T10:35:22.852] _job_complete: JobId=53343 done
[2022-12-01T10:38:00.689] _slurm_rpc_submit_batch_job: JobId=53344 InitPrio=800 usec=492
[2022-12-01T10:38:19.642] sched/backfill: _start_job: Started JobId=53344 in cpu-opteron on cpu10
[2022-12-01T10:38:20.648] _job_complete: JobId=53344 WEXITSTATUS 1
[2022-12-01T10:38:20.648] _job_complete: JobId=53344 done
[2022-12-01T10:39:17.451] _slurm_rpc_submit_batch_job: JobId=53345 InitPrio=800 usec=491
[2022-12-01T10:39:19.644] sched/backfill: _start_job: Started JobId=53345 in cpu-opteron on cpu10
[2022-12-01T10:39:20.606] _job_complete: JobId=53345 WEXITSTATUS 1
[2022-12-01T10:39:20.607] _job_complete: JobId=53345 done
[2022-12-01T10:40:26.772] _slurm_rpc_submit_batch_job: JobId=53346 InitPrio=800 usec=403
[2022-12-01T10:41:19.648] sched/backfill: _start_job: Started JobId=53346 in cpu-opteron on cpu10
[2022-12-01T10:41:20.634] _job_complete: JobId=53346 WEXITSTATUS 1
[2022-12-01T10:41:20.634] _job_complete: JobId=53346 done
[2022-12-01T10:43:53.027] _slurm_rpc_submit_batch_job: JobId=53347 InitPrio=800 usec=547
[2022-12-01T10:44:19.653] sched/backfill: _start_job: Started JobId=53347 in cpu-opteron on cpu10
[2022-12-01T10:44:20.756] _job_complete: JobId=53347 WEXITSTATUS 1
[2022-12-01T10:44:20.756] _job_complete: JobId=53347 done
[2022-12-01T10:59:23.535] sched: _slurm_rpc_allocate_resources JobId=53348 NodeList=(null) usec=985
[2022-12-01T11:00:19.675] sched/backfill: _start_job: Started JobId=53348 in cpu-opteron on cpu10
[2022-12-01T11:10:02.048] _slurm_rpc_submit_batch_job: JobId=53349 InitPrio=600 usec=432
[2022-12-01T11:10:07.283] _slurm_rpc_submit_batch_job: JobId=53350 InitPrio=600 usec=319
[2022-12-01T11:10:12.574] _slurm_rpc_submit_batch_job: JobId=53351 InitPrio=600 usec=331
[2022-12-01T11:10:22.524] _slurm_rpc_submit_batch_job: JobId=53352 InitPrio=600 usec=391
[2022-12-01T12:39:14.429] _slurm_rpc_submit_batch_job: JobId=53353 InitPrio=1400 usec=562
[2022-12-01T14:27:41.994] _slurm_rpc_submit_batch_job: JobId=53354 InitPrio=400 usec=664
[2022-12-01T15:03:57.241] _slurm_rpc_submit_batch_job: JobId=53355 InitPrio=19000 usec=5498
[2022-12-01T15:03:57.541] sched: Allocate JobId=53355 NodeList=cpu10 #CPUs=1 Partition=cpu-opteron
[2022-12-01T15:05:36.380] _job_complete: JobId=53355 WEXITSTATUS 0
[2022-12-01T15:05:36.380] _job_complete: JobId=53355 done
[2022-12-01T15:11:42.687] _slurm_rpc_submit_batch_job: JobId=53356 InitPrio=19000 usec=526
[2022-12-01T15:11:43.366] sched: Allocate JobId=53356 NodeList=cpu10 #CPUs=1 Partition=cpu-opteron
[2022-12-01T15:12:06.335] _job_complete: JobId=53356 WEXITSTATUS 0
[2022-12-01T15:12:06.335] _job_complete: JobId=53356 done
[2022-12-01T15:15:18.163] _slurm_rpc_submit_batch_job: JobId=53357 InitPrio=19000 usec=658
[2022-12-01T15:15:18.960] sched: Allocate JobId=53357 NodeList=cpu10 #CPUs=1 Partition=cpu-opteron
[2022-12-01T15:15:38.113] _job_complete: JobId=53357 WEXITSTATUS 0
[2022-12-01T15:15:38.114] _job_complete: JobId=53357 done
[2022-12-01T15:38:19.767] _job_complete: JobId=53348 WEXITSTATUS 0
[2022-12-01T15:38:19.768] _job_complete: JobId=53348 done
[2022-12-01T15:43:20.395] cleanup_completing: JobId=53348 completion process took 301 seconds
[2022-12-01T16:43:40.460] _slurm_rpc_submit_batch_job: JobId=53358 InitPrio=600 usec=435
[2022-12-01T16:44:37.097] _slurm_rpc_submit_batch_job: JobId=53359 InitPrio=10600 usec=322
[2022-12-01T16:45:38.330] _slurm_rpc_kill_job: REQUEST_KILL_JOB JobId=53359 uid 548200121
[2022-12-01T16:46:32.198] _slurm_rpc_submit_batch_job: JobId=53360 InitPrio=600 usec=472
[2022-12-01T16:57:15.795] _pick_best_nodes: JobId=53361 never runnable in partition cpu-opteron
[2022-12-01T16:57:15.796] _slurm_rpc_submit_batch_job: Requested node configuration is not available
[2022-12-01T16:57:32.869] _slurm_rpc_submit_batch_job: JobId=53362 InitPrio=10600 usec=412
[2022-12-01T16:57:33.749] sched: Allocate JobId=53362 NodeList=cpu03 #CPUs=4 Partition=cpu-opteron
[2022-12-01T17:57:57.343] Time limit exhausted for JobId=53362
[2022-12-01T18:04:41.577] _slurm_rpc_submit_batch_job: JobId=53363 InitPrio=10600 usec=463
[2022-12-01T18:04:42.024] sched: Allocate JobId=53363 NodeList=cpu10 #CPUs=2 Partition=cpu-opteron
[2022-12-01T18:14:55.927] _job_complete: JobId=53341 WEXITSTATUS 0
[2022-12-01T18:14:55.927] _job_complete: JobId=53341 done
[2022-12-01T18:19:56.302] cleanup_completing: JobId=53341 completion process took 301 seconds
[2022-12-01T19:04:57.648] Time limit exhausted for JobId=53363
[2022-12-01T19:05:59.180] _slurm_rpc_submit_batch_job: JobId=53364 InitPrio=600 usec=351
[2022-12-01T19:06:20.468] sched/backfill: _start_job: Started JobId=53364 in cpu-opteron on cpu10
[2022-12-01T19:28:05.527] _slurm_rpc_submit_batch_job: JobId=53365 InitPrio=200 usec=639
[2022-12-01T19:28:21.716] _slurm_rpc_kill_job: REQUEST_KILL_JOB JobId=53365 uid 548300621
[2022-12-01T19:28:22.467] _slurm_rpc_kill_job: REQUEST_KILL_JOB JobId=53365 uid 548300621
[2022-12-01T19:28:43.061] _slurm_rpc_submit_batch_job: JobId=53366 InitPrio=200 usec=534
[2022-12-02T00:48:34.589] _job_complete: JobId=53200 WEXITSTATUS 0
[2022-12-02T00:48:34.596] _job_complete: JobId=53200 done
[2022-12-02T00:48:37.830] sched: Allocate JobId=53353 NodeList=cpu09 #CPUs=35 Partition=cpu-opteron
[2022-12-02T02:53:31.746] _job_complete: JobId=53236 WEXITSTATUS 0
[2022-12-02T02:53:31.753] _job_complete: JobId=53236 done
[2022-12-02T04:47:14.731] _job_complete: JobId=53311 WEXITSTATUS 1
[2022-12-02T04:47:14.731] _job_complete: JobId=53311 done
[2022-12-02T04:47:15.097] sched: Allocate JobId=53326 NodeList=cpu12 #CPUs=48 Partition=cpu-epyc
[2022-12-02T07:20:03.440] _job_complete: JobId=53353 WEXITSTATUS 0
[2022-12-02T07:20:03.446] _job_complete: JobId=53353 done
[2022-12-02T07:20:25.671] sched: Allocate JobId=53334 NodeList=cpu09 #CPUs=64 Partition=cpu-opteron
[2022-12-02T08:21:29.418] sched: _slurm_rpc_allocate_resources JobId=53367 NodeList=(null) usec=1455
[2022-12-02T08:21:29.972] sched: Allocate JobId=53367 NodeList=cpu01 #CPUs=32 Partition=cpu-opteron
[2022-12-02T08:38:26.314] _slurm_rpc_submit_batch_job: JobId=53368 InitPrio=2000 usec=630
[2022-12-02T08:45:41.675] _slurm_rpc_submit_batch_job: JobId=53369 InitPrio=4800 usec=537
[2022-12-02T08:47:15.726] _slurm_rpc_kill_job: REQUEST_KILL_JOB JobId=53369 uid 548300557
[2022-12-02T08:47:28.973] _slurm_rpc_submit_batch_job: JobId=53370 InitPrio=2000 usec=505
[2022-12-02T08:48:05.073] _slurm_rpc_submit_batch_job: JobId=53371 InitPrio=4800 usec=616
[2022-12-02T08:53:29.814] Requeuing JobId=53326
[2022-12-02T08:53:29.837] sched: Allocate JobId=53328 NodeList=cpu12 #CPUs=24 Partition=cpu-epyc
[2022-12-02T08:53:29.852] sched: Allocate JobId=53368 NodeList=cpu12 #CPUs=24 Partition=cpu-epyc
[2022-12-02T08:54:51.684] _slurm_rpc_submit_batch_job: JobId=53372 InitPrio=400 usec=454
[2022-12-02T09:17:13.308] _job_complete: JobId=52551 OOM failure
[2022-12-02T09:17:13.315] _job_complete: JobId=52551 done
[2022-12-02T09:17:21.588] sched: Allocate JobId=52584 NodeList=gpu05 #CPUs=4 Partition=gpu-v100s
[2022-12-02T09:21:33.474] Time limit exhausted for JobId=53367
[2022-12-02T09:24:22.792] sched: _slurm_rpc_allocate_resources JobId=53373 NodeList=(null) usec=863
[2022-12-02T09:26:33.147] _slurm_rpc_kill_job: REQUEST_KILL_JOB JobId=53367 uid 548300642
[2022-12-02T09:26:34.704] cleanup_completing: JobId=53367 completion process took 301 seconds
[2022-12-02T09:26:34.705] sched: Allocate JobId=53373 NodeList=cpu01 #CPUs=32 Partition=cpu-opteron
[2022-12-02T09:26:45.710] Killing interactive JobId=53373: Communication connection failure
[2022-12-02T09:26:45.710] _job_complete: JobId=53373 WEXITSTATUS 1
[2022-12-02T09:26:45.710] _job_complete: JobId=53373 done
[2022-12-02T09:27:12.147] sched: _slurm_rpc_allocate_resources JobId=53374 NodeList=(null) usec=1097
[2022-12-02T09:27:13.027] sched: Allocate JobId=53374 NodeList=cpu01 #CPUs=32 Partition=cpu-opteron
[2022-12-02T09:27:28.236] _slurm_rpc_kill_job: REQUEST_KILL_JOB JobId=53374 uid 548300642
[2022-12-02T09:27:39.290] sched: _slurm_rpc_allocate_resources JobId=53375 NodeList=(null) usec=845
[2022-12-02T09:27:40.063] sched: Allocate JobId=53375 NodeList=cpu01 #CPUs=32 Partition=cpu-opteron
[2022-12-02T10:25:57.207] _slurm_rpc_submit_batch_job: JobId=53376 InitPrio=1000 usec=515
[2022-12-02T10:26:21.118] sched/backfill: _start_job: Started JobId=53376 in cpu-opteron on cpu01
[2022-12-02T10:29:22.582] _slurm_rpc_submit_batch_job: JobId=53377 InitPrio=1000 usec=494
[2022-12-02T10:29:46.050] _slurm_rpc_kill_job: REQUEST_KILL_JOB JobId=53377 uid 548200021
[2022-12-02T10:30:34.120] _slurm_rpc_submit_batch_job: JobId=53378 InitPrio=1000 usec=520
[2022-12-02T11:15:45.203] _slurm_rpc_kill_job: REQUEST_KILL_JOB JobId=53378 uid 548200021
[2022-12-02T11:16:06.897] _slurm_rpc_submit_batch_job: JobId=53379 InitPrio=1000 usec=512
[2022-12-02T11:16:21.202] sched/backfill: _start_job: Started JobId=53379 in cpu-opteron on cpu10
[2022-12-02T11:39:31.039] _job_complete: JobId=53376 WEXITSTATUS 0
[2022-12-02T11:39:31.039] _job_complete: JobId=53376 done
[2022-12-02T11:55:52.775] Terminate signal (SIGINT or SIGTERM) received
[2022-12-02T11:55:52.799] Saving all slurm state
[2022-12-02T11:55:54.523] slurmctld version 21.08.8-2 started on cluster um-hpc
[2022-12-02T11:55:54.529] accounting_storage/slurmdbd: clusteracct_storage_p_register_ctld: Registering slurmctld at port 6817 with slurmdbd
[2022-12-02T11:55:56.012] Recovered state of 19 nodes
[2022-12-02T11:55:56.012] Down nodes: umhpc
[2022-12-02T11:55:56.012] Recovered JobId=52498 Assoc=113
[2022-12-02T11:55:56.012] Recovered JobId=52584 StepId=extern
[2022-12-02T11:55:56.012] Recovered JobId=52584 StepId=batch
[2022-12-02T11:55:56.012] Recovered JobId=52584 Assoc=113
[2022-12-02T11:55:56.012] Recovered JobId=52773 Assoc=23
[2022-12-02T11:55:56.012] Recovered JobId=52777 Assoc=23
[2022-12-02T11:55:56.012] Recovered JobId=52922 StepId=extern
[2022-12-02T11:55:56.012] Recovered JobId=52922 StepId=batch
[2022-12-02T11:55:56.012] Recovered JobId=52922 Assoc=32
[2022-12-02T11:55:56.012] Recovered JobId=53178 Assoc=113
[2022-12-02T11:55:56.012] Recovered JobId=53189 StepId=extern
[2022-12-02T11:55:56.012] Recovered JobId=53189 StepId=batch
[2022-12-02T11:55:56.013] Recovered JobId=53189 Assoc=18
[2022-12-02T11:55:56.013] Recovered JobId=53195 StepId=extern
[2022-12-02T11:55:56.013] Recovered JobId=53195 StepId=batch
[2022-12-02T11:55:56.013] Recovered JobId=53195 Assoc=18
[2022-12-02T11:55:56.013] Recovered JobId=53196 StepId=extern
[2022-12-02T11:55:56.013] Recovered JobId=53196 StepId=batch
[2022-12-02T11:55:56.013] Recovered JobId=53196 Assoc=18
[2022-12-02T11:55:56.013] Recovered JobId=53209 Assoc=23
[2022-12-02T11:55:56.013] Recovered JobId=53220 Assoc=23
[2022-12-02T11:55:56.013] Recovered JobId=53226 Assoc=23
[2022-12-02T11:55:56.013] Recovered JobId=53238 StepId=extern
[2022-12-02T11:55:56.013] Recovered JobId=53238 StepId=batch
[2022-12-02T11:55:56.013] Recovered JobId=53238 Assoc=211
[2022-12-02T11:55:56.013] Recovered JobId=53240 StepId=extern
[2022-12-02T11:55:56.013] Recovered JobId=53240 StepId=batch
[2022-12-02T11:55:56.013] Recovered JobId=53240 Assoc=20
[2022-12-02T11:55:56.013] Recovered JobId=53241 Assoc=20
[2022-12-02T11:55:56.013] Recovered JobId=53306 StepId=extern
[2022-12-02T11:55:56.013] Recovered JobId=53306 StepId=batch
[2022-12-02T11:55:56.013] Recovered JobId=53306 Assoc=246
[2022-12-02T11:55:56.014] Recovered JobId=53309 StepId=extern
[2022-12-02T11:55:56.014] Recovered JobId=53309 StepId=batch
[2022-12-02T11:55:56.014] Recovered JobId=53309 StepId=0
[2022-12-02T11:55:56.014] Recovered JobId=53309 Assoc=8
[2022-12-02T11:55:56.014] Recovered JobId=53313 StepId=extern
[2022-12-02T11:55:56.014] Recovered JobId=53313 StepId=batch
[2022-12-02T11:55:56.014] Recovered JobId=53313 Assoc=246
[2022-12-02T11:55:56.014] Recovered JobId=53314 Assoc=113
[2022-12-02T11:55:56.014] Recovered JobId=53315 StepId=extern
[2022-12-02T11:55:56.014] Recovered JobId=53315 StepId=batch
[2022-12-02T11:55:56.014] Recovered JobId=53315 Assoc=211
[2022-12-02T11:55:56.014] Recovered JobId=53322 StepId=extern
[2022-12-02T11:55:56.014] Recovered JobId=53322 StepId=batch
[2022-12-02T11:55:56.014] Recovered JobId=53322 Assoc=32
[2022-12-02T11:55:56.014] Recovered JobId=53323 Assoc=32
[2022-12-02T11:55:56.014] Recovered JobId=53324 StepId=extern
[2022-12-02T11:55:56.014] Recovered JobId=53324 StepId=batch
[2022-12-02T11:55:56.014] Recovered JobId=53324 Assoc=32
[2022-12-02T11:55:56.014] Recovered JobId=53325 Assoc=32
[2022-12-02T11:55:56.015] Recovered JobId=53326 Assoc=172
[2022-12-02T11:55:56.015] Recovered JobId=53327 StepId=extern
[2022-12-02T11:55:56.015] Recovered JobId=53327 StepId=batch
[2022-12-02T11:55:56.015] Recovered JobId=53327 StepId=0
[2022-12-02T11:55:56.015] Recovered JobId=53327 Assoc=8
[2022-12-02T11:55:56.015] Recovered JobId=53328 StepId=extern
[2022-12-02T11:55:56.015] Recovered JobId=53328 StepId=batch
[2022-12-02T11:55:56.015] Recovered JobId=53328 Assoc=18
[2022-12-02T11:55:56.015] Recovered JobId=53332 StepId=extern
[2022-12-02T11:55:56.015] Recovered JobId=53332 StepId=batch
[2022-12-02T11:55:56.015] Recovered JobId=53332 Assoc=238
[2022-12-02T11:55:56.015] Recovered JobId=53333 StepId=extern
[2022-12-02T11:55:56.015] Recovered JobId=53333 StepId=batch
[2022-12-02T11:55:56.015] Recovered JobId=53333 Assoc=238
[2022-12-02T11:55:56.015] Recovered JobId=53334 StepId=extern
[2022-12-02T11:55:56.015] Recovered JobId=53334 StepId=batch
[2022-12-02T11:55:56.015] Recovered JobId=53334 Assoc=238
[2022-12-02T11:55:56.015] Recovered JobId=53335 Assoc=238
[2022-12-02T11:55:56.015] Recovered JobId=53336 Assoc=238
[2022-12-02T11:55:56.016] Recovered JobId=53338 StepId=extern
[2022-12-02T11:55:56.016] Recovered JobId=53338 StepId=batch
[2022-12-02T11:55:56.016] Recovered JobId=53338 Assoc=67
[2022-12-02T11:55:56.016] Recovered JobId=53339 StepId=extern
[2022-12-02T11:55:56.016] Recovered JobId=53339 StepId=batch
[2022-12-02T11:55:56.016] Recovered JobId=53339 StepId=0
[2022-12-02T11:55:56.016] Recovered JobId=53339 Assoc=8
[2022-12-02T11:55:56.016] Recovered JobId=53349 Assoc=113
[2022-12-02T11:55:56.016] Recovered JobId=53350 Assoc=113
[2022-12-02T11:55:56.016] Recovered JobId=53351 Assoc=113
[2022-12-02T11:55:56.016] Recovered JobId=53352 Assoc=113
[2022-12-02T11:55:56.016] Recovered JobId=53354 Assoc=18
[2022-12-02T11:55:56.016] Recovered JobId=53358 Assoc=113
[2022-12-02T11:55:56.016] Recovered JobId=53360 Assoc=113
[2022-12-02T11:55:56.016] Recovered JobId=53364 StepId=extern
[2022-12-02T11:55:56.016] Recovered JobId=53364 StepId=batch
[2022-12-02T11:55:56.016] Recovered JobId=53364 Assoc=113
[2022-12-02T11:55:56.016] Recovered JobId=53366 Assoc=238
[2022-12-02T11:55:56.016] Recovered JobId=53368 StepId=extern
[2022-12-02T11:55:56.016] Recovered JobId=53368 StepId=batch
[2022-12-02T11:55:56.016] Recovered JobId=53368 Assoc=246
[2022-12-02T11:55:56.016] Recovered JobId=53370 Assoc=246
[2022-12-02T11:55:56.016] Recovered JobId=53371 Assoc=187
[2022-12-02T11:55:56.016] Recovered JobId=53372 Assoc=18
[2022-12-02T11:55:56.017] Recovered JobId=53375 StepId=extern
[2022-12-02T11:55:56.017] Recovered JobId=53375 StepId=0
[2022-12-02T11:55:56.017] Recovered JobId=53375 Assoc=258
[2022-12-02T11:55:56.017] Recovered JobId=53379 StepId=extern
[2022-12-02T11:55:56.017] Recovered JobId=53379 StepId=batch
[2022-12-02T11:55:56.017] Recovered JobId=53379 Assoc=20
[2022-12-02T11:55:56.017] Recovered information about 49 jobs
[2022-12-02T11:55:56.017] select/cons_tres: part_data_create_array: select/cons_tres: preparing for 6 partitions
[2022-12-02T11:55:56.018] Recovered state of reservation cpu14_health_check
[2022-12-02T11:55:56.018] Recovered state of reservation cpu11_memtest
[2022-12-02T11:55:56.018] Recovered state of 2 reservations
[2022-12-02T11:55:56.019] read_slurm_conf: backup_controller not specified
[2022-12-02T11:55:56.019] select/cons_tres: select_p_reconfigure: select/cons_tres: reconfigure
[2022-12-02T11:55:56.019] select/cons_tres: part_data_create_array: select/cons_tres: preparing for 6 partitions
[2022-12-02T11:55:56.019] Running as primary controller
[2022-12-02T11:55:56.269] No parameter for mcs plugin, default values set
[2022-12-02T11:55:56.269] mcs: MCSParameters = (null). ondemand set.
[2022-12-02T11:56:00.280] error: Node cpu01 appears to have a different slurm.conf than the slurmctld.  This could cause issues with communication and functionality.  Please review both files and make sure they are the same.  If this is expected ignore, and set DebugFlags=NO_CONF_HASH in your slurm.conf.
[2022-12-02T11:56:00.281] error: Node cpu03 appears to have a different slurm.conf than the slurmctld.  This could cause issues with communication and functionality.  Please review both files and make sure they are the same.  If this is expected ignore, and set DebugFlags=NO_CONF_HASH in your slurm.conf.
[2022-12-02T11:56:00.281] error: Node cpu13 appears to have a different slurm.conf than the slurmctld.  This could cause issues with communication and functionality.  Please review both files and make sure they are the same.  If this is expected ignore, and set DebugFlags=NO_CONF_HASH in your slurm.conf.
[2022-12-02T11:56:00.282] error: Node cpu12 appears to have a different slurm.conf than the slurmctld.  This could cause issues with communication and functionality.  Please review both files and make sure they are the same.  If this is expected ignore, and set DebugFlags=NO_CONF_HASH in your slurm.conf.
[2022-12-02T11:56:00.282] error: Node cpu11 appears to have a different slurm.conf than the slurmctld.  This could cause issues with communication and functionality.  Please review both files and make sure they are the same.  If this is expected ignore, and set DebugFlags=NO_CONF_HASH in your slurm.conf.
[2022-12-02T11:56:00.282] error: Node cpu15 appears to have a different slurm.conf than the slurmctld.  This could cause issues with communication and functionality.  Please review both files and make sure they are the same.  If this is expected ignore, and set DebugFlags=NO_CONF_HASH in your slurm.conf.
[2022-12-02T11:56:00.282] error: Node cpu05 appears to have a different slurm.conf than the slurmctld.  This could cause issues with communication and functionality.  Please review both files and make sure they are the same.  If this is expected ignore, and set DebugFlags=NO_CONF_HASH in your slurm.conf.
[2022-12-02T11:56:00.283] error: Node cpu09 appears to have a different slurm.conf than the slurmctld.  This could cause issues with communication and functionality.  Please review both files and make sure they are the same.  If this is expected ignore, and set DebugFlags=NO_CONF_HASH in your slurm.conf.
[2022-12-02T11:56:00.283] error: Node gpu03 appears to have a different slurm.conf than the slurmctld.  This could cause issues with communication and functionality.  Please review both files and make sure they are the same.  If this is expected ignore, and set DebugFlags=NO_CONF_HASH in your slurm.conf.
[2022-12-02T11:56:00.284] error: Node cpu10 appears to have a different slurm.conf than the slurmctld.  This could cause issues with communication and functionality.  Please review both files and make sure they are the same.  If this is expected ignore, and set DebugFlags=NO_CONF_HASH in your slurm.conf.
[2022-12-02T11:56:00.284] error: Node gpu05 appears to have a different slurm.conf than the slurmctld.  This could cause issues with communication and functionality.  Please review both files and make sure they are the same.  If this is expected ignore, and set DebugFlags=NO_CONF_HASH in your slurm.conf.
[2022-12-02T11:56:00.284] error: Node gpu01 appears to have a different slurm.conf than the slurmctld.  This could cause issues with communication and functionality.  Please review both files and make sure they are the same.  If this is expected ignore, and set DebugFlags=NO_CONF_HASH in your slurm.conf.
[2022-12-02T11:56:00.284] error: Node cpu08 appears to have a different slurm.conf than the slurmctld.  This could cause issues with communication and functionality.  Please review both files and make sure they are the same.  If this is expected ignore, and set DebugFlags=NO_CONF_HASH in your slurm.conf.
[2022-12-02T11:56:00.284] error: Node cpu07 appears to have a different slurm.conf than the slurmctld.  This could cause issues with communication and functionality.  Please review both files and make sure they are the same.  If this is expected ignore, and set DebugFlags=NO_CONF_HASH in your slurm.conf.
[2022-12-02T11:56:00.284] error: Node gpu02 appears to have a different slurm.conf than the slurmctld.  This could cause issues with communication and functionality.  Please review both files and make sure they are the same.  If this is expected ignore, and set DebugFlags=NO_CONF_HASH in your slurm.conf.
[2022-12-02T11:56:00.284] error: Node gpu04 appears to have a different slurm.conf than the slurmctld.  This could cause issues with communication and functionality.  Please review both files and make sure they are the same.  If this is expected ignore, and set DebugFlags=NO_CONF_HASH in your slurm.conf.
[2022-12-02T11:56:00.287] error: Node cpu04 appears to have a different slurm.conf than the slurmctld.  This could cause issues with communication and functionality.  Please review both files and make sure they are the same.  If this is expected ignore, and set DebugFlags=NO_CONF_HASH in your slurm.conf.
[2022-12-02T11:56:00.323] error: Node cpu14 appears to have a different slurm.conf than the slurmctld.  This could cause issues with communication and functionality.  Please review both files and make sure they are the same.  If this is expected ignore, and set DebugFlags=NO_CONF_HASH in your slurm.conf.
[2022-12-02T11:56:01.276] SchedulerParameters=default_queue_depth=100,max_rpc_cnt=0,max_sched_time=2,partition_job_depth=0,sched_max_job_start=0,sched_min_interval=2
[2022-12-02T11:56:05.307] Processing Reconfiguration Request
[2022-12-02T11:56:05.315] restoring original state of nodes
[2022-12-02T11:56:05.315] select/cons_tres: part_data_create_array: select/cons_tres: preparing for 6 partitions
[2022-12-02T11:56:05.316] read_slurm_conf: backup_controller not specified
[2022-12-02T11:56:05.316] select/cons_tres: select_p_reconfigure: select/cons_tres: reconfigure
[2022-12-02T11:56:05.316] select/cons_tres: part_data_create_array: select/cons_tres: preparing for 6 partitions
[2022-12-02T11:56:05.316] No parameter for mcs plugin, default values set
[2022-12-02T11:56:05.316] mcs: MCSParameters = (null). ondemand set.
[2022-12-02T11:56:05.317] _slurm_rpc_reconfigure_controller: completed usec=10183
[2022-12-02T11:56:06.284] SchedulerParameters=default_queue_depth=100,max_rpc_cnt=0,max_sched_time=2,partition_job_depth=0,sched_max_job_start=0,sched_min_interval=2
[2022-12-02T11:56:17.305] Node management01 now responding
[2022-12-02T12:00:56.646] error: Nodes management01 not responding
[2022-12-02T12:10:52.127] _slurm_rpc_submit_batch_job: JobId=53380 InitPrio=3200 usec=1095
[2022-12-02T12:10:55.389] _slurm_rpc_submit_batch_job: JobId=53381 InitPrio=3200 usec=509
[2022-12-02T12:11:00.283] _slurm_rpc_submit_batch_job: JobId=53382 InitPrio=3200 usec=533
[2022-12-02T12:11:03.284] _slurm_rpc_submit_batch_job: JobId=53383 InitPrio=3200 usec=443
[2022-12-02T13:02:35.171] _job_complete: JobId=53379 WEXITSTATUS 0
[2022-12-02T13:02:35.171] _job_complete: JobId=53379 done
[2022-12-02T13:15:33.164] _slurm_rpc_submit_batch_job: JobId=53384 InitPrio=1000 usec=526
[2022-12-02T13:15:56.563] sched/backfill: _start_job: Started JobId=53384 in cpu-opteron on cpu10
[2022-12-02T13:15:57.603] _job_complete: JobId=53384 WEXITSTATUS 0
[2022-12-02T13:15:57.604] _job_complete: JobId=53384 done
[2022-12-02T14:00:09.993] _slurm_rpc_submit_batch_job: JobId=53385 InitPrio=1000 usec=627
[2022-12-02T14:00:56.636] sched/backfill: _start_job: Started JobId=53385 in cpu-opteron on cpu10
[2022-12-02T14:00:58.038] _job_complete: JobId=53385 WEXITSTATUS 0
[2022-12-02T14:00:58.039] _job_complete: JobId=53385 done
[2022-12-02T14:12:12.375] _slurm_rpc_kill_job: REQUEST_KILL_JOB JobId=53375 uid 548300642
[2022-12-02T14:12:30.855] sched: _slurm_rpc_allocate_resources JobId=53386 NodeList=(null) usec=1398
[2022-12-02T14:17:43.252] cleanup_completing: JobId=53375 completion process took 331 seconds
[2022-12-02T14:17:43.337] sched: Allocate JobId=53386 NodeList=cpu01 #CPUs=32 Partition=cpu-opteron
[2022-12-02T14:30:11.343] _slurm_rpc_submit_batch_job: JobId=53387 InitPrio=1000 usec=524
[2022-12-02T14:30:56.688] sched/backfill: _start_job: Started JobId=53387 in cpu-opteron on cpu10
[2022-12-02T15:38:09.706] _slurm_rpc_submit_batch_job: JobId=53388 InitPrio=600 usec=447
[2022-12-02T15:39:00.674] _slurm_rpc_kill_job: REQUEST_KILL_JOB JobId=53388 uid 548200121
[2022-12-02T15:39:11.915] _slurm_rpc_submit_batch_job: JobId=53389 InitPrio=600 usec=358
[2022-12-02T15:39:56.883] sched/backfill: _start_job: Started JobId=53389 in cpu-opteron on cpu10
[2022-12-02T16:18:50.679] _slurm_rpc_kill_job: REQUEST_KILL_JOB JobId=53386 uid 548300642
[2022-12-02T16:18:55.319] sched: _slurm_rpc_allocate_resources JobId=53390 NodeList=(null) usec=775
[2022-12-02T16:23:56.552] cleanup_completing: JobId=53386 completion process took 306 seconds
[2022-12-02T16:23:56.571] sched: Allocate JobId=53390 NodeList=cpu01 #CPUs=32 Partition=cpu-opteron
[2022-12-02T16:42:18.548] _slurm_rpc_submit_batch_job: JobId=53391 InitPrio=3200 usec=569
[2022-12-02T16:42:21.624] _slurm_rpc_submit_batch_job: JobId=53392 InitPrio=3200 usec=533
[2022-12-02T16:42:26.234] _slurm_rpc_submit_batch_job: JobId=53393 InitPrio=3200 usec=441
[2022-12-02T17:05:18.514] _slurm_rpc_submit_batch_job: JobId=53394 InitPrio=13400 usec=489
[2022-12-02T17:05:18.938] sched: Allocate JobId=53394 NodeList=cpu10 #CPUs=1 Partition=cpu-opteron
[2022-12-02T17:23:58.824] Time limit exhausted for JobId=53390
[2022-12-02T17:29:04.737] cleanup_completing: JobId=53390 completion process took 306 seconds
[2022-12-02T17:29:24.946] _job_complete: JobId=53394 WEXITSTATUS 0
[2022-12-02T17:29:24.946] _job_complete: JobId=53394 done
[2022-12-02T17:30:04.125] sched: _slurm_rpc_allocate_resources JobId=53395 NodeList=(null) usec=1235
[2022-12-02T17:30:04.431] sched: Allocate JobId=53395 NodeList=cpu01 #CPUs=32 Partition=cpu-opteron
[2022-12-02T17:34:06.536] _slurm_rpc_submit_batch_job: JobId=53396 InitPrio=13400 usec=445
[2022-12-02T17:34:06.912] sched: Allocate JobId=53396 NodeList=cpu10 #CPUs=1 Partition=cpu-opteron
[2022-12-02T17:56:17.821] _job_complete: JobId=53395 WEXITSTATUS 0
[2022-12-02T17:56:17.821] _job_complete: JobId=53395 done
[2022-12-02T18:05:00.415] _job_complete: JobId=53396 WEXITSTATUS 0
[2022-12-02T18:05:00.415] _job_complete: JobId=53396 done
[2022-12-02T19:06:28.087] Time limit exhausted for JobId=53364
[2022-12-02T20:03:26.004] _job_complete: JobId=53196 WEXITSTATUS 0
[2022-12-02T20:03:26.009] _job_complete: JobId=53196 done
[2022-12-02T20:03:29.309] sched: Allocate JobId=53335 NodeList=cpu08 #CPUs=64 Partition=cpu-opteron
[2022-12-02T20:23:33.884] _slurm_rpc_submit_batch_job: JobId=53397 InitPrio=400 usec=561
[2022-12-02T20:40:39.255] _slurm_rpc_submit_batch_job: JobId=53398 InitPrio=2000 usec=487
[2022-12-02T20:41:09.633] _slurm_rpc_kill_job: REQUEST_KILL_JOB JobId=53370 uid 548300630
[2022-12-02T20:49:00.601] _slurm_rpc_submit_batch_job: JobId=53399 InitPrio=2000 usec=492
[2022-12-02T20:49:24.629] _slurm_rpc_kill_job: REQUEST_KILL_JOB JobId=53398 uid 548300630
[2022-12-03T01:24:10.006] _job_complete: JobId=53368 WEXITSTATUS 0
[2022-12-03T01:24:10.006] _job_complete: JobId=53368 done
[2022-12-03T01:24:10.789] sched: Allocate JobId=53380 NodeList=cpu12 #CPUs=8 Partition=cpu-epyc
[2022-12-03T01:24:10.790] sched: Allocate JobId=53381 NodeList=cpu12 #CPUs=8 Partition=cpu-epyc
[2022-12-03T02:39:16.913] _job_complete: JobId=53387 WEXITSTATUS 1
[2022-12-03T02:39:16.914] _job_complete: JobId=53387 done
[2022-12-03T04:30:39.604] _job_complete: JobId=53306 WEXITSTATUS 1
[2022-12-03T04:30:39.604] _job_complete: JobId=53306 done
[2022-12-03T04:30:41.743] sched: Allocate JobId=53336 NodeList=cpu03 #CPUs=64 Partition=cpu-opteron
[2022-12-03T09:48:04.768] _slurm_rpc_submit_batch_job: JobId=53400 InitPrio=3400 usec=573
[2022-12-03T09:48:05.328] sched: Allocate JobId=53400 NodeList=cpu01 #CPUs=1 Partition=cpu-opteron
[2022-12-03T11:42:42.428] _job_complete: JobId=53338 WEXITSTATUS 0
[2022-12-03T11:42:42.434] _job_complete: JobId=53338 done
[2022-12-03T12:30:15.702] _job_complete: JobId=53400 WEXITSTATUS 0
[2022-12-03T12:30:15.702] _job_complete: JobId=53400 done
[2022-12-03T14:42:00.989] _job_complete: JobId=53381 WEXITSTATUS 0
[2022-12-03T14:42:00.989] _job_complete: JobId=53381 done
[2022-12-03T14:42:01.555] sched: Allocate JobId=53382 NodeList=cpu12 #CPUs=8 Partition=cpu-epyc
[2022-12-03T15:20:31.483] _job_complete: JobId=53380 WEXITSTATUS 0
[2022-12-03T15:20:31.483] _job_complete: JobId=53380 done
[2022-12-03T15:20:32.030] sched: Allocate JobId=53383 NodeList=cpu12 #CPUs=8 Partition=cpu-epyc
[2022-12-03T17:41:17.945] _job_complete: JobId=53313 WEXITSTATUS 1
[2022-12-03T17:41:17.945] _job_complete: JobId=53313 done
[2022-12-03T17:41:18.500] sched: Allocate JobId=53354 NodeList=cpu01 #CPUs=64 Partition=cpu-opteron
[2022-12-03T18:39:01.049] _slurm_rpc_kill_job: REQUEST_KILL_JOB JobId=53333 uid 548300621
[2022-12-03T18:39:01.884] _slurm_rpc_kill_job: REQUEST_KILL_JOB JobId=53333 uid 548300621
[2022-12-03T18:39:07.085] _slurm_rpc_kill_job: REQUEST_KILL_JOB JobId=53334 uid 548300621
[2022-12-03T18:39:08.341] _slurm_rpc_kill_job: REQUEST_KILL_JOB JobId=53334 uid 548300621
[2022-12-03T18:39:11.904] _slurm_rpc_submit_batch_job: JobId=53401 InitPrio=200 usec=629
[2022-12-03T18:39:15.951] _slurm_rpc_submit_batch_job: JobId=53402 InitPrio=200 usec=492
[2022-12-03T18:39:32.300] sched: Allocate JobId=53372 NodeList=cpu04 #CPUs=64 Partition=cpu-opteron
[2022-12-03T18:39:49.348] sched: Allocate JobId=53397 NodeList=cpu09 #CPUs=64 Partition=cpu-opteron
[2022-12-03T19:45:11.203] _slurm_rpc_submit_batch_job: JobId=53403 InitPrio=12200 usec=564
[2022-12-03T19:45:37.216] _slurm_rpc_kill_job: REQUEST_KILL_JOB JobId=53403 uid 548300630
[2022-12-03T19:47:02.064] _pick_best_nodes: JobId=53404 never runnable in partition cpu-opteron
[2022-12-03T19:47:02.064] _slurm_rpc_submit_batch_job: Requested node configuration is not available
[2022-12-03T19:47:37.540] _slurm_rpc_submit_batch_job: JobId=53405 InitPrio=12200 usec=514
[2022-12-03T19:47:37.648] sched: Allocate JobId=53405 NodeList=cpu10 #CPUs=8 Partition=cpu-opteron
[2022-12-03T19:47:46.261] _job_complete: JobId=53405 WEXITSTATUS 0
[2022-12-03T19:47:46.262] _job_complete: JobId=53405 done
[2022-12-03T19:53:47.354] _slurm_rpc_submit_batch_job: JobId=53406 InitPrio=2200 usec=550
[2022-12-04T04:04:08.985] _job_complete: JobId=53382 WEXITSTATUS 0
[2022-12-04T04:04:08.985] _job_complete: JobId=53382 done
[2022-12-04T04:04:09.657] sched: Allocate JobId=53391 NodeList=cpu12 #CPUs=8 Partition=cpu-epyc
[2022-12-04T04:28:51.034] _job_complete: JobId=53315 WEXITSTATUS 0
[2022-12-04T04:28:51.041] _job_complete: JobId=53315 done
[2022-12-04T04:44:32.968] _job_complete: JobId=53383 WEXITSTATUS 0
[2022-12-04T04:44:32.969] _job_complete: JobId=53383 done
[2022-12-04T04:44:33.577] sched: Allocate JobId=53392 NodeList=cpu12 #CPUs=8 Partition=cpu-epyc
[2022-12-04T07:05:54.038] _slurm_rpc_submit_batch_job: JobId=53407 InitPrio=1200 usec=1092
[2022-12-04T07:08:06.536] _slurm_rpc_kill_job: REQUEST_KILL_JOB JobId=53407 uid 548200029
[2022-12-04T07:17:07.339] _slurm_rpc_submit_batch_job: JobId=53408 InitPrio=1200 usec=820
[2022-12-04T07:18:48.761] _slurm_rpc_submit_batch_job: JobId=53409 InitPrio=1200 usec=776
[2022-12-04T07:21:12.047] _slurm_rpc_kill_job: REQUEST_KILL_JOB JobId=52922 uid 548200029
[2022-12-04T07:21:14.474] sched: Allocate JobId=53323 NodeList=gpu02 #CPUs=8 Partition=gpu-titan
[2022-12-04T07:23:04.938] _slurm_rpc_submit_batch_job: JobId=53410 InitPrio=1200 usec=1185
[2022-12-04T07:26:24.479] _slurm_rpc_submit_batch_job: JobId=53411 InitPrio=1200 usec=874
[2022-12-04T07:29:07.290] _slurm_rpc_kill_job: REQUEST_KILL_JOB JobId=53410 uid 548200029
[2022-12-04T07:30:17.206] _slurm_rpc_submit_batch_job: JobId=53412 InitPrio=1200 usec=1093
[2022-12-04T07:32:55.726] _slurm_rpc_kill_job: REQUEST_KILL_JOB JobId=53411 uid 548200029
[2022-12-04T07:33:02.728] _pick_best_nodes: JobId=53413 never runnable in partition gpu-k40c
[2022-12-04T07:33:02.729] _slurm_rpc_submit_batch_job: Requested node configuration is not available
[2022-12-04T07:33:22.322] _slurm_rpc_submit_batch_job: JobId=53414 InitPrio=1200 usec=840
[2022-12-04T07:41:10.657] _job_complete: JobId=53323 WEXITSTATUS 1
[2022-12-04T07:41:10.658] _job_complete: JobId=53323 done
[2022-12-04T07:41:11.414] sched: Allocate JobId=53349 NodeList=gpu02 #CPUs=8 Partition=gpu-titan
[2022-12-04T07:41:11.415] sched: Allocate JobId=53350 NodeList=gpu02 #CPUs=8 Partition=gpu-titan
[2022-12-04T08:35:06.334] sched: _update_job: setting time_limit to 43200 for JobId=53309
[2022-12-04T08:35:06.334] _update_job: updating accounting
[2022-12-04T08:35:06.334] _slurm_rpc_update_job: complete JobId=53309 uid=548200003 usec=1090
[2022-12-04T14:03:20.639] _job_complete: JobId=53354 WEXITSTATUS 0
[2022-12-04T14:03:20.645] _job_complete: JobId=53354 done
[2022-12-04T14:03:23.826] sched: Allocate JobId=53406 NodeList=cpu01 #CPUs=32 Partition=cpu-opteron
[2022-12-04T14:19:39.244] _slurm_rpc_submit_batch_job: JobId=53415 InitPrio=400 usec=522
[2022-12-04T14:20:01.172] _job_complete: JobId=53391 WEXITSTATUS 0
[2022-12-04T14:20:01.172] _job_complete: JobId=53391 done
[2022-12-04T14:20:01.869] sched: Allocate JobId=53393 NodeList=cpu12 #CPUs=8 Partition=cpu-epyc
[2022-12-04T15:28:39.328] _job_complete: JobId=53392 WEXITSTATUS 0
[2022-12-04T15:28:39.329] _job_complete: JobId=53392 done
[2022-12-04T22:21:25.045] _job_complete: JobId=53372 WEXITSTATUS 0
[2022-12-04T22:21:25.050] _job_complete: JobId=53372 done
[2022-12-04T22:21:28.313] sched: Allocate JobId=53401 NodeList=cpu04 #CPUs=64 Partition=cpu-opteron
[2022-12-05T00:17:45.988] _job_complete: JobId=53393 WEXITSTATUS 0
[2022-12-05T00:17:45.989] _job_complete: JobId=53393 done
[2022-12-05T00:17:46.581] sched: Allocate JobId=53399 NodeList=cpu12 #CPUs=24 Partition=cpu-epyc
[2022-12-05T08:14:31.238] _slurm_rpc_submit_batch_job: JobId=53416 InitPrio=3400 usec=585
[2022-12-05T08:14:31.664] sched: Allocate JobId=53416 NodeList=cpu07 #CPUs=1 Partition=cpu-opteron
[2022-12-05T08:23:08.272] _slurm_rpc_kill_job: REQUEST_KILL_JOB JobId=53389 uid 0
[2022-12-05T08:34:40.733] _slurm_rpc_submit_batch_job: JobId=53417 InitPrio=400 usec=499
[2022-12-05T09:11:11.557] _job_complete: JobId=53324 WEXITSTATUS 0
[2022-12-05T09:11:11.562] _job_complete: JobId=53324 done
[2022-12-05T09:11:14.060] sched: Allocate JobId=53325 NodeList=gpu01 #CPUs=16 Partition=gpu-k10
[2022-12-05T09:11:43.705] _slurm_rpc_kill_job: REQUEST_KILL_JOB JobId=53339 uid 548200003
[2022-12-05T09:11:43.705] _slurm_rpc_kill_job: REQUEST_KILL_JOB JobId=53327 uid 548200003
[2022-12-05T09:11:59.778] _slurm_rpc_delete_reservation complete for cpu11_memtest usec=165
[2022-12-05T09:12:00.331] sched: Allocate JobId=53402 NodeList=cpu11 #CPUs=64 Partition=cpu-opteron
[2022-12-05T10:28:32.592] _job_complete: JobId=53325 WEXITSTATUS 1
[2022-12-05T10:28:32.593] _job_complete: JobId=53325 done
[2022-12-05T10:28:33.798] sched: Allocate JobId=53360 NodeList=gpu01 #CPUs=8 Partition=gpu-k10
[2022-12-05T11:10:14.439] _slurm_rpc_kill_job: REQUEST_KILL_JOB JobId=53360 uid 548200121
[2022-12-05T11:10:17.066] sched: Allocate JobId=53412 NodeList=gpu01 #CPUs=16 Partition=gpu-k10
[2022-12-05T11:26:52.823] _slurm_rpc_submit_batch_job: JobId=53418 InitPrio=1000 usec=607
[2022-12-05T11:27:03.967] sched/backfill: _start_job: Started JobId=53418 in cpu-opteron on cpu01
[2022-12-05T11:56:22.410] _job_complete: JobId=53418 WEXITSTATUS 0
[2022-12-05T11:56:22.410] _job_complete: JobId=53418 done
[2022-12-05T12:02:41.944] _slurm_rpc_submit_batch_job: JobId=53419 InitPrio=1000 usec=572
[2022-12-05T12:03:04.009] sched/backfill: _start_job: Started JobId=53419 in cpu-opteron on cpu01
[2022-12-05T12:03:05.670] _job_complete: JobId=53419 WEXITSTATUS 0
[2022-12-05T12:03:05.670] _job_complete: JobId=53419 done
[2022-12-05T12:16:33.236] _slurm_rpc_submit_batch_job: JobId=53420 InitPrio=1000 usec=502
[2022-12-05T12:17:04.026] sched/backfill: _start_job: Started JobId=53420 in cpu-opteron on cpu01
[2022-12-05T12:19:24.169] _slurm_rpc_submit_batch_job: JobId=53421 InitPrio=600 usec=436
[2022-12-05T12:19:48.282] _slurm_rpc_kill_job: REQUEST_KILL_JOB JobId=53421 uid 548200121
[2022-12-05T12:32:17.468] _job_complete: JobId=53195 WEXITSTATUS 0
[2022-12-05T12:32:17.474] _job_complete: JobId=53195 done
[2022-12-05T12:32:18.395] sched: Allocate JobId=53366 NodeList=cpu15 #CPUs=48 Partition=cpu-epyc
[2022-12-05T13:00:57.260] _slurm_rpc_submit_batch_job: JobId=53422 InitPrio=400 usec=562
[2022-12-05T13:35:14.624] sched: Created reservation=gpu04_test users=jitkang nodes=gpu04 cores=16 licenses=(null) tres=cpu=32 watts=4294967294 start=2022-12-05T13:35:14 end=2023-12-05T13:35:14 MaxStartDelay=
[2022-12-05T13:55:58.834] _slurm_rpc_delete_reservation complete for gpu04_test usec=93
[2022-12-05T14:33:59.913] _slurm_rpc_submit_batch_job: JobId=53423 InitPrio=2800 usec=548
[2022-12-05T14:34:59.523] _slurm_rpc_submit_batch_job: JobId=53424 InitPrio=2800 usec=616
[2022-12-05T14:36:46.839] _slurm_rpc_submit_batch_job: JobId=53425 InitPrio=14600 usec=395
[2022-12-05T14:36:47.067] sched: Allocate JobId=53425 NodeList=cpu01 #CPUs=10 Partition=cpu-opteron
[2022-12-05T14:37:26.786] _job_complete: JobId=53425 WEXITSTATUS 1
[2022-12-05T14:37:26.786] _job_complete: JobId=53425 done
[2022-12-05T14:41:01.627] _slurm_rpc_submit_batch_job: JobId=53426 InitPrio=14600 usec=456
[2022-12-05T14:41:02.448] sched: Allocate JobId=53426 NodeList=cpu01 #CPUs=10 Partition=cpu-opteron
[2022-12-05T14:41:08.288] _job_complete: JobId=53426 WEXITSTATUS 1
[2022-12-05T14:41:08.288] _job_complete: JobId=53426 done
[2022-12-05T14:49:29.635] _slurm_rpc_submit_batch_job: JobId=53427 InitPrio=14600 usec=564
[2022-12-05T14:49:30.373] sched: Allocate JobId=53427 NodeList=cpu01 #CPUs=10 Partition=cpu-opteron
[2022-12-05T14:51:16.776] _slurm_rpc_submit_batch_job: JobId=53428 InitPrio=10400 usec=472
[2022-12-05T14:51:17.621] sched: Allocate JobId=53428 NodeList=cpu10 #CPUs=8 Partition=cpu-opteron
[2022-12-05T14:51:54.897] _job_complete: JobId=53428 WEXITSTATUS 0
[2022-12-05T14:51:54.898] _job_complete: JobId=53428 done
[2022-12-05T14:58:05.017] _job_complete: JobId=53427 WEXITSTATUS 0
[2022-12-05T14:58:05.018] _job_complete: JobId=53427 done
[2022-12-05T15:08:29.326] _slurm_rpc_submit_batch_job: JobId=53429 InitPrio=400 usec=643
[2022-12-05T15:09:02.178] _slurm_rpc_kill_job: REQUEST_KILL_JOB JobId=53429 uid 548200017
[2022-12-05T15:09:16.724] _slurm_rpc_submit_batch_job: JobId=53430 InitPrio=400 usec=501
[2022-12-05T15:09:45.064] _slurm_rpc_kill_job: REQUEST_KILL_JOB JobId=53430 uid 548200017
[2022-12-05T15:10:39.361] _slurm_rpc_submit_batch_job: JobId=53431 InitPrio=400 usec=628
[2022-12-05T15:26:33.038] _slurm_rpc_kill_job: REQUEST_KILL_JOB JobId=53431 uid 548200017
[2022-12-05T15:26:58.553] _slurm_rpc_submit_batch_job: JobId=53432 InitPrio=400 usec=483
[2022-12-05T15:38:51.796] _slurm_rpc_submit_batch_job: JobId=53433 InitPrio=2200 usec=562
[2022-12-05T15:44:57.057] _slurm_rpc_kill_job: REQUEST_KILL_JOB JobId=53433 uid 548300630
[2022-12-05T15:45:05.472] _slurm_rpc_submit_batch_job: JobId=53434 InitPrio=12000 usec=456
[2022-12-05T15:45:07.026] sched: Allocate JobId=53434 NodeList=cpu07 #CPUs=1 Partition=cpu-opteron
[2022-12-05T15:45:21.706] _slurm_rpc_kill_job: REQUEST_KILL_JOB JobId=53434 uid 548200003
[2022-12-05T15:49:06.152] _slurm_rpc_submit_batch_job: JobId=53435 InitPrio=12000 usec=411
[2022-12-05T15:49:07.473] sched: Allocate JobId=53435 NodeList=cpu01 #CPUs=1 Partition=cpu-opteron
[2022-12-05T15:49:09.233] _slurm_rpc_kill_job: REQUEST_KILL_JOB JobId=53435 uid 548200003
[2022-12-05T15:51:41.891] _slurm_rpc_submit_batch_job: JobId=53436 InitPrio=4600 usec=451
[2022-12-05T15:51:42.800] sched: Allocate JobId=53436 NodeList=cpu10 #CPUs=20 Partition=cpu-opteron
[2022-12-05T15:55:25.743] _slurm_rpc_submit_batch_job: JobId=53437 InitPrio=12000 usec=408
[2022-12-05T15:55:42.934] _slurm_rpc_kill_job: REQUEST_KILL_JOB JobId=53437 uid 548200003
[2022-12-05T15:58:24.935] _slurm_rpc_submit_batch_job: JobId=53438 InitPrio=2200 usec=512
[2022-12-05T15:58:25.505] sched: Allocate JobId=53438 NodeList=cpu07 #CPUs=16 Partition=cpu-opteron
[2022-12-05T15:58:57.096] _slurm_rpc_submit_batch_job: JobId=53439 InitPrio=2200 usec=470
[2022-12-05T15:59:47.843] _slurm_rpc_submit_batch_job: JobId=53440 InitPrio=2200 usec=435
[2022-12-05T16:00:21.363] _slurm_rpc_submit_batch_job: JobId=53441 InitPrio=4600 usec=431
[2022-12-05T16:00:21.639] sched: Allocate JobId=53441 NodeList=cpu07 #CPUs=20 Partition=cpu-opteron
[2022-12-05T16:00:36.775] _slurm_rpc_submit_batch_job: JobId=53442 InitPrio=2200 usec=510
[2022-12-05T16:01:59.994] _slurm_rpc_kill_job: REQUEST_KILL_JOB JobId=53439 uid 548300630
[2022-12-05T16:02:06.872] _slurm_rpc_kill_job: REQUEST_KILL_JOB JobId=53440 uid 548300630
[2022-12-05T16:02:48.255] _slurm_rpc_submit_batch_job: JobId=53443 InitPrio=2200 usec=470
[2022-12-05T16:09:46.602] _slurm_rpc_kill_job: REQUEST_KILL_JOB JobId=53443 uid 548300630
[2022-12-05T16:09:59.836] _slurm_rpc_submit_batch_job: JobId=53444 InitPrio=2200 usec=528
[2022-12-05T16:18:17.108] _update_job: setting QOS to short for JobId=53352
[2022-12-05T16:18:17.108] _update_job: updating accounting
[2022-12-05T16:18:17.108] _slurm_rpc_update_job: complete JobId=53352 uid=548200003 usec=896
[2022-12-05T16:18:31.809] sched: _update_job: setting time_limit to 1440 for JobId=53352
[2022-12-05T16:18:31.809] _update_job: updating accounting
[2022-12-05T16:18:31.809] _slurm_rpc_update_job: complete JobId=53352 uid=548200003 usec=847
[2022-12-05T16:18:44.869] sched: _update_job: setting time_limit to 1 for JobId=53352
[2022-12-05T16:18:44.869] _update_job: updating accounting
[2022-12-05T16:18:44.869] _slurm_rpc_update_job: complete JobId=53352 uid=548200003 usec=735
[2022-12-05T16:18:51.125] sched: _update_job: setting time_limit to 60 for JobId=53352
[2022-12-05T16:18:51.125] _update_job: updating accounting
[2022-12-05T16:18:51.126] _slurm_rpc_update_job: complete JobId=53352 uid=548200003 usec=917
[2022-12-05T16:19:02.843] _update_job: setting QOS to short for JobId=52498
[2022-12-05T16:19:02.843] sched: _update_job: setting time_limit to 60 for JobId=52498
[2022-12-05T16:19:02.843] _update_job: updating accounting
[2022-12-05T16:19:02.843] _slurm_rpc_update_job: complete JobId=52498 uid=548200003 usec=1000
[2022-12-05T16:19:12.805] _update_job: setting QOS to short for JobId=53314
[2022-12-05T16:19:12.805] sched: _update_job: setting time_limit to 60 for JobId=53314
[2022-12-05T16:19:12.805] _update_job: updating accounting
[2022-12-05T16:19:12.805] _slurm_rpc_update_job: complete JobId=53314 uid=548200003 usec=854
[2022-12-05T16:19:17.467] _update_job: setting QOS to short for JobId=53178
[2022-12-05T16:19:17.467] sched: _update_job: setting time_limit to 60 for JobId=53178
[2022-12-05T16:19:17.467] _update_job: updating accounting
[2022-12-05T16:19:17.467] _slurm_rpc_update_job: complete JobId=53178 uid=548200003 usec=794
[2022-12-05T16:19:48.974] _update_job: setting QOS to short for JobId=53351
[2022-12-05T16:19:48.974] sched: _update_job: setting time_limit to 60 for JobId=53351
[2022-12-05T16:19:48.974] _update_job: updating accounting
[2022-12-05T16:19:48.974] _slurm_rpc_update_job: complete JobId=53351 uid=548200003 usec=1169
[2022-12-05T16:19:52.896] _update_job: setting QOS to short for JobId=53358
[2022-12-05T16:19:52.896] sched: _update_job: setting time_limit to 60 for JobId=53358
[2022-12-05T16:19:52.896] _update_job: updating accounting
[2022-12-05T16:19:52.897] _slurm_rpc_update_job: complete JobId=53358 uid=548200003 usec=1123
[2022-12-05T16:23:50.898] _slurm_rpc_submit_batch_job: JobId=53445 InitPrio=12000 usec=456
[2022-12-05T16:23:51.227] sched: Allocate JobId=53445 NodeList=cpu07 #CPUs=1 Partition=cpu-opteron
[2022-12-05T16:24:19.631] _slurm_rpc_kill_job: REQUEST_KILL_JOB JobId=53445 uid 548200003
[2022-12-05T16:28:12.628] _slurm_rpc_submit_batch_job: JobId=53446 InitPrio=10600 usec=377
[2022-12-05T16:28:12.708] sched: Allocate JobId=53446 NodeList=cpu10 #CPUs=2 Partition=cpu-opteron
[2022-12-05T16:28:20.626] _slurm_rpc_kill_job: REQUEST_KILL_JOB JobId=53446 uid 548200121
[2022-12-05T17:28:51.172] _job_complete: JobId=53416 WEXITSTATUS 0
[2022-12-05T17:28:51.172] _job_complete: JobId=53416 done
[2022-12-05T17:28:52.571] sched: Allocate JobId=53442 NodeList=cpu07 #CPUs=16 Partition=cpu-opteron
[2022-12-05T20:10:04.369] _job_complete: JobId=53406 WEXITSTATUS 0
[2022-12-05T20:10:04.369] _job_complete: JobId=53406 done
[2022-12-05T23:38:25.353] _job_complete: JobId=53420 WEXITSTATUS 1
[2022-12-05T23:38:25.354] _job_complete: JobId=53420 done
[2022-12-05T23:38:26.033] sched: Allocate JobId=53415 NodeList=cpu01 #CPUs=64 Partition=cpu-opteron
[2022-12-06T08:16:31.677] _slurm_rpc_submit_batch_job: JobId=53447 InitPrio=13400 usec=486
[2022-12-06T08:16:31.734] sched: Allocate JobId=53447 NodeList=cpu10 #CPUs=1 Partition=cpu-opteron
[2022-12-06T08:31:59.229] _job_complete: JobId=53447 WEXITSTATUS 0
[2022-12-06T08:31:59.229] _job_complete: JobId=53447 done
[2022-12-06T08:32:52.404] _slurm_rpc_submit_batch_job: JobId=53448 InitPrio=13400 usec=485
[2022-12-06T08:32:53.369] sched: Allocate JobId=53448 NodeList=cpu10 #CPUs=1 Partition=cpu-opteron
[2022-12-06T09:14:03.779] sched: _slurm_rpc_allocate_resources JobId=53449 NodeList=(null) usec=991
[2022-12-06T09:14:04.712] sched: Allocate JobId=53449 NodeList=cpu10 #CPUs=1 Partition=cpu-opteron
[2022-12-06T09:29:02.735] _job_complete: JobId=53449 WEXITSTATUS 0
[2022-12-06T09:29:02.735] _job_complete: JobId=53449 done
[2022-12-06T09:32:58.967] _job_complete: JobId=53448 WEXITSTATUS 0
[2022-12-06T09:32:58.967] _job_complete: JobId=53448 done
[2022-12-06T09:47:09.630] _slurm_rpc_submit_batch_job: JobId=53450 InitPrio=13400 usec=623
[2022-12-06T09:47:10.300] sched: Allocate JobId=53450 NodeList=cpu10 #CPUs=1 Partition=cpu-opteron
[2022-12-06T10:15:06.799] _job_complete: JobId=53450 WEXITSTATUS 0
[2022-12-06T10:15:06.800] _job_complete: JobId=53450 done
[2022-12-06T10:27:48.026] _job_complete: JobId=53240 WEXITSTATUS 0
[2022-12-06T10:27:48.026] _job_complete: JobId=53240 done
[2022-12-06T10:27:50.184] sched: Allocate JobId=53241 NodeList=gpu03 #CPUs=16 Partition=gpu-k10
[2022-12-06T10:48:16.882] _slurm_rpc_kill_job: REQUEST_KILL_JOB JobId=52584 uid 548200003
[2022-12-06T10:48:27.103] sched: Allocate JobId=52777 NodeList=gpu05 #CPUs=16 Partition=gpu-v100s
[2022-12-06T10:48:27.122] sched: Allocate JobId=53178 NodeList=gpu05 #CPUs=8 Partition=gpu-v100s
[2022-12-06T11:04:21.743] _slurm_rpc_submit_batch_job: JobId=53451 InitPrio=1000 usec=549
[2022-12-06T11:48:35.991] Time limit exhausted for JobId=53178
[2022-12-06T11:49:06.568] sched/backfill: _start_job: Started JobId=53352 in gpu-v100s on gpu05
[2022-12-06T12:31:58.539] _slurm_rpc_kill_job: REQUEST_KILL_JOB JobId=53358 uid 548200121
[2022-12-06T12:32:11.273] _slurm_rpc_submit_batch_job: JobId=53452 InitPrio=10600 usec=750
[2022-12-06T12:32:19.794] _slurm_rpc_kill_job: REQUEST_KILL_JOB JobId=53452 uid 548200121
[2022-12-06T12:32:35.142] _slurm_rpc_submit_batch_job: JobId=53453 InitPrio=10600 usec=335
[2022-12-06T12:32:44.307] _slurm_rpc_kill_job: REQUEST_KILL_JOB JobId=53453 uid 548200121
[2022-12-06T12:33:29.991] _slurm_rpc_kill_job: REQUEST_KILL_JOB JobId=53352 uid 548200121
[2022-12-06T12:34:06.671] sched/backfill: _start_job: Started JobId=53371 in gpu-v100s on gpu05
[2022-12-06T12:38:36.629] _slurm_rpc_submit_batch_job: JobId=53454 InitPrio=600 usec=677
[2022-12-06T12:38:50.155] _slurm_rpc_submit_batch_job: JobId=53455 InitPrio=600 usec=743
[2022-12-06T12:39:21.343] _slurm_rpc_submit_batch_job: JobId=53456 InitPrio=600 usec=640
[2022-12-06T12:39:34.724] _slurm_rpc_submit_batch_job: JobId=53457 InitPrio=600 usec=558
[2022-12-06T12:39:44.523] _slurm_rpc_submit_batch_job: JobId=53458 InitPrio=600 usec=703
[2022-12-06T12:40:00.903] _slurm_rpc_kill_job: REQUEST_KILL_JOB JobId=53351 uid 548200121
[2022-12-06T12:40:05.895] _slurm_rpc_kill_job: REQUEST_KILL_JOB JobId=53314 uid 548200121
[2022-12-06T12:40:10.195] _slurm_rpc_kill_job: REQUEST_KILL_JOB JobId=52498 uid 548200121
[2022-12-06T13:24:51.269] _slurm_rpc_submit_batch_job: JobId=53459 InitPrio=600 usec=390
[2022-12-06T13:25:15.870] _slurm_rpc_submit_batch_job: JobId=53460 InitPrio=600 usec=365
[2022-12-06T13:40:42.571] error: Invalid qos (long;--job-name=JupLab)
[2022-12-06T13:40:42.571] _slurm_rpc_submit_batch_job: Invalid qos specification
[2022-12-06T13:41:03.056] error: Invalid qos (long,--job-name=Jup)
[2022-12-06T13:41:03.057] _slurm_rpc_submit_batch_job: Invalid qos specification
[2022-12-06T13:41:11.052] _slurm_rpc_submit_batch_job: JobId=53461 InitPrio=600 usec=307
[2022-12-06T14:03:46.336] _update_job: setting QOS to short for JobId=53460
[2022-12-06T14:03:46.337] sched: _update_job: setting time_limit to 60 for JobId=53460
[2022-12-06T14:03:46.337] _update_job: updating accounting
[2022-12-06T14:03:46.337] _slurm_rpc_update_job: complete JobId=53460 uid=548200003 usec=1117
[2022-12-06T14:03:55.985] _update_job: setting QOS to short for JobId=53461
[2022-12-06T14:03:55.985] sched: _update_job: setting time_limit to 60 for JobId=53461
[2022-12-06T14:03:55.985] _update_job: updating accounting
[2022-12-06T14:03:55.985] _slurm_rpc_update_job: complete JobId=53461 uid=548200003 usec=983
[2022-12-06T14:04:05.433] _update_job: setting QOS to short for JobId=53459
[2022-12-06T14:04:05.433] sched: _update_job: setting time_limit to 60 for JobId=53459
[2022-12-06T14:04:05.434] _update_job: updating accounting
[2022-12-06T14:04:05.434] _slurm_rpc_update_job: complete JobId=53459 uid=548200003 usec=1032
[2022-12-06T14:06:25.441] _update_job: setting QOS to normal for JobId=53459
[2022-12-06T14:06:25.441] _update_job: updating accounting
[2022-12-06T14:06:25.441] _slurm_rpc_update_job: complete JobId=53459 uid=548200003 usec=1046
[2022-12-06T14:06:28.521] _update_job: setting QOS to normal for JobId=53460
[2022-12-06T14:06:28.521] _update_job: updating accounting
[2022-12-06T14:06:28.522] _slurm_rpc_update_job: complete JobId=53460 uid=548200003 usec=1087
[2022-12-06T14:06:31.038] _update_job: setting QOS to normal for JobId=53461
[2022-12-06T14:06:31.038] _update_job: updating accounting
[2022-12-06T14:06:31.039] _slurm_rpc_update_job: complete JobId=53461 uid=548200003 usec=1256
[2022-12-06T14:07:13.697] _update_job: setting QOS to normal for JobId=53456
[2022-12-06T14:07:13.697] sched: _update_job: setting time_limit to 60 for JobId=53456
[2022-12-06T14:07:13.697] _update_job: updating accounting
[2022-12-06T14:07:13.697] _slurm_rpc_update_job: complete JobId=53456 uid=548200003 usec=1120
[2022-12-06T14:07:16.154] _update_job: setting QOS to normal for JobId=53457
[2022-12-06T14:07:16.154] sched: _update_job: setting time_limit to 60 for JobId=53457
[2022-12-06T14:07:16.154] _update_job: updating accounting
[2022-12-06T14:07:16.154] _slurm_rpc_update_job: complete JobId=53457 uid=548200003 usec=867
[2022-12-06T14:07:18.671] _update_job: setting QOS to normal for JobId=53458
[2022-12-06T14:07:18.671] sched: _update_job: setting time_limit to 60 for JobId=53458
[2022-12-06T14:07:18.671] _update_job: updating accounting
[2022-12-06T14:07:18.671] _slurm_rpc_update_job: complete JobId=53458 uid=548200003 usec=646
[2022-12-06T14:07:23.177] _update_job: setting QOS to normal for JobId=53454
[2022-12-06T14:07:23.177] sched: _update_job: setting time_limit to 60 for JobId=53454
[2022-12-06T14:07:23.177] _update_job: updating accounting
[2022-12-06T14:07:23.177] _slurm_rpc_update_job: complete JobId=53454 uid=548200003 usec=868
[2022-12-06T14:07:25.750] _update_job: setting QOS to normal for JobId=53455
[2022-12-06T14:07:25.750] sched: _update_job: setting time_limit to 60 for JobId=53455
[2022-12-06T14:07:25.750] _update_job: updating accounting
[2022-12-06T14:07:25.751] _slurm_rpc_update_job: complete JobId=53455 uid=548200003 usec=943
[2022-12-06T14:47:01.595] _job_complete: JobId=53241 WEXITSTATUS 1
[2022-12-06T14:47:01.595] _job_complete: JobId=53241 done
[2022-12-06T14:47:02.163] sched: Allocate JobId=53414 NodeList=gpu03 #CPUs=16 Partition=gpu-k10
[2022-12-06T15:00:31.945] _job_complete: JobId=53366 WEXITSTATUS 0
[2022-12-06T15:00:31.945] _job_complete: JobId=53366 done
[2022-12-06T15:00:32.337] sched: Allocate JobId=53444 NodeList=cpu15 #CPUs=24 Partition=cpu-epyc
[2022-12-06T15:00:32.352] sched: Allocate JobId=53422 NodeList=cpu15 #CPUs=24 Partition=cpu-epyc
[2022-12-06T15:34:45.216] _slurm_rpc_submit_batch_job: JobId=53462 InitPrio=9200 usec=401
[2022-12-06T15:39:41.482] _slurm_rpc_kill_job: REQUEST_KILL_JOB JobId=53462 uid 548300513
[2022-12-06T15:52:06.365] Time limit exhausted for JobId=53436
[2022-12-06T16:00:36.480] Time limit exhausted for JobId=53441
[2022-12-06T16:01:07.014] sched/backfill: _start_job: Started JobId=53451 in cpu-opteron on cpu07
[2022-12-06T16:04:51.972] _job_complete: JobId=53414 WEXITSTATUS 1
[2022-12-06T16:04:51.974] _job_complete: JobId=53414 done
[2022-12-06T16:20:12.203] _job_complete: JobId=53444 WEXITSTATUS 0
[2022-12-06T16:20:12.204] _job_complete: JobId=53444 done
[2022-12-06T16:31:29.425] _job_complete: JobId=53451 WEXITSTATUS 0
[2022-12-06T16:31:29.425] _job_complete: JobId=53451 done
[2022-12-06T16:53:40.438] _job_complete: JobId=53371 WEXITSTATUS 0
[2022-12-06T16:53:40.444] _job_complete: JobId=53371 done
[2022-12-06T16:53:41.579] sched: Allocate JobId=53220 NodeList=gpu05 #CPUs=16 Partition=gpu-v100s
[2022-12-06T18:25:36.541] Time limit exhausted for JobId=53238
[2022-12-06T18:25:40.915] sched: Allocate JobId=53417 NodeList=cpu10 #CPUs=64 Partition=cpu-opteron
[2022-12-06T18:35:52.730] _slurm_rpc_submit_batch_job: JobId=53463 InitPrio=4200 usec=623
[2022-12-06T18:46:07.489] _slurm_rpc_kill_job: REQUEST_KILL_JOB JobId=53336 uid 548300621
[2022-12-06T18:46:08.689] _slurm_rpc_kill_job: REQUEST_KILL_JOB JobId=53336 uid 548300621
[2022-12-06T18:46:12.578] _slurm_rpc_submit_batch_job: JobId=53464 InitPrio=200 usec=520
[2022-12-06T18:46:48.580] sched: Allocate JobId=53432 NodeList=cpu03 #CPUs=64 Partition=cpu-opteron
[2022-12-06T18:46:53.006] _job_complete: JobId=53432 WEXITSTATUS 2
[2022-12-06T18:46:53.006] _job_complete: JobId=53432 done
[2022-12-06T18:46:53.570] sched: Allocate JobId=53464 NodeList=cpu03 #CPUs=64 Partition=cpu-opteron
[2022-12-06T18:52:25.340] _job_complete: JobId=53335 WEXITSTATUS 0
[2022-12-06T18:52:25.340] _job_complete: JobId=53335 done
[2022-12-06T18:53:26.133] _slurm_rpc_submit_batch_job: JobId=53465 InitPrio=200 usec=497
[2022-12-06T19:11:29.442] _slurm_rpc_submit_batch_job: JobId=53466 InitPrio=400 usec=532
[2022-12-06T19:11:29.547] sched: Allocate JobId=53466 NodeList=cpu08 #CPUs=64 Partition=cpu-opteron
[2022-12-06T19:24:08.309] _job_complete: JobId=53466 OOM failure
[2022-12-06T19:24:08.309] _job_complete: JobId=53466 done
[2022-12-06T19:37:18.859] _slurm_rpc_submit_batch_job: JobId=53467 InitPrio=400 usec=489
[2022-12-06T19:37:19.069] sched: Allocate JobId=53467 NodeList=cpu08 #CPUs=64 Partition=cpu-opteron
[2022-12-06T19:49:59.795] _job_complete: JobId=53467 OOM failure
[2022-12-06T19:49:59.796] _job_complete: JobId=53467 done
[2022-12-06T20:08:51.878] _slurm_rpc_top_job for 53459 Access/permission denied
[2022-12-06T20:58:32.293] _slurm_rpc_submit_batch_job: JobId=53468 InitPrio=400 usec=490
[2022-12-06T20:58:32.879] sched: Allocate JobId=53468 NodeList=cpu08 #CPUs=64 Partition=cpu-opteron
[2022-12-06T21:00:40.641] _slurm_rpc_submit_batch_job: JobId=53469 InitPrio=13600 usec=549
[2022-12-06T21:00:41.048] sched: Allocate JobId=53469 NodeList=cpu07 #CPUs=6 Partition=cpu-opteron
[2022-12-06T21:00:44.263] _job_complete: JobId=53469 WEXITSTATUS 1
[2022-12-06T21:00:44.264] _job_complete: JobId=53469 done
[2022-12-06T21:05:11.657] _slurm_rpc_submit_batch_job: JobId=53470 InitPrio=13600 usec=548
[2022-12-06T21:05:12.478] sched: Allocate JobId=53470 NodeList=cpu07 #CPUs=10 Partition=cpu-opteron
[2022-12-06T21:05:13.532] _job_complete: JobId=53470 WEXITSTATUS 1
[2022-12-06T21:05:13.533] _job_complete: JobId=53470 done
[2022-12-06T21:13:39.034] _slurm_rpc_submit_batch_job: JobId=53471 InitPrio=13600 usec=447
[2022-12-06T21:13:39.352] sched: Allocate JobId=53471 NodeList=cpu07 #CPUs=6 Partition=cpu-opteron
[2022-12-06T21:17:58.444] _slurm_rpc_kill_job: REQUEST_KILL_JOB JobId=53468 uid 548200017
[2022-12-06T21:19:34.654] _slurm_rpc_submit_batch_job: JobId=53472 InitPrio=400 usec=478
[2022-12-06T21:19:34.916] sched: Allocate JobId=53472 NodeList=cpu08 #CPUs=64 Partition=cpu-opteron
[2022-12-06T21:21:46.738] _job_complete: JobId=53471 WEXITSTATUS 0
[2022-12-06T21:21:46.739] _job_complete: JobId=53471 done
[2022-12-06T22:14:01.700] _job_complete: JobId=53472 WEXITSTATUS 0
[2022-12-06T22:14:01.701] _job_complete: JobId=53472 done
[2022-12-06T22:30:50.639] _slurm_rpc_submit_batch_job: JobId=53473 InitPrio=13600 usec=511
[2022-12-06T22:30:51.257] sched: Allocate JobId=53473 NodeList=cpu07 #CPUs=20 Partition=cpu-opteron
[2022-12-06T23:24:07.279] _job_complete: JobId=53473 WEXITSTATUS 0
[2022-12-06T23:24:07.280] _job_complete: JobId=53473 done
[2022-12-07T03:04:48.778] _job_complete: JobId=53438 WEXITSTATUS 0
[2022-12-07T03:04:48.778] _job_complete: JobId=53438 done
[2022-12-07T07:07:39.364] Time limit exhausted for JobId=53189
[2022-12-07T07:07:50.413] sched: Allocate JobId=53465 NodeList=cpu13 #CPUs=48 Partition=cpu-epyc
[2022-12-07T08:05:19.706] Requeuing JobId=52777
[2022-12-07T08:05:19.723] sched: Allocate JobId=53226 NodeList=gpu05 #CPUs=16 Partition=gpu-v100s
[2022-12-07T08:05:35.847] Requeuing JobId=53220
[2022-12-07T08:05:35.865] sched: Allocate JobId=53463 NodeList=gpu05 #CPUs=16 Partition=gpu-v100s
[2022-12-07T08:06:14.125] _slurm_rpc_submit_batch_job: JobId=53474 InitPrio=400 usec=577
[2022-12-07T08:07:01.709] Requeuing JobId=53226
[2022-12-07T08:13:01.072] _slurm_rpc_submit_batch_job: JobId=53475 InitPrio=1400 usec=506
[2022-12-07T08:16:29.111] _slurm_rpc_kill_job: REQUEST_KILL_JOB JobId=53475 uid 548300593
[2022-12-07T08:16:53.696] _slurm_rpc_submit_batch_job: JobId=53476 InitPrio=1400 usec=426
[2022-12-07T08:16:54.574] sched: Allocate JobId=53476 NodeList=cpu07 #CPUs=32 Partition=cpu-opteron
[2022-12-07T08:16:55.645] _job_complete: JobId=53476 WEXITSTATUS 127
[2022-12-07T08:16:55.646] _job_complete: JobId=53476 done
[2022-12-07T08:17:44.291] _slurm_rpc_submit_batch_job: JobId=53477 InitPrio=1400 usec=558
[2022-12-07T08:17:44.626] sched: Allocate JobId=53477 NodeList=cpu07 #CPUs=32 Partition=cpu-opteron
[2022-12-07T08:17:50.890] _job_complete: JobId=53477 WEXITSTATUS 1
[2022-12-07T08:17:50.891] _job_complete: JobId=53477 done
[2022-12-07T08:19:16.159] _slurm_rpc_submit_batch_job: JobId=53478 InitPrio=400 usec=618
[2022-12-07T08:19:16.768] sched: Allocate JobId=53478 NodeList=cpu08 #CPUs=64 Partition=cpu-opteron
[2022-12-07T08:22:47.662] _job_complete: JobId=53422 WEXITSTATUS 0
[2022-12-07T08:22:47.663] _job_complete: JobId=53422 done
[2022-12-07T08:22:48.568] sched: Allocate JobId=53474 NodeList=cpu15 #CPUs=48 Partition=cpu-epyc
[2022-12-07T08:26:07.458] _slurm_rpc_submit_batch_job: JobId=53479 InitPrio=400 usec=530
[2022-12-07T08:37:09.322] _pick_best_nodes: JobId=53480 never runnable in partition cpu-epyc
[2022-12-07T08:37:09.323] _slurm_rpc_submit_batch_job: Requested node configuration is not available
[2022-12-07T08:37:50.637] _slurm_rpc_submit_batch_job: JobId=53481 InitPrio=400 usec=463
[2022-12-07T08:43:57.908] _slurm_rpc_submit_batch_job: JobId=53482 InitPrio=1400 usec=529
[2022-12-07T08:44:36.374] _slurm_rpc_kill_job: REQUEST_KILL_JOB JobId=53482 uid 548300593
[2022-12-07T08:44:38.513] _slurm_rpc_submit_batch_job: JobId=53483 InitPrio=1400 usec=508
[2022-12-07T09:04:19.603] _slurm_rpc_kill_job: REQUEST_KILL_JOB JobId=53350 uid 548200003
[2022-12-07T09:04:19.603] _slurm_rpc_kill_job: REQUEST_KILL_JOB JobId=53349 uid 548200003
[2022-12-07T09:04:50.643] sched: Allocate JobId=53408 NodeList=gpu02 #CPUs=8 Partition=gpu-titan
[2022-12-07T10:35:10.722] _slurm_rpc_submit_batch_job: JobId=53484 InitPrio=600 usec=584
[2022-12-07T10:46:38.210] _slurm_rpc_submit_batch_job: JobId=53485 InitPrio=3200 usec=597
[2022-12-07T10:48:16.321] _slurm_rpc_submit_batch_job: JobId=53486 InitPrio=3200 usec=492
[2022-12-07T10:48:21.429] _slurm_rpc_submit_batch_job: JobId=53487 InitPrio=3200 usec=468
[2022-12-07T10:48:25.745] _slurm_rpc_submit_batch_job: JobId=53488 InitPrio=3200 usec=491
[2022-12-07T10:48:31.153] _slurm_rpc_submit_batch_job: JobId=53489 InitPrio=3200 usec=491
[2022-12-07T10:48:35.521] _slurm_rpc_submit_batch_job: JobId=53490 InitPrio=3200 usec=569
[2022-12-07T10:48:39.200] _slurm_rpc_submit_batch_job: JobId=53491 InitPrio=3200 usec=445
[2022-12-07T10:48:45.664] _slurm_rpc_submit_batch_job: JobId=53492 InitPrio=3200 usec=496
[2022-12-07T10:48:50.106] _slurm_rpc_submit_batch_job: JobId=53493 InitPrio=3200 usec=575
[2022-12-07T10:48:54.963] _slurm_rpc_submit_batch_job: JobId=53494 InitPrio=3200 usec=469
[2022-12-07T10:49:00.155] _slurm_rpc_submit_batch_job: JobId=53495 InitPrio=3200 usec=515
[2022-12-07T10:49:04.332] _slurm_rpc_submit_batch_job: JobId=53496 InitPrio=3200 usec=439
[2022-12-07T10:49:20.060] _slurm_rpc_submit_batch_job: JobId=53497 InitPrio=3200 usec=489
[2022-12-07T10:49:24.442] _slurm_rpc_submit_batch_job: JobId=53498 InitPrio=3200 usec=425
[2022-12-07T10:49:29.194] _slurm_rpc_submit_batch_job: JobId=53499 InitPrio=3200 usec=490
[2022-12-07T10:49:32.722] _slurm_rpc_submit_batch_job: JobId=53500 InitPrio=3200 usec=504
[2022-12-07T10:49:35.962] _slurm_rpc_submit_batch_job: JobId=53501 InitPrio=3200 usec=494
[2022-12-07T10:49:39.234] _slurm_rpc_submit_batch_job: JobId=53502 InitPrio=3200 usec=438
[2022-12-07T10:49:43.666] _slurm_rpc_submit_batch_job: JobId=53503 InitPrio=3200 usec=546
[2022-12-07T10:49:51.690] _slurm_rpc_submit_batch_job: JobId=53504 InitPrio=3200 usec=406
[2022-12-07T10:49:55.330] _slurm_rpc_submit_batch_job: JobId=53505 InitPrio=3200 usec=493
[2022-12-07T10:49:59.169] _slurm_rpc_submit_batch_job: JobId=53506 InitPrio=3200 usec=602
[2022-12-07T10:50:02.882] _slurm_rpc_submit_batch_job: JobId=53507 InitPrio=3200 usec=499
[2022-12-07T10:50:06.579] _slurm_rpc_submit_batch_job: JobId=53508 InitPrio=3200 usec=431
[2022-12-07T10:50:09.906] _slurm_rpc_submit_batch_job: JobId=53509 InitPrio=3200 usec=532
[2022-12-07T10:50:24.059] _slurm_rpc_submit_batch_job: JobId=53510 InitPrio=3200 usec=500
[2022-12-07T10:50:28.411] _slurm_rpc_submit_batch_job: JobId=53511 InitPrio=3200 usec=688
[2022-12-07T11:08:09.491] _slurm_rpc_kill_job: REQUEST_KILL_JOB JobId=53461 uid 548200121
[2022-12-07T11:08:13.750] _slurm_rpc_kill_job: REQUEST_KILL_JOB JobId=53460 uid 548200121
[2022-12-07T11:08:17.350] _slurm_rpc_kill_job: REQUEST_KILL_JOB JobId=53459 uid 548200121
[2022-12-07T11:08:25.651] _slurm_rpc_submit_batch_job: JobId=53512 InitPrio=10600 usec=515
[2022-12-07T11:08:30.400] _slurm_rpc_kill_job: REQUEST_KILL_JOB JobId=53512 uid 548200121
[2022-12-07T11:08:41.420] _slurm_rpc_submit_batch_job: JobId=53513 InitPrio=600 usec=595
[2022-12-07T11:09:06.268] _slurm_rpc_submit_batch_job: JobId=53514 InitPrio=600 usec=493
[2022-12-07T11:09:34.866] _slurm_rpc_submit_batch_job: JobId=53515 InitPrio=600 usec=467
[2022-12-07T11:09:56.375] _slurm_rpc_submit_batch_job: JobId=53516 InitPrio=600 usec=497
[2022-12-07T11:09:56.868] sched: Allocate JobId=53516 NodeList=gpu03 #CPUs=4 Partition=gpu-k10
[2022-12-07T11:10:04.876] _job_complete: JobId=53516 WEXITSTATUS 1
[2022-12-07T11:10:04.876] _job_complete: JobId=53516 done
[2022-12-07T11:13:41.605] _slurm_rpc_submit_batch_job: JobId=53517 InitPrio=600 usec=460
[2022-12-07T11:13:42.312] sched: Allocate JobId=53517 NodeList=gpu03 #CPUs=4 Partition=gpu-k10
[2022-12-07T11:14:45.525] job_step_signal: JobId=53517 StepId=0 not found
[2022-12-07T11:21:06.475] _slurm_rpc_kill_job: REQUEST_KILL_JOB JobId=53517 uid 548200121
[2022-12-07T11:27:10.701] _slurm_rpc_submit_batch_job: JobId=53518 InitPrio=2200 usec=768
[2022-12-07T11:28:40.581] _slurm_rpc_kill_job: REQUEST_KILL_JOB JobId=53455 uid 548200121
[2022-12-07T11:28:40.581] _slurm_rpc_kill_job: REQUEST_KILL_JOB JobId=53454 uid 548200121
[2022-12-07T11:32:21.187] _slurm_rpc_kill_job: REQUEST_KILL_JOB JobId=53514 uid 548200121
[2022-12-07T11:32:21.187] _slurm_rpc_kill_job: REQUEST_KILL_JOB JobId=53456 uid 548200121
[2022-12-07T11:32:21.187] _slurm_rpc_kill_job: REQUEST_KILL_JOB JobId=53457 uid 548200121
[2022-12-07T11:32:21.187] _slurm_rpc_kill_job: REQUEST_KILL_JOB JobId=53513 uid 548200121
[2022-12-07T11:32:21.187] _slurm_rpc_kill_job: REQUEST_KILL_JOB JobId=53514 uid 548200121
[2022-12-07T11:32:21.187] _slurm_rpc_kill_job: REQUEST_KILL_JOB JobId=53458 uid 548200121
[2022-12-07T11:32:37.435] _slurm_rpc_kill_job: REQUEST_KILL_JOB JobId=53515 uid 548200121
[2022-12-07T11:32:37.435] _slurm_rpc_kill_job: REQUEST_KILL_JOB JobId=53484 uid 548200121
[2022-12-07T11:37:35.096] _slurm_rpc_submit_batch_job: JobId=53519 InitPrio=600 usec=620
[2022-12-07T11:39:07.556] _slurm_rpc_submit_batch_job: JobId=53520 InitPrio=600 usec=431
[2022-12-07T11:42:33.701] _slurm_rpc_submit_batch_job: JobId=53521 InitPrio=600 usec=410
[2022-12-07T11:43:02.999] _slurm_rpc_submit_batch_job: JobId=53522 InitPrio=600 usec=479
[2022-12-07T11:44:06.105] _slurm_rpc_kill_job: REQUEST_KILL_JOB JobId=53522 uid 548200121
[2022-12-07T11:44:08.454] _slurm_rpc_submit_batch_job: JobId=53523 InitPrio=600 usec=487
[2022-12-07T11:45:04.606] _slurm_rpc_kill_job: REQUEST_KILL_JOB JobId=53523 uid 548200121
[2022-12-07T11:45:06.609] _slurm_rpc_submit_batch_job: JobId=53524 InitPrio=600 usec=612
[2022-12-07T11:45:28.002] _slurm_rpc_submit_batch_job: JobId=53525 InitPrio=600 usec=475
[2022-12-07T11:45:51.549] _slurm_rpc_submit_batch_job: JobId=53526 InitPrio=600 usec=437
[2022-12-07T11:47:33.254] _slurm_rpc_submit_batch_job: JobId=53527 InitPrio=600 usec=505
[2022-12-07T11:47:55.410] _slurm_rpc_kill_job: REQUEST_KILL_JOB JobId=53527 uid 548200121
[2022-12-07T11:48:35.072] _slurm_rpc_submit_batch_job: JobId=53528 InitPrio=10600 usec=434
[2022-12-07T11:48:54.960] _slurm_rpc_kill_job: REQUEST_KILL_JOB JobId=53528 uid 548200121
[2022-12-07T11:49:05.194] _slurm_rpc_submit_batch_job: JobId=53529 InitPrio=10600 usec=458
[2022-12-07T11:49:05.879] sched: Allocate JobId=53529 NodeList=gpu05 #CPUs=4 Partition=gpu-v100s
[2022-12-07T12:00:08.972] _slurm_rpc_kill_job: REQUEST_KILL_JOB JobId=53519 uid 548200121
[2022-12-07T12:00:08.972] _slurm_rpc_kill_job: REQUEST_KILL_JOB JobId=53526 uid 548200121
[2022-12-07T12:00:08.972] _slurm_rpc_kill_job: REQUEST_KILL_JOB JobId=53521 uid 548200121
[2022-12-07T12:00:08.972] _slurm_rpc_kill_job: REQUEST_KILL_JOB JobId=53525 uid 548200121
[2022-12-07T12:00:08.972] _slurm_rpc_kill_job: REQUEST_KILL_JOB JobId=53524 uid 548200121
[2022-12-07T12:00:08.972] _slurm_rpc_kill_job: REQUEST_KILL_JOB JobId=53529 uid 548200121
[2022-12-07T12:00:08.973] _slurm_rpc_kill_job: REQUEST_KILL_JOB JobId=53520 uid 548200121
[2022-12-07T12:00:24.091] _slurm_rpc_submit_batch_job: JobId=53530 InitPrio=600 usec=526
[2022-12-07T12:00:26.367] _slurm_rpc_submit_batch_job: JobId=53531 InitPrio=600 usec=451
[2022-12-07T12:00:28.677] _slurm_rpc_submit_batch_job: JobId=53532 InitPrio=600 usec=475
[2022-12-07T12:00:30.520] _slurm_rpc_submit_batch_job: JobId=53533 InitPrio=600 usec=470
[2022-12-07T12:00:32.383] _slurm_rpc_submit_batch_job: JobId=53534 InitPrio=600 usec=537
[2022-12-07T12:00:35.368] _slurm_rpc_submit_batch_job: JobId=53535 InitPrio=600 usec=492
[2022-12-07T12:14:53.724] _slurm_rpc_kill_job: REQUEST_KILL_JOB JobId=53534 uid 548200121
[2022-12-07T12:14:53.724] _slurm_rpc_kill_job: REQUEST_KILL_JOB JobId=53533 uid 548200121
[2022-12-07T12:14:53.724] _slurm_rpc_kill_job: REQUEST_KILL_JOB JobId=53532 uid 548200121
[2022-12-07T12:14:53.724] _slurm_rpc_kill_job: REQUEST_KILL_JOB JobId=53531 uid 548200121
[2022-12-07T12:14:53.724] _slurm_rpc_kill_job: REQUEST_KILL_JOB JobId=53535 uid 548200121
[2022-12-07T12:14:53.724] _slurm_rpc_kill_job: REQUEST_KILL_JOB JobId=53530 uid 548200121
[2022-12-07T12:21:35.322] _slurm_rpc_submit_batch_job: JobId=53536 InitPrio=3800 usec=423
[2022-12-07T12:21:35.962] sched: Allocate JobId=53536 NodeList=cpu07 #CPUs=16 Partition=cpu-opteron
[2022-12-07T12:23:27.140] _job_complete: JobId=53463 WEXITSTATUS 0
[2022-12-07T12:23:27.145] _job_complete: JobId=53463 done
[2022-12-07T12:23:28.414] sched: Allocate JobId=53423 NodeList=gpu05 #CPUs=16 Partition=gpu-v100s
[2022-12-07T12:23:32.282] _job_complete: JobId=53423 WEXITSTATUS 1
[2022-12-07T12:23:32.283] _job_complete: JobId=53423 done
[2022-12-07T12:24:05.671] _slurm_rpc_submit_batch_job: JobId=53537 InitPrio=4400 usec=496
[2022-12-07T12:24:06.174] sched: Allocate JobId=53537 NodeList=cpu07 #CPUs=8 Partition=cpu-opteron
[2022-12-07T12:24:55.770] _job_complete: JobId=53537 WEXITSTATUS 0
[2022-12-07T12:24:55.771] _job_complete: JobId=53537 done
[2022-12-07T12:30:47.360] _slurm_rpc_submit_batch_job: JobId=53538 InitPrio=4400 usec=508
[2022-12-07T12:30:47.800] sched: Allocate JobId=53538 NodeList=cpu07 #CPUs=12 Partition=cpu-opteron
[2022-12-07T12:38:25.881] _job_complete: JobId=53538 WEXITSTATUS 0
[2022-12-07T12:38:25.881] _job_complete: JobId=53538 done
[2022-12-07T12:50:17.825] _slurm_rpc_submit_batch_job: JobId=53539 InitPrio=4400 usec=566
[2022-12-07T12:50:18.163] sched: Allocate JobId=53539 NodeList=cpu07 #CPUs=12 Partition=cpu-opteron
[2022-12-07T12:55:35.271] sched: _slurm_rpc_allocate_resources JobId=53540 NodeList=(null) usec=890
[2022-12-07T12:55:36.055] sched: Allocate JobId=53540 NodeList=gpu04 #CPUs=8 Partition=gpu-k40c
[2022-12-07T12:59:00.558] _job_complete: JobId=53539 WEXITSTATUS 0
[2022-12-07T12:59:00.558] _job_complete: JobId=53539 done
[2022-12-07T13:07:50.512] _slurm_rpc_submit_batch_job: JobId=53541 InitPrio=4400 usec=546
[2022-12-07T13:07:51.372] sched: Allocate JobId=53541 NodeList=cpu07 #CPUs=18 Partition=cpu-opteron
[2022-12-07T13:11:54.754] _job_complete: JobId=53540 WEXITSTATUS 1
[2022-12-07T13:11:54.755] _job_complete: JobId=53540 done
[2022-12-07T13:12:18.684] _slurm_rpc_submit_batch_job: JobId=53542 InitPrio=2800 usec=516
[2022-12-07T13:12:18.887] sched: Allocate JobId=53542 NodeList=gpu05 #CPUs=16 Partition=gpu-v100s
[2022-12-07T13:13:26.493] _slurm_rpc_submit_batch_job: JobId=53543 InitPrio=2800 usec=532
[2022-12-07T13:28:14.482] _slurm_rpc_submit_batch_job: JobId=53544 InitPrio=4400 usec=518
[2022-12-07T13:28:15.354] sched: Allocate JobId=53544 NodeList=cpu07 #CPUs=8 Partition=cpu-opteron
[2022-12-07T13:29:34.416] _job_complete: JobId=53544 WEXITSTATUS 0
[2022-12-07T13:29:34.416] _job_complete: JobId=53544 done
[2022-12-07T13:33:39.480] _slurm_rpc_submit_batch_job: JobId=53545 InitPrio=4400 usec=457
[2022-12-07T13:33:39.907] sched: Allocate JobId=53545 NodeList=cpu07 #CPUs=12 Partition=cpu-opteron
[2022-12-07T13:45:38.848] _job_complete: JobId=53545 WEXITSTATUS 0
[2022-12-07T13:45:38.848] _job_complete: JobId=53545 done
[2022-12-07T13:50:01.227] _slurm_rpc_submit_batch_job: JobId=53546 InitPrio=4400 usec=648
[2022-12-07T13:50:01.776] sched: Allocate JobId=53546 NodeList=cpu07 #CPUs=12 Partition=cpu-opteron
[2022-12-07T14:02:34.463] _job_complete: JobId=53546 WEXITSTATUS 0
[2022-12-07T14:02:34.463] _job_complete: JobId=53546 done
[2022-12-07T14:07:21.406] _slurm_rpc_submit_batch_job: JobId=53547 InitPrio=4400 usec=605
[2022-12-07T14:09:22.483] _slurm_rpc_submit_batch_job: JobId=53548 InitPrio=1000 usec=498
[2022-12-07T14:10:09.056] sched/backfill: _start_job: Started JobId=53548 in cpu-opteron on cpu07
[2022-12-07T14:10:10.483] _job_complete: JobId=53548 WEXITSTATUS 0
[2022-12-07T14:10:10.483] _job_complete: JobId=53548 done
[2022-12-07T14:22:28.024] _slurm_rpc_submit_batch_job: JobId=53549 InitPrio=3400 usec=480
[2022-12-07T14:33:53.179] _slurm_rpc_submit_batch_job: JobId=53550 InitPrio=4400 usec=643
[2022-12-07T14:34:09.133] sched/backfill: _start_job: Started JobId=53550 in cpu-opteron on cpu07
[2022-12-07T14:34:32.017] _slurm_rpc_kill_job: REQUEST_KILL_JOB JobId=53550 uid 548200084
[2022-12-07T14:34:45.524] _slurm_rpc_submit_batch_job: JobId=53551 InitPrio=4400 usec=499
[2022-12-07T14:35:09.138] sched/backfill: _start_job: Started JobId=53551 in cpu-opteron on cpu07
[2022-12-07T14:37:14.814] _job_complete: JobId=53551 WEXITSTATUS 0
[2022-12-07T14:37:14.814] _job_complete: JobId=53551 done
[2022-12-07T15:28:27.852] _slurm_rpc_submit_batch_job: JobId=53552 InitPrio=4400 usec=597
[2022-12-07T15:29:09.338] sched/backfill: _start_job: Started JobId=53552 in cpu-opteron on cpu07
[2022-12-07T15:45:47.423] _job_complete: JobId=53552 WEXITSTATUS 0
[2022-12-07T15:45:47.423] _job_complete: JobId=53552 done
[2022-12-07T16:21:33.249] _slurm_rpc_submit_batch_job: JobId=53553 InitPrio=400 usec=516
[2022-12-07T16:21:42.014] _slurm_rpc_submit_batch_job: JobId=53554 InitPrio=400 usec=551
[2022-12-07T16:21:55.391] _slurm_rpc_submit_batch_job: JobId=53555 InitPrio=1000 usec=548
[2022-12-07T16:22:25.491] _slurm_rpc_kill_job: REQUEST_KILL_JOB JobId=53554 uid 548200017
[2022-12-07T16:22:25.491] _slurm_rpc_kill_job: REQUEST_KILL_JOB JobId=53553 uid 548200017
[2022-12-07T16:23:16.492] _slurm_rpc_submit_batch_job: JobId=53556 InitPrio=400 usec=500
[2022-12-07T16:23:24.155] _slurm_rpc_submit_batch_job: JobId=53557 InitPrio=400 usec=429
[2022-12-07T16:42:33.083] _job_complete: JobId=53442 WEXITSTATUS 0
[2022-12-07T16:42:33.083] _job_complete: JobId=53442 done
[2022-12-07T16:42:33.946] sched: Allocate JobId=53547 NodeList=cpu07 #CPUs=18 Partition=cpu-opteron
[2022-12-07T16:50:48.558] _slurm_rpc_submit_batch_job: JobId=53558 InitPrio=1000 usec=653
[2022-12-07T17:19:39.583] _slurm_rpc_submit_batch_job: JobId=53559 InitPrio=4400 usec=621
[2022-12-07T17:19:39.656] sched: Allocate JobId=53559 NodeList=cpu07 #CPUs=12 Partition=cpu-opteron
[2022-12-07T17:21:10.824] _slurm_rpc_submit_batch_job: JobId=53560 InitPrio=4400 usec=556
[2022-12-07T17:35:19.135] _job_complete: JobId=53559 WEXITSTATUS 0
[2022-12-07T17:35:19.135] _job_complete: JobId=53559 done
[2022-12-07T17:35:19.936] sched: Allocate JobId=53560 NodeList=cpu07 #CPUs=8 Partition=cpu-opteron
[2022-12-07T17:38:41.767] _job_complete: JobId=53560 WEXITSTATUS 0
[2022-12-07T17:38:41.767] _job_complete: JobId=53560 done
[2022-12-07T17:41:44.827] _slurm_rpc_submit_batch_job: JobId=53561 InitPrio=4400 usec=559
[2022-12-07T17:41:45.478] sched: Allocate JobId=53561 NodeList=cpu07 #CPUs=12 Partition=cpu-opteron
[2022-12-07T18:01:07.637] _job_complete: JobId=53561 WEXITSTATUS 0
[2022-12-07T18:01:07.637] _job_complete: JobId=53561 done
[2022-12-07T18:14:15.279] _slurm_rpc_submit_batch_job: JobId=53562 InitPrio=4400 usec=561
[2022-12-07T18:14:15.847] sched: Allocate JobId=53562 NodeList=cpu07 #CPUs=12 Partition=cpu-opteron
[2022-12-07T18:31:13.672] _job_complete: JobId=53562 WEXITSTATUS 0
[2022-12-07T18:31:13.673] _job_complete: JobId=53562 done
[2022-12-07T18:34:53.534] _slurm_rpc_submit_batch_job: JobId=53563 InitPrio=4400 usec=566
[2022-12-07T18:35:17.698] _slurm_rpc_submit_batch_job: JobId=53564 InitPrio=4400 usec=504
[2022-12-07T19:31:12.693] Time limit exhausted for JobId=53332
[2022-12-07T19:31:19.020] sched: Allocate JobId=53563 NodeList=cpu05 #CPUs=18 Partition=cpu-opteron
[2022-12-07T19:31:19.021] sched: Allocate JobId=53564 NodeList=cpu05 #CPUs=18 Partition=cpu-opteron
[2022-12-07T20:02:41.701] _slurm_rpc_kill_job: REQUEST_KILL_JOB JobId=53424 uid 548300564
[2022-12-07T20:36:21.213] _job_complete: JobId=53397 WEXITSTATUS 0
[2022-12-07T20:36:21.218] _job_complete: JobId=53397 done
[2022-12-07T20:36:25.219] sched: Allocate JobId=53518 NodeList=cpu09 #CPUs=32 Partition=cpu-opteron
[2022-12-07T20:37:10.406] sched/backfill: _start_job: Started JobId=53555 in cpu-opteron on cpu05
[2022-12-07T20:37:10.407] sched/backfill: _start_job: Started JobId=53558 in cpu-opteron on cpu09
[2022-12-07T20:47:45.677] _job_complete: JobId=53417 WEXITSTATUS 0
[2022-12-07T20:47:45.678] _job_complete: JobId=53417 done
[2022-12-07T20:47:48.991] sched: Allocate JobId=53483 NodeList=cpu10 #CPUs=35 Partition=cpu-opteron
[2022-12-07T20:48:09.449] _job_complete: JobId=53483 WEXITSTATUS 1
[2022-12-07T20:48:09.450] _job_complete: JobId=53483 done
[2022-12-07T20:48:10.171] sched: Allocate JobId=53479 NodeList=cpu10 #CPUs=64 Partition=cpu-opteron
[2022-12-07T21:02:49.660] _job_complete: JobId=53555 WEXITSTATUS 0
[2022-12-07T21:02:49.660] _job_complete: JobId=53555 done
[2022-12-07T21:09:36.552] _job_complete: JobId=53558 WEXITSTATUS 0
[2022-12-07T21:09:36.552] _job_complete: JobId=53558 done
[2022-12-07T21:36:20.901] _slurm_rpc_submit_batch_job: JobId=53565 InitPrio=400 usec=561
[2022-12-07T23:26:18.805] _slurm_rpc_kill_job: REQUEST_KILL_JOB JobId=53536 uid 548300635
[2022-12-08T00:39:43.243] _job_complete: JobId=53541 WEXITSTATUS 0
[2022-12-08T00:39:43.243] _job_complete: JobId=53541 done
[2022-12-08T07:48:34.509] _job_complete: JobId=53542 WEXITSTATUS 0
[2022-12-08T07:48:34.515] _job_complete: JobId=53542 done
[2022-12-08T07:48:35.635] sched: Allocate JobId=53549 NodeList=gpu05 #CPUs=16 Partition=gpu-v100s
[2022-12-08T07:58:12.065] _job_complete: JobId=53547 WEXITSTATUS 0
[2022-12-08T07:58:12.065] _job_complete: JobId=53547 done
[2022-12-08T07:58:12.866] sched: Allocate JobId=53556 NodeList=cpu07 #CPUs=64 Partition=cpu-opteron
[2022-12-08T08:20:44.621] Time limit exhausted for JobId=53322
[2022-12-08T08:20:47.710] sched: Allocate JobId=53409 NodeList=gpu02 #CPUs=8 Partition=gpu-titan
[2022-12-08T08:28:03.221] _slurm_rpc_submit_batch_job: JobId=53566 InitPrio=13800 usec=605
[2022-12-08T08:28:03.613] sched: Allocate JobId=53566 NodeList=cpu05 #CPUs=1 Partition=cpu-opteron
[2022-12-08T09:22:42.060] _job_complete: JobId=53566 WEXITSTATUS 0
[2022-12-08T09:22:42.060] _job_complete: JobId=53566 done
[2022-12-08T09:22:51.705] _slurm_rpc_submit_batch_job: JobId=53567 InitPrio=13800 usec=502
[2022-12-08T09:22:52.349] sched: Allocate JobId=53567 NodeList=cpu05 #CPUs=1 Partition=cpu-opteron
[2022-12-08T10:14:25.123] _slurm_rpc_kill_job: REQUEST_KILL_JOB JobId=53309 uid 548200003
[2022-12-08T10:14:40.556] _slurm_rpc_delete_reservation complete for cpu14_health_check usec=95
[2022-12-08T10:14:40.930] sched: Allocate JobId=53485 NodeList=cpu14 #CPUs=16 Partition=cpu-epyc
[2022-12-08T10:14:40.931] sched: Allocate JobId=53486 NodeList=cpu14 #CPUs=16 Partition=cpu-epyc
[2022-12-08T10:14:40.934] sched: Allocate JobId=53487 NodeList=cpu14 #CPUs=16 Partition=cpu-epyc
[2022-12-08T10:16:53.160] _job_complete: JobId=53567 OOM failure
[2022-12-08T10:16:53.160] _job_complete: JobId=53567 done
[2022-12-08T10:33:00.314] _slurm_rpc_submit_batch_job: JobId=53568 InitPrio=13800 usec=488
[2022-12-08T10:33:00.827] sched: Allocate JobId=53568 NodeList=cpu05 #CPUs=1 Partition=cpu-opteron
[2022-12-08T11:08:33.287] _slurm_rpc_submit_batch_job: JobId=53569 InitPrio=3400 usec=507
[2022-12-08T11:08:34.184] sched: Allocate JobId=53569 NodeList=gpu05 #CPUs=16 Partition=gpu-v100s
[2022-12-08T11:15:35.285] _slurm_rpc_submit_batch_job: JobId=53570 InitPrio=3400 usec=593
[2022-12-08T11:21:08.402] _job_complete: JobId=53568 OOM failure
[2022-12-08T11:21:08.402] _job_complete: JobId=53568 done
[2022-12-08T12:09:39.716] _job_complete: JobId=53549 WEXITSTATUS 0
[2022-12-08T12:09:39.717] _job_complete: JobId=53549 done
[2022-12-08T12:09:40.801] sched: Allocate JobId=53570 NodeList=gpu05 #CPUs=16 Partition=gpu-v100s
[2022-12-08T12:21:44.850] _slurm_rpc_submit_batch_job: JobId=53571 InitPrio=3400 usec=547
[2022-12-08T12:36:01.265] _job_complete: JobId=53485 WEXITSTATUS 0
[2022-12-08T12:36:01.265] _job_complete: JobId=53485 done
[2022-12-08T12:36:01.541] sched: Allocate JobId=53488 NodeList=cpu14 #CPUs=16 Partition=cpu-epyc
[2022-12-08T12:36:38.950] _job_complete: JobId=53486 WEXITSTATUS 0
[2022-12-08T12:36:38.950] _job_complete: JobId=53486 done
[2022-12-08T12:36:39.194] sched: Allocate JobId=53489 NodeList=cpu14 #CPUs=16 Partition=cpu-epyc
[2022-12-08T12:57:00.308] _job_complete: JobId=53487 WEXITSTATUS 0
[2022-12-08T12:57:00.308] _job_complete: JobId=53487 done
[2022-12-08T12:57:00.532] sched: Allocate JobId=53490 NodeList=cpu14 #CPUs=16 Partition=cpu-epyc
[2022-12-08T13:45:17.380] _slurm_rpc_submit_batch_job: JobId=53572 InitPrio=13800 usec=600
[2022-12-08T13:45:17.979] sched: Allocate JobId=53572 NodeList=cpu05 #CPUs=1 Partition=cpu-opteron
[2022-12-08T14:13:41.033] _job_complete: JobId=53564 WEXITSTATUS 0
[2022-12-08T14:13:41.034] _job_complete: JobId=53564 done
[2022-12-08T14:33:07.980] _job_complete: JobId=53474 WEXITSTATUS 0
[2022-12-08T14:33:07.985] _job_complete: JobId=53474 done
[2022-12-08T14:33:10.893] sched: Allocate JobId=53491 NodeList=cpu15 #CPUs=16 Partition=cpu-epyc
[2022-12-08T14:33:10.894] sched: Allocate JobId=53492 NodeList=cpu15 #CPUs=16 Partition=cpu-epyc
[2022-12-08T14:33:10.895] sched: Allocate JobId=53493 NodeList=cpu15 #CPUs=16 Partition=cpu-epyc
[2022-12-08T14:45:44.434] Time limit exhausted for JobId=53572
[2022-12-08T14:47:33.599] _slurm_rpc_submit_batch_job: JobId=53573 InitPrio=13800 usec=507
[2022-12-08T14:47:33.697] sched: Allocate JobId=53573 NodeList=cpu05 #CPUs=1 Partition=cpu-opteron
[2022-12-08T14:58:05.162] _job_complete: JobId=53488 WEXITSTATUS 0
[2022-12-08T14:58:05.162] _job_complete: JobId=53488 done
[2022-12-08T14:58:05.402] sched: Allocate JobId=53494 NodeList=cpu14 #CPUs=16 Partition=cpu-epyc
[2022-12-08T15:21:14.328] _job_complete: JobId=53573 OOM failure
[2022-12-08T15:21:14.328] _job_complete: JobId=53573 done
[2022-12-08T15:25:53.747] _job_complete: JobId=53490 WEXITSTATUS 0
[2022-12-08T15:25:53.747] _job_complete: JobId=53490 done
[2022-12-08T15:25:53.992] sched: Allocate JobId=53495 NodeList=cpu14 #CPUs=16 Partition=cpu-epyc
[2022-12-08T15:26:42.741] _job_complete: JobId=53569 WEXITSTATUS 0
[2022-12-08T15:26:42.746] _job_complete: JobId=53569 done
[2022-12-08T15:26:43.765] sched: Allocate JobId=53571 NodeList=gpu05 #CPUs=16 Partition=gpu-v100s
[2022-12-08T15:39:13.274] _job_complete: JobId=53489 WEXITSTATUS 0
[2022-12-08T15:39:13.274] _job_complete: JobId=53489 done
[2022-12-08T15:39:13.495] sched: Allocate JobId=53496 NodeList=cpu14 #CPUs=16 Partition=cpu-epyc
[2022-12-08T15:47:29.625] _job_complete: JobId=53556 WEXITSTATUS 0
[2022-12-08T15:47:29.626] _job_complete: JobId=53556 done
[2022-12-08T15:47:31.875] sched: Allocate JobId=53565 NodeList=cpu07 #CPUs=64 Partition=cpu-opteron
[2022-12-08T16:17:17.575] _job_complete: JobId=53563 WEXITSTATUS 0
[2022-12-08T16:17:17.575] _job_complete: JobId=53563 done
[2022-12-08T16:22:38.957] _slurm_rpc_submit_batch_job: JobId=53574 InitPrio=10600 usec=407
[2022-12-08T16:23:35.871] _slurm_rpc_kill_job: REQUEST_KILL_JOB JobId=53574 uid 548200121
[2022-12-08T16:23:44.300] _slurm_rpc_submit_batch_job: JobId=53575 InitPrio=10600 usec=483
[2022-12-08T16:26:53.028] _slurm_rpc_submit_batch_job: JobId=53576 InitPrio=600 usec=595
[2022-12-08T16:26:55.176] _slurm_rpc_submit_batch_job: JobId=53577 InitPrio=600 usec=504
[2022-12-08T16:26:57.579] _slurm_rpc_submit_batch_job: JobId=53578 InitPrio=600 usec=488
[2022-12-08T16:26:59.627] _slurm_rpc_submit_batch_job: JobId=53579 InitPrio=600 usec=469
[2022-12-08T16:27:01.830] _slurm_rpc_submit_batch_job: JobId=53580 InitPrio=600 usec=427
[2022-12-08T16:27:03.978] _slurm_rpc_submit_batch_job: JobId=53581 InitPrio=600 usec=491
[2022-12-08T16:27:19.481] _slurm_rpc_kill_job: REQUEST_KILL_JOB JobId=53575 uid 548200121
[2022-12-08T16:29:46.488] _job_complete: JobId=53570 WEXITSTATUS 0
[2022-12-08T16:29:46.490] _job_complete: JobId=53570 done
[2022-12-08T16:42:37.407] _job_complete: JobId=53492 WEXITSTATUS 0
[2022-12-08T16:42:37.408] _job_complete: JobId=53492 done
[2022-12-08T16:42:37.750] sched: Allocate JobId=53497 NodeList=cpu15 #CPUs=16 Partition=cpu-epyc
[2022-12-08T16:52:20.369] _job_complete: JobId=53491 WEXITSTATUS 0
[2022-12-08T16:52:20.369] _job_complete: JobId=53491 done
[2022-12-08T16:52:20.676] sched: Allocate JobId=53498 NodeList=cpu15 #CPUs=16 Partition=cpu-epyc
[2022-12-08T17:15:04.270] _slurm_rpc_submit_batch_job: JobId=53582 InitPrio=10600 usec=484
[2022-12-08T17:15:04.833] sched: Allocate JobId=53582 NodeList=gpu05 #CPUs=4 Partition=gpu-v100s
[2022-12-08T17:23:23.300] _job_complete: JobId=53494 WEXITSTATUS 0
[2022-12-08T17:23:23.300] _job_complete: JobId=53494 done
[2022-12-08T17:23:23.567] sched: Allocate JobId=53499 NodeList=cpu14 #CPUs=16 Partition=cpu-epyc
[2022-12-08T17:35:08.763] _job_complete: JobId=53493 WEXITSTATUS 0
[2022-12-08T17:35:08.764] _job_complete: JobId=53493 done
[2022-12-08T17:35:09.123] sched: Allocate JobId=53500 NodeList=cpu15 #CPUs=16 Partition=cpu-epyc
[2022-12-08T17:52:19.707] _slurm_rpc_kill_job: REQUEST_KILL_JOB JobId=53582 uid 548200121
[2022-12-08T17:52:48.406] _job_complete: JobId=53496 WEXITSTATUS 0
[2022-12-08T17:52:48.406] _job_complete: JobId=53496 done
[2022-12-08T17:52:48.662] sched: Allocate JobId=53501 NodeList=cpu14 #CPUs=16 Partition=cpu-epyc
[2022-12-08T17:59:17.925] _job_complete: JobId=53495 WEXITSTATUS 0
[2022-12-08T17:59:17.925] _job_complete: JobId=53495 done
[2022-12-08T17:59:18.161] sched: Allocate JobId=53502 NodeList=cpu14 #CPUs=16 Partition=cpu-epyc
[2022-12-08T18:51:46.407] _job_complete: JobId=53571 WEXITSTATUS 0
[2022-12-08T18:51:46.413] _job_complete: JobId=53571 done
[2022-12-08T18:51:47.578] sched: Allocate JobId=53543 NodeList=gpu05 #CPUs=16 Partition=gpu-v100s
[2022-12-08T19:05:25.422] _job_complete: JobId=53497 WEXITSTATUS 0
[2022-12-08T19:05:25.422] _job_complete: JobId=53497 done
[2022-12-08T19:05:25.746] sched: Allocate JobId=53503 NodeList=cpu15 #CPUs=16 Partition=cpu-epyc
[2022-12-08T19:29:55.701] _job_complete: JobId=53499 WEXITSTATUS 0
[2022-12-08T19:29:55.702] _job_complete: JobId=53499 done
[2022-12-08T19:29:55.923] sched: Allocate JobId=53504 NodeList=cpu14 #CPUs=16 Partition=cpu-epyc
[2022-12-08T20:06:04.568] _job_complete: JobId=53501 WEXITSTATUS 0
[2022-12-08T20:06:04.568] _job_complete: JobId=53501 done
[2022-12-08T20:06:04.825] sched: Allocate JobId=53505 NodeList=cpu14 #CPUs=16 Partition=cpu-epyc
[2022-12-08T20:24:07.131] _job_complete: JobId=53500 WEXITSTATUS 0
[2022-12-08T20:24:07.132] _job_complete: JobId=53500 done
[2022-12-08T20:24:07.438] sched: Allocate JobId=53506 NodeList=cpu15 #CPUs=16 Partition=cpu-epyc
[2022-12-08T20:52:41.585] _job_complete: JobId=53502 WEXITSTATUS 0
[2022-12-08T20:52:41.586] _job_complete: JobId=53502 done
[2022-12-08T20:52:41.810] sched: Allocate JobId=53507 NodeList=cpu14 #CPUs=16 Partition=cpu-epyc
[2022-12-08T21:14:17.182] _job_complete: JobId=53399 WEXITSTATUS 1
[2022-12-08T21:14:17.182] _job_complete: JobId=53399 done
[2022-12-08T21:14:17.991] sched: Allocate JobId=53508 NodeList=cpu12 #CPUs=16 Partition=cpu-epyc
[2022-12-08T21:19:43.588] _job_complete: JobId=53498 WEXITSTATUS 0
[2022-12-08T21:19:43.588] _job_complete: JobId=53498 done
[2022-12-08T21:19:43.885] sched: Allocate JobId=53509 NodeList=cpu15 #CPUs=16 Partition=cpu-epyc
[2022-12-08T21:26:01.117] _job_complete: JobId=53503 WEXITSTATUS 0
[2022-12-08T21:26:01.117] _job_complete: JobId=53503 done
[2022-12-08T21:26:01.427] sched: Allocate JobId=53510 NodeList=cpu15 #CPUs=16 Partition=cpu-epyc
[2022-12-08T22:32:02.187] _job_complete: JobId=53505 WEXITSTATUS 0
[2022-12-08T22:32:02.187] _job_complete: JobId=53505 done
[2022-12-08T22:32:02.479] sched: Allocate JobId=53511 NodeList=cpu14 #CPUs=16 Partition=cpu-epyc
[2022-12-08T22:35:36.280] _job_complete: JobId=53504 WEXITSTATUS 0
[2022-12-08T22:35:36.281] _job_complete: JobId=53504 done
[2022-12-08T23:08:57.552] _job_complete: JobId=53506 WEXITSTATUS 0
[2022-12-08T23:08:57.552] _job_complete: JobId=53506 done
[2022-12-08T23:25:15.827] _job_complete: JobId=53508 WEXITSTATUS 0
[2022-12-08T23:25:15.828] _job_complete: JobId=53508 done
[2022-12-08T23:25:16.397] sched: Allocate JobId=53481 NodeList=cpu12 #CPUs=24 Partition=cpu-epyc
[2022-12-08T23:27:10.396] _job_complete: JobId=53507 WEXITSTATUS 0
[2022-12-08T23:27:10.396] _job_complete: JobId=53507 done
[2022-12-08T23:27:10.636] sched: Allocate JobId=53557 NodeList=cpu14 #CPUs=24 Partition=cpu-epyc
[2022-12-08T23:29:37.331] _job_complete: JobId=53509 WEXITSTATUS 0
[2022-12-08T23:29:37.331] _job_complete: JobId=53509 done
[2022-12-08T23:39:03.406] _job_complete: JobId=53510 WEXITSTATUS 0
[2022-12-08T23:39:03.406] _job_complete: JobId=53510 done
[2022-12-09T00:53:30.590] _slurm_rpc_submit_batch_job: JobId=53583 InitPrio=3200 usec=489
[2022-12-09T01:48:38.989] _job_complete: JobId=53478 WEXITSTATUS 2
[2022-12-09T01:48:38.996] _job_complete: JobId=53478 done
[2022-12-09T03:56:11.648] _job_complete: JobId=53557 WEXITSTATUS 0
[2022-12-09T03:56:11.654] _job_complete: JobId=53557 done
[2022-12-09T08:09:21.345] _slurm_rpc_submit_batch_job: JobId=53584 InitPrio=2200 usec=560
[2022-12-09T08:09:22.247] sched: Allocate JobId=53584 NodeList=cpu15 #CPUs=48 Partition=cpu-epyc
[2022-12-09T08:09:25.841] _job_complete: JobId=53584 WEXITSTATUS 1
[2022-12-09T08:09:25.841] _job_complete: JobId=53584 done
[2022-12-09T08:13:26.288] _slurm_rpc_submit_batch_job: JobId=53585 InitPrio=2200 usec=562
[2022-12-09T08:13:26.659] sched: Allocate JobId=53585 NodeList=cpu15 #CPUs=48 Partition=cpu-epyc
[2022-12-09T08:13:30.114] _job_complete: JobId=53585 WEXITSTATUS 1
[2022-12-09T08:13:30.114] _job_complete: JobId=53585 done
[2022-12-09T08:18:48.250] _slurm_rpc_submit_batch_job: JobId=53586 InitPrio=2200 usec=581
[2022-12-09T08:18:49.219] sched: Allocate JobId=53586 NodeList=cpu15 #CPUs=48 Partition=cpu-epyc
[2022-12-09T08:19:44.619] _slurm_rpc_kill_job: REQUEST_KILL_JOB JobId=53586 uid 548300630
[2022-12-09T08:20:06.336] _slurm_rpc_submit_batch_job: JobId=53587 InitPrio=2200 usec=429
[2022-12-09T08:20:07.319] sched: Allocate JobId=53587 NodeList=cpu15 #CPUs=48 Partition=cpu-epyc
[2022-12-09T08:35:26.057] _slurm_rpc_submit_batch_job: JobId=53588 InitPrio=2200 usec=530
[2022-12-09T08:36:49.371] _slurm_rpc_submit_batch_job: JobId=53589 InitPrio=2200 usec=489
[2022-12-09T08:36:49.415] sched: Allocate JobId=53589 NodeList=cpu05 #CPUs=64 Partition=cpu-opteron
[2022-12-09T08:36:53.805] _job_complete: JobId=53589 WEXITSTATUS 1
[2022-12-09T08:36:53.806] _job_complete: JobId=53589 done
[2022-12-09T08:48:49.921] _job_complete: JobId=53465 WEXITSTATUS 0
[2022-12-09T08:48:49.921] _job_complete: JobId=53465 done
[2022-12-09T08:48:50.334] sched: Allocate JobId=53588 NodeList=cpu13 #CPUs=48 Partition=cpu-epyc
[2022-12-09T08:48:51.748] _job_complete: JobId=53588 WEXITSTATUS 1
[2022-12-09T08:48:51.748] _job_complete: JobId=53588 done
[2022-12-09T08:53:49.119] Time limit exhausted for JobId=53328
[2022-12-09T08:59:52.860] _slurm_rpc_submit_batch_job: JobId=53590 InitPrio=2200 usec=698
[2022-12-09T08:59:53.713] sched: Allocate JobId=53590 NodeList=cpu05 #CPUs=64 Partition=cpu-opteron
[2022-12-09T09:04:59.739] _job_complete: JobId=53590 WEXITSTATUS 0
[2022-12-09T09:04:59.739] _job_complete: JobId=53590 done
[2022-12-09T10:20:25.287] _slurm_rpc_submit_batch_job: JobId=53591 InitPrio=2000 usec=615
[2022-12-09T10:20:25.335] sched: Allocate JobId=53591 NodeList=cpu12 #CPUs=8 Partition=cpu-epyc
[2022-12-09T10:20:28.002] _slurm_rpc_submit_batch_job: JobId=53592 InitPrio=2000 usec=511
[2022-12-09T10:20:28.322] sched: Allocate JobId=53592 NodeList=cpu12 #CPUs=8 Partition=cpu-epyc
[2022-12-09T10:20:30.348] _slurm_rpc_submit_batch_job: JobId=53593 InitPrio=2000 usec=519
[2022-12-09T10:20:31.325] sched: Allocate JobId=53593 NodeList=cpu12 #CPUs=8 Partition=cpu-epyc
[2022-12-09T10:20:32.699] _slurm_rpc_submit_batch_job: JobId=53594 InitPrio=2000 usec=559
[2022-12-09T10:20:34.329] sched: Allocate JobId=53594 NodeList=cpu14 #CPUs=8 Partition=cpu-epyc
[2022-12-09T10:20:35.082] _slurm_rpc_submit_batch_job: JobId=53595 InitPrio=2000 usec=567
[2022-12-09T10:20:37.333] sched: Allocate JobId=53595 NodeList=cpu14 #CPUs=8 Partition=cpu-epyc
[2022-12-09T10:20:37.514] _slurm_rpc_submit_batch_job: JobId=53596 InitPrio=2000 usec=496
[2022-12-09T10:20:40.051] _slurm_rpc_submit_batch_job: JobId=53597 InitPrio=2000 usec=558
[2022-12-09T10:20:40.339] sched: Allocate JobId=53596 NodeList=cpu14 #CPUs=8 Partition=cpu-epyc
[2022-12-09T10:20:40.340] sched: Allocate JobId=53597 NodeList=cpu14 #CPUs=8 Partition=cpu-epyc
[2022-12-09T10:20:42.555] _slurm_rpc_submit_batch_job: JobId=53598 InitPrio=2000 usec=490
[2022-12-09T10:20:43.343] sched: Allocate JobId=53598 NodeList=cpu13 #CPUs=8 Partition=cpu-epyc
[2022-12-09T10:20:44.963] _slurm_rpc_submit_batch_job: JobId=53599 InitPrio=2000 usec=579
[2022-12-09T10:20:46.347] sched: Allocate JobId=53599 NodeList=cpu13 #CPUs=8 Partition=cpu-epyc
[2022-12-09T10:20:47.522] _slurm_rpc_submit_batch_job: JobId=53600 InitPrio=2000 usec=522
[2022-12-09T10:20:49.351] sched: Allocate JobId=53600 NodeList=cpu13 #CPUs=8 Partition=cpu-epyc
[2022-12-09T10:20:49.843] _slurm_rpc_submit_batch_job: JobId=53601 InitPrio=2000 usec=509
[2022-12-09T10:20:52.355] sched: Allocate JobId=53601 NodeList=cpu13 #CPUs=8 Partition=cpu-epyc
[2022-12-09T10:20:52.365] _slurm_rpc_submit_batch_job: JobId=53602 InitPrio=2000 usec=467
[2022-12-09T10:20:54.736] _slurm_rpc_submit_batch_job: JobId=53603 InitPrio=2000 usec=480
[2022-12-09T10:20:55.358] sched: Allocate JobId=53602 NodeList=cpu13 #CPUs=8 Partition=cpu-epyc
[2022-12-09T10:20:55.359] sched: Allocate JobId=53603 NodeList=cpu13 #CPUs=8 Partition=cpu-epyc
[2022-12-09T10:21:01.636] _slurm_rpc_submit_batch_job: JobId=53604 InitPrio=2000 usec=478
[2022-12-09T10:21:04.108] _slurm_rpc_submit_batch_job: JobId=53605 InitPrio=2000 usec=514
[2022-12-09T10:21:06.591] _slurm_rpc_submit_batch_job: JobId=53606 InitPrio=2000 usec=506
[2022-12-09T10:21:09.299] _slurm_rpc_submit_batch_job: JobId=53607 InitPrio=2000 usec=578
[2022-12-09T10:21:12.779] _slurm_rpc_submit_batch_job: JobId=53608 InitPrio=2000 usec=563
[2022-12-09T10:21:16.243] _slurm_rpc_submit_batch_job: JobId=53609 InitPrio=2000 usec=594
[2022-12-09T10:21:19.723] _slurm_rpc_submit_batch_job: JobId=53610 InitPrio=2000 usec=506
[2022-12-09T10:21:22.275] _slurm_rpc_submit_batch_job: JobId=53611 InitPrio=2000 usec=599
[2022-12-09T10:21:24.950] _slurm_rpc_submit_batch_job: JobId=53612 InitPrio=2000 usec=533
[2022-12-09T10:21:27.741] _slurm_rpc_submit_batch_job: JobId=53613 InitPrio=2000 usec=647
[2022-12-09T10:21:30.259] _slurm_rpc_submit_batch_job: JobId=53614 InitPrio=2000 usec=499
[2022-12-09T10:21:32.724] _slurm_rpc_submit_batch_job: JobId=53615 InitPrio=2000 usec=575
[2022-12-09T10:21:35.981] _slurm_rpc_submit_batch_job: JobId=53616 InitPrio=2000 usec=463
[2022-12-09T10:21:38.444] _slurm_rpc_submit_batch_job: JobId=53617 InitPrio=2000 usec=485
[2022-12-09T10:21:41.026] _slurm_rpc_submit_batch_job: JobId=53618 InitPrio=2000 usec=543
[2022-12-09T10:42:35.791] _slurm_rpc_submit_batch_job: JobId=53619 InitPrio=2200 usec=547
[2022-12-09T10:42:36.028] sched: Allocate JobId=53619 NodeList=cpu05 #CPUs=64 Partition=cpu-opteron
[2022-12-09T10:42:36.678] _job_complete: JobId=53619 WEXITSTATUS 127
[2022-12-09T10:42:36.678] _job_complete: JobId=53619 done
[2022-12-09T10:46:50.470] _slurm_rpc_submit_batch_job: JobId=53620 InitPrio=2200 usec=560
[2022-12-09T10:46:51.446] sched: Allocate JobId=53620 NodeList=cpu05 #CPUs=64 Partition=cpu-opteron
[2022-12-09T10:46:52.104] _job_complete: JobId=53620 WEXITSTATUS 127
[2022-12-09T10:46:52.105] _job_complete: JobId=53620 done
[2022-12-09T11:49:01.204] _job_complete: JobId=53543 WEXITSTATUS 0
[2022-12-09T11:49:01.211] _job_complete: JobId=53543 done
[2022-12-09T11:49:02.408] sched: Allocate JobId=53583 NodeList=gpu05 #CPUs=16 Partition=gpu-v100s
[2022-12-09T11:49:02.427] sched: Allocate JobId=53576 NodeList=gpu05 #CPUs=8 Partition=gpu-v100s
[2022-12-09T12:51:42.886] _job_complete: JobId=53511 WEXITSTATUS 0
[2022-12-09T12:51:42.887] _job_complete: JobId=53511 done
[2022-12-09T12:51:43.269] sched: Allocate JobId=53604 NodeList=cpu14 #CPUs=8 Partition=cpu-epyc
[2022-12-09T12:51:43.270] sched: Allocate JobId=53605 NodeList=cpu14 #CPUs=8 Partition=cpu-epyc
[2022-12-09T13:08:36.303] _job_complete: JobId=53479 WEXITSTATUS 2
[2022-12-09T13:08:36.309] _job_complete: JobId=53479 done
[2022-12-09T14:15:41.708] _slurm_rpc_submit_batch_job: JobId=53621 InitPrio=13800 usec=503
[2022-12-09T14:15:42.440] sched: Allocate JobId=53621 NodeList=cpu05 #CPUs=1 Partition=cpu-opteron
[2022-12-09T14:50:44.129] _slurm_rpc_submit_batch_job: JobId=53622 InitPrio=1000 usec=571
[2022-12-09T14:50:44.808] sched: Allocate JobId=53622 NodeList=cpu05 #CPUs=1 Partition=cpu-opteron
[2022-12-09T14:50:46.203] _job_complete: JobId=53622 WEXITSTATUS 0
[2022-12-09T14:50:46.203] _job_complete: JobId=53622 done
[2022-12-09T14:53:35.505] _job_complete: JobId=53587 WEXITSTATUS 1
[2022-12-09T14:53:35.505] _job_complete: JobId=53587 done
[2022-12-09T14:53:35.833] sched: Allocate JobId=53606 NodeList=cpu15 #CPUs=8 Partition=cpu-epyc
[2022-12-09T14:53:35.834] sched: Allocate JobId=53607 NodeList=cpu15 #CPUs=8 Partition=cpu-epyc
[2022-12-09T14:53:35.835] sched: Allocate JobId=53608 NodeList=cpu15 #CPUs=8 Partition=cpu-epyc
[2022-12-09T14:53:35.836] sched: Allocate JobId=53609 NodeList=cpu15 #CPUs=8 Partition=cpu-epyc
[2022-12-09T14:53:35.837] sched: Allocate JobId=53610 NodeList=cpu15 #CPUs=8 Partition=cpu-epyc
[2022-12-09T14:53:35.838] sched: Allocate JobId=53611 NodeList=cpu15 #CPUs=8 Partition=cpu-epyc
[2022-12-09T15:14:05.919] _slurm_rpc_submit_batch_job: JobId=53623 InitPrio=1000 usec=524
[2022-12-09T15:14:06.484] sched: Allocate JobId=53623 NodeList=cpu05 #CPUs=1 Partition=cpu-opteron
[2022-12-09T15:14:08.049] _job_complete: JobId=53623 WEXITSTATUS 0
[2022-12-09T15:14:08.049] _job_complete: JobId=53623 done
[2022-12-09T15:15:50.609] Time limit exhausted for JobId=53621
[2022-12-09T15:18:02.859] _job_complete: JobId=53583 WEXITSTATUS 0
[2022-12-09T15:18:02.865] _job_complete: JobId=53583 done
[2022-12-09T15:28:19.868] _slurm_rpc_submit_batch_job: JobId=53624 InitPrio=1000 usec=466
[2022-12-09T15:28:20.160] sched: Allocate JobId=53624 NodeList=cpu05 #CPUs=16 Partition=cpu-opteron
[2022-12-09T15:28:23.728] _slurm_rpc_submit_batch_job: JobId=53625 InitPrio=1000 usec=430
[2022-12-09T15:28:24.165] sched: Allocate JobId=53625 NodeList=cpu05 #CPUs=16 Partition=cpu-opteron
[2022-12-09T15:40:01.271] _slurm_rpc_submit_batch_job: JobId=53626 InitPrio=13800 usec=570
[2022-12-09T15:40:01.396] sched: Allocate JobId=53626 NodeList=cpu05 #CPUs=1 Partition=cpu-opteron
[2022-12-09T15:56:17.561] _job_complete: JobId=53626 WEXITSTATUS 0
[2022-12-09T15:56:17.561] _job_complete: JobId=53626 done
[2022-12-09T16:12:59.504] _job_complete: JobId=53625 WEXITSTATUS 0
[2022-12-09T16:12:59.504] _job_complete: JobId=53625 done
[2022-12-09T16:27:09.723] _job_complete: JobId=53624 WEXITSTATUS 0
[2022-12-09T16:27:09.723] _job_complete: JobId=53624 done
[2022-12-09T17:14:26.694] _slurm_rpc_submit_batch_job: JobId=53627 InitPrio=1000 usec=566
[2022-12-09T17:14:27.278] sched: Allocate JobId=53627 NodeList=cpu05 #CPUs=1 Partition=cpu-opteron
[2022-12-09T17:15:23.895] _job_complete: JobId=53627 WEXITSTATUS 0
[2022-12-09T17:15:23.895] _job_complete: JobId=53627 done
[2022-12-09T17:17:14.128] No nodes satisfy requirements for JobId=53628 in partition gpu-k40c
[2022-12-09T17:17:14.128] _slurm_rpc_submit_batch_job: Requested node configuration is not available
[2022-12-09T17:17:36.152] _slurm_rpc_submit_batch_job: JobId=53629 InitPrio=1000 usec=638
[2022-12-09T17:17:36.611] sched: Allocate JobId=53629 NodeList=gpu03 #CPUs=16 Partition=gpu-k10
[2022-12-09T17:17:49.741] _job_complete: JobId=53629 WEXITSTATUS 127
[2022-12-09T17:17:49.741] _job_complete: JobId=53629 done
[2022-12-09T17:23:22.929] _slurm_rpc_submit_batch_job: JobId=53630 InitPrio=1000 usec=616
[2022-12-09T17:23:23.202] sched: Allocate JobId=53630 NodeList=gpu03 #CPUs=16 Partition=gpu-k10
[2022-12-09T19:24:49.450] _job_complete: JobId=53595 WEXITSTATUS 0
[2022-12-09T19:24:49.451] _job_complete: JobId=53595 done
[2022-12-09T19:24:49.734] sched: Allocate JobId=53612 NodeList=cpu14 #CPUs=8 Partition=cpu-epyc
[2022-12-09T19:29:39.923] _job_complete: JobId=53591 WEXITSTATUS 0
[2022-12-09T19:29:39.924] _job_complete: JobId=53591 done
[2022-12-09T19:29:40.360] sched: Allocate JobId=53613 NodeList=cpu12 #CPUs=8 Partition=cpu-epyc
[2022-12-09T19:43:23.415] _job_complete: JobId=53600 WEXITSTATUS 0
[2022-12-09T19:43:23.415] _job_complete: JobId=53600 done
[2022-12-09T19:43:23.838] sched: Allocate JobId=53614 NodeList=cpu13 #CPUs=8 Partition=cpu-epyc
[2022-12-09T19:50:40.348] _slurm_rpc_submit_batch_job: JobId=53631 InitPrio=3000 usec=497
[2022-12-09T19:50:41.348] sched: Allocate JobId=53631 NodeList=gpu05 #CPUs=16 Partition=gpu-v100s
[2022-12-09T20:12:36.753] _job_complete: JobId=53598 WEXITSTATUS 0
[2022-12-09T20:12:36.753] _job_complete: JobId=53598 done
[2022-12-09T20:12:37.174] sched: Allocate JobId=53615 NodeList=cpu13 #CPUs=8 Partition=cpu-epyc
[2022-12-09T20:18:28.081] _job_complete: JobId=53601 WEXITSTATUS 0
[2022-12-09T20:18:28.081] _job_complete: JobId=53601 done
[2022-12-09T20:18:28.610] sched: Allocate JobId=53616 NodeList=cpu13 #CPUs=8 Partition=cpu-epyc
[2022-12-09T20:34:40.953] _job_complete: JobId=53593 WEXITSTATUS 0
[2022-12-09T20:34:40.953] _job_complete: JobId=53593 done
[2022-12-09T20:34:41.433] sched: Allocate JobId=53617 NodeList=cpu12 #CPUs=8 Partition=cpu-epyc
[2022-12-09T22:03:04.208] _slurm_rpc_submit_batch_job: JobId=53632 InitPrio=10600 usec=584
[2022-12-09T22:03:34.219] _slurm_rpc_submit_batch_job: JobId=53633 InitPrio=10600 usec=323
[2022-12-09T22:03:34.796] sched: Allocate JobId=53633 NodeList=cpu05 #CPUs=1 Partition=cpu-opteron
[2022-12-09T22:03:39.910] _slurm_rpc_kill_job: REQUEST_KILL_JOB JobId=53632 uid 548200121
[2022-12-09T22:05:56.517] _job_complete: JobId=53592 WEXITSTATUS 0
[2022-12-09T22:05:56.517] _job_complete: JobId=53592 done
[2022-12-09T22:05:56.947] sched: Allocate JobId=53618 NodeList=cpu12 #CPUs=8 Partition=cpu-epyc
[2022-12-09T22:36:07.683] _job_complete: JobId=53603 WEXITSTATUS 0
[2022-12-09T22:36:07.683] _job_complete: JobId=53603 done
[2022-12-09T23:01:41.171] _job_complete: JobId=53594 WEXITSTATUS 0
[2022-12-09T23:01:41.171] _job_complete: JobId=53594 done
[2022-12-09T23:03:50.161] Time limit exhausted for JobId=53633
[2022-12-09T23:10:56.933] _slurm_rpc_submit_batch_job: JobId=53634 InitPrio=10600 usec=367
[2022-12-09T23:10:57.952] sched: Allocate JobId=53634 NodeList=cpu05 #CPUs=1 Partition=cpu-opteron
[2022-12-09T23:31:40.476] _job_complete: JobId=53596 WEXITSTATUS 0
[2022-12-09T23:31:40.477] _job_complete: JobId=53596 done
[2022-12-10T00:11:20.778] Time limit exhausted for JobId=53634
[2022-12-10T00:13:00.178] _slurm_rpc_submit_batch_job: JobId=53635 InitPrio=10600 usec=467
[2022-12-10T00:13:00.929] sched: Allocate JobId=53635 NodeList=cpu05 #CPUs=1 Partition=cpu-opteron
[2022-12-10T00:24:53.571] _slurm_rpc_kill_job: REQUEST_KILL_JOB JobId=53635 uid 548200121
[2022-12-10T01:03:09.886] _job_complete: JobId=53604 WEXITSTATUS 0
[2022-12-10T01:03:09.886] _job_complete: JobId=53604 done
[2022-12-10T01:20:17.530] _job_complete: JobId=53609 WEXITSTATUS 0
[2022-12-10T01:20:17.530] _job_complete: JobId=53609 done
[2022-12-10T01:38:06.670] _slurm_rpc_submit_batch_job: JobId=53636 InitPrio=3000 usec=615
[2022-12-10T01:46:47.253] _job_complete: JobId=53597 WEXITSTATUS 0
[2022-12-10T01:46:47.254] _job_complete: JobId=53597 done
[2022-12-10T02:07:38.425] _job_complete: JobId=53576 WEXITSTATUS 0
[2022-12-10T02:07:38.431] _job_complete: JobId=53576 done
[2022-12-10T02:07:42.611] sched: Allocate JobId=53636 NodeList=gpu05 #CPUs=16 Partition=gpu-v100s
[2022-12-10T02:27:39.832] _job_complete: JobId=53611 WEXITSTATUS 0
[2022-12-10T02:27:39.832] _job_complete: JobId=53611 done
[2022-12-10T02:59:36.803] _job_complete: JobId=53608 WEXITSTATUS 0
[2022-12-10T02:59:36.803] _job_complete: JobId=53608 done
[2022-12-10T03:04:47.727] _job_complete: JobId=53599 WEXITSTATUS 0
[2022-12-10T03:04:47.727] _job_complete: JobId=53599 done
[2022-12-10T03:42:38.162] _job_complete: JobId=53631 WEXITSTATUS 0
[2022-12-10T03:42:38.168] _job_complete: JobId=53631 done
[2022-12-10T04:11:35.968] _job_complete: JobId=53607 WEXITSTATUS 0
[2022-12-10T04:11:35.969] _job_complete: JobId=53607 done
[2022-12-10T04:23:56.711] _job_complete: JobId=53481 WEXITSTATUS 0
[2022-12-10T04:23:56.717] _job_complete: JobId=53481 done
[2022-12-10T04:55:48.370] _job_complete: JobId=53610 WEXITSTATUS 0
[2022-12-10T04:55:48.370] _job_complete: JobId=53610 done
[2022-12-10T05:29:17.185] _job_complete: JobId=53612 WEXITSTATUS 0
[2022-12-10T05:29:17.185] _job_complete: JobId=53612 done
[2022-12-10T05:39:04.814] _job_complete: JobId=53636 WEXITSTATUS 0
[2022-12-10T05:39:04.820] _job_complete: JobId=53636 done
[2022-12-10T05:39:06.911] sched: Allocate JobId=53578 NodeList=gpu05 #CPUs=8 Partition=gpu-v100s
[2022-12-10T05:40:25.163] _job_complete: JobId=53616 WEXITSTATUS 0
[2022-12-10T05:40:25.163] _job_complete: JobId=53616 done
[2022-12-10T06:53:51.378] _job_complete: JobId=53605 WEXITSTATUS 0
[2022-12-10T06:53:51.378] _job_complete: JobId=53605 done
[2022-12-10T08:13:59.267] _job_complete: JobId=53618 WEXITSTATUS 0
[2022-12-10T08:13:59.267] _job_complete: JobId=53618 done
[2022-12-10T08:43:03.461] _job_complete: JobId=53617 WEXITSTATUS 0
[2022-12-10T08:43:03.461] _job_complete: JobId=53617 done
[2022-12-10T11:03:07.068] _slurm_rpc_submit_batch_job: JobId=53637 InitPrio=10400 usec=590
[2022-12-10T11:03:07.597] sched: Allocate JobId=53637 NodeList=cpu05 #CPUs=16 Partition=cpu-opteron
[2022-12-10T11:03:14.167] _job_complete: JobId=53637 WEXITSTATUS 0
[2022-12-10T11:03:14.168] _job_complete: JobId=53637 done
[2022-12-10T11:14:46.726] _slurm_rpc_submit_batch_job: JobId=53638 InitPrio=400 usec=491
[2022-12-10T11:14:46.792] sched: Allocate JobId=53638 NodeList=cpu05 #CPUs=64 Partition=cpu-opteron
[2022-12-10T11:17:02.649] _slurm_rpc_submit_batch_job: JobId=53639 InitPrio=400 usec=462
[2022-12-10T11:17:03.524] sched: Allocate JobId=53639 NodeList=cpu13 #CPUs=24 Partition=cpu-epyc
[2022-12-10T11:19:35.857] _slurm_rpc_submit_batch_job: JobId=53640 InitPrio=400 usec=540
[2022-12-10T11:19:36.711] sched: Allocate JobId=53640 NodeList=cpu08 #CPUs=64 Partition=cpu-opteron
[2022-12-10T11:25:19.616] _slurm_rpc_submit_batch_job: JobId=53641 InitPrio=400 usec=467
[2022-12-10T11:25:20.229] sched: Allocate JobId=53641 NodeList=cpu10 #CPUs=64 Partition=cpu-opteron
[2022-12-10T11:27:33.076] _slurm_rpc_submit_batch_job: JobId=53642 InitPrio=400 usec=538
[2022-12-10T11:28:39.449] _slurm_rpc_submit_batch_job: JobId=53643 InitPrio=400 usec=506
[2022-12-10T11:30:48.190] _slurm_rpc_submit_batch_job: JobId=53644 InitPrio=400 usec=462
[2022-12-10T11:30:48.774] sched: Allocate JobId=53644 NodeList=cpu12 #CPUs=24 Partition=cpu-epyc
[2022-12-10T11:32:21.598] _slurm_rpc_submit_batch_job: JobId=53645 InitPrio=400 usec=513
[2022-12-10T11:32:21.987] sched: Allocate JobId=53645 NodeList=cpu15 #CPUs=24 Partition=cpu-epyc
[2022-12-10T11:32:24.665] _job_complete: JobId=53645 WEXITSTATUS 139
[2022-12-10T11:32:24.666] _job_complete: JobId=53645 done
[2022-12-10T11:34:38.498] _slurm_rpc_submit_batch_job: JobId=53646 InitPrio=400 usec=476
[2022-12-10T11:34:39.165] sched: Allocate JobId=53646 NodeList=cpu15 #CPUs=24 Partition=cpu-epyc
[2022-12-10T11:36:05.344] _slurm_rpc_submit_batch_job: JobId=53647 InitPrio=400 usec=495
[2022-12-10T11:36:05.531] sched: Allocate JobId=53647 NodeList=cpu14 #CPUs=24 Partition=cpu-epyc
[2022-12-10T11:42:36.005] _slurm_rpc_submit_batch_job: JobId=53648 InitPrio=400 usec=469
[2022-12-10T11:42:36.231] sched: Allocate JobId=53648 NodeList=cpu14 #CPUs=24 Partition=cpu-epyc
[2022-12-10T11:44:31.242] _slurm_rpc_submit_batch_job: JobId=53649 InitPrio=400 usec=461
[2022-12-10T11:45:48.867] _slurm_rpc_submit_batch_job: JobId=53650 InitPrio=15400 usec=495
[2022-12-10T11:45:49.506] sched: Allocate JobId=53650 NodeList=gpu04 #CPUs=4 Partition=gpu-k40c
[2022-12-10T11:51:35.823] _job_complete: JobId=53518 WEXITSTATUS 0
[2022-12-10T11:51:35.823] _job_complete: JobId=53518 done
[2022-12-10T11:56:49.206] _slurm_rpc_submit_batch_job: JobId=53651 InitPrio=3000 usec=448
[2022-12-10T11:57:32.479] _slurm_rpc_submit_batch_job: JobId=53652 InitPrio=3000 usec=464
[2022-12-10T11:59:58.894] _job_complete: JobId=53565 WEXITSTATUS 2
[2022-12-10T11:59:58.895] _job_complete: JobId=53565 done
[2022-12-10T12:00:02.145] sched: Allocate JobId=53642 NodeList=cpu07 #CPUs=64 Partition=cpu-opteron
[2022-12-10T12:03:49.021] _slurm_rpc_submit_batch_job: JobId=53653 InitPrio=400 usec=468
[2022-12-10T12:45:51.119] Time limit exhausted for JobId=53650
[2022-12-10T13:04:44.616] _job_complete: JobId=53606 WEXITSTATUS 0
[2022-12-10T13:04:44.617] _job_complete: JobId=53606 done
[2022-12-10T14:47:16.427] _job_complete: JobId=53615 WEXITSTATUS 0
[2022-12-10T14:47:16.427] _job_complete: JobId=53615 done
[2022-12-10T16:14:15.758] _slurm_rpc_submit_batch_job: JobId=53654 InitPrio=17600 usec=606
[2022-12-10T16:14:28.670] _slurm_rpc_submit_batch_job: JobId=53655 InitPrio=17600 usec=365
[2022-12-10T16:14:29.615] sched: Allocate JobId=53655 NodeList=cpu09 #CPUs=1 Partition=cpu-opteron
[2022-12-10T16:53:46.655] _slurm_rpc_submit_batch_job: JobId=53656 InitPrio=200 usec=629
[2022-12-10T17:14:51.598] Time limit exhausted for JobId=53655
[2022-12-10T18:33:33.112] _job_complete: JobId=53415 WEXITSTATUS 0
[2022-12-10T18:33:33.118] _job_complete: JobId=53415 done
[2022-12-10T18:33:36.358] sched: Allocate JobId=53643 NodeList=cpu01 #CPUs=64 Partition=cpu-opteron
[2022-12-10T20:43:30.121] _slurm_rpc_submit_batch_job: JobId=53657 InitPrio=400 usec=693
[2022-12-10T22:01:58.286] sched: _slurm_rpc_allocate_resources JobId=53658 NodeList=(null) usec=1073
[2022-12-10T22:01:59.181] sched: Allocate JobId=53658 NodeList=gpu04 #CPUs=8 Partition=gpu-k40c
[2022-12-10T22:07:13.139] _job_complete: JobId=53646 WEXITSTATUS 0
[2022-12-10T22:07:13.145] _job_complete: JobId=53646 done
[2022-12-10T22:07:14.090] sched: Allocate JobId=53649 NodeList=cpu15 #CPUs=24 Partition=cpu-epyc
[2022-12-10T22:09:07.179] _job_complete: JobId=53658 WEXITSTATUS 0
[2022-12-10T22:09:07.179] _job_complete: JobId=53658 done
[2022-12-10T22:18:28.834] _job_complete: JobId=53613 WEXITSTATUS 0
[2022-12-10T22:18:28.834] _job_complete: JobId=53613 done
[2022-12-10T22:32:22.946] _slurm_rpc_submit_batch_job: JobId=53659 InitPrio=4000 usec=513
[2022-12-10T22:32:23.851] sched: Allocate JobId=53659 NodeList=cpu09 #CPUs=16 Partition=cpu-opteron
[2022-12-10T22:41:32.936] _slurm_rpc_submit_batch_job: JobId=53660 InitPrio=4000 usec=531
[2022-12-10T22:41:32.951] sched: Allocate JobId=53660 NodeList=cpu09 #CPUs=16 Partition=cpu-opteron
[2022-12-11T00:34:13.745] _job_complete: JobId=53659 OOM failure
[2022-12-11T00:34:13.750] _job_complete: JobId=53659 done
[2022-12-11T00:47:13.628] _job_complete: JobId=53660 OOM failure
[2022-12-11T00:47:13.629] _job_complete: JobId=53660 done
[2022-12-11T01:36:50.904] _slurm_rpc_submit_batch_job: JobId=53661 InitPrio=17600 usec=494
[2022-12-11T01:36:51.858] sched: Allocate JobId=53661 NodeList=cpu09 #CPUs=1 Partition=cpu-opteron
[2022-12-11T02:14:47.242] _job_complete: JobId=53639 WEXITSTATUS 0
[2022-12-11T02:14:47.247] _job_complete: JobId=53639 done
[2022-12-11T02:17:54.303] _job_complete: JobId=53602 WEXITSTATUS 0
[2022-12-11T02:17:54.303] _job_complete: JobId=53602 done
[2022-12-11T02:33:24.382] _job_complete: JobId=53644 WEXITSTATUS 0
[2022-12-11T02:33:24.383] _job_complete: JobId=53644 done
[2022-12-11T02:33:25.380] sched: Allocate JobId=53656 NodeList=cpu12 #CPUs=48 Partition=cpu-epyc
[2022-12-11T02:35:39.988] _slurm_rpc_submit_batch_job: JobId=53662 InitPrio=17600 usec=447
[2022-12-11T02:35:40.868] sched: Allocate JobId=53662 NodeList=cpu09 #CPUs=1 Partition=cpu-opteron
[2022-12-11T02:35:58.609] _job_complete: JobId=53614 WEXITSTATUS 0
[2022-12-11T02:35:58.610] _job_complete: JobId=53614 done
[2022-12-11T02:36:52.101] Time limit exhausted for JobId=53661
[2022-12-11T03:35:53.837] Time limit exhausted for JobId=53662
[2022-12-11T03:39:37.116] _job_complete: JobId=53408 WEXITSTATUS 1
[2022-12-11T03:39:37.121] _job_complete: JobId=53408 done
[2022-12-11T03:39:38.318] sched: Allocate JobId=53577 NodeList=gpu02 #CPUs=8 Partition=gpu-titan
[2022-12-11T05:05:42.973] _job_complete: JobId=53647 WEXITSTATUS 0
[2022-12-11T05:05:42.978] _job_complete: JobId=53647 done
[2022-12-11T05:05:43.892] sched: Allocate JobId=53653 NodeList=cpu09 #CPUs=64 Partition=cpu-opteron
[2022-12-11T06:37:12.448] _job_complete: JobId=53648 WEXITSTATUS 0
[2022-12-11T06:37:12.453] _job_complete: JobId=53648 done
[2022-12-11T06:44:33.470] _job_complete: JobId=53578 WEXITSTATUS 0
[2022-12-11T06:44:33.475] _job_complete: JobId=53578 done
[2022-12-11T06:44:36.700] sched: Allocate JobId=53651 NodeList=gpu05 #CPUs=16 Partition=gpu-v100s
[2022-12-11T06:44:36.701] sched: Allocate JobId=53652 NodeList=gpu05 #CPUs=16 Partition=gpu-v100s
[2022-12-11T10:00:23.283] _job_complete: JobId=53652 WEXITSTATUS 0
[2022-12-11T10:00:23.289] _job_complete: JobId=53652 done
[2022-12-11T10:03:11.467] _job_complete: JobId=53651 WEXITSTATUS 0
[2022-12-11T10:03:11.468] _job_complete: JobId=53651 done
[2022-12-11T10:03:13.556] sched: Allocate JobId=53579 NodeList=gpu05 #CPUs=8 Partition=gpu-v100s
[2022-12-11T10:03:40.436] _job_complete: JobId=53649 WEXITSTATUS 0
[2022-12-11T10:03:40.440] _job_complete: JobId=53649 done
[2022-12-11T11:21:50.026] _slurm_rpc_submit_batch_job: JobId=53663 InitPrio=3800 usec=598
[2022-12-11T14:36:11.687] _job_complete: JobId=53640 WEXITSTATUS 2
[2022-12-11T14:36:11.693] _job_complete: JobId=53640 done
[2022-12-11T14:36:14.975] sched: Allocate JobId=53663 NodeList=cpu08 #CPUs=16 Partition=cpu-opteron
[2022-12-11T15:47:43.095] _job_complete: JobId=53638 WEXITSTATUS 2
[2022-12-11T15:47:43.097] _job_complete: JobId=53638 done
[2022-12-11T15:47:46.325] sched: Allocate JobId=53657 NodeList=cpu05 #CPUs=64 Partition=cpu-opteron
[2022-12-11T19:12:25.648] _job_complete: JobId=53657 WEXITSTATUS 0
[2022-12-11T19:12:25.653] _job_complete: JobId=53657 done
[2022-12-11T19:32:52.393] _job_complete: JobId=53409 WEXITSTATUS 0
[2022-12-11T19:32:52.398] _job_complete: JobId=53409 done
[2022-12-11T20:47:39.901] _slurm_rpc_submit_batch_job: JobId=53664 InitPrio=2400 usec=684
[2022-12-11T20:48:25.292] _slurm_rpc_submit_batch_job: JobId=53665 InitPrio=2400 usec=593
[2022-12-11T21:58:24.098] _job_complete: JobId=53577 WEXITSTATUS 0
[2022-12-11T21:58:24.105] _job_complete: JobId=53577 done
[2022-12-11T22:21:55.470] Time limit exhausted for JobId=53401
[2022-12-11T23:11:21.228] _slurm_rpc_submit_batch_job: JobId=53666 InitPrio=2800 usec=529
[2022-12-11T23:27:24.591] _slurm_rpc_submit_batch_job: JobId=53667 InitPrio=2800 usec=565
[2022-12-12T01:21:59.749] _slurm_rpc_submit_batch_job: JobId=53668 InitPrio=17600 usec=477
[2022-12-12T01:21:59.831] sched: Allocate JobId=53668 NodeList=cpu08 #CPUs=1 Partition=cpu-opteron
[2022-12-12T01:38:01.349] _slurm_rpc_submit_batch_job: JobId=53669 InitPrio=17600 usec=415
[2022-12-12T01:38:01.803] sched: Allocate JobId=53669 NodeList=gpu04 #CPUs=1 Partition=gpu-k40c
[2022-12-12T01:40:34.810] _slurm_rpc_kill_job: REQUEST_KILL_JOB JobId=53669 uid 548300670
[2022-12-12T01:40:40.995] _slurm_rpc_kill_job: REQUEST_KILL_JOB JobId=53654 uid 548300670
[2022-12-12T01:40:52.044] _slurm_rpc_submit_batch_job: JobId=53670 InitPrio=17600 usec=438
[2022-12-12T01:40:53.011] sched: Allocate JobId=53670 NodeList=gpu02 #CPUs=1 Partition=gpu-titan
[2022-12-12T02:22:26.520] Time limit exhausted for JobId=53668
[2022-12-12T02:40:56.409] Time limit exhausted for JobId=53670
[2022-12-12T05:49:40.123] _job_complete: JobId=53642 WEXITSTATUS 0
[2022-12-12T05:49:40.129] _job_complete: JobId=53642 done
[2022-12-12T08:24:29.138] _slurm_rpc_submit_batch_job: JobId=53671 InitPrio=14000 usec=526
[2022-12-12T08:24:30.025] sched: Allocate JobId=53671 NodeList=cpu04 #CPUs=1 Partition=cpu-opteron
[2022-12-12T08:57:57.660] _slurm_rpc_submit_batch_job: JobId=53672 InitPrio=1600 usec=1085
[2022-12-12T08:57:58.397] sched: Allocate JobId=53672 NodeList=cpu13 #CPUs=8 Partition=cpu-epyc
[2022-12-12T09:02:28.969] _job_complete: JobId=53653 WEXITSTATUS 2
[2022-12-12T09:02:28.974] _job_complete: JobId=53653 done
[2022-12-12T09:12:00.852] Time limit exhausted for JobId=53402
[2022-12-12T09:18:50.587] _slurm_rpc_submit_batch_job: JobId=53673 InitPrio=400 usec=449
[2022-12-12T09:18:51.478] sched: Allocate JobId=53673 NodeList=cpu09 #CPUs=64 Partition=cpu-opteron
[2022-12-12T09:23:57.350] _slurm_rpc_submit_batch_job: JobId=53674 InitPrio=400 usec=477
[2022-12-12T09:23:58.117] sched: Allocate JobId=53674 NodeList=cpu11 #CPUs=64 Partition=cpu-opteron
[2022-12-12T09:24:30.153] Time limit exhausted for JobId=53671
[2022-12-12T09:24:51.133] _slurm_rpc_submit_batch_job: JobId=53675 InitPrio=14000 usec=452
[2022-12-12T09:24:51.182] sched: Allocate JobId=53675 NodeList=cpu04 #CPUs=1 Partition=cpu-opteron
[2022-12-12T09:36:43.681] _slurm_rpc_submit_batch_job: JobId=53676 InitPrio=400 usec=549
[2022-12-12T09:36:44.487] sched: Allocate JobId=53676 NodeList=cpu05 #CPUs=64 Partition=cpu-opteron
[2022-12-12T09:38:53.156] _slurm_rpc_submit_batch_job: JobId=53677 InitPrio=1600 usec=677
[2022-12-12T09:38:53.651] sched: Allocate JobId=53677 NodeList=cpu13 #CPUs=8 Partition=cpu-epyc
[2022-12-12T09:38:55.541] _slurm_rpc_submit_batch_job: JobId=53678 InitPrio=1600 usec=516
[2022-12-12T09:38:56.654] sched: Allocate JobId=53678 NodeList=cpu13 #CPUs=8 Partition=cpu-epyc
[2022-12-12T09:38:58.405] _slurm_rpc_submit_batch_job: JobId=53679 InitPrio=1600 usec=509
[2022-12-12T09:38:59.657] sched: Allocate JobId=53679 NodeList=cpu13 #CPUs=8 Partition=cpu-epyc
[2022-12-12T09:39:00.893] _slurm_rpc_submit_batch_job: JobId=53680 InitPrio=1600 usec=578
[2022-12-12T09:39:02.660] sched: Allocate JobId=53680 NodeList=cpu13 #CPUs=8 Partition=cpu-epyc
[2022-12-12T09:39:03.414] _slurm_rpc_submit_batch_job: JobId=53681 InitPrio=1600 usec=491
[2022-12-12T09:39:05.664] sched: Allocate JobId=53681 NodeList=cpu13 #CPUs=8 Partition=cpu-epyc
[2022-12-12T09:39:05.888] _slurm_rpc_submit_batch_job: JobId=53682 InitPrio=1600 usec=514
[2022-12-12T09:39:08.501] _slurm_rpc_submit_batch_job: JobId=53683 InitPrio=1600 usec=641
[2022-12-12T09:39:08.668] sched: Allocate JobId=53682 NodeList=cpu14 #CPUs=8 Partition=cpu-epyc
[2022-12-12T09:39:08.668] sched: Allocate JobId=53683 NodeList=cpu14 #CPUs=8 Partition=cpu-epyc
[2022-12-12T09:39:11.014] _slurm_rpc_submit_batch_job: JobId=53684 InitPrio=1600 usec=561
[2022-12-12T09:39:11.672] sched: Allocate JobId=53684 NodeList=cpu14 #CPUs=8 Partition=cpu-epyc
[2022-12-12T09:39:13.813] _slurm_rpc_submit_batch_job: JobId=53685 InitPrio=1600 usec=486
[2022-12-12T09:39:14.676] sched: Allocate JobId=53685 NodeList=cpu14 #CPUs=8 Partition=cpu-epyc
[2022-12-12T09:39:16.726] _slurm_rpc_submit_batch_job: JobId=53686 InitPrio=1600 usec=551
[2022-12-12T09:39:17.277] sched/backfill: _start_job: Started JobId=53686 in cpu-epyc on cpu14
[2022-12-12T09:39:19.254] _slurm_rpc_submit_batch_job: JobId=53687 InitPrio=1600 usec=509
[2022-12-12T09:39:21.686] sched: Allocate JobId=53687 NodeList=cpu14 #CPUs=8 Partition=cpu-epyc
[2022-12-12T09:39:22.034] _slurm_rpc_submit_batch_job: JobId=53688 InitPrio=1600 usec=570
[2022-12-12T09:39:24.690] sched: Allocate JobId=53688 NodeList=cpu15 #CPUs=8 Partition=cpu-epyc
[2022-12-12T09:39:24.847] _slurm_rpc_submit_batch_job: JobId=53689 InitPrio=1600 usec=490
[2022-12-12T09:39:27.693] sched: Allocate JobId=53689 NodeList=cpu15 #CPUs=8 Partition=cpu-epyc
[2022-12-12T09:39:27.695] _slurm_rpc_submit_batch_job: JobId=53690 InitPrio=1600 usec=530
[2022-12-12T09:39:30.407] _slurm_rpc_submit_batch_job: JobId=53691 InitPrio=1600 usec=493
[2022-12-12T09:39:30.697] sched: Allocate JobId=53690 NodeList=cpu15 #CPUs=8 Partition=cpu-epyc
[2022-12-12T09:39:30.698] sched: Allocate JobId=53691 NodeList=cpu15 #CPUs=8 Partition=cpu-epyc
[2022-12-12T09:39:32.966] _slurm_rpc_submit_batch_job: JobId=53692 InitPrio=1600 usec=501
[2022-12-12T09:39:33.700] sched: Allocate JobId=53692 NodeList=cpu15 #CPUs=8 Partition=cpu-epyc
[2022-12-12T09:39:35.543] _slurm_rpc_submit_batch_job: JobId=53693 InitPrio=1600 usec=516
[2022-12-12T09:39:36.704] sched: Allocate JobId=53693 NodeList=cpu15 #CPUs=8 Partition=cpu-epyc
[2022-12-12T09:39:38.198] _slurm_rpc_submit_batch_job: JobId=53694 InitPrio=1600 usec=514
[2022-12-12T09:39:50.179] _slurm_rpc_submit_batch_job: JobId=53695 InitPrio=400 usec=474
[2022-12-12T09:40:49.698] _slurm_rpc_kill_job: REQUEST_KILL_JOB JobId=53695 uid 548200017
[2022-12-12T09:40:54.225] _slurm_rpc_submit_batch_job: JobId=53696 InitPrio=400 usec=483
[2022-12-12T09:40:54.802] sched: Allocate JobId=53696 NodeList=cpu07 #CPUs=64 Partition=cpu-opteron
[2022-12-12T10:18:00.507] _job_complete: JobId=53675 WEXITSTATUS 0
[2022-12-12T10:18:00.507] _job_complete: JobId=53675 done
[2022-12-12T10:54:14.356] _slurm_rpc_kill_job: REQUEST_KILL_JOB JobId=53673 uid 548200017
[2022-12-12T10:54:14.356] _slurm_rpc_kill_job: REQUEST_KILL_JOB JobId=53674 uid 548200017
[2022-12-12T10:54:14.356] _slurm_rpc_kill_job: REQUEST_KILL_JOB JobId=53643 uid 548200017
[2022-12-12T10:54:14.358] _slurm_rpc_kill_job: REQUEST_KILL_JOB JobId=53696 uid 548200017
[2022-12-12T10:54:14.358] _slurm_rpc_kill_job: REQUEST_KILL_JOB JobId=53676 uid 548200017
[2022-12-12T10:54:14.358] _slurm_rpc_kill_job: REQUEST_KILL_JOB JobId=53641 uid 548200017
[2022-12-12T10:58:40.664] _job_complete: JobId=53656 WEXITSTATUS 1
[2022-12-12T10:58:40.664] _job_complete: JobId=53656 done
[2022-12-12T10:58:41.186] sched: Allocate JobId=53694 NodeList=cpu12 #CPUs=8 Partition=cpu-epyc
[2022-12-12T11:06:46.017] _slurm_rpc_submit_batch_job: JobId=53697 InitPrio=14000 usec=520
[2022-12-12T11:06:46.790] sched: Allocate JobId=53697 NodeList=cpu01 #CPUs=1 Partition=cpu-opteron
[2022-12-12T11:08:31.148] _slurm_rpc_submit_batch_job: JobId=53698 InitPrio=400 usec=435
[2022-12-12T11:08:31.924] sched: Allocate JobId=53698 NodeList=cpu01 #CPUs=32 Partition=cpu-opteron
[2022-12-12T11:08:41.360] _slurm_rpc_submit_batch_job: JobId=53699 InitPrio=400 usec=493
[2022-12-12T11:08:41.924] sched: Allocate JobId=53699 NodeList=cpu08 #CPUs=32 Partition=cpu-opteron
[2022-12-12T11:08:50.872] _slurm_rpc_submit_batch_job: JobId=53700 InitPrio=400 usec=471
[2022-12-12T11:08:50.935] sched: Allocate JobId=53700 NodeList=cpu04 #CPUs=32 Partition=cpu-opteron
[2022-12-12T11:09:00.704] _slurm_rpc_submit_batch_job: JobId=53701 InitPrio=400 usec=494
[2022-12-12T11:09:00.947] sched: Allocate JobId=53701 NodeList=cpu04 #CPUs=32 Partition=cpu-opteron
[2022-12-12T11:10:30.059] Time limit exhausted for JobId=53412
[2022-12-12T11:32:49.391] _job_complete: JobId=53698 WEXITSTATUS 0
[2022-12-12T11:32:49.392] _job_complete: JobId=53698 done
[2022-12-12T11:36:08.186] _job_complete: JobId=53699 WEXITSTATUS 0
[2022-12-12T11:36:08.186] _job_complete: JobId=53699 done
[2022-12-12T11:41:21.930] _job_complete: JobId=53700 WEXITSTATUS 0
[2022-12-12T11:41:21.931] _job_complete: JobId=53700 done
[2022-12-12T11:49:44.028] _job_complete: JobId=53701 WEXITSTATUS 0
[2022-12-12T11:49:44.028] _job_complete: JobId=53701 done
[2022-12-12T12:07:00.242] Time limit exhausted for JobId=53697
[2022-12-12T12:10:13.200] _slurm_rpc_submit_batch_job: JobId=53702 InitPrio=14000 usec=924
[2022-12-12T12:10:13.499] sched: Allocate JobId=53702 NodeList=cpu01 #CPUs=1 Partition=cpu-opteron
[2022-12-12T12:16:31.075] _slurm_rpc_submit_batch_job: JobId=53703 InitPrio=400 usec=638
[2022-12-12T12:20:53.715] _slurm_rpc_submit_batch_job: JobId=53704 InitPrio=400 usec=485
[2022-12-12T12:27:36.002] _slurm_rpc_submit_batch_job: JobId=53705 InitPrio=400 usec=525
[2022-12-12T12:33:01.498] _slurm_rpc_submit_batch_job: JobId=53706 InitPrio=400 usec=516
[2022-12-12T12:33:02.257] sched: Allocate JobId=53706 NodeList=cpu04 #CPUs=64 Partition=cpu-opteron
[2022-12-12T12:44:31.751] _slurm_rpc_submit_batch_job: JobId=53707 InitPrio=400 usec=522
[2022-12-12T12:44:32.325] sched: Allocate JobId=53707 NodeList=cpu01 #CPUs=32 Partition=cpu-opteron
[2022-12-12T12:44:38.364] _slurm_rpc_submit_batch_job: JobId=53708 InitPrio=400 usec=451
[2022-12-12T12:44:39.332] sched: Allocate JobId=53708 NodeList=cpu08 #CPUs=32 Partition=cpu-opteron
[2022-12-12T12:44:45.914] _slurm_rpc_submit_batch_job: JobId=53709 InitPrio=400 usec=491
[2022-12-12T12:44:46.342] sched: Allocate JobId=53709 NodeList=cpu05 #CPUs=32 Partition=cpu-opteron
[2022-12-12T12:44:53.930] _slurm_rpc_submit_batch_job: JobId=53710 InitPrio=400 usec=544
[2022-12-12T12:44:54.352] sched: Allocate JobId=53710 NodeList=cpu05 #CPUs=32 Partition=cpu-opteron
[2022-12-12T13:06:13.012] _job_complete: JobId=53709 WEXITSTATUS 0
[2022-12-12T13:06:13.013] _job_complete: JobId=53709 done
[2022-12-12T13:10:31.056] Time limit exhausted for JobId=53702
[2022-12-12T13:29:05.797] _slurm_rpc_submit_batch_job: JobId=53711 InitPrio=14000 usec=516
[2022-12-12T13:29:06.088] sched: Allocate JobId=53711 NodeList=cpu01 #CPUs=1 Partition=cpu-opteron
[2022-12-12T13:34:29.095] _job_complete: JobId=53707 WEXITSTATUS 0
[2022-12-12T13:34:29.096] _job_complete: JobId=53707 done
[2022-12-12T13:55:05.969] _job_complete: JobId=53708 WEXITSTATUS 3
[2022-12-12T13:55:05.971] _job_complete: JobId=53708 done
[2022-12-12T14:13:43.979] _slurm_rpc_submit_batch_job: JobId=53712 InitPrio=400 usec=508
[2022-12-12T14:13:44.424] sched: Allocate JobId=53712 NodeList=cpu07 #CPUs=64 Partition=cpu-opteron
[2022-12-12T14:19:11.149] _slurm_rpc_submit_batch_job: JobId=53713 InitPrio=400 usec=502
[2022-12-12T14:19:11.923] sched: Allocate JobId=53713 NodeList=cpu09 #CPUs=64 Partition=cpu-opteron
[2022-12-12T14:22:15.882] _job_complete: JobId=53711 WEXITSTATUS 0
[2022-12-12T14:22:15.882] _job_complete: JobId=53711 done
[2022-12-12T14:23:01.932] _job_complete: JobId=53710 WEXITSTATUS 0
[2022-12-12T14:23:01.933] _job_complete: JobId=53710 done
[2022-12-12T14:24:12.939] _job_complete: JobId=53713 WEXITSTATUS 0
[2022-12-12T14:24:12.940] _job_complete: JobId=53713 done
[2022-12-12T14:36:31.110] Time limit exhausted for JobId=53663
[2022-12-12T14:55:09.564] _slurm_rpc_submit_batch_job: JobId=53714 InitPrio=14000 usec=544
[2022-12-12T14:55:09.933] sched: Allocate JobId=53714 NodeList=cpu01 #CPUs=1 Partition=cpu-opteron
[2022-12-12T15:55:32.841] Time limit exhausted for JobId=53714
[2022-12-12T15:56:25.582] _slurm_rpc_submit_batch_job: JobId=53715 InitPrio=18000 usec=532
[2022-12-12T15:56:26.104] sched: Allocate JobId=53715 NodeList=gpu02 #CPUs=11 Partition=gpu-titan
[2022-12-12T15:56:54.348] _slurm_rpc_submit_batch_job: JobId=53716 InitPrio=14000 usec=430
[2022-12-12T15:56:55.082] sched: Allocate JobId=53716 NodeList=cpu01 #CPUs=1 Partition=cpu-opteron
[2022-12-12T16:00:07.048] _job_complete: JobId=53715 WEXITSTATUS 0
[2022-12-12T16:00:07.048] _job_complete: JobId=53715 done
[2022-12-12T16:12:22.916] _slurm_rpc_submit_batch_job: JobId=53717 InitPrio=18000 usec=608
[2022-12-12T16:12:23.916] sched: Allocate JobId=53717 NodeList=gpu02 #CPUs=11 Partition=gpu-titan
[2022-12-12T16:15:45.315] _job_complete: JobId=53717 WEXITSTATUS 0
[2022-12-12T16:15:45.315] _job_complete: JobId=53717 done
[2022-12-12T16:33:14.802] _job_complete: JobId=53579 WEXITSTATUS 0
[2022-12-12T16:33:14.807] _job_complete: JobId=53579 done
[2022-12-12T16:33:19.336] sched: Allocate JobId=53580 NodeList=gpu05 #CPUs=8 Partition=gpu-v100s
[2022-12-12T16:45:12.811] _slurm_rpc_submit_batch_job: JobId=53718 InitPrio=17800 usec=642
[2022-12-12T16:45:13.670] sched: Allocate JobId=53718 NodeList=gpu02 #CPUs=11 Partition=gpu-titan
[2022-12-12T16:49:01.080] _job_complete: JobId=53718 WEXITSTATUS 0
[2022-12-12T16:49:01.080] _job_complete: JobId=53718 done
[2022-12-12T16:50:40.827] _slurm_rpc_submit_batch_job: JobId=53719 InitPrio=17800 usec=542
[2022-12-12T16:50:41.293] sched: Allocate JobId=53719 NodeList=gpu02 #CPUs=11 Partition=gpu-titan
[2022-12-12T16:54:33.143] _job_complete: JobId=53719 WEXITSTATUS 0
[2022-12-12T16:54:33.143] _job_complete: JobId=53719 done
[2022-12-12T16:57:03.004] Time limit exhausted for JobId=53716
[2022-12-12T16:59:17.765] _slurm_rpc_submit_batch_job: JobId=53720 InitPrio=17800 usec=536
[2022-12-12T16:59:18.176] sched: Allocate JobId=53720 NodeList=gpu02 #CPUs=11 Partition=gpu-titan
[2022-12-12T17:01:58.899] _slurm_rpc_submit_batch_job: JobId=53721 InitPrio=3200 usec=447
[2022-12-12T17:01:59.639] sched: Allocate JobId=53721 NodeList=cpu12 #CPUs=8 Partition=cpu-epyc
[2022-12-12T17:02:02.131] _slurm_rpc_submit_batch_job: JobId=53722 InitPrio=3200 usec=496
[2022-12-12T17:02:02.630] sched: Allocate JobId=53722 NodeList=cpu12 #CPUs=8 Partition=cpu-epyc
[2022-12-12T17:02:04.454] _slurm_rpc_submit_batch_job: JobId=53723 InitPrio=3200 usec=480
[2022-12-12T17:02:05.634] sched: Allocate JobId=53723 NodeList=cpu12 #CPUs=8 Partition=cpu-epyc
[2022-12-12T17:02:07.483] _slurm_rpc_submit_batch_job: JobId=53724 InitPrio=3200 usec=504
[2022-12-12T17:02:08.638] sched: Allocate JobId=53724 NodeList=cpu12 #CPUs=8 Partition=cpu-epyc
[2022-12-12T17:02:12.435] _slurm_rpc_submit_batch_job: JobId=53725 InitPrio=3200 usec=556
[2022-12-12T17:02:12.645] sched: Allocate JobId=53725 NodeList=cpu12 #CPUs=8 Partition=cpu-epyc
[2022-12-12T17:02:15.962] _slurm_rpc_submit_batch_job: JobId=53726 InitPrio=3200 usec=473
[2022-12-12T17:02:32.067] _slurm_rpc_submit_batch_job: JobId=53727 InitPrio=3200 usec=477
[2022-12-12T17:02:34.747] _slurm_rpc_submit_batch_job: JobId=53728 InitPrio=3200 usec=523
[2022-12-12T17:02:41.163] _slurm_rpc_submit_batch_job: JobId=53729 InitPrio=3200 usec=521
[2022-12-12T17:02:51.762] _slurm_rpc_submit_batch_job: JobId=53730 InitPrio=3200 usec=530
[2022-12-12T17:02:55.915] _slurm_rpc_submit_batch_job: JobId=53731 InitPrio=3200 usec=537
[2022-12-12T17:03:00.011] _slurm_rpc_submit_batch_job: JobId=53732 InitPrio=3200 usec=529
[2022-12-12T17:03:01.973] _job_complete: JobId=53720 WEXITSTATUS 0
[2022-12-12T17:03:01.974] _job_complete: JobId=53720 done
[2022-12-12T17:03:04.675] _slurm_rpc_submit_batch_job: JobId=53733 InitPrio=3200 usec=528
[2022-12-12T17:03:10.988] _slurm_rpc_submit_batch_job: JobId=53734 InitPrio=3200 usec=427
[2022-12-12T17:03:13.595] _slurm_rpc_submit_batch_job: JobId=53735 InitPrio=3200 usec=577
[2022-12-12T17:04:26.027] _slurm_rpc_submit_batch_job: JobId=53736 InitPrio=17800 usec=530
[2022-12-12T17:04:26.824] sched: Allocate JobId=53736 NodeList=gpu02 #CPUs=11 Partition=gpu-titan
[2022-12-12T17:05:45.971] _job_complete: JobId=53736 WEXITSTATUS 0
[2022-12-12T17:05:45.971] _job_complete: JobId=53736 done
[2022-12-12T17:07:32.290] _slurm_rpc_submit_batch_job: JobId=53737 InitPrio=17800 usec=552
[2022-12-12T17:07:33.200] sched: Allocate JobId=53737 NodeList=gpu02 #CPUs=11 Partition=gpu-titan
[2022-12-12T17:08:47.901] _job_complete: JobId=53737 WEXITSTATUS 0
[2022-12-12T17:08:47.901] _job_complete: JobId=53737 done
[2022-12-12T17:11:03.512] _slurm_rpc_submit_batch_job: JobId=53738 InitPrio=17800 usec=529
[2022-12-12T17:11:03.574] sched: Allocate JobId=53738 NodeList=gpu02 #CPUs=11 Partition=gpu-titan
[2022-12-12T17:11:53.928] _job_complete: JobId=53738 WEXITSTATUS 0
[2022-12-12T17:11:53.928] _job_complete: JobId=53738 done
[2022-12-12T17:17:22.526] sched: _slurm_rpc_allocate_resources JobId=53739 NodeList=gpu02 usec=1605
[2022-12-12T17:40:55.602] _slurm_rpc_kill_job: REQUEST_KILL_JOB JobId=53209 uid 548200023
[2022-12-12T17:40:59.720] _slurm_rpc_submit_batch_job: JobId=53740 InitPrio=1799 usec=663
[2022-12-12T17:45:02.710] _slurm_rpc_kill_job: REQUEST_KILL_JOB JobId=52773 uid 548200023
[2022-12-12T17:45:08.712] _slurm_rpc_submit_batch_job: JobId=53741 InitPrio=1799 usec=462
[2022-12-12T17:53:44.818] _job_complete: JobId=53739 WEXITSTATUS 0
[2022-12-12T17:53:44.819] _job_complete: JobId=53739 done
[2022-12-12T17:53:45.491] sched: Allocate JobId=53740 NodeList=gpu02 #CPUs=6 Partition=gpu-titan
[2022-12-12T17:53:45.492] sched: Allocate JobId=53741 NodeList=gpu02 #CPUs=6 Partition=gpu-titan
[2022-12-12T18:08:10.044] _slurm_rpc_submit_batch_job: JobId=53742 InitPrio=1799 usec=679
[2022-12-12T18:08:41.847] _slurm_rpc_kill_job: REQUEST_KILL_JOB JobId=53226 uid 548200023
[2022-12-12T18:10:43.593] _slurm_rpc_submit_batch_job: JobId=53743 InitPrio=1799 usec=535
[2022-12-12T18:11:01.706] _slurm_rpc_kill_job: REQUEST_KILL_JOB JobId=53742 uid 548200023
[2022-12-12T18:11:03.461] _slurm_rpc_kill_job: REQUEST_KILL_JOB JobId=53743 uid 548200023
[2022-12-12T18:11:14.823] _slurm_rpc_submit_batch_job: JobId=53744 InitPrio=1799 usec=588
[2022-12-12T18:12:49.579] _slurm_rpc_kill_job: REQUEST_KILL_JOB JobId=53220 uid 548200023
[2022-12-12T18:12:54.941] _slurm_rpc_kill_job: REQUEST_KILL_JOB JobId=52777 uid 548200023
[2022-12-12T18:12:58.828] _slurm_rpc_submit_batch_job: JobId=53745 InitPrio=1799 usec=707
[2022-12-12T18:13:50.199] _slurm_rpc_submit_batch_job: JobId=53746 InitPrio=1799 usec=602
[2022-12-12T18:15:19.737] _slurm_rpc_kill_job: REQUEST_KILL_JOB JobId=53740 uid 548200023
[2022-12-12T18:15:28.098] _slurm_rpc_submit_batch_job: JobId=53747 InitPrio=1799 usec=526
[2022-12-12T18:15:28.393] sched: Allocate JobId=53747 NodeList=gpu02 #CPUs=2 Partition=gpu-titan
[2022-12-12T18:15:34.900] _slurm_rpc_submit_batch_job: JobId=53748 InitPrio=1799 usec=595
[2022-12-12T18:15:35.400] sched: Allocate JobId=53748 NodeList=gpu02 #CPUs=6 Partition=gpu-titan
[2022-12-12T18:15:52.955] _job_complete: JobId=53747 WEXITSTATUS 0
[2022-12-12T18:15:52.956] _job_complete: JobId=53747 done
[2022-12-12T19:27:23.372] _job_complete: JobId=53724 WEXITSTATUS 0
[2022-12-12T19:27:23.372] _job_complete: JobId=53724 done
[2022-12-12T19:27:23.823] sched: Allocate JobId=53726 NodeList=cpu12 #CPUs=8 Partition=cpu-epyc
[2022-12-12T19:31:15.206] _job_complete: JobId=53723 WEXITSTATUS 0
[2022-12-12T19:31:15.207] _job_complete: JobId=53723 done
[2022-12-12T19:31:15.600] sched: Allocate JobId=53727 NodeList=cpu12 #CPUs=8 Partition=cpu-epyc
[2022-12-12T19:33:24.857] _job_complete: JobId=53722 WEXITSTATUS 0
[2022-12-12T19:33:24.857] _job_complete: JobId=53722 done
[2022-12-12T19:33:25.286] sched: Allocate JobId=53728 NodeList=cpu12 #CPUs=8 Partition=cpu-epyc
[2022-12-12T19:37:34.448] _job_complete: JobId=53725 WEXITSTATUS 0
[2022-12-12T19:37:34.448] _job_complete: JobId=53725 done
[2022-12-12T19:37:34.896] sched: Allocate JobId=53729 NodeList=cpu12 #CPUs=8 Partition=cpu-epyc
[2022-12-12T19:42:33.828] _job_complete: JobId=53721 WEXITSTATUS 0
[2022-12-12T19:42:33.828] _job_complete: JobId=53721 done
[2022-12-12T19:42:34.266] sched: Allocate JobId=53730 NodeList=cpu12 #CPUs=8 Partition=cpu-epyc
[2022-12-12T21:50:13.469] _job_complete: JobId=53726 WEXITSTATUS 0
[2022-12-12T21:50:13.469] _job_complete: JobId=53726 done
[2022-12-12T21:50:13.911] sched: Allocate JobId=53731 NodeList=cpu12 #CPUs=8 Partition=cpu-epyc
[2022-12-12T22:06:56.058] _job_complete: JobId=53729 WEXITSTATUS 0
[2022-12-12T22:06:56.058] _job_complete: JobId=53729 done
[2022-12-12T22:06:56.487] sched: Allocate JobId=53732 NodeList=cpu12 #CPUs=8 Partition=cpu-epyc
[2022-12-12T22:07:20.723] _job_complete: JobId=53728 WEXITSTATUS 0
[2022-12-12T22:07:20.723] _job_complete: JobId=53728 done
[2022-12-12T22:07:21.115] sched: Allocate JobId=53733 NodeList=cpu12 #CPUs=8 Partition=cpu-epyc
[2022-12-12T22:12:36.299] _job_complete: JobId=53727 WEXITSTATUS 0
[2022-12-12T22:12:36.299] _job_complete: JobId=53727 done
[2022-12-12T22:12:36.748] sched: Allocate JobId=53734 NodeList=cpu12 #CPUs=8 Partition=cpu-epyc
[2022-12-12T22:30:35.147] _job_complete: JobId=53730 WEXITSTATUS 0
[2022-12-12T22:30:35.148] _job_complete: JobId=53730 done
[2022-12-12T22:30:35.690] sched: Allocate JobId=53735 NodeList=cpu12 #CPUs=8 Partition=cpu-epyc
[2022-12-12T22:39:09.387] _slurm_rpc_submit_batch_job: JobId=53749 InitPrio=3599 usec=530
[2022-12-12T22:39:09.653] sched: Allocate JobId=53749 NodeList=cpu01 #CPUs=16 Partition=cpu-opteron
[2022-12-12T23:28:39.004] sched: _slurm_rpc_allocate_resources JobId=53750 NodeList=(null) usec=960
[2022-12-12T23:28:39.137] sched: Allocate JobId=53750 NodeList=cpu01 #CPUs=1 Partition=cpu-opteron
[2022-12-12T23:28:39.637] _job_complete: JobId=53750 WEXITSTATUS 2
[2022-12-12T23:28:39.637] _job_complete: JobId=53750 done
[2022-12-12T23:28:47.970] sched: _slurm_rpc_allocate_resources JobId=53751 NodeList=(null) usec=803
[2022-12-12T23:28:48.133] sched: Allocate JobId=53751 NodeList=cpu01 #CPUs=1 Partition=cpu-opteron
[2022-12-12T23:28:48.616] _job_complete: JobId=53751 WEXITSTATUS 2
[2022-12-12T23:28:48.616] _job_complete: JobId=53751 done
[2022-12-12T23:32:52.579] _slurm_rpc_submit_batch_job: JobId=53752 InitPrio=600 usec=509
[2022-12-12T23:34:59.022] _slurm_rpc_kill_job: REQUEST_KILL_JOB JobId=53752 uid 548200121
[2022-12-12T23:35:03.583] _slurm_rpc_submit_batch_job: JobId=53753 InitPrio=600 usec=543
[2022-12-12T23:35:52.919] _slurm_rpc_kill_job: REQUEST_KILL_JOB JobId=53753 uid 548200121
[2022-12-12T23:35:55.928] _slurm_rpc_submit_batch_job: JobId=53754 InitPrio=600 usec=489
[2022-12-12T23:43:15.979] _slurm_rpc_kill_job: REQUEST_KILL_JOB JobId=53754 uid 548200121
[2022-12-12T23:44:04.324] _slurm_rpc_submit_batch_job: JobId=53755 InitPrio=600 usec=559
[2022-12-12T23:45:08.626] _slurm_rpc_kill_job: REQUEST_KILL_JOB JobId=53755 uid 548200121
[2022-12-12T23:45:12.585] _slurm_rpc_submit_batch_job: JobId=53756 InitPrio=600 usec=489
[2022-12-12T23:45:24.786] _slurm_rpc_submit_batch_job: JobId=53757 InitPrio=600 usec=487
[2022-12-12T23:46:05.587] _slurm_rpc_submit_batch_job: JobId=53758 InitPrio=600 usec=497
[2022-12-12T23:46:33.675] _slurm_rpc_submit_batch_job: JobId=53759 InitPrio=600 usec=541
[2022-12-13T00:07:28.609] _slurm_rpc_submit_batch_job: JobId=53760 InitPrio=600 usec=508
[2022-12-13T00:07:29.602] sched: Allocate JobId=53760 NodeList=gpu02 #CPUs=4 Partition=gpu-titan
[2022-12-13T00:07:39.825] _slurm_rpc_kill_job: REQUEST_KILL_JOB JobId=53760 uid 548200121
[2022-12-13T00:07:57.100] _slurm_rpc_submit_batch_job: JobId=53761 InitPrio=600 usec=484
[2022-12-13T00:07:57.631] sched: Allocate JobId=53761 NodeList=gpu02 #CPUs=4 Partition=gpu-titan
[2022-12-13T00:08:24.642] _job_complete: JobId=53761 WEXITSTATUS 1
[2022-12-13T00:08:24.643] _job_complete: JobId=53761 done
[2022-12-13T00:09:18.302] _slurm_rpc_kill_job: REQUEST_KILL_JOB JobId=53758 uid 548200121
[2022-12-13T00:09:18.302] _slurm_rpc_kill_job: REQUEST_KILL_JOB JobId=53756 uid 548200121
[2022-12-13T00:09:18.303] _slurm_rpc_kill_job: REQUEST_KILL_JOB JobId=53757 uid 548200121
[2022-12-13T00:09:18.303] _slurm_rpc_kill_job: REQUEST_KILL_JOB JobId=53759 uid 548200121
[2022-12-13T00:10:02.468] _slurm_rpc_submit_batch_job: JobId=53762 InitPrio=600 usec=511
[2022-12-13T00:10:02.782] sched: Allocate JobId=53762 NodeList=gpu02 #CPUs=4 Partition=gpu-titan
[2022-12-13T00:11:52.614] _job_complete: JobId=53762 WEXITSTATUS 1
[2022-12-13T00:11:52.614] _job_complete: JobId=53762 done
[2022-12-13T00:12:21.267] _job_complete: JobId=53731 WEXITSTATUS 0
[2022-12-13T00:12:21.267] _job_complete: JobId=53731 done
[2022-12-13T00:13:03.617] _slurm_rpc_submit_batch_job: JobId=53763 InitPrio=600 usec=538
[2022-12-13T00:13:06.108] _slurm_rpc_submit_batch_job: JobId=53764 InitPrio=600 usec=488
[2022-12-13T00:13:08.206] _slurm_rpc_submit_batch_job: JobId=53765 InitPrio=600 usec=513
[2022-12-13T00:13:10.406] _slurm_rpc_submit_batch_job: JobId=53766 InitPrio=600 usec=559
[2022-12-13T00:13:35.258] _slurm_rpc_submit_batch_job: JobId=53767 InitPrio=600 usec=499
[2022-12-13T00:13:36.188] sched: Allocate JobId=53767 NodeList=gpu02 #CPUs=4 Partition=gpu-titan
[2022-12-13T00:15:17.142] _job_complete: JobId=53767 WEXITSTATUS 1
[2022-12-13T00:15:17.143] _job_complete: JobId=53767 done
[2022-12-13T00:15:17.869] _slurm_rpc_kill_job: REQUEST_KILL_JOB JobId=53764 uid 548200121
[2022-12-13T00:15:17.869] _slurm_rpc_kill_job: REQUEST_KILL_JOB JobId=53765 uid 548200121
[2022-12-13T00:15:17.870] _slurm_rpc_kill_job: REQUEST_KILL_JOB JobId=53764 uid 548200121
[2022-12-13T00:15:17.870] _slurm_rpc_kill_job: REQUEST_KILL_JOB JobId=53766 uid 548200121
[2022-12-13T00:15:20.057] _slurm_rpc_kill_job: REQUEST_KILL_JOB JobId=53763 uid 548200121
[2022-12-13T00:15:20.057] _slurm_rpc_kill_job: REQUEST_KILL_JOB JobId=53766 uid 548200121
[2022-12-13T00:15:20.057] _slurm_rpc_kill_job: REQUEST_KILL_JOB JobId=53765 uid 548200121
[2022-12-13T00:15:20.057] _slurm_rpc_kill_job: REQUEST_KILL_JOB JobId=53764 uid 548200121
[2022-12-13T00:15:28.919] _slurm_rpc_submit_batch_job: JobId=53768 InitPrio=600 usec=546
[2022-12-13T00:15:30.859] _slurm_rpc_submit_batch_job: JobId=53769 InitPrio=600 usec=537
[2022-12-13T00:15:32.909] _slurm_rpc_submit_batch_job: JobId=53770 InitPrio=600 usec=556
[2022-12-13T00:15:34.909] _slurm_rpc_submit_batch_job: JobId=53771 InitPrio=600 usec=552
[2022-12-13T00:16:59.222] _slurm_rpc_submit_batch_job: JobId=53772 InitPrio=10600 usec=437
[2022-12-13T00:16:59.556] sched: Allocate JobId=53772 NodeList=cpu12 #CPUs=2 Partition=cpu-epyc
[2022-12-13T00:18:15.524] _slurm_rpc_kill_job: REQUEST_KILL_JOB JobId=53772 uid 548200121
[2022-12-13T00:18:30.946] _slurm_rpc_submit_batch_job: JobId=53773 InitPrio=10600 usec=395
[2022-12-13T00:18:31.668] sched: Allocate JobId=53773 NodeList=gpu02 #CPUs=2 Partition=gpu-titan
[2022-12-13T00:21:53.494] sched: _slurm_rpc_allocate_resources JobId=53774 NodeList=(null) usec=1079
[2022-12-13T00:22:12.438] _job_complete: JobId=53774 WTERMSIG 126
[2022-12-13T00:22:12.438] _job_complete: JobId=53774 cancelled by interactive user
[2022-12-13T00:22:12.438] _job_complete: JobId=53774 done
[2022-12-13T00:22:20.858] sched: _slurm_rpc_allocate_resources JobId=53775 NodeList=(null) usec=835
[2022-12-13T00:22:58.005] _job_complete: JobId=53775 WTERMSIG 126
[2022-12-13T00:22:58.005] _job_complete: JobId=53775 cancelled by interactive user
[2022-12-13T00:22:58.005] _job_complete: JobId=53775 done
[2022-12-13T00:23:03.160] sched: _slurm_rpc_allocate_resources JobId=53776 NodeList=(null) usec=868
[2022-12-13T00:23:12.641] _job_complete: JobId=53776 WTERMSIG 126
[2022-12-13T00:23:12.641] _job_complete: JobId=53776 cancelled by interactive user
[2022-12-13T00:23:12.641] _job_complete: JobId=53776 done
[2022-12-13T00:23:19.521] sched: _slurm_rpc_allocate_resources JobId=53777 NodeList=(null) usec=857
[2022-12-13T00:23:37.508] _job_complete: JobId=53777 WTERMSIG 126
[2022-12-13T00:23:37.508] _job_complete: JobId=53777 cancelled by interactive user
[2022-12-13T00:23:37.508] _job_complete: JobId=53777 done
[2022-12-13T00:24:25.047] sched: _slurm_rpc_allocate_resources JobId=53778 NodeList=gpu04 usec=13501
[2022-12-13T00:34:23.675] _job_complete: JobId=53732 WEXITSTATUS 0
[2022-12-13T00:34:23.675] _job_complete: JobId=53732 done
[2022-12-13T00:37:20.521] _job_complete: JobId=53733 WEXITSTATUS 0
[2022-12-13T00:37:20.521] _job_complete: JobId=53733 done
[2022-12-13T00:38:15.528] _slurm_rpc_submit_batch_job: JobId=53779 InitPrio=17400 usec=406
[2022-12-13T00:38:40.421] _job_complete: JobId=53734 WEXITSTATUS 0
[2022-12-13T00:38:40.421] _job_complete: JobId=53734 done
[2022-12-13T00:39:40.985] _slurm_rpc_submit_batch_job: JobId=53780 InitPrio=17400 usec=394
[2022-12-13T00:39:41.954] sched: Allocate JobId=53780 NodeList=gpu01 #CPUs=1 Partition=gpu-k10
[2022-12-13T00:42:35.185] _job_complete: JobId=53778 WEXITSTATUS 0
[2022-12-13T00:42:35.185] _job_complete: JobId=53778 done
[2022-12-13T00:44:06.930] _slurm_rpc_kill_job: REQUEST_KILL_JOB JobId=53780 uid 548300670
[2022-12-13T00:44:18.937] _slurm_rpc_submit_batch_job: JobId=53781 InitPrio=17400 usec=411
[2022-12-13T00:44:19.409] sched: Allocate JobId=53781 NodeList=gpu04 #CPUs=1 Partition=gpu-k40c
[2022-12-13T00:45:14.142] _slurm_rpc_submit_batch_job: JobId=53782 InitPrio=600 usec=537
[2022-12-13T00:45:15.840] _slurm_rpc_submit_batch_job: JobId=53783 InitPrio=600 usec=455
[2022-12-13T00:45:33.929] _slurm_rpc_kill_job: REQUEST_KILL_JOB JobId=53773 uid 548200121
[2022-12-13T00:45:37.059] sched: Allocate JobId=53779 NodeList=gpu02 #CPUs=1 Partition=gpu-titan
[2022-12-13T00:47:14.992] _slurm_rpc_kill_job: REQUEST_KILL_JOB JobId=53781 uid 548300670
[2022-12-13T00:58:52.062] _job_complete: JobId=53735 WEXITSTATUS 0
[2022-12-13T00:58:52.062] _job_complete: JobId=53735 done
[2022-12-13T01:46:04.971] Time limit exhausted for JobId=53779
[2022-12-13T01:46:07.132] sched: Allocate JobId=53782 NodeList=gpu02 #CPUs=4 Partition=gpu-titan
[2022-12-13T01:46:09.620] _job_complete: JobId=53782 WEXITSTATUS 2
[2022-12-13T01:46:09.621] _job_complete: JobId=53782 done
[2022-12-13T01:46:10.285] sched: Allocate JobId=53783 NodeList=gpu02 #CPUs=4 Partition=gpu-titan
[2022-12-13T01:46:11.405] _job_complete: JobId=53783 WEXITSTATUS 2
[2022-12-13T01:46:11.406] _job_complete: JobId=53783 done
[2022-12-13T02:12:00.425] job_step_signal: JobId=53580 StepId=0 not found
[2022-12-13T04:16:38.044] _job_complete: JobId=53677 WEXITSTATUS 0
[2022-12-13T04:16:38.044] _job_complete: JobId=53677 done
[2022-12-13T04:32:21.468] _job_complete: JobId=53678 WEXITSTATUS 0
[2022-12-13T04:32:21.469] _job_complete: JobId=53678 done
[2022-12-13T06:26:03.987] _job_complete: JobId=53680 WEXITSTATUS 0
[2022-12-13T06:26:03.987] _job_complete: JobId=53680 done
[2022-12-13T06:29:39.862] _job_complete: JobId=53694 WEXITSTATUS 0
[2022-12-13T06:29:39.862] _job_complete: JobId=53694 done
[2022-12-13T06:29:40.309] sched: Allocate JobId=53703 NodeList=cpu12 #CPUs=48 Partition=cpu-epyc
[2022-12-13T06:34:38.996] _job_complete: JobId=53679 WEXITSTATUS 0
[2022-12-13T06:34:38.997] _job_complete: JobId=53679 done
[2022-12-13T06:41:58.928] _job_complete: JobId=53681 WEXITSTATUS 0
[2022-12-13T06:41:58.928] _job_complete: JobId=53681 done
[2022-12-13T07:41:34.887] Requeuing JobId=53741
[2022-12-13T07:41:42.101] Requeuing JobId=53748
[2022-12-13T07:47:15.287] _job_complete: JobId=53693 WEXITSTATUS 0
[2022-12-13T07:47:15.287] _job_complete: JobId=53693 done
[2022-12-13T08:05:43.999] _job_complete: JobId=53692 WEXITSTATUS 0
[2022-12-13T08:05:43.999] _job_complete: JobId=53692 done
[2022-12-13T08:10:27.535] _slurm_rpc_submit_batch_job: JobId=53784 InitPrio=14000 usec=538
[2022-12-13T08:10:28.488] sched: Allocate JobId=53784 NodeList=cpu01 #CPUs=1 Partition=cpu-opteron
[2022-12-13T08:16:41.441] _job_complete: JobId=53691 WEXITSTATUS 0
[2022-12-13T08:16:41.441] _job_complete: JobId=53691 done
[2022-12-13T08:28:05.868] _job_complete: JobId=53689 WEXITSTATUS 0
[2022-12-13T08:28:05.868] _job_complete: JobId=53689 done
[2022-12-13T08:40:02.207] _slurm_rpc_submit_batch_job: JobId=53785 InitPrio=1388 usec=605
[2022-12-13T08:40:02.377] sched: Allocate JobId=53785 NodeList=cpu01 #CPUs=8 Partition=cpu-opteron
[2022-12-13T08:50:58.736] _job_complete: JobId=53690 WEXITSTATUS 0
[2022-12-13T08:50:58.737] _job_complete: JobId=53690 done
[2022-12-13T09:10:34.618] Time limit exhausted for JobId=53784
[2022-12-13T09:47:42.853] _job_complete: JobId=53682 WEXITSTATUS 0
[2022-12-13T09:47:42.853] _job_complete: JobId=53682 done
[2022-12-13T10:01:23.965] _job_complete: JobId=53687 WEXITSTATUS 0
[2022-12-13T10:01:23.966] _job_complete: JobId=53687 done
[2022-12-13T10:02:55.709] _job_complete: JobId=53683 WEXITSTATUS 0
[2022-12-13T10:02:55.709] _job_complete: JobId=53683 done
[2022-12-13T10:15:48.920] sched: _hold_job_rec: hold on JobId=53768 by uid 548200003
[2022-12-13T10:15:48.921] sched: _update_job: set priority to 0 for JobId=53768
[2022-12-13T10:15:48.921] _update_job: updating accounting
[2022-12-13T10:15:48.921] _slurm_rpc_update_job: complete JobId=53768 uid=548200003 usec=1241
[2022-12-13T10:15:48.923] sched: _hold_job_rec: hold on JobId=53769 by uid 548200003
[2022-12-13T10:15:48.923] sched: _update_job: set priority to 0 for JobId=53769
[2022-12-13T10:15:48.923] _update_job: updating accounting
[2022-12-13T10:15:48.923] _slurm_rpc_update_job: complete JobId=53769 uid=548200003 usec=586
[2022-12-13T10:15:48.925] sched: _hold_job_rec: hold on JobId=53581 by uid 548200003
[2022-12-13T10:15:48.925] sched: _update_job: set priority to 0 for JobId=53581
[2022-12-13T10:15:48.925] _update_job: updating accounting
[2022-12-13T10:15:48.925] _slurm_rpc_update_job: complete JobId=53581 uid=548200003 usec=632
[2022-12-13T10:15:48.927] sched: _hold_job_rec: hold on JobId=53771 by uid 548200003
[2022-12-13T10:15:48.927] sched: _update_job: set priority to 0 for JobId=53771
[2022-12-13T10:15:48.927] _update_job: updating accounting
[2022-12-13T10:15:48.927] _slurm_rpc_update_job: complete JobId=53771 uid=548200003 usec=573
[2022-12-13T10:15:48.929] sched: _hold_job_rec: hold on JobId=53770 by uid 548200003
[2022-12-13T10:15:48.929] sched: _update_job: set priority to 0 for JobId=53770
[2022-12-13T10:15:48.929] _update_job: updating accounting
[2022-12-13T10:15:48.929] _slurm_rpc_update_job: complete JobId=53770 uid=548200003 usec=486
[2022-12-13T10:16:03.392] Requeuing JobId=53580
[2022-12-13T10:16:03.411] sched: Allocate JobId=53666 NodeList=gpu05 #CPUs=16 Partition=gpu-v100s
[2022-12-13T10:16:03.412] sched: Allocate JobId=53667 NodeList=gpu05 #CPUs=16 Partition=gpu-v100s
[2022-12-13T10:18:08.183] _job_complete: JobId=53686 WEXITSTATUS 0
[2022-12-13T10:18:08.183] _job_complete: JobId=53686 done
[2022-12-13T10:19:21.282] _job_complete: JobId=53684 WEXITSTATUS 0
[2022-12-13T10:19:21.282] _job_complete: JobId=53684 done
[2022-12-13T10:29:40.992] _slurm_rpc_kill_job: REQUEST_KILL_JOB JobId=53769 uid 548200121
[2022-12-13T10:29:40.992] _slurm_rpc_kill_job: REQUEST_KILL_JOB JobId=53771 uid 548200121
[2022-12-13T10:29:40.992] _slurm_rpc_kill_job: REQUEST_KILL_JOB JobId=53581 uid 548200121
[2022-12-13T10:29:40.992] _slurm_rpc_kill_job: REQUEST_KILL_JOB JobId=53770 uid 548200121
[2022-12-13T10:29:40.994] _slurm_rpc_kill_job: REQUEST_KILL_JOB JobId=53768 uid 548200121
[2022-12-13T10:29:50.017] _slurm_rpc_kill_job: REQUEST_KILL_JOB JobId=53580 uid 548200121
[2022-12-13T10:31:13.312] _slurm_rpc_submit_batch_job: JobId=53786 InitPrio=595 usec=498
[2022-12-13T10:31:13.607] sched: Allocate JobId=53786 NodeList=gpu02 #CPUs=4 Partition=gpu-titan
[2022-12-13T10:32:03.804] _slurm_rpc_submit_batch_job: JobId=53787 InitPrio=595 usec=433
[2022-12-13T10:32:04.659] sched: Allocate JobId=53787 NodeList=gpu02 #CPUs=4 Partition=gpu-titan
[2022-12-13T10:32:39.921] _slurm_rpc_submit_batch_job: JobId=53788 InitPrio=793 usec=581
[2022-12-13T10:32:40.724] sched: Allocate JobId=53788 NodeList=gpu01 #CPUs=16 Partition=gpu-k10
[2022-12-13T10:36:00.069] _slurm_rpc_submit_batch_job: JobId=53789 InitPrio=793 usec=575
[2022-12-13T10:36:01.041] sched: Allocate JobId=53789 NodeList=gpu02 #CPUs=8 Partition=gpu-titan
[2022-12-13T10:37:50.993] _slurm_rpc_submit_batch_job: JobId=53790 InitPrio=793 usec=643
[2022-12-13T10:40:33.065] _slurm_rpc_submit_batch_job: JobId=53791 InitPrio=793 usec=627
[2022-12-13T10:41:57.381] _slurm_rpc_submit_batch_job: JobId=53792 InitPrio=793 usec=714
[2022-12-13T10:43:06.336] _job_complete: JobId=53787 WEXITSTATUS 1
[2022-12-13T10:43:06.336] _job_complete: JobId=53787 done
[2022-12-13T10:50:16.445] _job_complete: JobId=53688 WEXITSTATUS 0
[2022-12-13T10:50:16.445] _job_complete: JobId=53688 done
[2022-12-13T10:50:16.867] sched: Allocate JobId=53704 NodeList=cpu15 #CPUs=48 Partition=cpu-epyc
[2022-12-13T10:51:06.821] _slurm_rpc_submit_batch_job: JobId=53793 InitPrio=595 usec=402
[2022-12-13T10:52:41.548] _slurm_rpc_submit_batch_job: JobId=53794 InitPrio=595 usec=550
[2022-12-13T10:52:46.877] _slurm_rpc_kill_job: REQUEST_KILL_JOB JobId=53793 uid 548200121
[2022-12-13T10:57:12.670] _slurm_rpc_submit_batch_job: JobId=53795 InitPrio=793 usec=625
[2022-12-13T10:57:13.162] sched: Allocate JobId=53795 NodeList=cpu01 #CPUs=16 Partition=cpu-opteron
[2022-12-13T10:57:18.478] _job_complete: JobId=53795 WEXITSTATUS 1
[2022-12-13T10:57:18.478] _job_complete: JobId=53795 done
[2022-12-13T10:57:31.799] _slurm_rpc_submit_batch_job: JobId=53796 InitPrio=595 usec=467
[2022-12-13T11:02:19.039] _job_complete: JobId=53685 WEXITSTATUS 0
[2022-12-13T11:02:19.039] _job_complete: JobId=53685 done
[2022-12-13T11:02:19.358] sched: Allocate JobId=53705 NodeList=cpu14 #CPUs=48 Partition=cpu-epyc
[2022-12-13T11:05:19.718] _slurm_rpc_submit_batch_job: JobId=53797 InitPrio=793 usec=479
[2022-12-13T11:05:19.923] sched: Allocate JobId=53797 NodeList=cpu01 #CPUs=16 Partition=cpu-opteron
[2022-12-13T11:05:22.369] _job_complete: JobId=53797 WEXITSTATUS 1
[2022-12-13T11:05:22.369] _job_complete: JobId=53797 done
[2022-12-13T11:05:30.919] _job_complete: JobId=53786 WEXITSTATUS 1
[2022-12-13T11:05:30.919] _job_complete: JobId=53786 done
[2022-12-13T11:05:32.095] sched: Allocate JobId=53790 NodeList=gpu02 #CPUs=8 Partition=gpu-titan
[2022-12-13T11:06:25.550] _slurm_rpc_submit_batch_job: JobId=53798 InitPrio=793 usec=438
[2022-12-13T11:06:26.162] sched: Allocate JobId=53798 NodeList=cpu01 #CPUs=16 Partition=cpu-opteron
[2022-12-13T11:06:28.343] _job_complete: JobId=53798 WEXITSTATUS 1
[2022-12-13T11:06:28.344] _job_complete: JobId=53798 done
[2022-12-13T11:08:22.305] _slurm_rpc_submit_batch_job: JobId=53799 InitPrio=793 usec=411
[2022-12-13T11:08:22.317] sched: Allocate JobId=53799 NodeList=cpu01 #CPUs=16 Partition=cpu-opteron
[2022-12-13T11:08:25.005] _job_complete: JobId=53799 WEXITSTATUS 1
[2022-12-13T11:08:25.005] _job_complete: JobId=53799 done
[2022-12-13T11:10:14.708] _slurm_rpc_submit_batch_job: JobId=53800 InitPrio=793 usec=462
[2022-12-13T11:10:15.457] sched: Allocate JobId=53800 NodeList=cpu01 #CPUs=16 Partition=cpu-opteron
[2022-12-13T11:10:17.552] _job_complete: JobId=53800 WEXITSTATUS 1
[2022-12-13T11:10:17.552] _job_complete: JobId=53800 done
[2022-12-13T11:12:51.345] _slurm_rpc_submit_batch_job: JobId=53801 InitPrio=793 usec=428
[2022-12-13T11:12:51.805] sched: Allocate JobId=53801 NodeList=cpu01 #CPUs=16 Partition=cpu-opteron
[2022-12-13T11:12:53.948] _job_complete: JobId=53801 WEXITSTATUS 1
[2022-12-13T11:12:53.949] _job_complete: JobId=53801 done
[2022-12-13T11:15:17.157] _slurm_rpc_submit_batch_job: JobId=53802 InitPrio=793 usec=428
[2022-12-13T11:15:18.950] sched/backfill: _start_job: Started JobId=53802 in cpu-opteron on cpu01
[2022-12-13T11:15:21.126] _job_complete: JobId=53802 WEXITSTATUS 1
[2022-12-13T11:15:21.127] _job_complete: JobId=53802 done
[2022-12-13T11:17:36.974] _slurm_rpc_submit_batch_job: JobId=53803 InitPrio=793 usec=455
[2022-12-13T11:17:37.445] sched: Allocate JobId=53803 NodeList=cpu01 #CPUs=16 Partition=cpu-opteron
[2022-12-13T11:17:39.642] _job_complete: JobId=53803 WEXITSTATUS 1
[2022-12-13T11:17:39.642] _job_complete: JobId=53803 done
[2022-12-13T11:19:39.449] _slurm_rpc_submit_batch_job: JobId=53804 InitPrio=793 usec=457
[2022-12-13T11:19:39.596] sched: Allocate JobId=53804 NodeList=cpu01 #CPUs=16 Partition=cpu-opteron
[2022-12-13T11:19:41.769] _job_complete: JobId=53804 WEXITSTATUS 1
[2022-12-13T11:19:41.769] _job_complete: JobId=53804 done
[2022-12-13T11:21:27.460] _job_complete: JobId=53785 WEXITSTATUS 0
[2022-12-13T11:21:27.460] _job_complete: JobId=53785 done
[2022-12-13T11:25:28.923] _slurm_rpc_submit_batch_job: JobId=53805 InitPrio=13968 usec=563
[2022-12-13T11:25:29.526] sched: Allocate JobId=53805 NodeList=cpu01 #CPUs=1 Partition=cpu-opteron
[2022-12-13T11:41:29.662] sched: _slurm_rpc_allocate_resources JobId=53806 NodeList=gpu04 usec=12997
[2022-12-13T12:05:55.570] sched: _slurm_rpc_allocate_resources JobId=53807 NodeList=(null) usec=1044
[2022-12-13T12:05:56.063] sched: Allocate JobId=53807 NodeList=cpu01 #CPUs=1 Partition=cpu-opteron
[2022-12-13T12:10:03.055] _slurm_rpc_submit_batch_job: JobId=53808 InitPrio=595 usec=527
[2022-12-13T12:10:50.090] _slurm_rpc_submit_batch_job: JobId=53809 InitPrio=595 usec=449
[2022-12-13T12:11:05.089] _slurm_rpc_kill_job: REQUEST_KILL_JOB JobId=53794 uid 548200121
[2022-12-13T12:19:13.435] _slurm_rpc_submit_batch_job: JobId=53810 InitPrio=396 usec=571
[2022-12-13T12:25:34.746] Time limit exhausted for JobId=53805
[2022-12-13T12:32:05.005] _job_complete: JobId=53806 WEXITSTATUS 0
[2022-12-13T12:32:05.006] _job_complete: JobId=53806 done
[2022-12-13T13:02:37.075] _slurm_rpc_submit_batch_job: JobId=53811 InitPrio=396 usec=503
[2022-12-13T13:02:37.641] sched: Allocate JobId=53811 NodeList=cpu05 #CPUs=64 Partition=cpu-opteron
[2022-12-13T13:03:05.095] _slurm_rpc_submit_batch_job: JobId=53812 InitPrio=2777 usec=483
[2022-12-13T13:23:36.234] _slurm_rpc_submit_batch_job: JobId=53813 InitPrio=396 usec=537
[2022-12-13T13:23:37.233] sched: Allocate JobId=53813 NodeList=cpu08 #CPUs=64 Partition=cpu-opteron
[2022-12-13T13:39:15.640] _slurm_rpc_submit_batch_job: JobId=53814 InitPrio=13968 usec=549
[2022-12-13T13:39:15.791] sched: Allocate JobId=53814 NodeList=cpu01 #CPUs=1 Partition=cpu-opteron
[2022-12-13T13:41:48.509] _job_complete: JobId=53667 WEXITSTATUS 0
[2022-12-13T13:41:48.514] _job_complete: JobId=53667 done
[2022-12-13T13:44:46.507] _job_complete: JobId=53666 WEXITSTATUS 0
[2022-12-13T13:44:46.508] _job_complete: JobId=53666 done
[2022-12-13T13:44:48.407] sched: Allocate JobId=53664 NodeList=gpu05 #CPUs=16 Partition=gpu-v100s
[2022-12-13T14:03:02.895] _slurm_rpc_submit_batch_job: JobId=53815 InitPrio=17738 usec=416
[2022-12-13T14:03:10.946] _slurm_rpc_submit_batch_job: JobId=53816 InitPrio=17142 usec=390
[2022-12-13T14:04:33.617] _slurm_rpc_submit_batch_job: JobId=53817 InitPrio=17142 usec=354
[2022-12-13T14:08:00.228] _slurm_rpc_kill_job: REQUEST_KILL_JOB JobId=53815 uid 548300565
[2022-12-13T14:20:09.644] _slurm_rpc_kill_job: REQUEST_KILL_JOB JobId=53745 uid 548200023
[2022-12-13T14:20:14.783] _slurm_rpc_kill_job: REQUEST_KILL_JOB JobId=53746 uid 548200023
[2022-12-13T14:20:58.262] _slurm_rpc_submit_batch_job: JobId=53818 InitPrio=1785 usec=843
[2022-12-13T14:21:58.690] _slurm_rpc_kill_job: REQUEST_KILL_JOB JobId=53744 uid 548200023
[2022-12-13T14:22:08.640] _slurm_rpc_submit_batch_job: JobId=53819 InitPrio=1785 usec=677
[2022-12-13T14:23:36.737] _slurm_rpc_submit_batch_job: JobId=53820 InitPrio=1785 usec=553
[2022-12-13T14:24:52.796] _slurm_rpc_submit_batch_job: JobId=53821 InitPrio=1785 usec=626
[2022-12-13T14:25:03.538] _slurm_rpc_kill_job: REQUEST_KILL_JOB JobId=53819 uid 548200023
[2022-12-13T14:27:10.994] _slurm_rpc_submit_batch_job: JobId=53822 InitPrio=17142 usec=426
[2022-12-13T14:27:27.065] _slurm_rpc_kill_job: REQUEST_KILL_JOB JobId=53748 uid 548200023
[2022-12-13T14:27:29.056] _slurm_rpc_kill_job: REQUEST_KILL_JOB JobId=53741 uid 548200023
[2022-12-13T14:27:33.275] _slurm_rpc_submit_batch_job: JobId=53823 InitPrio=1785 usec=713
[2022-12-13T14:29:25.236] _slurm_rpc_submit_batch_job: JobId=53824 InitPrio=1785 usec=572
[2022-12-13T14:39:34.116] Time limit exhausted for JobId=53814
[2022-12-13T14:47:15.757] _slurm_rpc_submit_batch_job: JobId=53825 InitPrio=13968 usec=505
[2022-12-13T14:47:15.969] sched: Allocate JobId=53825 NodeList=cpu01 #CPUs=1 Partition=cpu-opteron
[2022-12-13T14:49:13.545] _slurm_rpc_submit_batch_job: JobId=53826 InitPrio=1388 usec=560
[2022-12-13T14:49:14.132] sched: Allocate JobId=53826 NodeList=cpu01 #CPUs=8 Partition=cpu-opteron
[2022-12-13T14:55:43.256] _job_complete: JobId=53825 WEXITSTATUS 0
[2022-12-13T14:55:43.256] _job_complete: JobId=53825 done
[2022-12-13T15:00:47.105] _slurm_rpc_submit_batch_job: JobId=53827 InitPrio=992 usec=500
[2022-12-13T15:00:47.342] sched: Allocate JobId=53827 NodeList=cpu01 #CPUs=1 Partition=cpu-opteron
[2022-12-13T15:00:48.517] _job_complete: JobId=53827 WEXITSTATUS 0
[2022-12-13T15:00:48.517] _job_complete: JobId=53827 done
[2022-12-13T15:05:11.606] _slurm_rpc_submit_batch_job: JobId=53828 InitPrio=992 usec=611
[2022-12-13T15:05:11.757] sched: Allocate JobId=53828 NodeList=cpu01 #CPUs=1 Partition=cpu-opteron
[2022-12-13T15:05:13.003] _job_complete: JobId=53828 WEXITSTATUS 0
[2022-12-13T15:05:13.003] _job_complete: JobId=53828 done
[2022-12-13T15:27:11.437] _slurm_rpc_submit_batch_job: JobId=53829 InitPrio=992 usec=520
[2022-12-13T15:27:11.537] sched: Allocate JobId=53829 NodeList=cpu01 #CPUs=16 Partition=cpu-opteron
[2022-12-13T15:32:04.814] _slurm_rpc_submit_batch_job: JobId=53830 InitPrio=1388 usec=608
[2022-12-13T15:32:05.039] sched: Allocate JobId=53830 NodeList=cpu13 #CPUs=8 Partition=cpu-epyc
[2022-12-13T15:32:09.268] _slurm_rpc_submit_batch_job: JobId=53831 InitPrio=1388 usec=485
[2022-12-13T15:32:10.044] sched: Allocate JobId=53831 NodeList=cpu13 #CPUs=8 Partition=cpu-epyc
[2022-12-13T15:32:13.342] _slurm_rpc_submit_batch_job: JobId=53832 InitPrio=1388 usec=479
[2022-12-13T15:32:18.237] _slurm_rpc_submit_batch_job: JobId=53833 InitPrio=1388 usec=531
[2022-12-13T15:32:21.542] _slurm_rpc_submit_batch_job: JobId=53834 InitPrio=1388 usec=512
[2022-12-13T15:32:24.917] _slurm_rpc_submit_batch_job: JobId=53835 InitPrio=1388 usec=434
[2022-12-13T15:42:56.534] _slurm_rpc_submit_batch_job: JobId=53836 InitPrio=992 usec=501
[2022-12-13T15:42:57.109] sched: Allocate JobId=53836 NodeList=cpu01 #CPUs=16 Partition=cpu-opteron
[2022-12-13T15:44:48.359] sched: _slurm_rpc_allocate_resources JobId=53837 NodeList=(null) usec=921
[2022-12-13T15:44:49.259] sched: Allocate JobId=53837 NodeList=gpu04 #CPUs=8 Partition=gpu-k40c
[2022-12-13T16:26:49.546] _job_complete: JobId=53837 WEXITSTATUS 0
[2022-12-13T16:26:49.546] _job_complete: JobId=53837 done
[2022-12-13T17:04:35.377] _job_complete: JobId=53836 WEXITSTATUS 0
[2022-12-13T17:04:35.377] _job_complete: JobId=53836 done
[2022-12-13T17:08:04.725] _job_complete: JobId=53829 WEXITSTATUS 0
[2022-12-13T17:08:04.725] _job_complete: JobId=53829 done
[2022-12-13T17:32:46.598] sched: _slurm_rpc_allocate_resources JobId=53838 NodeList=(null) usec=982
[2022-12-13T17:32:47.391] sched: Allocate JobId=53838 NodeList=gpu04 #CPUs=8 Partition=gpu-k40c
[2022-12-13T17:58:34.395] _job_complete: JobId=53807 WEXITSTATUS 0
[2022-12-13T17:58:34.395] _job_complete: JobId=53807 done
[2022-12-13T18:03:36.396] cleanup_completing: JobId=53807 completion process took 302 seconds
[2022-12-13T18:17:53.874] _slurm_rpc_submit_batch_job: JobId=53839 InitPrio=992 usec=556
[2022-12-13T18:17:54.065] sched: Allocate JobId=53839 NodeList=cpu01 #CPUs=1 Partition=cpu-opteron
[2022-12-13T18:17:57.605] _job_complete: JobId=53839 WEXITSTATUS 0
[2022-12-13T18:17:57.605] _job_complete: JobId=53839 done
[2022-12-13T18:35:05.607] _job_complete: JobId=53838 WEXITSTATUS 0
[2022-12-13T18:35:05.607] _job_complete: JobId=53838 done
[2022-12-13T18:40:59.231] _slurm_rpc_submit_batch_job: JobId=53840 InitPrio=198 usec=539
[2022-12-13T18:41:14.671] _slurm_rpc_kill_job: REQUEST_KILL_JOB JobId=53464 uid 548300621
[2022-12-13T18:41:16.254] _slurm_rpc_kill_job: REQUEST_KILL_JOB JobId=53464 uid 548300621
[2022-12-13T19:56:44.646] _slurm_rpc_submit_batch_job: JobId=53841 InitPrio=992 usec=579
[2022-12-13T19:56:45.417] sched: Allocate JobId=53841 NodeList=cpu01 #CPUs=16 Partition=cpu-opteron
[2022-12-13T19:57:02.584] _job_complete: JobId=53841 WEXITSTATUS 1
[2022-12-13T19:57:02.584] _job_complete: JobId=53841 done
[2022-12-13T19:57:35.128] _slurm_rpc_submit_batch_job: JobId=53842 InitPrio=992 usec=526
[2022-12-13T19:57:35.463] sched: Allocate JobId=53842 NodeList=cpu01 #CPUs=16 Partition=cpu-opteron
[2022-12-13T21:19:46.502] _slurm_rpc_submit_batch_job: JobId=53843 InitPrio=198 usec=588
[2022-12-13T21:19:46.973] sched: Allocate JobId=53843 NodeList=cpu03 #CPUs=64 Partition=cpu-opteron
[2022-12-13T21:19:49.829] _slurm_rpc_submit_batch_job: JobId=53844 InitPrio=198 usec=458
[2022-12-13T21:19:49.963] sched: Allocate JobId=53844 NodeList=cpu09 #CPUs=64 Partition=cpu-opteron
[2022-12-13T21:23:11.146] _slurm_rpc_submit_batch_job: JobId=53845 InitPrio=198 usec=604
[2022-12-13T21:23:11.331] sched: Allocate JobId=53845 NodeList=cpu10 #CPUs=64 Partition=cpu-opteron
[2022-12-13T21:23:40.529] _slurm_rpc_submit_batch_job: JobId=53846 InitPrio=198 usec=501
[2022-12-13T21:23:41.369] sched: Allocate JobId=53846 NodeList=cpu11 #CPUs=64 Partition=cpu-opteron
[2022-12-13T21:30:08.643] _slurm_rpc_submit_batch_job: JobId=53847 InitPrio=198 usec=537
[2022-12-13T21:30:12.594] _slurm_rpc_submit_batch_job: JobId=53848 InitPrio=198 usec=566
[2022-12-13T21:30:15.653] _slurm_rpc_submit_batch_job: JobId=53849 InitPrio=198 usec=459
[2022-12-13T21:30:18.700] _slurm_rpc_submit_batch_job: JobId=53850 InitPrio=198 usec=467
[2022-12-13T22:39:35.858] Time limit exhausted for JobId=53749
[2022-12-14T01:28:53.322] _slurm_rpc_submit_batch_job: JobId=53851 InitPrio=992 usec=623
[2022-12-14T01:28:53.490] sched: Allocate JobId=53851 NodeList=cpu01 #CPUs=16 Partition=cpu-opteron
[2022-12-14T01:37:40.524] _slurm_rpc_submit_batch_job: JobId=53852 InitPrio=992 usec=609
[2022-12-14T01:37:41.203] sched: Allocate JobId=53852 NodeList=cpu01 #CPUs=16 Partition=cpu-opteron
[2022-12-14T01:46:09.868] _job_complete: JobId=53851 WEXITSTATUS 0
[2022-12-14T01:46:09.868] _job_complete: JobId=53851 done
[2022-12-14T01:50:48.439] _slurm_rpc_submit_batch_job: JobId=53853 InitPrio=992 usec=604
[2022-12-14T01:50:48.652] sched: Allocate JobId=53853 NodeList=cpu01 #CPUs=16 Partition=cpu-opteron
[2022-12-14T01:50:52.673] _slurm_rpc_submit_batch_job: JobId=53854 InitPrio=992 usec=470
[2022-12-14T02:07:48.904] _job_complete: JobId=53842 WEXITSTATUS 0
[2022-12-14T02:07:48.905] _job_complete: JobId=53842 done
[2022-12-14T02:07:49.856] sched: Allocate JobId=53854 NodeList=cpu01 #CPUs=16 Partition=cpu-opteron
[2022-12-14T02:18:44.605] _job_complete: JobId=53853 WEXITSTATUS 0
[2022-12-14T02:18:44.606] _job_complete: JobId=53853 done
[2022-12-14T04:07:04.029] _job_complete: JobId=53664 WEXITSTATUS 0
[2022-12-14T04:07:04.035] _job_complete: JobId=53664 done
[2022-12-14T04:07:04.982] sched: Allocate JobId=53817 NodeList=gpu05 #CPUs=1 Partition=gpu-v100s
[2022-12-14T04:07:05.003] sched: Allocate JobId=53812 NodeList=gpu05 #CPUs=16 Partition=gpu-v100s
[2022-12-14T04:13:56.527] _job_complete: JobId=53854 WEXITSTATUS 0
[2022-12-14T04:13:56.527] _job_complete: JobId=53854 done
[2022-12-14T04:25:54.967] _job_complete: JobId=53852 WEXITSTATUS 0
[2022-12-14T04:25:54.967] _job_complete: JobId=53852 done
[2022-12-14T04:52:31.919] _job_complete: JobId=53831 WEXITSTATUS 0
[2022-12-14T04:52:31.919] _job_complete: JobId=53831 done
[2022-12-14T04:52:32.503] sched: Allocate JobId=53832 NodeList=cpu13 #CPUs=8 Partition=cpu-epyc
[2022-12-14T04:59:31.220] _job_complete: JobId=53830 WEXITSTATUS 0
[2022-12-14T04:59:31.220] _job_complete: JobId=53830 done
[2022-12-14T04:59:31.498] sched: Allocate JobId=53833 NodeList=cpu13 #CPUs=8 Partition=cpu-epyc
[2022-12-14T05:07:05.203] Time limit exhausted for JobId=53817
[2022-12-14T07:32:51.628] _job_complete: JobId=53812 WEXITSTATUS 0
[2022-12-14T07:32:51.634] _job_complete: JobId=53812 done
[2022-12-14T07:32:52.568] sched: Allocate JobId=53665 NodeList=gpu05 #CPUs=16 Partition=gpu-v100s
[2022-12-14T08:34:09.716] _slurm_rpc_submit_batch_job: JobId=53855 InitPrio=13952 usec=484
[2022-12-14T08:34:09.929] sched: Allocate JobId=53855 NodeList=cpu01 #CPUs=1 Partition=cpu-opteron
[2022-12-14T09:34:35.959] Time limit exhausted for JobId=53855
[2022-12-14T09:39:00.953] _slurm_rpc_submit_batch_job: JobId=53856 InitPrio=13952 usec=538
[2022-12-14T09:39:01.469] sched: Allocate JobId=53856 NodeList=cpu01 #CPUs=1 Partition=cpu-opteron
[2022-12-14T09:39:42.924] _slurm_rpc_submit_batch_job: JobId=53857 InitPrio=790 usec=462
[2022-12-14T09:40:11.784] _slurm_rpc_submit_batch_job: JobId=53858 InitPrio=790 usec=399
[2022-12-14T09:40:21.211] sched/backfill: _start_job: Started JobId=53857 in cpu-opteron on cpu01
[2022-12-14T09:40:21.212] sched/backfill: _start_job: Started JobId=53858 in cpu-opteron on cpu01
[2022-12-14T09:40:52.871] _job_complete: JobId=53858 WEXITSTATUS 0
[2022-12-14T09:40:52.871] _job_complete: JobId=53858 done
[2022-12-14T09:40:53.024] _slurm_rpc_submit_batch_job: JobId=53859 InitPrio=790 usec=462
[2022-12-14T09:41:14.593] _slurm_rpc_submit_batch_job: JobId=53860 InitPrio=790 usec=527
[2022-12-14T09:41:21.215] sched/backfill: _start_job: Started JobId=53859 in cpu-opteron on cpu01
[2022-12-14T09:41:41.278] _job_complete: JobId=53859 WEXITSTATUS 0
[2022-12-14T09:41:41.279] _job_complete: JobId=53859 done
[2022-12-14T09:41:52.206] _slurm_rpc_submit_batch_job: JobId=53861 InitPrio=790 usec=475
[2022-12-14T09:42:18.782] _slurm_rpc_submit_batch_job: JobId=53862 InitPrio=790 usec=469
[2022-12-14T09:42:21.219] sched/backfill: _start_job: Started JobId=53860 in cpu-opteron on cpu01
[2022-12-14T09:42:40.537] _slurm_rpc_submit_batch_job: JobId=53863 InitPrio=790 usec=624
[2022-12-14T09:42:59.421] _job_complete: JobId=53860 WEXITSTATUS 0
[2022-12-14T09:42:59.422] _job_complete: JobId=53860 done
[2022-12-14T09:43:21.222] sched/backfill: _start_job: Started JobId=53861 in cpu-opteron on cpu01
[2022-12-14T09:48:43.188] _slurm_rpc_submit_batch_job: JobId=53864 InitPrio=2766 usec=503
[2022-12-14T10:08:00.090] _job_complete: JobId=53861 WEXITSTATUS 0
[2022-12-14T10:08:00.091] _job_complete: JobId=53861 done
[2022-12-14T10:08:21.271] sched/backfill: _start_job: Started JobId=53862 in cpu-opteron on cpu01
[2022-12-14T10:08:59.325] _job_complete: JobId=53862 WEXITSTATUS 0
[2022-12-14T10:08:59.325] _job_complete: JobId=53862 done
[2022-12-14T10:09:21.274] sched/backfill: _start_job: Started JobId=53863 in cpu-opteron on cpu01
[2022-12-14T10:10:00.988] _job_complete: JobId=53863 WEXITSTATUS 0
[2022-12-14T10:10:00.988] _job_complete: JobId=53863 done
[2022-12-14T10:13:15.771] _slurm_rpc_kill_job: REQUEST_KILL_JOB JobId=53856 uid 548300642
[2022-12-14T10:16:45.385] _job_complete: JobId=53857 WEXITSTATUS 0
[2022-12-14T10:16:45.386] _job_complete: JobId=53857 done
[2022-12-14T10:47:21.334] _slurm_rpc_submit_batch_job: JobId=53865 InitPrio=790 usec=586
[2022-12-14T10:47:21.344] sched/backfill: _start_job: Started JobId=53865 in cpu-opteron on cpu01
[2022-12-14T10:47:26.581] _job_complete: JobId=53865 WEXITSTATUS 1
[2022-12-14T10:47:26.582] _job_complete: JobId=53865 done
[2022-12-14T10:48:17.475] _slurm_rpc_submit_batch_job: JobId=53866 InitPrio=790 usec=453
[2022-12-14T10:48:21.347] sched/backfill: _start_job: Started JobId=53866 in cpu-opteron on cpu01
[2022-12-14T10:48:23.402] _job_complete: JobId=53866 WEXITSTATUS 1
[2022-12-14T10:48:23.403] _job_complete: JobId=53866 done
[2022-12-14T10:48:42.601] _slurm_rpc_submit_batch_job: JobId=53867 InitPrio=790 usec=405
[2022-12-14T10:49:21.350] sched/backfill: _start_job: Started JobId=53867 in cpu-opteron on cpu01
[2022-12-14T10:49:31.687] _job_complete: JobId=53867 WEXITSTATUS 0
[2022-12-14T10:49:31.687] _job_complete: JobId=53867 done
[2022-12-14T11:16:16.607] _slurm_rpc_submit_batch_job: JobId=53868 InitPrio=790 usec=510
[2022-12-14T11:16:21.414] sched/backfill: _start_job: Started JobId=53868 in cpu-opteron on cpu01
[2022-12-14T11:16:51.404] _job_complete: JobId=53868 WEXITSTATUS 0
[2022-12-14T11:16:51.405] _job_complete: JobId=53868 done
[2022-12-14T11:35:11.113] _slurm_rpc_submit_batch_job: JobId=53869 InitPrio=13952 usec=544
[2022-12-14T11:35:11.894] sched: Allocate JobId=53869 NodeList=cpu01 #CPUs=1 Partition=cpu-opteron
[2022-12-14T12:04:19.109] sched: _slurm_rpc_allocate_resources JobId=53870 NodeList=(null) usec=1275
[2022-12-14T12:04:20.090] sched: Allocate JobId=53870 NodeList=gpu04 #CPUs=8 Partition=gpu-k40c
[2022-12-14T12:21:04.923] sched: _slurm_rpc_allocate_resources JobId=53871 NodeList=(null) usec=1269
[2022-12-14T12:21:05.187] sched: Allocate JobId=53871 NodeList=cpu13 #CPUs=8 Partition=cpu-epyc
[2022-12-14T12:35:36.487] Time limit exhausted for JobId=53869
[2022-12-14T12:35:59.869] _slurm_rpc_submit_batch_job: JobId=53872 InitPrio=13952 usec=487
[2022-12-14T12:36:00.617] sched: Allocate JobId=53872 NodeList=cpu01 #CPUs=1 Partition=cpu-opteron
[2022-12-14T12:43:54.268] _job_complete: JobId=53672 WEXITSTATUS 0
[2022-12-14T12:43:54.268] _job_complete: JobId=53672 done
[2022-12-14T12:54:39.312] _slurm_rpc_submit_batch_job: JobId=53873 InitPrio=790 usec=1305
[2022-12-14T12:55:51.088] _slurm_rpc_kill_job: REQUEST_KILL_JOB JobId=53873 uid 548200029
[2022-12-14T12:56:18.415] _slurm_rpc_submit_batch_job: JobId=53874 InitPrio=790 usec=1239
[2022-12-14T13:21:06.208] Time limit exhausted for JobId=53871
[2022-12-14T13:24:07.318] _job_complete: JobId=53872 WEXITSTATUS 0
[2022-12-14T13:24:07.318] _job_complete: JobId=53872 done
[2022-12-14T13:26:07.860] cleanup_completing: JobId=53871 completion process took 301 seconds
[2022-12-14T14:08:44.143] sched: _slurm_rpc_allocate_resources JobId=53875 NodeList=(null) usec=5341
[2022-12-14T14:08:44.658] sched: Allocate JobId=53875 NodeList=cpu01 #CPUs=1 Partition=cpu-opteron
[2022-12-14T14:20:37.181] job_step_signal: JobId=53875 StepId=0 not found
[2022-12-14T14:20:37.254] _job_complete: JobId=53875 WEXITSTATUS 0
[2022-12-14T14:20:37.254] _job_complete: JobId=53875 done
[2022-12-14T14:23:40.432] sched: _slurm_rpc_allocate_resources JobId=53876 NodeList=(null) usec=782
[2022-12-14T14:23:41.146] sched: Allocate JobId=53876 NodeList=cpu01 #CPUs=1 Partition=cpu-opteron
[2022-12-14T14:27:30.648] _job_complete: JobId=53870 WEXITSTATUS 0
[2022-12-14T14:27:30.649] _job_complete: JobId=53870 done
[2022-12-14T14:32:30.903] cleanup_completing: JobId=53870 completion process took 300 seconds
[2022-12-14T14:43:30.659] _slurm_rpc_submit_batch_job: JobId=53877 InitPrio=15533 usec=445
[2022-12-14T17:27:41.892] _slurm_rpc_submit_batch_job: JobId=53878 InitPrio=10592 usec=428
[2022-12-14T17:27:42.182] sched: Allocate JobId=53878 NodeList=cpu01 #CPUs=2 Partition=cpu-opteron
[2022-12-14T17:33:04.056] _job_complete: JobId=53876 WEXITSTATUS 0
[2022-12-14T17:33:04.057] _job_complete: JobId=53876 done
[2022-12-14T17:38:04.795] cleanup_completing: JobId=53876 completion process took 300 seconds
[2022-12-14T17:41:03.630] _slurm_rpc_submit_batch_job: JobId=53879 InitPrio=13557 usec=537
[2022-12-14T17:41:04.549] sched: Allocate JobId=53879 NodeList=cpu01 #CPUs=12 Partition=cpu-opteron
[2022-12-14T17:43:08.489] sched: _slurm_rpc_allocate_resources JobId=53880 NodeList=(null) usec=966
[2022-12-14T17:43:08.704] sched: Allocate JobId=53880 NodeList=gpu04 #CPUs=8 Partition=gpu-k40c
[2022-12-14T18:09:31.913] _job_complete: JobId=53832 WEXITSTATUS 0
[2022-12-14T18:09:31.913] _job_complete: JobId=53832 done
[2022-12-14T18:09:32.657] sched: Allocate JobId=53834 NodeList=cpu13 #CPUs=8 Partition=cpu-epyc
[2022-12-14T18:22:51.732] _job_complete: JobId=53833 WEXITSTATUS 0
[2022-12-14T18:22:51.732] _job_complete: JobId=53833 done
[2022-12-14T18:22:52.056] sched: Allocate JobId=53835 NodeList=cpu13 #CPUs=8 Partition=cpu-epyc
[2022-12-14T18:25:27.137] _job_complete: JobId=53880 WEXITSTATUS 0
[2022-12-14T18:25:27.138] _job_complete: JobId=53880 done
[2022-12-14T18:28:07.568] Time limit exhausted for JobId=53878
[2022-12-14T18:41:07.930] Time limit exhausted for JobId=53879
[2022-12-14T18:57:24.716] _slurm_rpc_kill_job: REQUEST_KILL_JOB JobId=53703 uid 548200017
[2022-12-14T18:57:24.716] _slurm_rpc_kill_job: REQUEST_KILL_JOB JobId=53705 uid 548200017
[2022-12-14T18:57:24.716] _slurm_rpc_kill_job: REQUEST_KILL_JOB JobId=53704 uid 548200017
[2022-12-14T18:57:30.677] sched: Allocate JobId=53810 NodeList=cpu14 #CPUs=48 Partition=cpu-epyc
[2022-12-14T18:57:32.900] sched: Allocate JobId=53840 NodeList=cpu15 #CPUs=48 Partition=cpu-epyc
[2022-12-14T18:58:07.657] _slurm_rpc_kill_job: REQUEST_KILL_JOB JobId=53811 uid 548200017
[2022-12-14T18:58:07.657] _slurm_rpc_kill_job: REQUEST_KILL_JOB JobId=53813 uid 548200017
[2022-12-14T18:58:07.657] _slurm_rpc_kill_job: REQUEST_KILL_JOB JobId=53706 uid 548200017
[2022-12-14T18:58:07.657] _slurm_rpc_kill_job: REQUEST_KILL_JOB JobId=53712 uid 548200017
[2022-12-14T18:58:10.003] sched: Allocate JobId=53847 NodeList=cpu08 #CPUs=64 Partition=cpu-opteron
[2022-12-14T18:58:10.072] sched: Allocate JobId=53848 NodeList=cpu07 #CPUs=64 Partition=cpu-opteron
[2022-12-14T19:01:43.739] _slurm_rpc_submit_batch_job: JobId=53881 InitPrio=197 usec=526
[2022-12-14T19:01:44.146] sched: Allocate JobId=53881 NodeList=cpu04 #CPUs=64 Partition=cpu-opteron
[2022-12-14T19:08:27.113] _slurm_rpc_submit_batch_job: JobId=53882 InitPrio=197 usec=449
[2022-12-14T19:08:27.928] sched: Allocate JobId=53882 NodeList=cpu12 #CPUs=48 Partition=cpu-epyc
[2022-12-14T19:14:26.796] _job_complete: JobId=53881 OOM failure
[2022-12-14T19:14:26.797] _job_complete: JobId=53881 done
[2022-12-14T21:01:22.307] _slurm_rpc_submit_batch_job: JobId=53883 InitPrio=10592 usec=410
[2022-12-14T21:01:23.005] sched: Allocate JobId=53883 NodeList=cpu01 #CPUs=2 Partition=cpu-opteron
[2022-12-14T21:51:04.013] sched: _slurm_rpc_allocate_resources JobId=53884 NodeList=(null) usec=1120
[2022-12-14T21:51:04.398] sched: Allocate JobId=53884 NodeList=gpu04 #CPUs=8 Partition=gpu-k40c
[2022-12-14T21:54:57.951] _slurm_rpc_submit_batch_job: JobId=53885 InitPrio=197 usec=537
[2022-12-14T21:54:58.705] sched: Allocate JobId=53885 NodeList=cpu04 #CPUs=64 Partition=cpu-opteron
[2022-12-14T22:01:38.489] Time limit exhausted for JobId=53883
[2022-12-14T22:09:53.001] _slurm_rpc_submit_batch_job: JobId=53886 InitPrio=10592 usec=440
[2022-12-14T22:09:53.223] sched: Allocate JobId=53886 NodeList=cpu01 #CPUs=2 Partition=cpu-opteron
[2022-12-14T22:09:53.895] _slurm_rpc_submit_batch_job: JobId=53887 InitPrio=197 usec=474
[2022-12-14T22:09:56.226] sched: Allocate JobId=53887 NodeList=cpu13 #CPUs=24 Partition=cpu-epyc
[2022-12-14T22:10:20.365] _slurm_rpc_kill_job: REQUEST_KILL_JOB JobId=53887 uid 548200017
[2022-12-14T22:10:46.257] _slurm_rpc_submit_batch_job: JobId=53888 InitPrio=197 usec=466
[2022-12-14T22:10:46.288] sched: Allocate JobId=53888 NodeList=cpu05 #CPUs=64 Partition=cpu-opteron
[2022-12-14T22:14:13.977] _slurm_rpc_submit_batch_job: JobId=53889 InitPrio=592 usec=577
[2022-12-14T22:14:15.885] _slurm_rpc_submit_batch_job: JobId=53890 InitPrio=592 usec=529
[2022-12-14T22:14:57.264] _slurm_rpc_kill_job: REQUEST_KILL_JOB JobId=53890 uid 548200121
[2022-12-14T22:14:59.016] _slurm_rpc_kill_job: REQUEST_KILL_JOB JobId=53889 uid 548200121
[2022-12-14T22:15:27.871] _slurm_rpc_submit_batch_job: JobId=53891 InitPrio=592 usec=654
[2022-12-14T22:15:29.942] _slurm_rpc_submit_batch_job: JobId=53892 InitPrio=592 usec=548
[2022-12-14T22:16:15.299] _slurm_rpc_submit_batch_job: JobId=53893 InitPrio=197 usec=487
[2022-12-14T22:16:49.754] _slurm_rpc_kill_job: REQUEST_KILL_JOB JobId=53893 uid 548200017
[2022-12-14T22:17:17.587] _slurm_rpc_submit_batch_job: JobId=53894 InitPrio=197 usec=465
[2022-12-14T22:17:20.007] sched: Allocate JobId=53894 NodeList=cpu13 #CPUs=24 Partition=cpu-epyc
[2022-12-14T22:54:21.258] _slurm_rpc_kill_job: REQUEST_KILL_JOB JobId=53886 uid 548200121
[2022-12-14T22:54:32.749] _slurm_rpc_submit_batch_job: JobId=53895 InitPrio=10592 usec=413
[2022-12-14T22:54:32.943] sched: Allocate JobId=53895 NodeList=cpu01 #CPUs=2 Partition=cpu-opteron
[2022-12-14T23:09:26.100] sched: _slurm_rpc_allocate_resources JobId=53896 NodeList=(null) usec=916
[2022-12-14T23:09:26.710] sched: Allocate JobId=53896 NodeList=gpu04 #CPUs=8 Partition=gpu-k40c
[2022-12-14T23:09:32.642] _job_complete: JobId=53896 WEXITSTATUS 0
[2022-12-14T23:09:32.642] _job_complete: JobId=53896 done
[2022-12-14T23:09:36.268] _get_job_parts: invalid partition specified: gpu-k40cn
[2022-12-14T23:09:36.268] _slurm_rpc_submit_batch_job: Invalid partition name specified
[2022-12-14T23:10:12.735] _slurm_rpc_submit_batch_job: JobId=53897 InitPrio=4940 usec=578
[2022-12-14T23:10:12.766] sched: Allocate JobId=53897 NodeList=gpu04 #CPUs=8 Partition=gpu-k40c
[2022-12-14T23:10:43.837] _job_complete: JobId=53884 WEXITSTATUS 0
[2022-12-14T23:10:43.837] _job_complete: JobId=53884 done
[2022-12-14T23:37:13.792] _slurm_rpc_submit_batch_job: JobId=53898 InitPrio=988 usec=502
[2022-12-14T23:37:14.342] sched: Allocate JobId=53898 NodeList=cpu01 #CPUs=1 Partition=cpu-opteron
[2022-12-14T23:37:17.533] _job_complete: JobId=53898 WEXITSTATUS 0
[2022-12-14T23:37:17.533] _job_complete: JobId=53898 done
[2022-12-14T23:54:39.065] Time limit exhausted for JobId=53895
[2022-12-15T00:01:22.499] _job_complete: JobId=53897 WEXITSTATUS 0
[2022-12-15T00:01:22.499] _job_complete: JobId=53897 done
[2022-12-15T00:10:38.563] _slurm_rpc_submit_batch_job: JobId=53899 InitPrio=4940 usec=639
[2022-12-15T00:10:38.984] sched: Allocate JobId=53899 NodeList=gpu04 #CPUs=8 Partition=gpu-k40c
[2022-12-15T00:11:14.254] _job_complete: JobId=53899 WEXITSTATUS 0
[2022-12-15T00:11:14.254] _job_complete: JobId=53899 done
[2022-12-15T00:13:01.956] _slurm_rpc_submit_batch_job: JobId=53900 InitPrio=4940 usec=653
[2022-12-15T00:13:02.283] sched: Allocate JobId=53900 NodeList=gpu04 #CPUs=8 Partition=gpu-k40c
[2022-12-15T00:14:30.768] _slurm_rpc_submit_batch_job: JobId=53901 InitPrio=4940 usec=505
[2022-12-15T00:14:31.390] sched: Allocate JobId=53901 NodeList=gpu04 #CPUs=8 Partition=gpu-k40c
[2022-12-15T00:14:36.706] _job_complete: JobId=53901 WEXITSTATUS 0
[2022-12-15T00:14:36.706] _job_complete: JobId=53901 done
[2022-12-15T00:15:33.310] sched: _slurm_rpc_allocate_resources JobId=53902 NodeList=(null) usec=871
[2022-12-15T00:15:33.464] sched: Allocate JobId=53902 NodeList=gpu04 #CPUs=8 Partition=gpu-k40c
[2022-12-15T00:16:34.144] _job_complete: JobId=53902 WEXITSTATUS 0
[2022-12-15T00:16:34.144] _job_complete: JobId=53902 done
[2022-12-15T00:16:56.607] _slurm_rpc_submit_batch_job: JobId=53903 InitPrio=4940 usec=551
[2022-12-15T00:16:56.756] sched: Allocate JobId=53903 NodeList=gpu04 #CPUs=8 Partition=gpu-k40c
[2022-12-15T00:24:10.972] _job_complete: JobId=53903 WEXITSTATUS 0
[2022-12-15T00:24:10.972] _job_complete: JobId=53903 done
[2022-12-15T00:40:48.461] _slurm_rpc_submit_batch_job: JobId=53904 InitPrio=4940 usec=553
[2022-12-15T00:40:48.611] sched: Allocate JobId=53904 NodeList=gpu04 #CPUs=8 Partition=gpu-k40c
[2022-12-15T01:04:30.615] _job_complete: JobId=53900 WEXITSTATUS 0
[2022-12-15T01:04:30.616] _job_complete: JobId=53900 done
[2022-12-15T01:32:12.346] _job_complete: JobId=53904 WEXITSTATUS 0
[2022-12-15T01:32:12.346] _job_complete: JobId=53904 done
[2022-12-15T02:19:50.191] sched: _slurm_rpc_allocate_resources JobId=53905 NodeList=(null) usec=953
[2022-12-15T02:19:51.128] sched: Allocate JobId=53905 NodeList=gpu04 #CPUs=8 Partition=gpu-k40c
[2022-12-15T02:52:17.400] _job_complete: JobId=53905 WEXITSTATUS 0
[2022-12-15T02:52:17.400] _job_complete: JobId=53905 done
[2022-12-15T03:20:38.029] sched: _slurm_rpc_allocate_resources JobId=53906 NodeList=(null) usec=1023
[2022-12-15T03:20:38.056] sched: Allocate JobId=53906 NodeList=gpu04 #CPUs=8 Partition=gpu-k40c
[2022-12-15T03:43:08.340] _job_complete: JobId=53906 WEXITSTATUS 130
[2022-12-15T03:43:08.341] _job_complete: JobId=53906 done
[2022-12-15T03:44:02.691] _slurm_rpc_submit_batch_job: JobId=53907 InitPrio=4940 usec=540
[2022-12-15T03:44:03.000] sched: Allocate JobId=53907 NodeList=gpu04 #CPUs=8 Partition=gpu-k40c
[2022-12-15T06:13:13.858] _job_complete: JobId=53834 WEXITSTATUS 0
[2022-12-15T06:13:13.858] _job_complete: JobId=53834 done
[2022-12-15T06:32:33.821] _job_complete: JobId=53835 WEXITSTATUS 0
[2022-12-15T06:32:33.821] _job_complete: JobId=53835 done
[2022-12-15T06:57:19.372] _job_complete: JobId=53885 WEXITSTATUS 0
[2022-12-15T06:57:19.378] _job_complete: JobId=53885 done
[2022-12-15T07:59:40.083] _job_complete: JobId=53907 WEXITSTATUS 0
[2022-12-15T07:59:40.084] _job_complete: JobId=53907 done
[2022-12-15T08:50:53.654] _slurm_rpc_submit_batch_job: JobId=53908 InitPrio=4545 usec=545
[2022-12-15T08:50:54.122] sched: Allocate JobId=53908 NodeList=gpu04 #CPUs=8 Partition=gpu-k40c
[2022-12-15T08:53:43.928] _job_complete: JobId=53908 WEXITSTATUS 0
[2022-12-15T08:53:43.928] _job_complete: JobId=53908 done
[2022-12-15T08:54:52.317] _job_complete: JobId=53789 WEXITSTATUS 0
[2022-12-15T08:54:52.322] _job_complete: JobId=53789 done
[2022-12-15T08:54:53.534] sched: Allocate JobId=53816 NodeList=gpu02 #CPUs=1 Partition=gpu-titan
[2022-12-15T08:54:53.535] sched: Allocate JobId=53822 NodeList=gpu02 #CPUs=1 Partition=gpu-titan
[2022-12-15T09:15:32.918] _slurm_rpc_submit_batch_job: JobId=53909 InitPrio=1383 usec=526
[2022-12-15T09:15:33.192] sched: Allocate JobId=53909 NodeList=cpu13 #CPUs=8 Partition=cpu-epyc
[2022-12-15T09:15:36.158] _slurm_rpc_submit_batch_job: JobId=53910 InitPrio=1383 usec=532
[2022-12-15T09:15:36.179] sched: Allocate JobId=53910 NodeList=cpu13 #CPUs=8 Partition=cpu-epyc
[2022-12-15T09:15:39.409] _slurm_rpc_submit_batch_job: JobId=53911 InitPrio=1383 usec=446
[2022-12-15T09:15:42.613] _slurm_rpc_submit_batch_job: JobId=53912 InitPrio=1383 usec=523
[2022-12-15T09:15:46.478] _slurm_rpc_submit_batch_job: JobId=53913 InitPrio=1383 usec=652
[2022-12-15T09:15:50.324] _slurm_rpc_submit_batch_job: JobId=53914 InitPrio=1383 usec=428
[2022-12-15T09:16:01.541] _slurm_rpc_submit_batch_job: JobId=53915 InitPrio=1383 usec=526
[2022-12-15T09:16:11.499] _slurm_rpc_submit_batch_job: JobId=53916 InitPrio=1383 usec=501
[2022-12-15T09:16:21.091] _slurm_rpc_submit_batch_job: JobId=53917 InitPrio=1383 usec=509
[2022-12-15T09:43:29.871] _slurm_rpc_submit_batch_job: JobId=53918 InitPrio=4545 usec=615
[2022-12-15T09:43:30.092] sched: Allocate JobId=53918 NodeList=gpu04 #CPUs=8 Partition=gpu-k40c
[2022-12-15T09:55:11.174] Time limit exhausted for JobId=53816
[2022-12-15T09:55:11.176] Time limit exhausted for JobId=53822
[2022-12-15T09:55:12.055] sched: Allocate JobId=53823 NodeList=gpu02 #CPUs=6 Partition=gpu-titan
[2022-12-15T10:13:52.586] _slurm_rpc_kill_job: REQUEST_KILL_JOB JobId=53918 uid 548300544
[2022-12-15T10:15:15.098] _slurm_rpc_kill_job: REQUEST_KILL_JOB JobId=53790 uid 548200029
[2022-12-15T10:15:17.180] sched: Allocate JobId=53824 NodeList=gpu02 #CPUs=6 Partition=gpu-titan
[2022-12-15T10:19:11.103] sched: _slurm_rpc_allocate_resources JobId=53919 NodeList=(null) usec=930
[2022-12-15T10:19:11.188] sched: Allocate JobId=53919 NodeList=gpu04 #CPUs=8 Partition=gpu-k40c
[2022-12-15T10:21:16.409] _slurm_rpc_submit_batch_job: JobId=53920 InitPrio=790 usec=647
[2022-12-15T10:24:11.382] _job_complete: JobId=53919 WEXITSTATUS 1
[2022-12-15T10:24:11.382] _job_complete: JobId=53919 done
[2022-12-15T10:24:43.316] sched: _slurm_rpc_allocate_resources JobId=53921 NodeList=(null) usec=927
[2022-12-15T10:24:43.752] sched: Allocate JobId=53921 NodeList=gpu04 #CPUs=16 Partition=gpu-k40c
[2022-12-15T10:29:57.712] sched: _slurm_rpc_allocate_resources JobId=53922 NodeList=(null) usec=876
[2022-12-15T10:29:58.257] sched: Allocate JobId=53922 NodeList=cpu01 #CPUs=1 Partition=cpu-opteron
[2022-12-15T10:30:11.514] _job_complete: JobId=53922 WTERMSIG 2
[2022-12-15T10:30:11.514] _job_complete: JobId=53922 done
[2022-12-15T10:30:27.141] _slurm_rpc_submit_batch_job: JobId=53923 InitPrio=4545 usec=664
[2022-12-15T10:30:51.062] _job_complete: JobId=53921 WEXITSTATUS 0
[2022-12-15T10:30:51.062] _job_complete: JobId=53921 done
[2022-12-15T10:30:52.147] sched: Allocate JobId=53923 NodeList=gpu04 #CPUs=16 Partition=gpu-k40c
[2022-12-15T10:38:44.451] _slurm_rpc_submit_batch_job: JobId=53924 InitPrio=395 usec=495
[2022-12-15T10:38:45.169] sched: Allocate JobId=53924 NodeList=cpu01 #CPUs=32 Partition=cpu-opteron
[2022-12-15T10:38:51.474] _job_complete: JobId=53924 WEXITSTATUS 1
[2022-12-15T10:38:51.475] _job_complete: JobId=53924 done
[2022-12-15T10:38:55.936] _slurm_rpc_submit_batch_job: JobId=53925 InitPrio=395 usec=481
[2022-12-15T10:38:56.161] sched: Allocate JobId=53925 NodeList=cpu01 #CPUs=32 Partition=cpu-opteron
[2022-12-15T10:39:04.594] _slurm_rpc_submit_batch_job: JobId=53926 InitPrio=395 usec=467
[2022-12-15T10:39:05.174] sched: Allocate JobId=53926 NodeList=cpu04 #CPUs=32 Partition=cpu-opteron
[2022-12-15T10:39:13.775] _slurm_rpc_submit_batch_job: JobId=53927 InitPrio=395 usec=460
[2022-12-15T10:39:14.185] sched: Allocate JobId=53927 NodeList=cpu04 #CPUs=32 Partition=cpu-opteron
[2022-12-15T10:39:27.379] _slurm_rpc_submit_batch_job: JobId=53928 InitPrio=395 usec=484
[2022-12-15T10:39:43.695] _slurm_rpc_submit_batch_job: JobId=53929 InitPrio=395 usec=461
[2022-12-15T10:39:53.987] _slurm_rpc_submit_batch_job: JobId=53930 InitPrio=395 usec=464
[2022-12-15T10:40:10.055] _slurm_rpc_kill_job: REQUEST_KILL_JOB JobId=53792 uid 548200029
[2022-12-15T10:41:00.720] _job_complete: JobId=53927 WEXITSTATUS 1
[2022-12-15T10:41:00.720] _job_complete: JobId=53927 done
[2022-12-15T10:41:01.361] sched: Allocate JobId=53928 NodeList=cpu04 #CPUs=32 Partition=cpu-opteron
[2022-12-15T10:41:16.601] _slurm_rpc_kill_job: REQUEST_KILL_JOB JobId=53930 uid 548200017
[2022-12-15T10:41:16.601] _slurm_rpc_kill_job: REQUEST_KILL_JOB JobId=53929 uid 548200017
[2022-12-15T10:41:16.601] _slurm_rpc_kill_job: REQUEST_KILL_JOB JobId=53928 uid 548200017
[2022-12-15T10:41:41.882] _slurm_rpc_kill_job: REQUEST_KILL_JOB JobId=53925 uid 548200017
[2022-12-15T10:41:41.883] _slurm_rpc_kill_job: REQUEST_KILL_JOB JobId=53926 uid 548200017
[2022-12-15T10:41:41.883] _slurm_rpc_kill_job: REQUEST_KILL_JOB JobId=53927 uid 548200017
[2022-12-15T10:45:46.657] _slurm_rpc_submit_batch_job: JobId=53931 InitPrio=395 usec=514
[2022-12-15T10:45:46.806] sched: Allocate JobId=53931 NodeList=cpu01 #CPUs=32 Partition=cpu-opteron
[2022-12-15T10:46:01.467] _slurm_rpc_submit_batch_job: JobId=53932 InitPrio=395 usec=484
[2022-12-15T10:46:01.980] sched: Allocate JobId=53932 NodeList=cpu04 #CPUs=32 Partition=cpu-opteron
[2022-12-15T10:46:11.173] _slurm_rpc_submit_batch_job: JobId=53933 InitPrio=395 usec=485
[2022-12-15T10:46:12.033] sched: Allocate JobId=53933 NodeList=cpu04 #CPUs=32 Partition=cpu-opteron
[2022-12-15T10:46:25.155] _slurm_rpc_submit_batch_job: JobId=53934 InitPrio=395 usec=462
[2022-12-15T10:46:44.822] _slurm_rpc_submit_batch_job: JobId=53935 InitPrio=395 usec=455
[2022-12-15T10:46:59.416] _slurm_rpc_submit_batch_job: JobId=53936 InitPrio=395 usec=579
[2022-12-15T10:47:12.584] _slurm_rpc_submit_batch_job: JobId=53937 InitPrio=395 usec=458
[2022-12-15T10:48:39.107] _job_complete: JobId=53932 WEXITSTATUS 1
[2022-12-15T10:48:39.108] _job_complete: JobId=53932 done
[2022-12-15T10:48:39.772] sched: Allocate JobId=53934 NodeList=cpu04 #CPUs=32 Partition=cpu-opteron
[2022-12-15T10:50:22.595] _job_complete: JobId=53934 WEXITSTATUS 1
[2022-12-15T10:50:22.596] _job_complete: JobId=53934 done
[2022-12-15T10:50:23.283] sched: Allocate JobId=53935 NodeList=cpu04 #CPUs=32 Partition=cpu-opteron
[2022-12-15T11:09:09.732] _slurm_rpc_submit_batch_job: JobId=53938 InitPrio=790 usec=897
[2022-12-15T11:27:59.350] _slurm_rpc_submit_batch_job: JobId=53939 InitPrio=10592 usec=406
[2022-12-15T11:27:59.498] sched: Allocate JobId=53939 NodeList=cpu01 #CPUs=2 Partition=cpu-opteron
[2022-12-15T11:44:33.321] _slurm_rpc_submit_batch_job: JobId=53940 InitPrio=6719 usec=496
[2022-12-15T11:44:34.256] sched: Allocate JobId=53940 NodeList=cpu01 #CPUs=1 Partition=cpu-opteron
[2022-12-15T11:44:38.382] _job_complete: JobId=53940 WEXITSTATUS 1
[2022-12-15T11:44:38.382] _job_complete: JobId=53940 done
[2022-12-15T11:46:44.150] _slurm_rpc_submit_batch_job: JobId=53941 InitPrio=988 usec=697
[2022-12-15T12:02:41.353] _slurm_rpc_submit_batch_job: JobId=53942 InitPrio=6719 usec=529
[2022-12-15T12:02:41.564] sched: Allocate JobId=53942 NodeList=cpu01 #CPUs=1 Partition=cpu-opteron
[2022-12-15T12:03:04.199] _job_complete: JobId=53942 WEXITSTATUS 1
[2022-12-15T12:03:04.199] _job_complete: JobId=53942 done
[2022-12-15T12:13:56.251] _slurm_rpc_submit_batch_job: JobId=53943 InitPrio=10592 usec=378
[2022-12-15T12:13:56.707] sched: Allocate JobId=53943 NodeList=cpu01 #CPUs=2 Partition=cpu-opteron
[2022-12-15T12:15:28.950] _slurm_rpc_kill_job: REQUEST_KILL_JOB JobId=53939 uid 548200121
[2022-12-15T12:16:22.215] _get_job_parts: invalid partition specified: opteron
[2022-12-15T12:16:22.215] _slurm_rpc_submit_batch_job: Invalid partition name specified
[2022-12-15T12:16:53.819] _slurm_rpc_submit_batch_job: JobId=53944 InitPrio=988 usec=489
[2022-12-15T12:16:54.038] sched: Allocate JobId=53944 NodeList=cpu01 #CPUs=1 Partition=cpu-opteron
[2022-12-15T12:17:00.133] _job_complete: JobId=53944 WEXITSTATUS 1
[2022-12-15T12:17:00.134] _job_complete: JobId=53944 done
[2022-12-15T12:19:08.932] _slurm_rpc_submit_batch_job: JobId=53945 InitPrio=988 usec=505
[2022-12-15T12:19:09.188] sched: Allocate JobId=53945 NodeList=cpu01 #CPUs=1 Partition=cpu-opteron
[2022-12-15T12:19:12.038] _job_complete: JobId=53945 WEXITSTATUS 0
[2022-12-15T12:19:12.038] _job_complete: JobId=53945 done
[2022-12-15T12:21:17.495] Requeuing JobId=53824
[2022-12-15T12:21:18.488] Requeuing JobId=53823
[2022-12-15T12:21:18.490] sched: Allocate JobId=53808 NodeList=gpu02 #CPUs=8 Partition=gpu-titan
[2022-12-15T12:21:18.491] sched: Allocate JobId=53809 NodeList=gpu02 #CPUs=8 Partition=gpu-titan
[2022-12-15T12:22:51.333] _slurm_rpc_submit_batch_job: JobId=53946 InitPrio=988 usec=594
[2022-12-15T12:23:10.502] _slurm_rpc_submit_batch_job: JobId=53947 InitPrio=988 usec=529
[2022-12-15T12:33:17.400] _job_complete: JobId=53809 WEXITSTATUS 1
[2022-12-15T12:33:17.401] _job_complete: JobId=53809 done
[2022-12-15T12:33:18.538] sched: Allocate JobId=53874 NodeList=gpu02 #CPUs=8 Partition=gpu-titan
[2022-12-15T12:55:57.311] _job_complete: JobId=53808 WEXITSTATUS 1
[2022-12-15T12:55:57.312] _job_complete: JobId=53808 done
[2022-12-15T13:05:46.457] _job_complete: JobId=53933 WEXITSTATUS 0
[2022-12-15T13:05:46.463] _job_complete: JobId=53933 done
[2022-12-15T13:05:47.237] sched: Allocate JobId=53936 NodeList=cpu04 #CPUs=32 Partition=cpu-opteron
[2022-12-15T13:07:15.682] _slurm_rpc_submit_batch_job: JobId=53948 InitPrio=592 usec=630
[2022-12-15T13:07:16.457] sched: Allocate JobId=53948 NodeList=gpu02 #CPUs=8 Partition=gpu-titan
[2022-12-15T13:07:17.735] _slurm_rpc_submit_batch_job: JobId=53949 InitPrio=592 usec=646
[2022-12-15T13:07:19.445] sched: Allocate JobId=53949 NodeList=gpu02 #CPUs=8 Partition=gpu-titan
[2022-12-15T13:11:56.665] sched: _slurm_rpc_allocate_resources JobId=53950 NodeList=(null) usec=798
[2022-12-15T13:11:56.951] sched: Allocate JobId=53950 NodeList=cpu01 #CPUs=1 Partition=cpu-opteron
[2022-12-15T13:14:11.131] Time limit exhausted for JobId=53943
[2022-12-15T13:18:09.319] _job_complete: JobId=53874 WEXITSTATUS 1
[2022-12-15T13:18:09.320] _job_complete: JobId=53874 done
[2022-12-15T13:18:53.920] _job_complete: JobId=53949 WEXITSTATUS 1
[2022-12-15T13:18:53.921] _job_complete: JobId=53949 done
[2022-12-15T13:19:02.332] _slurm_rpc_submit_batch_job: JobId=53951 InitPrio=10592 usec=359
[2022-12-15T13:19:02.612] sched: Allocate JobId=53951 NodeList=cpu01 #CPUs=2 Partition=cpu-opteron
[2022-12-15T13:20:06.652] _job_complete: JobId=53935 WEXITSTATUS 0
[2022-12-15T13:20:06.653] _job_complete: JobId=53935 done
[2022-12-15T13:20:07.421] sched: Allocate JobId=53937 NodeList=cpu04 #CPUs=32 Partition=cpu-opteron
[2022-12-15T13:20:08.969] _job_complete: JobId=53937 WEXITSTATUS 1
[2022-12-15T13:20:08.969] _job_complete: JobId=53937 done
[2022-12-15T13:21:22.493] _slurm_rpc_submit_batch_job: JobId=53952 InitPrio=592 usec=584
[2022-12-15T13:21:23.316] sched: Allocate JobId=53952 NodeList=gpu02 #CPUs=16 Partition=gpu-titan
[2022-12-15T13:25:16.890] _job_complete: JobId=53788 WEXITSTATUS 0
[2022-12-15T13:25:16.891] _job_complete: JobId=53788 done
[2022-12-15T13:25:18.781] sched: Allocate JobId=53791 NodeList=gpu01 #CPUs=16 Partition=gpu-k10
[2022-12-15T13:25:23.429] _job_complete: JobId=53952 WEXITSTATUS 1
[2022-12-15T13:25:23.430] _job_complete: JobId=53952 done
[2022-12-15T13:30:37.855] _slurm_rpc_submit_batch_job: JobId=53953 InitPrio=592 usec=626
[2022-12-15T13:30:38.119] sched: Allocate JobId=53953 NodeList=gpu02 #CPUs=16 Partition=gpu-titan
[2022-12-15T13:30:41.379] _job_complete: JobId=53953 WEXITSTATUS 1
[2022-12-15T13:30:41.380] _job_complete: JobId=53953 done
[2022-12-15T13:31:52.565] _slurm_rpc_submit_batch_job: JobId=53954 InitPrio=592 usec=557
[2022-12-15T13:31:53.313] sched: Allocate JobId=53954 NodeList=gpu02 #CPUs=16 Partition=gpu-titan
[2022-12-15T13:32:47.644] _job_complete: JobId=53954 WEXITSTATUS 1
[2022-12-15T13:32:47.645] _job_complete: JobId=53954 done
[2022-12-15T13:35:08.861] _slurm_rpc_submit_batch_job: JobId=53955 InitPrio=592 usec=525
[2022-12-15T13:35:09.568] sched: Allocate JobId=53955 NodeList=gpu02 #CPUs=16 Partition=gpu-titan
[2022-12-15T13:38:43.278] _job_complete: JobId=53948 WEXITSTATUS 137
[2022-12-15T13:38:43.279] _job_complete: JobId=53948 done
[2022-12-15T13:39:12.034] _slurm_rpc_submit_batch_job: JobId=53956 InitPrio=592 usec=520
[2022-12-15T13:39:14.680] _slurm_rpc_submit_batch_job: JobId=53957 InitPrio=592 usec=653
[2022-12-15T13:43:43.471] cleanup_completing: JobId=53948 completion process took 300 seconds
[2022-12-15T13:43:43.474] sched: Allocate JobId=53956 NodeList=gpu02 #CPUs=8 Partition=gpu-titan
[2022-12-15T13:43:43.475] sched: Allocate JobId=53957 NodeList=gpu02 #CPUs=8 Partition=gpu-titan
[2022-12-15T13:43:49.112] _job_complete: JobId=53956 WEXITSTATUS 1
[2022-12-15T13:43:49.113] _job_complete: JobId=53956 done
[2022-12-15T13:43:49.209] _job_complete: JobId=53957 WEXITSTATUS 1
[2022-12-15T13:43:49.210] _job_complete: JobId=53957 done
[2022-12-15T13:44:24.121] _slurm_rpc_submit_batch_job: JobId=53958 InitPrio=592 usec=680
[2022-12-15T13:44:24.740] sched: Allocate JobId=53958 NodeList=gpu02 #CPUs=8 Partition=gpu-titan
[2022-12-15T13:44:51.269] _slurm_rpc_submit_batch_job: JobId=53959 InitPrio=592 usec=657
[2022-12-15T13:44:51.775] sched: Allocate JobId=53959 NodeList=gpu02 #CPUs=8 Partition=gpu-titan
[2022-12-15T13:45:39.626] _job_complete: JobId=53950 WEXITSTATUS 0
[2022-12-15T13:45:39.626] _job_complete: JobId=53950 done
[2022-12-15T14:05:43.846] _job_complete: JobId=53959 WEXITSTATUS 1
[2022-12-15T14:05:43.847] _job_complete: JobId=53959 done
[2022-12-15T14:13:41.089] _slurm_rpc_submit_batch_job: JobId=53960 InitPrio=592 usec=679
[2022-12-15T14:13:52.564] _slurm_rpc_kill_job: REQUEST_KILL_JOB JobId=53958 uid 548200121
[2022-12-15T14:18:54.358] cleanup_completing: JobId=53958 completion process took 302 seconds
[2022-12-15T14:18:54.361] sched: Allocate JobId=53960 NodeList=gpu02 #CPUs=16 Partition=gpu-titan
[2022-12-15T14:18:58.659] _job_complete: JobId=53960 WEXITSTATUS 1
[2022-12-15T14:18:58.660] _job_complete: JobId=53960 done
[2022-12-15T14:19:11.327] Time limit exhausted for JobId=53951
[2022-12-15T14:21:13.140] _slurm_rpc_submit_batch_job: JobId=53961 InitPrio=988 usec=1055
[2022-12-15T14:21:13.621] sched: Allocate JobId=53961 NodeList=cpu01 #CPUs=1 Partition=cpu-opteron
[2022-12-15T14:21:20.721] _job_complete: JobId=53961 WEXITSTATUS 1
[2022-12-15T14:21:20.721] _job_complete: JobId=53961 done
[2022-12-15T14:21:48.422] _slurm_rpc_submit_batch_job: JobId=53962 InitPrio=4940 usec=530
[2022-12-15T14:21:54.468] _slurm_rpc_submit_batch_job: JobId=53963 InitPrio=4940 usec=468
[2022-12-15T14:22:00.401] _slurm_rpc_submit_batch_job: JobId=53964 InitPrio=988 usec=489
[2022-12-15T14:22:00.661] sched: Allocate JobId=53964 NodeList=cpu01 #CPUs=2 Partition=cpu-opteron
[2022-12-15T14:22:18.405] _slurm_rpc_submit_batch_job: JobId=53965 InitPrio=10592 usec=362
[2022-12-15T14:22:18.686] sched: Allocate JobId=53965 NodeList=cpu01 #CPUs=2 Partition=cpu-opteron
[2022-12-15T14:23:15.968] _slurm_rpc_submit_batch_job: JobId=53966 InitPrio=988 usec=464
[2022-12-15T14:23:16.761] sched: Allocate JobId=53966 NodeList=cpu01 #CPUs=2 Partition=cpu-opteron
[2022-12-15T14:24:07.283] _slurm_rpc_kill_job: REQUEST_KILL_JOB JobId=53966 uid 548200021
[2022-12-15T14:24:19.306] _slurm_rpc_submit_batch_job: JobId=53967 InitPrio=592 usec=706
[2022-12-15T14:24:19.839] sched: Allocate JobId=53967 NodeList=gpu02 #CPUs=16 Partition=gpu-titan
[2022-12-15T14:25:37.752] _slurm_rpc_submit_batch_job: JobId=53968 InitPrio=988 usec=527
[2022-12-15T14:25:37.935] sched: Allocate JobId=53968 NodeList=cpu01 #CPUs=2 Partition=cpu-opteron
[2022-12-15T14:26:09.322] _job_complete: JobId=53967 WEXITSTATUS 1
[2022-12-15T14:26:09.323] _job_complete: JobId=53967 done
[2022-12-15T14:40:05.553] _job_complete: JobId=53931 WEXITSTATUS 0
[2022-12-15T14:40:05.558] _job_complete: JobId=53931 done
[2022-12-15T14:42:37.191] _slurm_rpc_submit_batch_job: JobId=53969 InitPrio=6719 usec=486
[2022-12-15T14:42:37.598] sched: Allocate JobId=53969 NodeList=cpu04 #CPUs=1 Partition=cpu-opteron
[2022-12-15T14:42:58.817] _job_complete: JobId=53969 WEXITSTATUS 1
[2022-12-15T14:42:58.818] _job_complete: JobId=53969 done
[2022-12-15T14:43:35.693] _job_complete: JobId=53936 WEXITSTATUS 0
[2022-12-15T14:43:35.693] _job_complete: JobId=53936 done
[2022-12-15T14:48:43.669] _slurm_rpc_submit_batch_job: JobId=53970 InitPrio=790 usec=745
[2022-12-15T14:51:27.189] _job_complete: JobId=53923 WEXITSTATUS 0
[2022-12-15T14:51:27.190] _job_complete: JobId=53923 done
[2022-12-15T15:10:52.468] sched: _slurm_rpc_allocate_resources JobId=53971 NodeList=(null) usec=945
[2022-12-15T15:10:52.618] sched: Allocate JobId=53971 NodeList=cpu01 #CPUs=1 Partition=cpu-opteron
[2022-12-15T15:12:19.206] _slurm_rpc_kill_job: REQUEST_KILL_JOB JobId=53824 uid 548200023
[2022-12-15T15:12:22.695] _slurm_rpc_kill_job: REQUEST_KILL_JOB JobId=53821 uid 548200023
[2022-12-15T15:12:27.635] _slurm_rpc_submit_batch_job: JobId=53972 InitPrio=1976 usec=480
[2022-12-15T15:12:27.844] sched: Allocate JobId=53972 NodeList=gpu02 #CPUs=5 Partition=gpu-titan
[2022-12-15T15:13:16.888] _slurm_rpc_kill_job: REQUEST_KILL_JOB JobId=53972 uid 548200023
[2022-12-15T15:13:23.396] _slurm_rpc_submit_batch_job: JobId=53973 InitPrio=1976 usec=431
[2022-12-15T15:13:23.893] sched: Allocate JobId=53973 NodeList=gpu02 #CPUs=2 Partition=gpu-titan
[2022-12-15T15:13:27.883] _slurm_rpc_submit_batch_job: JobId=53974 InitPrio=1976 usec=575
[2022-12-15T15:13:27.898] sched: Allocate JobId=53974 NodeList=gpu02 #CPUs=5 Partition=gpu-titan
[2022-12-15T15:13:50.043] _job_complete: JobId=53973 WEXITSTATUS 0
[2022-12-15T15:13:50.044] _job_complete: JobId=53973 done
[2022-12-15T15:13:57.368] _slurm_rpc_kill_job: REQUEST_KILL_JOB JobId=53823 uid 548200023
[2022-12-15T15:17:28.491] _slurm_rpc_submit_batch_job: JobId=53975 InitPrio=1976 usec=617
[2022-12-15T15:22:41.822] Time limit exhausted for JobId=53965
[2022-12-15T15:30:49.019] _slurm_rpc_submit_batch_job: JobId=53976 InitPrio=10592 usec=388
[2022-12-15T15:30:49.562] sched: Allocate JobId=53976 NodeList=cpu01 #CPUs=2 Partition=cpu-opteron
[2022-12-15T15:42:23.589] _job_complete: JobId=53971 WEXITSTATUS 0
[2022-12-15T15:42:23.589] _job_complete: JobId=53971 done
[2022-12-15T15:46:35.096] _job_complete: JobId=53909 WEXITSTATUS 0
[2022-12-15T15:46:35.096] _job_complete: JobId=53909 done
[2022-12-15T15:46:35.518] sched: Allocate JobId=53911 NodeList=cpu13 #CPUs=8 Partition=cpu-epyc
[2022-12-15T15:47:59.471] _slurm_rpc_submit_batch_job: JobId=53977 InitPrio=3557 usec=556
[2022-12-15T15:48:00.456] sched: Allocate JobId=53977 NodeList=cpu01 #CPUs=16 Partition=cpu-opteron
[2022-12-15T15:49:18.027] _slurm_rpc_kill_job: REQUEST_KILL_JOB JobId=53976 uid 548200121
[2022-12-15T15:55:42.276] _job_complete: JobId=53910 WEXITSTATUS 0
[2022-12-15T15:55:42.276] _job_complete: JobId=53910 done
[2022-12-15T15:55:42.699] sched: Allocate JobId=53912 NodeList=cpu13 #CPUs=8 Partition=cpu-epyc
[2022-12-15T15:59:58.610] _slurm_rpc_submit_batch_job: JobId=53978 InitPrio=6719 usec=439
[2022-12-15T15:59:59.561] sched: Allocate JobId=53978 NodeList=cpu01 #CPUs=1 Partition=cpu-opteron
[2022-12-15T16:01:12.743] _job_complete: JobId=53978 WEXITSTATUS 1
[2022-12-15T16:01:12.744] _job_complete: JobId=53978 done
[2022-12-15T16:13:19.535] _slurm_rpc_kill_job: REQUEST_KILL_JOB JobId=53964 uid 548200021
[2022-12-15T16:13:23.149] _slurm_rpc_kill_job: REQUEST_KILL_JOB JobId=53968 uid 548200021
[2022-12-15T16:21:56.230] _job_create: exceeded association/QOS limit for user 548200021: QOSMaxWallDurationPerJobLimit
[2022-12-15T16:21:56.230] _slurm_rpc_submit_batch_job: Job violates accounting/QOS policy (job submit limit, user's size and/or time limits)
[2022-12-15T16:23:03.097] _slurm_rpc_submit_batch_job: JobId=53979 InitPrio=988 usec=633
[2022-12-15T16:23:04.002] sched: Allocate JobId=53979 NodeList=cpu01 #CPUs=2 Partition=cpu-opteron
[2022-12-15T16:25:04.629] _slurm_rpc_submit_batch_job: JobId=53980 InitPrio=988 usec=477
[2022-12-15T16:25:05.140] sched: Allocate JobId=53980 NodeList=cpu01 #CPUs=2 Partition=cpu-opteron
[2022-12-15T16:25:06.542] _job_complete: JobId=53980 WEXITSTATUS 1
[2022-12-15T16:25:06.542] _job_complete: JobId=53980 done
[2022-12-15T16:27:20.057] _slurm_rpc_submit_batch_job: JobId=53981 InitPrio=988 usec=556
[2022-12-15T16:27:20.653] sched: Allocate JobId=53981 NodeList=cpu01 #CPUs=2 Partition=cpu-opteron
[2022-12-15T16:28:03.465] sched: _slurm_rpc_allocate_resources JobId=53982 NodeList=(null) usec=1027
[2022-12-15T16:28:03.723] sched: Allocate JobId=53982 NodeList=gpu04 #CPUs=8 Partition=gpu-k40c
[2022-12-15T16:32:39.275] _job_complete: JobId=53981 WEXITSTATUS 0
[2022-12-15T16:32:39.275] _job_complete: JobId=53981 done
[2022-12-15T16:41:59.621] _slurm_rpc_submit_batch_job: JobId=53983 InitPrio=988 usec=515
[2022-12-15T16:42:00.504] sched: Allocate JobId=53983 NodeList=cpu01 #CPUs=2 Partition=cpu-opteron
[2022-12-15T16:43:28.207] _slurm_rpc_submit_batch_job: JobId=53984 InitPrio=988 usec=473
[2022-12-15T16:43:28.614] sched: Allocate JobId=53984 NodeList=cpu01 #CPUs=2 Partition=cpu-opteron
[2022-12-15T16:43:33.024] _slurm_rpc_submit_batch_job: JobId=53985 InitPrio=988 usec=463
[2022-12-15T16:43:33.620] sched: Allocate JobId=53985 NodeList=cpu01 #CPUs=2 Partition=cpu-opteron
[2022-12-15T16:43:34.956] _job_complete: JobId=53985 WEXITSTATUS 1
[2022-12-15T16:43:34.956] _job_complete: JobId=53985 done
[2022-12-15T16:45:31.617] _slurm_rpc_submit_batch_job: JobId=53986 InitPrio=988 usec=568
[2022-12-15T16:45:31.774] sched: Allocate JobId=53986 NodeList=cpu01 #CPUs=2 Partition=cpu-opteron
[2022-12-15T17:11:29.452] _job_complete: JobId=53982 WEXITSTATUS 130
[2022-12-15T17:11:29.453] _job_complete: JobId=53982 done
[2022-12-15T17:12:17.197] _slurm_rpc_submit_batch_job: JobId=53987 InitPrio=4347 usec=608
[2022-12-15T17:12:17.795] sched: Allocate JobId=53987 NodeList=gpu04 #CPUs=8 Partition=gpu-k40c
[2022-12-15T17:25:42.039] _job_complete: JobId=53894 WEXITSTATUS 0
[2022-12-15T17:25:42.046] _job_complete: JobId=53894 done
[2022-12-15T18:27:01.643] _slurm_rpc_submit_batch_job: JobId=53988 InitPrio=988 usec=592
[2022-12-15T18:27:02.030] sched: Allocate JobId=53988 NodeList=cpu01 #CPUs=16 Partition=cpu-opteron
[2022-12-15T18:44:56.672] _slurm_rpc_submit_batch_job: JobId=53989 InitPrio=988 usec=516
[2022-12-15T18:44:57.082] sched: Allocate JobId=53989 NodeList=cpu01 #CPUs=16 Partition=cpu-opteron
[2022-12-15T19:18:08.899] _job_complete: JobId=53988 WEXITSTATUS 0
[2022-12-15T19:18:08.899] _job_complete: JobId=53988 done
[2022-12-15T19:18:13.132] _slurm_rpc_kill_job: REQUEST_KILL_JOB JobId=53977 uid 548300635
[2022-12-15T19:31:51.167] _slurm_rpc_submit_batch_job: JobId=53990 InitPrio=3557 usec=548
[2022-12-15T19:31:51.443] sched: Allocate JobId=53990 NodeList=cpu01 #CPUs=16 Partition=cpu-opteron
[2022-12-15T19:34:25.306] _slurm_rpc_submit_batch_job: JobId=53991 InitPrio=395 usec=470
[2022-12-15T19:34:25.340] sched/backfill: _start_job: Started JobId=53991 in cpu-opteron on cpu04
[2022-12-15T19:37:09.445] _slurm_rpc_submit_batch_job: JobId=53992 InitPrio=395 usec=484
[2022-12-15T19:38:19.973] _slurm_rpc_submit_batch_job: JobId=53993 InitPrio=395 usec=780
[2022-12-15T19:50:30.404] _job_complete: JobId=53989 WEXITSTATUS 0
[2022-12-15T19:50:30.404] _job_complete: JobId=53989 done
[2022-12-15T19:50:31.172] sched: Allocate JobId=53992 NodeList=cpu01 #CPUs=32 Partition=cpu-opteron
[2022-12-15T20:11:22.949] _slurm_rpc_submit_batch_job: JobId=53994 InitPrio=592 usec=479
[2022-12-15T20:12:23.731] _slurm_rpc_submit_batch_job: JobId=53995 InitPrio=10592 usec=347
[2022-12-15T20:16:07.153] _slurm_rpc_kill_job: REQUEST_KILL_JOB JobId=53995 uid 548200121
[2022-12-15T20:16:15.516] _slurm_rpc_submit_batch_job: JobId=53996 InitPrio=10592 usec=378
[2022-12-15T20:16:16.138] sched: Allocate JobId=53996 NodeList=cpu13 #CPUs=2 Partition=cpu-epyc
[2022-12-15T20:28:29.183] _job_complete: JobId=53992 WEXITSTATUS 0
[2022-12-15T20:28:29.184] _job_complete: JobId=53992 done
[2022-12-15T20:28:30.583] sched: Allocate JobId=53993 NodeList=cpu01 #CPUs=32 Partition=cpu-opteron
[2022-12-15T20:32:58.846] _job_complete: JobId=53987 WEXITSTATUS 0
[2022-12-15T20:32:58.846] _job_complete: JobId=53987 done
[2022-12-15T20:33:17.487] _slurm_rpc_kill_job: REQUEST_KILL_JOB JobId=53996 uid 548200121
[2022-12-15T20:33:41.162] _slurm_rpc_submit_batch_job: JobId=53997 InitPrio=10592 usec=421
[2022-12-15T20:33:41.386] sched: Allocate JobId=53997 NodeList=cpu13 #CPUs=4 Partition=cpu-epyc
[2022-12-15T20:36:04.144] _job_complete: JobId=53955 WEXITSTATUS 0
[2022-12-15T20:36:04.144] _job_complete: JobId=53955 done
[2022-12-15T20:36:06.407] sched: Allocate JobId=53975 NodeList=gpu02 #CPUs=6 Partition=gpu-titan
[2022-12-15T21:31:23.961] _slurm_rpc_submit_batch_job: JobId=53998 InitPrio=988 usec=520
[2022-12-15T21:31:34.770] _slurm_rpc_submit_batch_job: JobId=53999 InitPrio=988 usec=531
[2022-12-15T21:32:27.321] _slurm_rpc_kill_job: REQUEST_KILL_JOB JobId=53999 uid 548200021
[2022-12-15T21:32:30.207] _slurm_rpc_kill_job: REQUEST_KILL_JOB JobId=53998 uid 548200021
[2022-12-15T21:33:30.838] _slurm_rpc_submit_batch_job: JobId=54000 InitPrio=988 usec=574
[2022-12-15T21:33:42.314] Time limit exhausted for JobId=53997
[2022-12-15T21:34:17.846] _slurm_rpc_submit_batch_job: JobId=54001 InitPrio=988 usec=824
[2022-12-15T21:34:48.141] _slurm_rpc_kill_job: REQUEST_KILL_JOB JobId=54000 uid 548200021
[2022-12-15T21:34:50.998] _slurm_rpc_kill_job: REQUEST_KILL_JOB JobId=54001 uid 548200021
[2022-12-15T21:35:07.298] _slurm_rpc_submit_batch_job: JobId=54002 InitPrio=988 usec=424
[2022-12-15T21:35:25.416] sched: _slurm_rpc_allocate_resources JobId=54003 NodeList=(null) usec=824
[2022-12-15T21:35:25.575] sched/backfill: _start_job: Started JobId=54002 in cpu-epyc on cpu13
[2022-12-15T21:35:27.517] _job_complete: JobId=54002 WEXITSTATUS 0
[2022-12-15T21:35:27.517] _job_complete: JobId=54002 done
[2022-12-15T21:35:48.677] _job_complete: JobId=54003 WTERMSIG 126
[2022-12-15T21:35:48.678] _job_complete: JobId=54003 cancelled by interactive user
[2022-12-15T21:35:48.678] _job_complete: JobId=54003 done
[2022-12-15T21:35:48.680] _slurm_rpc_complete_job_allocation: JobId=54003 error Job/step already completing or completed
[2022-12-15T21:49:14.904] _slurm_rpc_submit_batch_job: JobId=54004 InitPrio=988 usec=726
[2022-12-15T21:49:18.060] _slurm_rpc_submit_batch_job: JobId=54005 InitPrio=988 usec=428
[2022-12-15T21:49:37.963] _job_complete: JobId=53993 WEXITSTATUS 0
[2022-12-15T21:49:37.964] _job_complete: JobId=53993 done
[2022-12-15T21:49:39.299] sched: Allocate JobId=54004 NodeList=cpu01 #CPUs=16 Partition=cpu-opteron
[2022-12-15T21:49:39.300] sched: Allocate JobId=54005 NodeList=cpu01 #CPUs=16 Partition=cpu-opteron
[2022-12-15T22:03:55.405] _slurm_rpc_submit_batch_job: JobId=54006 InitPrio=10592 usec=363
[2022-12-15T22:03:55.557] sched: Allocate JobId=54006 NodeList=cpu13 #CPUs=2 Partition=cpu-epyc
[2022-12-15T22:11:07.183] _job_complete: JobId=53911 WEXITSTATUS 0
[2022-12-15T22:11:07.183] _job_complete: JobId=53911 done
[2022-12-15T22:11:07.563] sched: Allocate JobId=53913 NodeList=cpu13 #CPUs=8 Partition=cpu-epyc
[2022-12-15T22:19:19.230] _slurm_rpc_kill_job: REQUEST_KILL_JOB JobId=54006 uid 548200121
[2022-12-15T22:19:29.739] _slurm_rpc_submit_batch_job: JobId=54007 InitPrio=10592 usec=384
[2022-12-15T22:19:30.730] sched: Allocate JobId=54007 NodeList=cpu13 #CPUs=4 Partition=cpu-epyc
[2022-12-15T22:19:58.104] _job_complete: JobId=54004 WEXITSTATUS 0
[2022-12-15T22:19:58.104] _job_complete: JobId=54004 done
[2022-12-15T22:26:58.281] _job_complete: JobId=53991 WEXITSTATUS 0
[2022-12-15T22:26:58.282] _job_complete: JobId=53991 done
[2022-12-15T22:27:32.663] _slurm_rpc_kill_job: REQUEST_KILL_JOB JobId=54007 uid 548200121
[2022-12-15T22:28:47.523] _job_complete: JobId=53912 WEXITSTATUS 0
[2022-12-15T22:28:47.523] _job_complete: JobId=53912 done
[2022-12-15T22:28:47.857] sched: Allocate JobId=53914 NodeList=cpu13 #CPUs=8 Partition=cpu-epyc
[2022-12-15T22:29:07.285] _slurm_rpc_submit_batch_job: JobId=54008 InitPrio=10592 usec=334
[2022-12-15T22:29:07.824] sched: Allocate JobId=54008 NodeList=cpu13 #CPUs=4 Partition=cpu-epyc
[2022-12-15T22:32:38.617] _slurm_rpc_submit_batch_job: JobId=54009 InitPrio=6719 usec=509
[2022-12-15T22:32:39.279] sched: Allocate JobId=54009 NodeList=cpu01 #CPUs=1 Partition=cpu-opteron
[2022-12-15T22:33:18.814] _slurm_rpc_kill_job: REQUEST_KILL_JOB JobId=54009 uid 548200009
[2022-12-15T22:33:21.551] _slurm_rpc_submit_batch_job: JobId=54010 InitPrio=6719 usec=551
[2022-12-15T22:33:23.310] sched: Allocate JobId=54010 NodeList=cpu01 #CPUs=1 Partition=cpu-opteron
[2022-12-15T22:33:43.580] _job_complete: JobId=54010 WEXITSTATUS 1
[2022-12-15T22:33:43.581] _job_complete: JobId=54010 done
[2022-12-15T22:44:23.163] _slurm_rpc_submit_batch_job: JobId=54011 InitPrio=395 usec=432
[2022-12-15T22:44:25.708] sched/backfill: _start_job: Started JobId=54011 in cpu-epyc on cpu13
[2022-12-15T22:44:31.253] _slurm_rpc_submit_batch_job: JobId=54012 InitPrio=395 usec=488
[2022-12-15T22:44:38.774] _slurm_rpc_submit_batch_job: JobId=54013 InitPrio=395 usec=513
[2022-12-15T22:44:39.416] sched: Allocate JobId=54013 NodeList=cpu04 #CPUs=64 Partition=cpu-opteron
[2022-12-15T22:44:51.156] _slurm_rpc_submit_batch_job: JobId=54014 InitPrio=395 usec=483
[2022-12-15T23:18:22.097] _slurm_rpc_kill_job: REQUEST_KILL_JOB JobId=54008 uid 548200121
[2022-12-15T23:23:25.687] _slurm_rpc_submit_batch_job: JobId=54015 InitPrio=10592 usec=399
[2022-12-15T23:23:25.720] sched: Allocate JobId=54015 NodeList=cpu13 #CPUs=2 Partition=cpu-epyc
[2022-12-15T23:32:08.255] _slurm_rpc_kill_job: REQUEST_KILL_JOB JobId=54015 uid 548200121
[2022-12-15T23:32:16.369] _slurm_rpc_submit_batch_job: JobId=54016 InitPrio=10592 usec=333
[2022-12-15T23:32:16.805] sched: Allocate JobId=54016 NodeList=cpu13 #CPUs=4 Partition=cpu-epyc
[2022-12-15T23:39:19.912] _slurm_rpc_kill_job: REQUEST_KILL_JOB JobId=54016 uid 548200121
[2022-12-16T00:03:52.000] _job_complete: JobId=54005 WEXITSTATUS 0
[2022-12-16T00:03:52.000] _job_complete: JobId=54005 done
[2022-12-16T00:13:35.495] _slurm_rpc_submit_batch_job: JobId=54017 InitPrio=988 usec=663
[2022-12-16T00:14:25.929] sched/backfill: _start_job: Started JobId=54017 in cpu-epyc on cpu13
[2022-12-16T00:14:27.820] _job_complete: JobId=54017 WEXITSTATUS 0
[2022-12-16T00:14:27.820] _job_complete: JobId=54017 done
[2022-12-16T01:19:15.474] _job_complete: JobId=53665 WEXITSTATUS 0
[2022-12-16T01:19:15.479] _job_complete: JobId=53665 done
[2022-12-16T01:19:16.507] sched: Allocate JobId=53877 NodeList=gpu05 #CPUs=1 Partition=gpu-v100s
[2022-12-16T01:57:00.070] _slurm_rpc_submit_batch_job: JobId=54018 InitPrio=17707 usec=452
[2022-12-16T01:57:00.599] sched: Allocate JobId=54018 NodeList=cpu01 #CPUs=1 Partition=cpu-opteron
[2022-12-16T02:02:04.144] _slurm_rpc_submit_batch_job: JobId=54019 InitPrio=988 usec=465
[2022-12-16T02:02:05.073] sched: Allocate JobId=54019 NodeList=cpu01 #CPUs=16 Partition=cpu-opteron
[2022-12-16T02:02:08.118] _slurm_rpc_submit_batch_job: JobId=54020 InitPrio=988 usec=520
[2022-12-16T02:18:00.228] _slurm_rpc_submit_batch_job: JobId=54021 InitPrio=988 usec=566
[2022-12-16T02:19:43.313] Time limit exhausted for JobId=53877
[2022-12-16T02:19:43.861] sched: Allocate JobId=53962 NodeList=gpu05 #CPUs=32 Partition=gpu-v100s
[2022-12-16T02:20:46.966] _slurm_rpc_submit_batch_job: JobId=54022 InitPrio=988 usec=523
[2022-12-16T02:23:04.896] _slurm_rpc_submit_batch_job: JobId=54023 InitPrio=17707 usec=539
[2022-12-16T02:23:05.812] sched: Allocate JobId=54023 NodeList=cpu01 #CPUs=1 Partition=cpu-opteron
[2022-12-16T02:23:11.814] error: slurm_receive_msgs: [[gpu05.dicc.um.edu.my]:6818] failed: Socket timed out on send/recv operation
[2022-12-16T02:23:18.903] _slurm_rpc_kill_job: REQUEST_KILL_JOB JobId=54018 uid 548300565
[2022-12-16T02:23:31.832] error: slurm_receive_msgs: [[gpu05.dicc.um.edu.my]:6818] failed: Socket timed out on send/recv operation
[2022-12-16T02:23:41.854] requeue job JobId=53962 due to failure of node gpu05
[2022-12-16T02:23:41.855] Requeuing JobId=53962
[2022-12-16T02:23:41.855] error: Nodes gpu05 not responding, setting DOWN
[2022-12-16T02:23:51.858] error: slurm_receive_msgs: [[gpu05.dicc.um.edu.my]:6818] failed: Socket timed out on send/recv operation
[2022-12-16T02:25:54.411] _job_complete: JobId=54023 WEXITSTATUS 0
[2022-12-16T02:25:54.411] _job_complete: JobId=54023 done
[2022-12-16T02:25:55.183] _slurm_rpc_kill_job: REQUEST_KILL_JOB JobId=54023 uid 548300565
[2022-12-16T02:25:55.802] sched: Allocate JobId=54020 NodeList=cpu01 #CPUs=16 Partition=cpu-opteron
[2022-12-16T02:26:09.250] error: Registered PENDING JobId=53962 StepId=53962.extern on node gpu05
[2022-12-16T02:26:09.250] error: Registered PENDING JobId=53962 StepId=53962.batch on node gpu05
[2022-12-16T02:26:09.250] Node gpu05 now responding
[2022-12-16T02:26:09.250] node gpu05 returned to service
[2022-12-16T02:26:09.332] sched: Allocate JobId=53963 NodeList=gpu05 #CPUs=32 Partition=gpu-v100s
[2022-12-16T02:26:09.728] step_partial_comp: JobId=53962 pending
[2022-12-16T02:28:33.587] _slurm_rpc_submit_batch_job: JobId=54024 InitPrio=17707 usec=501
[2022-12-16T02:32:47.579] _slurm_rpc_submit_batch_job: JobId=54025 InitPrio=17707 usec=538
[2022-12-16T02:33:00.265] _slurm_rpc_kill_job: REQUEST_KILL_JOB JobId=54025 uid 548300565
[2022-12-16T03:03:11.960] _job_complete: JobId=54011 WEXITSTATUS 0
[2022-12-16T03:03:11.966] _job_complete: JobId=54011 done
[2022-12-16T04:21:52.120] _job_complete: JobId=53913 WEXITSTATUS 0
[2022-12-16T04:21:52.120] _job_complete: JobId=53913 done
[2022-12-16T04:21:52.482] sched: Allocate JobId=53915 NodeList=cpu13 #CPUs=8 Partition=cpu-epyc
[2022-12-16T04:33:09.910] _job_complete: JobId=53914 WEXITSTATUS 0
[2022-12-16T04:33:09.911] _job_complete: JobId=53914 done
[2022-12-16T04:33:10.263] sched: Allocate JobId=53916 NodeList=cpu13 #CPUs=8 Partition=cpu-epyc
[2022-12-16T04:33:26.559] sched/backfill: _start_job: Started JobId=54012 in cpu-epyc on cpu13
[2022-12-16T04:51:51.205] _slurm_rpc_kill_job: REQUEST_KILL_JOB JobId=54024 uid 548300565
[2022-12-16T05:54:49.029] _job_complete: JobId=53963 WEXITSTATUS 1
[2022-12-16T05:54:49.035] _job_complete: JobId=53963 done
[2022-12-16T05:54:54.115] sched: Allocate JobId=53818 NodeList=gpu05 #CPUs=16 Partition=gpu-v100s
[2022-12-16T05:54:54.116] sched: Allocate JobId=53820 NodeList=gpu05 #CPUs=16 Partition=gpu-v100s
[2022-12-16T08:29:52.416] _slurm_rpc_submit_batch_job: JobId=54026 InitPrio=12173 usec=574
[2022-12-16T08:30:17.905] _slurm_rpc_kill_job: REQUEST_KILL_JOB JobId=54026 uid 548200003
[2022-12-16T08:30:49.751] _slurm_rpc_submit_batch_job: JobId=54027 InitPrio=12173 usec=440
[2022-12-16T08:30:50.066] sched: Allocate JobId=54027 NodeList=cpu13 #CPUs=1 Partition=cpu-epyc
[2022-12-16T08:37:16.219] _slurm_rpc_kill_job: REQUEST_KILL_JOB JobId=54027 uid 548200003
[2022-12-16T08:37:20.152] _slurm_rpc_submit_batch_job: JobId=54028 InitPrio=12173 usec=414
[2022-12-16T08:37:20.816] sched: Allocate JobId=54028 NodeList=cpu13 #CPUs=1 Partition=cpu-epyc
[2022-12-16T08:40:45.061] _slurm_rpc_submit_batch_job: JobId=54029 InitPrio=790 usec=1152
[2022-12-16T08:44:11.936] _slurm_rpc_kill_job: REQUEST_KILL_JOB JobId=54028 uid 548200003
[2022-12-16T08:45:20.858] _slurm_rpc_submit_batch_job: JobId=54030 InitPrio=790 usec=562
[2022-12-16T08:48:20.655] _slurm_rpc_submit_batch_job: JobId=54031 InitPrio=790 usec=491
[2022-12-16T09:00:38.331] Requeuing JobId=53818
[2022-12-16T09:00:38.355] sched: Allocate JobId=53864 NodeList=gpu05 #CPUs=16 Partition=gpu-v100s
[2022-12-16T09:00:52.146] Requeuing JobId=53820
[2022-12-16T09:01:28.828] Requeuing JobId=53974
[2022-12-16T09:01:28.850] sched: Allocate JobId=53994 NodeList=gpu02 #CPUs=8 Partition=gpu-titan
[2022-12-16T09:01:33.049] Requeuing JobId=53975
[2022-12-16T09:01:33.069] sched: Allocate JobId=54029 NodeList=gpu02 #CPUs=8 Partition=gpu-titan
[2022-12-16T09:03:40.952] _slurm_rpc_submit_batch_job: JobId=54032 InitPrio=395 usec=500
[2022-12-16T09:03:49.362] _slurm_rpc_submit_batch_job: JobId=54033 InitPrio=395 usec=471
[2022-12-16T09:03:56.650] _slurm_rpc_submit_batch_job: JobId=54034 InitPrio=395 usec=469
[2022-12-16T09:04:07.091] _slurm_rpc_submit_batch_job: JobId=54035 InitPrio=395 usec=437
[2022-12-16T09:18:03.740] _slurm_rpc_kill_job: REQUEST_KILL_JOB JobId=54034 uid 548200017
[2022-12-16T09:18:41.719] _slurm_rpc_submit_batch_job: JobId=54036 InitPrio=393 usec=509
[2022-12-16T09:45:36.307] _slurm_rpc_submit_batch_job: JobId=54037 InitPrio=590 usec=590
[2022-12-16T09:45:43.768] _slurm_rpc_kill_job: REQUEST_KILL_JOB JobId=53994 uid 548200121
[2022-12-16T09:48:16.565] _slurm_rpc_submit_batch_job: JobId=54038 InitPrio=10590 usec=377
[2022-12-16T09:48:17.257] sched: Allocate JobId=54038 NodeList=cpu13 #CPUs=4 Partition=cpu-epyc
[2022-12-16T09:50:45.636] cleanup_completing: JobId=53994 completion process took 302 seconds
[2022-12-16T09:50:45.639] sched: Allocate JobId=54037 NodeList=gpu02 #CPUs=8 Partition=gpu-titan
[2022-12-16T09:55:23.095] _slurm_rpc_submit_batch_job: JobId=54039 InitPrio=590 usec=536
[2022-12-16T09:57:43.262] _slurm_rpc_kill_job: REQUEST_KILL_JOB JobId=54038 uid 548200121
[2022-12-16T09:59:42.051] _slurm_rpc_submit_batch_job: JobId=54040 InitPrio=4330 usec=613
[2022-12-16T09:59:42.638] sched: Allocate JobId=54040 NodeList=gpu04 #CPUs=8 Partition=gpu-k40c
[2022-12-16T10:08:27.274] _job_complete: JobId=54040 WEXITSTATUS 0
[2022-12-16T10:08:27.275] _job_complete: JobId=54040 done
[2022-12-16T10:30:24.289] _slurm_rpc_submit_batch_job: JobId=54041 InitPrio=6692 usec=876
[2022-12-16T10:32:55.773] _slurm_rpc_kill_job: REQUEST_KILL_JOB JobId=54041 uid 548200009
[2022-12-16T10:37:21.875] _slurm_rpc_submit_batch_job: JobId=54042 InitPrio=16692 usec=495
[2022-12-16T10:44:55.515] _job_complete: JobId=54012 WEXITSTATUS 0
[2022-12-16T10:44:55.516] _job_complete: JobId=54012 done
[2022-12-16T10:45:27.439] sched/backfill: _start_job: Started JobId=54032 in cpu-epyc on cpu13
[2022-12-16T10:45:32.364] _job_complete: JobId=54032 WEXITSTATUS 1
[2022-12-16T10:45:32.365] _job_complete: JobId=54032 done
[2022-12-16T10:46:27.444] sched/backfill: _start_job: Started JobId=54033 in cpu-epyc on cpu13
[2022-12-16T10:57:52.815] _job_complete: JobId=53915 WEXITSTATUS 0
[2022-12-16T10:57:52.815] _job_complete: JobId=53915 done
[2022-12-16T10:57:53.163] sched: Allocate JobId=53917 NodeList=cpu13 #CPUs=8 Partition=cpu-epyc
[2022-12-16T11:01:29.850] _job_complete: JobId=53916 WEXITSTATUS 0
[2022-12-16T11:01:29.850] _job_complete: JobId=53916 done
[2022-12-16T11:04:11.235] _slurm_rpc_submit_batch_job: JobId=54043 InitPrio=4330 usec=642
[2022-12-16T11:04:11.346] sched: Allocate JobId=54043 NodeList=gpu04 #CPUs=8 Partition=gpu-k40c
[2022-12-16T11:10:06.110] _job_complete: JobId=54043 WEXITSTATUS 0
[2022-12-16T11:10:06.110] _job_complete: JobId=54043 done
[2022-12-16T11:17:21.113] _job_complete: JobId=53846 WEXITSTATUS 0
[2022-12-16T11:17:21.113] _job_complete: JobId=53846 done
[2022-12-16T11:17:21.871] sched: Allocate JobId=54042 NodeList=cpu11 #CPUs=1 Partition=cpu-opteron
[2022-12-16T11:17:38.277] _slurm_rpc_submit_batch_job: JobId=54044 InitPrio=17677 usec=464
[2022-12-16T11:17:38.864] sched: Allocate JobId=54044 NodeList=cpu11 #CPUs=1 Partition=cpu-opteron
[2022-12-16T11:17:45.782] _job_complete: JobId=54042 WEXITSTATUS 1
[2022-12-16T11:17:45.783] _job_complete: JobId=54042 done
[2022-12-16T11:28:39.605] _slurm_rpc_kill_job: REQUEST_KILL_JOB JobId=54044 uid 548300565
[2022-12-16T11:28:40.316] sched: Allocate JobId=53849 NodeList=cpu11 #CPUs=64 Partition=cpu-opteron
[2022-12-16T11:31:43.919] _slurm_rpc_submit_batch_job: JobId=54045 InitPrio=17677 usec=488
[2022-12-16T11:45:00.956] _slurm_rpc_kill_job: REQUEST_KILL_JOB JobId=54045 uid 548300565
[2022-12-16T11:45:28.768] _slurm_rpc_kill_job: REQUEST_KILL_JOB JobId=53974 uid 548200023
[2022-12-16T11:45:33.076] _slurm_rpc_submit_batch_job: JobId=54046 InitPrio=1771 usec=529
[2022-12-16T11:47:00.570] _slurm_rpc_submit_batch_job: JobId=54047 InitPrio=1771 usec=584
[2022-12-16T11:47:13.417] _slurm_rpc_kill_job: REQUEST_KILL_JOB JobId=53975 uid 548200023
[2022-12-16T11:48:59.584] _slurm_rpc_kill_job: REQUEST_KILL_JOB JobId=53820 uid 548200023
[2022-12-16T11:49:02.927] _slurm_rpc_kill_job: REQUEST_KILL_JOB JobId=53818 uid 548200023
[2022-12-16T11:49:04.969] _slurm_rpc_submit_batch_job: JobId=54048 InitPrio=1771 usec=565
[2022-12-16T11:50:14.286] _slurm_rpc_submit_batch_job: JobId=54049 InitPrio=1771 usec=866
[2022-12-16T11:53:13.296] _slurm_rpc_submit_batch_job: JobId=54050 InitPrio=16692 usec=482
[2022-12-16T12:28:27.846] _slurm_rpc_submit_batch_job: JobId=54051 InitPrio=3149 usec=615
[2022-12-16T12:28:28.159] sched: Allocate JobId=54051 NodeList=cpu13 #CPUs=8 Partition=cpu-epyc
[2022-12-16T12:28:30.430] _slurm_rpc_submit_batch_job: JobId=54052 InitPrio=3149 usec=574
[2022-12-16T12:28:31.148] sched: Allocate JobId=54052 NodeList=cpu13 #CPUs=8 Partition=cpu-epyc
[2022-12-16T12:28:32.741] _slurm_rpc_submit_batch_job: JobId=54053 InitPrio=3149 usec=485
[2022-12-16T12:28:34.733] _slurm_rpc_submit_batch_job: JobId=54054 InitPrio=3149 usec=519
[2022-12-16T12:28:36.669] _slurm_rpc_submit_batch_job: JobId=54055 InitPrio=3149 usec=483
[2022-12-16T12:28:38.629] _slurm_rpc_submit_batch_job: JobId=54056 InitPrio=3149 usec=455
[2022-12-16T12:28:40.581] _slurm_rpc_submit_batch_job: JobId=54057 InitPrio=3149 usec=628
[2022-12-16T12:28:42.543] _slurm_rpc_submit_batch_job: JobId=54058 InitPrio=3149 usec=527
[2022-12-16T12:28:44.878] _slurm_rpc_submit_batch_job: JobId=54059 InitPrio=3149 usec=544
[2022-12-16T12:28:47.799] _slurm_rpc_submit_batch_job: JobId=54060 InitPrio=3149 usec=508
[2022-12-16T12:28:49.607] _slurm_rpc_submit_batch_job: JobId=54061 InitPrio=3149 usec=546
[2022-12-16T12:28:51.527] _slurm_rpc_submit_batch_job: JobId=54062 InitPrio=3149 usec=505
[2022-12-16T12:28:53.901] _slurm_rpc_submit_batch_job: JobId=54063 InitPrio=3149 usec=431
[2022-12-16T12:28:55.727] _slurm_rpc_submit_batch_job: JobId=54064 InitPrio=3149 usec=597
[2022-12-16T12:28:57.670] _slurm_rpc_submit_batch_job: JobId=54065 InitPrio=3149 usec=494
[2022-12-16T12:28:59.646] _slurm_rpc_submit_batch_job: JobId=54066 InitPrio=3149 usec=452
[2022-12-16T12:29:01.975] _slurm_rpc_submit_batch_job: JobId=54067 InitPrio=3149 usec=567
[2022-12-16T12:29:04.654] _slurm_rpc_submit_batch_job: JobId=54068 InitPrio=3149 usec=473
[2022-12-16T12:29:06.789] _slurm_rpc_submit_batch_job: JobId=54069 InitPrio=3149 usec=506
[2022-12-16T12:29:10.006] _slurm_rpc_submit_batch_job: JobId=54070 InitPrio=3149 usec=487
[2022-12-16T12:29:11.822] _slurm_rpc_submit_batch_job: JobId=54071 InitPrio=3149 usec=535
[2022-12-16T12:29:13.629] _slurm_rpc_submit_batch_job: JobId=54072 InitPrio=3149 usec=535
[2022-12-16T12:29:15.341] _slurm_rpc_submit_batch_job: JobId=54073 InitPrio=3149 usec=500
[2022-12-16T12:29:17.424] _slurm_rpc_submit_batch_job: JobId=54074 InitPrio=3149 usec=550
[2022-12-16T12:29:19.855] _slurm_rpc_submit_batch_job: JobId=54075 InitPrio=3149 usec=550
[2022-12-16T12:29:21.754] _slurm_rpc_submit_batch_job: JobId=54076 InitPrio=3149 usec=500
[2022-12-16T12:29:23.537] _job_complete: JobId=53864 WEXITSTATUS 0
[2022-12-16T12:29:23.542] _job_complete: JobId=53864 done
[2022-12-16T12:29:23.583] _slurm_rpc_submit_batch_job: JobId=54077 InitPrio=3149 usec=613
[2022-12-16T12:29:24.476] sched: Allocate JobId=53962 NodeList=gpu05 #CPUs=32 Partition=gpu-v100s
[2022-12-16T13:22:19.042] _job_complete: JobId=54013 WEXITSTATUS 0
[2022-12-16T13:22:19.048] _job_complete: JobId=54013 done
[2022-12-16T13:22:21.300] sched: Allocate JobId=54050 NodeList=cpu04 #CPUs=1 Partition=cpu-opteron
[2022-12-16T13:22:21.317] sched: Allocate JobId=54021 NodeList=cpu04 #CPUs=16 Partition=cpu-opteron
[2022-12-16T13:22:21.318] sched: Allocate JobId=54022 NodeList=cpu04 #CPUs=16 Partition=cpu-opteron
[2022-12-16T13:49:14.050] _job_complete: JobId=53984 WEXITSTATUS 0
[2022-12-16T13:49:14.050] _job_complete: JobId=53984 done
[2022-12-16T14:09:27.555] _slurm_rpc_submit_batch_job: JobId=54078 InitPrio=14133 usec=506
[2022-12-16T14:09:27.971] sched: Allocate JobId=54078 NodeList=cpu01 #CPUs=1 Partition=cpu-opteron
[2022-12-16T14:17:44.815] Time limit exhausted for JobId=54050
[2022-12-16T14:19:10.435] _job_complete: JobId=54051 WEXITSTATUS 0
[2022-12-16T14:19:10.435] _job_complete: JobId=54051 done
[2022-12-16T14:19:10.818] sched: Allocate JobId=54053 NodeList=cpu13 #CPUs=8 Partition=cpu-epyc
[2022-12-16T14:25:07.471] _job_complete: JobId=53986 WEXITSTATUS 0
[2022-12-16T14:25:07.471] _job_complete: JobId=53986 done
[2022-12-16T14:27:39.429] _job_complete: JobId=54052 WEXITSTATUS 0
[2022-12-16T14:27:39.429] _job_complete: JobId=54052 done
[2022-12-16T14:27:39.803] sched: Allocate JobId=54054 NodeList=cpu13 #CPUs=8 Partition=cpu-epyc
[2022-12-16T14:28:16.926] _slurm_rpc_submit_batch_job: JobId=54079 InitPrio=984 usec=556
[2022-12-16T14:29:00.681] _slurm_rpc_kill_job: REQUEST_KILL_JOB JobId=54079 uid 548200021
[2022-12-16T14:29:20.653] _slurm_rpc_submit_batch_job: JobId=54080 InitPrio=984 usec=502
[2022-12-16T14:32:37.303] _slurm_rpc_submit_batch_job: JobId=54081 InitPrio=6692 usec=579
[2022-12-16T14:32:37.765] sched: Allocate JobId=54081 NodeList=cpu01 #CPUs=1 Partition=cpu-opteron
[2022-12-16T14:34:38.985] _slurm_rpc_submit_batch_job: JobId=54082 InitPrio=984 usec=516
[2022-12-16T14:34:39.917] sched: Allocate JobId=54082 NodeList=gpu04 #CPUs=1 Partition=gpu-k40c
[2022-12-16T14:34:55.034] _job_complete: JobId=54082 WEXITSTATUS 1
[2022-12-16T14:34:55.034] _job_complete: JobId=54082 done
[2022-12-16T14:35:47.755] _slurm_rpc_submit_batch_job: JobId=54083 InitPrio=984 usec=468
[2022-12-16T14:35:48.001] sched: Allocate JobId=54083 NodeList=gpu04 #CPUs=1 Partition=gpu-k40c
[2022-12-16T14:35:50.381] _job_complete: JobId=54083 WEXITSTATUS 1
[2022-12-16T14:35:50.382] _job_complete: JobId=54083 done
[2022-12-16T14:37:36.646] _slurm_rpc_submit_batch_job: JobId=54084 InitPrio=984 usec=476
[2022-12-16T14:37:36.686] sched: Allocate JobId=54084 NodeList=gpu04 #CPUs=1 Partition=gpu-k40c
[2022-12-16T14:37:38.436] _job_complete: JobId=54084 WEXITSTATUS 1
[2022-12-16T14:37:38.436] _job_complete: JobId=54084 done
[2022-12-16T14:39:33.838] _slurm_rpc_submit_batch_job: JobId=54085 InitPrio=984 usec=507
[2022-12-16T14:39:33.840] sched: Allocate JobId=54085 NodeList=gpu04 #CPUs=1 Partition=gpu-k40c
[2022-12-16T14:39:44.721] _job_complete: JobId=54085 WEXITSTATUS 1
[2022-12-16T14:39:44.722] _job_complete: JobId=54085 done
[2022-12-16T14:41:34.554] _slurm_rpc_submit_batch_job: JobId=54086 InitPrio=984 usec=488
[2022-12-16T14:41:35.135] sched: Allocate JobId=54086 NodeList=gpu04 #CPUs=1 Partition=gpu-k40c
[2022-12-16T14:41:36.855] _job_complete: JobId=54086 WEXITSTATUS 1
[2022-12-16T14:41:36.855] _job_complete: JobId=54086 done
[2022-12-16T14:45:36.605] _slurm_rpc_submit_batch_job: JobId=54087 InitPrio=984 usec=425
[2022-12-16T14:45:37.444] sched: Allocate JobId=54087 NodeList=gpu04 #CPUs=1 Partition=gpu-k40c
[2022-12-16T14:45:48.275] _job_complete: JobId=54087 WEXITSTATUS 1
[2022-12-16T14:45:48.275] _job_complete: JobId=54087 done
[2022-12-16T14:47:17.860] _slurm_rpc_submit_batch_job: JobId=54088 InitPrio=984 usec=549
[2022-12-16T14:48:23.328] _job_complete: JobId=53630 WEXITSTATUS 0
[2022-12-16T14:48:23.328] _job_complete: JobId=53630 done
[2022-12-16T14:48:25.428] sched: Allocate JobId=53941 NodeList=gpu03 #CPUs=16 Partition=gpu-k10
[2022-12-16T14:55:43.832] _slurm_rpc_submit_batch_job: JobId=54089 InitPrio=5314 usec=539
[2022-12-16T14:55:46.311] _slurm_rpc_submit_batch_job: JobId=54090 InitPrio=5314 usec=460
