[2022-07-01T00:13:16.699] _job_complete: JobId=45424 WEXITSTATUS 0
[2022-07-01T00:13:16.699] _job_complete: JobId=45424 done
[2022-07-01T00:29:27.356] _slurm_rpc_submit_batch_job: JobId=45432 InitPrio=20551 usec=418
[2022-07-01T00:29:27.416] sched: Allocate JobId=45432 NodeList=cpu12 #CPUs=32 Partition=cpu-epyc
[2022-07-01T00:45:53.676] _slurm_rpc_submit_batch_job: JobId=45433 InitPrio=20417 usec=504
[2022-07-01T00:47:08.274] _slurm_rpc_submit_batch_job: JobId=45434 InitPrio=20417 usec=439
[2022-07-01T00:47:09.263] sched: Allocate JobId=45434 NodeList=cpu11 #CPUs=16 Partition=cpu-opteron
[2022-07-01T02:23:42.183] _job_complete: JobId=45432 WEXITSTATUS 0
[2022-07-01T02:23:42.183] _job_complete: JobId=45432 done
[2022-07-01T03:04:14.675] _job_complete: JobId=45431 WEXITSTATUS 0
[2022-07-01T03:04:14.675] _job_complete: JobId=45431 done
[2022-07-01T03:43:03.067] _job_complete: JobId=45428 WEXITSTATUS 0
[2022-07-01T03:43:03.067] _job_complete: JobId=45428 done
[2022-07-01T05:11:28.926] _job_complete: JobId=45401 WEXITSTATUS 0
[2022-07-01T05:11:28.926] _job_complete: JobId=45401 done
[2022-07-01T05:11:29.507] sched: Allocate JobId=45433 NodeList=cpu01 #CPUs=16 Partition=cpu-opteron
[2022-07-01T05:40:29.326] _job_complete: JobId=45427 WEXITSTATUS 0
[2022-07-01T05:40:29.326] _job_complete: JobId=45427 done
[2022-07-01T08:17:05.341] _slurm_rpc_submit_batch_job: JobId=45435 InitPrio=20551 usec=411
[2022-07-01T08:17:06.111] sched: Allocate JobId=45435 NodeList=cpu12 #CPUs=32 Partition=cpu-epyc
[2022-07-01T08:18:46.711] _slurm_rpc_submit_batch_job: JobId=45436 InitPrio=20414 usec=437
[2022-07-01T08:18:47.351] sched: Allocate JobId=45436 NodeList=cpu11 #CPUs=48 Partition=cpu-opteron
[2022-07-01T08:19:52.559] _slurm_rpc_kill_job: REQUEST_KILL_JOB JobId=45436 uid 548200021
[2022-07-01T08:21:29.464] _slurm_rpc_submit_batch_job: JobId=45437 InitPrio=20414 usec=493
[2022-07-01T08:21:29.572] sched: Allocate JobId=45437 NodeList=cpu11 #CPUs=48 Partition=cpu-opteron
[2022-07-01T08:22:07.053] _slurm_rpc_kill_job: REQUEST_KILL_JOB JobId=45437 uid 548200021
[2022-07-01T08:25:13.362] _slurm_rpc_submit_batch_job: JobId=45438 InitPrio=20414 usec=601
[2022-07-01T08:25:14.106] sched: Allocate JobId=45438 NodeList=cpu11 #CPUs=48 Partition=cpu-opteron
[2022-07-01T08:30:54.630] _slurm_rpc_submit_batch_job: JobId=45439 InitPrio=20551 usec=401
[2022-07-01T08:30:54.900] sched: Allocate JobId=45439 NodeList=cpu13 #CPUs=32 Partition=cpu-epyc
[2022-07-01T08:42:56.669] _job_complete: JobId=45252 WEXITSTATUS 0
[2022-07-01T08:42:56.674] _job_complete: JobId=45252 done
[2022-07-01T08:44:14.499] _job_complete: JobId=45438 WEXITSTATUS 0
[2022-07-01T08:44:14.499] _job_complete: JobId=45438 done
[2022-07-01T09:12:55.918] sched: _slurm_rpc_allocate_resources JobId=45440 NodeList=cpu11 usec=15448
[2022-07-01T09:40:59.574] _job_complete: JobId=45289 WEXITSTATUS 0
[2022-07-01T09:40:59.575] _job_complete: JobId=45289 done
[2022-07-01T09:42:34.672] _slurm_rpc_submit_batch_job: JobId=45441 InitPrio=20516 usec=434
[2022-07-01T09:42:35.101] sched: Allocate JobId=45441 NodeList=cpu11 #CPUs=36 Partition=cpu-opteron
[2022-07-01T10:14:54.340] _slurm_rpc_submit_batch_job: JobId=45442 InitPrio=19196 usec=425
[2022-07-01T10:14:54.938] sched: Allocate JobId=45442 NodeList=cpu03 #CPUs=64 Partition=cpu-opteron
[2022-07-01T10:17:23.480] Processing Reconfiguration Request
[2022-07-01T10:17:23.488] restoring original state of nodes
[2022-07-01T10:17:23.488] select/cons_tres: part_data_create_array: select/cons_tres: preparing for 6 partitions
[2022-07-01T10:17:23.489] read_slurm_conf: backup_controller not specified
[2022-07-01T10:17:23.490] select/cons_tres: select_p_reconfigure: select/cons_tres: reconfigure
[2022-07-01T10:17:23.490] select/cons_tres: part_data_create_array: select/cons_tres: preparing for 6 partitions
[2022-07-01T10:17:23.490] No parameter for mcs plugin, default values set
[2022-07-01T10:17:23.490] mcs: MCSParameters = (null). ondemand set.
[2022-07-01T10:17:23.491] _slurm_rpc_reconfigure_controller: completed usec=10694
[2022-07-01T10:17:24.127] SchedulerParameters=default_queue_depth=100,max_rpc_cnt=0,max_sched_time=2,partition_job_depth=0,sched_max_job_start=0,sched_min_interval=2
[2022-07-01T11:48:15.504] _slurm_rpc_submit_batch_job: JobId=45443 InitPrio=20551 usec=513
[2022-07-01T11:48:15.701] sched: Allocate JobId=45443 NodeList=cpu07 #CPUs=32 Partition=cpu-opteron
[2022-07-01T11:53:32.856] _slurm_rpc_submit_batch_job: JobId=45444 InitPrio=20280 usec=481
[2022-07-01T11:53:33.290] sched: Allocate JobId=45444 NodeList=cpu07 #CPUs=32 Partition=cpu-opteron
[2022-07-01T11:54:39.204] _slurm_rpc_submit_batch_job: JobId=45445 InitPrio=20460 usec=487
[2022-07-01T11:54:39.369] sched: Allocate JobId=45445 NodeList=cpu11 #CPUs=11 Partition=cpu-opteron
[2022-07-01T11:56:10.306] _slurm_rpc_submit_batch_job: JobId=45446 InitPrio=20551 usec=418
[2022-07-01T12:08:26.241] job_step_signal: JobId=45440 StepId=0 not found
[2022-07-01T12:08:26.243] _job_complete: JobId=45440 WTERMSIG 126
[2022-07-01T12:08:26.243] _job_complete: JobId=45440 cancelled by interactive user
[2022-07-01T12:08:26.243] _job_complete: JobId=45440 done
[2022-07-01T13:14:07.395] _job_complete: JobId=45399 OOM failure
[2022-07-01T13:14:07.399] _job_complete: JobId=45399 done
[2022-07-01T13:14:07.785] sched: Allocate JobId=45446 NodeList=cpu04 #CPUs=32 Partition=cpu-opteron
[2022-07-01T13:15:31.672] _job_complete: JobId=45446 WEXITSTATUS 1
[2022-07-01T13:15:31.672] _job_complete: JobId=45446 done
[2022-07-01T13:38:46.746] _slurm_rpc_submit_batch_job: JobId=45447 InitPrio=19194 usec=538
[2022-07-01T13:38:46.798] sched: Allocate JobId=45447 NodeList=cpu04 #CPUs=64 Partition=cpu-opteron
[2022-07-01T14:20:36.962] _slurm_rpc_kill_job: REQUEST_KILL_JOB JobId=45447 uid 548200017
[2022-07-01T14:20:41.950] _slurm_rpc_submit_batch_job: JobId=45448 InitPrio=19194 usec=439
[2022-07-01T14:21:08.072] sched: Allocate JobId=45448 NodeList=cpu04 #CPUs=64 Partition=cpu-opteron
[2022-07-01T14:31:51.411] _slurm_rpc_kill_job: REQUEST_KILL_JOB JobId=45410 uid 548200017
[2022-07-01T14:31:55.820] _slurm_rpc_submit_batch_job: JobId=45449 InitPrio=19194 usec=398
[2022-07-01T14:31:56.265] sched: Allocate JobId=45449 NodeList=cpu05 #CPUs=64 Partition=cpu-opteron
[2022-07-01T14:45:59.065] _slurm_rpc_submit_batch_job: JobId=45450 InitPrio=24444 usec=545
[2022-07-01T14:47:18.607] _slurm_rpc_submit_batch_job: JobId=45451 InitPrio=24444 usec=457
[2022-07-01T14:47:50.872] _slurm_rpc_submit_batch_job: JobId=45452 InitPrio=20680 usec=408
[2022-07-01T14:47:51.105] sched: Allocate JobId=45452 NodeList=gpu05 #CPUs=16 Partition=gpu-v100s
[2022-07-01T14:48:29.851] _slurm_rpc_submit_batch_job: JobId=45453 InitPrio=24444 usec=442
[2022-07-01T14:52:19.796] _job_complete: JobId=45452 WEXITSTATUS 0
[2022-07-01T14:52:19.796] _job_complete: JobId=45452 done
[2022-07-01T14:54:03.245] _slurm_rpc_submit_batch_job: JobId=45454 InitPrio=20680 usec=438
[2022-07-01T14:54:03.716] sched: Allocate JobId=45454 NodeList=gpu05 #CPUs=16 Partition=gpu-v100s
[2022-07-01T14:54:24.415] _slurm_rpc_submit_batch_job: JobId=45455 InitPrio=24444 usec=458
[2022-07-01T14:56:26.406] _slurm_rpc_submit_batch_job: JobId=45456 InitPrio=24444 usec=447
[2022-07-01T14:57:08.308] _job_complete: JobId=45454 WEXITSTATUS 0
[2022-07-01T14:57:08.309] _job_complete: JobId=45454 done
[2022-07-01T15:04:42.258] _slurm_rpc_submit_batch_job: JobId=45457 InitPrio=20680 usec=460
[2022-07-01T15:04:42.838] sched: Allocate JobId=45457 NodeList=gpu05 #CPUs=16 Partition=gpu-v100s
[2022-07-01T15:04:43.567] _job_complete: JobId=45457 WEXITSTATUS 1
[2022-07-01T15:04:43.567] _job_complete: JobId=45457 done
[2022-07-01T15:05:51.657] _slurm_rpc_submit_batch_job: JobId=45458 InitPrio=20680 usec=459
[2022-07-01T15:05:51.930] sched: Allocate JobId=45458 NodeList=gpu05 #CPUs=16 Partition=gpu-v100s
[2022-07-01T15:07:31.582] _slurm_rpc_submit_batch_job: JobId=45459 InitPrio=20680 usec=596
[2022-07-01T16:27:03.432] _slurm_rpc_submit_batch_job: JobId=45460 InitPrio=24444 usec=603
[2022-07-01T16:29:20.679] _slurm_rpc_submit_batch_job: JobId=45461 InitPrio=24444 usec=620
[2022-07-01T16:31:34.832] _slurm_rpc_submit_batch_job: JobId=45462 InitPrio=24444 usec=453
[2022-07-01T16:33:26.015] _slurm_rpc_submit_batch_job: JobId=45463 InitPrio=24444 usec=501
[2022-07-01T16:36:39.012] _slurm_rpc_submit_batch_job: JobId=45464 InitPrio=24444 usec=413
[2022-07-01T16:39:57.058] _slurm_rpc_submit_batch_job: JobId=45465 InitPrio=24444 usec=477
[2022-07-01T16:41:48.329] _slurm_rpc_submit_batch_job: JobId=45466 InitPrio=24444 usec=620
[2022-07-01T16:44:12.385] _slurm_rpc_submit_batch_job: JobId=45467 InitPrio=24444 usec=588
[2022-07-01T16:46:03.648] _slurm_rpc_submit_batch_job: JobId=45468 InitPrio=24444 usec=428
[2022-07-01T16:53:05.328] _slurm_rpc_submit_batch_job: JobId=45469 InitPrio=24444 usec=474
[2022-07-01T16:58:36.921] _slurm_rpc_submit_batch_job: JobId=45470 InitPrio=24444 usec=436
[2022-07-01T17:01:37.896] _slurm_rpc_submit_batch_job: JobId=45471 InitPrio=24444 usec=554
[2022-07-01T18:32:34.428] _job_complete: JobId=45441 WEXITSTATUS 0
[2022-07-01T18:32:34.428] _job_complete: JobId=45441 done
[2022-07-01T18:32:35.038] sched: Allocate JobId=45450 NodeList=cpu11 #CPUs=16 Partition=cpu-opteron
[2022-07-01T18:32:35.039] sched: Allocate JobId=45451 NodeList=cpu11 #CPUs=16 Partition=cpu-opteron
[2022-07-01T19:51:36.742] _job_complete: JobId=45458 WEXITSTATUS 0
[2022-07-01T19:51:36.742] _job_complete: JobId=45458 done
[2022-07-01T19:51:37.073] sched: Allocate JobId=45459 NodeList=gpu05 #CPUs=16 Partition=gpu-v100s
[2022-07-01T21:30:40.353] _job_complete: JobId=45448 OOM failure
[2022-07-01T21:30:40.358] _job_complete: JobId=45448 done
[2022-07-01T21:30:40.752] sched: Allocate JobId=45453 NodeList=cpu04 #CPUs=16 Partition=cpu-opteron
[2022-07-01T21:30:40.753] sched: Allocate JobId=45455 NodeList=cpu04 #CPUs=16 Partition=cpu-opteron
[2022-07-01T21:30:40.754] sched: Allocate JobId=45456 NodeList=cpu04 #CPUs=16 Partition=cpu-opteron
[2022-07-01T21:30:40.754] sched: Allocate JobId=45460 NodeList=cpu04 #CPUs=16 Partition=cpu-opteron
[2022-07-01T22:42:42.287] _slurm_rpc_submit_batch_job: JobId=45472 InitPrio=20137 usec=424
[2022-07-01T23:05:08.879] _slurm_rpc_submit_batch_job: JobId=45473 InitPrio=19468 usec=413
[2022-07-01T23:05:23.866] _slurm_rpc_kill_job: REQUEST_KILL_JOB JobId=45310 uid 548200017
[2022-07-01T23:05:27.733] sched: Allocate JobId=45473 NodeList=cpu14 #CPUs=32 Partition=cpu-epyc
[2022-07-01T23:05:43.270] _slurm_rpc_submit_batch_job: JobId=45474 InitPrio=19468 usec=351
[2022-07-01T23:09:28.398] _slurm_rpc_submit_batch_job: JobId=45475 InitPrio=19468 usec=391
[2022-07-01T23:34:27.291] _job_complete: JobId=45443 WEXITSTATUS 0
[2022-07-01T23:34:27.291] _job_complete: JobId=45443 done
[2022-07-01T23:34:27.811] sched: Allocate JobId=45461 NodeList=cpu07 #CPUs=16 Partition=cpu-opteron
[2022-07-01T23:34:27.811] sched: Allocate JobId=45462 NodeList=cpu07 #CPUs=16 Partition=cpu-opteron
[2022-07-02T00:31:43.240] _slurm_rpc_submit_batch_job: JobId=45476 InitPrio=20774 usec=559
[2022-07-02T00:31:44.129] sched: Allocate JobId=45476 NodeList=cpu11 #CPUs=5 Partition=cpu-opteron
[2022-07-02T00:39:50.162] _job_complete: JobId=45459 WEXITSTATUS 0
[2022-07-02T00:39:50.162] _job_complete: JobId=45459 done
[2022-07-02T00:47:24.708] Time limit exhausted for JobId=45434
[2022-07-02T00:47:25.667] sched: Allocate JobId=45463 NodeList=cpu11 #CPUs=16 Partition=cpu-opteron
[2022-07-02T03:58:23.918] _job_complete: JobId=45473 WEXITSTATUS 2
[2022-07-02T03:58:23.922] _job_complete: JobId=45473 done
[2022-07-02T03:58:26.835] sched: Allocate JobId=45474 NodeList=cpu14 #CPUs=32 Partition=cpu-epyc
[2022-07-02T04:46:22.312] _job_complete: JobId=45302 WEXITSTATUS 0
[2022-07-02T04:46:22.312] _job_complete: JobId=45302 done
[2022-07-02T04:46:23.174] sched: Allocate JobId=45472 NodeList=cpu15 #CPUs=48 Partition=cpu-epyc
[2022-07-02T04:52:51.980] _job_complete: JobId=45472 WEXITSTATUS 1
[2022-07-02T04:52:51.980] _job_complete: JobId=45472 done
[2022-07-02T04:52:52.219] sched: Allocate JobId=45475 NodeList=cpu15 #CPUs=32 Partition=cpu-epyc
[2022-07-02T05:11:54.101] Time limit exhausted for JobId=45433
[2022-07-02T05:11:54.773] sched: Allocate JobId=45464 NodeList=cpu01 #CPUs=16 Partition=cpu-opteron
[2022-07-02T05:39:58.381] _job_complete: JobId=45455 WEXITSTATUS 0
[2022-07-02T05:39:58.381] _job_complete: JobId=45455 done
[2022-07-02T05:39:58.926] sched: Allocate JobId=45465 NodeList=cpu04 #CPUs=16 Partition=cpu-opteron
[2022-07-02T06:37:13.282] _job_complete: JobId=45460 WEXITSTATUS 0
[2022-07-02T06:37:13.282] _job_complete: JobId=45460 done
[2022-07-02T06:37:13.716] sched: Allocate JobId=45466 NodeList=cpu04 #CPUs=16 Partition=cpu-opteron
[2022-07-02T08:16:09.524] _slurm_rpc_submit_batch_job: JobId=45477 InitPrio=19468 usec=555
[2022-07-02T08:18:21.909] _slurm_rpc_kill_job: REQUEST_KILL_JOB JobId=45474 uid 548200017
[2022-07-02T08:18:25.823] sched: Allocate JobId=45477 NodeList=cpu14 #CPUs=32 Partition=cpu-epyc
[2022-07-02T08:18:26.862] _slurm_rpc_submit_batch_job: JobId=45478 InitPrio=19468 usec=442
[2022-07-02T08:20:18.672] _slurm_rpc_kill_job: REQUEST_KILL_JOB JobId=45475 uid 548200017
[2022-07-02T08:20:20.525] sched: Allocate JobId=45478 NodeList=cpu15 #CPUs=32 Partition=cpu-epyc
[2022-07-02T08:20:23.994] _slurm_rpc_submit_batch_job: JobId=45479 InitPrio=19468 usec=453
[2022-07-02T08:55:57.821] _job_complete: JobId=45463 WEXITSTATUS 1
[2022-07-02T08:55:57.821] _job_complete: JobId=45463 done
[2022-07-02T08:55:58.516] sched: Allocate JobId=45467 NodeList=cpu11 #CPUs=16 Partition=cpu-opteron
[2022-07-02T09:25:42.103] _slurm_rpc_submit_batch_job: JobId=45480 InitPrio=20411 usec=453
[2022-07-02T09:25:42.178] sched: Allocate JobId=45480 NodeList=cpu15 #CPUs=16 Partition=cpu-epyc
[2022-07-02T09:33:28.387] _slurm_rpc_submit_batch_job: JobId=45481 InitPrio=20680 usec=529
[2022-07-02T09:34:25.251] _slurm_rpc_submit_batch_job: JobId=45482 InitPrio=20680 usec=458
[2022-07-02T11:40:57.568] _job_complete: JobId=45466 WEXITSTATUS 0
[2022-07-02T11:40:57.568] _job_complete: JobId=45466 done
[2022-07-02T11:40:58.088] sched: Allocate JobId=45468 NodeList=cpu04 #CPUs=16 Partition=cpu-opteron
[2022-07-02T11:53:54.920] Time limit exhausted for JobId=45444
[2022-07-02T11:53:55.955] sched: Allocate JobId=45469 NodeList=cpu07 #CPUs=16 Partition=cpu-opteron
[2022-07-02T11:53:55.955] sched: Allocate JobId=45470 NodeList=cpu07 #CPUs=16 Partition=cpu-opteron
[2022-07-02T11:54:55.002] Time limit exhausted for JobId=45445
[2022-07-02T13:25:47.515] _job_complete: JobId=45419 WEXITSTATUS 0
[2022-07-02T13:25:47.516] _job_complete: JobId=45419 done
[2022-07-02T13:36:54.676] _slurm_rpc_submit_batch_job: JobId=45483 InitPrio=23100 usec=642
[2022-07-02T14:39:46.004] _job_complete: JobId=45453 WEXITSTATUS 0
[2022-07-02T14:39:46.004] _job_complete: JobId=45453 done
[2022-07-02T14:39:46.530] sched: Allocate JobId=45471 NodeList=cpu04 #CPUs=16 Partition=cpu-opteron
[2022-07-02T15:15:22.433] _slurm_rpc_submit_batch_job: JobId=45484 InitPrio=20480 usec=475
[2022-07-02T15:15:22.499] sched: Allocate JobId=45484 NodeList=gpu02 #CPUs=8 Partition=gpu-titan
[2022-07-02T15:29:11.745] _job_complete: JobId=45467 WEXITSTATUS 1
[2022-07-02T15:29:11.745] _job_complete: JobId=45467 done
[2022-07-02T15:29:12.251] sched: Allocate JobId=45483 NodeList=cpu11 #CPUs=16 Partition=cpu-opteron
[2022-07-02T16:00:47.631] sched: _slurm_rpc_allocate_resources JobId=45485 NodeList=(null) usec=852
[2022-07-02T16:00:47.651] sched: Allocate JobId=45485 NodeList=cpu11 #CPUs=1 Partition=cpu-opteron
[2022-07-02T16:19:00.278] No nodes satisfy requirements for JobId=45486 in partition cpu-opteron
[2022-07-02T16:19:00.278] _slurm_rpc_submit_batch_job: Requested node configuration is not available
[2022-07-02T16:19:00.337] _slurm_rpc_submit_batch_job: JobId=45487 InitPrio=22831 usec=364
[2022-07-02T16:19:14.646] _slurm_rpc_submit_batch_job: JobId=45488 InitPrio=20263 usec=521
[2022-07-02T16:19:14.728] sched: Allocate JobId=45488 NodeList=cpu11 #CPUs=2 Partition=cpu-opteron
[2022-07-02T16:19:17.400] _job_complete: JobId=45488 WEXITSTATUS 0
[2022-07-02T16:19:17.400] _job_complete: JobId=45488 done
[2022-07-02T16:30:00.923] _slurm_rpc_submit_batch_job: JobId=45489 InitPrio=20263 usec=447
[2022-07-02T16:30:01.899] sched: Allocate JobId=45489 NodeList=cpu11 #CPUs=2 Partition=cpu-opteron
[2022-07-02T16:30:29.020] _job_complete: JobId=45489 WEXITSTATUS 1
[2022-07-02T16:30:29.020] _job_complete: JobId=45489 done
[2022-07-02T16:35:14.246] _slurm_rpc_submit_batch_job: JobId=45490 InitPrio=20143 usec=397
[2022-07-02T16:35:14.458] sched: Allocate JobId=45490 NodeList=gpu05 #CPUs=16 Partition=gpu-v100s
[2022-07-02T16:35:49.753] _slurm_rpc_kill_job: REQUEST_KILL_JOB JobId=45490 uid 548200021
[2022-07-02T16:36:03.427] _slurm_rpc_submit_batch_job: JobId=45491 InitPrio=20143 usec=501
[2022-07-02T16:36:03.529] sched: Allocate JobId=45491 NodeList=gpu05 #CPUs=16 Partition=gpu-v100s
[2022-07-02T16:36:09.455] _job_complete: JobId=45491 WEXITSTATUS 1
[2022-07-02T16:36:09.455] _job_complete: JobId=45491 done
[2022-07-02T16:37:21.204] _slurm_rpc_submit_batch_job: JobId=45492 InitPrio=20143 usec=481
[2022-07-02T16:37:21.640] sched: Allocate JobId=45492 NodeList=gpu05 #CPUs=16 Partition=gpu-v100s
[2022-07-02T17:28:44.341] _job_complete: JobId=45461 WEXITSTATUS 0
[2022-07-02T17:28:44.341] _job_complete: JobId=45461 done
[2022-07-02T17:28:44.847] sched: Allocate JobId=45487 NodeList=cpu07 #CPUs=16 Partition=cpu-opteron
[2022-07-02T17:59:05.231] _job_complete: JobId=45450 WEXITSTATUS 0
[2022-07-02T17:59:05.231] _job_complete: JobId=45450 done
[2022-07-02T17:59:05.787] sched: Allocate JobId=45481 NodeList=cpu11 #CPUs=16 Partition=cpu-opteron
[2022-07-02T18:06:36.141] _job_complete: JobId=45470 WEXITSTATUS 0
[2022-07-02T18:06:36.141] _job_complete: JobId=45470 done
[2022-07-02T18:06:36.602] sched: Allocate JobId=45482 NodeList=cpu07 #CPUs=16 Partition=cpu-opteron
[2022-07-02T18:06:38.935] _job_complete: JobId=45482 WEXITSTATUS 1
[2022-07-02T18:06:38.935] _job_complete: JobId=45482 done
[2022-07-02T19:02:25.998] _job_complete: JobId=45485 WEXITSTATUS 0
[2022-07-02T19:02:25.998] _job_complete: JobId=45485 done
[2022-07-02T19:17:40.216] _slurm_rpc_submit_batch_job: JobId=45493 InitPrio=19194 usec=451
[2022-07-02T19:17:52.889] _slurm_rpc_kill_job: REQUEST_KILL_JOB JobId=45449 uid 548200017
[2022-07-02T19:17:54.943] sched: Allocate JobId=45493 NodeList=cpu05 #CPUs=64 Partition=cpu-opteron
[2022-07-02T19:25:21.279] _slurm_rpc_submit_batch_job: JobId=45494 InitPrio=19194 usec=689
[2022-07-02T19:25:28.455] _slurm_rpc_kill_job: REQUEST_KILL_JOB JobId=45442 uid 548200017
[2022-07-02T19:25:30.456] sched: Allocate JobId=45494 NodeList=cpu03 #CPUs=64 Partition=cpu-opteron
[2022-07-02T19:53:13.116] _job_complete: JobId=45471 WEXITSTATUS 1
[2022-07-02T19:53:13.116] _job_complete: JobId=45471 done
[2022-07-02T20:16:18.709] _job_complete: JobId=45468 WEXITSTATUS 0
[2022-07-02T20:16:18.709] _job_complete: JobId=45468 done
[2022-07-02T20:16:39.614] _slurm_rpc_submit_batch_job: JobId=45495 InitPrio=22831 usec=544
[2022-07-02T20:16:40.245] sched: Allocate JobId=45495 NodeList=cpu07 #CPUs=16 Partition=cpu-opteron
[2022-07-02T20:40:17.644] _slurm_rpc_kill_job: REQUEST_KILL_JOB JobId=45479 uid 548200017
[2022-07-02T20:42:50.688] _slurm_rpc_kill_job: REQUEST_KILL_JOB JobId=45478 uid 548200017
[2022-07-02T20:43:01.584] _slurm_rpc_submit_batch_job: JobId=45496 InitPrio=19468 usec=456
[2022-07-02T20:43:02.531] sched: Allocate JobId=45496 NodeList=cpu15 #CPUs=32 Partition=cpu-epyc
[2022-07-02T20:46:15.657] _slurm_rpc_submit_batch_job: JobId=45497 InitPrio=19468 usec=515
[2022-07-02T20:56:48.037] _slurm_rpc_submit_batch_job: JobId=45498 InitPrio=20006 usec=499
[2022-07-02T20:56:48.220] sched: Allocate JobId=45498 NodeList=cpu04 #CPUs=32 Partition=cpu-opteron
[2022-07-02T21:06:29.149] _job_complete: JobId=45465 WEXITSTATUS 0
[2022-07-02T21:06:29.149] _job_complete: JobId=45465 done
[2022-07-02T21:09:16.496] _job_complete: JobId=45451 WEXITSTATUS 0
[2022-07-02T21:09:16.496] _job_complete: JobId=45451 done
[2022-07-02T21:24:35.685] _job_complete: JobId=45464 WEXITSTATUS 0
[2022-07-02T21:24:35.686] _job_complete: JobId=45464 done
[2022-07-02T22:10:48.509] _job_complete: JobId=45456 WEXITSTATUS 0
[2022-07-02T22:10:48.509] _job_complete: JobId=45456 done
[2022-07-02T22:20:46.200] _slurm_rpc_submit_batch_job: JobId=45499 InitPrio=20006 usec=596
[2022-07-02T22:20:46.421] sched: Allocate JobId=45499 NodeList=cpu04 #CPUs=32 Partition=cpu-opteron
[2022-07-02T22:39:14.308] _slurm_rpc_kill_job: REQUEST_KILL_JOB JobId=45493 uid 548200017
[2022-07-02T22:39:29.042] _slurm_rpc_submit_batch_job: JobId=45500 InitPrio=19194 usec=415
[2022-07-02T22:39:29.586] sched: Allocate JobId=45500 NodeList=cpu05 #CPUs=64 Partition=cpu-opteron
[2022-07-02T22:41:42.333] _slurm_rpc_kill_job: REQUEST_KILL_JOB JobId=45494 uid 548200017
[2022-07-02T22:41:51.351] _slurm_rpc_submit_batch_job: JobId=45501 InitPrio=19194 usec=416
[2022-07-02T22:41:51.767] sched: Allocate JobId=45501 NodeList=cpu03 #CPUs=64 Partition=cpu-opteron
[2022-07-02T23:32:19.940] _job_complete: JobId=45469 WEXITSTATUS 0
[2022-07-02T23:32:19.940] _job_complete: JobId=45469 done
[2022-07-03T00:31:55.858] Time limit exhausted for JobId=45476
[2022-07-03T01:58:38.199] _job_complete: JobId=45492 WEXITSTATUS 1
[2022-07-03T01:58:38.200] _job_complete: JobId=45492 done
[2022-07-03T05:18:00.851] _job_complete: JobId=45483 WEXITSTATUS 0
[2022-07-03T05:18:00.851] _job_complete: JobId=45483 done
[2022-07-03T07:36:01.531] _slurm_rpc_kill_job: REQUEST_KILL_JOB JobId=45497 uid 548200017
[2022-07-03T07:36:08.529] _slurm_rpc_submit_batch_job: JobId=45502 InitPrio=19468 usec=411
[2022-07-03T07:36:23.233] _slurm_rpc_kill_job: REQUEST_KILL_JOB JobId=45477 uid 548200017
[2022-07-03T07:36:27.143] sched: Allocate JobId=45502 NodeList=cpu14 #CPUs=32 Partition=cpu-epyc
[2022-07-03T07:38:16.465] _slurm_rpc_kill_job: REQUEST_KILL_JOB JobId=45496 uid 548200017
[2022-07-03T07:38:20.840] _slurm_rpc_submit_batch_job: JobId=45503 InitPrio=19468 usec=389
[2022-07-03T07:38:21.084] sched: Allocate JobId=45503 NodeList=cpu15 #CPUs=32 Partition=cpu-epyc
[2022-07-03T07:40:13.722] _slurm_rpc_kill_job: REQUEST_KILL_JOB JobId=45500 uid 548200017
[2022-07-03T07:40:20.507] _slurm_rpc_submit_batch_job: JobId=45504 InitPrio=19194 usec=411
[2022-07-03T07:40:21.252] sched: Allocate JobId=45504 NodeList=cpu05 #CPUs=64 Partition=cpu-opteron
[2022-07-03T07:41:39.809] _slurm_rpc_kill_job: REQUEST_KILL_JOB JobId=45501 uid 548200017
[2022-07-03T07:41:43.002] _slurm_rpc_submit_batch_job: JobId=45505 InitPrio=19194 usec=466
[2022-07-03T07:41:43.365] sched: Allocate JobId=45505 NodeList=cpu03 #CPUs=64 Partition=cpu-opteron
[2022-07-03T07:42:00.536] _job_complete: JobId=45498 WEXITSTATUS 0
[2022-07-03T07:42:00.537] _job_complete: JobId=45498 done
[2022-07-03T07:49:51.682] _slurm_rpc_submit_batch_job: JobId=45506 InitPrio=19331 usec=397
[2022-07-03T07:49:52.334] sched: Allocate JobId=45506 NodeList=cpu11 #CPUs=48 Partition=cpu-opteron
[2022-07-03T07:50:12.696] _slurm_rpc_kill_job: REQUEST_KILL_JOB JobId=45418 uid 548200017
[2022-07-03T07:57:01.961] _slurm_rpc_submit_batch_job: JobId=45507 InitPrio=19468 usec=473
[2022-07-03T08:59:58.328] _slurm_rpc_submit_batch_job: JobId=45508 InitPrio=19463 usec=524
[2022-07-03T08:59:59.576] sched: Allocate JobId=45508 NodeList=cpu01 #CPUs=64 Partition=cpu-opteron
[2022-07-03T09:00:28.103] _slurm_rpc_kill_job: REQUEST_KILL_JOB JobId=45508 uid 548200021
[2022-07-03T09:07:28.334] _slurm_rpc_submit_batch_job: JobId=45509 InitPrio=19463 usec=399
[2022-07-03T09:07:28.496] sched: Allocate JobId=45509 NodeList=cpu01 #CPUs=64 Partition=cpu-opteron
[2022-07-03T09:09:53.792] _slurm_rpc_kill_job: REQUEST_KILL_JOB JobId=45509 uid 548200021
[2022-07-03T09:10:58.439] _slurm_rpc_submit_batch_job: JobId=45510 InitPrio=19463 usec=428
[2022-07-03T09:10:59.837] sched: Allocate JobId=45510 NodeList=cpu01 #CPUs=64 Partition=cpu-opteron
[2022-07-03T09:16:53.096] _slurm_rpc_kill_job: REQUEST_KILL_JOB JobId=45510 uid 548200021
[2022-07-03T09:17:00.323] _slurm_rpc_submit_batch_job: JobId=45511 InitPrio=19463 usec=546
[2022-07-03T09:17:00.499] sched: Allocate JobId=45511 NodeList=cpu01 #CPUs=64 Partition=cpu-opteron
[2022-07-03T09:23:18.971] _slurm_rpc_kill_job: REQUEST_KILL_JOB JobId=45484 uid 548200045
[2022-07-03T10:26:22.754] _slurm_rpc_kill_job: REQUEST_KILL_JOB JobId=45507 uid 548200017
[2022-07-03T10:27:43.025] _slurm_rpc_kill_job: REQUEST_KILL_JOB JobId=45502 uid 548200017
[2022-07-03T10:27:45.953] _slurm_rpc_submit_batch_job: JobId=45512 InitPrio=19468 usec=414
[2022-07-03T10:27:46.894] sched: Allocate JobId=45512 NodeList=cpu14 #CPUs=32 Partition=cpu-epyc
[2022-07-03T10:29:20.318] _slurm_rpc_kill_job: REQUEST_KILL_JOB JobId=45503 uid 548200017
[2022-07-03T10:29:23.730] _slurm_rpc_submit_batch_job: JobId=45513 InitPrio=19468 usec=417
[2022-07-03T10:29:24.542] sched: Allocate JobId=45513 NodeList=cpu15 #CPUs=32 Partition=cpu-epyc
[2022-07-03T10:31:32.900] _slurm_rpc_kill_job: REQUEST_KILL_JOB JobId=45505 uid 548200017
[2022-07-03T10:31:35.892] _slurm_rpc_submit_batch_job: JobId=45514 InitPrio=19194 usec=406
[2022-07-03T10:31:36.732] sched: Allocate JobId=45514 NodeList=cpu03 #CPUs=64 Partition=cpu-opteron
[2022-07-03T10:33:12.664] _slurm_rpc_kill_job: REQUEST_KILL_JOB JobId=45504 uid 548200017
[2022-07-03T10:33:15.369] _slurm_rpc_submit_batch_job: JobId=45515 InitPrio=19194 usec=383
[2022-07-03T10:33:15.992] sched: Allocate JobId=45515 NodeList=cpu05 #CPUs=64 Partition=cpu-opteron
[2022-07-03T10:35:20.401] _slurm_rpc_submit_batch_job: JobId=45516 InitPrio=19468 usec=426
[2022-07-03T10:41:16.334] sched: _slurm_rpc_allocate_resources JobId=45517 NodeList=(null) usec=939
[2022-07-03T10:41:16.780] sched: Allocate JobId=45517 NodeList=gpu02 #CPUs=8 Partition=gpu-titan
[2022-07-03T11:51:53.890] _job_complete: JobId=45517 WEXITSTATUS 1
[2022-07-03T11:51:53.890] _job_complete: JobId=45517 done
[2022-07-03T12:17:05.185] _job_complete: JobId=45439 WEXITSTATUS 1
[2022-07-03T12:17:05.185] _job_complete: JobId=45439 done
[2022-07-03T12:17:05.450] sched: Allocate JobId=45516 NodeList=cpu13 #CPUs=32 Partition=cpu-epyc
[2022-07-03T12:42:01.921] _job_complete: JobId=45378 WEXITSTATUS 1
[2022-07-03T12:42:01.921] _job_complete: JobId=45378 done
[2022-07-03T12:51:00.174] _slurm_rpc_submit_batch_job: JobId=45518 InitPrio=19874 usec=673
[2022-07-03T12:51:00.517] sched: Allocate JobId=45518 NodeList=cpu13 #CPUs=16 Partition=cpu-epyc
[2022-07-03T16:38:28.415] _job_complete: JobId=45480 WEXITSTATUS 0
[2022-07-03T16:38:28.415] _job_complete: JobId=45480 done
[2022-07-03T17:06:56.961] _job_complete: JobId=45516 WEXITSTATUS 2
[2022-07-03T17:06:56.966] _job_complete: JobId=45516 done
[2022-07-03T17:17:59.715] _slurm_rpc_kill_job: REQUEST_KILL_JOB JobId=45512 uid 548200017
[2022-07-03T17:18:03.290] _slurm_rpc_submit_batch_job: JobId=45519 InitPrio=19468 usec=396
[2022-07-03T17:18:03.819] sched: Allocate JobId=45519 NodeList=cpu13 #CPUs=32 Partition=cpu-epyc
[2022-07-03T17:20:13.942] _slurm_rpc_kill_job: REQUEST_KILL_JOB JobId=45513 uid 548200017
[2022-07-03T17:20:17.097] _slurm_rpc_submit_batch_job: JobId=45520 InitPrio=19468 usec=397
[2022-07-03T17:20:17.991] sched: Allocate JobId=45520 NodeList=cpu14 #CPUs=32 Partition=cpu-epyc
[2022-07-03T17:22:39.213] _slurm_rpc_submit_batch_job: JobId=45521 InitPrio=19331 usec=365
[2022-07-03T17:22:39.468] sched: Allocate JobId=45521 NodeList=cpu15 #CPUs=48 Partition=cpu-epyc
[2022-07-03T17:25:31.222] _slurm_rpc_kill_job: REQUEST_KILL_JOB JobId=45514 uid 548200017
[2022-07-03T17:25:34.301] _slurm_rpc_submit_batch_job: JobId=45522 InitPrio=19194 usec=466
[2022-07-03T17:25:34.757] sched: Allocate JobId=45522 NodeList=cpu03 #CPUs=64 Partition=cpu-opteron
[2022-07-03T17:27:23.531] _slurm_rpc_kill_job: REQUEST_KILL_JOB JobId=45515 uid 548200017
[2022-07-03T17:27:27.235] _slurm_rpc_submit_batch_job: JobId=45523 InitPrio=19194 usec=379
[2022-07-03T17:27:27.957] sched: Allocate JobId=45523 NodeList=cpu05 #CPUs=64 Partition=cpu-opteron
[2022-07-03T17:40:00.699] _job_complete: JobId=45487 WEXITSTATUS 0
[2022-07-03T17:40:00.699] _job_complete: JobId=45487 done
[2022-07-03T17:59:26.609] Time limit exhausted for JobId=45481
[2022-07-03T18:38:56.008] _job_complete: JobId=45365 WEXITSTATUS 0
[2022-07-03T18:38:56.013] _job_complete: JobId=45365 done
[2022-07-03T18:39:02.942] sched: Allocate JobId=45421 NodeList=gpu04 #CPUs=16 Partition=gpu-k40c
[2022-07-03T18:39:06.603] _slurm_rpc_submit_batch_job: JobId=45524 InitPrio=25920 usec=520
[2022-07-03T18:39:07.128] sched: Allocate JobId=45524 NodeList=cpu04 #CPUs=32 Partition=cpu-opteron
[2022-07-03T18:43:28.098] _job_complete: JobId=45524 WEXITSTATUS 0
[2022-07-03T18:43:28.098] _job_complete: JobId=45524 done
[2022-07-03T18:58:53.318] _slurm_rpc_submit_batch_job: JobId=45525 InitPrio=25920 usec=463
[2022-07-03T18:58:53.332] sched: Allocate JobId=45525 NodeList=cpu04 #CPUs=32 Partition=cpu-opteron
[2022-07-03T19:00:01.360] _job_complete: JobId=45525 WEXITSTATUS 0
[2022-07-03T19:00:01.360] _job_complete: JobId=45525 done
[2022-07-03T19:00:52.624] _slurm_rpc_kill_job: REQUEST_KILL_JOB JobId=45519 uid 548200017
[2022-07-03T19:00:55.470] _slurm_rpc_submit_batch_job: JobId=45526 InitPrio=19468 usec=391
[2022-07-03T19:00:55.514] sched: Allocate JobId=45526 NodeList=cpu13 #CPUs=32 Partition=cpu-epyc
[2022-07-03T19:02:44.372] _slurm_rpc_kill_job: REQUEST_KILL_JOB JobId=45520 uid 548200017
[2022-07-03T19:02:47.155] _slurm_rpc_submit_batch_job: JobId=45527 InitPrio=19468 usec=401
[2022-07-03T19:02:48.227] sched: Allocate JobId=45527 NodeList=cpu14 #CPUs=32 Partition=cpu-epyc
[2022-07-03T19:04:19.692] _slurm_rpc_submit_batch_job: JobId=45528 InitPrio=21756 usec=579
[2022-07-03T19:04:19.910] sched: Allocate JobId=45528 NodeList=gpu01 #CPUs=16 Partition=gpu-k10
[2022-07-03T19:04:42.080] _slurm_rpc_kill_job: REQUEST_KILL_JOB JobId=45521 uid 548200017
[2022-07-03T19:04:44.913] _slurm_rpc_submit_batch_job: JobId=45529 InitPrio=19331 usec=390
[2022-07-03T19:04:44.929] sched: Allocate JobId=45529 NodeList=cpu15 #CPUs=48 Partition=cpu-epyc
[2022-07-03T19:06:22.704] _slurm_rpc_kill_job: REQUEST_KILL_JOB JobId=45522 uid 548200017
[2022-07-03T19:06:25.789] _slurm_rpc_submit_batch_job: JobId=45530 InitPrio=19194 usec=393
[2022-07-03T19:06:26.071] sched: Allocate JobId=45530 NodeList=cpu03 #CPUs=64 Partition=cpu-opteron
[2022-07-03T19:08:03.981] _slurm_rpc_kill_job: REQUEST_KILL_JOB JobId=45523 uid 548200017
[2022-07-03T19:08:32.029] _slurm_rpc_submit_batch_job: JobId=45531 InitPrio=19194 usec=402
[2022-07-03T19:08:32.353] sched: Allocate JobId=45531 NodeList=cpu05 #CPUs=64 Partition=cpu-opteron
[2022-07-03T20:42:58.714] _slurm_rpc_submit_batch_job: JobId=45532 InitPrio=25920 usec=551
[2022-07-03T20:43:00.542] sched: Allocate JobId=45532 NodeList=cpu04 #CPUs=32 Partition=cpu-opteron
[2022-07-03T20:43:05.117] _job_complete: JobId=45532 WEXITSTATUS 1
[2022-07-03T20:43:05.117] _job_complete: JobId=45532 done
[2022-07-03T20:45:00.068] _slurm_rpc_submit_batch_job: JobId=45533 InitPrio=25920 usec=471
[2022-07-03T20:45:00.693] sched: Allocate JobId=45533 NodeList=cpu04 #CPUs=32 Partition=cpu-opteron
[2022-07-03T20:45:05.221] _job_complete: JobId=45533 WEXITSTATUS 1
[2022-07-03T20:45:05.221] _job_complete: JobId=45533 done
[2022-07-03T21:16:19.556] _job_complete: JobId=45495 WEXITSTATUS 0
[2022-07-03T21:16:19.556] _job_complete: JobId=45495 done
[2022-07-03T21:23:26.086] _slurm_rpc_submit_batch_job: JobId=45534 InitPrio=25920 usec=511
[2022-07-03T21:23:26.095] sched: Allocate JobId=45534 NodeList=cpu04 #CPUs=32 Partition=cpu-opteron
[2022-07-03T22:11:53.831] _slurm_rpc_submit_batch_job: JobId=45535 InitPrio=25920 usec=539
[2022-07-03T22:11:54.196] sched: Allocate JobId=45535 NodeList=cpu07 #CPUs=32 Partition=cpu-opteron
[2022-07-03T22:13:09.766] _slurm_rpc_kill_job: REQUEST_KILL_JOB JobId=45526 uid 548200017
[2022-07-03T22:13:12.518] _slurm_rpc_submit_batch_job: JobId=45536 InitPrio=19468 usec=380
[2022-07-03T22:13:13.475] sched: Allocate JobId=45536 NodeList=cpu13 #CPUs=32 Partition=cpu-epyc
[2022-07-03T22:14:19.709] _slurm_rpc_kill_job: REQUEST_KILL_JOB JobId=45536 uid 548200017
[2022-07-03T22:14:22.575] _slurm_rpc_submit_batch_job: JobId=45537 InitPrio=19468 usec=377
[2022-07-03T22:15:56.892] _slurm_rpc_kill_job: REQUEST_KILL_JOB JobId=45537 uid 548200017
[2022-07-03T22:16:02.556] _pick_best_nodes: JobId=45538 never runnable in partition cpu-epyc
[2022-07-03T22:16:02.556] _slurm_rpc_submit_batch_job: Requested node configuration is not available
[2022-07-03T22:16:24.775] _slurm_rpc_submit_batch_job: JobId=45539 InitPrio=19331 usec=430
[2022-07-03T22:16:51.273] _slurm_rpc_kill_job: REQUEST_KILL_JOB JobId=45529 uid 548200017
[2022-07-03T22:16:53.130] sched: Allocate JobId=45539 NodeList=cpu15 #CPUs=48 Partition=cpu-epyc
[2022-07-03T22:17:14.969] _slurm_rpc_kill_job: REQUEST_KILL_JOB JobId=45527 uid 548200017
[2022-07-03T22:18:15.174] _job_complete: JobId=45535 WEXITSTATUS 0
[2022-07-03T22:18:15.174] _job_complete: JobId=45535 done
[2022-07-03T22:19:10.418] _slurm_rpc_submit_batch_job: JobId=45540 InitPrio=19331 usec=434
[2022-07-03T22:19:48.507] _slurm_rpc_kill_job: REQUEST_KILL_JOB JobId=45540 uid 548200017
[2022-07-03T22:19:52.102] _pick_best_nodes: JobId=45541 never runnable in partition cpu-epyc
[2022-07-03T22:19:52.102] _slurm_rpc_submit_batch_job: Requested node configuration is not available
[2022-07-03T22:20:30.534] _slurm_rpc_submit_batch_job: JobId=45542 InitPrio=19468 usec=348
[2022-07-03T22:20:31.254] sched: Allocate JobId=45542 NodeList=cpu13 #CPUs=32 Partition=cpu-epyc
[2022-07-03T22:21:09.205] _slurm_rpc_kill_job: REQUEST_KILL_JOB JobId=45542 uid 548200017
[2022-07-03T22:21:32.022] _slurm_rpc_submit_batch_job: JobId=45543 InitPrio=19331 usec=461
[2022-07-03T22:24:06.267] _slurm_rpc_submit_batch_job: JobId=45544 InitPrio=19331 usec=402
[2022-07-03T22:26:01.132] _slurm_rpc_kill_job: REQUEST_KILL_JOB JobId=45530 uid 548200017
[2022-07-03T22:26:04.509] _slurm_rpc_submit_batch_job: JobId=45545 InitPrio=19194 usec=439
[2022-07-03T22:26:04.852] sched: Allocate JobId=45545 NodeList=cpu03 #CPUs=64 Partition=cpu-opteron
[2022-07-03T22:27:24.098] _slurm_rpc_kill_job: REQUEST_KILL_JOB JobId=45531 uid 548200017
[2022-07-03T22:27:26.900] _slurm_rpc_submit_batch_job: JobId=45546 InitPrio=19194 usec=417
[2022-07-03T22:27:27.003] sched: Allocate JobId=45546 NodeList=cpu05 #CPUs=64 Partition=cpu-opteron
[2022-07-03T22:30:22.244] _slurm_rpc_kill_job: REQUEST_KILL_JOB JobId=45539 uid 548200017
[2022-07-03T22:30:24.104] sched: Allocate JobId=45543 NodeList=cpu15 #CPUs=48 Partition=cpu-epyc
[2022-07-03T22:30:25.094] _slurm_rpc_submit_batch_job: JobId=45547 InitPrio=19331 usec=482
[2022-07-03T22:31:57.930] _slurm_rpc_kill_job: REQUEST_KILL_JOB JobId=45543 uid 548200017
[2022-07-03T22:31:59.778] sched: Allocate JobId=45544 NodeList=cpu15 #CPUs=48 Partition=cpu-epyc
[2022-07-03T22:32:00.948] _slurm_rpc_submit_batch_job: JobId=45548 InitPrio=19331 usec=372
[2022-07-03T22:32:43.864] _slurm_rpc_kill_job: REQUEST_KILL_JOB JobId=45545 uid 548200017
[2022-07-03T22:32:46.795] _slurm_rpc_submit_batch_job: JobId=45549 InitPrio=19194 usec=409
[2022-07-03T22:32:47.610] sched: Allocate JobId=45549 NodeList=cpu03 #CPUs=64 Partition=cpu-opteron
[2022-07-03T22:33:28.076] _slurm_rpc_kill_job: REQUEST_KILL_JOB JobId=45546 uid 548200017
[2022-07-03T22:33:30.896] _slurm_rpc_submit_batch_job: JobId=45550 InitPrio=19194 usec=408
[2022-07-03T22:33:31.671] sched: Allocate JobId=45550 NodeList=cpu05 #CPUs=64 Partition=cpu-opteron
[2022-07-03T22:35:39.284] _slurm_rpc_kill_job: REQUEST_KILL_JOB JobId=45544 uid 548200017
[2022-07-03T22:35:39.284] _slurm_rpc_kill_job: REQUEST_KILL_JOB JobId=45548 uid 548200017
[2022-07-03T22:35:39.284] _slurm_rpc_kill_job: REQUEST_KILL_JOB JobId=45547 uid 548200017
[2022-07-03T22:36:06.196] _slurm_rpc_submit_batch_job: JobId=45551 InitPrio=19331 usec=384
[2022-07-03T22:36:06.892] sched: Allocate JobId=45551 NodeList=cpu15 #CPUs=48 Partition=cpu-epyc
[2022-07-03T22:37:26.467] _slurm_rpc_submit_batch_job: JobId=45552 InitPrio=19468 usec=400
[2022-07-03T22:37:27.023] sched: Allocate JobId=45552 NodeList=cpu13 #CPUs=32 Partition=cpu-epyc
[2022-07-03T22:39:20.321] _slurm_rpc_submit_batch_job: JobId=45553 InitPrio=19331 usec=469
[2022-07-03T22:49:18.641] _slurm_rpc_submit_batch_job: JobId=45554 InitPrio=19703 usec=387
[2022-07-03T22:50:04.753] _slurm_rpc_submit_batch_job: JobId=45555 InitPrio=19737 usec=421
[2022-07-03T22:50:05.368] sched: Allocate JobId=45555 NodeList=cpu14 #CPUs=32 Partition=cpu-epyc
[2022-07-03T22:50:18.631] _slurm_rpc_kill_job: REQUEST_KILL_JOB JobId=4554 uid 548200021
[2022-07-03T22:50:18.631] job_str_signal(3): invalid JobId=4554
[2022-07-03T22:50:18.631] _slurm_rpc_kill_job: job_str_signal() uid=548200021 JobId=4554 sig=9 returned: Invalid job id specified
[2022-07-03T23:25:00.730] _job_complete: JobId=45534 WEXITSTATUS 0
[2022-07-03T23:25:00.730] _job_complete: JobId=45534 done
[2022-07-04T00:20:16.774] _slurm_rpc_kill_job: REQUEST_KILL_JOB JobId=45462 uid 548200133
[2022-07-04T00:22:32.012] _slurm_rpc_submit_batch_job: JobId=45556 InitPrio=22694 usec=445
[2022-07-04T00:22:32.500] sched: Allocate JobId=45556 NodeList=cpu04 #CPUs=32 Partition=cpu-opteron
[2022-07-04T05:53:14.105] _job_complete: JobId=45556 WEXITSTATUS 0
[2022-07-04T05:53:14.105] _job_complete: JobId=45556 done
[2022-07-04T09:11:46.535] _slurm_rpc_kill_job: REQUEST_KILL_JOB JobId=45553 uid 548200017
[2022-07-04T09:11:46.535] _slurm_rpc_kill_job: REQUEST_KILL_JOB JobId=45552 uid 548200017
[2022-07-04T09:11:49.295] _slurm_rpc_submit_batch_job: JobId=45557 InitPrio=19468 usec=442
[2022-07-04T09:11:49.430] sched: Allocate JobId=45557 NodeList=cpu13 #CPUs=32 Partition=cpu-epyc
[2022-07-04T09:12:55.649] _slurm_rpc_submit_batch_job: JobId=45558 InitPrio=19331 usec=463
[2022-07-04T09:14:55.250] _slurm_rpc_kill_job: REQUEST_KILL_JOB JobId=45549 uid 548200017
[2022-07-04T09:14:58.248] _slurm_rpc_submit_batch_job: JobId=45559 InitPrio=19194 usec=406
[2022-07-04T09:14:58.834] sched: Allocate JobId=45559 NodeList=cpu03 #CPUs=64 Partition=cpu-opteron
[2022-07-04T10:11:23.307] _slurm_rpc_submit_batch_job: JobId=45560 InitPrio=19463 usec=442
[2022-07-04T10:11:23.455] sched: Allocate JobId=45560 NodeList=cpu07 #CPUs=64 Partition=cpu-opteron
[2022-07-04T11:03:07.583] _slurm_rpc_submit_batch_job: JobId=45561 InitPrio=19737 usec=429
[2022-07-04T11:03:08.132] sched: Allocate JobId=45561 NodeList=cpu04 #CPUs=32 Partition=cpu-opteron
[2022-07-04T11:03:30.952] _job_complete: JobId=45561 WEXITSTATUS 1
[2022-07-04T11:03:30.952] _job_complete: JobId=45561 done
[2022-07-04T11:08:58.914] sched: _slurm_rpc_allocate_resources JobId=45562 NodeList=(null) usec=768
[2022-07-04T11:09:01.741] sched: Allocate JobId=45562 NodeList=cpu11 #CPUs=1 Partition=cpu-opteron
[2022-07-04T11:12:14.459] _slurm_rpc_submit_batch_job: JobId=45563 InitPrio=19737 usec=393
[2022-07-04T11:12:15.010] sched: Allocate JobId=45563 NodeList=cpu04 #CPUs=32 Partition=cpu-opteron
[2022-07-04T11:12:38.207] _job_complete: JobId=45563 WEXITSTATUS 1
[2022-07-04T11:12:38.207] _job_complete: JobId=45563 done
[2022-07-04T11:18:03.606] _slurm_rpc_submit_batch_job: JobId=45564 InitPrio=21756 usec=499
[2022-07-04T11:18:03.736] sched: Allocate JobId=45564 NodeList=cpu04 #CPUs=16 Partition=cpu-opteron
[2022-07-04T11:26:46.000] _job_complete: JobId=45564 WEXITSTATUS 0
[2022-07-04T11:26:46.001] _job_complete: JobId=45564 done
[2022-07-04T11:31:51.619] _slurm_rpc_submit_batch_job: JobId=45565 InitPrio=19737 usec=586
[2022-07-04T11:32:08.777] _job_complete: JobId=45562 WEXITSTATUS 0
[2022-07-04T11:32:08.777] _job_complete: JobId=45562 done
[2022-07-04T11:32:29.601] _slurm_rpc_submit_batch_job: JobId=45566 InitPrio=19737 usec=617
[2022-07-04T11:32:30.206] sched: Allocate JobId=45566 NodeList=cpu04 #CPUs=32 Partition=cpu-opteron
[2022-07-04T11:32:49.870] _slurm_rpc_kill_job: REQUEST_KILL_JOB JobId=45565 uid 548200021
[2022-07-04T11:33:08.066] _slurm_rpc_submit_batch_job: JobId=45567 InitPrio=21619 usec=448
[2022-07-04T11:34:18.239] _slurm_rpc_kill_job: REQUEST_KILL_JOB JobId=45567 uid 548200029
[2022-07-04T11:35:21.612] _slurm_rpc_submit_batch_job: JobId=45568 InitPrio=21619 usec=477
[2022-07-04T11:35:34.834] _slurm_rpc_kill_job: REQUEST_KILL_JOB JobId=45568 uid 548200029
[2022-07-04T11:48:43.003] _slurm_rpc_submit_batch_job: JobId=45569 InitPrio=21619 usec=388
[2022-07-04T11:50:37.526] _slurm_rpc_submit_batch_job: JobId=45570 InitPrio=21619 usec=355
[2022-07-04T11:51:42.062] _slurm_rpc_submit_batch_job: JobId=45571 InitPrio=21619 usec=396
[2022-07-04T11:54:36.698] _slurm_rpc_submit_batch_job: JobId=45572 InitPrio=21619 usec=429
[2022-07-04T11:58:33.458] _slurm_rpc_submit_batch_job: JobId=45573 InitPrio=21619 usec=454
[2022-07-04T12:00:16.603] _slurm_rpc_submit_batch_job: JobId=45574 InitPrio=21619 usec=404
[2022-07-04T12:13:04.147] _slurm_rpc_submit_batch_job: JobId=45575 InitPrio=25920 usec=479
[2022-07-04T14:15:36.174] _slurm_rpc_submit_batch_job: JobId=45576 InitPrio=20680 usec=549
[2022-07-04T14:15:36.608] sched: Allocate JobId=45576 NodeList=cpu11 #CPUs=16 Partition=cpu-opteron
[2022-07-04T14:15:39.971] _job_complete: JobId=45576 WEXITSTATUS 1
[2022-07-04T14:15:39.971] _job_complete: JobId=45576 done
[2022-07-04T14:16:19.273] _slurm_rpc_submit_batch_job: JobId=45577 InitPrio=20680 usec=556
[2022-07-04T14:16:19.654] sched: Allocate JobId=45577 NodeList=cpu11 #CPUs=16 Partition=cpu-opteron
[2022-07-04T16:07:01.169] _job_complete: JobId=45566 WEXITSTATUS 0
[2022-07-04T16:07:01.169] _job_complete: JobId=45566 done
[2022-07-04T16:07:01.589] sched: Allocate JobId=45575 NodeList=cpu04 #CPUs=32 Partition=cpu-opteron
[2022-07-04T16:09:24.545] _job_complete: JobId=45575 WEXITSTATUS 0
[2022-07-04T16:09:24.545] _job_complete: JobId=45575 done
[2022-07-04T16:09:25.084] sched: Allocate JobId=45569 NodeList=cpu04 #CPUs=32 Partition=cpu-opteron
[2022-07-04T16:09:32.065] _job_complete: JobId=45569 WEXITSTATUS 1
[2022-07-04T16:09:32.066] _job_complete: JobId=45569 done
[2022-07-04T16:09:32.539] sched: Allocate JobId=45570 NodeList=cpu04 #CPUs=32 Partition=cpu-opteron
[2022-07-04T16:09:34.281] _job_complete: JobId=45570 WEXITSTATUS 1
[2022-07-04T16:09:34.281] _job_complete: JobId=45570 done
[2022-07-04T16:09:34.681] sched: Allocate JobId=45571 NodeList=cpu04 #CPUs=32 Partition=cpu-opteron
[2022-07-04T16:09:36.859] _job_complete: JobId=45571 WEXITSTATUS 1
[2022-07-04T16:09:36.860] _job_complete: JobId=45571 done
[2022-07-04T16:09:37.237] sched: Allocate JobId=45572 NodeList=cpu04 #CPUs=32 Partition=cpu-opteron
[2022-07-04T16:09:39.660] _job_complete: JobId=45572 WEXITSTATUS 1
[2022-07-04T16:09:39.661] _job_complete: JobId=45572 done
[2022-07-04T16:09:40.065] sched: Allocate JobId=45573 NodeList=cpu04 #CPUs=32 Partition=cpu-opteron
[2022-07-04T16:09:42.292] _job_complete: JobId=45573 WEXITSTATUS 1
[2022-07-04T16:09:42.292] _job_complete: JobId=45573 done
[2022-07-04T16:09:42.673] sched: Allocate JobId=45574 NodeList=cpu04 #CPUs=32 Partition=cpu-opteron
[2022-07-04T16:09:44.746] _job_complete: JobId=45574 WEXITSTATUS 1
[2022-07-04T16:09:44.747] _job_complete: JobId=45574 done
[2022-07-04T16:23:37.980] _job_complete: JobId=45551 WEXITSTATUS 0
[2022-07-04T16:23:37.985] _job_complete: JobId=45551 done
[2022-07-04T16:23:39.840] sched: Allocate JobId=45554 NodeList=cpu15 #CPUs=36 Partition=cpu-epyc
[2022-07-04T18:36:57.075] _slurm_rpc_submit_batch_job: JobId=45578 InitPrio=25920 usec=430
[2022-07-04T18:36:57.771] sched: Allocate JobId=45578 NodeList=cpu04 #CPUs=32 Partition=cpu-opteron
[2022-07-04T18:43:23.934] _job_complete: JobId=45578 WEXITSTATUS 0
[2022-07-04T18:43:23.935] _job_complete: JobId=45578 done
[2022-07-04T18:51:11.681] _slurm_rpc_submit_batch_job: JobId=45579 InitPrio=22694 usec=449
[2022-07-04T18:51:12.352] sched: Allocate JobId=45579 NodeList=cpu04 #CPUs=32 Partition=cpu-opteron
[2022-07-04T19:18:52.440] _slurm_rpc_submit_batch_job: JobId=45580 InitPrio=22899 usec=525
[2022-07-04T19:21:08.558] _slurm_rpc_submit_batch_job: JobId=45581 InitPrio=22899 usec=371
[2022-07-04T19:23:38.210] _slurm_rpc_submit_batch_job: JobId=45582 InitPrio=22899 usec=405
[2022-07-04T19:26:00.081] _slurm_rpc_submit_batch_job: JobId=45583 InitPrio=22899 usec=575
[2022-07-04T19:27:38.001] _slurm_rpc_submit_batch_job: JobId=45584 InitPrio=22899 usec=534
[2022-07-04T19:29:10.537] _slurm_rpc_submit_batch_job: JobId=45585 InitPrio=22899 usec=445
[2022-07-04T19:31:00.125] _slurm_rpc_submit_batch_job: JobId=45586 InitPrio=22899 usec=512
[2022-07-04T19:32:28.578] _slurm_rpc_submit_batch_job: JobId=45587 InitPrio=22899 usec=423
[2022-07-04T19:33:46.227] _slurm_rpc_submit_batch_job: JobId=45588 InitPrio=22899 usec=474
[2022-07-04T19:35:25.681] _slurm_rpc_submit_batch_job: JobId=45589 InitPrio=22899 usec=436
[2022-07-04T19:42:28.807] _slurm_rpc_submit_batch_job: JobId=45590 InitPrio=22899 usec=517
[2022-07-04T19:44:15.738] _slurm_rpc_submit_batch_job: JobId=45591 InitPrio=22899 usec=511
[2022-07-04T19:46:01.213] _slurm_rpc_submit_batch_job: JobId=45592 InitPrio=22899 usec=456
[2022-07-04T19:48:56.259] _slurm_rpc_submit_batch_job: JobId=45593 InitPrio=22899 usec=426
[2022-07-04T19:50:45.055] _slurm_rpc_submit_batch_job: JobId=45594 InitPrio=22899 usec=546
[2022-07-04T19:53:21.965] _slurm_rpc_submit_batch_job: JobId=45595 InitPrio=22899 usec=465
[2022-07-04T19:54:58.710] _slurm_rpc_submit_batch_job: JobId=45596 InitPrio=22899 usec=622
[2022-07-04T19:56:32.727] _slurm_rpc_submit_batch_job: JobId=45597 InitPrio=22899 usec=463
[2022-07-04T19:58:10.447] _slurm_rpc_submit_batch_job: JobId=45598 InitPrio=22899 usec=542
[2022-07-04T19:59:33.510] _slurm_rpc_submit_batch_job: JobId=45599 InitPrio=22899 usec=428
[2022-07-04T20:01:43.674] _slurm_rpc_submit_batch_job: JobId=45600 InitPrio=22899 usec=520
[2022-07-04T20:14:35.312] _slurm_rpc_submit_batch_job: JobId=45601 InitPrio=25920 usec=451
[2022-07-04T20:18:57.857] _slurm_rpc_kill_job: REQUEST_KILL_JOB JobId=45601 uid 548200084
[2022-07-04T20:19:25.686] _slurm_rpc_submit_batch_job: JobId=45602 InitPrio=26091 usec=488
[2022-07-04T20:19:25.811] sched: Allocate JobId=45602 NodeList=cpu15 #CPUs=12 Partition=cpu-epyc
[2022-07-04T20:21:03.032] _job_complete: JobId=45602 WEXITSTATUS 0
[2022-07-04T20:21:03.032] _job_complete: JobId=45602 done
[2022-07-04T20:21:48.433] _slurm_rpc_submit_batch_job: JobId=45603 InitPrio=26091 usec=393
[2022-07-04T20:21:48.997] sched: Allocate JobId=45603 NodeList=cpu15 #CPUs=12 Partition=cpu-epyc
[2022-07-04T20:24:34.246] _job_complete: JobId=45603 WEXITSTATUS 0
[2022-07-04T20:24:34.246] _job_complete: JobId=45603 done
[2022-07-04T20:49:22.108] _slurm_rpc_submit_batch_job: JobId=45604 InitPrio=26091 usec=485
[2022-07-04T20:49:22.986] sched: Allocate JobId=45604 NodeList=cpu15 #CPUs=12 Partition=cpu-epyc
[2022-07-04T20:51:59.125] _job_complete: JobId=45604 WEXITSTATUS 0
[2022-07-04T20:51:59.126] _job_complete: JobId=45604 done
[2022-07-04T21:11:36.191] _job_complete: JobId=45416 WEXITSTATUS 0
[2022-07-04T21:11:36.191] _job_complete: JobId=45416 done
[2022-07-04T21:11:36.607] sched: Allocate JobId=45580 NodeList=cpu10 #CPUs=8 Partition=cpu-opteron
[2022-07-04T21:11:36.608] sched: Allocate JobId=45581 NodeList=cpu10 #CPUs=8 Partition=cpu-opteron
[2022-07-04T21:24:13.180] _slurm_rpc_submit_batch_job: JobId=45605 InitPrio=26091 usec=416
[2022-07-04T21:24:14.155] sched: Allocate JobId=45605 NodeList=cpu15 #CPUs=12 Partition=cpu-epyc
[2022-07-04T21:24:17.901] _job_complete: JobId=45605 WEXITSTATUS 1
[2022-07-04T21:24:17.901] _job_complete: JobId=45605 done
[2022-07-04T21:28:18.717] _slurm_rpc_submit_batch_job: JobId=45606 InitPrio=19908 usec=388
[2022-07-04T21:28:19.620] sched: Allocate JobId=45606 NodeList=cpu15 #CPUs=12 Partition=cpu-epyc
[2022-07-04T21:31:37.765] _slurm_rpc_kill_job: REQUEST_KILL_JOB JobId=45606 uid 548200021
[2022-07-04T21:33:08.708] _slurm_rpc_submit_batch_job: JobId=45607 InitPrio=21052 usec=377
[2022-07-04T21:33:09.101] sched: Allocate JobId=45607 NodeList=cpu10 #CPUs=4 Partition=cpu-opteron
[2022-07-04T21:33:10.573] _job_complete: JobId=45607 WEXITSTATUS 0
[2022-07-04T21:33:10.574] _job_complete: JobId=45607 done
[2022-07-04T21:36:11.526] _slurm_rpc_submit_batch_job: JobId=45608 InitPrio=20949 usec=760
[2022-07-04T21:36:12.346] sched: Allocate JobId=45608 NodeList=cpu10 #CPUs=16 Partition=cpu-opteron
[2022-07-04T21:36:13.729] _slurm_rpc_submit_batch_job: JobId=45609 InitPrio=19908 usec=405
[2022-07-04T21:36:15.351] sched: Allocate JobId=45609 NodeList=cpu15 #CPUs=12 Partition=cpu-epyc
[2022-07-04T21:36:24.933] _job_complete: JobId=45608 WEXITSTATUS 0
[2022-07-04T21:36:24.934] _job_complete: JobId=45608 done
[2022-07-04T21:37:06.990] _slurm_rpc_submit_batch_job: JobId=45610 InitPrio=21078 usec=589
[2022-07-04T21:37:07.424] sched: Allocate JobId=45610 NodeList=gpu05 #CPUs=1 Partition=gpu-v100s
[2022-07-04T21:37:20.121] _job_complete: JobId=45610 WEXITSTATUS 0
[2022-07-04T21:37:20.121] _job_complete: JobId=45610 done
[2022-07-04T21:37:40.775] _slurm_rpc_submit_batch_job: JobId=45611 InitPrio=21052 usec=447
[2022-07-04T21:37:41.584] sched: Allocate JobId=45611 NodeList=cpu10 #CPUs=4 Partition=cpu-opteron
[2022-07-04T21:37:42.999] _job_complete: JobId=45611 WEXITSTATUS 0
[2022-07-04T21:37:42.999] _job_complete: JobId=45611 done
[2022-07-04T21:40:41.231] _slurm_rpc_submit_batch_job: JobId=45612 InitPrio=20949 usec=469
[2022-07-04T21:40:41.843] sched: Allocate JobId=45612 NodeList=cpu10 #CPUs=16 Partition=cpu-opteron
[2022-07-04T21:40:54.087] _job_complete: JobId=45612 WEXITSTATUS 0
[2022-07-04T21:40:54.088] _job_complete: JobId=45612 done
[2022-07-04T21:45:06.454] _slurm_rpc_submit_batch_job: JobId=45613 InitPrio=20230 usec=477
[2022-07-04T21:45:47.889] _slurm_rpc_kill_job: REQUEST_KILL_JOB JobId=45613 uid 548200023
[2022-07-04T21:46:24.909] _slurm_rpc_submit_batch_job: JobId=45614 InitPrio=20401 usec=467
[2022-07-04T21:47:12.247] _slurm_rpc_kill_job: REQUEST_KILL_JOB JobId=45614 uid 548200023
[2022-07-04T21:47:39.818] _slurm_rpc_submit_batch_job: JobId=45615 InitPrio=20812 usec=650
[2022-07-04T21:47:57.566] _slurm_rpc_kill_job: REQUEST_KILL_JOB JobId=45615 uid 548200023
[2022-07-04T21:48:10.770] _slurm_rpc_submit_batch_job: JobId=45616 InitPrio=20949 usec=529
[2022-07-04T21:48:11.726] sched: Allocate JobId=45616 NodeList=gpu05 #CPUs=16 Partition=gpu-v100s
[2022-07-04T21:48:52.464] _slurm_rpc_submit_batch_job: JobId=45617 InitPrio=21018 usec=405
[2022-07-04T21:48:52.781] sched: Allocate JobId=45617 NodeList=cpu10 #CPUs=8 Partition=cpu-opteron
[2022-07-04T21:49:24.720] _job_complete: JobId=45617 WEXITSTATUS 0
[2022-07-04T21:49:24.720] _job_complete: JobId=45617 done
[2022-07-04T21:49:59.273] _job_complete: JobId=45616 WEXITSTATUS 0
[2022-07-04T21:49:59.273] _job_complete: JobId=45616 done
[2022-07-04T21:50:45.797] _slurm_rpc_submit_batch_job: JobId=45618 InitPrio=21078 usec=446
[2022-07-04T21:50:45.937] sched: Allocate JobId=45618 NodeList=gpu05 #CPUs=1 Partition=gpu-v100s
[2022-07-04T21:50:57.942] _job_complete: JobId=45618 WEXITSTATUS 0
[2022-07-04T21:50:57.942] _job_complete: JobId=45618 done
[2022-07-04T21:51:12.199] _slurm_rpc_submit_batch_job: JobId=45619 InitPrio=21052 usec=442
[2022-07-04T21:51:12.977] sched: Allocate JobId=45619 NodeList=cpu10 #CPUs=4 Partition=cpu-opteron
[2022-07-04T21:51:14.270] _job_complete: JobId=45619 WEXITSTATUS 0
[2022-07-04T21:51:14.270] _job_complete: JobId=45619 done
[2022-07-04T21:52:12.078] _slurm_rpc_submit_batch_job: JobId=45620 InitPrio=20949 usec=506
[2022-07-04T21:52:13.061] sched: Allocate JobId=45620 NodeList=cpu10 #CPUs=16 Partition=cpu-opteron
[2022-07-04T21:52:25.581] _job_complete: JobId=45620 WEXITSTATUS 0
[2022-07-04T21:52:25.581] _job_complete: JobId=45620 done
[2022-07-04T21:53:25.343] _slurm_rpc_submit_batch_job: JobId=45621 InitPrio=20949 usec=489
[2022-07-04T21:53:26.240] sched: Allocate JobId=45621 NodeList=gpu05 #CPUs=16 Partition=gpu-v100s
[2022-07-04T21:55:13.120] _slurm_rpc_submit_batch_job: JobId=45622 InitPrio=21078 usec=529
[2022-07-04T21:55:13.392] sched: Allocate JobId=45622 NodeList=gpu02 #CPUs=1 Partition=gpu-titan
[2022-07-04T21:55:15.283] _job_complete: JobId=45621 WEXITSTATUS 0
[2022-07-04T21:55:15.283] _job_complete: JobId=45621 done
[2022-07-04T21:55:32.594] _job_complete: JobId=45622 WEXITSTATUS 0
[2022-07-04T21:55:32.594] _job_complete: JobId=45622 done
[2022-07-04T21:55:57.995] _slurm_rpc_submit_batch_job: JobId=45623 InitPrio=21052 usec=411
[2022-07-04T21:55:58.455] sched: Allocate JobId=45623 NodeList=cpu10 #CPUs=4 Partition=cpu-opteron
[2022-07-04T21:55:59.733] _job_complete: JobId=45623 WEXITSTATUS 0
[2022-07-04T21:55:59.733] _job_complete: JobId=45623 done
[2022-07-04T21:56:46.497] _slurm_rpc_submit_batch_job: JobId=45624 InitPrio=20949 usec=459
[2022-07-04T21:56:46.522] sched: Allocate JobId=45624 NodeList=cpu10 #CPUs=16 Partition=cpu-opteron
[2022-07-04T21:56:58.990] _job_complete: JobId=45624 WEXITSTATUS 0
[2022-07-04T21:56:58.991] _job_complete: JobId=45624 done
[2022-07-04T21:57:17.596] _slurm_rpc_submit_batch_job: JobId=45625 InitPrio=20949 usec=544
[2022-07-04T21:57:18.567] sched: Allocate JobId=45625 NodeList=gpu05 #CPUs=16 Partition=gpu-v100s
[2022-07-04T22:13:28.992] _job_complete: JobId=45415 WEXITSTATUS 0
[2022-07-04T22:13:28.992] _job_complete: JobId=45415 done
[2022-07-04T22:13:29.507] sched: Allocate JobId=45582 NodeList=cpu10 #CPUs=8 Partition=cpu-opteron
[2022-07-04T22:13:29.507] sched: Allocate JobId=45583 NodeList=cpu10 #CPUs=8 Partition=cpu-opteron
[2022-07-04T22:23:37.472] _get_job_parts: invalid partition specified: cpu-opterom
[2022-07-04T22:23:37.472] _slurm_rpc_submit_batch_job: Invalid partition name specified
[2022-07-04T22:23:52.843] _slurm_rpc_submit_batch_job: JobId=45626 InitPrio=26057 usec=665
[2022-07-04T22:23:53.453] sched: Allocate JobId=45626 NodeList=cpu10 #CPUs=16 Partition=cpu-opteron
[2022-07-04T22:23:55.751] _job_complete: JobId=45626 WEXITSTATUS 1
[2022-07-04T22:23:55.751] _job_complete: JobId=45626 done
[2022-07-04T22:25:59.075] _slurm_rpc_submit_batch_job: JobId=45627 InitPrio=26057 usec=415
[2022-07-04T22:26:01.621] sched: Allocate JobId=45627 NodeList=cpu10 #CPUs=16 Partition=cpu-opteron
[2022-07-04T22:26:06.331] _job_complete: JobId=45627 WEXITSTATUS 1
[2022-07-04T22:26:06.331] _job_complete: JobId=45627 done
[2022-07-04T23:20:26.386] _slurm_rpc_submit_batch_job: JobId=45628 InitPrio=20675 usec=511
[2022-07-04T23:21:03.200] _slurm_rpc_submit_batch_job: JobId=45629 InitPrio=20675 usec=457
[2022-07-04T23:29:48.841] _job_complete: JobId=45609 WEXITSTATUS 0
[2022-07-04T23:29:48.842] _job_complete: JobId=45609 done
[2022-07-04T23:45:11.684] _job_complete: JobId=45528 WEXITSTATUS 0
[2022-07-04T23:45:11.689] _job_complete: JobId=45528 done
[2022-07-05T00:44:33.958] sched: _slurm_rpc_allocate_resources JobId=45630 NodeList=(null) usec=1150
[2022-07-05T00:45:18.451] _job_complete: JobId=45630 WTERMSIG 126
[2022-07-05T00:45:18.452] _job_complete: JobId=45630 cancelled by interactive user
[2022-07-05T00:45:18.452] _job_complete: JobId=45630 done
[2022-07-05T00:45:31.586] sched: _slurm_rpc_allocate_resources JobId=45631 NodeList=(null) usec=1140
[2022-07-05T00:45:32.197] sched: Allocate JobId=45631 NodeList=cpu15 #CPUs=12 Partition=cpu-epyc
[2022-07-05T01:01:01.284] _job_complete: JobId=45631 WEXITSTATUS 0
[2022-07-05T01:01:01.284] _job_complete: JobId=45631 done
[2022-07-05T01:29:42.881] _job_complete: JobId=45579 WEXITSTATUS 1
[2022-07-05T01:29:42.881] _job_complete: JobId=45579 done
[2022-07-05T01:29:44.991] sched: Allocate JobId=45584 NodeList=cpu04 #CPUs=8 Partition=cpu-opteron
[2022-07-05T01:29:44.991] sched: Allocate JobId=45585 NodeList=cpu04 #CPUs=8 Partition=cpu-opteron
[2022-07-05T01:29:44.992] sched: Allocate JobId=45586 NodeList=cpu04 #CPUs=8 Partition=cpu-opteron
[2022-07-05T01:40:44.755] _slurm_rpc_submit_batch_job: JobId=45632 InitPrio=22059 usec=518
[2022-07-05T01:40:45.690] sched: Allocate JobId=45632 NodeList=cpu15 #CPUs=12 Partition=cpu-epyc
[2022-07-05T01:40:55.186] _job_complete: JobId=45632 WEXITSTATUS 1
[2022-07-05T01:40:55.186] _job_complete: JobId=45632 done
[2022-07-05T02:14:51.989] _job_complete: JobId=45581 WEXITSTATUS 0
[2022-07-05T02:14:51.989] _job_complete: JobId=45581 done
[2022-07-05T02:14:52.516] sched: Allocate JobId=45587 NodeList=cpu10 #CPUs=8 Partition=cpu-opteron
[2022-07-05T02:30:51.778] _job_complete: JobId=45580 WEXITSTATUS 0
[2022-07-05T02:30:51.778] _job_complete: JobId=45580 done
[2022-07-05T02:30:52.192] sched: Allocate JobId=45588 NodeList=cpu10 #CPUs=8 Partition=cpu-opteron
[2022-07-05T02:50:07.855] _job_complete: JobId=45583 WEXITSTATUS 0
[2022-07-05T02:50:07.855] _job_complete: JobId=45583 done
[2022-07-05T02:50:08.269] sched: Allocate JobId=45589 NodeList=cpu10 #CPUs=8 Partition=cpu-opteron
[2022-07-05T03:17:41.354] _slurm_rpc_submit_batch_job: JobId=45633 InitPrio=22059 usec=466
[2022-07-05T03:17:41.922] sched: Allocate JobId=45633 NodeList=cpu15 #CPUs=12 Partition=cpu-epyc
[2022-07-05T03:17:50.526] _job_complete: JobId=45633 WEXITSTATUS 1
[2022-07-05T03:17:50.526] _job_complete: JobId=45633 done
[2022-07-05T03:19:33.126] _job_complete: JobId=45582 WEXITSTATUS 0
[2022-07-05T03:19:33.127] _job_complete: JobId=45582 done
[2022-07-05T03:19:33.656] sched: Allocate JobId=45590 NodeList=cpu10 #CPUs=8 Partition=cpu-opteron
[2022-07-05T03:27:38.015] _slurm_rpc_submit_batch_job: JobId=45634 InitPrio=22059 usec=462
[2022-07-05T03:27:38.931] sched: Allocate JobId=45634 NodeList=cpu15 #CPUs=12 Partition=cpu-epyc
[2022-07-05T03:32:52.652] _slurm_rpc_submit_batch_job: JobId=45635 InitPrio=21887 usec=512
[2022-07-05T03:32:53.539] sched: Allocate JobId=45635 NodeList=cpu10 #CPUs=32 Partition=cpu-opteron
[2022-07-05T03:33:11.509] _job_complete: JobId=45635 WEXITSTATUS 1
[2022-07-05T03:33:11.509] _job_complete: JobId=45635 done
[2022-07-05T03:34:55.558] _slurm_rpc_submit_batch_job: JobId=45636 InitPrio=21887 usec=509
[2022-07-05T03:34:55.711] sched: Allocate JobId=45636 NodeList=cpu10 #CPUs=32 Partition=cpu-opteron
[2022-07-05T03:37:25.522] _get_job_parts: invalid partition specified: cpu-epcy
[2022-07-05T03:37:25.522] _slurm_rpc_submit_batch_job: Invalid partition name specified
[2022-07-05T03:37:41.269] _slurm_rpc_submit_batch_job: JobId=45637 InitPrio=21750 usec=458
[2022-07-05T03:47:37.860] _slurm_rpc_submit_batch_job: JobId=45638 InitPrio=21750 usec=493
[2022-07-05T03:50:02.912] _slurm_rpc_submit_batch_job: JobId=45639 InitPrio=21750 usec=563
[2022-07-05T04:14:05.704] _job_complete: JobId=45636 WEXITSTATUS 0
[2022-07-05T04:14:05.704] _job_complete: JobId=45636 done
[2022-07-05T04:24:23.570] _job_complete: JobId=45634 WEXITSTATUS 0
[2022-07-05T04:24:23.570] _job_complete: JobId=45634 done
[2022-07-05T05:32:44.365] _job_complete: JobId=45586 WEXITSTATUS 0
[2022-07-05T05:32:44.365] _job_complete: JobId=45586 done
[2022-07-05T05:32:44.885] sched: Allocate JobId=45591 NodeList=cpu04 #CPUs=8 Partition=cpu-opteron
[2022-07-05T05:37:22.578] _job_complete: JobId=45585 WEXITSTATUS 0
[2022-07-05T05:37:22.578] _job_complete: JobId=45585 done
[2022-07-05T05:37:23.081] sched: Allocate JobId=45592 NodeList=cpu04 #CPUs=8 Partition=cpu-opteron
[2022-07-05T05:38:51.692] _job_complete: JobId=45584 WEXITSTATUS 0
[2022-07-05T05:38:51.692] _job_complete: JobId=45584 done
[2022-07-05T05:38:52.207] sched: Allocate JobId=45593 NodeList=cpu04 #CPUs=8 Partition=cpu-opteron
[2022-07-05T06:19:03.704] _job_complete: JobId=45587 WEXITSTATUS 0
[2022-07-05T06:19:03.704] _job_complete: JobId=45587 done
[2022-07-05T06:19:04.104] sched: Allocate JobId=45594 NodeList=cpu10 #CPUs=8 Partition=cpu-opteron
[2022-07-05T06:21:56.665] _job_complete: JobId=45589 WEXITSTATUS 0
[2022-07-05T06:21:56.665] _job_complete: JobId=45589 done
[2022-07-05T06:21:57.047] sched: Allocate JobId=45595 NodeList=cpu10 #CPUs=8 Partition=cpu-opteron
[2022-07-05T06:24:11.562] _job_complete: JobId=45588 WEXITSTATUS 0
[2022-07-05T06:24:11.563] _job_complete: JobId=45588 done
[2022-07-05T06:24:11.952] sched: Allocate JobId=45596 NodeList=cpu10 #CPUs=8 Partition=cpu-opteron
[2022-07-05T07:44:48.604] _slurm_rpc_submit_batch_job: JobId=45640 InitPrio=26057 usec=484
[2022-07-05T07:44:48.739] sched: Allocate JobId=45640 NodeList=cpu10 #CPUs=16 Partition=cpu-opteron
[2022-07-05T07:44:52.519] _job_complete: JobId=45640 WEXITSTATUS 1
[2022-07-05T07:44:52.519] _job_complete: JobId=45640 done
[2022-07-05T07:59:30.447] _slurm_rpc_submit_batch_job: JobId=45641 InitPrio=26091 usec=465
[2022-07-05T07:59:31.409] sched: Allocate JobId=45641 NodeList=cpu15 #CPUs=12 Partition=cpu-epyc
[2022-07-05T07:59:35.907] _job_complete: JobId=45641 WEXITSTATUS 1
[2022-07-05T07:59:35.907] _job_complete: JobId=45641 done
[2022-07-05T08:11:36.012] _slurm_rpc_submit_batch_job: JobId=45642 InitPrio=26091 usec=430
[2022-07-05T08:11:36.708] sched: Allocate JobId=45642 NodeList=cpu10 #CPUs=12 Partition=cpu-opteron
[2022-07-05T08:18:54.595] _job_complete: JobId=45642 WEXITSTATUS 0
[2022-07-05T08:18:54.596] _job_complete: JobId=45642 done
[2022-07-05T08:34:18.583] _slurm_rpc_submit_batch_job: JobId=45643 InitPrio=26091 usec=407
[2022-07-05T08:34:19.369] sched: Allocate JobId=45643 NodeList=cpu15 #CPUs=12 Partition=cpu-epyc
[2022-07-05T08:34:22.515] _job_complete: JobId=45643 WEXITSTATUS 1
[2022-07-05T08:34:22.516] _job_complete: JobId=45643 done
[2022-07-05T08:42:15.689] _job_complete: JobId=45590 WEXITSTATUS 0
[2022-07-05T08:42:15.689] _job_complete: JobId=45590 done
[2022-07-05T08:42:16.108] sched: Allocate JobId=45597 NodeList=cpu10 #CPUs=8 Partition=cpu-opteron
[2022-07-05T08:52:40.252] _slurm_rpc_submit_batch_job: JobId=45644 InitPrio=26091 usec=448
[2022-07-05T08:52:57.870] _slurm_rpc_kill_job: REQUEST_KILL_JOB JobId=456444 uid 548200084
[2022-07-05T08:52:57.870] job_str_signal(3): invalid JobId=456444
[2022-07-05T08:52:57.870] _slurm_rpc_kill_job: job_str_signal() uid=548200084 JobId=456444 sig=9 returned: Invalid job id specified
[2022-07-05T08:53:10.135] _slurm_rpc_submit_batch_job: JobId=45645 InitPrio=26091 usec=436
[2022-07-05T08:53:10.646] sched: Allocate JobId=45645 NodeList=cpu15 #CPUs=12 Partition=cpu-epyc
[2022-07-05T08:53:14.118] _job_complete: JobId=45645 WEXITSTATUS 1
[2022-07-05T08:53:14.118] _job_complete: JobId=45645 done
[2022-07-05T09:06:29.560] _slurm_rpc_submit_batch_job: JobId=45646 InitPrio=26091 usec=390
[2022-07-05T09:06:30.141] sched: Allocate JobId=45646 NodeList=cpu15 #CPUs=12 Partition=cpu-epyc
[2022-07-05T09:06:33.807] _job_complete: JobId=45646 WEXITSTATUS 1
[2022-07-05T09:06:33.807] _job_complete: JobId=45646 done
[2022-07-05T09:09:34.670] _slurm_rpc_kill_job: REQUEST_KILL_JOB JobId=45644 uid 548200084
[2022-07-05T09:14:33.320] _slurm_rpc_submit_batch_job: JobId=45647 InitPrio=26057 usec=424
[2022-07-05T09:14:34.230] sched: Allocate JobId=45647 NodeList=cpu10 #CPUs=16 Partition=cpu-opteron
[2022-07-05T09:24:22.275] _job_complete: JobId=45647 WEXITSTATUS 0
[2022-07-05T09:24:22.275] _job_complete: JobId=45647 done
[2022-07-05T10:12:32.984] _job_complete: JobId=45591 WEXITSTATUS 0
[2022-07-05T10:12:32.984] _job_complete: JobId=45591 done
[2022-07-05T10:12:33.446] sched: Allocate JobId=45598 NodeList=cpu04 #CPUs=8 Partition=cpu-opteron
[2022-07-05T10:13:56.882] _job_complete: JobId=45596 WEXITSTATUS 0
[2022-07-05T10:13:56.882] _job_complete: JobId=45596 done
[2022-07-05T10:13:57.301] sched: Allocate JobId=45599 NodeList=cpu10 #CPUs=8 Partition=cpu-opteron
[2022-07-05T10:25:34.063] _job_complete: JobId=45595 WEXITSTATUS 0
[2022-07-05T10:25:34.064] _job_complete: JobId=45595 done
[2022-07-05T10:25:34.613] sched: Allocate JobId=45600 NodeList=cpu10 #CPUs=8 Partition=cpu-opteron
[2022-07-05T10:34:28.927] _job_complete: JobId=45592 WEXITSTATUS 0
[2022-07-05T10:34:28.927] _job_complete: JobId=45592 done
[2022-07-05T10:42:49.035] _job_complete: JobId=45594 WEXITSTATUS 0
[2022-07-05T10:42:49.035] _job_complete: JobId=45594 done
[2022-07-05T11:11:36.361] _job_complete: JobId=45593 WEXITSTATUS 0
[2022-07-05T11:11:36.361] _job_complete: JobId=45593 done
[2022-07-05T11:29:50.056] _slurm_rpc_submit_batch_job: JobId=45648 InitPrio=19908 usec=421
[2022-07-05T11:29:50.367] sched: Allocate JobId=45648 NodeList=cpu15 #CPUs=12 Partition=cpu-epyc
[2022-07-05T12:21:05.370] _slurm_rpc_submit_batch_job: JobId=45649 InitPrio=26022 usec=511
[2022-07-05T12:21:05.761] sched: Allocate JobId=45649 NodeList=cpu04 #CPUs=20 Partition=cpu-opteron
[2022-07-05T12:21:24.117] _job_complete: JobId=45649 WEXITSTATUS 0
[2022-07-05T12:21:24.117] _job_complete: JobId=45649 done
[2022-07-05T12:32:40.525] _job_complete: JobId=45597 WEXITSTATUS 0
[2022-07-05T12:32:40.525] _job_complete: JobId=45597 done
[2022-07-05T12:39:13.887] _slurm_rpc_kill_job: REQUEST_KILL_JOB JobId=45559 uid 548200017
[2022-07-05T12:39:17.066] _slurm_rpc_submit_batch_job: JobId=45650 InitPrio=19194 usec=370
[2022-07-05T12:39:17.750] sched: Allocate JobId=45650 NodeList=cpu03 #CPUs=64 Partition=cpu-opteron
[2022-07-05T12:40:49.755] _slurm_rpc_kill_job: REQUEST_KILL_JOB JobId=45650 uid 548200017
[2022-07-05T12:40:53.229] _slurm_rpc_submit_batch_job: JobId=45651 InitPrio=19194 usec=425
[2022-07-05T12:40:53.867] sched: Allocate JobId=45651 NodeList=cpu03 #CPUs=64 Partition=cpu-opteron
[2022-07-05T12:42:22.247] _slurm_rpc_kill_job: REQUEST_KILL_JOB JobId=45651 uid 548200017
[2022-07-05T12:42:25.104] _slurm_rpc_submit_batch_job: JobId=45652 InitPrio=19194 usec=356
[2022-07-05T12:42:25.992] sched: Allocate JobId=45652 NodeList=cpu03 #CPUs=64 Partition=cpu-opteron
[2022-07-05T13:16:52.853] _slurm_rpc_submit_batch_job: JobId=45653 InitPrio=25988 usec=500
[2022-07-05T13:16:53.740] sched: Allocate JobId=45653 NodeList=cpu04 #CPUs=24 Partition=cpu-opteron
[2022-07-05T13:16:58.378] _job_complete: JobId=45653 WEXITSTATUS 139
[2022-07-05T13:16:58.378] _job_complete: JobId=45653 done
[2022-07-05T13:31:36.803] _slurm_rpc_submit_batch_job: JobId=45654 InitPrio=25988 usec=504
[2022-07-05T13:31:37.328] sched: Allocate JobId=45654 NodeList=cpu04 #CPUs=24 Partition=cpu-opteron
[2022-07-05T13:31:41.235] _job_complete: JobId=45654 WEXITSTATUS 1
[2022-07-05T13:31:41.235] _job_complete: JobId=45654 done
[2022-07-05T13:43:21.749] _slurm_rpc_submit_batch_job: JobId=45655 InitPrio=25988 usec=537
[2022-07-05T13:43:22.679] sched: Allocate JobId=45655 NodeList=cpu04 #CPUs=24 Partition=cpu-opteron
[2022-07-05T13:43:27.644] _job_complete: JobId=45655 WEXITSTATUS 139
[2022-07-05T13:43:27.644] _job_complete: JobId=45655 done
[2022-07-05T13:46:03.696] _job_complete: JobId=45598 WEXITSTATUS 0
[2022-07-05T13:46:03.696] _job_complete: JobId=45598 done
[2022-07-05T13:56:32.592] _slurm_rpc_submit_batch_job: JobId=45656 InitPrio=25988 usec=486
[2022-07-05T13:56:33.195] sched: Allocate JobId=45656 NodeList=cpu04 #CPUs=24 Partition=cpu-opteron
[2022-07-05T13:56:38.802] _job_complete: JobId=45656 WEXITSTATUS 139
[2022-07-05T13:56:38.803] _job_complete: JobId=45656 done
[2022-07-05T14:16:37.532] Time limit exhausted for JobId=45577
[2022-07-05T14:24:14.833] _slurm_rpc_submit_batch_job: JobId=45657 InitPrio=25988 usec=465
[2022-07-05T14:24:15.374] sched: Allocate JobId=45657 NodeList=cpu04 #CPUs=24 Partition=cpu-opteron
[2022-07-05T14:24:18.887] _job_complete: JobId=45657 WEXITSTATUS 1
[2022-07-05T14:24:18.887] _job_complete: JobId=45657 done
[2022-07-05T15:00:58.042] _job_complete: JobId=45600 WEXITSTATUS 0
[2022-07-05T15:00:58.042] _job_complete: JobId=45600 done
[2022-07-05T15:08:46.057] _job_complete: JobId=45599 WEXITSTATUS 0
[2022-07-05T15:08:46.057] _job_complete: JobId=45599 done
[2022-07-05T15:16:01.031] _job_complete: JobId=45511 WEXITSTATUS 2
[2022-07-05T15:16:01.031] _job_complete: JobId=45511 done
[2022-07-05T15:20:12.368] _slurm_rpc_submit_batch_job: JobId=45658 InitPrio=19468 usec=402
[2022-07-05T15:20:13.195] sched: Allocate JobId=45658 NodeList=cpu04 #CPUs=32 Partition=cpu-opteron
[2022-07-05T15:20:15.675] _job_complete: JobId=45658 WEXITSTATUS 1
[2022-07-05T15:20:15.675] _job_complete: JobId=45658 done
[2022-07-05T15:25:08.957] _slurm_rpc_submit_batch_job: JobId=45659 InitPrio=19468 usec=368
[2022-07-05T15:25:09.943] sched: Allocate JobId=45659 NodeList=cpu04 #CPUs=32 Partition=cpu-opteron
[2022-07-05T15:26:57.673] _slurm_rpc_submit_batch_job: JobId=45660 InitPrio=19194 usec=407
[2022-07-05T15:26:58.093] sched: Allocate JobId=45660 NodeList=cpu01 #CPUs=64 Partition=cpu-opteron
[2022-07-05T15:27:08.103] _slurm_rpc_kill_job: REQUEST_KILL_JOB JobId=45558 uid 548200017
[2022-07-05T15:32:09.915] _slurm_rpc_submit_batch_job: JobId=45661 InitPrio=19874 usec=484
[2022-07-05T15:32:10.686] sched: Allocate JobId=45661 NodeList=gpu02 #CPUs=16 Partition=gpu-titan
[2022-07-05T15:32:25.696] _slurm_rpc_submit_batch_job: JobId=45662 InitPrio=28067 usec=357
[2022-07-05T15:32:26.710] sched: Allocate JobId=45662 NodeList=cpu11 #CPUs=1 Partition=cpu-opteron
[2022-07-05T15:34:35.063] _slurm_rpc_kill_job: REQUEST_KILL_JOB JobId=45662 uid 548200009
[2022-07-05T15:34:51.727] _slurm_rpc_submit_batch_job: JobId=45663 InitPrio=28067 usec=385
[2022-07-05T15:34:51.969] sched: Allocate JobId=45663 NodeList=cpu11 #CPUs=1 Partition=cpu-opteron
[2022-07-05T15:36:35.523] _job_complete: JobId=45659 WEXITSTATUS 0
[2022-07-05T15:36:35.524] _job_complete: JobId=45659 done
[2022-07-05T15:36:35.838] _slurm_rpc_kill_job: REQUEST_KILL_JOB JobId=45663 uid 548200009
[2022-07-05T15:36:50.977] sched: _slurm_rpc_allocate_resources JobId=45664 NodeList=(null) usec=840
[2022-07-05T15:36:51.126] sched: Allocate JobId=45664 NodeList=cpu04 #CPUs=1 Partition=cpu-opteron
[2022-07-05T15:41:18.524] _slurm_rpc_kill_job: REQUEST_KILL_JOB JobId=45664 uid 548200009
[2022-07-05T15:42:10.497] _slurm_rpc_submit_batch_job: JobId=45665 InitPrio=28067 usec=446
[2022-07-05T15:42:10.655] sched: Allocate JobId=45665 NodeList=cpu04 #CPUs=1 Partition=cpu-opteron
[2022-07-05T15:50:38.351] _slurm_rpc_kill_job: REQUEST_KILL_JOB JobId=45665 uid 548200009
[2022-07-05T16:06:36.413] _slurm_rpc_submit_batch_job: JobId=45666 InitPrio=19468 usec=374
[2022-07-05T16:06:36.545] sched: Allocate JobId=45666 NodeList=cpu04 #CPUs=32 Partition=cpu-opteron
[2022-07-05T16:06:40.061] _job_complete: JobId=45666 WEXITSTATUS 1
[2022-07-05T16:06:40.061] _job_complete: JobId=45666 done
[2022-07-05T16:06:48.235] _slurm_rpc_submit_batch_job: JobId=45667 InitPrio=19468 usec=368
[2022-07-05T16:06:48.558] sched: Allocate JobId=45667 NodeList=cpu04 #CPUs=32 Partition=cpu-opteron
[2022-07-05T16:06:50.642] _job_complete: JobId=45667 WEXITSTATUS 1
[2022-07-05T16:06:50.643] _job_complete: JobId=45667 done
[2022-07-05T16:07:39.083] _slurm_rpc_submit_batch_job: JobId=45668 InitPrio=19468 usec=362
[2022-07-05T16:07:39.763] sched: Allocate JobId=45668 NodeList=cpu04 #CPUs=32 Partition=cpu-opteron
[2022-07-05T16:09:49.236] _slurm_rpc_submit_batch_job: JobId=45669 InitPrio=19468 usec=388
[2022-07-05T16:09:49.988] sched: Allocate JobId=45669 NodeList=cpu10 #CPUs=32 Partition=cpu-opteron
[2022-07-05T16:11:21.866] _job_complete: JobId=45669 WEXITSTATUS 1
[2022-07-05T16:11:21.866] _job_complete: JobId=45669 done
[2022-07-05T16:14:00.189] _job_complete: JobId=45668 WEXITSTATUS 0
[2022-07-05T16:14:00.190] _job_complete: JobId=45668 done
[2022-07-05T16:25:10.586] _slurm_rpc_submit_batch_job: JobId=45670 InitPrio=19468 usec=451
[2022-07-05T16:25:10.607] sched: Allocate JobId=45670 NodeList=cpu04 #CPUs=32 Partition=cpu-opteron
[2022-07-05T16:25:20.278] _slurm_rpc_submit_batch_job: JobId=45671 InitPrio=19468 usec=432
[2022-07-05T16:25:20.619] sched: Allocate JobId=45671 NodeList=cpu10 #CPUs=32 Partition=cpu-opteron
[2022-07-05T16:26:36.710] _job_complete: JobId=45670 WEXITSTATUS 0
[2022-07-05T16:26:36.710] _job_complete: JobId=45670 done
[2022-07-05T16:31:12.302] _job_complete: JobId=45671 WEXITSTATUS 0
[2022-07-05T16:31:12.303] _job_complete: JobId=45671 done
[2022-07-05T16:33:28.246] _slurm_rpc_submit_batch_job: JobId=45672 InitPrio=19468 usec=435
[2022-07-05T16:33:28.595] sched: Allocate JobId=45672 NodeList=cpu04 #CPUs=32 Partition=cpu-opteron
[2022-07-05T16:34:33.014] _job_complete: JobId=45672 WEXITSTATUS 0
[2022-07-05T16:34:33.015] _job_complete: JobId=45672 done
[2022-07-05T16:36:07.775] _slurm_rpc_submit_batch_job: JobId=45673 InitPrio=25920 usec=459
[2022-07-05T16:36:07.824] sched: Allocate JobId=45673 NodeList=cpu04 #CPUs=32 Partition=cpu-opteron
[2022-07-05T16:36:14.142] _job_complete: JobId=45673 WEXITSTATUS 0
[2022-07-05T16:36:14.142] _job_complete: JobId=45673 done
[2022-07-05T16:44:29.398] _slurm_rpc_submit_batch_job: JobId=45674 InitPrio=19468 usec=426
[2022-07-05T16:44:29.708] sched: Allocate JobId=45674 NodeList=cpu04 #CPUs=32 Partition=cpu-opteron
[2022-07-05T16:49:56.284] _slurm_rpc_submit_batch_job: JobId=45675 InitPrio=19468 usec=376
[2022-07-05T16:49:57.275] sched: Allocate JobId=45675 NodeList=cpu10 #CPUs=32 Partition=cpu-opteron
[2022-07-05T16:53:53.687] _slurm_rpc_submit_batch_job: JobId=45676 InitPrio=19468 usec=414
[2022-07-05T16:53:53.733] sched: Allocate JobId=45676 NodeList=cpu10 #CPUs=32 Partition=cpu-opteron
[2022-07-05T16:55:22.078] _job_complete: JobId=45676 WEXITSTATUS 0
[2022-07-05T16:55:22.079] _job_complete: JobId=45676 done
[2022-07-05T16:57:36.206] _slurm_rpc_submit_batch_job: JobId=45677 InitPrio=26057 usec=471
[2022-07-05T16:57:37.142] sched: Allocate JobId=45677 NodeList=cpu11 #CPUs=16 Partition=cpu-opteron
[2022-07-05T16:57:38.803] _job_complete: JobId=45677 WEXITSTATUS 1
[2022-07-05T16:57:38.803] _job_complete: JobId=45677 done
[2022-07-05T17:00:58.379] _slurm_rpc_submit_batch_job: JobId=45678 InitPrio=26125 usec=620
[2022-07-05T17:00:58.457] sched: Allocate JobId=45678 NodeList=cpu11 #CPUs=8 Partition=cpu-opteron
[2022-07-05T17:01:00.937] _job_complete: JobId=45678 WEXITSTATUS 1
[2022-07-05T17:01:00.937] _job_complete: JobId=45678 done
[2022-07-05T17:01:51.564] _slurm_rpc_submit_batch_job: JobId=45679 InitPrio=26125 usec=455
[2022-07-05T17:01:52.534] sched: Allocate JobId=45679 NodeList=cpu11 #CPUs=8 Partition=cpu-opteron
[2022-07-05T17:01:54.003] _job_complete: JobId=45679 WEXITSTATUS 1
[2022-07-05T17:01:54.003] _job_complete: JobId=45679 done
[2022-07-05T17:04:42.536] _job_complete: JobId=45675 WEXITSTATUS 0
[2022-07-05T17:04:42.537] _job_complete: JobId=45675 done
[2022-07-05T17:15:22.646] _slurm_rpc_submit_batch_job: JobId=45680 InitPrio=26125 usec=461
[2022-07-05T17:15:23.034] sched: Allocate JobId=45680 NodeList=cpu11 #CPUs=8 Partition=cpu-opteron
[2022-07-05T17:15:24.490] _job_complete: JobId=45680 WEXITSTATUS 1
[2022-07-05T17:15:24.490] _job_complete: JobId=45680 done
[2022-07-05T17:16:49.786] _slurm_rpc_submit_batch_job: JobId=45681 InitPrio=26125 usec=494
[2022-07-05T17:16:50.150] sched: Allocate JobId=45681 NodeList=cpu11 #CPUs=8 Partition=cpu-opteron
[2022-07-05T17:16:51.811] _job_complete: JobId=45681 WEXITSTATUS 1
[2022-07-05T17:16:51.811] _job_complete: JobId=45681 done
[2022-07-05T17:18:24.751] _slurm_rpc_submit_batch_job: JobId=45682 InitPrio=25920 usec=557
[2022-07-05T17:18:25.398] sched: Allocate JobId=45682 NodeList=cpu10 #CPUs=32 Partition=cpu-opteron
[2022-07-05T17:18:26.696] _job_complete: JobId=45682 WEXITSTATUS 1
[2022-07-05T17:18:26.696] _job_complete: JobId=45682 done
[2022-07-05T17:32:01.559] _job_complete: JobId=45674 WEXITSTATUS 0
[2022-07-05T17:32:01.560] _job_complete: JobId=45674 done
[2022-07-05T18:00:47.122] _job_complete: JobId=45661 WEXITSTATUS 0
[2022-07-05T18:00:47.122] _job_complete: JobId=45661 done
[2022-07-05T21:04:44.269] _slurm_rpc_submit_batch_job: JobId=45683 InitPrio=22694 usec=412
[2022-07-05T21:04:44.364] sched: Allocate JobId=45683 NodeList=cpu04 #CPUs=32 Partition=cpu-opteron
[2022-07-05T21:09:38.587] _slurm_rpc_submit_batch_job: JobId=45684 InitPrio=21887 usec=479
[2022-07-05T21:09:38.871] sched: Allocate JobId=45684 NodeList=cpu10 #CPUs=32 Partition=cpu-opteron
[2022-07-05T21:09:56.748] _job_complete: JobId=45684 WEXITSTATUS 1
[2022-07-05T21:09:56.748] _job_complete: JobId=45684 done
[2022-07-05T21:10:44.342] _slurm_rpc_submit_batch_job: JobId=45685 InitPrio=21887 usec=449
[2022-07-05T21:10:44.945] sched: Allocate JobId=45685 NodeList=cpu10 #CPUs=32 Partition=cpu-opteron
[2022-07-05T21:11:24.460] _slurm_rpc_submit_batch_job: JobId=45686 InitPrio=21613 usec=433
[2022-07-05T21:12:37.126] _slurm_rpc_submit_batch_job: JobId=45687 InitPrio=22024 usec=461
[2022-07-05T21:12:37.160] sched: Allocate JobId=45687 NodeList=cpu11 #CPUs=16 Partition=cpu-opteron
[2022-07-05T21:12:55.043] _slurm_rpc_kill_job: REQUEST_KILL_JOB JobId=45685 uid 548300570
[2022-07-05T21:12:57.065] sched: Allocate JobId=45686 NodeList=cpu10 #CPUs=64 Partition=cpu-opteron
[2022-07-05T21:16:10.426] _slurm_rpc_submit_batch_job: JobId=45688 InitPrio=21613 usec=494
[2022-07-05T21:17:18.902] _slurm_rpc_submit_batch_job: JobId=45689 InitPrio=21887 usec=524
[2022-07-05T21:18:08.051] _slurm_rpc_submit_batch_job: JobId=45690 InitPrio=22024 usec=461
[2022-07-05T22:29:33.944] _slurm_rpc_submit_batch_job: JobId=45691 InitPrio=19874 usec=654
[2022-07-05T22:29:34.409] sched: Allocate JobId=45691 NodeList=gpu02 #CPUs=16 Partition=gpu-titan
[2022-07-05T22:31:10.947] _slurm_rpc_submit_batch_job: JobId=45692 InitPrio=19908 usec=533
[2022-07-05T22:31:11.530] sched: Allocate JobId=45692 NodeList=gpu01 #CPUs=12 Partition=gpu-k10
[2022-07-05T22:32:06.249] _slurm_rpc_kill_job: REQUEST_KILL_JOB JobId=45692 uid 548200021
[2022-07-05T22:32:09.750] _slurm_rpc_submit_batch_job: JobId=45693 InitPrio=19908 usec=465
[2022-07-05T22:32:11.154] sched: Allocate JobId=45693 NodeList=gpu01 #CPUs=12 Partition=gpu-k10
[2022-07-05T22:35:00.316] _job_complete: JobId=45693 WEXITSTATUS 0
[2022-07-05T22:35:00.316] _job_complete: JobId=45693 done
[2022-07-05T22:44:43.204] _slurm_rpc_submit_batch_job: JobId=45694 InitPrio=19874 usec=457
[2022-07-05T22:45:10.405] _slurm_rpc_kill_job: REQUEST_KILL_JOB JobId=45691 uid 548200021
[2022-07-05T22:45:12.320] sched: Allocate JobId=45694 NodeList=gpu02 #CPUs=16 Partition=gpu-titan
[2022-07-05T22:47:43.627] _job_complete: JobId=45694 WEXITSTATUS 0
[2022-07-05T22:47:43.627] _job_complete: JobId=45694 done
[2022-07-05T22:54:04.471] _slurm_rpc_submit_batch_job: JobId=45695 InitPrio=19874 usec=443
[2022-07-05T22:54:04.991] sched: Allocate JobId=45695 NodeList=gpu02 #CPUs=16 Partition=gpu-titan
[2022-07-05T23:00:58.467] _job_complete: JobId=45695 WEXITSTATUS 0
[2022-07-05T23:00:58.467] _job_complete: JobId=45695 done
[2022-07-05T23:21:38.016] Time limit exhausted for JobId=44678
[2022-07-05T23:21:40.042] sched: Allocate JobId=45690 NodeList=cpu09 #CPUs=16 Partition=cpu-opteron
[2022-07-05T23:21:40.042] sched: Allocate JobId=45689 NodeList=cpu09 #CPUs=32 Partition=cpu-opteron
[2022-07-05T23:28:14.773] _slurm_rpc_submit_batch_job: JobId=45696 InitPrio=22024 usec=579
[2022-07-05T23:28:14.872] sched: Allocate JobId=45696 NodeList=cpu09 #CPUs=16 Partition=cpu-opteron
[2022-07-05T23:29:10.222] _job_complete: JobId=45696 WEXITSTATUS 0
[2022-07-05T23:29:10.222] _job_complete: JobId=45696 done
[2022-07-05T23:33:47.237] _slurm_rpc_submit_batch_job: JobId=45697 InitPrio=21887 usec=439
[2022-07-05T23:35:39.502] _slurm_rpc_submit_batch_job: JobId=45698 InitPrio=22024 usec=476
[2022-07-05T23:35:39.588] sched: Allocate JobId=45698 NodeList=cpu09 #CPUs=16 Partition=cpu-opteron
[2022-07-05T23:36:02.114] _job_complete: JobId=45698 WEXITSTATUS 1
[2022-07-05T23:36:02.114] _job_complete: JobId=45698 done
[2022-07-05T23:43:12.150] _slurm_rpc_submit_batch_job: JobId=45699 InitPrio=22024 usec=433
[2022-07-05T23:43:12.437] sched: Allocate JobId=45699 NodeList=cpu09 #CPUs=16 Partition=cpu-opteron
[2022-07-05T23:43:34.830] _job_complete: JobId=45699 WEXITSTATUS 1
[2022-07-05T23:43:34.831] _job_complete: JobId=45699 done
[2022-07-05T23:43:41.913] _slurm_rpc_kill_job: REQUEST_KILL_JOB JobId=45699 uid 548300570
[2022-07-05T23:45:33.865] _slurm_rpc_submit_batch_job: JobId=45700 InitPrio=22024 usec=440
[2022-07-05T23:45:34.634] sched: Allocate JobId=45700 NodeList=cpu09 #CPUs=16 Partition=cpu-opteron
[2022-07-05T23:54:29.808] _slurm_rpc_submit_batch_job: JobId=45701 InitPrio=19874 usec=497
[2022-07-05T23:54:30.636] sched: Allocate JobId=45701 NodeList=gpu02 #CPUs=16 Partition=gpu-titan
[2022-07-05T23:55:05.906] _job_complete: JobId=45701 WEXITSTATUS 1
[2022-07-05T23:55:05.906] _job_complete: JobId=45701 done
[2022-07-06T00:05:17.747] _slurm_rpc_submit_batch_job: JobId=45702 InitPrio=19874 usec=481
[2022-07-06T00:05:18.746] sched: Allocate JobId=45702 NodeList=gpu02 #CPUs=16 Partition=gpu-titan
[2022-07-06T00:12:29.708] _job_complete: JobId=45686 WEXITSTATUS 0
[2022-07-06T00:12:29.708] _job_complete: JobId=45686 done
[2022-07-06T00:12:30.182] sched: Allocate JobId=45697 NodeList=cpu10 #CPUs=32 Partition=cpu-opteron
[2022-07-06T00:12:48.151] _job_complete: JobId=45697 WEXITSTATUS 1
[2022-07-06T00:12:48.152] _job_complete: JobId=45697 done
[2022-07-06T00:12:48.551] sched: Allocate JobId=45688 NodeList=cpu10 #CPUs=64 Partition=cpu-opteron
[2022-07-06T00:12:51.731] _job_complete: JobId=45688 WEXITSTATUS 1
[2022-07-06T00:12:51.731] _job_complete: JobId=45688 done
[2022-07-06T00:33:23.290] _slurm_rpc_submit_batch_job: JobId=45703 InitPrio=21613 usec=417
[2022-07-06T00:33:23.695] sched: Allocate JobId=45703 NodeList=cpu10 #CPUs=64 Partition=cpu-opteron
[2022-07-06T01:11:27.913] _slurm_rpc_submit_batch_job: JobId=45704 InitPrio=21613 usec=501
[2022-07-06T01:15:54.260] _slurm_rpc_submit_batch_job: JobId=45705 InitPrio=21613 usec=480
[2022-07-06T02:22:47.028] _job_complete: JobId=45555 WEXITSTATUS 0
[2022-07-06T02:22:47.028] _job_complete: JobId=45555 done
[2022-07-06T02:31:43.501] _job_complete: JobId=45285 WEXITSTATUS 0
[2022-07-06T02:31:43.506] _job_complete: JobId=45285 done
[2022-07-06T02:45:58.442] _job_complete: JobId=45702 WEXITSTATUS 0
[2022-07-06T02:45:58.442] _job_complete: JobId=45702 done
[2022-07-06T02:46:05.538] _job_complete: JobId=45683 WEXITSTATUS 0
[2022-07-06T02:46:05.539] _job_complete: JobId=45683 done
[2022-07-06T02:57:33.914] _slurm_rpc_submit_batch_job: JobId=45706 InitPrio=21756 usec=495
[2022-07-06T02:57:33.969] sched: Allocate JobId=45706 NodeList=gpu01 #CPUs=16 Partition=gpu-k10
[2022-07-06T03:00:04.007] _slurm_rpc_submit_batch_job: JobId=45707 InitPrio=21619 usec=411
[2022-07-06T03:00:04.202] sched: Allocate JobId=45707 NodeList=cpu04 #CPUs=32 Partition=cpu-opteron
[2022-07-06T03:00:15.113] _slurm_rpc_submit_batch_job: JobId=45708 InitPrio=21619 usec=382
[2022-07-06T03:00:23.427] _job_complete: JobId=45707 WEXITSTATUS 0
[2022-07-06T03:00:23.427] _job_complete: JobId=45707 done
[2022-07-06T03:00:24.474] sched: Allocate JobId=45708 NodeList=cpu04 #CPUs=32 Partition=cpu-opteron
[2022-07-06T03:00:32.650] _slurm_rpc_submit_batch_job: JobId=45709 InitPrio=21619 usec=507
[2022-07-06T03:00:45.385] _job_complete: JobId=45708 WEXITSTATUS 0
[2022-07-06T03:00:45.386] _job_complete: JobId=45708 done
[2022-07-06T03:00:45.794] sched: Allocate JobId=45709 NodeList=cpu04 #CPUs=32 Partition=cpu-opteron
[2022-07-06T03:00:48.072] _job_complete: JobId=45709 WEXITSTATUS 1
[2022-07-06T03:00:48.073] _job_complete: JobId=45709 done
[2022-07-06T03:00:50.932] _slurm_rpc_submit_batch_job: JobId=45710 InitPrio=21619 usec=361
[2022-07-06T03:00:51.268] sched: Allocate JobId=45710 NodeList=cpu04 #CPUs=32 Partition=cpu-opteron
[2022-07-06T03:00:53.605] _job_complete: JobId=45710 WEXITSTATUS 1
[2022-07-06T03:00:53.605] _job_complete: JobId=45710 done
[2022-07-06T03:01:18.073] _slurm_rpc_submit_batch_job: JobId=45711 InitPrio=21619 usec=420
[2022-07-06T03:01:18.307] sched: Allocate JobId=45711 NodeList=cpu04 #CPUs=32 Partition=cpu-opteron
[2022-07-06T03:01:20.749] _job_complete: JobId=45711 WEXITSTATUS 1
[2022-07-06T03:01:20.749] _job_complete: JobId=45711 done
[2022-07-06T03:01:23.308] _slurm_rpc_submit_batch_job: JobId=45712 InitPrio=21619 usec=402
[2022-07-06T03:01:23.314] sched: Allocate JobId=45712 NodeList=cpu04 #CPUs=32 Partition=cpu-opteron
[2022-07-06T03:01:25.341] _job_complete: JobId=45712 WEXITSTATUS 1
[2022-07-06T03:01:25.342] _job_complete: JobId=45712 done
[2022-07-06T03:01:33.189] _slurm_rpc_submit_batch_job: JobId=45713 InitPrio=21619 usec=821
[2022-07-06T03:01:33.328] sched: Allocate JobId=45713 NodeList=cpu04 #CPUs=32 Partition=cpu-opteron
[2022-07-06T03:01:37.024] _job_complete: JobId=45713 WEXITSTATUS 1
[2022-07-06T03:01:37.024] _job_complete: JobId=45713 done
[2022-07-06T03:02:35.892] _slurm_rpc_submit_batch_job: JobId=45714 InitPrio=21619 usec=405
[2022-07-06T03:02:36.462] sched: Allocate JobId=45714 NodeList=cpu04 #CPUs=32 Partition=cpu-opteron
[2022-07-06T03:02:40.785] _slurm_rpc_submit_batch_job: JobId=45715 InitPrio=21619 usec=390
[2022-07-06T03:02:45.118] _slurm_rpc_submit_batch_job: JobId=45716 InitPrio=21619 usec=384
[2022-07-06T03:02:54.944] _job_complete: JobId=45714 WEXITSTATUS 0
[2022-07-06T03:02:54.945] _job_complete: JobId=45714 done
[2022-07-06T03:02:55.952] sched: Allocate JobId=45715 NodeList=cpu04 #CPUs=32 Partition=cpu-opteron
[2022-07-06T03:03:00.317] _slurm_rpc_submit_batch_job: JobId=45717 InitPrio=21619 usec=384
[2022-07-06T03:03:05.239] _slurm_rpc_submit_batch_job: JobId=45718 InitPrio=21619 usec=326
[2022-07-06T03:03:09.465] _slurm_rpc_submit_batch_job: JobId=45719 InitPrio=21619 usec=427
[2022-07-06T03:03:15.315] _job_complete: JobId=45715 WEXITSTATUS 0
[2022-07-06T03:03:15.315] _job_complete: JobId=45715 done
[2022-07-06T03:03:15.600] _slurm_rpc_submit_batch_job: JobId=45720 InitPrio=21619 usec=376
[2022-07-06T03:03:15.714] sched: Allocate JobId=45716 NodeList=cpu04 #CPUs=32 Partition=cpu-opteron
[2022-07-06T03:03:19.797] _job_complete: JobId=45716 WEXITSTATUS 0
[2022-07-06T03:03:19.797] _job_complete: JobId=45716 done
[2022-07-06T03:03:20.227] sched: Allocate JobId=45717 NodeList=cpu04 #CPUs=32 Partition=cpu-opteron
[2022-07-06T03:03:32.652] _job_complete: JobId=45717 WEXITSTATUS 0
[2022-07-06T03:03:32.652] _job_complete: JobId=45717 done
[2022-07-06T03:03:33.141] sched: Allocate JobId=45718 NodeList=cpu04 #CPUs=32 Partition=cpu-opteron
[2022-07-06T03:04:47.999] _job_complete: JobId=45718 WEXITSTATUS 0
[2022-07-06T03:04:47.999] _job_complete: JobId=45718 done
[2022-07-06T03:04:49.018] sched: Allocate JobId=45719 NodeList=cpu04 #CPUs=32 Partition=cpu-opteron
[2022-07-06T03:05:05.408] _slurm_rpc_submit_batch_job: JobId=45721 InitPrio=21619 usec=414
[2022-07-06T03:05:27.863] _slurm_rpc_kill_job: REQUEST_KILL_JOB JobId=45721 uid 548200029
[2022-07-06T03:05:46.665] _slurm_rpc_submit_batch_job: JobId=45722 InitPrio=21619 usec=391
[2022-07-06T03:06:07.344] _job_complete: JobId=45719 WEXITSTATUS 0
[2022-07-06T03:06:07.344] _job_complete: JobId=45719 done
[2022-07-06T03:06:07.839] sched: Allocate JobId=45720 NodeList=cpu04 #CPUs=32 Partition=cpu-opteron
[2022-07-06T03:06:21.616] _job_complete: JobId=45720 WEXITSTATUS 0
[2022-07-06T03:06:21.616] _job_complete: JobId=45720 done
[2022-07-06T03:06:22.007] sched: Allocate JobId=45722 NodeList=cpu04 #CPUs=32 Partition=cpu-opteron
[2022-07-06T03:06:25.912] _job_complete: JobId=45722 WEXITSTATUS 0
[2022-07-06T03:06:25.912] _job_complete: JobId=45722 done
[2022-07-06T03:08:41.837] _slurm_rpc_submit_batch_job: JobId=45723 InitPrio=21619 usec=471
[2022-07-06T03:08:42.168] sched: Allocate JobId=45723 NodeList=cpu04 #CPUs=32 Partition=cpu-opteron
[2022-07-06T03:08:50.884] _job_complete: JobId=45723 WEXITSTATUS 0
[2022-07-06T03:08:50.885] _job_complete: JobId=45723 done
[2022-07-06T03:09:24.017] _slurm_rpc_submit_batch_job: JobId=45724 InitPrio=21619 usec=351
[2022-07-06T03:09:24.226] sched: Allocate JobId=45724 NodeList=cpu04 #CPUs=32 Partition=cpu-opteron
[2022-07-06T03:09:26.198] _job_complete: JobId=45724 WEXITSTATUS 1
[2022-07-06T03:09:26.199] _job_complete: JobId=45724 done
[2022-07-06T03:09:45.701] _slurm_rpc_submit_batch_job: JobId=45725 InitPrio=21619 usec=439
[2022-07-06T03:09:46.256] sched: Allocate JobId=45725 NodeList=cpu04 #CPUs=32 Partition=cpu-opteron
[2022-07-06T03:09:48.341] _job_complete: JobId=45725 WEXITSTATUS 1
[2022-07-06T03:09:48.342] _job_complete: JobId=45725 done
[2022-07-06T03:10:03.985] _slurm_rpc_submit_batch_job: JobId=45726 InitPrio=21619 usec=445
[2022-07-06T03:10:04.281] sched: Allocate JobId=45726 NodeList=cpu04 #CPUs=32 Partition=cpu-opteron
[2022-07-06T03:11:24.290] _job_complete: JobId=45726 WEXITSTATUS 0
[2022-07-06T03:11:24.290] _job_complete: JobId=45726 done
[2022-07-06T03:12:28.735] _slurm_rpc_submit_batch_job: JobId=45727 InitPrio=21619 usec=397
[2022-07-06T03:12:29.529] sched: Allocate JobId=45727 NodeList=cpu04 #CPUs=32 Partition=cpu-opteron
[2022-07-06T03:12:36.218] _slurm_rpc_submit_batch_job: JobId=45728 InitPrio=21619 usec=397
[2022-07-06T03:12:48.342] _job_complete: JobId=45727 WEXITSTATUS 0
[2022-07-06T03:12:48.343] _job_complete: JobId=45727 done
[2022-07-06T03:12:49.320] sched: Allocate JobId=45728 NodeList=cpu04 #CPUs=32 Partition=cpu-opteron
[2022-07-06T03:13:07.451] _slurm_rpc_submit_batch_job: JobId=45729 InitPrio=21619 usec=375
[2022-07-06T03:13:13.625] _job_complete: JobId=45728 WEXITSTATUS 0
[2022-07-06T03:13:13.625] _job_complete: JobId=45728 done
[2022-07-06T03:13:14.106] sched: Allocate JobId=45729 NodeList=cpu04 #CPUs=32 Partition=cpu-opteron
[2022-07-06T03:13:14.405] _slurm_rpc_submit_batch_job: JobId=45730 InitPrio=21619 usec=354
[2022-07-06T03:13:18.315] _job_complete: JobId=45729 WEXITSTATUS 0
[2022-07-06T03:13:18.316] _job_complete: JobId=45729 done
[2022-07-06T03:13:18.823] sched: Allocate JobId=45730 NodeList=cpu04 #CPUs=32 Partition=cpu-opteron
[2022-07-06T03:13:21.237] _slurm_rpc_submit_batch_job: JobId=45731 InitPrio=21619 usec=468
[2022-07-06T03:13:25.321] _slurm_rpc_submit_batch_job: JobId=45732 InitPrio=21619 usec=392
[2022-07-06T03:13:32.701] _job_complete: JobId=45730 WEXITSTATUS 0
[2022-07-06T03:13:32.701] _job_complete: JobId=45730 done
[2022-07-06T03:13:33.125] sched: Allocate JobId=45731 NodeList=cpu04 #CPUs=32 Partition=cpu-opteron
[2022-07-06T03:13:36.503] _slurm_rpc_submit_batch_job: JobId=45733 InitPrio=21619 usec=399
[2022-07-06T03:14:47.231] _job_complete: JobId=45731 WEXITSTATUS 0
[2022-07-06T03:14:47.232] _job_complete: JobId=45731 done
[2022-07-06T03:14:47.764] sched: Allocate JobId=45732 NodeList=cpu04 #CPUs=32 Partition=cpu-opteron
[2022-07-06T03:14:49.861] _job_complete: JobId=45732 WEXITSTATUS 1
[2022-07-06T03:14:49.861] _job_complete: JobId=45732 done
[2022-07-06T03:14:50.392] sched: Allocate JobId=45733 NodeList=cpu04 #CPUs=32 Partition=cpu-opteron
[2022-07-06T03:15:04.012] _job_complete: JobId=45733 WEXITSTATUS 0
[2022-07-06T03:15:04.012] _job_complete: JobId=45733 done
[2022-07-06T03:15:11.053] _slurm_rpc_submit_batch_job: JobId=45734 InitPrio=21619 usec=362
[2022-07-06T03:15:11.801] sched: Allocate JobId=45734 NodeList=cpu04 #CPUs=32 Partition=cpu-opteron
[2022-07-06T03:15:15.275] _slurm_rpc_submit_batch_job: JobId=45735 InitPrio=21619 usec=397
[2022-07-06T03:15:19.975] _slurm_rpc_submit_batch_job: JobId=45736 InitPrio=21619 usec=365
[2022-07-06T03:15:25.398] _slurm_rpc_submit_batch_job: JobId=45737 InitPrio=21619 usec=388
[2022-07-06T03:15:30.453] _job_complete: JobId=45734 WEXITSTATUS 0
[2022-07-06T03:15:30.453] _job_complete: JobId=45734 done
[2022-07-06T03:15:31.444] sched: Allocate JobId=45735 NodeList=cpu04 #CPUs=32 Partition=cpu-opteron
[2022-07-06T03:15:37.351] _slurm_rpc_submit_batch_job: JobId=45738 InitPrio=21619 usec=420
[2022-07-06T03:15:41.888] _slurm_rpc_submit_batch_job: JobId=45739 InitPrio=21619 usec=374
[2022-07-06T03:15:51.500] _slurm_rpc_submit_batch_job: JobId=45740 InitPrio=21619 usec=346
[2022-07-06T03:15:56.133] _job_complete: JobId=45735 WEXITSTATUS 0
[2022-07-06T03:15:56.133] _job_complete: JobId=45735 done
[2022-07-06T03:15:56.570] sched: Allocate JobId=45736 NodeList=cpu04 #CPUs=32 Partition=cpu-opteron
[2022-07-06T03:16:00.853] _job_complete: JobId=45736 WEXITSTATUS 0
[2022-07-06T03:16:00.853] _job_complete: JobId=45736 done
[2022-07-06T03:16:01.336] sched: Allocate JobId=45737 NodeList=cpu04 #CPUs=32 Partition=cpu-opteron
[2022-07-06T03:16:15.356] _job_complete: JobId=45737 WEXITSTATUS 0
[2022-07-06T03:16:15.357] _job_complete: JobId=45737 done
[2022-07-06T03:16:15.750] sched: Allocate JobId=45738 NodeList=cpu04 #CPUs=32 Partition=cpu-opteron
[2022-07-06T03:17:24.882] _job_complete: JobId=45738 WEXITSTATUS 0
[2022-07-06T03:17:24.883] _job_complete: JobId=45738 done
[2022-07-06T03:17:25.365] sched: Allocate JobId=45739 NodeList=cpu04 #CPUs=32 Partition=cpu-opteron
[2022-07-06T03:17:27.505] _job_complete: JobId=45739 WEXITSTATUS 1
[2022-07-06T03:17:27.505] _job_complete: JobId=45739 done
[2022-07-06T03:17:27.982] sched: Allocate JobId=45740 NodeList=cpu04 #CPUs=32 Partition=cpu-opteron
[2022-07-06T03:17:41.685] _job_complete: JobId=45740 WEXITSTATUS 0
[2022-07-06T03:17:41.685] _job_complete: JobId=45740 done
[2022-07-06T03:18:08.749] _slurm_rpc_submit_batch_job: JobId=45741 InitPrio=21619 usec=433
[2022-07-06T03:18:09.129] sched: Allocate JobId=45741 NodeList=cpu04 #CPUs=32 Partition=cpu-opteron
[2022-07-06T03:18:13.146] _slurm_rpc_submit_batch_job: JobId=45742 InitPrio=21619 usec=451
[2022-07-06T03:18:18.382] _slurm_rpc_submit_batch_job: JobId=45743 InitPrio=21619 usec=380
[2022-07-06T03:18:22.788] _slurm_rpc_submit_batch_job: JobId=45744 InitPrio=21619 usec=379
[2022-07-06T03:18:27.039] _job_complete: JobId=45741 WEXITSTATUS 0
[2022-07-06T03:18:27.040] _job_complete: JobId=45741 done
[2022-07-06T03:18:28.054] sched: Allocate JobId=45742 NodeList=cpu04 #CPUs=32 Partition=cpu-opteron
[2022-07-06T03:18:28.763] _slurm_rpc_submit_batch_job: JobId=45745 InitPrio=21619 usec=455
[2022-07-06T03:18:33.089] _slurm_rpc_submit_batch_job: JobId=45746 InitPrio=21619 usec=371
[2022-07-06T03:18:38.820] _slurm_rpc_submit_batch_job: JobId=45747 InitPrio=21619 usec=439
[2022-07-06T03:18:47.040] _job_complete: JobId=45742 WEXITSTATUS 0
[2022-07-06T03:18:47.040] _job_complete: JobId=45742 done
[2022-07-06T03:18:47.429] sched: Allocate JobId=45743 NodeList=cpu04 #CPUs=32 Partition=cpu-opteron
[2022-07-06T03:18:51.411] _job_complete: JobId=45743 WEXITSTATUS 0
[2022-07-06T03:18:51.412] _job_complete: JobId=45743 done
[2022-07-06T03:18:51.903] sched: Allocate JobId=45744 NodeList=cpu04 #CPUs=32 Partition=cpu-opteron
[2022-07-06T03:19:04.609] _job_complete: JobId=45744 WEXITSTATUS 0
[2022-07-06T03:19:04.610] _job_complete: JobId=45744 done
[2022-07-06T03:19:05.098] sched: Allocate JobId=45745 NodeList=cpu04 #CPUs=32 Partition=cpu-opteron
[2022-07-06T03:20:21.895] _job_complete: JobId=45745 WEXITSTATUS 0
[2022-07-06T03:20:21.896] _job_complete: JobId=45745 done
[2022-07-06T03:20:22.425] sched: Allocate JobId=45746 NodeList=cpu04 #CPUs=32 Partition=cpu-opteron
[2022-07-06T03:21:41.030] _job_complete: JobId=45746 WEXITSTATUS 0
[2022-07-06T03:21:41.031] _job_complete: JobId=45746 done
[2022-07-06T03:21:42.061] sched: Allocate JobId=45747 NodeList=cpu04 #CPUs=32 Partition=cpu-opteron
[2022-07-06T03:21:55.762] _job_complete: JobId=45747 WEXITSTATUS 0
[2022-07-06T03:21:55.763] _job_complete: JobId=45747 done
[2022-07-06T03:23:51.540] _get_job_parts: invalid partition specified: cpu-epcy
[2022-07-06T03:23:51.540] _slurm_rpc_submit_batch_job: Invalid partition name specified
[2022-07-06T03:24:05.875] _slurm_rpc_submit_batch_job: JobId=45748 InitPrio=21887 usec=438
[2022-07-06T03:24:06.737] sched: Allocate JobId=45748 NodeList=cpu14 #CPUs=32 Partition=cpu-epyc
[2022-07-06T03:27:08.680] _slurm_rpc_submit_batch_job: JobId=45749 InitPrio=21887 usec=468
[2022-07-06T03:34:47.565] _slurm_rpc_submit_batch_job: JobId=45750 InitPrio=21619 usec=479
[2022-07-06T03:34:47.875] sched: Allocate JobId=45750 NodeList=cpu04 #CPUs=32 Partition=cpu-opteron
[2022-07-06T03:35:06.363] _job_complete: JobId=45750 WEXITSTATUS 0
[2022-07-06T03:35:06.364] _job_complete: JobId=45750 done
[2022-07-06T03:39:20.321] _slurm_rpc_submit_batch_job: JobId=45751 InitPrio=21619 usec=349
[2022-07-06T03:39:20.333] sched: Allocate JobId=45751 NodeList=cpu04 #CPUs=32 Partition=cpu-opteron
[2022-07-06T03:39:33.201] _slurm_rpc_submit_batch_job: JobId=45752 InitPrio=21619 usec=387
[2022-07-06T03:39:40.147] _job_complete: JobId=45751 WEXITSTATUS 0
[2022-07-06T03:39:40.147] _job_complete: JobId=45751 done
[2022-07-06T03:39:40.746] sched: Allocate JobId=45752 NodeList=cpu04 #CPUs=32 Partition=cpu-opteron
[2022-07-06T03:39:44.867] _job_complete: JobId=45752 WEXITSTATUS 0
[2022-07-06T03:39:44.867] _job_complete: JobId=45752 done
[2022-07-06T03:40:49.643] _slurm_rpc_submit_batch_job: JobId=45753 InitPrio=21619 usec=432
[2022-07-06T03:40:50.461] sched: Allocate JobId=45753 NodeList=cpu04 #CPUs=32 Partition=cpu-opteron
[2022-07-06T03:41:02.979] _job_complete: JobId=45753 WEXITSTATUS 0
[2022-07-06T03:41:02.980] _job_complete: JobId=45753 done
[2022-07-06T03:41:21.115] _slurm_rpc_submit_batch_job: JobId=45754 InitPrio=21619 usec=426
[2022-07-06T03:41:21.505] sched: Allocate JobId=45754 NodeList=cpu04 #CPUs=32 Partition=cpu-opteron
[2022-07-06T03:41:37.946] _slurm_rpc_submit_batch_job: JobId=45755 InitPrio=21619 usec=380
[2022-07-06T03:42:33.768] _job_complete: JobId=45754 WEXITSTATUS 0
[2022-07-06T03:42:33.768] _job_complete: JobId=45754 done
[2022-07-06T03:42:34.273] sched: Allocate JobId=45755 NodeList=cpu04 #CPUs=32 Partition=cpu-opteron
[2022-07-06T03:43:42.292] _slurm_rpc_submit_batch_job: JobId=45756 InitPrio=21619 usec=360
[2022-07-06T03:43:50.502] _job_complete: JobId=45755 WEXITSTATUS 0
[2022-07-06T03:43:50.503] _job_complete: JobId=45755 done
[2022-07-06T03:43:51.008] sched: Allocate JobId=45756 NodeList=cpu04 #CPUs=32 Partition=cpu-opteron
[2022-07-06T03:44:04.580] _job_complete: JobId=45756 WEXITSTATUS 0
[2022-07-06T03:44:04.581] _job_complete: JobId=45756 done
[2022-07-06T03:46:42.157] _slurm_rpc_submit_batch_job: JobId=45757 InitPrio=21887 usec=459
[2022-07-06T03:46:43.118] sched: Allocate JobId=45757 NodeList=cpu04 #CPUs=32 Partition=cpu-opteron
[2022-07-06T03:48:03.283] _slurm_rpc_submit_batch_job: JobId=45758 InitPrio=21619 usec=400
[2022-07-06T03:51:59.859] _slurm_rpc_submit_batch_job: JobId=45759 InitPrio=21619 usec=420
[2022-07-06T03:52:16.851] _slurm_rpc_submit_batch_job: JobId=45760 InitPrio=21619 usec=537
[2022-07-06T03:53:58.665] _slurm_rpc_submit_batch_job: JobId=45761 InitPrio=21619 usec=422
[2022-07-06T03:54:51.133] _slurm_rpc_submit_batch_job: JobId=45762 InitPrio=21619 usec=395
[2022-07-06T03:55:04.725] _slurm_rpc_submit_batch_job: JobId=45763 InitPrio=21619 usec=346
[2022-07-06T03:57:07.214] _slurm_rpc_submit_batch_job: JobId=45764 InitPrio=21619 usec=403
[2022-07-06T04:02:39.917] _slurm_rpc_submit_batch_job: JobId=45765 InitPrio=21619 usec=436
[2022-07-06T04:06:38.194] _slurm_rpc_submit_batch_job: JobId=45766 InitPrio=21619 usec=383
[2022-07-06T04:10:17.419] _slurm_rpc_submit_batch_job: JobId=45767 InitPrio=21619 usec=492
[2022-07-06T04:14:49.298] _slurm_rpc_submit_batch_job: JobId=45768 InitPrio=21619 usec=452
[2022-07-06T05:24:58.540] _job_complete: JobId=45757 WEXITSTATUS 1
[2022-07-06T05:24:58.541] _job_complete: JobId=45757 done
[2022-07-06T05:24:59.553] sched: Allocate JobId=45758 NodeList=cpu04 #CPUs=32 Partition=cpu-opteron
[2022-07-06T05:25:05.465] _job_complete: JobId=45758 WEXITSTATUS 1
[2022-07-06T05:25:05.466] _job_complete: JobId=45758 done
[2022-07-06T05:25:05.959] sched: Allocate JobId=45759 NodeList=cpu04 #CPUs=32 Partition=cpu-opteron
[2022-07-06T05:25:09.192] _job_complete: JobId=45759 WEXITSTATUS 1
[2022-07-06T05:25:09.192] _job_complete: JobId=45759 done
[2022-07-06T05:25:09.698] sched: Allocate JobId=45760 NodeList=cpu04 #CPUs=32 Partition=cpu-opteron
[2022-07-06T05:25:11.739] _job_complete: JobId=45760 WEXITSTATUS 1
[2022-07-06T05:25:11.739] _job_complete: JobId=45760 done
[2022-07-06T05:25:12.170] sched: Allocate JobId=45761 NodeList=cpu04 #CPUs=32 Partition=cpu-opteron
[2022-07-06T05:25:13.656] _job_complete: JobId=45761 WEXITSTATUS 1
[2022-07-06T05:25:13.657] _job_complete: JobId=45761 done
[2022-07-06T05:25:14.177] sched: Allocate JobId=45762 NodeList=cpu04 #CPUs=32 Partition=cpu-opteron
[2022-07-06T05:25:16.189] _job_complete: JobId=45762 WEXITSTATUS 1
[2022-07-06T05:25:16.190] _job_complete: JobId=45762 done
[2022-07-06T05:25:16.587] sched: Allocate JobId=45763 NodeList=cpu04 #CPUs=32 Partition=cpu-opteron
[2022-07-06T05:25:18.636] _job_complete: JobId=45763 WEXITSTATUS 1
[2022-07-06T05:25:18.637] _job_complete: JobId=45763 done
[2022-07-06T05:25:19.036] sched: Allocate JobId=45764 NodeList=cpu04 #CPUs=32 Partition=cpu-opteron
[2022-07-06T05:25:22.854] _job_complete: JobId=45764 WEXITSTATUS 1
[2022-07-06T05:25:22.855] _job_complete: JobId=45764 done
[2022-07-06T05:25:23.363] sched: Allocate JobId=45765 NodeList=cpu04 #CPUs=32 Partition=cpu-opteron
[2022-07-06T05:25:46.488] _job_complete: JobId=45765 WEXITSTATUS 0
[2022-07-06T05:25:46.489] _job_complete: JobId=45765 done
[2022-07-06T05:25:47.493] sched: Allocate JobId=45766 NodeList=cpu04 #CPUs=32 Partition=cpu-opteron
[2022-07-06T05:26:15.062] _job_complete: JobId=45766 WEXITSTATUS 0
[2022-07-06T05:26:15.062] _job_complete: JobId=45766 done
[2022-07-06T05:26:16.080] sched: Allocate JobId=45767 NodeList=cpu04 #CPUs=32 Partition=cpu-opteron
[2022-07-06T05:26:44.297] _job_complete: JobId=45767 WEXITSTATUS 0
[2022-07-06T05:26:44.297] _job_complete: JobId=45767 done
[2022-07-06T05:26:45.290] sched: Allocate JobId=45768 NodeList=cpu04 #CPUs=32 Partition=cpu-opteron
[2022-07-06T05:27:07.735] _job_complete: JobId=45768 WEXITSTATUS 0
[2022-07-06T05:27:07.735] _job_complete: JobId=45768 done
[2022-07-06T06:16:30.506] _job_complete: JobId=45748 WEXITSTATUS 0
[2022-07-06T06:16:30.506] _job_complete: JobId=45748 done
[2022-07-06T06:16:31.338] sched: Allocate JobId=45749 NodeList=cpu14 #CPUs=32 Partition=cpu-epyc
[2022-07-06T06:56:57.956] _job_complete: JobId=45749 WEXITSTATUS 1
[2022-07-06T06:56:57.956] _job_complete: JobId=45749 done
[2022-07-06T07:24:27.511] _job_complete: JobId=45706 WEXITSTATUS 1
[2022-07-06T07:24:27.516] _job_complete: JobId=45706 done
[2022-07-06T08:58:32.777] _job_complete: JobId=45689 WEXITSTATUS 0
[2022-07-06T08:58:32.777] _job_complete: JobId=45689 done
[2022-07-06T09:33:45.598] _slurm_rpc_submit_batch_job: JobId=45769 InitPrio=20143 usec=498
[2022-07-06T09:33:46.320] sched: Allocate JobId=45769 NodeList=gpu05 #CPUs=16 Partition=gpu-v100s
[2022-07-06T09:33:54.992] _job_complete: JobId=45769 WEXITSTATUS 1
[2022-07-06T09:33:54.992] _job_complete: JobId=45769 done
[2022-07-06T09:34:26.910] _slurm_rpc_submit_batch_job: JobId=45770 InitPrio=20143 usec=445
[2022-07-06T09:34:27.361] sched: Allocate JobId=45770 NodeList=gpu05 #CPUs=16 Partition=gpu-v100s
[2022-07-06T09:34:31.655] _job_complete: JobId=45770 WEXITSTATUS 1
[2022-07-06T09:34:31.656] _job_complete: JobId=45770 done
[2022-07-06T09:35:50.786] _slurm_rpc_submit_batch_job: JobId=45771 InitPrio=20143 usec=388
[2022-07-06T09:35:51.481] sched: Allocate JobId=45771 NodeList=gpu05 #CPUs=16 Partition=gpu-v100s
[2022-07-06T09:35:55.707] _job_complete: JobId=45771 WEXITSTATUS 1
[2022-07-06T09:35:55.708] _job_complete: JobId=45771 done
[2022-07-06T09:37:15.044] _slurm_rpc_submit_batch_job: JobId=45772 InitPrio=20143 usec=456
[2022-07-06T09:37:15.602] sched: Allocate JobId=45772 NodeList=gpu05 #CPUs=16 Partition=gpu-v100s
[2022-07-06T09:37:46.104] _job_complete: JobId=45772 WEXITSTATUS 1
[2022-07-06T09:37:46.105] _job_complete: JobId=45772 done
[2022-07-06T09:40:29.511] _slurm_rpc_submit_batch_job: JobId=45773 InitPrio=20143 usec=503
[2022-07-06T09:40:30.092] sched: Allocate JobId=45773 NodeList=gpu05 #CPUs=16 Partition=gpu-v100s
[2022-07-06T09:40:51.779] _job_complete: JobId=45773 WEXITSTATUS 1
[2022-07-06T09:40:51.780] _job_complete: JobId=45773 done
[2022-07-06T09:44:05.113] _slurm_rpc_submit_batch_job: JobId=45774 InitPrio=20143 usec=500
[2022-07-06T09:44:06.484] sched: Allocate JobId=45774 NodeList=gpu05 #CPUs=16 Partition=gpu-v100s
[2022-07-06T09:44:28.227] _job_complete: JobId=45774 WEXITSTATUS 1
[2022-07-06T09:44:28.227] _job_complete: JobId=45774 done
[2022-07-06T09:45:51.041] _slurm_rpc_submit_batch_job: JobId=45775 InitPrio=20143 usec=418
[2022-07-06T09:45:51.628] sched: Allocate JobId=45775 NodeList=gpu05 #CPUs=16 Partition=gpu-v100s
[2022-07-06T09:46:13.124] _job_complete: JobId=45775 WEXITSTATUS 1
[2022-07-06T09:46:13.125] _job_complete: JobId=45775 done
[2022-07-06T09:49:02.401] _slurm_rpc_submit_batch_job: JobId=45776 InitPrio=20143 usec=359
[2022-07-06T09:49:03.009] sched: Allocate JobId=45776 NodeList=gpu05 #CPUs=16 Partition=gpu-v100s
[2022-07-06T09:49:24.812] _job_complete: JobId=45776 WEXITSTATUS 1
[2022-07-06T09:49:24.812] _job_complete: JobId=45776 done
[2022-07-06T09:51:45.028] _slurm_rpc_submit_batch_job: JobId=45777 InitPrio=20143 usec=464
[2022-07-06T09:51:45.240] sched: Allocate JobId=45777 NodeList=gpu05 #CPUs=16 Partition=gpu-v100s
[2022-07-06T09:52:06.915] _job_complete: JobId=45777 WEXITSTATUS 1
[2022-07-06T09:52:06.915] _job_complete: JobId=45777 done
[2022-07-06T09:53:49.078] _slurm_rpc_submit_batch_job: JobId=45778 InitPrio=20143 usec=406
[2022-07-06T09:53:49.567] sched: Allocate JobId=45778 NodeList=gpu05 #CPUs=16 Partition=gpu-v100s
[2022-07-06T09:54:46.719] _slurm_rpc_kill_job: REQUEST_KILL_JOB JobId=45778 uid 548300547
[2022-07-06T09:57:10.848] Time limit exhausted for JobId=45320
[2022-07-06T09:58:10.644] _slurm_rpc_submit_batch_job: JobId=45779 InitPrio=20143 usec=389
[2022-07-06T09:58:11.045] sched: Allocate JobId=45779 NodeList=gpu05 #CPUs=16 Partition=gpu-v100s
[2022-07-06T10:05:08.511] _slurm_rpc_kill_job: REQUEST_KILL_JOB JobId=45779 uid 548300547
[2022-07-06T10:05:56.744] _slurm_rpc_submit_batch_job: JobId=45780 InitPrio=20143 usec=428
[2022-07-06T10:05:56.890] sched: Allocate JobId=45780 NodeList=gpu05 #CPUs=16 Partition=gpu-v100s
[2022-07-06T10:10:50.414] _slurm_rpc_submit_batch_job: JobId=45781 InitPrio=26377 usec=517
[2022-07-06T10:10:50.558] sched: Allocate JobId=45781 NodeList=gpu02 #CPUs=10 Partition=gpu-titan
[2022-07-06T10:31:46.459] _job_complete: JobId=45703 WEXITSTATUS 0
[2022-07-06T10:31:46.459] _job_complete: JobId=45703 done
[2022-07-06T10:31:46.968] sched: Allocate JobId=45704 NodeList=cpu10 #CPUs=64 Partition=cpu-opteron
[2022-07-06T10:34:03.130] _slurm_rpc_submit_batch_job: JobId=45782 InitPrio=19959 usec=402
[2022-07-06T10:34:06.121] sched: Allocate JobId=45782 NodeList=gpu02 #CPUs=6 Partition=gpu-titan
[2022-07-06T10:34:20.527] _slurm_rpc_submit_batch_job: JobId=45783 InitPrio=19959 usec=393
[2022-07-06T10:34:48.063] _slurm_rpc_kill_job: REQUEST_KILL_JOB JobId=45782 uid 548200021
[2022-07-06T10:34:49.948] sched: Allocate JobId=45783 NodeList=gpu02 #CPUs=6 Partition=gpu-titan
[2022-07-06T10:42:28.080] _job_complete: JobId=45783 WEXITSTATUS 0
[2022-07-06T10:42:28.081] _job_complete: JobId=45783 done
[2022-07-06T10:45:17.171] _slurm_rpc_submit_batch_job: JobId=45784 InitPrio=26966 usec=375
[2022-07-06T10:45:17.248] sched: Allocate JobId=45784 NodeList=cpu04 #CPUs=4 Partition=cpu-opteron
[2022-07-06T10:47:14.103] _slurm_rpc_submit_batch_job: JobId=45785 InitPrio=19959 usec=439
[2022-07-06T10:47:14.398] sched: Allocate JobId=45785 NodeList=gpu02 #CPUs=6 Partition=gpu-titan
[2022-07-06T10:48:34.425] sched: _slurm_rpc_allocate_resources JobId=45786 NodeList=(null) usec=1234
[2022-07-06T10:48:34.580] sched: Allocate JobId=45786 NodeList=cpu04 #CPUs=4 Partition=cpu-opteron
[2022-07-06T10:51:42.207] _slurm_rpc_kill_job: REQUEST_KILL_JOB JobId=45786 uid 548300543
[2022-07-06T10:51:46.296] _slurm_rpc_kill_job: REQUEST_KILL_JOB JobId=45784 uid 548300543
[2022-07-06T10:54:52.296] _job_complete: JobId=45785 WEXITSTATUS 0
[2022-07-06T10:54:52.296] _job_complete: JobId=45785 done
[2022-07-06T10:57:25.797] _slurm_rpc_submit_batch_job: JobId=45787 InitPrio=24175 usec=413
[2022-07-06T10:57:26.428] sched: Allocate JobId=45787 NodeList=cpu12 #CPUs=16 Partition=cpu-epyc
[2022-07-06T10:57:29.495] _slurm_rpc_submit_batch_job: JobId=45788 InitPrio=24175 usec=430
[2022-07-06T10:57:32.383] _slurm_rpc_submit_batch_job: JobId=45789 InitPrio=24175 usec=477
[2022-07-06T10:57:35.054] _slurm_rpc_submit_batch_job: JobId=45790 InitPrio=24175 usec=432
[2022-07-06T10:57:37.918] _slurm_rpc_submit_batch_job: JobId=45791 InitPrio=24175 usec=425
[2022-07-06T10:57:41.482] _slurm_rpc_submit_batch_job: JobId=45792 InitPrio=24175 usec=417
[2022-07-06T10:57:50.790] _slurm_rpc_submit_batch_job: JobId=45793 InitPrio=24175 usec=454
[2022-07-06T10:57:54.077] _slurm_rpc_submit_batch_job: JobId=45794 InitPrio=24175 usec=391
[2022-07-06T10:57:56.742] _slurm_rpc_submit_batch_job: JobId=45795 InitPrio=24175 usec=456
[2022-07-06T10:58:00.103] _slurm_rpc_submit_batch_job: JobId=45796 InitPrio=24175 usec=413
[2022-07-06T10:59:31.504] _slurm_rpc_submit_batch_job: JobId=45797 InitPrio=19737 usec=449
[2022-07-06T10:59:31.680] sched: Allocate JobId=45797 NodeList=cpu04 #CPUs=32 Partition=cpu-opteron
[2022-07-06T10:59:32.489] _job_complete: JobId=45797 WEXITSTATUS 2
[2022-07-06T10:59:32.489] _job_complete: JobId=45797 done
[2022-07-06T11:00:10.695] _slurm_rpc_submit_batch_job: JobId=45798 InitPrio=19737 usec=456
[2022-07-06T11:00:10.731] sched: Allocate JobId=45798 NodeList=cpu04 #CPUs=32 Partition=cpu-opteron
[2022-07-06T11:00:11.534] _job_complete: JobId=45798 WEXITSTATUS 2
[2022-07-06T11:00:11.535] _job_complete: JobId=45798 done
[2022-07-06T11:00:32.743] _slurm_rpc_submit_batch_job: JobId=45799 InitPrio=19737 usec=443
[2022-07-06T11:00:32.762] sched: Allocate JobId=45799 NodeList=cpu04 #CPUs=32 Partition=cpu-opteron
[2022-07-06T11:00:55.840] _job_complete: JobId=45799 WEXITSTATUS 1
[2022-07-06T11:00:55.840] _job_complete: JobId=45799 done
[2022-07-06T11:01:29.180] _slurm_rpc_submit_batch_job: JobId=45800 InitPrio=19737 usec=433
[2022-07-06T11:01:29.840] sched: Allocate JobId=45800 NodeList=cpu04 #CPUs=32 Partition=cpu-opteron
[2022-07-06T11:08:42.391] _slurm_rpc_submit_batch_job: JobId=45801 InitPrio=28067 usec=611
[2022-07-06T11:08:42.646] sched: Allocate JobId=45801 NodeList=cpu09 #CPUs=1 Partition=cpu-opteron
[2022-07-06T11:11:00.830] _slurm_rpc_kill_job: REQUEST_KILL_JOB JobId=45801 uid 548200009
[2022-07-06T11:11:03.976] _slurm_rpc_submit_batch_job: JobId=45802 InitPrio=28067 usec=360
[2022-07-06T11:11:06.825] sched: Allocate JobId=45802 NodeList=cpu09 #CPUs=1 Partition=cpu-opteron
[2022-07-06T11:13:02.159] _slurm_rpc_kill_job: REQUEST_KILL_JOB JobId=45802 uid 548200009
[2022-07-06T11:13:08.923] _slurm_rpc_submit_batch_job: JobId=45803 InitPrio=28067 usec=333
[2022-07-06T11:13:09.100] sched: Allocate JobId=45803 NodeList=cpu09 #CPUs=1 Partition=cpu-opteron
[2022-07-06T11:13:54.157] _slurm_rpc_kill_job: REQUEST_KILL_JOB JobId=45803 uid 548200009
[2022-07-06T11:14:00.033] _slurm_rpc_submit_batch_job: JobId=45804 InitPrio=19959 usec=559
[2022-07-06T11:14:00.177] sched: Allocate JobId=45804 NodeList=gpu02 #CPUs=6 Partition=gpu-titan
[2022-07-06T11:14:06.458] _job_complete: JobId=45804 WEXITSTATUS 1
[2022-07-06T11:14:06.458] _job_complete: JobId=45804 done
[2022-07-06T11:14:53.326] _slurm_rpc_submit_batch_job: JobId=45805 InitPrio=19959 usec=380
[2022-07-06T11:14:54.249] sched: Allocate JobId=45805 NodeList=gpu02 #CPUs=6 Partition=gpu-titan
[2022-07-06T11:18:23.618] _job_complete: JobId=45805 WEXITSTATUS 1
[2022-07-06T11:18:23.618] _job_complete: JobId=45805 done
[2022-07-06T11:21:37.823] _slurm_rpc_submit_batch_job: JobId=45806 InitPrio=20812 usec=449
[2022-07-06T11:21:37.920] sched: Allocate JobId=45806 NodeList=cpu14 #CPUs=32 Partition=cpu-epyc
[2022-07-06T11:23:17.441] sched: _slurm_rpc_allocate_resources JobId=45807 NodeList=(null) usec=829
[2022-07-06T11:23:18.257] sched: Allocate JobId=45807 NodeList=cpu09 #CPUs=1 Partition=cpu-opteron
[2022-07-06T11:23:21.418] _job_complete: JobId=45806 WEXITSTATUS 0
[2022-07-06T11:23:21.419] _job_complete: JobId=45806 done
[2022-07-06T11:24:35.587] _slurm_rpc_submit_batch_job: JobId=45808 InitPrio=20812 usec=525
[2022-07-06T11:24:36.369] sched: Allocate JobId=45808 NodeList=cpu14 #CPUs=32 Partition=cpu-epyc
[2022-07-06T11:24:54.543] _job_complete: JobId=45808 WEXITSTATUS 0
[2022-07-06T11:24:54.543] _job_complete: JobId=45808 done
[2022-07-06T11:25:12.910] _slurm_rpc_submit_batch_job: JobId=45809 InitPrio=20812 usec=487
[2022-07-06T11:25:13.421] sched: Allocate JobId=45809 NodeList=cpu14 #CPUs=32 Partition=cpu-epyc
[2022-07-06T11:26:33.840] _slurm_rpc_kill_job: REQUEST_KILL_JOB JobId=45780 uid 548300547
[2022-07-06T11:27:22.692] _job_complete: JobId=45807 WEXITSTATUS 0
[2022-07-06T11:27:22.692] _job_complete: JobId=45807 done
[2022-07-06T11:29:57.626] _slurm_rpc_submit_batch_job: JobId=45810 InitPrio=19977 usec=424
[2022-07-06T11:29:57.914] sched: Allocate JobId=45810 NodeList=cpu09 #CPUs=4 Partition=cpu-opteron
[2022-07-06T11:29:59.681] _job_complete: JobId=45810 WEXITSTATUS 1
[2022-07-06T11:29:59.681] _job_complete: JobId=45810 done
[2022-07-06T11:31:08.128] _slurm_rpc_submit_batch_job: JobId=45811 InitPrio=19977 usec=572
[2022-07-06T11:31:09.009] sched: Allocate JobId=45811 NodeList=cpu09 #CPUs=4 Partition=cpu-opteron
[2022-07-06T11:31:10.188] _job_complete: JobId=45811 WEXITSTATUS 127
[2022-07-06T11:31:10.188] _job_complete: JobId=45811 done
[2022-07-06T11:31:20.551] _slurm_rpc_submit_batch_job: JobId=45812 InitPrio=20143 usec=367
[2022-07-06T11:31:21.038] sched: Allocate JobId=45812 NodeList=gpu05 #CPUs=16 Partition=gpu-v100s
[2022-07-06T11:31:31.923] _slurm_rpc_submit_batch_job: JobId=45813 InitPrio=19977 usec=530
[2022-07-06T11:31:32.040] sched: Allocate JobId=45813 NodeList=cpu09 #CPUs=4 Partition=cpu-opteron
[2022-07-06T11:31:33.085] _job_complete: JobId=45813 WEXITSTATUS 127
[2022-07-06T11:31:33.085] _job_complete: JobId=45813 done
[2022-07-06T11:31:52.825] _job_complete: JobId=45812 WEXITSTATUS 1
[2022-07-06T11:31:52.826] _job_complete: JobId=45812 done
[2022-07-06T11:32:11.119] sched: _slurm_rpc_allocate_resources JobId=45814 NodeList=(null) usec=717
[2022-07-06T11:32:12.094] sched: Allocate JobId=45814 NodeList=cpu09 #CPUs=8 Partition=cpu-opteron
[2022-07-06T11:33:29.559] _slurm_rpc_submit_batch_job: JobId=45815 InitPrio=20143 usec=436
[2022-07-06T11:33:30.331] sched: Allocate JobId=45815 NodeList=gpu05 #CPUs=16 Partition=gpu-v100s
[2022-07-06T11:33:35.173] _job_complete: JobId=45815 WEXITSTATUS 1
[2022-07-06T11:33:35.174] _job_complete: JobId=45815 done
[2022-07-06T11:34:38.135] _slurm_rpc_submit_batch_job: JobId=45816 InitPrio=20143 usec=439
[2022-07-06T11:34:38.427] sched: Allocate JobId=45816 NodeList=gpu05 #CPUs=16 Partition=gpu-v100s
[2022-07-06T11:34:59.691] _job_complete: JobId=45816 WEXITSTATUS 1
[2022-07-06T11:34:59.691] _job_complete: JobId=45816 done
[2022-07-06T11:36:18.472] _slurm_rpc_submit_batch_job: JobId=45817 InitPrio=20143 usec=366
[2022-07-06T11:36:18.567] sched: Allocate JobId=45817 NodeList=gpu05 #CPUs=16 Partition=gpu-v100s
[2022-07-06T11:38:20.293] _job_complete: JobId=45809 WEXITSTATUS 0
[2022-07-06T11:38:20.293] _job_complete: JobId=45809 done
[2022-07-06T11:40:21.312] _job_complete: JobId=45814 WEXITSTATUS 0
[2022-07-06T11:40:21.312] _job_complete: JobId=45814 done
[2022-07-06T11:41:14.920] _slurm_rpc_submit_batch_job: JobId=45818 InitPrio=19737 usec=451
[2022-07-06T11:41:15.103] sched: Allocate JobId=45818 NodeList=cpu14 #CPUs=32 Partition=cpu-epyc
[2022-07-06T11:41:40.630] _job_complete: JobId=45818 WEXITSTATUS 1
[2022-07-06T11:41:40.630] _job_complete: JobId=45818 done
[2022-07-06T11:42:01.737] _slurm_rpc_submit_batch_job: JobId=45819 InitPrio=19737 usec=372
[2022-07-06T11:42:02.168] sched: Allocate JobId=45819 NodeList=cpu14 #CPUs=32 Partition=cpu-epyc
[2022-07-06T11:42:27.834] _job_complete: JobId=45819 WEXITSTATUS 1
[2022-07-06T11:42:27.834] _job_complete: JobId=45819 done
[2022-07-06T11:43:51.244] _slurm_rpc_submit_batch_job: JobId=45820 InitPrio=19737 usec=470
[2022-07-06T11:43:51.467] sched: Allocate JobId=45820 NodeList=cpu14 #CPUs=32 Partition=cpu-epyc
[2022-07-06T11:44:16.724] _job_complete: JobId=45820 WEXITSTATUS 1
[2022-07-06T11:44:16.724] _job_complete: JobId=45820 done
[2022-07-06T11:44:40.683] _slurm_rpc_submit_batch_job: JobId=45821 InitPrio=19737 usec=406
[2022-07-06T11:44:41.536] sched: Allocate JobId=45821 NodeList=cpu14 #CPUs=32 Partition=cpu-epyc
[2022-07-06T11:48:49.184] _slurm_rpc_submit_batch_job: JobId=45822 InitPrio=19737 usec=481
[2022-07-06T11:48:49.985] sched: Allocate JobId=45822 NodeList=cpu09 #CPUs=32 Partition=cpu-opteron
[2022-07-06T11:55:07.587] _slurm_rpc_submit_batch_job: JobId=45823 InitPrio=28067 usec=357
[2022-07-06T12:06:59.077] _slurm_rpc_submit_batch_job: JobId=45824 InitPrio=26966 usec=406
[2022-07-06T12:07:34.999] _slurm_rpc_kill_job: REQUEST_KILL_JOB JobId=45824 uid 548300543
[2022-07-06T12:09:26.075] _slurm_rpc_submit_batch_job: JobId=45825 InitPrio=26992 usec=380
[2022-07-06T12:09:28.371] _slurm_rpc_kill_job: REQUEST_KILL_JOB JobId=45825 uid 548300543
[2022-07-06T12:21:31.249] _slurm_rpc_submit_batch_job: JobId=45826 InitPrio=25379 usec=432
[2022-07-06T12:22:34.204] _slurm_rpc_kill_job: REQUEST_KILL_JOB JobId=45826 uid 548200003
[2022-07-06T12:22:48.089] _slurm_rpc_submit_batch_job: JobId=45827 InitPrio=25379 usec=337
[2022-07-06T12:23:37.497] _slurm_rpc_kill_job: REQUEST_KILL_JOB JobId=45827 uid 548200003
[2022-07-06T12:23:45.254] _slurm_rpc_submit_batch_job: JobId=45828 InitPrio=25379 usec=316
[2022-07-06T12:23:45.833] sched: Allocate JobId=45828 NodeList=gpu01 #CPUs=1 Partition=gpu-k10
[2022-07-06T12:24:01.873] _slurm_rpc_kill_job: REQUEST_KILL_JOB JobId=45828 uid 548200003
[2022-07-06T12:28:13.940] _pick_best_nodes: JobId=45829 never runnable in partition cpu-opteron
[2022-07-06T12:28:13.941] _slurm_rpc_submit_batch_job: Requested node configuration is not available
[2022-07-06T12:40:09.020] _job_complete: JobId=45704 WEXITSTATUS 0
[2022-07-06T12:40:09.020] _job_complete: JobId=45704 done
[2022-07-06T12:40:09.538] sched: Allocate JobId=45823 NodeList=cpu10 #CPUs=1 Partition=cpu-opteron
[2022-07-06T12:41:07.188] _slurm_rpc_submit_batch_job: JobId=45830 InitPrio=20543 usec=610
[2022-07-06T12:41:07.618] sched: Allocate JobId=45830 NodeList=cpu10 #CPUs=32 Partition=cpu-opteron
[2022-07-06T12:41:41.042] _slurm_rpc_submit_batch_job: JobId=45831 InitPrio=20689 usec=402
[2022-07-06T12:41:41.654] sched: Allocate JobId=45831 NodeList=cpu10 #CPUs=15 Partition=cpu-opteron
[2022-07-06T12:41:45.373] _slurm_rpc_submit_batch_job: JobId=45832 InitPrio=28067 usec=372
[2022-07-06T12:41:45.660] sched: Allocate JobId=45832 NodeList=cpu10 #CPUs=1 Partition=cpu-opteron
[2022-07-06T12:42:37.771] _slurm_rpc_submit_batch_job: JobId=45833 InitPrio=20680 usec=548
[2022-07-06T12:43:05.425] _slurm_rpc_kill_job: REQUEST_KILL_JOB JobId=45833 uid 548200019
[2022-07-06T12:43:18.248] _slurm_rpc_submit_batch_job: JobId=45834 InitPrio=20689 usec=468
[2022-07-06T12:43:18.896] sched: Allocate JobId=45834 NodeList=cpu10 #CPUs=15 Partition=cpu-opteron
[2022-07-06T12:45:07.087] _slurm_rpc_kill_job: REQUEST_KILL_JOB JobId=45832 uid 548200009
[2022-07-06T12:46:09.181] _slurm_rpc_kill_job: REQUEST_KILL_JOB JobId=45823 uid 548200009
[2022-07-06T13:22:48.507] _slurm_rpc_kill_job: REQUEST_KILL_JOB JobId=45660 uid 548200017
[2022-07-06T13:22:48.507] _slurm_rpc_kill_job: REQUEST_KILL_JOB JobId=45550 uid 548200017
[2022-07-06T13:22:48.507] _slurm_rpc_kill_job: REQUEST_KILL_JOB JobId=45506 uid 548200017
[2022-07-06T13:22:48.507] _slurm_rpc_kill_job: REQUEST_KILL_JOB JobId=45652 uid 548200017
[2022-07-06T13:22:50.518] sched: Allocate JobId=45705 NodeList=cpu03 #CPUs=64 Partition=cpu-opteron
[2022-07-06T13:24:31.613] _slurm_rpc_submit_batch_job: JobId=45835 InitPrio=19194 usec=502
[2022-07-06T13:24:32.289] sched: Allocate JobId=45835 NodeList=cpu01 #CPUs=64 Partition=cpu-opteron
[2022-07-06T13:24:33.643] _job_complete: JobId=45835 WEXITSTATUS 1
[2022-07-06T13:24:33.644] _job_complete: JobId=45835 done
[2022-07-06T13:26:21.351] _slurm_rpc_submit_batch_job: JobId=45836 InitPrio=19194 usec=414
[2022-07-06T13:26:21.430] sched: Allocate JobId=45836 NodeList=cpu01 #CPUs=64 Partition=cpu-opteron
[2022-07-06T13:26:23.851] _job_complete: JobId=45836 WEXITSTATUS 1
[2022-07-06T13:26:23.851] _job_complete: JobId=45836 done
[2022-07-06T13:27:57.916] _slurm_rpc_submit_batch_job: JobId=45837 InitPrio=19194 usec=453
[2022-07-06T13:27:58.678] sched: Allocate JobId=45837 NodeList=cpu01 #CPUs=64 Partition=cpu-opteron
[2022-07-06T13:30:15.238] _slurm_rpc_submit_batch_job: JobId=45838 InitPrio=19194 usec=483
[2022-07-06T13:30:15.867] sched: Allocate JobId=45838 NodeList=cpu05 #CPUs=64 Partition=cpu-opteron
[2022-07-06T13:31:37.991] _slurm_rpc_submit_batch_job: JobId=45839 InitPrio=19331 usec=418
[2022-07-06T13:31:38.981] sched: Allocate JobId=45839 NodeList=cpu11 #CPUs=48 Partition=cpu-opteron
[2022-07-06T13:46:37.683] _slurm_rpc_submit_batch_job: JobId=45840 InitPrio=20949 usec=480
[2022-07-06T13:47:08.217] _slurm_rpc_kill_job: REQUEST_KILL_JOB JobId=45840 uid 548200023
[2022-07-06T13:50:11.657] _slurm_rpc_submit_batch_job: JobId=45841 InitPrio=21000 usec=481
[2022-07-06T13:50:12.010] sched: Allocate JobId=45841 NodeList=gpu01 #CPUs=10 Partition=gpu-k10
[2022-07-06T13:52:04.951] _job_complete: JobId=45841 WEXITSTATUS 0
[2022-07-06T13:52:04.951] _job_complete: JobId=45841 done
[2022-07-06T13:54:25.719] _slurm_rpc_submit_batch_job: JobId=45842 InitPrio=21069 usec=566
[2022-07-06T13:54:26.431] sched: Allocate JobId=45842 NodeList=cpu10 #CPUs=2 Partition=cpu-opteron
[2022-07-06T13:54:29.892] _job_complete: JobId=45842 WEXITSTATUS 0
[2022-07-06T13:54:29.892] _job_complete: JobId=45842 done
[2022-07-06T13:54:41.425] _job_complete: JobId=45690 WEXITSTATUS 0
[2022-07-06T13:54:41.425] _job_complete: JobId=45690 done
[2022-07-06T13:55:57.724] _slurm_rpc_submit_batch_job: JobId=45843 InitPrio=21000 usec=428
[2022-07-06T13:55:58.558] sched: Allocate JobId=45843 NodeList=gpu01 #CPUs=10 Partition=gpu-k10
[2022-07-06T13:57:53.777] _job_complete: JobId=45843 WEXITSTATUS 0
[2022-07-06T13:57:53.778] _job_complete: JobId=45843 done
[2022-07-06T13:57:56.697] _slurm_rpc_submit_batch_job: JobId=45844 InitPrio=21000 usec=504
[2022-07-06T13:57:56.836] sched: Allocate JobId=45844 NodeList=gpu01 #CPUs=10 Partition=gpu-k10
[2022-07-06T13:58:31.254] _slurm_rpc_submit_batch_job: JobId=45845 InitPrio=21069 usec=439
[2022-07-06T13:58:31.887] sched: Allocate JobId=45845 NodeList=cpu10 #CPUs=2 Partition=cpu-opteron
[2022-07-06T13:58:35.141] _job_complete: JobId=45845 WEXITSTATUS 0
[2022-07-06T13:58:35.141] _job_complete: JobId=45845 done
[2022-07-06T13:59:50.440] _job_complete: JobId=45844 WEXITSTATUS 0
[2022-07-06T13:59:50.440] _job_complete: JobId=45844 done
[2022-07-06T14:00:32.944] _slurm_rpc_submit_batch_job: JobId=45846 InitPrio=21000 usec=489
[2022-07-06T14:00:33.058] sched: Allocate JobId=45846 NodeList=gpu01 #CPUs=10 Partition=gpu-k10
[2022-07-06T14:00:53.399] _slurm_rpc_submit_batch_job: JobId=45847 InitPrio=21069 usec=412
[2022-07-06T14:00:54.083] sched: Allocate JobId=45847 NodeList=cpu10 #CPUs=2 Partition=cpu-opteron
[2022-07-06T14:00:57.477] _job_complete: JobId=45847 WEXITSTATUS 0
[2022-07-06T14:00:57.477] _job_complete: JobId=45847 done
[2022-07-06T14:01:58.906] _slurm_rpc_submit_batch_job: JobId=45848 InitPrio=21000 usec=528
[2022-07-06T14:01:59.171] sched: Allocate JobId=45848 NodeList=gpu03 #CPUs=10 Partition=gpu-k10
[2022-07-06T14:02:26.337] _job_complete: JobId=45846 WEXITSTATUS 0
[2022-07-06T14:02:26.337] _job_complete: JobId=45846 done
[2022-07-06T14:03:32.159] _slurm_rpc_submit_batch_job: JobId=45849 InitPrio=21069 usec=653
[2022-07-06T14:03:32.395] sched: Allocate JobId=45849 NodeList=cpu10 #CPUs=2 Partition=cpu-opteron
[2022-07-06T14:03:35.449] _job_complete: JobId=45849 WEXITSTATUS 0
[2022-07-06T14:03:35.449] _job_complete: JobId=45849 done
[2022-07-06T14:03:55.319] _job_complete: JobId=45848 WEXITSTATUS 0
[2022-07-06T14:03:55.319] _job_complete: JobId=45848 done
[2022-07-06T14:04:20.763] _slurm_rpc_submit_batch_job: JobId=45850 InitPrio=21069 usec=445
[2022-07-06T14:04:21.463] sched: Allocate JobId=45850 NodeList=cpu10 #CPUs=2 Partition=cpu-opteron
[2022-07-06T14:04:23.953] _job_complete: JobId=45850 WEXITSTATUS 0
[2022-07-06T14:04:23.953] _job_complete: JobId=45850 done
[2022-07-06T14:06:01.764] _slurm_rpc_submit_batch_job: JobId=45851 InitPrio=21069 usec=459
[2022-07-06T14:06:02.602] sched: Allocate JobId=45851 NodeList=cpu10 #CPUs=2 Partition=cpu-opteron
[2022-07-06T14:06:05.692] _job_complete: JobId=45851 WEXITSTATUS 0
[2022-07-06T14:06:05.692] _job_complete: JobId=45851 done
[2022-07-06T14:07:08.103] _slurm_rpc_submit_batch_job: JobId=45852 InitPrio=21000 usec=537
[2022-07-06T14:07:08.694] sched: Allocate JobId=45852 NodeList=gpu01 #CPUs=10 Partition=gpu-k10
[2022-07-06T14:08:50.366] _job_complete: JobId=45852 WEXITSTATUS 0
[2022-07-06T14:08:50.366] _job_complete: JobId=45852 done
[2022-07-06T14:11:08.750] _slurm_rpc_submit_batch_job: JobId=45853 InitPrio=21069 usec=428
[2022-07-06T14:11:09.167] sched: Allocate JobId=45853 NodeList=cpu10 #CPUs=2 Partition=cpu-opteron
[2022-07-06T14:11:12.053] _job_complete: JobId=45853 WEXITSTATUS 0
[2022-07-06T14:11:12.053] _job_complete: JobId=45853 done
[2022-07-06T14:49:49.254] _slurm_rpc_submit_batch_job: JobId=45854 InitPrio=20949 usec=663
[2022-07-06T14:49:49.307] sched: Allocate JobId=45854 NodeList=cpu09 #CPUs=16 Partition=cpu-opteron
[2022-07-06T14:49:50.960] _job_complete: JobId=45854 WEXITSTATUS 0
[2022-07-06T14:49:50.960] _job_complete: JobId=45854 done
[2022-07-06T14:50:46.209] _slurm_rpc_submit_batch_job: JobId=45855 InitPrio=20949 usec=394
[2022-07-06T14:50:46.382] sched: Allocate JobId=45855 NodeList=cpu09 #CPUs=16 Partition=cpu-opteron
[2022-07-06T14:50:47.324] _job_complete: JobId=45855 WEXITSTATUS 1
[2022-07-06T14:50:47.324] _job_complete: JobId=45855 done
[2022-07-06T14:51:47.968] _job_complete: JobId=45554 WEXITSTATUS 0
[2022-07-06T14:51:47.968] _job_complete: JobId=45554 done
[2022-07-06T14:51:48.340] sched: Allocate JobId=45788 NodeList=cpu15 #CPUs=16 Partition=cpu-epyc
[2022-07-06T14:51:56.288] _slurm_rpc_submit_batch_job: JobId=45856 InitPrio=20949 usec=431
[2022-07-06T14:51:56.480] sched: Allocate JobId=45856 NodeList=cpu09 #CPUs=16 Partition=cpu-opteron
[2022-07-06T14:51:57.434] _job_complete: JobId=45856 WEXITSTATUS 1
[2022-07-06T14:51:57.434] _job_complete: JobId=45856 done
[2022-07-06T14:55:19.242] _slurm_rpc_submit_batch_job: JobId=45857 InitPrio=20949 usec=437
[2022-07-06T14:55:19.905] sched: Allocate JobId=45857 NodeList=cpu09 #CPUs=16 Partition=cpu-opteron
[2022-07-06T14:55:20.926] _job_complete: JobId=45857 WEXITSTATUS 1
[2022-07-06T14:55:20.926] _job_complete: JobId=45857 done
[2022-07-06T14:56:43.992] _slurm_rpc_submit_batch_job: JobId=45858 InitPrio=20949 usec=588
[2022-07-06T14:56:44.024] sched: Allocate JobId=45858 NodeList=cpu09 #CPUs=16 Partition=cpu-opteron
[2022-07-06T14:56:44.963] _job_complete: JobId=45858 WEXITSTATUS 1
[2022-07-06T14:56:44.963] _job_complete: JobId=45858 done
[2022-07-06T15:06:08.255] _slurm_rpc_submit_batch_job: JobId=45859 InitPrio=20949 usec=430
[2022-07-06T15:06:09.035] sched: Allocate JobId=45859 NodeList=cpu09 #CPUs=16 Partition=cpu-opteron
[2022-07-06T15:06:10.043] _job_complete: JobId=45859 WEXITSTATUS 1
[2022-07-06T15:06:10.043] _job_complete: JobId=45859 done
[2022-07-06T15:43:57.961] _slurm_rpc_submit_batch_job: JobId=45860 InitPrio=26022 usec=431
[2022-07-06T15:43:58.778] sched: Allocate JobId=45860 NodeList=cpu15 #CPUs=20 Partition=cpu-epyc
[2022-07-06T15:44:02.728] _job_complete: JobId=45860 WEXITSTATUS 1
[2022-07-06T15:44:02.728] _job_complete: JobId=45860 done
[2022-07-06T15:44:24.506] _slurm_rpc_submit_batch_job: JobId=45861 InitPrio=26022 usec=375
[2022-07-06T15:44:24.801] sched: Allocate JobId=45861 NodeList=cpu15 #CPUs=20 Partition=cpu-epyc
[2022-07-06T15:44:37.168] _job_complete: JobId=45861 WEXITSTATUS 0
[2022-07-06T15:44:37.168] _job_complete: JobId=45861 done
[2022-07-06T16:10:34.063] _slurm_rpc_submit_batch_job: JobId=45862 InitPrio=26022 usec=545
[2022-07-06T16:10:34.636] sched: Allocate JobId=45862 NodeList=cpu15 #CPUs=20 Partition=cpu-epyc
[2022-07-06T16:11:07.757] _job_complete: JobId=45862 WEXITSTATUS 0
[2022-07-06T16:11:07.757] _job_complete: JobId=45862 done
[2022-07-06T16:22:21.621] _job_complete: JobId=45787 WEXITSTATUS 0
[2022-07-06T16:22:21.621] _job_complete: JobId=45787 done
[2022-07-06T16:22:21.896] sched: Allocate JobId=45789 NodeList=cpu12 #CPUs=16 Partition=cpu-epyc
[2022-07-06T16:51:26.671] _slurm_rpc_submit_batch_job: JobId=45863 InitPrio=22899 usec=431
[2022-07-06T16:51:27.059] sched: Allocate JobId=45863 NodeList=cpu09 #CPUs=8 Partition=cpu-opteron
[2022-07-06T17:03:39.176] _slurm_rpc_submit_batch_job: JobId=45864 InitPrio=26022 usec=442
[2022-07-06T17:03:39.398] sched: Allocate JobId=45864 NodeList=cpu15 #CPUs=20 Partition=cpu-epyc
[2022-07-06T17:03:56.733] _job_complete: JobId=45864 WEXITSTATUS 0
[2022-07-06T17:03:56.733] _job_complete: JobId=45864 done
[2022-07-06T17:05:01.495] _job_complete: JobId=45705 WEXITSTATUS 0
[2022-07-06T17:05:01.495] _job_complete: JobId=45705 done
[2022-07-06T17:24:31.156] _slurm_rpc_submit_batch_job: JobId=45865 InitPrio=20001 usec=464
[2022-07-06T17:24:31.701] sched: Allocate JobId=45865 NodeList=cpu03 #CPUs=64 Partition=cpu-opteron
[2022-07-06T18:37:55.281] _slurm_rpc_kill_job: REQUEST_KILL_JOB JobId=45557 uid 548200017
[2022-07-06T18:40:33.674] _pick_best_nodes: JobId=45866 never runnable in partition cpu-epyc
[2022-07-06T18:40:33.675] _slurm_rpc_submit_batch_job: Requested node configuration is not available
[2022-07-06T18:41:57.293] _slurm_rpc_submit_batch_job: JobId=45867 InitPrio=19331 usec=417
[2022-07-06T18:52:12.422] _slurm_rpc_submit_batch_job: JobId=45868 InitPrio=25920 usec=448
[2022-07-06T18:52:12.871] sched: Allocate JobId=45868 NodeList=cpu13 #CPUs=32 Partition=cpu-epyc
[2022-07-06T18:52:56.160] _job_complete: JobId=45868 WEXITSTATUS 0
[2022-07-06T18:52:56.160] _job_complete: JobId=45868 done
[2022-07-06T18:55:07.537] _slurm_rpc_submit_batch_job: JobId=45869 InitPrio=19194 usec=366
[2022-07-06T18:55:19.508] _slurm_rpc_kill_job: REQUEST_KILL_JOB JobId=44851 uid 548200017
[2022-07-06T18:55:40.558] sched: Allocate JobId=45869 NodeList=cpu08 #CPUs=64 Partition=cpu-opteron
[2022-07-06T19:10:51.277] _slurm_rpc_submit_batch_job: JobId=45870 InitPrio=25920 usec=510
[2022-07-06T19:10:52.084] sched: Allocate JobId=45870 NodeList=cpu13 #CPUs=32 Partition=cpu-epyc
[2022-07-06T19:11:12.185] _job_complete: JobId=45870 WEXITSTATUS 0
[2022-07-06T19:11:12.185] _job_complete: JobId=45870 done
[2022-07-06T19:25:30.871] _slurm_rpc_submit_batch_job: JobId=45871 InitPrio=25920 usec=459
[2022-07-06T19:25:30.909] sched: Allocate JobId=45871 NodeList=cpu13 #CPUs=32 Partition=cpu-epyc
[2022-07-06T19:25:36.813] _job_complete: JobId=45871 WEXITSTATUS 1
[2022-07-06T19:25:36.814] _job_complete: JobId=45871 done
[2022-07-06T20:01:34.327] _job_complete: JobId=45788 WEXITSTATUS 0
[2022-07-06T20:01:34.327] _job_complete: JobId=45788 done
[2022-07-06T20:01:34.566] sched: Allocate JobId=45790 NodeList=cpu15 #CPUs=16 Partition=cpu-epyc
[2022-07-06T20:36:00.592] _slurm_rpc_submit_batch_job: JobId=45872 InitPrio=25920 usec=485
[2022-07-06T20:36:01.261] sched/backfill: _start_job: Started JobId=45872 in cpu-epyc on cpu13
[2022-07-06T20:36:08.009] _job_complete: JobId=45872 WEXITSTATUS 0
[2022-07-06T20:36:08.009] _job_complete: JobId=45872 done
[2022-07-06T20:47:27.555] _slurm_rpc_submit_batch_job: JobId=45873 InitPrio=25920 usec=404
[2022-07-06T20:47:27.796] sched: Allocate JobId=45873 NodeList=cpu13 #CPUs=32 Partition=cpu-epyc
[2022-07-06T20:48:43.042] _job_complete: JobId=45873 WEXITSTATUS 0
[2022-07-06T20:48:43.042] _job_complete: JobId=45873 done
[2022-07-06T21:02:02.148] _job_complete: JobId=45863 WEXITSTATUS 0
[2022-07-06T21:02:02.148] _job_complete: JobId=45863 done
[2022-07-06T21:16:43.981] Time limit exhausted for JobId=45379
[2022-07-06T21:16:45.862] sched: Allocate JobId=45791 NodeList=cpu14 #CPUs=16 Partition=cpu-epyc
[2022-07-06T21:42:15.771] _job_complete: JobId=45789 WEXITSTATUS 0
[2022-07-06T21:42:15.771] _job_complete: JobId=45789 done
[2022-07-06T21:42:16.052] sched: Allocate JobId=45792 NodeList=cpu12 #CPUs=16 Partition=cpu-epyc
[2022-07-06T21:52:37.526] _slurm_rpc_submit_batch_job: JobId=45874 InitPrio=20812 usec=508
[2022-07-06T21:52:38.105] _slurm_rpc_submit_batch_job: JobId=45875 InitPrio=25920 usec=550
[2022-07-06T21:52:40.823] sched: Allocate JobId=45875 NodeList=cpu13 #CPUs=32 Partition=cpu-epyc
[2022-07-06T21:52:47.170] _job_complete: JobId=45875 WEXITSTATUS 0
[2022-07-06T21:52:47.170] _job_complete: JobId=45875 done
[2022-07-06T21:53:03.787] _slurm_rpc_kill_job: REQUEST_KILL_JOB JobId=45874 uid 548200023
[2022-07-06T21:53:43.768] _slurm_rpc_submit_batch_job: JobId=45876 InitPrio=20949 usec=409
[2022-07-06T21:53:43.927] sched: Allocate JobId=45876 NodeList=cpu15 #CPUs=16 Partition=cpu-epyc
[2022-07-06T21:54:04.500] _job_complete: JobId=45876 WEXITSTATUS 0
[2022-07-06T21:54:04.500] _job_complete: JobId=45876 done
[2022-07-06T21:56:41.571] _slurm_rpc_submit_batch_job: JobId=45877 InitPrio=26022 usec=443
[2022-07-06T21:56:42.165] sched: Allocate JobId=45877 NodeList=cpu15 #CPUs=20 Partition=cpu-epyc
[2022-07-06T21:56:48.228] _slurm_rpc_submit_batch_job: JobId=45878 InitPrio=20949 usec=375
[2022-07-06T21:56:49.175] sched: Allocate JobId=45878 NodeList=cpu13 #CPUs=16 Partition=cpu-epyc
[2022-07-06T21:57:11.450] _job_complete: JobId=45878 WEXITSTATUS 0
[2022-07-06T21:57:11.450] _job_complete: JobId=45878 done
[2022-07-06T21:57:22.150] _slurm_rpc_submit_batch_job: JobId=45879 InitPrio=20949 usec=421
[2022-07-06T21:57:22.221] sched: Allocate JobId=45879 NodeList=cpu13 #CPUs=16 Partition=cpu-epyc
[2022-07-06T21:57:23.057] _job_complete: JobId=45879 WEXITSTATUS 1
[2022-07-06T21:57:23.057] _job_complete: JobId=45879 done
[2022-07-06T21:58:11.395] _slurm_rpc_submit_batch_job: JobId=45880 InitPrio=20949 usec=397
[2022-07-06T21:58:11.460] sched: Allocate JobId=45880 NodeList=cpu13 #CPUs=16 Partition=cpu-epyc
[2022-07-06T21:58:32.081] _job_complete: JobId=45880 WEXITSTATUS 0
[2022-07-06T21:58:32.081] _job_complete: JobId=45880 done
[2022-07-06T21:59:09.826] _slurm_rpc_submit_batch_job: JobId=45881 InitPrio=26022 usec=482
[2022-07-06T21:59:10.544] sched: Allocate JobId=45881 NodeList=cpu13 #CPUs=20 Partition=cpu-epyc
[2022-07-06T21:59:13.689] _job_complete: JobId=45881 WEXITSTATUS 1
[2022-07-06T21:59:13.689] _job_complete: JobId=45881 done
[2022-07-06T21:59:39.631] _slurm_rpc_submit_batch_job: JobId=45882 InitPrio=26022 usec=460
[2022-07-06T21:59:40.585] sched: Allocate JobId=45882 NodeList=cpu13 #CPUs=20 Partition=cpu-epyc
[2022-07-06T22:01:12.693] _slurm_rpc_submit_batch_job: JobId=45883 InitPrio=20949 usec=472
[2022-07-06T22:02:01.575] _slurm_rpc_submit_batch_job: JobId=45884 InitPrio=20949 usec=429
[2022-07-06T22:02:49.885] _slurm_rpc_submit_batch_job: JobId=45885 InitPrio=20949 usec=430
[2022-07-06T22:03:28.573] _slurm_rpc_submit_batch_job: JobId=45886 InitPrio=20949 usec=434
[2022-07-06T22:04:08.156] _slurm_rpc_kill_job: REQUEST_KILL_JOB JobId=45883 uid 548200023
[2022-07-06T22:04:11.170] _slurm_rpc_kill_job: REQUEST_KILL_JOB JobId=45886 uid 548200023
[2022-07-06T22:04:15.568] _slurm_rpc_kill_job: REQUEST_KILL_JOB JobId=45885 uid 548200023
[2022-07-06T22:04:16.910] _slurm_rpc_kill_job: REQUEST_KILL_JOB JobId=45884 uid 548200023
[2022-07-06T22:04:31.944] _slurm_rpc_submit_batch_job: JobId=45887 InitPrio=20983 usec=445
[2022-07-06T22:04:32.078] sched: Allocate JobId=45887 NodeList=cpu13 #CPUs=12 Partition=cpu-epyc
[2022-07-06T22:04:55.609] _job_complete: JobId=45887 WEXITSTATUS 0
[2022-07-06T22:04:55.610] _job_complete: JobId=45887 done
[2022-07-06T22:05:30.150] _slurm_rpc_submit_batch_job: JobId=45888 InitPrio=20983 usec=408
[2022-07-06T22:05:30.158] sched: Allocate JobId=45888 NodeList=cpu13 #CPUs=12 Partition=cpu-epyc
[2022-07-06T22:05:30.931] _job_complete: JobId=45888 WEXITSTATUS 1
[2022-07-06T22:05:30.931] _job_complete: JobId=45888 done
[2022-07-06T22:05:53.870] _slurm_rpc_submit_batch_job: JobId=45889 InitPrio=20983 usec=516
[2022-07-06T22:05:54.190] sched: Allocate JobId=45889 NodeList=cpu13 #CPUs=12 Partition=cpu-epyc
[2022-07-06T22:06:17.984] _job_complete: JobId=45889 WEXITSTATUS 0
[2022-07-06T22:06:17.984] _job_complete: JobId=45889 done
[2022-07-06T22:06:20.945] _slurm_rpc_submit_batch_job: JobId=45890 InitPrio=20983 usec=409
[2022-07-06T22:06:21.227] sched: Allocate JobId=45890 NodeList=cpu13 #CPUs=12 Partition=cpu-epyc
[2022-07-06T22:06:44.682] _job_complete: JobId=45890 WEXITSTATUS 0
[2022-07-06T22:06:44.683] _job_complete: JobId=45890 done
[2022-07-06T22:08:23.213] _slurm_rpc_submit_batch_job: JobId=45891 InitPrio=20983 usec=423
[2022-07-06T22:08:23.570] sched: Allocate JobId=45891 NodeList=cpu13 #CPUs=12 Partition=cpu-epyc
[2022-07-06T22:08:57.790] _slurm_rpc_submit_batch_job: JobId=45892 InitPrio=20983 usec=583
[2022-07-06T22:09:30.883] _slurm_rpc_submit_batch_job: JobId=45893 InitPrio=20983 usec=476
[2022-07-06T22:09:51.620] _job_complete: JobId=45891 WEXITSTATUS 0
[2022-07-06T22:09:51.620] _job_complete: JobId=45891 done
[2022-07-06T22:09:51.902] sched: Allocate JobId=45892 NodeList=cpu13 #CPUs=12 Partition=cpu-epyc
[2022-07-06T22:10:11.742] _slurm_rpc_submit_batch_job: JobId=45894 InitPrio=20983 usec=427
[2022-07-06T22:10:52.135] _slurm_rpc_submit_batch_job: JobId=45895 InitPrio=20983 usec=537
[2022-07-06T22:11:20.920] _slurm_rpc_submit_batch_job: JobId=45896 InitPrio=20983 usec=411
[2022-07-06T22:11:26.739] _job_complete: JobId=45892 WEXITSTATUS 0
[2022-07-06T22:11:26.740] _job_complete: JobId=45892 done
[2022-07-06T22:11:27.015] sched: Allocate JobId=45893 NodeList=cpu13 #CPUs=12 Partition=cpu-epyc
[2022-07-06T22:13:05.373] _job_complete: JobId=45893 WEXITSTATUS 0
[2022-07-06T22:13:05.373] _job_complete: JobId=45893 done
[2022-07-06T22:13:05.683] sched: Allocate JobId=45894 NodeList=cpu13 #CPUs=12 Partition=cpu-epyc
[2022-07-06T22:14:42.971] _job_complete: JobId=45894 WEXITSTATUS 0
[2022-07-06T22:14:42.972] _job_complete: JobId=45894 done
[2022-07-06T22:14:43.226] sched: Allocate JobId=45895 NodeList=cpu13 #CPUs=12 Partition=cpu-epyc
[2022-07-06T22:16:17.581] _job_complete: JobId=45895 WEXITSTATUS 0
[2022-07-06T22:16:17.581] _job_complete: JobId=45895 done
[2022-07-06T22:16:17.832] sched: Allocate JobId=45896 NodeList=cpu13 #CPUs=12 Partition=cpu-epyc
[2022-07-06T22:17:57.145] _job_complete: JobId=45896 WEXITSTATUS 0
[2022-07-06T22:17:57.145] _job_complete: JobId=45896 done
[2022-07-06T22:20:30.650] _job_complete: JobId=45781 WEXITSTATUS 0
[2022-07-06T22:20:30.650] _job_complete: JobId=45781 done
[2022-07-06T22:23:55.769] _slurm_rpc_submit_batch_job: JobId=45897 InitPrio=25988 usec=438
[2022-07-06T22:45:03.411] _job_complete: JobId=45421 WEXITSTATUS 0
[2022-07-06T22:45:03.416] _job_complete: JobId=45421 done
[2022-07-06T22:58:54.097] _job_complete: JobId=45877 WEXITSTATUS 0
[2022-07-06T22:58:54.097] _job_complete: JobId=45877 done
[2022-07-06T23:18:06.318] _slurm_rpc_kill_job: REQUEST_KILL_JOB JobId=45897 uid 548200084
[2022-07-06T23:18:24.304] _slurm_rpc_submit_batch_job: JobId=45898 InitPrio=25719 usec=450
[2022-07-06T23:20:56.351] _slurm_rpc_submit_batch_job: JobId=45899 InitPrio=25856 usec=469
[2022-07-06T23:20:56.407] sched: Allocate JobId=45899 NodeList=cpu13 #CPUs=8 Partition=cpu-epyc
[2022-07-06T23:20:59.105] _job_complete: JobId=45899 WEXITSTATUS 0
[2022-07-06T23:20:59.105] _job_complete: JobId=45899 done
[2022-07-06T23:23:26.643] _slurm_rpc_submit_batch_job: JobId=45900 InitPrio=25856 usec=488
[2022-07-06T23:23:26.702] sched: Allocate JobId=45900 NodeList=cpu09 #CPUs=8 Partition=cpu-opteron
[2022-07-06T23:29:16.491] _job_complete: JobId=45900 WEXITSTATUS 0
[2022-07-06T23:29:16.491] _job_complete: JobId=45900 done
[2022-07-06T23:42:25.883] _job_complete: JobId=45882 WEXITSTATUS 0
[2022-07-06T23:42:25.883] _job_complete: JobId=45882 done
[2022-07-06T23:42:26.133] sched: Allocate JobId=45898 NodeList=cpu13 #CPUs=24 Partition=cpu-epyc
[2022-07-06T23:46:27.948] _slurm_rpc_submit_batch_job: JobId=45901 InitPrio=25587 usec=439
[2022-07-06T23:46:28.096] sched: Allocate JobId=45901 NodeList=cpu13 #CPUs=8 Partition=cpu-epyc
[2022-07-06T23:48:22.221] _job_complete: JobId=45901 WEXITSTATUS 0
[2022-07-06T23:48:22.221] _job_complete: JobId=45901 done
[2022-07-07T00:14:06.616] sched: _slurm_rpc_allocate_resources JobId=45902 NodeList=(null) usec=1163
[2022-07-07T00:14:08.395] sched: Allocate JobId=45902 NodeList=cpu09 #CPUs=8 Partition=cpu-opteron
[2022-07-07T00:18:52.797] _slurm_rpc_submit_batch_job: JobId=45903 InitPrio=19840 usec=441
[2022-07-07T00:18:52.928] sched: Allocate JobId=45903 NodeList=cpu15 #CPUs=20 Partition=cpu-epyc
[2022-07-07T00:23:37.643] _job_complete: JobId=45902 WEXITSTATUS 0
[2022-07-07T00:23:37.643] _job_complete: JobId=45902 done
[2022-07-07T00:25:55.919] _slurm_rpc_submit_batch_job: JobId=45904 InitPrio=19942 usec=386
[2022-07-07T00:25:56.676] sched: Allocate JobId=45904 NodeList=cpu13 #CPUs=8 Partition=cpu-epyc
[2022-07-07T01:12:06.323] _job_complete: JobId=45790 WEXITSTATUS 0
[2022-07-07T01:12:06.324] _job_complete: JobId=45790 done
[2022-07-07T01:12:06.574] sched: Allocate JobId=45793 NodeList=cpu15 #CPUs=16 Partition=cpu-epyc
[2022-07-07T01:55:40.230] _job_complete: JobId=45898 WEXITSTATUS 0
[2022-07-07T01:55:40.230] _job_complete: JobId=45898 done
[2022-07-07T02:41:35.717] _job_complete: JobId=45700 WEXITSTATUS 0
[2022-07-07T02:41:35.717] _job_complete: JobId=45700 done
[2022-07-07T02:44:21.294] _job_complete: JobId=45625 WEXITSTATUS 0
[2022-07-07T02:44:21.295] _job_complete: JobId=45625 done
[2022-07-07T02:59:06.303] _job_complete: JobId=45791 WEXITSTATUS 0
[2022-07-07T02:59:06.304] _job_complete: JobId=45791 done
[2022-07-07T02:59:06.585] sched: Allocate JobId=45794 NodeList=cpu14 #CPUs=16 Partition=cpu-epyc
[2022-07-07T03:18:04.671] _job_complete: JobId=45792 WEXITSTATUS 0
[2022-07-07T03:18:04.671] _job_complete: JobId=45792 done
[2022-07-07T03:18:04.913] sched: Allocate JobId=45795 NodeList=cpu12 #CPUs=16 Partition=cpu-epyc
[2022-07-07T04:30:43.807] _slurm_rpc_submit_batch_job: JobId=45905 InitPrio=21687 usec=571
[2022-07-07T04:30:43.977] sched: Allocate JobId=45905 NodeList=cpu13 #CPUs=24 Partition=cpu-epyc
[2022-07-07T04:33:19.110] _slurm_rpc_submit_batch_job: JobId=45906 InitPrio=21619 usec=735
[2022-07-07T04:33:19.284] sched: Allocate JobId=45906 NodeList=cpu09 #CPUs=32 Partition=cpu-opteron
[2022-07-07T04:33:19.934] _job_complete: JobId=45906 WEXITSTATUS 1
[2022-07-07T04:33:19.934] _job_complete: JobId=45906 done
[2022-07-07T04:34:36.263] _slurm_rpc_submit_batch_job: JobId=45907 InitPrio=21619 usec=558
[2022-07-07T04:34:36.393] sched: Allocate JobId=45907 NodeList=cpu09 #CPUs=32 Partition=cpu-opteron
[2022-07-07T06:17:02.288] _job_complete: JobId=45821 WEXITSTATUS 0
[2022-07-07T06:17:02.288] _job_complete: JobId=45821 done
[2022-07-07T06:17:02.634] sched: Allocate JobId=45796 NodeList=cpu14 #CPUs=16 Partition=cpu-epyc
[2022-07-07T06:21:47.450] _job_complete: JobId=45905 WEXITSTATUS 0
[2022-07-07T06:21:47.450] _job_complete: JobId=45905 done
[2022-07-07T06:52:55.498] _job_complete: JobId=45793 WEXITSTATUS 0
[2022-07-07T06:52:55.498] _job_complete: JobId=45793 done
[2022-07-07T07:02:33.186] _slurm_rpc_submit_batch_job: JobId=45908 InitPrio=24913 usec=464
[2022-07-07T07:02:33.677] sched: Allocate JobId=45908 NodeList=cpu13 #CPUs=24 Partition=cpu-epyc
[2022-07-07T07:03:57.432] _job_complete: JobId=45908 WEXITSTATUS 0
[2022-07-07T07:03:57.432] _job_complete: JobId=45908 done
[2022-07-07T07:04:05.980] _slurm_rpc_submit_batch_job: JobId=45909 InitPrio=25050 usec=416
[2022-07-07T07:04:08.843] sched: Allocate JobId=45909 NodeList=cpu14 #CPUs=8 Partition=cpu-epyc
[2022-07-07T07:04:11.958] _job_complete: JobId=45909 WEXITSTATUS 0
[2022-07-07T07:04:11.959] _job_complete: JobId=45909 done
[2022-07-07T07:20:29.275] _slurm_rpc_submit_batch_job: JobId=45910 InitPrio=25050 usec=458
[2022-07-07T07:20:29.676] sched: Allocate JobId=45910 NodeList=cpu14 #CPUs=8 Partition=cpu-epyc
[2022-07-07T07:20:32.486] _job_complete: JobId=45910 WEXITSTATUS 1
[2022-07-07T07:20:32.486] _job_complete: JobId=45910 done
[2022-07-07T07:21:36.946] _job_complete: JobId=45687 WEXITSTATUS 1
[2022-07-07T07:21:36.946] _job_complete: JobId=45687 done
[2022-07-07T07:27:39.340] _slurm_rpc_submit_batch_job: JobId=45911 InitPrio=24913 usec=425
[2022-07-07T07:27:39.570] sched: Allocate JobId=45911 NodeList=cpu13 #CPUs=24 Partition=cpu-epyc
[2022-07-07T07:42:30.087] _slurm_rpc_submit_batch_job: JobId=45912 InitPrio=25050 usec=414
[2022-07-07T07:42:30.270] sched: Allocate JobId=45912 NodeList=cpu11 #CPUs=8 Partition=cpu-opteron
[2022-07-07T07:42:35.530] _job_complete: JobId=45912 WEXITSTATUS 0
[2022-07-07T07:42:35.530] _job_complete: JobId=45912 done
[2022-07-07T07:46:56.802] _slurm_rpc_submit_batch_job: JobId=45913 InitPrio=24981 usec=656
[2022-07-07T07:46:57.683] sched: Allocate JobId=45913 NodeList=cpu14 #CPUs=16 Partition=cpu-epyc
[2022-07-07T08:12:52.443] _job_complete: JobId=45911 WEXITSTATUS 0
[2022-07-07T08:12:52.443] _job_complete: JobId=45911 done
[2022-07-07T08:30:07.826] _job_complete: JobId=45794 WEXITSTATUS 0
[2022-07-07T08:30:07.826] _job_complete: JobId=45794 done
[2022-07-07T08:36:01.317] _slurm_rpc_submit_batch_job: JobId=45914 InitPrio=24913 usec=534
[2022-07-07T08:36:01.453] sched: Allocate JobId=45914 NodeList=cpu13 #CPUs=24 Partition=cpu-epyc
[2022-07-07T08:36:05.488] _job_complete: JobId=45914 WEXITSTATUS 1
[2022-07-07T08:36:05.489] _job_complete: JobId=45914 done
[2022-07-07T08:42:41.833] _slurm_rpc_submit_batch_job: JobId=45915 InitPrio=24913 usec=443
[2022-07-07T08:42:42.268] sched: Allocate JobId=45915 NodeList=cpu13 #CPUs=24 Partition=cpu-epyc
[2022-07-07T08:58:41.555] _job_complete: JobId=45795 WEXITSTATUS 0
[2022-07-07T08:58:41.555] _job_complete: JobId=45795 done
[2022-07-07T09:10:36.762] _slurm_rpc_kill_job: REQUEST_KILL_JOB JobId=45867 uid 548200017
[2022-07-07T09:10:50.927] _slurm_rpc_submit_batch_job: JobId=45916 InitPrio=19468 usec=486
[2022-07-07T09:16:11.869] _slurm_rpc_submit_batch_job: JobId=45917 InitPrio=20949 usec=419
[2022-07-07T09:16:11.926] sched: Allocate JobId=45917 NodeList=cpu11 #CPUs=16 Partition=cpu-opteron
[2022-07-07T09:17:11.947] _slurm_rpc_submit_batch_job: JobId=45918 InitPrio=20949 usec=477
[2022-07-07T09:17:34.622] _slurm_rpc_kill_job: REQUEST_KILL_JOB JobId=45918 uid 548200023
[2022-07-07T09:17:54.086] _slurm_rpc_submit_batch_job: JobId=45919 InitPrio=20949 usec=443
[2022-07-07T09:17:54.170] sched: Allocate JobId=45919 NodeList=cpu12 #CPUs=16 Partition=cpu-epyc
[2022-07-07T09:19:01.427] _job_complete: JobId=45919 WEXITSTATUS 0
[2022-07-07T09:19:01.427] _job_complete: JobId=45919 done
[2022-07-07T09:20:00.666] _job_complete: JobId=45917 WEXITSTATUS 0
[2022-07-07T09:20:00.666] _job_complete: JobId=45917 done
[2022-07-07T09:20:15.874] _slurm_rpc_submit_batch_job: JobId=45920 InitPrio=20949 usec=438
[2022-07-07T09:20:16.364] sched: Allocate JobId=45920 NodeList=cpu12 #CPUs=16 Partition=cpu-epyc
[2022-07-07T09:22:36.013] _slurm_rpc_kill_job: REQUEST_KILL_JOB JobId=45920 uid 548200023
[2022-07-07T09:23:27.042] _slurm_rpc_submit_batch_job: JobId=45921 InitPrio=20949 usec=362
[2022-07-07T09:23:27.782] sched: Allocate JobId=45921 NodeList=cpu12 #CPUs=16 Partition=cpu-epyc
[2022-07-07T09:24:44.403] _slurm_rpc_submit_batch_job: JobId=45922 InitPrio=20949 usec=460
[2022-07-07T09:24:44.886] sched: Allocate JobId=45922 NodeList=cpu14 #CPUs=16 Partition=cpu-epyc
[2022-07-07T09:26:21.677] _slurm_rpc_submit_batch_job: JobId=45923 InitPrio=20949 usec=452
[2022-07-07T09:26:22.020] sched: Allocate JobId=45923 NodeList=cpu15 #CPUs=16 Partition=cpu-epyc
[2022-07-07T09:27:25.889] _slurm_rpc_submit_batch_job: JobId=45924 InitPrio=20949 usec=724
[2022-07-07T09:27:26.105] sched: Allocate JobId=45924 NodeList=cpu11 #CPUs=16 Partition=cpu-opteron
[2022-07-07T09:27:45.951] _job_complete: JobId=45923 WEXITSTATUS 0
[2022-07-07T09:27:45.951] _job_complete: JobId=45923 done
[2022-07-07T09:28:18.719] _job_complete: JobId=45924 WEXITSTATUS 0
[2022-07-07T09:28:18.719] _job_complete: JobId=45924 done
[2022-07-07T09:31:23.829] _job_complete: JobId=45913 WEXITSTATUS 0
[2022-07-07T09:31:23.829] _job_complete: JobId=45913 done
[2022-07-07T09:45:14.955] error: _find_node_record: lookup failure for node "=cpu10"
[2022-07-07T09:47:45.629] _job_complete: JobId=45921 WEXITSTATUS 0
[2022-07-07T09:47:45.629] _job_complete: JobId=45921 done
[2022-07-07T09:49:29.771] _job_complete: JobId=45922 WEXITSTATUS 0
[2022-07-07T09:49:29.771] _job_complete: JobId=45922 done
[2022-07-07T09:49:38.636] sched: Allocate JobId=45916 NodeList=cpu14 #CPUs=32 Partition=cpu-epyc
[2022-07-07T10:02:18.622] _slurm_rpc_submit_batch_job: JobId=45925 InitPrio=21052 usec=542
[2022-07-07T10:02:19.106] sched: Allocate JobId=45925 NodeList=cpu11 #CPUs=4 Partition=cpu-opteron
[2022-07-07T10:03:13.667] _job_complete: JobId=45925 WEXITSTATUS 0
[2022-07-07T10:03:13.667] _job_complete: JobId=45925 done
[2022-07-07T10:07:28.840] _slurm_rpc_submit_batch_job: JobId=45926 InitPrio=20949 usec=368
[2022-07-07T10:07:29.623] sched: Allocate JobId=45926 NodeList=cpu12 #CPUs=16 Partition=cpu-epyc
[2022-07-07T10:26:54.949] _slurm_rpc_submit_batch_job: JobId=45927 InitPrio=26377 usec=562
[2022-07-07T10:26:55.770] sched: Allocate JobId=45927 NodeList=gpu02 #CPUs=10 Partition=gpu-titan
[2022-07-07T10:32:50.342] _job_complete: JobId=45926 WEXITSTATUS 0
[2022-07-07T10:32:50.342] _job_complete: JobId=45926 done
[2022-07-07T10:34:32.884] sched: _slurm_rpc_allocate_resources JobId=45928 NodeList=(null) usec=762
[2022-07-07T10:34:33.644] sched: Allocate JobId=45928 NodeList=cpu10 #CPUs=1 Partition=cpu-opteron
[2022-07-07T10:55:29.802] _job_complete: JobId=45915 WEXITSTATUS 0
[2022-07-07T10:55:29.803] _job_complete: JobId=45915 done
[2022-07-07T11:12:12.118] _slurm_rpc_submit_batch_job: JobId=45929 InitPrio=19959 usec=399
[2022-07-07T11:12:12.454] sched: Allocate JobId=45929 NodeList=gpu02 #CPUs=6 Partition=gpu-titan
[2022-07-07T11:27:46.461] _get_job_parts: invalid partition specified: gpu-5
[2022-07-07T11:27:46.461] _slurm_rpc_submit_batch_job: Invalid partition name specified
[2022-07-07T11:28:05.544] _slurm_rpc_submit_batch_job: JobId=45930 InitPrio=19874 usec=396
[2022-07-07T11:28:08.221] sched: Allocate JobId=45930 NodeList=gpu05 #CPUs=16 Partition=gpu-v100s
[2022-07-07T11:28:13.073] _job_complete: JobId=45930 WEXITSTATUS 1
[2022-07-07T11:28:13.073] _job_complete: JobId=45930 done
[2022-07-07T11:36:55.531] _slurm_rpc_submit_batch_job: JobId=45931 InitPrio=23637 usec=502
[2022-07-07T11:36:56.106] sched: Allocate JobId=45931 NodeList=cpu12 #CPUs=16 Partition=cpu-epyc
[2022-07-07T11:38:31.658] _slurm_rpc_submit_batch_job: JobId=45932 InitPrio=23637 usec=470
[2022-07-07T11:38:32.323] sched: Allocate JobId=45932 NodeList=cpu15 #CPUs=16 Partition=cpu-epyc
[2022-07-07T11:46:52.646] _slurm_rpc_submit_batch_job: JobId=45933 InitPrio=23637 usec=491
[2022-07-07T11:46:54.646] _slurm_rpc_submit_batch_job: JobId=45934 InitPrio=23637 usec=624
[2022-07-07T11:47:00.988] _slurm_rpc_submit_batch_job: JobId=45935 InitPrio=26377 usec=508
[2022-07-07T11:51:48.635] _job_complete: JobId=45796 WEXITSTATUS 0
[2022-07-07T11:51:48.635] _job_complete: JobId=45796 done
[2022-07-07T11:51:48.907] sched: Allocate JobId=45933 NodeList=cpu14 #CPUs=16 Partition=cpu-epyc
[2022-07-07T11:54:28.165] _slurm_rpc_submit_batch_job: JobId=45936 InitPrio=19874 usec=652
[2022-07-07T11:54:28.928] sched: Allocate JobId=45936 NodeList=gpu05 #CPUs=16 Partition=gpu-v100s
[2022-07-07T11:56:46.980] _job_complete: JobId=45936 WEXITSTATUS 1
[2022-07-07T11:56:46.980] _job_complete: JobId=45936 done
[2022-07-07T12:05:57.885] _job_complete: JobId=45929 WEXITSTATUS 0
[2022-07-07T12:05:57.885] _job_complete: JobId=45929 done
[2022-07-07T12:17:14.780] _slurm_rpc_submit_batch_job: JobId=45937 InitPrio=23637 usec=404
[2022-07-07T12:17:28.640] _slurm_rpc_submit_batch_job: JobId=45938 InitPrio=23637 usec=517
[2022-07-07T12:17:44.952] _slurm_rpc_submit_batch_job: JobId=45939 InitPrio=23637 usec=402
[2022-07-07T12:17:52.489] _slurm_rpc_submit_batch_job: JobId=45940 InitPrio=23637 usec=601
[2022-07-07T12:18:04.593] _slurm_rpc_submit_batch_job: JobId=45941 InitPrio=23637 usec=473
[2022-07-07T12:18:14.602] _slurm_rpc_submit_batch_job: JobId=45942 InitPrio=23637 usec=373
[2022-07-07T12:18:20.042] _slurm_rpc_submit_batch_job: JobId=45943 InitPrio=23637 usec=442
[2022-07-07T12:18:26.353] _slurm_rpc_submit_batch_job: JobId=45944 InitPrio=23637 usec=457
[2022-07-07T12:18:31.713] _slurm_rpc_submit_batch_job: JobId=45945 InitPrio=23637 usec=403
[2022-07-07T12:18:36.265] _slurm_rpc_submit_batch_job: JobId=45946 InitPrio=23637 usec=474
[2022-07-07T12:18:41.097] _slurm_rpc_submit_batch_job: JobId=45947 InitPrio=23637 usec=384
[2022-07-07T12:18:47.201] _slurm_rpc_submit_batch_job: JobId=45948 InitPrio=23637 usec=551
[2022-07-07T12:18:51.665] _slurm_rpc_submit_batch_job: JobId=45949 InitPrio=23637 usec=417
[2022-07-07T12:18:56.129] _slurm_rpc_submit_batch_job: JobId=45950 InitPrio=23637 usec=429
[2022-07-07T12:19:01.913] _slurm_rpc_submit_batch_job: JobId=45951 InitPrio=23637 usec=402
[2022-07-07T12:19:09.705] _slurm_rpc_submit_batch_job: JobId=45952 InitPrio=23637 usec=423
[2022-07-07T12:19:15.697] _slurm_rpc_submit_batch_job: JobId=45953 InitPrio=23637 usec=507
[2022-07-07T12:19:19.993] _slurm_rpc_submit_batch_job: JobId=45954 InitPrio=23637 usec=567
[2022-07-07T12:19:24.649] _slurm_rpc_submit_batch_job: JobId=45955 InitPrio=23637 usec=434
[2022-07-07T12:19:29.242] _slurm_rpc_submit_batch_job: JobId=45956 InitPrio=23637 usec=459
[2022-07-07T12:19:34.034] _slurm_rpc_submit_batch_job: JobId=45957 InitPrio=23637 usec=649
[2022-07-07T12:19:51.618] _slurm_rpc_submit_batch_job: JobId=45958 InitPrio=23637 usec=465
[2022-07-07T12:20:33.650] _slurm_rpc_submit_batch_job: JobId=45959 InitPrio=23637 usec=468
[2022-07-07T12:20:48.306] _slurm_rpc_submit_batch_job: JobId=45960 InitPrio=23637 usec=488
[2022-07-07T12:20:53.002] _slurm_rpc_submit_batch_job: JobId=45961 InitPrio=23637 usec=475
[2022-07-07T12:20:56.835] _slurm_rpc_submit_batch_job: JobId=45962 InitPrio=23637 usec=436
[2022-07-07T12:21:01.690] _slurm_rpc_submit_batch_job: JobId=45963 InitPrio=23637 usec=392
[2022-07-07T12:21:05.940] _slurm_rpc_submit_batch_job: JobId=45964 InitPrio=23637 usec=481
[2022-07-07T12:21:09.955] _slurm_rpc_submit_batch_job: JobId=45965 InitPrio=23637 usec=423
[2022-07-07T12:21:14.058] _slurm_rpc_submit_batch_job: JobId=45966 InitPrio=23637 usec=459
[2022-07-07T12:21:18.106] _slurm_rpc_submit_batch_job: JobId=45967 InitPrio=23637 usec=447
[2022-07-07T12:21:24.122] _slurm_rpc_submit_batch_job: JobId=45968 InitPrio=23637 usec=993
[2022-07-07T12:21:28.875] _slurm_rpc_submit_batch_job: JobId=45969 InitPrio=23637 usec=498
[2022-07-07T12:21:34.116] _slurm_rpc_submit_batch_job: JobId=45970 InitPrio=23637 usec=732
[2022-07-07T12:21:39.363] _slurm_rpc_submit_batch_job: JobId=45971 InitPrio=23637 usec=437
[2022-07-07T12:21:43.003] _slurm_rpc_submit_batch_job: JobId=45972 InitPrio=23637 usec=412
[2022-07-07T12:21:49.123] _slurm_rpc_submit_batch_job: JobId=45973 InitPrio=23637 usec=481
[2022-07-07T12:21:52.941] _slurm_rpc_submit_batch_job: JobId=45974 InitPrio=23637 usec=435
[2022-07-07T12:21:57.612] _slurm_rpc_submit_batch_job: JobId=45975 InitPrio=23637 usec=406
[2022-07-07T12:22:01.139] _slurm_rpc_submit_batch_job: JobId=45976 InitPrio=23637 usec=506
[2022-07-07T12:22:06.002] _slurm_rpc_submit_batch_job: JobId=45977 InitPrio=23637 usec=436
[2022-07-07T12:22:12.859] _slurm_rpc_submit_batch_job: JobId=45978 InitPrio=23637 usec=518
[2022-07-07T12:22:17.307] _slurm_rpc_submit_batch_job: JobId=45979 InitPrio=23637 usec=396
[2022-07-07T12:22:20.970] _slurm_rpc_submit_batch_job: JobId=45980 InitPrio=23637 usec=453
[2022-07-07T12:22:25.811] _slurm_rpc_submit_batch_job: JobId=45981 InitPrio=23637 usec=397
[2022-07-07T12:22:29.786] _slurm_rpc_submit_batch_job: JobId=45982 InitPrio=23637 usec=400
[2022-07-07T12:22:35.643] _slurm_rpc_submit_batch_job: JobId=45983 InitPrio=23637 usec=446
[2022-07-07T12:40:49.303] _slurm_rpc_submit_batch_job: JobId=45984 InitPrio=25519 usec=406
[2022-07-07T12:40:49.847] sched: Allocate JobId=45984 NodeList=cpu13 #CPUs=16 Partition=cpu-epyc
[2022-07-07T12:41:14.850] Time limit exhausted for JobId=45830
[2022-07-07T12:41:27.010] _slurm_rpc_kill_job: REQUEST_KILL_JOB JobId=45984 uid 548200003
[2022-07-07T12:41:44.892] Time limit exhausted for JobId=45831
[2022-07-07T12:42:20.789] _slurm_rpc_submit_batch_job: JobId=45985 InitPrio=25519 usec=459
[2022-07-07T12:42:20.942] sched: Allocate JobId=45985 NodeList=cpu13 #CPUs=16 Partition=cpu-epyc
[2022-07-07T12:42:36.138] _slurm_rpc_kill_job: REQUEST_KILL_JOB JobId=45985 uid 548200003
[2022-07-07T12:42:54.922] _slurm_rpc_submit_batch_job: JobId=45986 InitPrio=25519 usec=485
[2022-07-07T12:42:55.069] sched: Allocate JobId=45986 NodeList=cpu13 #CPUs=16 Partition=cpu-epyc
[2022-07-07T12:43:29.179] _slurm_rpc_kill_job: REQUEST_KILL_JOB JobId=45986 uid 548200003
[2022-07-07T12:43:44.136] Time limit exhausted for JobId=45834
[2022-07-07T12:43:44.464] _slurm_rpc_submit_batch_job: JobId=45987 InitPrio=25519 usec=445
[2022-07-07T12:43:45.138] sched: Allocate JobId=45987 NodeList=cpu13 #CPUs=16 Partition=cpu-epyc
[2022-07-07T12:43:52.226] _slurm_rpc_kill_job: REQUEST_KILL_JOB JobId=45987 uid 548200003
[2022-07-07T12:44:11.437] _slurm_rpc_submit_batch_job: JobId=45988 InitPrio=25519 usec=576
[2022-07-07T12:44:12.173] sched: Allocate JobId=45988 NodeList=cpu13 #CPUs=16 Partition=cpu-epyc
[2022-07-07T12:44:46.148] _job_complete: JobId=45988 WEXITSTATUS 137
[2022-07-07T12:44:46.148] _job_complete: JobId=45988 done
[2022-07-07T12:44:50.967] _job_complete: JobId=45931 WEXITSTATUS 0
[2022-07-07T12:44:50.967] _job_complete: JobId=45931 done
[2022-07-07T12:44:51.198] sched: Allocate JobId=45934 NodeList=cpu12 #CPUs=16 Partition=cpu-epyc
[2022-07-07T12:46:41.913] _slurm_rpc_submit_batch_job: JobId=45989 InitPrio=25519 usec=461
[2022-07-07T12:46:42.381] sched: Allocate JobId=45989 NodeList=cpu13 #CPUs=16 Partition=cpu-epyc
[2022-07-07T12:46:46.039] _job_complete: JobId=45989 WEXITSTATUS 137
[2022-07-07T12:46:46.039] _job_complete: JobId=45989 done
[2022-07-07T12:50:16.454] _slurm_rpc_submit_batch_job: JobId=45990 InitPrio=24776 usec=559
[2022-07-07T12:50:50.335] _slurm_rpc_kill_job: REQUEST_KILL_JOB JobId=45990 uid 548200084
[2022-07-07T12:51:07.525] _slurm_rpc_submit_batch_job: JobId=45991 InitPrio=24913 usec=410
[2022-07-07T12:51:08.885] sched: Allocate JobId=45991 NodeList=cpu13 #CPUs=24 Partition=cpu-epyc
[2022-07-07T12:51:14.924] _job_complete: JobId=45991 WEXITSTATUS 0
[2022-07-07T12:51:14.924] _job_complete: JobId=45991 done
[2022-07-07T12:52:20.579] _job_complete: JobId=45933 WEXITSTATUS 0
[2022-07-07T12:52:20.579] _job_complete: JobId=45933 done
[2022-07-07T12:52:20.843] sched: Allocate JobId=45937 NodeList=cpu14 #CPUs=16 Partition=cpu-epyc
[2022-07-07T12:52:36.297] _slurm_rpc_submit_batch_job: JobId=45992 InitPrio=25519 usec=439
[2022-07-07T12:52:37.029] sched: Allocate JobId=45992 NodeList=cpu13 #CPUs=16 Partition=cpu-epyc
[2022-07-07T12:52:55.625] _job_complete: JobId=45992 WEXITSTATUS 137
[2022-07-07T12:52:55.625] _job_complete: JobId=45992 done
[2022-07-07T12:53:48.886] _slurm_rpc_submit_batch_job: JobId=45993 InitPrio=25519 usec=461
[2022-07-07T12:53:49.161] sched: Allocate JobId=45993 NodeList=cpu13 #CPUs=16 Partition=cpu-epyc
[2022-07-07T12:55:05.034] _slurm_rpc_submit_batch_job: JobId=45994 InitPrio=19959 usec=429
[2022-07-07T12:55:13.714] _slurm_rpc_kill_job: REQUEST_KILL_JOB JobId=45993 uid 548200003
[2022-07-07T12:56:01.793] sched/backfill: _start_job: Started JobId=45994 in gpu-titan on gpu02
[2022-07-07T12:56:08.722] _slurm_rpc_kill_job: REQUEST_KILL_JOB JobId=45994 uid 548200021
[2022-07-07T12:56:39.154] _slurm_rpc_submit_batch_job: JobId=45995 InitPrio=25519 usec=528
[2022-07-07T12:56:39.394] sched: Allocate JobId=45995 NodeList=cpu13 #CPUs=16 Partition=cpu-epyc
[2022-07-07T12:56:42.888] _job_complete: JobId=45995 WEXITSTATUS 137
[2022-07-07T12:56:42.888] _job_complete: JobId=45995 done
[2022-07-07T12:57:44.116] _slurm_rpc_submit_batch_job: JobId=45996 InitPrio=19874 usec=593
[2022-07-07T12:57:44.652] sched: Allocate JobId=45996 NodeList=gpu01 #CPUs=16 Partition=gpu-k10
[2022-07-07T12:57:49.939] _slurm_rpc_submit_batch_job: JobId=45997 InitPrio=25519 usec=374
[2022-07-07T12:57:50.659] sched: Allocate JobId=45997 NodeList=cpu13 #CPUs=16 Partition=cpu-epyc
[2022-07-07T12:57:54.411] _job_complete: JobId=45997 WEXITSTATUS 137
[2022-07-07T12:57:54.411] _job_complete: JobId=45997 done
[2022-07-07T12:58:50.880] _job_complete: JobId=45932 WEXITSTATUS 0
[2022-07-07T12:58:50.880] _job_complete: JobId=45932 done
[2022-07-07T12:58:51.117] sched: Allocate JobId=45938 NodeList=cpu15 #CPUs=16 Partition=cpu-epyc
[2022-07-07T13:00:15.949] _slurm_rpc_submit_batch_job: JobId=45998 InitPrio=25519 usec=498
[2022-07-07T13:00:16.861] sched: Allocate JobId=45998 NodeList=cpu13 #CPUs=16 Partition=cpu-epyc
[2022-07-07T13:01:08.153] _slurm_rpc_submit_batch_job: JobId=45999 InitPrio=19959 usec=410
[2022-07-07T13:01:12.320] _job_complete: JobId=45996 WEXITSTATUS 1
[2022-07-07T13:01:12.320] _job_complete: JobId=45996 done
[2022-07-07T13:01:33.485] _slurm_rpc_kill_job: REQUEST_KILL_JOB JobId=45999 uid 548200021
[2022-07-07T13:02:23.774] No nodes satisfy requirements for JobId=46000 in partition gpu-k10
[2022-07-07T13:02:23.775] _slurm_rpc_submit_batch_job: Requested node configuration is not available
[2022-07-07T13:02:36.367] _job_complete: JobId=45998 WEXITSTATUS 0
[2022-07-07T13:02:36.367] _job_complete: JobId=45998 done
[2022-07-07T13:02:53.575] _slurm_rpc_submit_batch_job: JobId=46001 InitPrio=19874 usec=391
[2022-07-07T13:02:54.434] sched: Allocate JobId=46001 NodeList=gpu03 #CPUs=16 Partition=gpu-k10
[2022-07-07T13:06:50.604] _job_complete: JobId=46001 WEXITSTATUS 1
[2022-07-07T13:06:50.605] _job_complete: JobId=46001 done
[2022-07-07T13:07:48.059] _job_complete: JobId=45907 WEXITSTATUS 0
[2022-07-07T13:07:48.059] _job_complete: JobId=45907 done
[2022-07-07T13:08:51.921] _slurm_rpc_submit_batch_job: JobId=46002 InitPrio=25519 usec=425
[2022-07-07T13:08:52.218] sched: Allocate JobId=46002 NodeList=cpu13 #CPUs=16 Partition=cpu-epyc
[2022-07-07T13:11:39.593] _job_complete: JobId=46002 WEXITSTATUS 0
[2022-07-07T13:11:39.594] _job_complete: JobId=46002 done
[2022-07-07T13:17:26.594] _slurm_rpc_submit_batch_job: JobId=46003 InitPrio=25519 usec=449
[2022-07-07T13:17:27.179] sched: Allocate JobId=46003 NodeList=cpu13 #CPUs=16 Partition=cpu-epyc
[2022-07-07T13:18:33.524] _get_job_parts: invalid partition specified: cpu-opeteron
[2022-07-07T13:18:33.524] _slurm_rpc_submit_batch_job: Invalid partition name specified
[2022-07-07T13:18:46.757] _slurm_rpc_submit_batch_job: JobId=46004 InitPrio=19994 usec=395
[2022-07-07T13:18:47.345] sched: Allocate JobId=46004 NodeList=cpu11 #CPUs=2 Partition=cpu-opteron
[2022-07-07T13:18:49.849] _job_complete: JobId=46004 WEXITSTATUS 0
[2022-07-07T13:18:49.849] _job_complete: JobId=46004 done
[2022-07-07T13:19:46.851] _job_complete: JobId=46003 WEXITSTATUS 0
[2022-07-07T13:19:46.851] _job_complete: JobId=46003 done
[2022-07-07T13:24:45.539] _slurm_rpc_submit_batch_job: JobId=46005 InitPrio=19994 usec=411
[2022-07-07T13:24:45.955] sched: Allocate JobId=46005 NodeList=cpu11 #CPUs=2 Partition=cpu-opteron
[2022-07-07T13:24:48.277] _job_complete: JobId=46005 WEXITSTATUS 0
[2022-07-07T13:24:48.277] _job_complete: JobId=46005 done
[2022-07-07T13:26:31.584] _slurm_rpc_submit_batch_job: JobId=46006 InitPrio=19874 usec=430
[2022-07-07T13:26:32.105] sched: Allocate JobId=46006 NodeList=gpu03 #CPUs=16 Partition=gpu-k10
[2022-07-07T13:29:36.689] _slurm_rpc_submit_batch_job: JobId=46007 InitPrio=19874 usec=437
[2022-07-07T13:29:37.486] sched: Allocate JobId=46007 NodeList=gpu01 #CPUs=16 Partition=gpu-k10
[2022-07-07T13:32:19.549] _job_complete: JobId=46006 WEXITSTATUS 0
[2022-07-07T13:32:19.549] _job_complete: JobId=46006 done
[2022-07-07T13:33:31.393] _job_complete: JobId=46007 WEXITSTATUS 1
[2022-07-07T13:33:31.393] _job_complete: JobId=46007 done
[2022-07-07T13:38:42.598] _slurm_rpc_submit_batch_job: JobId=46008 InitPrio=24913 usec=393
[2022-07-07T13:38:43.485] sched: Allocate JobId=46008 NodeList=cpu13 #CPUs=24 Partition=cpu-epyc
[2022-07-07T13:38:47.168] _job_complete: JobId=46008 WEXITSTATUS 1
[2022-07-07T13:38:47.168] _job_complete: JobId=46008 done
[2022-07-07T13:39:18.743] _slurm_rpc_submit_batch_job: JobId=46009 InitPrio=24913 usec=379
[2022-07-07T13:39:19.531] sched: Allocate JobId=46009 NodeList=cpu13 #CPUs=24 Partition=cpu-epyc
[2022-07-07T13:39:39.672] _job_complete: JobId=46009 WEXITSTATUS 0
[2022-07-07T13:39:39.673] _job_complete: JobId=46009 done
[2022-07-07T13:39:59.249] _slurm_rpc_submit_batch_job: JobId=46010 InitPrio=19874 usec=504
[2022-07-07T13:39:59.591] sched: Allocate JobId=46010 NodeList=gpu05 #CPUs=16 Partition=gpu-v100s
[2022-07-07T13:42:17.797] _job_complete: JobId=45928 WEXITSTATUS 0
[2022-07-07T13:42:17.797] _job_complete: JobId=45928 done
[2022-07-07T13:43:21.473] _job_complete: JobId=46010 WEXITSTATUS 0
[2022-07-07T13:43:21.473] _job_complete: JobId=46010 done
[2022-07-07T13:44:38.655] _slurm_rpc_submit_batch_job: JobId=46011 InitPrio=19874 usec=505
[2022-07-07T13:44:39.066] sched: Allocate JobId=46011 NodeList=gpu03 #CPUs=16 Partition=gpu-k10
[2022-07-07T13:45:03.689] _slurm_rpc_submit_batch_job: JobId=46012 InitPrio=25519 usec=436
[2022-07-07T13:45:04.100] sched: Allocate JobId=46012 NodeList=cpu13 #CPUs=16 Partition=cpu-epyc
[2022-07-07T13:45:04.755] _job_complete: JobId=46012 WEXITSTATUS 127
[2022-07-07T13:45:04.755] _job_complete: JobId=46012 done
[2022-07-07T13:47:06.955] _slurm_rpc_submit_batch_job: JobId=46013 InitPrio=19874 usec=490
[2022-07-07T13:47:08.262] sched: Allocate JobId=46013 NodeList=gpu01 #CPUs=16 Partition=gpu-k10
[2022-07-07T13:48:34.651] _job_complete: JobId=46011 WEXITSTATUS 1
[2022-07-07T13:48:34.651] _job_complete: JobId=46011 done
[2022-07-07T13:49:27.205] _slurm_rpc_submit_batch_job: JobId=46014 InitPrio=25519 usec=392
[2022-07-07T13:49:27.556] sched: Allocate JobId=46014 NodeList=cpu13 #CPUs=16 Partition=cpu-epyc
[2022-07-07T13:49:28.392] _slurm_rpc_submit_batch_job: JobId=46015 InitPrio=19874 usec=418
[2022-07-07T13:49:30.562] sched: Allocate JobId=46015 NodeList=gpu03 #CPUs=16 Partition=gpu-k10
[2022-07-07T13:51:48.180] _job_complete: JobId=46014 WEXITSTATUS 0
[2022-07-07T13:51:48.180] _job_complete: JobId=46014 done
[2022-07-07T13:53:18.925] _slurm_rpc_submit_batch_job: JobId=46016 InitPrio=25519 usec=358
[2022-07-07T13:53:18.977] sched: Allocate JobId=46016 NodeList=cpu13 #CPUs=16 Partition=cpu-epyc
[2022-07-07T13:55:20.919] _job_complete: JobId=45937 WEXITSTATUS 0
[2022-07-07T13:55:20.919] _job_complete: JobId=45937 done
[2022-07-07T13:55:21.411] sched: Allocate JobId=45939 NodeList=cpu14 #CPUs=16 Partition=cpu-epyc
[2022-07-07T13:55:38.063] _job_complete: JobId=46016 WEXITSTATUS 0
[2022-07-07T13:55:38.063] _job_complete: JobId=46016 done
[2022-07-07T14:02:09.219] _slurm_rpc_submit_batch_job: JobId=46017 InitPrio=25519 usec=448
[2022-07-07T14:02:09.813] sched: Allocate JobId=46017 NodeList=cpu13 #CPUs=16 Partition=cpu-epyc
[2022-07-07T14:02:14.672] _job_complete: JobId=46017 WEXITSTATUS 139
[2022-07-07T14:02:14.672] _job_complete: JobId=46017 done
[2022-07-07T14:06:35.835] _job_complete: JobId=45934 WEXITSTATUS 0
[2022-07-07T14:06:35.835] _job_complete: JobId=45934 done
[2022-07-07T14:06:36.084] sched: Allocate JobId=45940 NodeList=cpu12 #CPUs=16 Partition=cpu-epyc
[2022-07-07T14:09:52.571] _slurm_rpc_submit_batch_job: JobId=46018 InitPrio=24913 usec=437
[2022-07-07T14:09:52.731] sched: Allocate JobId=46018 NodeList=cpu13 #CPUs=24 Partition=cpu-epyc
[2022-07-07T14:10:01.309] _job_complete: JobId=46018 WEXITSTATUS 0
[2022-07-07T14:10:01.309] _job_complete: JobId=46018 done
[2022-07-07T14:16:48.106] _job_complete: JobId=46013 WEXITSTATUS 0
[2022-07-07T14:16:48.106] _job_complete: JobId=46013 done
[2022-07-07T14:33:41.057] _job_complete: JobId=45938 WEXITSTATUS 0
[2022-07-07T14:33:41.057] _job_complete: JobId=45938 done
[2022-07-07T14:33:41.313] sched: Allocate JobId=45941 NodeList=cpu15 #CPUs=16 Partition=cpu-epyc
[2022-07-07T14:38:10.577] _slurm_rpc_submit_batch_job: JobId=46019 InitPrio=19874 usec=472
[2022-07-07T14:38:11.001] sched: Allocate JobId=46019 NodeList=gpu01 #CPUs=16 Partition=gpu-k10
[2022-07-07T14:45:12.957] _slurm_rpc_submit_batch_job: JobId=46020 InitPrio=24913 usec=441
[2022-07-07T14:45:13.641] sched: Allocate JobId=46020 NodeList=cpu13 #CPUs=24 Partition=cpu-epyc
[2022-07-07T14:45:41.049] _job_complete: JobId=46020 WEXITSTATUS 0
[2022-07-07T14:45:41.049] _job_complete: JobId=46020 done
[2022-07-07T14:46:24.816] _slurm_rpc_submit_batch_job: JobId=46021 InitPrio=25108 usec=452
[2022-07-07T14:46:25.741] sched: Allocate JobId=46021 NodeList=cpu10 #CPUs=64 Partition=cpu-opteron
[2022-07-07T14:53:53.221] _job_complete: JobId=46021 WEXITSTATUS 0
[2022-07-07T14:53:53.222] _job_complete: JobId=46021 done
[2022-07-07T14:57:30.946] _slurm_rpc_submit_batch_job: JobId=46022 InitPrio=25519 usec=575
[2022-07-07T14:57:31.499] sched: Allocate JobId=46022 NodeList=cpu11 #CPUs=16 Partition=cpu-opteron
[2022-07-07T14:58:51.660] _job_complete: JobId=45939 WEXITSTATUS 0
[2022-07-07T14:58:51.660] _job_complete: JobId=45939 done
[2022-07-07T14:58:51.938] sched: Allocate JobId=45942 NodeList=cpu14 #CPUs=16 Partition=cpu-epyc
[2022-07-07T15:08:26.943] _slurm_rpc_submit_batch_job: JobId=46023 InitPrio=23637 usec=444
[2022-07-07T15:14:59.977] _job_complete: JobId=46022 WEXITSTATUS 0
[2022-07-07T15:14:59.977] _job_complete: JobId=46022 done
[2022-07-07T15:16:27.562] _job_complete: JobId=45940 WEXITSTATUS 0
[2022-07-07T15:16:27.562] _job_complete: JobId=45940 done
[2022-07-07T15:16:27.835] sched: Allocate JobId=45943 NodeList=cpu12 #CPUs=16 Partition=cpu-epyc
[2022-07-07T15:17:10.739] _slurm_rpc_submit_batch_job: JobId=46024 InitPrio=24913 usec=432
[2022-07-07T15:17:11.653] sched: Allocate JobId=46024 NodeList=cpu13 #CPUs=24 Partition=cpu-epyc
[2022-07-07T15:17:24.204] _job_complete: JobId=46024 WEXITSTATUS 0
[2022-07-07T15:17:24.204] _job_complete: JobId=46024 done
[2022-07-07T15:36:59.691] _job_complete: JobId=45941 WEXITSTATUS 0
[2022-07-07T15:36:59.691] _job_complete: JobId=45941 done
[2022-07-07T15:36:59.916] sched: Allocate JobId=45944 NodeList=cpu15 #CPUs=16 Partition=cpu-epyc
[2022-07-07T16:02:46.614] _job_complete: JobId=46015 WEXITSTATUS 0
[2022-07-07T16:02:46.614] _job_complete: JobId=46015 done
[2022-07-07T16:12:32.194] _slurm_rpc_submit_batch_job: JobId=46025 InitPrio=24913 usec=514
[2022-07-07T16:12:32.787] sched: Allocate JobId=46025 NodeList=cpu13 #CPUs=24 Partition=cpu-epyc
[2022-07-07T16:13:18.461] _job_complete: JobId=46025 WEXITSTATUS 0
[2022-07-07T16:13:18.461] _job_complete: JobId=46025 done
[2022-07-07T16:19:25.169] _slurm_rpc_submit_batch_job: JobId=46026 InitPrio=23637 usec=558
[2022-07-07T16:19:49.173] _slurm_rpc_submit_batch_job: JobId=46027 InitPrio=23637 usec=409
[2022-07-07T16:20:02.058] _slurm_rpc_submit_batch_job: JobId=46028 InitPrio=23637 usec=387
[2022-07-07T16:20:10.030] _slurm_rpc_submit_batch_job: JobId=46029 InitPrio=23637 usec=463
[2022-07-07T16:20:17.450] _slurm_rpc_submit_batch_job: JobId=46030 InitPrio=23637 usec=462
[2022-07-07T16:20:24.755] _slurm_rpc_submit_batch_job: JobId=46031 InitPrio=23637 usec=472
[2022-07-07T16:20:37.003] _slurm_rpc_submit_batch_job: JobId=46032 InitPrio=23637 usec=586
[2022-07-07T16:21:00.521] _slurm_rpc_submit_batch_job: JobId=46033 InitPrio=23637 usec=437
[2022-07-07T16:21:07.243] _slurm_rpc_submit_batch_job: JobId=46034 InitPrio=23637 usec=526
[2022-07-07T16:21:14.452] _slurm_rpc_submit_batch_job: JobId=46035 InitPrio=23637 usec=404
[2022-07-07T16:21:22.652] _slurm_rpc_submit_batch_job: JobId=46036 InitPrio=23637 usec=454
[2022-07-07T16:21:30.588] _slurm_rpc_submit_batch_job: JobId=46037 InitPrio=23637 usec=403
[2022-07-07T16:21:37.758] _slurm_rpc_submit_batch_job: JobId=46038 InitPrio=23637 usec=469
[2022-07-07T16:21:43.591] _slurm_rpc_submit_batch_job: JobId=46039 InitPrio=23637 usec=446
[2022-07-07T16:21:50.222] _slurm_rpc_submit_batch_job: JobId=46040 InitPrio=23637 usec=478
[2022-07-07T16:25:07.221] _job_complete: JobId=45943 WEXITSTATUS 0
[2022-07-07T16:25:07.222] _job_complete: JobId=45943 done
[2022-07-07T16:25:07.585] sched: Allocate JobId=45945 NodeList=cpu12 #CPUs=16 Partition=cpu-epyc
[2022-07-07T16:34:41.143] _job_complete: JobId=45944 WEXITSTATUS 0
[2022-07-07T16:34:41.143] _job_complete: JobId=45944 done
[2022-07-07T16:34:41.372] sched: Allocate JobId=45946 NodeList=cpu15 #CPUs=16 Partition=cpu-epyc
[2022-07-07T16:37:08.334] _slurm_rpc_submit_batch_job: JobId=46041 InitPrio=24981 usec=497
[2022-07-07T16:37:10.533] sched: Allocate JobId=46041 NodeList=cpu11 #CPUs=16 Partition=cpu-opteron
[2022-07-07T16:37:12.141] _job_complete: JobId=46041 WEXITSTATUS 1
[2022-07-07T16:37:12.141] _job_complete: JobId=46041 done
[2022-07-07T16:40:06.880] _slurm_rpc_submit_batch_job: JobId=46042 InitPrio=24981 usec=426
[2022-07-07T16:40:06.907] sched: Allocate JobId=46042 NodeList=cpu11 #CPUs=16 Partition=cpu-opteron
[2022-07-07T16:40:09.037] _job_complete: JobId=46042 WEXITSTATUS 1
[2022-07-07T16:40:09.037] _job_complete: JobId=46042 done
[2022-07-07T16:41:20.387] _slurm_rpc_submit_batch_job: JobId=46043 InitPrio=24981 usec=550
[2022-07-07T16:41:21.012] sched: Allocate JobId=46043 NodeList=cpu11 #CPUs=16 Partition=cpu-opteron
[2022-07-07T16:41:23.889] _job_complete: JobId=46043 WEXITSTATUS 1
[2022-07-07T16:41:23.889] _job_complete: JobId=46043 done
[2022-07-07T16:44:43.140] _slurm_rpc_submit_batch_job: JobId=46044 InitPrio=24981 usec=481
[2022-07-07T16:44:43.421] sched: Allocate JobId=46044 NodeList=cpu11 #CPUs=16 Partition=cpu-opteron
[2022-07-07T16:44:45.164] _job_complete: JobId=46044 WEXITSTATUS 1
[2022-07-07T16:44:45.164] _job_complete: JobId=46044 done
[2022-07-07T16:45:25.320] _slurm_rpc_submit_batch_job: JobId=46045 InitPrio=24981 usec=509
[2022-07-07T16:45:25.477] sched: Allocate JobId=46045 NodeList=cpu11 #CPUs=16 Partition=cpu-opteron
[2022-07-07T16:45:26.412] _job_complete: JobId=46045 WEXITSTATUS 127
[2022-07-07T16:45:26.412] _job_complete: JobId=46045 done
[2022-07-07T16:49:27.325] _job_complete: JobId=45942 WEXITSTATUS 0
[2022-07-07T16:49:27.325] _job_complete: JobId=45942 done
[2022-07-07T16:49:27.569] sched: Allocate JobId=45947 NodeList=cpu14 #CPUs=16 Partition=cpu-epyc
[2022-07-07T17:14:34.614] _slurm_rpc_submit_batch_job: JobId=46046 InitPrio=24913 usec=598
[2022-07-07T17:14:34.828] sched: Allocate JobId=46046 NodeList=cpu13 #CPUs=24 Partition=cpu-epyc
[2022-07-07T17:14:39.577] _job_complete: JobId=46046 WEXITSTATUS 0
[2022-07-07T17:14:39.577] _job_complete: JobId=46046 done
[2022-07-07T17:35:09.065] _job_complete: JobId=45946 WEXITSTATUS 0
[2022-07-07T17:35:09.065] _job_complete: JobId=45946 done
[2022-07-07T17:35:09.313] sched: Allocate JobId=45948 NodeList=cpu15 #CPUs=16 Partition=cpu-epyc
[2022-07-07T17:42:45.069] _job_complete: JobId=45945 WEXITSTATUS 0
[2022-07-07T17:42:45.069] _job_complete: JobId=45945 done
[2022-07-07T17:42:45.323] sched: Allocate JobId=45949 NodeList=cpu12 #CPUs=16 Partition=cpu-epyc
[2022-07-07T17:49:30.557] _slurm_rpc_submit_batch_job: JobId=46047 InitPrio=20915 usec=430
[2022-07-07T17:49:49.914] _slurm_rpc_kill_job: REQUEST_KILL_JOB JobId=46047 uid 548200023
[2022-07-07T17:50:21.647] _job_create: exceeded association/QOS limit for user 548200023: AssocGrpCpuLimit
[2022-07-07T17:50:21.647] _slurm_rpc_submit_batch_job: Job violates accounting/QOS policy (job submit limit, user's size and/or time limits)
[2022-07-07T17:50:33.913] _job_complete: JobId=45947 WEXITSTATUS 0
[2022-07-07T17:50:33.913] _job_complete: JobId=45947 done
[2022-07-07T17:50:34.139] sched: Allocate JobId=45950 NodeList=cpu14 #CPUs=16 Partition=cpu-epyc
[2022-07-07T17:50:43.926] _slurm_rpc_submit_batch_job: JobId=46048 InitPrio=20949 usec=470
[2022-07-07T17:50:44.746] sched: Allocate JobId=46048 NodeList=cpu11 #CPUs=16 Partition=cpu-opteron
[2022-07-07T17:51:47.537] _job_complete: JobId=46048 WEXITSTATUS 0
[2022-07-07T17:51:47.537] _job_complete: JobId=46048 done
[2022-07-07T17:52:12.785] _slurm_rpc_submit_batch_job: JobId=46049 InitPrio=20949 usec=434
[2022-07-07T17:52:12.854] sched: Allocate JobId=46049 NodeList=cpu11 #CPUs=16 Partition=cpu-opteron
[2022-07-07T17:53:09.738] _job_complete: JobId=46049 WEXITSTATUS 0
[2022-07-07T17:53:09.738] _job_complete: JobId=46049 done
[2022-07-07T18:06:14.542] _slurm_rpc_submit_batch_job: JobId=46050 InitPrio=20949 usec=415
[2022-07-07T18:06:15.345] sched: Allocate JobId=46050 NodeList=cpu11 #CPUs=16 Partition=cpu-opteron
[2022-07-07T18:07:27.909] _job_complete: JobId=46050 WEXITSTATUS 0
[2022-07-07T18:07:27.909] _job_complete: JobId=46050 done
[2022-07-07T18:40:51.230] _job_complete: JobId=45948 WEXITSTATUS 0
[2022-07-07T18:40:51.231] _job_complete: JobId=45948 done
[2022-07-07T18:40:51.481] sched: Allocate JobId=45951 NodeList=cpu15 #CPUs=16 Partition=cpu-epyc
[2022-07-07T18:53:43.138] _job_complete: JobId=45950 WEXITSTATUS 0
[2022-07-07T18:53:43.138] _job_complete: JobId=45950 done
[2022-07-07T18:53:43.377] sched: Allocate JobId=45952 NodeList=cpu14 #CPUs=16 Partition=cpu-epyc
[2022-07-07T19:22:50.758] _job_complete: JobId=45949 WEXITSTATUS 0
[2022-07-07T19:22:50.759] _job_complete: JobId=45949 done
[2022-07-07T19:22:51.034] sched: Allocate JobId=45953 NodeList=cpu12 #CPUs=16 Partition=cpu-epyc
[2022-07-07T20:06:57.850] _job_complete: JobId=45952 WEXITSTATUS 0
[2022-07-07T20:06:57.850] _job_complete: JobId=45952 done
[2022-07-07T20:06:58.100] sched: Allocate JobId=45954 NodeList=cpu14 #CPUs=16 Partition=cpu-epyc
[2022-07-07T20:13:52.764] _job_complete: JobId=45951 WEXITSTATUS 0
[2022-07-07T20:13:52.764] _job_complete: JobId=45951 done
[2022-07-07T20:13:53.004] sched: Allocate JobId=45955 NodeList=cpu15 #CPUs=16 Partition=cpu-epyc
[2022-07-07T20:45:06.060] _job_complete: JobId=45953 WEXITSTATUS 0
[2022-07-07T20:45:06.060] _job_complete: JobId=45953 done
[2022-07-07T20:45:06.309] sched: Allocate JobId=45956 NodeList=cpu12 #CPUs=16 Partition=cpu-epyc
[2022-07-07T21:17:06.750] _job_complete: JobId=45954 WEXITSTATUS 0
[2022-07-07T21:17:06.751] _job_complete: JobId=45954 done
[2022-07-07T21:17:06.974] sched: Allocate JobId=45957 NodeList=cpu14 #CPUs=16 Partition=cpu-epyc
[2022-07-07T21:24:29.122] _job_complete: JobId=45955 WEXITSTATUS 0
[2022-07-07T21:24:29.122] _job_complete: JobId=45955 done
[2022-07-07T21:24:29.343] sched: Allocate JobId=45958 NodeList=cpu15 #CPUs=16 Partition=cpu-epyc
[2022-07-07T21:46:39.274] No nodes satisfy requirements for JobId=46051 in partition gpu-k10
[2022-07-07T21:46:39.274] _slurm_rpc_submit_batch_job: Requested node configuration is not available
[2022-07-07T21:46:58.453] _slurm_rpc_submit_batch_job: JobId=46052 InitPrio=19874 usec=392
[2022-07-07T21:46:59.297] sched: Allocate JobId=46052 NodeList=gpu03 #CPUs=16 Partition=gpu-k10
[2022-07-07T21:47:01.457] _job_complete: JobId=46052 WEXITSTATUS 1
[2022-07-07T21:47:01.457] _job_complete: JobId=46052 done
[2022-07-07T21:48:34.095] _slurm_rpc_submit_batch_job: JobId=46053 InitPrio=19874 usec=515
[2022-07-07T21:48:34.562] sched: Allocate JobId=46053 NodeList=gpu03 #CPUs=16 Partition=gpu-k10
[2022-07-07T21:52:10.740] _job_complete: JobId=45956 WEXITSTATUS 0
[2022-07-07T21:52:10.741] _job_complete: JobId=45956 done
[2022-07-07T21:52:11.001] sched: Allocate JobId=45959 NodeList=cpu12 #CPUs=16 Partition=cpu-epyc
[2022-07-07T22:00:07.176] _slurm_rpc_kill_job: REQUEST_KILL_JOB JobId=45904 uid 548200021
[2022-07-07T22:00:09.022] sched: Allocate JobId=45960 NodeList=cpu13 #CPUs=16 Partition=cpu-epyc
[2022-07-07T22:00:09.023] sched: Allocate JobId=45961 NodeList=cpu13 #CPUs=16 Partition=cpu-epyc
[2022-07-07T22:01:04.083] _slurm_rpc_submit_batch_job: JobId=46054 InitPrio=19463 usec=612
[2022-07-07T22:01:04.852] sched: Allocate JobId=46054 NodeList=cpu10 #CPUs=64 Partition=cpu-opteron
[2022-07-07T22:50:04.455] _job_complete: JobId=45958 WEXITSTATUS 0
[2022-07-07T22:50:04.455] _job_complete: JobId=45958 done
[2022-07-07T22:50:04.696] sched: Allocate JobId=45962 NodeList=cpu15 #CPUs=16 Partition=cpu-epyc
[2022-07-07T23:02:24.180] _job_complete: JobId=45959 WEXITSTATUS 0
[2022-07-07T23:02:24.181] _job_complete: JobId=45959 done
[2022-07-07T23:02:24.440] sched: Allocate JobId=45963 NodeList=cpu12 #CPUs=16 Partition=cpu-epyc
[2022-07-07T23:11:53.295] _job_complete: JobId=45957 WEXITSTATUS 0
[2022-07-07T23:11:53.296] _job_complete: JobId=45957 done
[2022-07-07T23:11:53.580] sched: Allocate JobId=45964 NodeList=cpu14 #CPUs=16 Partition=cpu-epyc
[2022-07-07T23:12:31.966] _job_complete: JobId=45961 WEXITSTATUS 0
[2022-07-07T23:12:31.967] _job_complete: JobId=45961 done
[2022-07-07T23:12:32.221] sched: Allocate JobId=45965 NodeList=cpu13 #CPUs=16 Partition=cpu-epyc
[2022-07-07T23:20:02.703] _job_complete: JobId=45960 WEXITSTATUS 0
[2022-07-07T23:20:02.703] _job_complete: JobId=45960 done
[2022-07-07T23:20:02.935] sched: Allocate JobId=45966 NodeList=cpu13 #CPUs=16 Partition=cpu-epyc
[2022-07-07T23:49:52.168] _job_complete: JobId=45962 WEXITSTATUS 0
[2022-07-07T23:49:52.168] _job_complete: JobId=45962 done
[2022-07-07T23:49:52.407] sched: Allocate JobId=45967 NodeList=cpu15 #CPUs=16 Partition=cpu-epyc
[2022-07-08T00:16:54.541] _job_complete: JobId=45964 WEXITSTATUS 0
[2022-07-08T00:16:54.541] _job_complete: JobId=45964 done
[2022-07-08T00:16:54.767] sched: Allocate JobId=45968 NodeList=cpu14 #CPUs=16 Partition=cpu-epyc
[2022-07-08T00:20:40.931] _job_complete: JobId=45963 WEXITSTATUS 0
[2022-07-08T00:20:40.932] _job_complete: JobId=45963 done
[2022-07-08T00:20:41.205] sched: Allocate JobId=45969 NodeList=cpu12 #CPUs=16 Partition=cpu-epyc
[2022-07-08T00:21:09.209] _job_complete: JobId=45965 WEXITSTATUS 0
[2022-07-08T00:21:09.210] _job_complete: JobId=45965 done
[2022-07-08T00:21:09.463] sched: Allocate JobId=45970 NodeList=cpu13 #CPUs=16 Partition=cpu-epyc
[2022-07-08T00:56:05.161] _job_complete: JobId=45967 WEXITSTATUS 0
[2022-07-08T00:56:05.161] _job_complete: JobId=45967 done
[2022-07-08T00:56:05.383] sched: Allocate JobId=45971 NodeList=cpu15 #CPUs=16 Partition=cpu-epyc
[2022-07-08T01:28:16.795] _job_complete: JobId=45968 WEXITSTATUS 0
[2022-07-08T01:28:16.796] _job_complete: JobId=45968 done
[2022-07-08T01:28:17.059] sched: Allocate JobId=45972 NodeList=cpu14 #CPUs=16 Partition=cpu-epyc
[2022-07-08T01:33:42.292] _job_complete: JobId=45970 WEXITSTATUS 0
[2022-07-08T01:33:42.292] _job_complete: JobId=45970 done
[2022-07-08T01:33:42.579] sched: Allocate JobId=45973 NodeList=cpu13 #CPUs=16 Partition=cpu-epyc
[2022-07-08T01:49:18.457] _job_complete: JobId=45969 WEXITSTATUS 0
[2022-07-08T01:49:18.457] _job_complete: JobId=45969 done
[2022-07-08T01:49:18.702] sched: Allocate JobId=45974 NodeList=cpu12 #CPUs=16 Partition=cpu-epyc
[2022-07-08T01:55:28.823] _job_complete: JobId=45971 WEXITSTATUS 0
[2022-07-08T01:55:28.823] _job_complete: JobId=45971 done
[2022-07-08T01:55:29.042] sched: Allocate JobId=45975 NodeList=cpu15 #CPUs=16 Partition=cpu-epyc
[2022-07-08T03:00:06.170] _job_complete: JobId=45974 WEXITSTATUS 0
[2022-07-08T03:00:06.170] _job_complete: JobId=45974 done
[2022-07-08T03:00:06.415] sched: Allocate JobId=45976 NodeList=cpu12 #CPUs=16 Partition=cpu-epyc
[2022-07-08T03:05:31.292] _job_complete: JobId=45975 WEXITSTATUS 0
[2022-07-08T03:05:31.292] _job_complete: JobId=45975 done
[2022-07-08T03:05:31.512] sched: Allocate JobId=45977 NodeList=cpu15 #CPUs=16 Partition=cpu-epyc
[2022-07-08T03:13:33.031] _job_complete: JobId=45972 WEXITSTATUS 0
[2022-07-08T03:13:33.032] _job_complete: JobId=45972 done
[2022-07-08T03:13:33.282] sched: Allocate JobId=45978 NodeList=cpu14 #CPUs=16 Partition=cpu-epyc
[2022-07-08T03:22:34.728] _slurm_rpc_submit_batch_job: JobId=46055 InitPrio=24832 usec=418
[2022-07-08T03:23:03.561] sched/backfill: _start_job: Started JobId=46055 in gpu-titan on gpu02
[2022-07-08T03:28:07.476] _job_complete: JobId=45973 WEXITSTATUS 0
[2022-07-08T03:28:07.476] _job_complete: JobId=45973 done
[2022-07-08T03:28:07.724] sched: Allocate JobId=45979 NodeList=cpu13 #CPUs=16 Partition=cpu-epyc
[2022-07-08T03:46:07.961] _job_complete: JobId=45927 WEXITSTATUS 0
[2022-07-08T03:46:07.961] _job_complete: JobId=45927 done
[2022-07-08T03:46:08.394] sched: Allocate JobId=45935 NodeList=gpu02 #CPUs=10 Partition=gpu-titan
[2022-07-08T04:12:17.557] _job_complete: JobId=45976 WEXITSTATUS 0
[2022-07-08T04:12:17.557] _job_complete: JobId=45976 done
[2022-07-08T04:12:17.820] sched: Allocate JobId=45980 NodeList=cpu12 #CPUs=16 Partition=cpu-epyc
[2022-07-08T04:17:26.359] _job_complete: JobId=45977 WEXITSTATUS 0
[2022-07-08T04:17:26.359] _job_complete: JobId=45977 done
[2022-07-08T04:17:26.573] sched: Allocate JobId=45981 NodeList=cpu15 #CPUs=16 Partition=cpu-epyc
[2022-07-08T04:23:30.175] _job_complete: JobId=45978 WEXITSTATUS 0
[2022-07-08T04:23:30.175] _job_complete: JobId=45978 done
[2022-07-08T04:23:30.419] sched: Allocate JobId=45982 NodeList=cpu14 #CPUs=16 Partition=cpu-epyc
[2022-07-08T05:00:04.414] _job_complete: JobId=46053 WEXITSTATUS 1
[2022-07-08T05:00:04.414] _job_complete: JobId=46053 done
[2022-07-08T05:17:31.403] _job_complete: JobId=45980 WEXITSTATUS 0
[2022-07-08T05:17:31.403] _job_complete: JobId=45980 done
[2022-07-08T05:17:31.680] sched: Allocate JobId=45983 NodeList=cpu12 #CPUs=16 Partition=cpu-epyc
[2022-07-08T05:28:11.418] _job_complete: JobId=45979 WEXITSTATUS 0
[2022-07-08T05:28:11.418] _job_complete: JobId=45979 done
[2022-07-08T05:28:11.672] sched: Allocate JobId=46023 NodeList=cpu13 #CPUs=16 Partition=cpu-epyc
[2022-07-08T05:32:17.001] _job_complete: JobId=45982 WEXITSTATUS 0
[2022-07-08T05:32:17.001] _job_complete: JobId=45982 done
[2022-07-08T05:32:17.300] sched: Allocate JobId=46026 NodeList=cpu14 #CPUs=16 Partition=cpu-epyc
[2022-07-08T05:54:58.258] _job_complete: JobId=45981 WEXITSTATUS 0
[2022-07-08T05:54:58.258] _job_complete: JobId=45981 done
[2022-07-08T06:03:40.247] _job_complete: JobId=46023 WEXITSTATUS 0
[2022-07-08T06:03:40.247] _job_complete: JobId=46023 done
[2022-07-08T06:13:48.668] _job_complete: JobId=45435 WEXITSTATUS 0
[2022-07-08T06:13:48.668] _job_complete: JobId=45435 done
[2022-07-08T06:13:49.018] sched: Allocate JobId=46027 NodeList=cpu12 #CPUs=16 Partition=cpu-epyc
[2022-07-08T06:13:49.018] sched: Allocate JobId=46028 NodeList=cpu12 #CPUs=16 Partition=cpu-epyc
[2022-07-08T06:25:26.016] _job_complete: JobId=45983 WEXITSTATUS 0
[2022-07-08T06:25:26.016] _job_complete: JobId=45983 done
[2022-07-08T08:26:09.753] _slurm_rpc_submit_batch_job: JobId=46056 InitPrio=19468 usec=369
[2022-07-08T08:26:46.275] _job_complete: JobId=45966 WEXITSTATUS 0
[2022-07-08T08:26:46.276] _job_complete: JobId=45966 done
[2022-07-08T08:26:46.529] sched: Allocate JobId=46056 NodeList=cpu13 #CPUs=32 Partition=cpu-epyc
[2022-07-08T08:26:51.847] _job_complete: JobId=46056 WEXITSTATUS 1
[2022-07-08T08:26:51.848] _job_complete: JobId=46056 done
[2022-07-08T08:40:11.142] _slurm_rpc_kill_job: REQUEST_KILL_JOB JobId=45020 uid 548200003
[2022-07-08T08:44:24.635] _slurm_rpc_submit_batch_job: JobId=46057 InitPrio=19468 usec=444
[2022-07-08T08:44:24.912] sched: Allocate JobId=46057 NodeList=cpu13 #CPUs=32 Partition=cpu-epyc
[2022-07-08T08:49:22.703] _slurm_rpc_submit_batch_job: JobId=46058 InitPrio=21218 usec=547
[2022-07-08T08:49:23.491] sched: Allocate JobId=46058 NodeList=gpu04 #CPUs=16 Partition=gpu-k40c
[2022-07-08T09:05:50.857] _slurm_rpc_submit_batch_job: JobId=46059 InitPrio=19605 usec=532
[2022-07-08T09:05:51.369] sched: Allocate JobId=46059 NodeList=cpu12 #CPUs=16 Partition=cpu-epyc
[2022-07-08T09:06:32.787] _job_complete: JobId=46059 WEXITSTATUS 0
[2022-07-08T09:06:32.787] _job_complete: JobId=46059 done
[2022-07-08T09:31:36.470] _slurm_rpc_submit_batch_job: JobId=46060 InitPrio=24572 usec=509
[2022-07-08T09:31:37.233] sched: Allocate JobId=46060 NodeList=gpu02 #CPUs=1 Partition=gpu-titan
[2022-07-08T09:36:55.141] _slurm_rpc_submit_batch_job: JobId=46061 InitPrio=24512 usec=461
[2022-07-08T09:51:34.329] _slurm_rpc_submit_batch_job: JobId=46062 InitPrio=25250 usec=436
[2022-07-08T09:51:34.428] sched: Allocate JobId=46062 NodeList=cpu12 #CPUs=16 Partition=cpu-epyc
[2022-07-08T09:51:39.859] _job_complete: JobId=46062 WEXITSTATUS 1
[2022-07-08T09:51:39.860] _job_complete: JobId=46062 done
[2022-07-08T10:02:16.684] sched: _slurm_rpc_allocate_resources JobId=46063 NodeList=cpu11 usec=17703
[2022-07-08T10:06:54.604] _slurm_rpc_submit_batch_job: JobId=46064 InitPrio=25250 usec=426
[2022-07-08T10:06:55.081] sched: Allocate JobId=46064 NodeList=cpu12 #CPUs=16 Partition=cpu-epyc
[2022-07-08T10:07:08.277] _job_complete: JobId=46064 WEXITSTATUS 0
[2022-07-08T10:07:08.277] _job_complete: JobId=46064 done
[2022-07-08T10:29:38.826] _slurm_rpc_submit_batch_job: JobId=46065 InitPrio=24243 usec=507
[2022-07-08T10:34:14.306] _slurm_rpc_submit_batch_job: JobId=46066 InitPrio=24295 usec=310
[2022-07-08T10:34:15.084] sched: Allocate JobId=46066 NodeList=gpu03 #CPUs=2 Partition=gpu-k10
[2022-07-08T10:40:35.120] _job_complete: JobId=46066 WEXITSTATUS 0
[2022-07-08T10:40:35.120] _job_complete: JobId=46066 done
[2022-07-08T10:51:06.017] _job_complete: JobId=46063 WEXITSTATUS 0
[2022-07-08T10:51:06.017] _job_complete: JobId=46063 done
[2022-07-08T10:56:14.350] _slurm_rpc_submit_batch_job: JobId=46067 InitPrio=25250 usec=543
[2022-07-08T10:56:14.359] sched: Allocate JobId=46067 NodeList=cpu12 #CPUs=16 Partition=cpu-epyc
[2022-07-08T10:56:20.345] _job_complete: JobId=46067 WEXITSTATUS 1
[2022-07-08T10:56:20.345] _job_complete: JobId=46067 done
[2022-07-08T11:12:46.481] _job_complete: JobId=46019 WEXITSTATUS 0
[2022-07-08T11:12:46.482] _job_complete: JobId=46019 done
[2022-07-08T11:54:49.740] _job_complete: JobId=46055 WEXITSTATUS 0
[2022-07-08T11:54:49.740] _job_complete: JobId=46055 done
[2022-07-08T12:12:04.630] _slurm_rpc_submit_batch_job: JobId=46068 InitPrio=25250 usec=427
[2022-07-08T12:12:04.664] sched: Allocate JobId=46068 NodeList=cpu12 #CPUs=16 Partition=cpu-epyc
[2022-07-08T12:12:33.238] _job_complete: JobId=46068 WEXITSTATUS 0
[2022-07-08T12:12:33.238] _job_complete: JobId=46068 done
[2022-07-08T12:13:34.288] _slurm_rpc_submit_batch_job: JobId=46069 InitPrio=25250 usec=506
[2022-07-08T12:13:34.900] sched: Allocate JobId=46069 NodeList=cpu12 #CPUs=16 Partition=cpu-epyc
[2022-07-08T12:15:27.885] _slurm_rpc_submit_batch_job: JobId=46070 InitPrio=25182 usec=459
[2022-07-08T12:15:37.500] _slurm_rpc_kill_job: REQUEST_KILL_JOB JobId=46070 uid 548200084
[2022-07-08T12:16:14.575] _slurm_rpc_submit_batch_job: JobId=46071 InitPrio=25250 usec=522
[2022-07-08T12:16:15.128] sched: Allocate JobId=46071 NodeList=cpu15 #CPUs=16 Partition=cpu-epyc
[2022-07-08T13:08:43.108] _job_complete: JobId=46069 WEXITSTATUS 0
[2022-07-08T13:08:43.108] _job_complete: JobId=46069 done
[2022-07-08T13:54:45.644] _job_complete: JobId=46071 WEXITSTATUS 0
[2022-07-08T13:54:45.644] _job_complete: JobId=46071 done
[2022-07-08T14:34:15.553] sched: _slurm_rpc_allocate_resources JobId=46072 NodeList=cpu11 usec=14292
[2022-07-08T14:53:56.832] _job_complete: JobId=45935 WEXITSTATUS 0
[2022-07-08T14:53:56.832] _job_complete: JobId=45935 done
[2022-07-08T14:53:57.158] sched: Allocate JobId=46061 NodeList=gpu02 #CPUs=8 Partition=gpu-titan
[2022-07-08T15:17:49.385] _slurm_rpc_submit_batch_job: JobId=46073 InitPrio=25250 usec=407
[2022-07-08T15:17:49.741] sched: Allocate JobId=46073 NodeList=cpu12 #CPUs=16 Partition=cpu-epyc
[2022-07-08T15:18:16.272] _job_complete: JobId=46073 WEXITSTATUS 0
[2022-07-08T15:18:16.273] _job_complete: JobId=46073 done
[2022-07-08T15:19:29.839] _slurm_rpc_submit_batch_job: JobId=46074 InitPrio=25250 usec=441
[2022-07-08T15:19:29.867] sched: Allocate JobId=46074 NodeList=cpu12 #CPUs=16 Partition=cpu-epyc
[2022-07-08T15:19:33.183] _job_complete: JobId=46074 WEXITSTATUS 1
[2022-07-08T15:19:33.184] _job_complete: JobId=46074 done
[2022-07-08T15:21:27.990] _slurm_rpc_submit_batch_job: JobId=46075 InitPrio=25250 usec=464
[2022-07-08T15:21:28.032] sched: Allocate JobId=46075 NodeList=cpu12 #CPUs=16 Partition=cpu-epyc
[2022-07-08T15:22:30.861] _job_complete: JobId=46075 WEXITSTATUS 0
[2022-07-08T15:22:30.861] _job_complete: JobId=46075 done
[2022-07-08T15:24:59.246] _job_complete: JobId=46072 WEXITSTATUS 0
[2022-07-08T15:24:59.246] _job_complete: JobId=46072 done
[2022-07-08T15:25:59.489] _slurm_rpc_submit_batch_job: JobId=46076 InitPrio=25250 usec=470
[2022-07-08T15:25:59.613] sched: Allocate JobId=46076 NodeList=cpu12 #CPUs=16 Partition=cpu-epyc
[2022-07-08T15:26:37.539] _job_complete: JobId=46076 WEXITSTATUS 0
[2022-07-08T15:26:37.539] _job_complete: JobId=46076 done
[2022-07-08T15:35:21.791] _job_complete: JobId=46060 WEXITSTATUS 0
[2022-07-08T15:35:21.791] _job_complete: JobId=46060 done
[2022-07-08T15:35:22.189] sched: Allocate JobId=46065 NodeList=gpu02 #CPUs=8 Partition=gpu-titan
[2022-07-08T16:03:45.316] _slurm_rpc_submit_batch_job: JobId=46077 InitPrio=19994 usec=612
[2022-07-08T16:03:45.803] sched: Allocate JobId=46077 NodeList=cpu15 #CPUs=2 Partition=cpu-epyc
[2022-07-08T16:04:17.435] _job_complete: JobId=46077 WEXITSTATUS 0
[2022-07-08T16:04:17.435] _job_complete: JobId=46077 done
[2022-07-08T16:08:58.486] _slurm_rpc_submit_batch_job: JobId=46078 InitPrio=19874 usec=533
[2022-07-08T16:08:59.359] sched: Allocate JobId=46078 NodeList=gpu05 #CPUs=16 Partition=gpu-v100s
[2022-07-08T16:09:07.389] _job_complete: JobId=46078 WEXITSTATUS 1
[2022-07-08T16:09:07.389] _job_complete: JobId=46078 done
[2022-07-08T16:11:53.766] _slurm_rpc_submit_batch_job: JobId=46079 InitPrio=19874 usec=446
[2022-07-08T16:11:54.594] sched: Allocate JobId=46079 NodeList=gpu05 #CPUs=16 Partition=gpu-v100s
[2022-07-08T16:12:02.873] _job_complete: JobId=46079 WEXITSTATUS 1
[2022-07-08T16:12:02.873] _job_complete: JobId=46079 done
[2022-07-08T16:13:17.814] _slurm_rpc_submit_batch_job: JobId=46080 InitPrio=19874 usec=483
[2022-07-08T16:13:17.829] sched: Allocate JobId=46080 NodeList=gpu05 #CPUs=16 Partition=gpu-v100s
[2022-07-08T16:13:26.056] _job_complete: JobId=46080 WEXITSTATUS 1
[2022-07-08T16:13:26.056] _job_complete: JobId=46080 done
[2022-07-08T16:14:25.212] _slurm_rpc_submit_batch_job: JobId=46081 InitPrio=19874 usec=401
[2022-07-08T16:14:25.926] sched: Allocate JobId=46081 NodeList=gpu05 #CPUs=16 Partition=gpu-v100s
[2022-07-08T16:20:03.170] _slurm_rpc_submit_batch_job: JobId=46082 InitPrio=19994 usec=430
[2022-07-08T16:20:03.540] sched: Allocate JobId=46082 NodeList=cpu11 #CPUs=2 Partition=cpu-opteron
[2022-07-08T16:20:06.201] _job_complete: JobId=46082 WEXITSTATUS 0
[2022-07-08T16:20:06.201] _job_complete: JobId=46082 done
[2022-07-08T16:28:01.013] _slurm_rpc_submit_batch_job: JobId=46083 InitPrio=21052 usec=470
[2022-07-08T16:28:01.719] sched: Allocate JobId=46083 NodeList=cpu11 #CPUs=4 Partition=cpu-opteron
[2022-07-08T16:28:20.230] _job_complete: JobId=46083 WEXITSTATUS 0
[2022-07-08T16:28:20.230] _job_complete: JobId=46083 done
[2022-07-08T16:28:47.912] _slurm_rpc_submit_batch_job: JobId=46084 InitPrio=20949 usec=503
[2022-07-08T16:28:48.771] sched: Allocate JobId=46084 NodeList=cpu15 #CPUs=16 Partition=cpu-epyc
[2022-07-08T17:18:21.563] _slurm_rpc_submit_batch_job: JobId=46085 InitPrio=19994 usec=443
[2022-07-08T17:19:06.900] _slurm_rpc_kill_job: REQUEST_KILL_JOB JobId=46085 uid 548200021
[2022-07-08T17:19:10.261] _slurm_rpc_submit_batch_job: JobId=46086 InitPrio=19994 usec=396
[2022-07-08T17:19:12.106] sched: Allocate JobId=46086 NodeList=cpu12 #CPUs=2 Partition=cpu-epyc
[2022-07-08T17:19:55.731] _job_complete: JobId=46086 WEXITSTATUS 0
[2022-07-08T17:19:55.731] _job_complete: JobId=46086 done
[2022-07-08T17:22:03.867] _slurm_rpc_submit_batch_job: JobId=46087 InitPrio=19874 usec=538
[2022-07-08T20:05:58.607] _slurm_rpc_submit_batch_job: JobId=46088 InitPrio=20411 usec=451
[2022-07-08T20:06:16.604] _slurm_rpc_kill_job: REQUEST_KILL_JOB JobId=46088 uid 548200045
[2022-07-08T20:06:28.321] _slurm_rpc_submit_batch_job: JobId=46089 InitPrio=20411 usec=373
[2022-07-08T20:06:28.460] sched: Allocate JobId=46089 NodeList=cpu12 #CPUs=16 Partition=cpu-epyc
[2022-07-08T21:18:23.225] _job_complete: JobId=46058 WEXITSTATUS 0
[2022-07-08T21:18:23.229] _job_complete: JobId=46058 done
[2022-07-08T22:52:01.213] _job_complete: JobId=46061 WEXITSTATUS 0
[2022-07-08T22:52:01.213] _job_complete: JobId=46061 done
[2022-07-08T23:07:18.822] _job_complete: JobId=46081 WEXITSTATUS 0
[2022-07-08T23:07:18.822] _job_complete: JobId=46081 done
[2022-07-08T23:07:19.696] sched: Allocate JobId=46087 NodeList=gpu05 #CPUs=16 Partition=gpu-v100s
[2022-07-08T23:17:30.985] _job_complete: JobId=45518 WEXITSTATUS 0
[2022-07-08T23:17:30.985] _job_complete: JobId=45518 done
[2022-07-08T23:17:31.303] sched: Allocate JobId=46029 NodeList=cpu13 #CPUs=16 Partition=cpu-epyc
[2022-07-08T23:43:38.434] _slurm_rpc_submit_batch_job: JobId=46090 InitPrio=19874 usec=433
[2022-07-08T23:43:39.227] sched: Allocate JobId=46090 NodeList=gpu03 #CPUs=16 Partition=gpu-k10
[2022-07-08T23:45:00.389] _slurm_rpc_kill_job: REQUEST_KILL_JOB JobId=46090 uid 548200021
[2022-07-08T23:45:57.704] _slurm_rpc_submit_batch_job: JobId=46091 InitPrio=19874 usec=447
[2022-07-08T23:45:58.419] sched: Allocate JobId=46091 NodeList=gpu03 #CPUs=16 Partition=gpu-k10
[2022-07-08T23:47:57.765] _slurm_rpc_submit_batch_job: JobId=46092 InitPrio=19874 usec=445
[2022-07-08T23:47:58.695] sched: Allocate JobId=46092 NodeList=gpu01 #CPUs=16 Partition=gpu-k10
[2022-07-08T23:57:21.606] _slurm_rpc_kill_job: REQUEST_KILL_JOB JobId=46091 uid 548200021
[2022-07-08T23:58:06.609] _job_complete: JobId=46084 WEXITSTATUS 0
[2022-07-08T23:58:06.609] _job_complete: JobId=46084 done
[2022-07-09T00:02:26.889] _slurm_rpc_submit_batch_job: JobId=46093 InitPrio=21218 usec=394
[2022-07-09T00:02:27.517] sched: Allocate JobId=46093 NodeList=gpu04 #CPUs=16 Partition=gpu-k40c
[2022-07-09T00:03:26.818] _job_create: exceeded association/QOS limit for user 548200021: QOSMaxWallDurationPerJobLimit
[2022-07-09T00:03:26.819] _slurm_rpc_submit_batch_job: Job violates accounting/QOS policy (job submit limit, user's size and/or time limits)
[2022-07-09T00:04:23.893] _slurm_rpc_submit_batch_job: JobId=46094 InitPrio=19874 usec=503
[2022-07-09T02:02:07.855] _job_complete: JobId=46092 WEXITSTATUS 0
[2022-07-09T02:02:07.856] _job_complete: JobId=46092 done
[2022-07-09T02:27:23.306] _job_complete: JobId=46027 WEXITSTATUS 0
[2022-07-09T02:27:23.306] _job_complete: JobId=46027 done
[2022-07-09T02:27:23.611] sched: Allocate JobId=46030 NodeList=cpu12 #CPUs=16 Partition=cpu-epyc
[2022-07-09T02:46:41.204] _job_complete: JobId=46065 WEXITSTATUS 0
[2022-07-09T02:46:41.204] _job_complete: JobId=46065 done
[2022-07-09T02:53:52.807] _job_complete: JobId=45560 WEXITSTATUS 0
[2022-07-09T02:53:52.808] _job_complete: JobId=45560 done
[2022-07-09T03:19:43.087] _job_complete: JobId=46026 WEXITSTATUS 0
[2022-07-09T03:19:43.088] _job_complete: JobId=46026 done
[2022-07-09T03:19:43.355] sched: Allocate JobId=46031 NodeList=cpu14 #CPUs=16 Partition=cpu-epyc
[2022-07-09T04:10:28.777] _slurm_rpc_submit_batch_job: JobId=46095 InitPrio=29014 usec=440
[2022-07-09T04:11:08.767] _slurm_rpc_submit_batch_job: JobId=46096 InitPrio=29065 usec=426
[2022-07-09T04:11:09.304] sched: Allocate JobId=46096 NodeList=gpu02 #CPUs=10 Partition=gpu-titan
[2022-07-09T04:11:32.585] _job_complete: JobId=46096 WEXITSTATUS 0
[2022-07-09T04:11:32.586] _job_complete: JobId=46096 done
[2022-07-09T04:21:44.088] _slurm_rpc_kill_job: REQUEST_KILL_JOB JobId=46095 uid 548300561
[2022-07-09T04:21:52.033] _slurm_rpc_submit_batch_job: JobId=46097 InitPrio=29065 usec=498
[2022-07-09T04:21:52.412] sched: Allocate JobId=46097 NodeList=gpu02 #CPUs=10 Partition=gpu-titan
[2022-07-09T04:22:50.906] _job_complete: JobId=46097 WEXITSTATUS 0
[2022-07-09T04:22:50.907] _job_complete: JobId=46097 done
[2022-07-09T04:23:29.166] _slurm_rpc_submit_batch_job: JobId=46098 InitPrio=29014 usec=436
[2022-07-09T07:33:39.921] _job_complete: JobId=46087 WEXITSTATUS 0
[2022-07-09T07:33:39.921] _job_complete: JobId=46087 done
[2022-07-09T07:33:40.841] sched: Allocate JobId=46098 NodeList=gpu05 #CPUs=16 Partition=gpu-v100s
[2022-07-09T07:34:34.767] _job_complete: JobId=46098 WEXITSTATUS 0
[2022-07-09T07:34:34.767] _job_complete: JobId=46098 done
[2022-07-09T07:34:35.651] sched: Allocate JobId=46094 NodeList=gpu05 #CPUs=16 Partition=gpu-v100s
[2022-07-09T07:39:26.794] _job_complete: JobId=46028 WEXITSTATUS 0
[2022-07-09T07:39:26.795] _job_complete: JobId=46028 done
[2022-07-09T07:39:27.038] sched: Allocate JobId=46032 NodeList=cpu12 #CPUs=16 Partition=cpu-epyc
[2022-07-09T08:54:30.188] _job_complete: JobId=46094 WEXITSTATUS 0
[2022-07-09T08:54:30.188] _job_complete: JobId=46094 done
[2022-07-09T10:39:27.306] _slurm_rpc_submit_batch_job: JobId=46099 InitPrio=19194 usec=545
[2022-07-09T10:39:27.403] sched: Allocate JobId=46099 NodeList=cpu07 #CPUs=64 Partition=cpu-opteron
[2022-07-09T10:41:05.015] _slurm_rpc_submit_batch_job: JobId=46100 InitPrio=19468 usec=422
[2022-07-09T13:15:14.522] _slurm_rpc_submit_batch_job: JobId=46101 InitPrio=20680 usec=507
[2022-07-09T13:15:15.170] sched: Allocate JobId=46101 NodeList=cpu15 #CPUs=16 Partition=cpu-epyc
[2022-07-09T13:15:57.272] _slurm_rpc_submit_batch_job: JobId=46102 InitPrio=20680 usec=427
[2022-07-09T13:16:49.811] _slurm_rpc_submit_batch_job: JobId=46103 InitPrio=20543 usec=496
[2022-07-09T13:16:50.283] sched: Allocate JobId=46103 NodeList=cpu09 #CPUs=32 Partition=cpu-opteron
[2022-07-09T16:07:29.350] _job_complete: JobId=46029 WEXITSTATUS 0
[2022-07-09T16:07:29.351] _job_complete: JobId=46029 done
[2022-07-09T16:07:29.773] sched: Allocate JobId=46033 NodeList=cpu13 #CPUs=16 Partition=cpu-epyc
[2022-07-09T18:22:31.176] _job_complete: JobId=46030 WEXITSTATUS 0
[2022-07-09T18:22:31.176] _job_complete: JobId=46030 done
[2022-07-09T18:22:31.530] sched: Allocate JobId=46034 NodeList=cpu12 #CPUs=16 Partition=cpu-epyc
[2022-07-09T21:34:04.703] _job_complete: JobId=46031 WEXITSTATUS 0
[2022-07-09T21:34:04.703] _job_complete: JobId=46031 done
[2022-07-09T21:34:04.967] sched: Allocate JobId=46035 NodeList=cpu14 #CPUs=16 Partition=cpu-epyc
[2022-07-09T21:35:32.223] _slurm_rpc_submit_batch_job: JobId=46104 InitPrio=24175 usec=419
[2022-07-09T21:35:32.420] sched: Allocate JobId=46104 NodeList=gpu05 #CPUs=16 Partition=gpu-v100s
[2022-07-09T21:46:37.205] _job_complete: JobId=46093 WEXITSTATUS 0
[2022-07-09T21:46:37.210] _job_complete: JobId=46093 done
[2022-07-09T23:20:49.012] Time limit exhausted for JobId=45499
[2022-07-10T00:04:44.994] _slurm_rpc_submit_batch_job: JobId=46105 InitPrio=19874 usec=506
[2022-07-10T00:04:45.409] sched: Allocate JobId=46105 NodeList=gpu02 #CPUs=16 Partition=gpu-titan
[2022-07-10T00:05:15.567] _job_complete: JobId=46105 OOM failure
[2022-07-10T00:05:15.567] _job_complete: JobId=46105 done
[2022-07-10T00:11:17.499] _slurm_rpc_submit_batch_job: JobId=46106 InitPrio=19874 usec=408
[2022-07-10T00:11:17.979] sched: Allocate JobId=46106 NodeList=gpu02 #CPUs=16 Partition=gpu-titan
[2022-07-10T00:13:09.715] _job_complete: JobId=46106 WEXITSTATUS 139
[2022-07-10T00:13:09.715] _job_complete: JobId=46106 done
[2022-07-10T00:42:22.192] _slurm_rpc_submit_batch_job: JobId=46107 InitPrio=21887 usec=441
[2022-07-10T00:42:22.237] sched: Allocate JobId=46107 NodeList=cpu04 #CPUs=32 Partition=cpu-opteron
[2022-07-10T00:42:25.432] _job_complete: JobId=46107 WEXITSTATUS 0
[2022-07-10T00:42:25.432] _job_complete: JobId=46107 done
[2022-07-10T00:50:40.179] _slurm_rpc_kill_job: REQUEST_KILL_JOB JobId=46104 uid 548300558
[2022-07-10T00:52:05.058] _slurm_rpc_submit_batch_job: JobId=46108 InitPrio=21887 usec=414
[2022-07-10T00:52:05.184] sched: Allocate JobId=46108 NodeList=cpu04 #CPUs=32 Partition=cpu-opteron
[2022-07-10T00:52:10.073] _job_complete: JobId=46108 WEXITSTATUS 0
[2022-07-10T00:52:10.073] _job_complete: JobId=46108 done
[2022-07-10T00:59:41.356] _slurm_rpc_submit_batch_job: JobId=46109 InitPrio=19959 usec=449
[2022-07-10T00:59:42.103] sched: Allocate JobId=46109 NodeList=gpu02 #CPUs=6 Partition=gpu-titan
[2022-07-10T01:01:14.868] _slurm_rpc_submit_batch_job: JobId=46110 InitPrio=21887 usec=424
[2022-07-10T01:01:15.223] sched: Allocate JobId=46110 NodeList=cpu04 #CPUs=32 Partition=cpu-opteron
[2022-07-10T01:01:45.280] _job_complete: JobId=46109 WEXITSTATUS 139
[2022-07-10T01:01:45.280] _job_complete: JobId=46109 done
[2022-07-10T01:02:33.794] _job_complete: JobId=46110 WEXITSTATUS 0
[2022-07-10T01:02:33.795] _job_complete: JobId=46110 done
[2022-07-10T01:02:59.860] _slurm_rpc_submit_batch_job: JobId=46111 InitPrio=19959 usec=513
[2022-07-10T01:02:59.875] sched: Allocate JobId=46111 NodeList=gpu05 #CPUs=6 Partition=gpu-v100s
[2022-07-10T01:09:02.507] _slurm_rpc_submit_batch_job: JobId=46112 InitPrio=21887 usec=417
[2022-07-10T01:09:02.555] sched: Allocate JobId=46112 NodeList=cpu04 #CPUs=32 Partition=cpu-opteron
[2022-07-10T01:09:04.974] _job_complete: JobId=46112 WEXITSTATUS 1
[2022-07-10T01:09:04.975] _job_complete: JobId=46112 done
[2022-07-10T01:09:44.399] _job_complete: JobId=46111 WEXITSTATUS 0
[2022-07-10T01:09:44.399] _job_complete: JobId=46111 done
[2022-07-10T01:09:59.346] _slurm_rpc_submit_batch_job: JobId=46113 InitPrio=21887 usec=375
[2022-07-10T01:09:59.629] sched: Allocate JobId=46113 NodeList=cpu04 #CPUs=32 Partition=cpu-opteron
[2022-07-10T01:10:01.611] _job_complete: JobId=46113 WEXITSTATUS 1
[2022-07-10T01:10:01.612] _job_complete: JobId=46113 done
[2022-07-10T01:11:40.720] _slurm_rpc_submit_batch_job: JobId=46114 InitPrio=21887 usec=357
[2022-07-10T01:11:40.772] sched: Allocate JobId=46114 NodeList=cpu04 #CPUs=32 Partition=cpu-opteron
[2022-07-10T01:11:44.842] _job_complete: JobId=46114 WEXITSTATUS 0
[2022-07-10T01:11:44.843] _job_complete: JobId=46114 done
[2022-07-10T01:16:20.636] _slurm_rpc_submit_batch_job: JobId=46115 InitPrio=21887 usec=503
[2022-07-10T01:16:21.279] sched: Allocate JobId=46115 NodeList=cpu04 #CPUs=32 Partition=cpu-opteron
[2022-07-10T01:16:25.474] _job_complete: JobId=46115 WEXITSTATUS 0
[2022-07-10T01:16:25.474] _job_complete: JobId=46115 done
[2022-07-10T01:18:39.733] _slurm_rpc_submit_batch_job: JobId=46116 InitPrio=21887 usec=467
[2022-07-10T01:18:40.616] sched: Allocate JobId=46116 NodeList=cpu04 #CPUs=32 Partition=cpu-opteron
[2022-07-10T01:19:56.552] _job_complete: JobId=46116 WEXITSTATUS 0
[2022-07-10T01:19:56.552] _job_complete: JobId=46116 done
[2022-07-10T01:28:00.590] _slurm_rpc_submit_batch_job: JobId=46117 InitPrio=21887 usec=448
[2022-07-10T01:28:00.663] sched: Allocate JobId=46117 NodeList=cpu04 #CPUs=32 Partition=cpu-opteron
[2022-07-10T01:28:03.330] _job_complete: JobId=46117 WEXITSTATUS 0
[2022-07-10T01:28:03.331] _job_complete: JobId=46117 done
[2022-07-10T01:34:16.646] _slurm_rpc_submit_batch_job: JobId=46118 InitPrio=21887 usec=472
[2022-07-10T01:34:17.289] sched: Allocate JobId=46118 NodeList=cpu04 #CPUs=32 Partition=cpu-opteron
[2022-07-10T01:34:21.889] _job_complete: JobId=46118 WEXITSTATUS 0
[2022-07-10T01:34:21.889] _job_complete: JobId=46118 done
[2022-07-10T01:42:32.736] _slurm_rpc_submit_batch_job: JobId=46119 InitPrio=21887 usec=390
[2022-07-10T01:42:33.151] sched: Allocate JobId=46119 NodeList=cpu04 #CPUs=32 Partition=cpu-opteron
[2022-07-10T01:42:35.827] _job_complete: JobId=46119 WEXITSTATUS 0
[2022-07-10T01:42:35.828] _job_complete: JobId=46119 done
[2022-07-10T01:43:55.371] _slurm_rpc_submit_batch_job: JobId=46120 InitPrio=21887 usec=428
[2022-07-10T01:43:56.309] sched: Allocate JobId=46120 NodeList=cpu04 #CPUs=32 Partition=cpu-opteron
[2022-07-10T01:44:00.778] _job_complete: JobId=46120 WEXITSTATUS 0
[2022-07-10T01:44:00.778] _job_complete: JobId=46120 done
[2022-07-10T01:48:03.851] _slurm_rpc_submit_batch_job: JobId=46121 InitPrio=21887 usec=367
[2022-07-10T01:48:04.757] sched: Allocate JobId=46121 NodeList=cpu04 #CPUs=32 Partition=cpu-opteron
[2022-07-10T01:48:05.686] _job_complete: JobId=46121 WEXITSTATUS 1
[2022-07-10T01:48:05.687] _job_complete: JobId=46121 done
[2022-07-10T01:53:38.876] _slurm_rpc_submit_batch_job: JobId=46122 InitPrio=21887 usec=415
[2022-07-10T01:53:39.329] sched: Allocate JobId=46122 NodeList=cpu04 #CPUs=32 Partition=cpu-opteron
[2022-07-10T01:53:57.960] _job_complete: JobId=46122 WEXITSTATUS 0
[2022-07-10T01:53:57.960] _job_complete: JobId=46122 done
[2022-07-10T01:54:01.137] _slurm_rpc_submit_batch_job: JobId=46123 InitPrio=21887 usec=424
[2022-07-10T01:54:01.355] sched: Allocate JobId=46123 NodeList=cpu04 #CPUs=32 Partition=cpu-opteron
[2022-07-10T01:54:03.547] _job_complete: JobId=46123 WEXITSTATUS 0
[2022-07-10T01:54:03.548] _job_complete: JobId=46123 done
[2022-07-10T01:54:14.558] _slurm_rpc_submit_batch_job: JobId=46124 InitPrio=21887 usec=411
[2022-07-10T01:54:15.375] sched: Allocate JobId=46124 NodeList=cpu04 #CPUs=32 Partition=cpu-opteron
[2022-07-10T01:54:19.393] _job_complete: JobId=46124 WEXITSTATUS 0
[2022-07-10T01:54:19.393] _job_complete: JobId=46124 done
[2022-07-10T01:54:26.205] _slurm_rpc_submit_batch_job: JobId=46125 InitPrio=21887 usec=364
[2022-07-10T01:54:26.389] sched: Allocate JobId=46125 NodeList=cpu04 #CPUs=32 Partition=cpu-opteron
[2022-07-10T01:54:39.295] _job_complete: JobId=46125 WEXITSTATUS 0
[2022-07-10T01:54:39.296] _job_complete: JobId=46125 done
[2022-07-10T01:54:50.218] _slurm_rpc_submit_batch_job: JobId=46126 InitPrio=21887 usec=364
[2022-07-10T01:54:50.425] sched: Allocate JobId=46126 NodeList=cpu04 #CPUs=32 Partition=cpu-opteron
[2022-07-10T01:55:00.834] _slurm_rpc_submit_batch_job: JobId=46127 InitPrio=21887 usec=400
[2022-07-10T01:55:47.245] _slurm_rpc_submit_batch_job: JobId=46128 InitPrio=21887 usec=514
[2022-07-10T01:56:06.180] _job_complete: JobId=46126 WEXITSTATUS 0
[2022-07-10T01:56:06.181] _job_complete: JobId=46126 done
[2022-07-10T01:56:06.667] sched: Allocate JobId=46127 NodeList=cpu04 #CPUs=32 Partition=cpu-opteron
[2022-07-10T01:57:23.228] _job_complete: JobId=46127 WEXITSTATUS 0
[2022-07-10T01:57:23.229] _job_complete: JobId=46127 done
[2022-07-10T01:57:23.699] sched: Allocate JobId=46128 NodeList=cpu04 #CPUs=32 Partition=cpu-opteron
[2022-07-10T01:57:39.170] _job_complete: JobId=46128 WEXITSTATUS 0
[2022-07-10T01:57:39.171] _job_complete: JobId=46128 done
[2022-07-10T02:08:53.671] _slurm_rpc_submit_batch_job: JobId=46129 InitPrio=21887 usec=428
[2022-07-10T02:08:54.259] sched: Allocate JobId=46129 NodeList=cpu04 #CPUs=32 Partition=cpu-opteron
[2022-07-10T02:09:14.223] _job_complete: JobId=46129 WEXITSTATUS 0
[2022-07-10T02:09:14.223] _job_complete: JobId=46129 done
[2022-07-10T02:47:13.512] _slurm_rpc_submit_batch_job: JobId=46130 InitPrio=21218 usec=443
[2022-07-10T02:47:15.717] sched: Allocate JobId=46130 NodeList=gpu04 #CPUs=16 Partition=gpu-k40c
[2022-07-10T07:33:18.938] _job_complete: JobId=46101 WEXITSTATUS 0
[2022-07-10T07:33:18.938] _job_complete: JobId=46101 done
[2022-07-10T07:33:19.803] sched: Allocate JobId=46102 NodeList=cpu15 #CPUs=16 Partition=cpu-epyc
[2022-07-10T09:00:15.334] _job_complete: JobId=46032 WEXITSTATUS 0
[2022-07-10T09:00:15.335] _job_complete: JobId=46032 done
[2022-07-10T09:00:15.645] sched: Allocate JobId=46036 NodeList=cpu12 #CPUs=16 Partition=cpu-epyc
[2022-07-10T13:16:51.654] Time limit exhausted for JobId=46103
[2022-07-10T14:08:42.792] _job_complete: JobId=46033 WEXITSTATUS 0
[2022-07-10T14:08:42.793] _job_complete: JobId=46033 done
[2022-07-10T14:08:43.103] sched: Allocate JobId=46037 NodeList=cpu13 #CPUs=16 Partition=cpu-epyc
[2022-07-10T14:39:04.480] _job_complete: JobId=46035 WEXITSTATUS 0
[2022-07-10T14:39:04.480] _job_complete: JobId=46035 done
[2022-07-10T14:39:04.735] sched: Allocate JobId=46038 NodeList=cpu14 #CPUs=16 Partition=cpu-epyc
[2022-07-10T15:15:53.221] _job_complete: JobId=46034 WEXITSTATUS 0
[2022-07-10T15:15:53.221] _job_complete: JobId=46034 done
[2022-07-10T15:15:53.465] sched: Allocate JobId=46039 NodeList=cpu12 #CPUs=16 Partition=cpu-epyc
[2022-07-10T15:36:54.566] _job_complete: JobId=45822 WEXITSTATUS 0
[2022-07-10T15:36:54.566] _job_complete: JobId=45822 done
[2022-07-11T02:47:23.392] Time limit exhausted for JobId=46130
[2022-07-11T04:05:45.116] _slurm_rpc_submit_batch_job: JobId=46131 InitPrio=24303 usec=526
[2022-07-11T04:05:45.305] sched: Allocate JobId=46131 NodeList=gpu02 #CPUs=1 Partition=gpu-titan
[2022-07-11T07:33:25.212] Time limit exhausted for JobId=46102
[2022-07-11T07:39:01.719] _job_complete: JobId=46037 WEXITSTATUS 0
[2022-07-11T07:39:01.719] _job_complete: JobId=46037 done
[2022-07-11T07:39:02.117] sched: Allocate JobId=46040 NodeList=cpu13 #CPUs=16 Partition=cpu-epyc
[2022-07-11T07:58:35.402] _slurm_rpc_submit_batch_job: JobId=46132 InitPrio=21218 usec=533
[2022-07-11T07:58:36.375] sched: Allocate JobId=46132 NodeList=gpu04 #CPUs=16 Partition=gpu-k40c
[2022-07-11T09:13:15.243] _job_complete: JobId=46131 WEXITSTATUS 0
[2022-07-11T09:13:15.244] _job_complete: JobId=46131 done
[2022-07-11T09:37:05.141] _job_complete: JobId=46038 WEXITSTATUS 0
[2022-07-11T09:37:05.141] _job_complete: JobId=46038 done
[2022-07-11T10:01:52.818] _slurm_rpc_submit_batch_job: JobId=46133 InitPrio=24303 usec=463
[2022-07-11T10:01:53.097] sched: Allocate JobId=46133 NodeList=gpu02 #CPUs=1 Partition=gpu-titan
[2022-07-11T10:31:17.288] _job_complete: JobId=46039 WEXITSTATUS 0
[2022-07-11T10:31:17.288] _job_complete: JobId=46039 done
[2022-07-11T11:26:51.420] _job_complete: JobId=46036 WEXITSTATUS 0
[2022-07-11T11:26:51.420] _job_complete: JobId=46036 done
[2022-07-11T11:26:51.668] sched: Allocate JobId=46100 NodeList=cpu12 #CPUs=32 Partition=cpu-epyc
[2022-07-11T11:58:51.219] _pick_best_nodes: JobId=46134 never runnable in partition gpu-v100s
[2022-07-11T11:58:51.224] _slurm_rpc_submit_batch_job: Requested node configuration is not available
[2022-07-11T12:05:10.300] _pick_best_nodes: JobId=46135 never runnable in partition gpu-v100s
[2022-07-11T12:05:10.300] _slurm_rpc_submit_batch_job: Requested node configuration is not available
[2022-07-11T12:08:44.320] _slurm_rpc_submit_batch_job: JobId=46136 InitPrio=29152 usec=357
[2022-07-11T12:09:21.566] _slurm_rpc_kill_job: REQUEST_KILL_JOB JobId=46136 uid 548300504
[2022-07-11T12:09:47.257] _slurm_rpc_submit_batch_job: JobId=46137 InitPrio=29152 usec=351
[2022-07-11T12:09:53.557] _slurm_rpc_kill_job: REQUEST_KILL_JOB JobId=46137 uid 548300504
[2022-07-11T12:11:30.094] _slurm_rpc_submit_batch_job: JobId=46138 InitPrio=29952 usec=467
[2022-07-11T12:13:14.887] _slurm_rpc_kill_job: REQUEST_KILL_JOB JobId=46138 uid 548300504
[2022-07-11T12:13:57.166] _slurm_rpc_submit_batch_job: JobId=46139 InitPrio=29152 usec=391
[2022-07-11T12:14:26.079] _slurm_rpc_kill_job: REQUEST_KILL_JOB JobId=46139 uid 548300504
[2022-07-11T12:15:12.379] _slurm_rpc_submit_batch_job: JobId=46140 InitPrio=29952 usec=585
[2022-07-11T12:50:06.643] _slurm_rpc_submit_batch_job: JobId=46141 InitPrio=20680 usec=645
[2022-07-11T12:50:07.033] sched: Allocate JobId=46141 NodeList=cpu14 #CPUs=16 Partition=cpu-epyc
[2022-07-11T12:51:04.173] _slurm_rpc_submit_batch_job: JobId=46142 InitPrio=20680 usec=401
[2022-07-11T12:51:05.103] sched: Allocate JobId=46142 NodeList=cpu15 #CPUs=16 Partition=cpu-epyc
[2022-07-11T13:17:39.491] _slurm_rpc_kill_job: REQUEST_KILL_JOB JobId=46140 uid 548300504
[2022-07-11T13:18:02.062] _slurm_rpc_submit_batch_job: JobId=46143 InitPrio=29952 usec=468
[2022-07-11T14:12:36.362] _job_complete: JobId=46142 WEXITSTATUS 0
[2022-07-11T14:12:36.362] _job_complete: JobId=46142 done
[2022-07-11T14:47:35.522] _slurm_rpc_submit_batch_job: JobId=46144 InitPrio=20538 usec=526
[2022-07-11T14:47:35.709] sched: Allocate JobId=46144 NodeList=cpu09 #CPUs=64 Partition=cpu-opteron
[2022-07-11T14:47:40.506] _job_complete: JobId=46144 WEXITSTATUS 1
[2022-07-11T14:47:40.506] _job_complete: JobId=46144 done
[2022-07-11T14:48:18.506] _slurm_rpc_submit_batch_job: JobId=46145 InitPrio=20538 usec=421
[2022-07-11T14:48:18.790] sched: Allocate JobId=46145 NodeList=cpu09 #CPUs=64 Partition=cpu-opteron
[2022-07-11T14:48:25.986] _job_complete: JobId=46145 WEXITSTATUS 1
[2022-07-11T14:48:25.987] _job_complete: JobId=46145 done
[2022-07-11T14:51:53.126] _slurm_rpc_submit_batch_job: JobId=46146 InitPrio=20538 usec=452
[2022-07-11T14:51:54.086] sched: Allocate JobId=46146 NodeList=cpu09 #CPUs=64 Partition=cpu-opteron
[2022-07-11T14:52:00.714] _job_complete: JobId=46146 WEXITSTATUS 1
[2022-07-11T14:52:00.714] _job_complete: JobId=46146 done
[2022-07-11T14:53:44.408] _slurm_rpc_submit_batch_job: JobId=46147 InitPrio=20538 usec=382
[2022-07-11T14:53:45.323] sched: Allocate JobId=46147 NodeList=cpu09 #CPUs=64 Partition=cpu-opteron
[2022-07-11T14:53:50.596] _job_complete: JobId=46147 WEXITSTATUS 1
[2022-07-11T14:53:50.596] _job_complete: JobId=46147 done
[2022-07-11T14:54:22.987] _slurm_rpc_submit_batch_job: JobId=46148 InitPrio=20538 usec=546
[2022-07-11T14:54:23.374] sched: Allocate JobId=46148 NodeList=cpu09 #CPUs=64 Partition=cpu-opteron
[2022-07-11T15:08:23.345] _job_complete: JobId=46133 WEXITSTATUS 0
[2022-07-11T15:08:23.345] _job_complete: JobId=46133 done
[2022-07-11T16:30:36.890] _job_complete: JobId=46132 WEXITSTATUS 0
[2022-07-11T16:30:36.896] _job_complete: JobId=46132 done
[2022-07-11T22:27:13.200] sched: _slurm_rpc_allocate_resources JobId=46149 NodeList=cpu11 usec=17468
[2022-07-11T22:29:35.486] _slurm_rpc_kill_job: REQUEST_KILL_JOB JobId=46143 uid 548300504
[2022-07-11T22:46:33.726] _slurm_rpc_submit_batch_job: JobId=46150 InitPrio=19874 usec=421
[2022-07-11T22:46:34.053] sched: Allocate JobId=46150 NodeList=cpu15 #CPUs=16 Partition=cpu-epyc
[2022-07-11T22:47:46.474] _slurm_rpc_kill_job: REQUEST_KILL_JOB JobId=46150 uid 548200021
[2022-07-11T22:47:56.716] _slurm_rpc_submit_batch_job: JobId=46151 InitPrio=19874 usec=382
[2022-07-11T22:47:57.280] sched: Allocate JobId=46151 NodeList=cpu15 #CPUs=16 Partition=cpu-epyc
[2022-07-11T23:10:14.972] _get_job_parts: invalid partition specified: cpu-v100s
[2022-07-11T23:10:14.972] _slurm_rpc_submit_batch_job: Invalid partition name specified
[2022-07-11T23:10:29.847] _slurm_rpc_submit_batch_job: JobId=46152 InitPrio=19874 usec=496
[2022-07-11T23:10:30.601] sched: Allocate JobId=46152 NodeList=gpu05 #CPUs=16 Partition=gpu-v100s
[2022-07-11T23:11:40.550] _slurm_rpc_kill_job: REQUEST_KILL_JOB JobId=46152 uid 548200021
[2022-07-11T23:12:22.407] _slurm_rpc_submit_batch_job: JobId=46153 InitPrio=19874 usec=510
[2022-07-11T23:12:22.754] sched: Allocate JobId=46153 NodeList=gpu05 #CPUs=16 Partition=gpu-v100s
[2022-07-11T23:12:48.161] _job_complete: JobId=46153 WEXITSTATUS 1
[2022-07-11T23:12:48.161] _job_complete: JobId=46153 done
[2022-07-11T23:20:28.083] _slurm_rpc_submit_batch_job: JobId=46154 InitPrio=19737 usec=474
[2022-07-11T23:20:28.590] sched: Allocate JobId=46154 NodeList=cpu04 #CPUs=32 Partition=cpu-opteron
[2022-07-11T23:38:07.893] _job_complete: JobId=46154 WEXITSTATUS 0
[2022-07-11T23:38:07.893] _job_complete: JobId=46154 done
[2022-07-12T00:16:09.691] _slurm_rpc_submit_batch_job: JobId=46155 InitPrio=29152 usec=385
[2022-07-12T00:18:19.757] _pick_best_nodes: JobId=46156 never runnable in partition gpu-v100s
[2022-07-12T00:18:19.762] _slurm_rpc_submit_batch_job: Requested node configuration is not available
[2022-07-12T00:20:12.600] _slurm_rpc_kill_job: REQUEST_KILL_JOB JobId=45817 uid 548300504
[2022-07-12T00:20:12.600] error: Security violation, REQUEST_KILL_JOB RPC for JobId=45817 from uid 548300504
[2022-07-12T00:20:12.600] _slurm_rpc_kill_job: job_str_signal() uid=548300504 JobId=45817 sig=9 returned: Access/permission denied
[2022-07-12T00:20:25.951] _slurm_rpc_kill_job: REQUEST_KILL_JOB JobId=46155 uid 548300504
[2022-07-12T00:23:26.654] _slurm_rpc_submit_batch_job: JobId=46157 InitPrio=29152 usec=399
[2022-07-12T00:23:34.196] _slurm_rpc_kill_job: REQUEST_KILL_JOB JobId=46157 uid 548300504
[2022-07-12T00:25:29.549] _slurm_rpc_submit_batch_job: JobId=46158 InitPrio=29426 usec=316
[2022-07-12T00:25:57.728] _slurm_rpc_kill_job: REQUEST_KILL_JOB JobId=46158 uid 548300504
[2022-07-12T00:26:17.527] _pick_best_nodes: JobId=46159 never runnable in partition gpu-titan
[2022-07-12T00:26:17.527] _slurm_rpc_submit_batch_job: Requested node configuration is not available
[2022-07-12T00:32:06.622] _pick_best_nodes: JobId=46160 never runnable in partition gpu-v100s
[2022-07-12T00:32:06.622] _slurm_rpc_submit_batch_job: Requested node configuration is not available
[2022-07-12T00:32:24.211] _slurm_rpc_submit_batch_job: JobId=46161 InitPrio=29152 usec=342
[2022-07-12T00:32:35.439] _slurm_rpc_kill_job: REQUEST_KILL_JOB JobId=46161 uid 548300504
[2022-07-12T00:34:02.223] _pick_best_nodes: JobId=46162 never runnable in partition gpu-titan
[2022-07-12T00:34:02.223] _slurm_rpc_submit_batch_job: Requested node configuration is not available
[2022-07-12T00:34:33.994] _slurm_rpc_submit_batch_job: JobId=46163 InitPrio=29426 usec=311
[2022-07-12T00:35:15.460] _slurm_rpc_kill_job: REQUEST_KILL_JOB JobId=46163 uid 548300504
[2022-07-12T00:36:06.633] _pick_best_nodes: JobId=46164 never runnable in partition gpu-titan
[2022-07-12T00:36:06.633] _slurm_rpc_submit_batch_job: Requested node configuration is not available
[2022-07-12T00:37:03.709] _pick_best_nodes: JobId=46165 never runnable in partition gpu-titan
[2022-07-12T00:37:03.709] _slurm_rpc_submit_batch_job: Requested node configuration is not available
[2022-07-12T00:37:31.786] _pick_best_nodes: JobId=46166 never runnable in partition gpu-titan
[2022-07-12T00:37:31.786] _slurm_rpc_submit_batch_job: Requested node configuration is not available
[2022-07-12T00:38:14.999] _slurm_rpc_submit_batch_job: JobId=46167 InitPrio=30089 usec=495
[2022-07-12T00:38:15.681] sched: Allocate JobId=46167 NodeList=gpu02 #CPUs=16 Partition=gpu-titan
[2022-07-12T00:40:24.721] _slurm_rpc_submit_batch_job: JobId=46168 InitPrio=29152 usec=399
[2022-07-12T00:40:41.960] _slurm_rpc_kill_job: REQUEST_KILL_JOB JobId=46168 uid 548300504
[2022-07-12T00:50:28.869] _slurm_rpc_kill_job: REQUEST_KILL_JOB JobId=46167 uid 548300504
[2022-07-12T00:51:57.891] _slurm_rpc_submit_batch_job: JobId=46169 InitPrio=29551 usec=574
[2022-07-12T00:51:58.094] sched: Allocate JobId=46169 NodeList=gpu02 #CPUs=16 Partition=gpu-titan
[2022-07-12T00:51:58.438] _job_complete: JobId=46169 WEXITSTATUS 1
[2022-07-12T00:51:58.438] _job_complete: JobId=46169 done
[2022-07-12T00:52:13.907] _slurm_rpc_kill_job: REQUEST_KILL_JOB JobId=46169 uid 548300504
[2022-07-12T00:53:57.308] _slurm_rpc_submit_batch_job: JobId=46170 InitPrio=29551 usec=393
[2022-07-12T00:53:57.363] sched: Allocate JobId=46170 NodeList=gpu02 #CPUs=16 Partition=gpu-titan
[2022-07-12T00:53:57.603] _job_complete: JobId=46170 WEXITSTATUS 1
[2022-07-12T00:53:57.603] _job_complete: JobId=46170 done
[2022-07-12T00:54:22.478] _slurm_rpc_submit_batch_job: JobId=46171 InitPrio=29551 usec=439
[2022-07-12T00:54:23.398] sched: Allocate JobId=46171 NodeList=gpu02 #CPUs=16 Partition=gpu-titan
[2022-07-12T00:54:23.654] _job_complete: JobId=46171 WEXITSTATUS 1
[2022-07-12T00:54:23.655] _job_complete: JobId=46171 done
[2022-07-12T00:54:49.995] _slurm_rpc_kill_job: REQUEST_KILL_JOB JobId=46171 uid 548300504
[2022-07-12T00:56:35.060] _slurm_rpc_submit_batch_job: JobId=46172 InitPrio=29551 usec=398
[2022-07-12T00:56:35.586] sched: Allocate JobId=46172 NodeList=cpu04 #CPUs=16 Partition=cpu-opteron
[2022-07-12T00:56:36.413] _job_complete: JobId=46172 WEXITSTATUS 2
[2022-07-12T00:56:36.413] _job_complete: JobId=46172 done
[2022-07-12T00:57:02.404] _job_complete: JobId=46149 WEXITSTATUS 0
[2022-07-12T00:57:02.404] _job_complete: JobId=46149 done
[2022-07-12T00:57:09.939] _slurm_rpc_kill_job: REQUEST_KILL_JOB JobId=46172 uid 548300504
[2022-07-12T00:57:20.574] _slurm_rpc_kill_job: REQUEST_KILL_JOB JobId=46171 uid 548300504
[2022-07-12T00:57:23.612] _slurm_rpc_kill_job: REQUEST_KILL_JOB JobId=46170 uid 548300504
[2022-07-12T00:57:27.198] _slurm_rpc_kill_job: REQUEST_KILL_JOB JobId=46169 uid 548300504
[2022-07-12T00:57:34.515] _slurm_rpc_kill_job: REQUEST_KILL_JOB JobId=46168 uid 548300504
[2022-07-12T00:57:34.515] job_str_signal(3): invalid JobId=46168
[2022-07-12T00:57:34.515] _slurm_rpc_kill_job: job_str_signal() uid=548300504 JobId=46168 sig=9 returned: Invalid job id specified
[2022-07-12T00:57:37.753] _slurm_rpc_kill_job: REQUEST_KILL_JOB JobId=46167 uid 548300504
[2022-07-12T00:57:41.856] _slurm_rpc_kill_job: REQUEST_KILL_JOB JobId=46166 uid 548300504
[2022-07-12T00:57:41.856] job_str_signal(3): invalid JobId=46166
[2022-07-12T00:57:41.856] _slurm_rpc_kill_job: job_str_signal() uid=548300504 JobId=46166 sig=9 returned: Invalid job id specified
[2022-07-12T00:57:49.711] _slurm_rpc_kill_job: REQUEST_KILL_JOB JobId=45817 uid 548300504
[2022-07-12T00:57:49.711] error: Security violation, REQUEST_KILL_JOB RPC for JobId=45817 from uid 548300504
[2022-07-12T00:57:49.711] _slurm_rpc_kill_job: job_str_signal() uid=548300504 JobId=45817 sig=9 returned: Access/permission denied
[2022-07-12T00:57:58.058] _slurm_rpc_kill_job: REQUEST_KILL_JOB JobId=46165 uid 548300504
[2022-07-12T00:57:58.058] job_str_signal(3): invalid JobId=46165
[2022-07-12T00:57:58.058] _slurm_rpc_kill_job: job_str_signal() uid=548300504 JobId=46165 sig=9 returned: Invalid job id specified
[2022-07-12T00:58:01.119] _slurm_rpc_kill_job: REQUEST_KILL_JOB JobId=46164 uid 548300504
[2022-07-12T00:58:01.119] job_str_signal(3): invalid JobId=46164
[2022-07-12T00:58:01.119] _slurm_rpc_kill_job: job_str_signal() uid=548300504 JobId=46164 sig=9 returned: Invalid job id specified
[2022-07-12T00:58:04.031] _slurm_rpc_kill_job: REQUEST_KILL_JOB JobId=46163 uid 548300504
[2022-07-12T00:58:04.031] job_str_signal(3): invalid JobId=46163
[2022-07-12T00:58:04.031] _slurm_rpc_kill_job: job_str_signal() uid=548300504 JobId=46163 sig=9 returned: Invalid job id specified
[2022-07-12T00:58:06.739] _slurm_rpc_kill_job: REQUEST_KILL_JOB JobId=46162 uid 548300504
[2022-07-12T00:58:06.739] job_str_signal(3): invalid JobId=46162
[2022-07-12T00:58:06.739] _slurm_rpc_kill_job: job_str_signal() uid=548300504 JobId=46162 sig=9 returned: Invalid job id specified
[2022-07-12T00:58:09.370] _slurm_rpc_kill_job: REQUEST_KILL_JOB JobId=46161 uid 548300504
[2022-07-12T00:58:09.370] job_str_signal(3): invalid JobId=46161
[2022-07-12T00:58:09.370] _slurm_rpc_kill_job: job_str_signal() uid=548300504 JobId=46161 sig=9 returned: Invalid job id specified
[2022-07-12T00:58:13.586] _slurm_rpc_kill_job: REQUEST_KILL_JOB JobId=46160 uid 548300504
[2022-07-12T00:58:13.586] job_str_signal(3): invalid JobId=46160
[2022-07-12T00:58:13.587] _slurm_rpc_kill_job: job_str_signal() uid=548300504 JobId=46160 sig=9 returned: Invalid job id specified
[2022-07-12T00:58:15.394] _slurm_rpc_kill_job: REQUEST_KILL_JOB JobId=46160 uid 548300504
[2022-07-12T00:58:15.394] job_str_signal(3): invalid JobId=46160
[2022-07-12T00:58:15.394] _slurm_rpc_kill_job: job_str_signal() uid=548300504 JobId=46160 sig=9 returned: Invalid job id specified
[2022-07-12T00:58:19.279] _slurm_rpc_kill_job: REQUEST_KILL_JOB JobId=46159 uid 548300504
[2022-07-12T00:58:19.279] job_str_signal(3): invalid JobId=46159
[2022-07-12T00:58:19.279] _slurm_rpc_kill_job: job_str_signal() uid=548300504 JobId=46159 sig=9 returned: Invalid job id specified
[2022-07-12T00:58:24.780] _slurm_rpc_kill_job: REQUEST_KILL_JOB JobId=46158 uid 548300504
[2022-07-12T00:58:24.780] job_str_signal(3): invalid JobId=46158
[2022-07-12T00:58:24.780] _slurm_rpc_kill_job: job_str_signal() uid=548300504 JobId=46158 sig=9 returned: Invalid job id specified
[2022-07-12T00:58:28.281] _slurm_rpc_kill_job: REQUEST_KILL_JOB JobId=46157 uid 548300504
[2022-07-12T00:58:28.281] job_str_signal(3): invalid JobId=46157
[2022-07-12T00:58:28.281] _slurm_rpc_kill_job: job_str_signal() uid=548300504 JobId=46157 sig=9 returned: Invalid job id specified
[2022-07-12T00:58:31.171] _slurm_rpc_kill_job: REQUEST_KILL_JOB JobId=46156 uid 548300504
[2022-07-12T00:58:31.171] job_str_signal(3): invalid JobId=46156
[2022-07-12T00:58:31.171] _slurm_rpc_kill_job: job_str_signal() uid=548300504 JobId=46156 sig=9 returned: Invalid job id specified
[2022-07-12T00:58:34.414] _slurm_rpc_kill_job: REQUEST_KILL_JOB JobId=46155 uid 548300504
[2022-07-12T00:58:34.414] job_str_signal(3): invalid JobId=46155
[2022-07-12T00:58:34.414] _slurm_rpc_kill_job: job_str_signal() uid=548300504 JobId=46155 sig=9 returned: Invalid job id specified
[2022-07-12T00:58:37.167] _slurm_rpc_kill_job: REQUEST_KILL_JOB JobId=46154 uid 548300504
[2022-07-12T00:58:37.167] job_str_signal(3): invalid JobId=46154
[2022-07-12T00:58:37.167] _slurm_rpc_kill_job: job_str_signal() uid=548300504 JobId=46154 sig=9 returned: Invalid job id specified
[2022-07-12T00:58:39.770] _slurm_rpc_kill_job: REQUEST_KILL_JOB JobId=46153 uid 548300504
[2022-07-12T00:58:39.770] job_str_signal(3): invalid JobId=46153
[2022-07-12T00:58:39.770] _slurm_rpc_kill_job: job_str_signal() uid=548300504 JobId=46153 sig=9 returned: Invalid job id specified
[2022-07-12T00:58:43.805] _slurm_rpc_kill_job: REQUEST_KILL_JOB JobId=46152 uid 548300504
[2022-07-12T00:58:43.805] job_str_signal(3): invalid JobId=46152
[2022-07-12T00:58:43.805] _slurm_rpc_kill_job: job_str_signal() uid=548300504 JobId=46152 sig=9 returned: Invalid job id specified
[2022-07-12T00:58:48.479] _slurm_rpc_kill_job: REQUEST_KILL_JOB JobId=46151 uid 548300504
[2022-07-12T00:58:48.479] error: Security violation, REQUEST_KILL_JOB RPC for JobId=46151 from uid 548300504
[2022-07-12T00:58:48.479] _slurm_rpc_kill_job: job_str_signal() uid=548300504 JobId=46151 sig=9 returned: Access/permission denied
[2022-07-12T01:03:28.418] _slurm_rpc_submit_batch_job: JobId=46173 InitPrio=29414 usec=532
[2022-07-12T01:06:05.362] _slurm_rpc_kill_job: REQUEST_KILL_JOB JobId=46173 uid 548300504
[2022-07-12T01:08:11.812] _pick_best_nodes: JobId=46174 never runnable in partition gpu-titan
[2022-07-12T01:08:11.812] _slurm_rpc_allocate_resources: Requested node configuration is not available 
[2022-07-12T01:08:30.595] sched: _slurm_rpc_allocate_resources JobId=46175 NodeList=gpu02 usec=4645
[2022-07-12T01:09:42.718] _job_complete: JobId=46175 WEXITSTATUS 130
[2022-07-12T01:09:42.718] _job_complete: JobId=46175 done
[2022-07-12T01:10:23.355] _slurm_rpc_submit_batch_job: JobId=46176 InitPrio=29551 usec=358
[2022-07-12T01:10:23.500] sched: Allocate JobId=46176 NodeList=gpu02 #CPUs=16 Partition=gpu-titan
[2022-07-12T01:25:04.067] sched: _slurm_rpc_allocate_resources JobId=46177 NodeList=(null) usec=902
[2022-07-12T01:25:05.038] sched: Allocate JobId=46177 NodeList=cpu11 #CPUs=16 Partition=cpu-opteron
[2022-07-12T01:32:10.973] _job_complete: JobId=46177 WEXITSTATUS 0
[2022-07-12T01:32:10.973] _job_complete: JobId=46177 done
[2022-07-12T01:39:38.363] sched: _slurm_rpc_allocate_resources JobId=46178 NodeList=(null) usec=838
[2022-07-12T01:39:38.594] sched: Allocate JobId=46178 NodeList=cpu11 #CPUs=16 Partition=cpu-opteron
[2022-07-12T02:38:38.955] _job_complete: JobId=46178 WEXITSTATUS 1
[2022-07-12T02:38:38.956] _job_complete: JobId=46178 done
[2022-07-12T02:39:01.605] sched: _slurm_rpc_allocate_resources JobId=46179 NodeList=(null) usec=943
[2022-07-12T02:39:01.858] sched: Allocate JobId=46179 NodeList=cpu11 #CPUs=16 Partition=cpu-opteron
[2022-07-12T02:51:00.481] _job_complete: JobId=46179 WEXITSTATUS 0
[2022-07-12T02:51:00.481] _job_complete: JobId=46179 done
[2022-07-12T03:02:20.448] _slurm_rpc_submit_batch_job: JobId=46180 InitPrio=22425 usec=417
[2022-07-12T04:53:37.363] _job_complete: JobId=46040 WEXITSTATUS 0
[2022-07-12T04:53:37.363] _job_complete: JobId=46040 done
[2022-07-12T08:42:15.993] Requeuing JobId=46176
[2022-07-12T09:10:48.492] _slurm_rpc_kill_job: REQUEST_KILL_JOB JobId=46176 uid 548300504
[2022-07-12T09:13:13.677] _pick_best_nodes: JobId=46181 never runnable in partition gpu-titan
[2022-07-12T09:13:13.677] _slurm_rpc_submit_batch_job: Requested node configuration is not available
[2022-07-12T09:15:46.412] _slurm_rpc_submit_batch_job: JobId=46182 InitPrio=26646 usec=374
[2022-07-12T09:15:47.384] sched: Allocate JobId=46182 NodeList=gpu02 #CPUs=10 Partition=gpu-titan
[2022-07-12T09:25:38.630] _slurm_rpc_kill_job: REQUEST_KILL_JOB JobId=46182 uid 548300504
[2022-07-12T09:28:35.538] _slurm_rpc_submit_batch_job: JobId=46183 InitPrio=26646 usec=425
[2022-07-12T09:28:35.850] sched: Allocate JobId=46183 NodeList=gpu02 #CPUs=10 Partition=gpu-titan
[2022-07-12T09:34:13.974] _slurm_rpc_submit_batch_job: JobId=46184 InitPrio=24303 usec=561
[2022-07-12T09:34:14.546] sched: Allocate JobId=46184 NodeList=gpu02 #CPUs=1 Partition=gpu-titan
[2022-07-12T09:35:57.199] _slurm_rpc_submit_batch_job: JobId=46185 InitPrio=24303 usec=435
[2022-07-12T10:14:42.454] _slurm_rpc_submit_batch_job: JobId=46186 InitPrio=29414 usec=456
[2022-07-12T10:17:57.838] _slurm_rpc_submit_batch_job: JobId=46187 InitPrio=29414 usec=551
[2022-07-12T10:20:17.570] _slurm_rpc_kill_job: REQUEST_KILL_JOB JobId=46187 uid 548200036
[2022-07-12T10:21:03.647] _slurm_rpc_submit_batch_job: JobId=46188 InitPrio=29620 usec=433
[2022-07-12T10:21:04.145] sched: Allocate JobId=46188 NodeList=cpu13 #CPUs=8 Partition=cpu-epyc
[2022-07-12T10:21:09.882] _job_complete: JobId=46188 WEXITSTATUS 1
[2022-07-12T10:21:09.882] _job_complete: JobId=46188 done
[2022-07-12T10:22:31.741] _slurm_rpc_submit_batch_job: JobId=46189 InitPrio=29551 usec=456
[2022-07-12T10:22:32.248] sched: Allocate JobId=46189 NodeList=cpu11 #CPUs=16 Partition=cpu-opteron
[2022-07-12T10:22:33.709] _job_complete: JobId=46189 WEXITSTATUS 1
[2022-07-12T10:22:33.709] _job_complete: JobId=46189 done
[2022-07-12T10:25:24.502] _slurm_rpc_submit_batch_job: JobId=46190 InitPrio=29620 usec=440
[2022-07-12T10:25:24.523] sched: Allocate JobId=46190 NodeList=cpu13 #CPUs=8 Partition=cpu-epyc
[2022-07-12T10:25:30.449] _job_complete: JobId=46190 WEXITSTATUS 1
[2022-07-12T10:25:30.449] _job_complete: JobId=46190 done
[2022-07-12T10:26:03.517] _slurm_rpc_kill_job: REQUEST_KILL_JOB JobId=46186 uid 548200036
[2022-07-12T10:28:45.053] _slurm_rpc_submit_batch_job: JobId=46191 InitPrio=29277 usec=384
[2022-07-12T10:29:38.339] _slurm_rpc_submit_batch_job: JobId=46192 InitPrio=68927 usec=504
[2022-07-12T10:29:39.135] sched: Allocate JobId=46192 NodeList=cpu11 #CPUs=1 Partition=cpu-opteron
[2022-07-12T10:30:56.418] _slurm_rpc_kill_job: REQUEST_KILL_JOB JobId=46191 uid 548200036
[2022-07-12T10:32:26.909] _slurm_rpc_submit_batch_job: JobId=46193 InitPrio=29620 usec=443
[2022-07-12T10:32:27.322] sched: Allocate JobId=46193 NodeList=cpu13 #CPUs=8 Partition=cpu-epyc
[2022-07-12T10:34:21.594] _job_complete: JobId=46183 WEXITSTATUS 0
[2022-07-12T10:34:21.600] _job_complete: JobId=46183 done
[2022-07-12T10:34:23.521] sched: Allocate JobId=46185 NodeList=gpu02 #CPUs=1 Partition=gpu-titan
[2022-07-12T10:35:06.331] _slurm_rpc_submit_batch_job: JobId=46194 InitPrio=29620 usec=483
[2022-07-12T10:35:06.463] sched/backfill: _start_job: Started JobId=46194 in cpu-epyc on cpu13
[2022-07-12T10:35:42.859] _slurm_rpc_submit_batch_job: JobId=46195 InitPrio=29620 usec=380
[2022-07-12T10:35:56.732] _slurm_rpc_submit_batch_job: JobId=46196 InitPrio=29620 usec=432
[2022-07-12T10:36:30.267] _slurm_rpc_submit_batch_job: JobId=46197 InitPrio=29620 usec=419
[2022-07-12T10:38:07.622] _slurm_rpc_kill_job: REQUEST_KILL_JOB JobId=46197 uid 548200036
[2022-07-12T10:38:51.747] _slurm_rpc_submit_batch_job: JobId=46198 InitPrio=29620 usec=591
[2022-07-12T10:38:52.031] sched: Allocate JobId=46198 NodeList=cpu11 #CPUs=8 Partition=cpu-opteron
[2022-07-12T10:39:27.894] _slurm_rpc_kill_job: REQUEST_KILL_JOB JobId=46196 uid 548200036
[2022-07-12T10:39:56.010] _slurm_rpc_submit_batch_job: JobId=46199 InitPrio=29620 usec=620
[2022-07-12T10:39:56.123] sched: Allocate JobId=46199 NodeList=cpu04 #CPUs=8 Partition=cpu-opteron
[2022-07-12T10:40:22.485] _slurm_rpc_kill_job: REQUEST_KILL_JOB JobId=46195 uid 548200036
[2022-07-12T10:40:41.406] _slurm_rpc_submit_batch_job: JobId=46200 InitPrio=29620 usec=447
[2022-07-12T10:41:03.003] _slurm_rpc_kill_job: REQUEST_KILL_JOB JobId=46200 uid 548200036
[2022-07-12T10:41:26.778] _slurm_rpc_submit_batch_job: JobId=46201 InitPrio=29620 usec=683
[2022-07-12T10:43:24.613] _slurm_rpc_submit_batch_job: JobId=46202 InitPrio=28813 usec=401
[2022-07-12T10:45:04.713] _slurm_rpc_submit_batch_job: JobId=46203 InitPrio=28822 usec=606
[2022-07-12T10:45:05.682] sched: Allocate JobId=46203 NodeList=cpu11 #CPUs=7 Partition=cpu-opteron
[2022-07-12T10:45:57.320] _slurm_rpc_kill_job: REQUEST_KILL_JOB JobId=46202 uid 548200036
[2022-07-12T10:46:30.104] _slurm_rpc_kill_job: REQUEST_KILL_JOB JobId=46193 uid 548200036
[2022-07-12T10:46:32.079] sched: Allocate JobId=46201 NodeList=cpu13 #CPUs=8 Partition=cpu-epyc
[2022-07-12T10:46:37.845] _job_complete: JobId=46201 WEXITSTATUS 1
[2022-07-12T10:46:37.845] _job_complete: JobId=46201 done
[2022-07-12T10:48:14.761] _slurm_rpc_submit_batch_job: JobId=46204 InitPrio=28813 usec=392
[2022-07-12T10:48:15.000] sched: Allocate JobId=46204 NodeList=cpu13 #CPUs=8 Partition=cpu-epyc
[2022-07-12T10:48:21.020] _job_complete: JobId=46204 WEXITSTATUS 1
[2022-07-12T10:48:21.020] _job_complete: JobId=46204 done
[2022-07-12T10:49:50.924] _slurm_rpc_submit_batch_job: JobId=46205 InitPrio=28813 usec=468
[2022-07-12T10:49:51.133] sched: Allocate JobId=46205 NodeList=cpu13 #CPUs=8 Partition=cpu-epyc
[2022-07-12T10:49:56.525] _job_complete: JobId=46205 WEXITSTATUS 1
[2022-07-12T10:49:56.525] _job_complete: JobId=46205 done
[2022-07-12T11:14:26.171] _job_complete: JobId=46194 WEXITSTATUS 1
[2022-07-12T11:14:26.171] _job_complete: JobId=46194 done
[2022-07-12T12:50:33.664] Time limit exhausted for JobId=46141
[2022-07-12T13:17:59.250] _job_complete: JobId=46199 WEXITSTATUS 1
[2022-07-12T13:17:59.250] _job_complete: JobId=46199 done
[2022-07-12T13:22:24.678] _job_complete: JobId=46198 WEXITSTATUS 1
[2022-07-12T13:22:24.678] _job_complete: JobId=46198 done
[2022-07-12T13:29:22.605] _slurm_rpc_submit_batch_job: JobId=46206 InitPrio=26646 usec=392
[2022-07-12T13:29:43.630] _slurm_rpc_kill_job: REQUEST_KILL_JOB JobId=46206 uid 548300504
[2022-07-12T13:39:59.928] _slurm_rpc_submit_batch_job: JobId=46207 InitPrio=26646 usec=507
[2022-07-12T14:07:50.705] _job_complete: JobId=46203 WEXITSTATUS 1
[2022-07-12T14:07:50.705] _job_complete: JobId=46203 done
[2022-07-12T14:11:42.699] _slurm_rpc_kill_job: REQUEST_KILL_JOB JobId=46192 uid 548200003
[2022-07-12T15:08:56.649] _job_complete: JobId=46184 WEXITSTATUS 0
[2022-07-12T15:08:56.649] _job_complete: JobId=46184 done
[2022-07-12T15:08:57.123] sched: Allocate JobId=46207 NodeList=gpu02 #CPUs=10 Partition=gpu-titan
[2022-07-12T15:10:09.798] _job_complete: JobId=46207 WEXITSTATUS 1
[2022-07-12T15:10:09.799] _job_complete: JobId=46207 done
[2022-07-12T15:45:27.613] _slurm_rpc_submit_batch_job: JobId=46208 InitPrio=27738 usec=492
[2022-07-12T15:46:22.362] _job_complete: JobId=46185 WEXITSTATUS 0
[2022-07-12T15:46:22.362] _job_complete: JobId=46185 done
[2022-07-12T15:48:22.538] _slurm_rpc_submit_batch_job: JobId=46209 InitPrio=27670 usec=488
[2022-07-12T15:48:23.084] sched: Allocate JobId=46209 NodeList=cpu11 #CPUs=16 Partition=cpu-opteron
[2022-07-12T15:50:02.282] _slurm_rpc_submit_batch_job: JobId=46210 InitPrio=27670 usec=519
[2022-07-12T15:51:29.546] _slurm_rpc_submit_batch_job: JobId=46211 InitPrio=27670 usec=423
[2022-07-12T15:51:30.326] sched: Allocate JobId=46211 NodeList=cpu04 #CPUs=16 Partition=cpu-opteron
[2022-07-12T15:52:52.677] _slurm_rpc_submit_batch_job: JobId=46212 InitPrio=27670 usec=525
[2022-07-12T16:15:28.568] _slurm_rpc_submit_batch_job: JobId=46213 InitPrio=27401 usec=474
[2022-07-12T16:18:27.279] _slurm_rpc_submit_batch_job: JobId=46214 InitPrio=27401 usec=607
[2022-07-12T16:20:07.862] _slurm_rpc_submit_batch_job: JobId=46215 InitPrio=27401 usec=394
[2022-07-12T16:20:27.589] _slurm_rpc_submit_batch_job: JobId=46216 InitPrio=24478 usec=277
[2022-07-12T16:20:33.631] _slurm_rpc_kill_job: REQUEST_KILL_JOB JobId=46215 uid 548200036
[2022-07-12T16:21:25.461] _slurm_rpc_kill_job: REQUEST_KILL_JOB JobId=46216 uid 548300513
[2022-07-12T16:21:36.421] _slurm_rpc_submit_batch_job: JobId=46217 InitPrio=24444 usec=341
[2022-07-12T16:28:04.621] _slurm_rpc_submit_batch_job: JobId=46218 InitPrio=27401 usec=471
[2022-07-12T16:28:06.833] sched/backfill: _start_job: Started JobId=46218 in cpu-epyc on cpu13
[2022-07-12T16:28:13.383] _job_complete: JobId=46218 WEXITSTATUS 1
[2022-07-12T16:28:13.383] _job_complete: JobId=46218 done
[2022-07-12T16:34:38.843] _slurm_rpc_submit_batch_job: JobId=46219 InitPrio=27469 usec=463
[2022-07-12T16:34:39.366] sched: Allocate JobId=46219 NodeList=cpu04 #CPUs=8 Partition=cpu-opteron
[2022-07-12T16:34:53.938] _job_complete: JobId=46219 WEXITSTATUS 1
[2022-07-12T16:34:53.938] _job_complete: JobId=46219 done
[2022-07-12T16:34:56.292] _slurm_rpc_kill_job: REQUEST_KILL_JOB JobId=46212 uid 548200036
[2022-07-12T16:39:51.060] _slurm_rpc_submit_batch_job: JobId=46220 InitPrio=27469 usec=443
[2022-07-12T16:39:51.298] sched: Allocate JobId=46220 NodeList=cpu04 #CPUs=8 Partition=cpu-opteron
[2022-07-12T16:40:03.332] _slurm_rpc_submit_batch_job: JobId=46221 InitPrio=27469 usec=453
[2022-07-12T16:40:04.981] _job_complete: JobId=46220 WEXITSTATUS 1
[2022-07-12T16:40:04.981] _job_complete: JobId=46220 done
[2022-07-12T16:40:05.424] sched: Allocate JobId=46221 NodeList=cpu04 #CPUs=8 Partition=cpu-opteron
[2022-07-12T16:40:06.269] _job_complete: JobId=46221 WEXITSTATUS 1
[2022-07-12T16:40:06.269] _job_complete: JobId=46221 done
[2022-07-12T16:41:10.471] _slurm_rpc_submit_batch_job: JobId=46222 InitPrio=27469 usec=641
[2022-07-12T16:41:11.406] sched: Allocate JobId=46222 NodeList=cpu04 #CPUs=8 Partition=cpu-opteron
[2022-07-12T20:42:20.263] _slurm_rpc_submit_batch_job: JobId=46223 InitPrio=21218 usec=427
[2022-07-12T20:42:20.770] sched: Allocate JobId=46223 NodeList=gpu04 #CPUs=16 Partition=gpu-k40c
[2022-07-12T21:27:45.063] _slurm_rpc_submit_batch_job: JobId=46224 InitPrio=26646 usec=412
[2022-07-12T21:27:45.546] sched: Allocate JobId=46224 NodeList=gpu02 #CPUs=10 Partition=gpu-titan
[2022-07-12T23:55:55.460] _job_complete: JobId=46057 WEXITSTATUS 0
[2022-07-12T23:55:55.465] _job_complete: JobId=46057 done
[2022-07-12T23:55:58.326] sched: Allocate JobId=45637 NodeList=cpu13 #CPUs=48 Partition=cpu-epyc
[2022-07-13T00:09:35.077] _job_complete: JobId=45637 WEXITSTATUS 0
[2022-07-13T00:09:35.078] _job_complete: JobId=45637 done
[2022-07-13T00:09:35.307] sched: Allocate JobId=45638 NodeList=cpu13 #CPUs=48 Partition=cpu-epyc
[2022-07-13T00:19:34.025] _job_complete: JobId=45638 WEXITSTATUS 1
[2022-07-13T00:19:34.025] _job_complete: JobId=45638 done
[2022-07-13T00:19:34.250] sched: Allocate JobId=45639 NodeList=cpu13 #CPUs=48 Partition=cpu-epyc
[2022-07-13T01:08:05.783] _job_complete: JobId=45639 WEXITSTATUS 0
[2022-07-13T01:08:05.783] _job_complete: JobId=45639 done
[2022-07-13T01:08:06.017] sched: Allocate JobId=45628 NodeList=cpu13 #CPUs=48 Partition=cpu-epyc
[2022-07-13T01:08:07.384] sched/backfill: _start_job: Started JobId=46208 in cpu-epyc on cpu14
[2022-07-13T01:08:13.784] _job_complete: JobId=45628 WEXITSTATUS 1
[2022-07-13T01:08:13.784] _job_complete: JobId=45628 done
[2022-07-13T01:08:14.190] sched: Allocate JobId=45629 NodeList=cpu13 #CPUs=48 Partition=cpu-epyc
[2022-07-13T01:08:14.920] _job_complete: JobId=45629 WEXITSTATUS 1
[2022-07-13T01:08:14.921] _job_complete: JobId=45629 done
[2022-07-13T01:08:15.186] sched: Allocate JobId=46210 NodeList=cpu13 #CPUs=16 Partition=cpu-epyc
[2022-07-13T01:08:15.187] sched: Allocate JobId=46214 NodeList=cpu13 #CPUs=16 Partition=cpu-epyc
[2022-07-13T01:08:15.204] sched: Allocate JobId=46217 NodeList=cpu13 #CPUs=16 Partition=cpu-epyc
[2022-07-13T01:08:27.315] _job_complete: JobId=46214 WEXITSTATUS 1
[2022-07-13T01:08:27.316] _job_complete: JobId=46214 done
[2022-07-13T01:08:27.759] _job_complete: JobId=46210 WEXITSTATUS 1
[2022-07-13T01:08:27.759] _job_complete: JobId=46210 done
[2022-07-13T01:11:31.578] _slurm_rpc_submit_batch_job: JobId=46225 InitPrio=21756 usec=592
[2022-07-13T01:11:32.518] sched: Allocate JobId=46225 NodeList=cpu13 #CPUs=16 Partition=cpu-epyc
[2022-07-13T01:12:03.261] _slurm_rpc_submit_batch_job: JobId=46226 InitPrio=21756 usec=501
[2022-07-13T01:12:38.702] _slurm_rpc_kill_job: REQUEST_KILL_JOB JobId=46226 uid 548300570
[2022-07-13T01:13:10.258] _slurm_rpc_submit_batch_job: JobId=46227 InitPrio=21756 usec=500
[2022-07-13T01:13:10.734] sched: Allocate JobId=46227 NodeList=cpu13 #CPUs=16 Partition=cpu-epyc
[2022-07-13T01:21:01.976] _slurm_rpc_submit_batch_job: JobId=46228 InitPrio=21824 usec=464
[2022-07-13T01:21:02.583] sched: Allocate JobId=46228 NodeList=cpu14 #CPUs=8 Partition=cpu-epyc
[2022-07-13T01:54:10.907] _job_complete: JobId=46228 WEXITSTATUS 0
[2022-07-13T01:54:10.908] _job_complete: JobId=46228 done
[2022-07-13T02:20:38.036] _slurm_rpc_submit_batch_job: JobId=46229 InitPrio=21756 usec=532
[2022-07-13T02:21:18.473] _slurm_rpc_submit_batch_job: JobId=46230 InitPrio=21756 usec=480
[2022-07-13T02:21:46.961] _slurm_rpc_submit_batch_job: JobId=46231 InitPrio=21756 usec=507
[2022-07-13T03:10:40.278] _job_complete: JobId=46227 WEXITSTATUS 0
[2022-07-13T03:10:40.278] _job_complete: JobId=46227 done
[2022-07-13T03:46:34.907] _slurm_rpc_kill_job: REQUEST_KILL_JOB JobId=46217 uid 548300513
[2022-07-13T03:46:37.758] sched: Allocate JobId=46229 NodeList=cpu13 #CPUs=16 Partition=cpu-epyc
[2022-07-13T04:10:52.462] _job_complete: JobId=46229 WEXITSTATUS 0
[2022-07-13T04:10:52.462] _job_complete: JobId=46229 done
[2022-07-13T04:10:52.725] sched: Allocate JobId=46230 NodeList=cpu13 #CPUs=16 Partition=cpu-epyc
[2022-07-13T04:14:49.279] _slurm_rpc_submit_batch_job: JobId=46232 InitPrio=24035 usec=475
[2022-07-13T04:14:50.281] sched: Allocate JobId=46232 NodeList=gpu02 #CPUs=1 Partition=gpu-titan
[2022-07-13T04:16:30.257] _slurm_rpc_submit_batch_job: JobId=46233 InitPrio=24035 usec=612
[2022-07-13T04:20:52.781] _job_complete: JobId=46225 WEXITSTATUS 0
[2022-07-13T04:20:52.781] _job_complete: JobId=46225 done
[2022-07-13T04:20:53.021] sched: Allocate JobId=46231 NodeList=cpu13 #CPUs=16 Partition=cpu-epyc
[2022-07-13T04:34:43.681] _job_complete: JobId=46230 WEXITSTATUS 0
[2022-07-13T04:34:43.681] _job_complete: JobId=46230 done
[2022-07-13T04:47:05.032] _job_complete: JobId=46231 WEXITSTATUS 0
[2022-07-13T04:47:05.032] _job_complete: JobId=46231 done
[2022-07-13T04:47:05.895] _slurm_rpc_submit_batch_job: JobId=46234 InitPrio=24035 usec=661
[2022-07-13T04:47:06.830] sched: Allocate JobId=46234 NodeList=gpu03 #CPUs=1 Partition=gpu-k10
[2022-07-13T04:47:08.262] _job_complete: JobId=46234 WEXITSTATUS 127
[2022-07-13T04:47:08.262] _job_complete: JobId=46234 done
[2022-07-13T04:51:51.194] _slurm_rpc_submit_batch_job: JobId=46235 InitPrio=24035 usec=450
[2022-07-13T04:52:58.108] _slurm_rpc_kill_job: REQUEST_KILL_JOB JobId=46235 uid 548200110
[2022-07-13T04:53:45.330] _slurm_rpc_submit_batch_job: JobId=46236 InitPrio=24035 usec=560
[2022-07-13T04:54:55.570] _slurm_rpc_submit_batch_job: JobId=46237 InitPrio=24035 usec=500
[2022-07-13T05:58:02.345] _job_complete: JobId=46224 WEXITSTATUS 0
[2022-07-13T05:58:02.350] _job_complete: JobId=46224 done
[2022-07-13T05:58:10.277] sched: Allocate JobId=46233 NodeList=gpu02 #CPUs=1 Partition=gpu-titan
[2022-07-13T06:06:05.508] _job_complete: JobId=46208 WEXITSTATUS 1
[2022-07-13T06:06:05.508] _job_complete: JobId=46208 done
[2022-07-13T07:39:16.433] _job_complete: JobId=46089 WEXITSTATUS 0
[2022-07-13T07:39:16.434] _job_complete: JobId=46089 done
[2022-07-13T09:24:33.529] sched: _slurm_rpc_allocate_resources JobId=46238 NodeList=(null) usec=845
[2022-07-13T09:24:50.623] _job_complete: JobId=46151 WEXITSTATUS 0
[2022-07-13T09:24:50.623] _job_complete: JobId=46151 done
[2022-07-13T09:27:50.367] _job_complete: JobId=46222 WEXITSTATUS 1
[2022-07-13T09:27:50.367] _job_complete: JobId=46222 done
[2022-07-13T09:27:50.848] sched: Allocate JobId=46238 NodeList=cpu04 #CPUs=1 Partition=cpu-opteron
[2022-07-13T09:45:14.861] _job_complete: JobId=46232 WEXITSTATUS 0
[2022-07-13T09:45:14.861] _job_complete: JobId=46232 done
[2022-07-13T09:45:15.297] sched: Allocate JobId=46236 NodeList=gpu02 #CPUs=1 Partition=gpu-titan
[2022-07-13T09:50:05.351] _slurm_rpc_submit_batch_job: JobId=46239 InitPrio=22562 usec=413
[2022-07-13T09:50:05.422] sched: Allocate JobId=46239 NodeList=gpu05 #CPUs=16 Partition=gpu-v100s
[2022-07-13T09:50:07.748] _job_complete: JobId=46239 WEXITSTATUS 127
[2022-07-13T09:50:07.748] _job_complete: JobId=46239 done
[2022-07-13T09:50:36.268] _slurm_rpc_submit_batch_job: JobId=46240 InitPrio=22562 usec=391
[2022-07-13T09:50:36.455] sched: Allocate JobId=46240 NodeList=gpu05 #CPUs=16 Partition=gpu-v100s
[2022-07-13T09:50:38.221] _job_complete: JobId=46240 WEXITSTATUS 127
[2022-07-13T09:50:38.221] _job_complete: JobId=46240 done
[2022-07-13T09:50:57.539] _slurm_rpc_kill_job: REQUEST_KILL_JOB JobId=46180 uid 548200083
[2022-07-13T09:52:48.046] _slurm_rpc_submit_batch_job: JobId=46241 InitPrio=22562 usec=380
[2022-07-13T09:52:48.709] sched: Allocate JobId=46241 NodeList=gpu05 #CPUs=16 Partition=gpu-v100s
[2022-07-13T09:53:13.193] _job_complete: JobId=46241 WEXITSTATUS 1
[2022-07-13T09:53:13.194] _job_complete: JobId=46241 done
[2022-07-13T09:54:49.821] _slurm_rpc_submit_batch_job: JobId=46242 InitPrio=22562 usec=574
[2022-07-13T09:54:49.881] sched: Allocate JobId=46242 NodeList=gpu05 #CPUs=16 Partition=gpu-v100s
[2022-07-13T09:55:09.957] _job_complete: JobId=46242 WEXITSTATUS 1
[2022-07-13T09:55:09.958] _job_complete: JobId=46242 done
[2022-07-13T09:56:47.505] _slurm_rpc_submit_batch_job: JobId=46243 InitPrio=22562 usec=481
[2022-07-13T09:56:48.050] sched: Allocate JobId=46243 NodeList=gpu05 #CPUs=16 Partition=gpu-v100s
[2022-07-13T10:51:55.041] _slurm_rpc_submit_batch_job: JobId=46244 InitPrio=22024 usec=447
[2022-07-13T10:54:07.989] _slurm_rpc_submit_batch_job: JobId=46245 InitPrio=22024 usec=528
[2022-07-13T11:09:22.223] _job_complete: JobId=46233 WEXITSTATUS 0
[2022-07-13T11:09:22.223] _job_complete: JobId=46233 done
[2022-07-13T11:09:22.660] sched: Allocate JobId=46237 NodeList=gpu02 #CPUs=1 Partition=gpu-titan
[2022-07-13T11:53:48.659] _job_complete: JobId=46238 WEXITSTATUS 0
[2022-07-13T11:53:48.659] _job_complete: JobId=46238 done
[2022-07-13T11:55:49.150] sched: _slurm_rpc_allocate_resources JobId=46246 NodeList=cpu04 usec=15961
[2022-07-13T13:22:47.490] _slurm_rpc_submit_batch_job: JobId=46247 InitPrio=21218 usec=449
[2022-07-13T14:22:39.448] _job_complete: JobId=46246 WEXITSTATUS 0
[2022-07-13T14:22:39.448] _job_complete: JobId=46246 done
[2022-07-13T14:55:42.410] _slurm_rpc_submit_batch_job: JobId=46248 InitPrio=22562 usec=464
[2022-07-13T14:55:43.235] sched: Allocate JobId=46248 NodeList=cpu12 #CPUs=16 Partition=cpu-epyc
[2022-07-13T15:11:29.521] _job_complete: JobId=46236 WEXITSTATUS 0
[2022-07-13T15:11:29.521] _job_complete: JobId=46236 done
[2022-07-13T15:49:58.221] _job_complete: JobId=46248 WEXITSTATUS 0
[2022-07-13T15:49:58.221] _job_complete: JobId=46248 done
[2022-07-13T16:19:59.375] _job_complete: JobId=46237 WEXITSTATUS 0
[2022-07-13T16:19:59.375] _job_complete: JobId=46237 done
[2022-07-13T16:49:32.803] _slurm_rpc_submit_batch_job: JobId=46249 InitPrio=20543 usec=599
[2022-07-13T16:49:33.696] sched: Allocate JobId=46249 NodeList=cpu13 #CPUs=32 Partition=cpu-epyc
[2022-07-13T18:32:53.039] _job_complete: JobId=45817 WEXITSTATUS 0
[2022-07-13T18:32:53.043] _job_complete: JobId=45817 done
[2022-07-13T18:39:05.854] _job_complete: JobId=45865 WEXITSTATUS 0
[2022-07-13T18:39:05.854] _job_complete: JobId=45865 done
[2022-07-13T18:39:06.350] sched: Allocate JobId=46213 NodeList=cpu03 #CPUs=16 Partition=cpu-opteron
[2022-07-13T18:39:06.365] sched: Allocate JobId=46244 NodeList=cpu03 #CPUs=16 Partition=cpu-opteron
[2022-07-13T18:39:06.366] sched: Allocate JobId=46245 NodeList=cpu03 #CPUs=16 Partition=cpu-opteron
[2022-07-13T18:39:21.415] _job_complete: JobId=46245 WEXITSTATUS 1
[2022-07-13T18:39:21.415] _job_complete: JobId=46245 done
[2022-07-13T18:39:28.368] _job_complete: JobId=46213 WEXITSTATUS 1
[2022-07-13T18:39:28.368] _job_complete: JobId=46213 done
[2022-07-13T18:46:00.471] _job_complete: JobId=46244 WEXITSTATUS 0
[2022-07-13T18:46:00.472] _job_complete: JobId=46244 done
[2022-07-13T21:37:59.587] _slurm_rpc_submit_batch_job: JobId=46250 InitPrio=20514 usec=509
[2022-07-13T21:37:59.963] sched: Allocate JobId=46250 NodeList=gpu02 #CPUs=4 Partition=gpu-titan
[2022-07-13T21:40:40.296] _slurm_rpc_submit_batch_job: JobId=46251 InitPrio=19468 usec=370
[2022-07-13T21:41:31.377] _slurm_rpc_kill_job: REQUEST_KILL_JOB JobId=46251 uid 548200017
[2022-07-13T21:41:59.955] _slurm_rpc_submit_batch_job: JobId=46252 InitPrio=19194 usec=388
[2022-07-13T21:42:00.298] sched: Allocate JobId=46252 NodeList=cpu03 #CPUs=64 Partition=cpu-opteron
[2022-07-13T21:56:24.351] _slurm_rpc_submit_batch_job: JobId=46253 InitPrio=19468 usec=505
[2022-07-13T21:56:38.508] _slurm_rpc_kill_job: REQUEST_KILL_JOB JobId=46100 uid 548200017
[2022-07-13T21:56:40.414] sched: Allocate JobId=46253 NodeList=cpu12 #CPUs=32 Partition=cpu-epyc
[2022-07-13T22:02:00.409] _slurm_rpc_kill_job: REQUEST_KILL_JOB JobId=46099 uid 548200017
[2022-07-13T23:28:44.407] _job_complete: JobId=46253 WEXITSTATUS 1
[2022-07-13T23:28:44.412] _job_complete: JobId=46253 done
[2022-07-13T23:34:04.626] sched: _slurm_rpc_allocate_resources JobId=46254 NodeList=cpu04 usec=14622
[2022-07-13T23:49:33.919] _slurm_rpc_submit_batch_job: JobId=46255 InitPrio=19994 usec=504
[2022-07-13T23:49:34.216] sched: Allocate JobId=46255 NodeList=cpu13 #CPUs=2 Partition=cpu-epyc
[2022-07-13T23:49:37.138] _job_complete: JobId=46255 WEXITSTATUS 0
[2022-07-13T23:49:37.138] _job_complete: JobId=46255 done
[2022-07-13T23:52:59.414] _slurm_rpc_submit_batch_job: JobId=46256 InitPrio=19994 usec=367
[2022-07-13T23:52:59.591] sched: Allocate JobId=46256 NodeList=cpu13 #CPUs=2 Partition=cpu-epyc
[2022-07-13T23:53:01.951] _job_complete: JobId=46256 WEXITSTATUS 0
[2022-07-13T23:53:01.951] _job_complete: JobId=46256 done
[2022-07-13T23:56:17.765] _slurm_rpc_submit_batch_job: JobId=46257 InitPrio=19994 usec=453
[2022-07-13T23:56:17.868] sched: Allocate JobId=46257 NodeList=cpu13 #CPUs=2 Partition=cpu-epyc
[2022-07-13T23:56:19.007] _job_complete: JobId=46257 WEXITSTATUS 1
[2022-07-13T23:56:19.007] _job_complete: JobId=46257 done
[2022-07-13T23:56:57.900] _slurm_rpc_submit_batch_job: JobId=46258 InitPrio=19994 usec=409
[2022-07-13T23:56:57.928] sched: Allocate JobId=46258 NodeList=cpu13 #CPUs=2 Partition=cpu-epyc
[2022-07-13T23:57:00.069] _job_complete: JobId=46258 WEXITSTATUS 0
[2022-07-13T23:57:00.070] _job_complete: JobId=46258 done
[2022-07-14T00:04:18.472] _job_complete: JobId=46254 WEXITSTATUS 0
[2022-07-14T00:04:18.472] _job_complete: JobId=46254 done
[2022-07-14T00:05:12.783] _slurm_rpc_submit_batch_job: JobId=46259 InitPrio=21418 usec=526
[2022-07-14T00:05:12.974] sched: Allocate JobId=46259 NodeList=cpu12 #CPUs=24 Partition=cpu-epyc
[2022-07-14T00:05:19.584] _slurm_rpc_submit_batch_job: JobId=46260 InitPrio=21418 usec=493
[2022-07-14T00:05:19.970] sched: Allocate JobId=46260 NodeList=cpu12 #CPUs=24 Partition=cpu-epyc
[2022-07-14T00:05:28.958] _slurm_rpc_kill_job: REQUEST_KILL_JOB JobId=46260 uid 548300570
[2022-07-14T00:16:32.863] _slurm_rpc_submit_batch_job: JobId=46261 InitPrio=19994 usec=401
[2022-07-14T00:16:33.173] sched: Allocate JobId=46261 NodeList=cpu13 #CPUs=2 Partition=cpu-epyc
[2022-07-14T00:17:14.418] _job_complete: JobId=46261 WEXITSTATUS 0
[2022-07-14T00:17:14.419] _job_complete: JobId=46261 done
[2022-07-14T00:21:26.960] _slurm_rpc_submit_batch_job: JobId=46262 InitPrio=19874 usec=395
[2022-07-14T00:21:27.684] sched: Allocate JobId=46262 NodeList=gpu05 #CPUs=16 Partition=gpu-v100s
[2022-07-14T00:21:37.473] _job_complete: JobId=46262 WEXITSTATUS 1
[2022-07-14T00:21:37.473] _job_complete: JobId=46262 done
[2022-07-14T00:23:03.568] _slurm_rpc_submit_batch_job: JobId=46263 InitPrio=19874 usec=476
[2022-07-14T00:23:03.910] sched: Allocate JobId=46263 NodeList=gpu05 #CPUs=16 Partition=gpu-v100s
[2022-07-14T00:31:47.008] _slurm_rpc_submit_batch_job: JobId=46264 InitPrio=19994 usec=414
[2022-07-14T00:31:47.701] sched: Allocate JobId=46264 NodeList=cpu13 #CPUs=2 Partition=cpu-epyc
[2022-07-14T00:32:28.565] _job_complete: JobId=46264 WEXITSTATUS 0
[2022-07-14T00:32:28.565] _job_complete: JobId=46264 done
[2022-07-14T00:35:43.071] _slurm_rpc_submit_batch_job: JobId=46265 InitPrio=19874 usec=613
[2022-07-14T00:37:08.898] _job_complete: JobId=46252 WEXITSTATUS 1
[2022-07-14T00:37:08.899] _job_complete: JobId=46252 done
[2022-07-14T00:40:02.903] _slurm_rpc_submit_batch_job: JobId=46266 InitPrio=19994 usec=411
[2022-07-14T00:40:03.542] sched: Allocate JobId=46266 NodeList=cpu13 #CPUs=2 Partition=cpu-epyc
[2022-07-14T00:40:45.453] _job_complete: JobId=46266 WEXITSTATUS 0
[2022-07-14T00:40:45.453] _job_complete: JobId=46266 done
[2022-07-14T00:42:30.546] _slurm_rpc_submit_batch_job: JobId=46267 InitPrio=19874 usec=405
[2022-07-14T01:42:00.512] _slurm_rpc_submit_batch_job: JobId=46268 InitPrio=21521 usec=514
[2022-07-14T01:42:01.472] sched: Allocate JobId=46268 NodeList=cpu13 #CPUs=12 Partition=cpu-epyc
[2022-07-14T01:42:01.914] _job_complete: JobId=46268 WEXITSTATUS 1
[2022-07-14T01:42:01.914] _job_complete: JobId=46268 done
[2022-07-14T01:42:23.466] _slurm_rpc_submit_batch_job: JobId=46269 InitPrio=21521 usec=616
[2022-07-14T01:42:25.491] sched: Allocate JobId=46269 NodeList=cpu13 #CPUs=12 Partition=cpu-epyc
[2022-07-14T01:42:25.705] _job_complete: JobId=46269 WEXITSTATUS 1
[2022-07-14T01:42:25.705] _job_complete: JobId=46269 done
[2022-07-14T01:43:01.078] _slurm_rpc_kill_job: REQUEST_KILL_JOB JobId=46269 uid 548300570
[2022-07-14T01:43:18.719] _slurm_rpc_submit_batch_job: JobId=46270 InitPrio=21521 usec=403
[2022-07-14T01:43:18.735] sched: Allocate JobId=46270 NodeList=cpu13 #CPUs=12 Partition=cpu-epyc
[2022-07-14T01:51:10.399] _job_complete: JobId=46259 WEXITSTATUS 0
[2022-07-14T01:51:10.399] _job_complete: JobId=46259 done
[2022-07-14T01:51:28.248] _slurm_rpc_submit_batch_job: JobId=46271 InitPrio=21418 usec=418
[2022-07-14T01:51:28.494] sched: Allocate JobId=46271 NodeList=cpu12 #CPUs=24 Partition=cpu-epyc
[2022-07-14T01:51:37.172] _job_complete: JobId=46271 WEXITSTATUS 1
[2022-07-14T01:51:37.172] _job_complete: JobId=46271 done
[2022-07-14T01:54:31.139] _slurm_rpc_submit_batch_job: JobId=46272 InitPrio=21418 usec=479
[2022-07-14T01:54:31.870] sched: Allocate JobId=46272 NodeList=cpu12 #CPUs=24 Partition=cpu-epyc
[2022-07-14T01:55:58.479] _slurm_rpc_submit_batch_job: JobId=46273 InitPrio=21487 usec=572
[2022-07-14T01:55:58.985] sched: Allocate JobId=46273 NodeList=cpu14 #CPUs=16 Partition=cpu-epyc
[2022-07-14T01:57:10.230] _slurm_rpc_submit_batch_job: JobId=46274 InitPrio=21487 usec=420
[2022-07-14T01:57:11.087] sched: Allocate JobId=46274 NodeList=cpu15 #CPUs=16 Partition=cpu-epyc
[2022-07-14T01:57:20.917] _job_complete: JobId=46274 WEXITSTATUS 1
[2022-07-14T01:57:20.917] _job_complete: JobId=46274 done
[2022-07-14T02:05:56.073] _job_complete: JobId=46270 WEXITSTATUS 0
[2022-07-14T02:05:56.073] _job_complete: JobId=46270 done
[2022-07-14T02:17:35.281] _slurm_rpc_submit_batch_job: JobId=46275 InitPrio=21418 usec=466
[2022-07-14T02:17:35.618] sched: Allocate JobId=46275 NodeList=cpu12 #CPUs=24 Partition=cpu-epyc
[2022-07-14T02:19:15.601] _slurm_rpc_submit_batch_job: JobId=46276 InitPrio=21487 usec=469
[2022-07-14T02:19:15.786] sched: Allocate JobId=46276 NodeList=cpu13 #CPUs=16 Partition=cpu-epyc
[2022-07-14T02:21:55.426] _slurm_rpc_submit_batch_job: JobId=46277 InitPrio=21487 usec=578
[2022-07-14T02:22:19.765] _slurm_rpc_kill_job: REQUEST_KILL_JOB JobId=46277 uid 548300570
[2022-07-14T02:22:46.953] _slurm_rpc_submit_batch_job: JobId=46278 InitPrio=21487 usec=461
[2022-07-14T02:22:47.175] sched: Allocate JobId=46278 NodeList=cpu15 #CPUs=16 Partition=cpu-epyc
[2022-07-14T03:09:24.269] _job_complete: JobId=46209 WEXITSTATUS 1
[2022-07-14T03:09:24.270] _job_complete: JobId=46209 done
[2022-07-14T03:16:16.199] _job_complete: JobId=46275 WEXITSTATUS 1
[2022-07-14T03:16:16.199] _job_complete: JobId=46275 done
[2022-07-14T03:17:31.920] _slurm_rpc_kill_job: REQUEST_KILL_JOB JobId=46250 uid 548200045
[2022-07-14T03:18:37.363] _slurm_rpc_submit_batch_job: JobId=46279 InitPrio=20480 usec=473
[2022-07-14T03:18:37.534] sched: Allocate JobId=46279 NodeList=gpu02 #CPUs=8 Partition=gpu-titan
[2022-07-14T03:51:37.448] _job_complete: JobId=46273 WEXITSTATUS 1
[2022-07-14T03:51:37.449] _job_complete: JobId=46273 done
[2022-07-14T05:28:36.462] _job_complete: JobId=46272 WEXITSTATUS 0
[2022-07-14T05:28:36.462] _job_complete: JobId=46272 done
[2022-07-14T05:50:41.660] _job_complete: JobId=46278 WEXITSTATUS 0
[2022-07-14T05:50:41.661] _job_complete: JobId=46278 done
[2022-07-14T06:43:03.417] _job_complete: JobId=45903 WEXITSTATUS 0
[2022-07-14T06:43:03.417] _job_complete: JobId=45903 done
[2022-07-14T07:34:47.907] _job_complete: JobId=46276 WEXITSTATUS 0
[2022-07-14T07:34:47.908] _job_complete: JobId=46276 done
[2022-07-14T08:09:31.232] _slurm_rpc_submit_batch_job: JobId=46280 InitPrio=19194 usec=417
[2022-07-14T08:09:32.010] sched: Allocate JobId=46280 NodeList=cpu03 #CPUs=64 Partition=cpu-opteron
[2022-07-14T08:12:37.400] _slurm_rpc_submit_batch_job: JobId=46281 InitPrio=19468 usec=386
[2022-07-14T08:12:38.393] sched: Allocate JobId=46281 NodeList=cpu15 #CPUs=32 Partition=cpu-epyc
[2022-07-14T08:29:54.236] _slurm_rpc_kill_job: REQUEST_KILL_JOB JobId=46281 uid 548200017
[2022-07-14T08:30:00.725] _slurm_rpc_submit_batch_job: JobId=46282 InitPrio=19468 usec=387
[2022-07-14T08:30:01.318] sched: Allocate JobId=46282 NodeList=cpu15 #CPUs=32 Partition=cpu-epyc
[2022-07-14T08:30:47.964] _slurm_rpc_kill_job: REQUEST_KILL_JOB JobId=46280 uid 548200017
[2022-07-14T08:30:53.443] _slurm_rpc_submit_batch_job: JobId=46283 InitPrio=19194 usec=388
[2022-07-14T08:30:54.388] sched: Allocate JobId=46283 NodeList=cpu03 #CPUs=64 Partition=cpu-opteron
[2022-07-14T10:17:21.907] _slurm_rpc_submit_batch_job: JobId=46284 InitPrio=24444 usec=554
[2022-07-14T10:17:22.679] sched: Allocate JobId=46284 NodeList=cpu13 #CPUs=16 Partition=cpu-epyc
[2022-07-14T10:17:24.997] _job_complete: JobId=46284 WEXITSTATUS 1
[2022-07-14T10:17:24.997] _job_complete: JobId=46284 done
[2022-07-14T10:20:09.629] _slurm_rpc_submit_batch_job: JobId=46285 InitPrio=24444 usec=472
[2022-07-14T10:20:10.081] sched: Allocate JobId=46285 NodeList=cpu13 #CPUs=16 Partition=cpu-epyc
[2022-07-14T10:20:12.006] _job_complete: JobId=46285 WEXITSTATUS 1
[2022-07-14T10:20:12.006] _job_complete: JobId=46285 done
[2022-07-14T10:22:36.689] _slurm_rpc_submit_batch_job: JobId=46286 InitPrio=24444 usec=434
[2022-07-14T10:22:37.323] sched: Allocate JobId=46286 NodeList=cpu13 #CPUs=16 Partition=cpu-epyc
[2022-07-14T10:22:39.466] _job_complete: JobId=46286 WEXITSTATUS 1
[2022-07-14T10:22:39.466] _job_complete: JobId=46286 done
[2022-07-14T10:28:44.359] _slurm_rpc_submit_batch_job: JobId=46287 InitPrio=24444 usec=482
[2022-07-14T10:28:44.989] sched: Allocate JobId=46287 NodeList=cpu13 #CPUs=16 Partition=cpu-epyc
[2022-07-14T10:29:48.756] _slurm_rpc_submit_batch_job: JobId=46288 InitPrio=24444 usec=374
[2022-07-14T10:29:49.073] sched: Allocate JobId=46288 NodeList=cpu14 #CPUs=16 Partition=cpu-epyc
[2022-07-14T10:31:13.644] _slurm_rpc_submit_batch_job: JobId=46289 InitPrio=24444 usec=557
[2022-07-14T10:31:14.194] sched: Allocate JobId=46289 NodeList=cpu12 #CPUs=16 Partition=cpu-epyc
[2022-07-14T10:31:20.823] _job_complete: JobId=46289 WEXITSTATUS 1
[2022-07-14T10:31:20.823] _job_complete: JobId=46289 done
[2022-07-14T10:33:36.289] _slurm_rpc_submit_batch_job: JobId=46290 InitPrio=24444 usec=447
[2022-07-14T10:33:36.491] sched: Allocate JobId=46290 NodeList=cpu12 #CPUs=16 Partition=cpu-epyc
[2022-07-14T10:33:42.291] _job_complete: JobId=46290 WEXITSTATUS 1
[2022-07-14T10:33:42.291] _job_complete: JobId=46290 done
[2022-07-14T10:39:56.905] _slurm_rpc_submit_batch_job: JobId=46291 InitPrio=24444 usec=368
[2022-07-14T10:39:57.180] sched: Allocate JobId=46291 NodeList=cpu12 #CPUs=16 Partition=cpu-epyc
[2022-07-14T10:40:02.784] _job_complete: JobId=46291 WEXITSTATUS 1
[2022-07-14T10:40:02.784] _job_complete: JobId=46291 done
[2022-07-14T10:42:53.269] _slurm_rpc_submit_batch_job: JobId=46292 InitPrio=24444 usec=480
[2022-07-14T10:42:53.523] sched: Allocate JobId=46292 NodeList=cpu12 #CPUs=16 Partition=cpu-epyc
[2022-07-14T10:42:59.365] _job_complete: JobId=46292 WEXITSTATUS 1
[2022-07-14T10:42:59.365] _job_complete: JobId=46292 done
[2022-07-14T10:46:03.321] _slurm_rpc_submit_batch_job: JobId=46293 InitPrio=24444 usec=417
[2022-07-14T10:46:03.789] sched: Allocate JobId=46293 NodeList=cpu12 #CPUs=16 Partition=cpu-epyc
[2022-07-14T10:46:09.581] _job_complete: JobId=46293 WEXITSTATUS 1
[2022-07-14T10:46:09.581] _job_complete: JobId=46293 done
[2022-07-14T10:47:36.831] _job_complete: JobId=46288 WEXITSTATUS 1
[2022-07-14T10:47:36.831] _job_complete: JobId=46288 done
[2022-07-14T10:47:50.297] _job_complete: JobId=46287 WEXITSTATUS 1
[2022-07-14T10:47:50.297] _job_complete: JobId=46287 done
[2022-07-14T10:49:02.154] _slurm_rpc_submit_batch_job: JobId=46294 InitPrio=24444 usec=460
[2022-07-14T10:49:02.214] sched: Allocate JobId=46294 NodeList=cpu13 #CPUs=16 Partition=cpu-epyc
[2022-07-14T10:49:08.357] _job_complete: JobId=46294 WEXITSTATUS 1
[2022-07-14T10:49:08.357] _job_complete: JobId=46294 done
[2022-07-14T10:53:06.276] _slurm_rpc_submit_batch_job: JobId=46295 InitPrio=24444 usec=619
[2022-07-14T10:53:06.685] sched: Allocate JobId=46295 NodeList=cpu13 #CPUs=16 Partition=cpu-epyc
[2022-07-14T10:57:50.349] _slurm_rpc_submit_batch_job: JobId=46296 InitPrio=24444 usec=422
[2022-07-14T10:57:51.168] sched: Allocate JobId=46296 NodeList=cpu14 #CPUs=16 Partition=cpu-epyc
[2022-07-14T10:57:57.847] _job_complete: JobId=46296 WEXITSTATUS 1
[2022-07-14T10:57:57.847] _job_complete: JobId=46296 done
[2022-07-14T10:59:09.948] _slurm_rpc_submit_batch_job: JobId=46297 InitPrio=24444 usec=455
[2022-07-14T10:59:10.276] sched: Allocate JobId=46297 NodeList=cpu14 #CPUs=16 Partition=cpu-epyc
[2022-07-14T11:03:35.825] _job_complete: JobId=46282 WEXITSTATUS 0
[2022-07-14T11:03:35.830] _job_complete: JobId=46282 done
[2022-07-14T11:15:06.326] _slurm_rpc_submit_batch_job: JobId=46298 InitPrio=24444 usec=405
[2022-07-14T11:15:06.996] sched: Allocate JobId=46298 NodeList=cpu15 #CPUs=16 Partition=cpu-epyc
[2022-07-14T11:15:09.617] _job_complete: JobId=46298 WEXITSTATUS 1
[2022-07-14T11:15:09.618] _job_complete: JobId=46298 done
[2022-07-14T11:15:39.226] _slurm_rpc_kill_job: REQUEST_KILL_JOB JobId=46295 uid 548200036
[2022-07-14T11:16:40.084] _slurm_rpc_submit_batch_job: JobId=46299 InitPrio=24444 usec=422
[2022-07-14T11:16:40.121] sched: Allocate JobId=46299 NodeList=cpu15 #CPUs=16 Partition=cpu-epyc
[2022-07-14T11:16:42.448] _job_complete: JobId=46299 WEXITSTATUS 1
[2022-07-14T11:16:42.449] _job_complete: JobId=46299 done
[2022-07-14T11:17:02.534] _slurm_rpc_submit_batch_job: JobId=46300 InitPrio=24444 usec=434
[2022-07-14T11:17:03.152] sched: Allocate JobId=46300 NodeList=cpu15 #CPUs=16 Partition=cpu-epyc
[2022-07-14T11:17:05.449] _job_complete: JobId=46300 WEXITSTATUS 1
[2022-07-14T11:17:05.449] _job_complete: JobId=46300 done
[2022-07-14T11:21:27.578] _slurm_rpc_submit_batch_job: JobId=46301 InitPrio=24444 usec=421
[2022-07-14T11:21:27.612] sched: Allocate JobId=46301 NodeList=cpu15 #CPUs=16 Partition=cpu-epyc
[2022-07-14T11:21:30.046] _job_complete: JobId=46301 WEXITSTATUS 1
[2022-07-14T11:21:30.046] _job_complete: JobId=46301 done
[2022-07-14T11:22:19.150] _job_complete: JobId=46263 WEXITSTATUS 0
[2022-07-14T11:22:19.150] _job_complete: JobId=46263 done
[2022-07-14T11:22:20.027] sched: Allocate JobId=46265 NodeList=gpu05 #CPUs=16 Partition=gpu-v100s
[2022-07-14T11:22:29.052] _job_complete: JobId=46265 WEXITSTATUS 1
[2022-07-14T11:22:29.052] _job_complete: JobId=46265 done
[2022-07-14T11:22:29.350] sched: Allocate JobId=46267 NodeList=gpu05 #CPUs=16 Partition=gpu-v100s
[2022-07-14T11:22:37.798] _job_complete: JobId=46267 WEXITSTATUS 1
[2022-07-14T11:22:37.798] _job_complete: JobId=46267 done
[2022-07-14T11:23:30.861] _slurm_rpc_submit_batch_job: JobId=46302 InitPrio=22293 usec=383
[2022-07-14T11:23:30.898] sched: Allocate JobId=46302 NodeList=cpu11 #CPUs=16 Partition=cpu-opteron
[2022-07-14T11:24:01.510] _job_complete: JobId=46302 WEXITSTATUS 1
[2022-07-14T11:24:01.510] _job_complete: JobId=46302 done
[2022-07-14T11:35:26.232] _slurm_rpc_submit_batch_job: JobId=46303 InitPrio=22293 usec=485
[2022-07-14T11:35:27.058] sched: Allocate JobId=46303 NodeList=gpu01 #CPUs=16 Partition=gpu-k10
[2022-07-14T11:36:59.418] _slurm_rpc_submit_batch_job: JobId=46304 InitPrio=22293 usec=461
[2022-07-14T11:37:00.186] sched: Allocate JobId=46304 NodeList=cpu11 #CPUs=16 Partition=cpu-opteron
[2022-07-14T11:38:11.815] _job_complete: JobId=46304 WEXITSTATUS 0
[2022-07-14T11:38:11.816] _job_complete: JobId=46304 done
[2022-07-14T11:59:13.629] Time limit exhausted for JobId=46297
[2022-07-14T12:08:42.247] _slurm_rpc_submit_batch_job: JobId=46305 InitPrio=22562 usec=502
[2022-07-14T12:08:42.768] sched: Allocate JobId=46305 NodeList=cpu13 #CPUs=16 Partition=cpu-epyc
[2022-07-14T12:08:52.425] _slurm_rpc_submit_batch_job: JobId=46306 InitPrio=22562 usec=406
[2022-07-14T12:08:52.769] sched: Allocate JobId=46306 NodeList=cpu12 #CPUs=16 Partition=cpu-epyc
[2022-07-14T12:09:04.979] _slurm_rpc_submit_batch_job: JobId=46307 InitPrio=22562 usec=403
[2022-07-14T12:09:05.787] sched: Allocate JobId=46307 NodeList=cpu12 #CPUs=16 Partition=cpu-epyc
[2022-07-14T12:09:12.306] _slurm_rpc_submit_batch_job: JobId=46308 InitPrio=22562 usec=439
[2022-07-14T12:09:12.796] sched: Allocate JobId=46308 NodeList=cpu14 #CPUs=16 Partition=cpu-epyc
[2022-07-14T12:16:57.241] _slurm_rpc_submit_batch_job: JobId=46309 InitPrio=22562 usec=529
[2022-07-14T12:16:57.752] sched: Allocate JobId=46309 NodeList=cpu15 #CPUs=16 Partition=cpu-epyc
[2022-07-14T12:17:03.935] _slurm_rpc_submit_batch_job: JobId=46310 InitPrio=22562 usec=512
[2022-07-14T12:17:12.390] _slurm_rpc_submit_batch_job: JobId=46311 InitPrio=22562 usec=398
[2022-07-14T12:17:17.943] _slurm_rpc_submit_batch_job: JobId=46312 InitPrio=22562 usec=404
[2022-07-14T12:57:44.409] _slurm_rpc_submit_batch_job: JobId=46313 InitPrio=19194 usec=544
[2022-07-14T12:57:45.322] sched: Allocate JobId=46313 NodeList=cpu07 #CPUs=64 Partition=cpu-opteron
[2022-07-14T13:03:45.052] _slurm_rpc_submit_batch_job: JobId=46314 InitPrio=20680 usec=526
[2022-07-14T13:03:45.924] sched: Allocate JobId=46314 NodeList=cpu12 #CPUs=16 Partition=cpu-epyc
[2022-07-14T13:08:32.083] _slurm_rpc_submit_batch_job: JobId=46315 InitPrio=20680 usec=510
[2022-07-14T13:08:32.407] sched: Allocate JobId=46315 NodeList=cpu04 #CPUs=16 Partition=cpu-opteron
[2022-07-14T13:12:17.943] _slurm_rpc_submit_batch_job: JobId=46316 InitPrio=19194 usec=414
[2022-07-14T13:38:50.931] _slurm_rpc_submit_batch_job: JobId=46317 InitPrio=25788 usec=506
[2022-07-14T13:38:51.551] sched: Allocate JobId=46317 NodeList=gpu05 #CPUs=16 Partition=gpu-v100s
[2022-07-14T13:39:32.249] _job_complete: JobId=46317 WEXITSTATUS 1
[2022-07-14T13:39:32.249] _job_complete: JobId=46317 done
[2022-07-14T13:50:41.798] _slurm_rpc_submit_batch_job: JobId=46318 InitPrio=25788 usec=350
[2022-07-14T13:50:41.866] sched: Allocate JobId=46318 NodeList=gpu05 #CPUs=16 Partition=gpu-v100s
[2022-07-14T13:51:19.910] _slurm_rpc_submit_batch_job: JobId=46319 InitPrio=21721 usec=511
[2022-07-14T13:51:19.929] sched: Allocate JobId=46319 NodeList=cpu15 #CPUs=20 Partition=cpu-epyc
[2022-07-14T13:54:28.000] _slurm_rpc_submit_batch_job: JobId=46320 InitPrio=21756 usec=548
[2022-07-14T13:54:28.263] sched: Allocate JobId=46320 NodeList=cpu11 #CPUs=16 Partition=cpu-opteron
[2022-07-14T13:54:50.137] _job_complete: JobId=46320 WEXITSTATUS 1
[2022-07-14T13:54:50.137] _job_complete: JobId=46320 done
[2022-07-14T14:13:22.660] _job_complete: JobId=46306 WEXITSTATUS 1
[2022-07-14T14:13:22.660] _job_complete: JobId=46306 done
[2022-07-14T14:13:22.998] sched: Allocate JobId=46310 NodeList=cpu12 #CPUs=16 Partition=cpu-epyc
[2022-07-14T14:14:37.178] _slurm_rpc_submit_batch_job: JobId=46321 InitPrio=24444 usec=523
[2022-07-14T14:16:37.073] _slurm_rpc_submit_batch_job: JobId=46322 InitPrio=24512 usec=383
[2022-07-14T14:16:37.509] sched: Allocate JobId=46322 NodeList=cpu11 #CPUs=8 Partition=cpu-opteron
[2022-07-14T14:16:40.922] _job_complete: JobId=46322 WEXITSTATUS 1
[2022-07-14T14:16:40.923] _job_complete: JobId=46322 done
[2022-07-14T14:17:04.732] _slurm_rpc_submit_batch_job: JobId=46323 InitPrio=24512 usec=416
[2022-07-14T14:17:05.533] sched: Allocate JobId=46323 NodeList=cpu11 #CPUs=8 Partition=cpu-opteron
[2022-07-14T14:17:08.436] _job_complete: JobId=46323 WEXITSTATUS 1
[2022-07-14T14:17:08.436] _job_complete: JobId=46323 done
[2022-07-14T14:18:22.261] _slurm_rpc_submit_batch_job: JobId=46324 InitPrio=24512 usec=498
[2022-07-14T14:18:22.737] sched: Allocate JobId=46324 NodeList=cpu11 #CPUs=8 Partition=cpu-opteron
[2022-07-14T14:18:44.057] _slurm_rpc_kill_job: REQUEST_KILL_JOB JobId=46321 uid 548200036
[2022-07-14T14:22:34.646] _slurm_rpc_submit_batch_job: JobId=46325 InitPrio=24512 usec=454
[2022-07-14T14:24:46.764] _slurm_rpc_submit_batch_job: JobId=46326 InitPrio=24512 usec=455
[2022-07-14T14:24:47.367] sched: Allocate JobId=46326 NodeList=cpu11 #CPUs=8 Partition=cpu-opteron
[2022-07-14T14:24:57.740] _job_complete: JobId=46326 WEXITSTATUS 1
[2022-07-14T14:24:57.740] _job_complete: JobId=46326 done
[2022-07-14T14:25:36.982] _slurm_rpc_submit_batch_job: JobId=46327 InitPrio=24512 usec=424
[2022-07-14T14:25:37.441] sched: Allocate JobId=46327 NodeList=cpu11 #CPUs=8 Partition=cpu-opteron
[2022-07-14T14:25:47.306] _job_complete: JobId=46327 WEXITSTATUS 1
[2022-07-14T14:25:47.306] _job_complete: JobId=46327 done
[2022-07-14T14:26:22.297] _slurm_rpc_submit_batch_job: JobId=46328 InitPrio=24512 usec=441
[2022-07-14T14:26:22.506] sched: Allocate JobId=46328 NodeList=cpu11 #CPUs=8 Partition=cpu-opteron
[2022-07-14T14:26:33.123] _job_complete: JobId=46328 WEXITSTATUS 1
[2022-07-14T14:26:33.123] _job_complete: JobId=46328 done
[2022-07-14T14:27:43.403] _slurm_rpc_submit_batch_job: JobId=46329 InitPrio=24512 usec=459
[2022-07-14T14:27:43.720] sched: Allocate JobId=46329 NodeList=cpu11 #CPUs=8 Partition=cpu-opteron
[2022-07-14T14:27:54.075] _job_complete: JobId=46329 WEXITSTATUS 1
[2022-07-14T14:27:54.076] _job_complete: JobId=46329 done
[2022-07-14T14:33:06.165] _slurm_rpc_submit_batch_job: JobId=46330 InitPrio=24512 usec=424
[2022-07-14T14:33:06.339] sched: Allocate JobId=46330 NodeList=cpu11 #CPUs=8 Partition=cpu-opteron
[2022-07-14T14:35:03.245] _slurm_rpc_submit_batch_job: JobId=46331 InitPrio=24512 usec=397
[2022-07-14T14:41:44.968] _slurm_rpc_submit_batch_job: JobId=46332 InitPrio=21756 usec=482
[2022-07-14T15:04:36.557] _job_complete: JobId=46303 WEXITSTATUS 1
[2022-07-14T15:04:36.562] _job_complete: JobId=46303 done
[2022-07-14T15:14:09.664] _job_complete: JobId=46283 WEXITSTATUS 0
[2022-07-14T15:14:09.669] _job_complete: JobId=46283 done
[2022-07-14T15:14:14.637] sched: Allocate JobId=46331 NodeList=cpu03 #CPUs=8 Partition=cpu-opteron
[2022-07-14T15:14:28.463] _job_complete: JobId=46331 WEXITSTATUS 1
[2022-07-14T15:14:28.463] _job_complete: JobId=46331 done
[2022-07-14T15:14:28.834] sched: Allocate JobId=46316 NodeList=cpu03 #CPUs=64 Partition=cpu-opteron
[2022-07-14T15:45:58.315] _slurm_rpc_submit_batch_job: JobId=46333 InitPrio=24444 usec=486
[2022-07-14T15:46:19.006] _slurm_rpc_submit_batch_job: JobId=46334 InitPrio=24444 usec=415
[2022-07-14T15:55:03.933] _slurm_rpc_submit_batch_job: JobId=46335 InitPrio=24512 usec=404
[2022-07-14T16:01:45.594] _job_complete: JobId=46223 WEXITSTATUS 0
[2022-07-14T16:01:45.599] _job_complete: JobId=46223 done
[2022-07-14T16:01:51.529] sched: Allocate JobId=46247 NodeList=gpu04 #CPUs=16 Partition=gpu-k40c
[2022-07-14T16:08:25.342] _job_complete: JobId=46247 WEXITSTATUS 0
[2022-07-14T16:08:25.343] _job_complete: JobId=46247 done
[2022-07-14T16:10:44.990] _slurm_rpc_submit_batch_job: JobId=46336 InitPrio=21218 usec=501
[2022-07-14T16:10:45.133] sched: Allocate JobId=46336 NodeList=gpu04 #CPUs=16 Partition=gpu-k40c
[2022-07-14T16:49:47.370] Time limit exhausted for JobId=46249
[2022-07-14T16:49:49.250] sched: Allocate JobId=46325 NodeList=cpu13 #CPUs=8 Partition=cpu-epyc
[2022-07-14T16:49:49.250] sched: Allocate JobId=46333 NodeList=cpu13 #CPUs=16 Partition=cpu-epyc
[2022-07-14T16:49:54.970] _job_complete: JobId=46333 WEXITSTATUS 1
[2022-07-14T16:49:54.970] _job_complete: JobId=46333 done
[2022-07-14T16:49:55.202] sched: Allocate JobId=46334 NodeList=cpu13 #CPUs=16 Partition=cpu-epyc
[2022-07-14T16:49:55.691] _job_complete: JobId=46334 WEXITSTATUS 1
[2022-07-14T16:49:55.692] _job_complete: JobId=46334 done
[2022-07-14T17:04:02.694] _job_complete: JobId=46324 WEXITSTATUS 1
[2022-07-14T17:04:02.694] _job_complete: JobId=46324 done
[2022-07-14T17:04:03.279] sched: Allocate JobId=46335 NodeList=cpu11 #CPUs=8 Partition=cpu-opteron
[2022-07-14T17:04:13.760] _job_complete: JobId=46335 WEXITSTATUS 1
[2022-07-14T17:04:13.760] _job_complete: JobId=46335 done
[2022-07-14T17:04:24.276] _slurm_rpc_submit_batch_job: JobId=46337 InitPrio=19537 usec=382
[2022-07-14T17:04:26.933] sched: Allocate JobId=46337 NodeList=cpu13 #CPUs=24 Partition=cpu-epyc
[2022-07-14T17:12:31.954] _slurm_rpc_submit_batch_job: JobId=46338 InitPrio=19194 usec=376
[2022-07-14T17:16:37.982] _job_complete: JobId=46330 WEXITSTATUS 1
[2022-07-14T17:16:37.982] _job_complete: JobId=46330 done
[2022-07-14T17:25:44.759] _job_complete: JobId=46325 WEXITSTATUS 1
[2022-07-14T17:25:44.759] _job_complete: JobId=46325 done
[2022-07-14T17:31:01.228] _slurm_rpc_submit_batch_job: JobId=46339 InitPrio=20949 usec=508
[2022-07-14T17:31:02.226] sched: Allocate JobId=46339 NodeList=cpu11 #CPUs=16 Partition=cpu-opteron
[2022-07-14T17:31:13.706] _job_complete: JobId=46339 WEXITSTATUS 1
[2022-07-14T17:31:13.706] _job_complete: JobId=46339 done
[2022-07-14T17:38:53.646] _slurm_rpc_submit_batch_job: JobId=46340 InitPrio=20949 usec=432
[2022-07-14T17:38:54.116] sched: Allocate JobId=46340 NodeList=cpu11 #CPUs=16 Partition=cpu-opteron
[2022-07-14T17:39:06.121] _job_complete: JobId=46340 WEXITSTATUS 1
[2022-07-14T17:39:06.121] _job_complete: JobId=46340 done
[2022-07-14T17:40:49.509] _slurm_rpc_submit_batch_job: JobId=46341 InitPrio=20949 usec=397
[2022-07-14T17:40:50.279] sched: Allocate JobId=46341 NodeList=cpu11 #CPUs=16 Partition=cpu-opteron
[2022-07-14T17:41:02.949] _job_complete: JobId=46341 WEXITSTATUS 1
[2022-07-14T17:41:02.949] _job_complete: JobId=46341 done
[2022-07-14T17:41:58.773] _slurm_rpc_submit_batch_job: JobId=46342 InitPrio=20949 usec=463
[2022-07-14T17:41:59.378] sched: Allocate JobId=46342 NodeList=cpu11 #CPUs=16 Partition=cpu-opteron
[2022-07-14T17:42:11.170] _job_complete: JobId=46342 WEXITSTATUS 1
[2022-07-14T17:42:11.170] _job_complete: JobId=46342 done
[2022-07-14T17:45:27.217] _slurm_rpc_submit_batch_job: JobId=46343 InitPrio=20949 usec=426
[2022-07-14T17:45:27.783] sched: Allocate JobId=46343 NodeList=cpu11 #CPUs=16 Partition=cpu-opteron
[2022-07-14T17:45:39.532] _job_complete: JobId=46343 WEXITSTATUS 1
[2022-07-14T17:45:39.532] _job_complete: JobId=46343 done
[2022-07-14T18:05:08.278] _slurm_rpc_submit_batch_job: JobId=46344 InitPrio=20949 usec=554
[2022-07-14T18:05:08.335] sched/backfill: _start_job: Started JobId=46344 in cpu-opteron on cpu11
[2022-07-14T18:05:19.509] _job_complete: JobId=46344 WEXITSTATUS 1
[2022-07-14T18:05:19.509] _job_complete: JobId=46344 done
[2022-07-14T18:05:43.388] _slurm_rpc_submit_batch_job: JobId=46345 InitPrio=20949 usec=647
[2022-07-14T18:05:43.882] sched: Allocate JobId=46345 NodeList=cpu11 #CPUs=16 Partition=cpu-opteron
[2022-07-14T18:05:55.427] _job_complete: JobId=46345 WEXITSTATUS 1
[2022-07-14T18:05:55.427] _job_complete: JobId=46345 done
[2022-07-14T18:17:02.489] _slurm_rpc_submit_batch_job: JobId=46346 InitPrio=20949 usec=429
[2022-07-14T18:17:03.039] sched: Allocate JobId=46346 NodeList=cpu11 #CPUs=16 Partition=cpu-opteron
[2022-07-14T19:42:28.121] _job_complete: JobId=46346 WEXITSTATUS 0
[2022-07-14T19:42:28.121] _job_complete: JobId=46346 done
[2022-07-14T19:49:34.730] _job_complete: JobId=46307 WEXITSTATUS 1
[2022-07-14T19:49:34.731] _job_complete: JobId=46307 done
[2022-07-14T19:49:35.103] sched: Allocate JobId=46311 NodeList=cpu12 #CPUs=16 Partition=cpu-epyc
[2022-07-14T21:03:43.198] _job_complete: JobId=46318 WEXITSTATUS 0
[2022-07-14T21:03:43.203] _job_complete: JobId=46318 done
[2022-07-14T21:41:24.063] _job_complete: JobId=46336 WEXITSTATUS 0
[2022-07-14T21:41:24.069] _job_complete: JobId=46336 done
[2022-07-14T21:55:28.460] _slurm_rpc_submit_batch_job: JobId=46347 InitPrio=21218 usec=443
[2022-07-14T21:55:28.814] sched: Allocate JobId=46347 NodeList=gpu04 #CPUs=16 Partition=gpu-k40c
[2022-07-14T22:00:50.244] _job_complete: JobId=46148 WEXITSTATUS 0
[2022-07-14T22:00:50.244] _job_complete: JobId=46148 done
[2022-07-14T22:00:50.664] sched: Allocate JobId=46338 NodeList=cpu09 #CPUs=64 Partition=cpu-opteron
[2022-07-14T22:59:44.756] _job_complete: JobId=46319 WEXITSTATUS 0
[2022-07-14T22:59:44.757] _job_complete: JobId=46319 done
[2022-07-14T23:09:17.099] sched: _slurm_rpc_allocate_resources JobId=46348 NodeList=cpu11 usec=15483
[2022-07-14T23:20:11.389] _slurm_rpc_submit_batch_job: JobId=46349 InitPrio=19994 usec=423
[2022-07-14T23:20:11.770] sched: Allocate JobId=46349 NodeList=cpu13 #CPUs=2 Partition=cpu-epyc
[2022-07-14T23:20:14.131] _job_complete: JobId=46349 WEXITSTATUS 0
[2022-07-14T23:20:14.131] _job_complete: JobId=46349 done
[2022-07-14T23:21:32.818] _job_complete: JobId=46348 WEXITSTATUS 0
[2022-07-14T23:21:32.818] _job_complete: JobId=46348 done
[2022-07-14T23:25:38.254] _slurm_rpc_submit_batch_job: JobId=46350 InitPrio=19994 usec=391
[2022-07-14T23:25:38.343] sched: Allocate JobId=46350 NodeList=cpu13 #CPUs=2 Partition=cpu-epyc
[2022-07-14T23:26:10.572] _job_complete: JobId=46350 WEXITSTATUS 0
[2022-07-14T23:26:10.572] _job_complete: JobId=46350 done
[2022-07-14T23:29:19.186] _slurm_rpc_submit_batch_job: JobId=46351 InitPrio=19874 usec=479
[2022-07-14T23:29:19.747] sched: Allocate JobId=46351 NodeList=gpu05 #CPUs=16 Partition=gpu-v100s
[2022-07-14T23:29:26.426] _job_complete: JobId=46351 WEXITSTATUS 1
[2022-07-14T23:29:26.426] _job_complete: JobId=46351 done
[2022-07-14T23:30:26.006] _slurm_rpc_submit_batch_job: JobId=46352 InitPrio=19874 usec=394
[2022-07-14T23:30:27.846] sched: Allocate JobId=46352 NodeList=gpu05 #CPUs=16 Partition=gpu-v100s
[2022-07-14T23:35:27.234] _slurm_rpc_submit_batch_job: JobId=46353 InitPrio=19874 usec=433
[2022-07-14T23:35:27.357] sched: Allocate JobId=46353 NodeList=gpu03 #CPUs=16 Partition=gpu-k10
[2022-07-14T23:41:07.302] _slurm_rpc_kill_job: REQUEST_KILL_JOB JobId=46353 uid 548200021
[2022-07-14T23:41:40.125] _slurm_rpc_submit_batch_job: JobId=46354 InitPrio=19874 usec=482
[2022-07-14T23:41:41.002] sched: Allocate JobId=46354 NodeList=gpu03 #CPUs=16 Partition=gpu-k10
[2022-07-14T23:42:01.371] _job_complete: JobId=46354 WEXITSTATUS 1
[2022-07-14T23:42:01.371] _job_complete: JobId=46354 done
[2022-07-14T23:43:56.518] _slurm_rpc_submit_batch_job: JobId=46355 InitPrio=19874 usec=474
[2022-07-14T23:43:57.235] sched: Allocate JobId=46355 NodeList=gpu01 #CPUs=16 Partition=gpu-k10
[2022-07-14T23:44:19.556] _job_complete: JobId=46355 WEXITSTATUS 1
[2022-07-14T23:44:19.556] _job_complete: JobId=46355 done
[2022-07-14T23:46:08.396] _slurm_rpc_submit_batch_job: JobId=46356 InitPrio=19942 usec=410
[2022-07-14T23:46:08.413] sched: Allocate JobId=46356 NodeList=gpu02 #CPUs=8 Partition=gpu-titan
[2022-07-14T23:48:55.062] _slurm_rpc_submit_batch_job: JobId=46357 InitPrio=19874 usec=426
[2022-07-14T23:52:06.846] _slurm_rpc_submit_batch_job: JobId=46358 InitPrio=19874 usec=513
[2022-07-15T00:02:29.315] _job_complete: JobId=46356 WEXITSTATUS 0
[2022-07-15T00:02:29.316] _job_complete: JobId=46356 done
[2022-07-15T00:10:19.238] _job_complete: JobId=46308 WEXITSTATUS 0
[2022-07-15T00:10:19.238] _job_complete: JobId=46308 done
[2022-07-15T00:10:19.409] sched: Allocate JobId=46312 NodeList=cpu14 #CPUs=16 Partition=cpu-epyc
[2022-07-15T00:15:30.339] _job_complete: JobId=46305 WEXITSTATUS 0
[2022-07-15T00:15:30.339] _job_complete: JobId=46305 done
[2022-07-15T00:15:30.712] sched: Allocate JobId=46332 NodeList=cpu13 #CPUs=16 Partition=cpu-epyc
[2022-07-15T00:21:47.740] _slurm_rpc_submit_batch_job: JobId=46359 InitPrio=19977 usec=424
[2022-07-15T00:21:48.587] sched: Allocate JobId=46359 NodeList=cpu11 #CPUs=4 Partition=cpu-opteron
[2022-07-15T00:21:52.874] _job_complete: JobId=46359 WEXITSTATUS 0
[2022-07-15T00:21:52.874] _job_complete: JobId=46359 done
[2022-07-15T01:34:38.894] _job_complete: JobId=46309 WEXITSTATUS 0
[2022-07-15T01:34:38.894] _job_complete: JobId=46309 done
[2022-07-15T01:57:02.840] _job_complete: JobId=46313 WEXITSTATUS 0
[2022-07-15T01:57:02.846] _job_complete: JobId=46313 done
[2022-07-15T02:00:06.367] _job_complete: JobId=46332 WEXITSTATUS 0
[2022-07-15T02:00:06.367] _job_complete: JobId=46332 done
[2022-07-15T02:11:11.218] _slurm_rpc_submit_batch_job: JobId=46360 InitPrio=20411 usec=495
[2022-07-15T02:11:11.393] sched: Allocate JobId=46360 NodeList=cpu13 #CPUs=16 Partition=cpu-epyc
[2022-07-15T02:11:59.175] _slurm_rpc_kill_job: REQUEST_KILL_JOB JobId=46360 uid 548200045
[2022-07-15T02:15:41.206] _slurm_rpc_submit_batch_job: JobId=46361 InitPrio=20411 usec=458
[2022-07-15T02:15:41.893] sched: Allocate JobId=46361 NodeList=cpu13 #CPUs=16 Partition=cpu-epyc
[2022-07-15T02:19:41.044] _slurm_rpc_kill_job: REQUEST_KILL_JOB JobId=46361 uid 548200045
[2022-07-15T02:20:05.701] _slurm_rpc_submit_batch_job: JobId=46362 InitPrio=20274 usec=447
[2022-07-15T02:20:06.433] sched: Allocate JobId=46362 NodeList=cpu15 #CPUs=32 Partition=cpu-epyc
[2022-07-15T02:28:07.982] _job_complete: JobId=46243 WEXITSTATUS 0
[2022-07-15T02:28:07.988] _job_complete: JobId=46243 done
[2022-07-15T02:54:53.469] _job_complete: JobId=46362 WEXITSTATUS 0
[2022-07-15T02:54:53.470] _job_complete: JobId=46362 done
[2022-07-15T03:24:09.187] _job_complete: JobId=46310 WEXITSTATUS 0
[2022-07-15T03:24:09.188] _job_complete: JobId=46310 done
[2022-07-15T03:27:00.749] _job_complete: JobId=46347 WEXITSTATUS 0
[2022-07-15T03:27:00.754] _job_complete: JobId=46347 done
[2022-07-15T04:46:53.034] _slurm_rpc_submit_batch_job: JobId=46363 InitPrio=22630 usec=415
[2022-07-15T04:46:53.057] sched: Allocate JobId=46363 NodeList=cpu11 #CPUs=8 Partition=cpu-opteron
[2022-07-15T04:49:54.974] _job_complete: JobId=46363 WEXITSTATUS 1
[2022-07-15T04:49:54.974] _job_complete: JobId=46363 done
[2022-07-15T05:04:09.684] _slurm_rpc_submit_batch_job: JobId=46364 InitPrio=22630 usec=495
[2022-07-15T05:04:09.987] sched: Allocate JobId=46364 NodeList=cpu11 #CPUs=8 Partition=cpu-opteron
[2022-07-15T05:28:51.324] _slurm_rpc_submit_batch_job: JobId=46365 InitPrio=22562 usec=519
[2022-07-15T05:28:51.445] sched: Allocate JobId=46365 NodeList=cpu07 #CPUs=16 Partition=cpu-opteron
[2022-07-15T05:29:09.299] _slurm_rpc_kill_job: REQUEST_KILL_JOB JobId=46365 uid 548200029
[2022-07-15T05:30:32.035] _slurm_rpc_submit_batch_job: JobId=46366 InitPrio=22562 usec=474
[2022-07-15T05:30:32.582] sched: Allocate JobId=46366 NodeList=cpu07 #CPUs=16 Partition=cpu-opteron
[2022-07-15T05:34:10.152] _slurm_rpc_submit_batch_job: JobId=46367 InitPrio=22562 usec=376
[2022-07-15T05:34:10.740] sched: Allocate JobId=46367 NodeList=cpu07 #CPUs=16 Partition=cpu-opteron
[2022-07-15T05:38:43.903] _slurm_rpc_submit_batch_job: JobId=46368 InitPrio=22562 usec=376
[2022-07-15T05:38:44.650] sched: Allocate JobId=46368 NodeList=cpu07 #CPUs=16 Partition=cpu-opteron
[2022-07-15T05:51:50.049] _job_complete: JobId=46367 WEXITSTATUS 0
[2022-07-15T05:51:50.050] _job_complete: JobId=46367 done
[2022-07-15T05:55:08.740] _job_complete: JobId=46366 WEXITSTATUS 0
[2022-07-15T05:55:08.740] _job_complete: JobId=46366 done
[2022-07-15T05:58:53.211] _job_complete: JobId=46316 WEXITSTATUS 0
[2022-07-15T05:58:53.216] _job_complete: JobId=46316 done
[2022-07-15T06:02:36.787] _job_complete: JobId=46368 WEXITSTATUS 0
[2022-07-15T06:02:36.788] _job_complete: JobId=46368 done
[2022-07-15T06:29:38.322] _slurm_rpc_submit_batch_job: JobId=46369 InitPrio=21218 usec=402
[2022-07-15T06:29:38.676] sched: Allocate JobId=46369 NodeList=gpu04 #CPUs=16 Partition=gpu-k40c
[2022-07-15T06:30:29.896] _job_complete: JobId=46364 WEXITSTATUS 0
[2022-07-15T06:30:29.897] _job_complete: JobId=46364 done
[2022-07-15T07:05:16.125] _job_complete: JobId=46352 WEXITSTATUS 0
[2022-07-15T07:05:16.126] _job_complete: JobId=46352 done
[2022-07-15T07:05:17.001] sched: Allocate JobId=46357 NodeList=gpu05 #CPUs=16 Partition=gpu-v100s
[2022-07-15T07:57:28.909] _slurm_rpc_submit_batch_job: JobId=46370 InitPrio=19194 usec=406
[2022-07-15T07:57:29.856] sched: Allocate JobId=46370 NodeList=cpu03 #CPUs=64 Partition=cpu-opteron
[2022-07-15T08:35:31.826] _job_complete: JobId=46311 WEXITSTATUS 0
[2022-07-15T08:35:31.826] _job_complete: JobId=46311 done
[2022-07-15T08:43:03.856] _slurm_rpc_submit_batch_job: JobId=46371 InitPrio=19434 usec=395
[2022-07-15T08:43:03.909] sched: Allocate JobId=46371 NodeList=cpu15 #CPUs=36 Partition=cpu-epyc
[2022-07-15T09:03:12.338] _slurm_rpc_submit_batch_job: JobId=46372 InitPrio=19468 usec=364
[2022-07-15T09:03:13.069] sched: Allocate JobId=46372 NodeList=cpu12 #CPUs=32 Partition=cpu-epyc
[2022-07-15T11:21:32.389] _slurm_rpc_submit_batch_job: JobId=46373 InitPrio=20274 usec=457
[2022-07-15T12:43:32.514] _slurm_rpc_submit_batch_job: JobId=46374 InitPrio=21218 usec=845
[2022-07-15T13:03:48.213] Time limit exhausted for JobId=46314
[2022-07-15T13:08:48.720] Time limit exhausted for JobId=46315
[2022-07-15T13:15:54.742] _slurm_rpc_submit_batch_job: JobId=46375 InitPrio=20680 usec=539
[2022-07-15T13:15:55.420] sched: Allocate JobId=46375 NodeList=cpu12 #CPUs=16 Partition=cpu-epyc
[2022-07-15T13:16:23.562] _slurm_rpc_submit_batch_job: JobId=46376 InitPrio=20680 usec=455
[2022-07-15T13:16:24.444] sched: Allocate JobId=46376 NodeList=cpu13 #CPUs=16 Partition=cpu-epyc
[2022-07-15T13:58:23.827] _slurm_rpc_submit_batch_job: JobId=46377 InitPrio=20269 usec=549
[2022-07-15T13:58:23.914] sched: Allocate JobId=46377 NodeList=cpu07 #CPUs=64 Partition=cpu-opteron
[2022-07-15T14:58:22.245] _job_complete: JobId=46312 WEXITSTATUS 0
[2022-07-15T14:58:22.245] _job_complete: JobId=46312 done
[2022-07-15T15:14:58.821] _job_complete: JobId=46357 WEXITSTATUS 0
[2022-07-15T15:14:58.821] _job_complete: JobId=46357 done
[2022-07-15T15:14:59.699] sched: Allocate JobId=46358 NodeList=gpu05 #CPUs=16 Partition=gpu-v100s
[2022-07-15T16:43:26.241] _job_complete: JobId=46375 WEXITSTATUS 0
[2022-07-15T16:43:26.241] _job_complete: JobId=46375 done
[2022-07-15T16:56:50.495] _slurm_rpc_submit_batch_job: JobId=46378 InitPrio=23637 usec=525
[2022-07-15T16:56:51.280] sched: Allocate JobId=46378 NodeList=cpu12 #CPUs=16 Partition=cpu-epyc
[2022-07-15T16:56:56.217] _slurm_rpc_submit_batch_job: JobId=46379 InitPrio=23637 usec=401
[2022-07-15T16:56:56.272] sched: Allocate JobId=46379 NodeList=cpu14 #CPUs=16 Partition=cpu-epyc
[2022-07-15T16:57:01.477] _slurm_rpc_submit_batch_job: JobId=46380 InitPrio=23637 usec=398
[2022-07-15T16:57:06.642] _slurm_rpc_submit_batch_job: JobId=46381 InitPrio=23637 usec=447
[2022-07-15T16:57:11.909] _slurm_rpc_submit_batch_job: JobId=46382 InitPrio=23637 usec=446
[2022-07-15T16:57:18.386] _slurm_rpc_submit_batch_job: JobId=46383 InitPrio=23637 usec=426
[2022-07-15T16:57:29.979] _slurm_rpc_submit_batch_job: JobId=46384 InitPrio=23637 usec=410
[2022-07-15T16:57:35.349] _slurm_rpc_submit_batch_job: JobId=46385 InitPrio=23637 usec=426
[2022-07-15T16:57:43.194] _slurm_rpc_submit_batch_job: JobId=46386 InitPrio=23637 usec=472
[2022-07-15T16:57:49.027] _slurm_rpc_submit_batch_job: JobId=46387 InitPrio=23637 usec=400
[2022-07-15T17:21:13.511] _job_complete: JobId=46379 WEXITSTATUS 0
[2022-07-15T17:21:13.511] _job_complete: JobId=46379 done
[2022-07-15T17:21:13.790] sched: Allocate JobId=46380 NodeList=cpu14 #CPUs=16 Partition=cpu-epyc
[2022-07-15T17:24:31.811] _job_complete: JobId=46378 WEXITSTATUS 0
[2022-07-15T17:24:31.811] _job_complete: JobId=46378 done
[2022-07-15T17:24:32.003] sched: Allocate JobId=46381 NodeList=cpu12 #CPUs=16 Partition=cpu-epyc
[2022-07-15T17:45:48.907] _job_complete: JobId=46380 WEXITSTATUS 0
[2022-07-15T17:45:48.908] _job_complete: JobId=46380 done
[2022-07-15T17:45:49.155] sched: Allocate JobId=46382 NodeList=cpu14 #CPUs=16 Partition=cpu-epyc
[2022-07-15T17:54:08.216] _job_complete: JobId=46381 WEXITSTATUS 0
[2022-07-15T17:54:08.217] _job_complete: JobId=46381 done
[2022-07-15T17:54:08.427] sched: Allocate JobId=46383 NodeList=cpu12 #CPUs=16 Partition=cpu-epyc
[2022-07-15T18:04:34.605] _job_complete: JobId=45648 WEXITSTATUS 2
[2022-07-15T18:04:34.605] _job_complete: JobId=45648 done
[2022-07-15T18:10:25.155] _job_complete: JobId=46382 WEXITSTATUS 0
[2022-07-15T18:10:25.155] _job_complete: JobId=46382 done
[2022-07-15T18:10:25.491] sched: Allocate JobId=46384 NodeList=cpu14 #CPUs=16 Partition=cpu-epyc
[2022-07-15T18:26:33.023] _job_complete: JobId=46383 WEXITSTATUS 0
[2022-07-15T18:26:33.023] _job_complete: JobId=46383 done
[2022-07-15T18:26:33.367] sched: Allocate JobId=46385 NodeList=cpu12 #CPUs=16 Partition=cpu-epyc
[2022-07-15T18:34:08.057] _job_complete: JobId=46384 WEXITSTATUS 0
[2022-07-15T18:34:08.057] _job_complete: JobId=46384 done
[2022-07-15T18:34:08.288] sched: Allocate JobId=46386 NodeList=cpu14 #CPUs=16 Partition=cpu-epyc
[2022-07-15T18:55:22.602] _job_complete: JobId=46385 WEXITSTATUS 0
[2022-07-15T18:55:22.602] _job_complete: JobId=46385 done
[2022-07-15T18:55:22.828] sched: Allocate JobId=46387 NodeList=cpu12 #CPUs=16 Partition=cpu-epyc
[2022-07-15T18:58:03.849] _job_complete: JobId=46386 WEXITSTATUS 0
[2022-07-15T18:58:03.849] _job_complete: JobId=46386 done
[2022-07-15T19:27:44.741] _job_complete: JobId=46387 WEXITSTATUS 0
[2022-07-15T19:27:44.741] _job_complete: JobId=46387 done
[2022-07-15T20:25:16.461] _slurm_rpc_submit_batch_job: JobId=46388 InitPrio=19194 usec=432
[2022-07-15T20:25:29.579] _slurm_rpc_submit_batch_job: JobId=46389 InitPrio=19194 usec=407
[2022-07-15T20:25:47.417] _slurm_rpc_kill_job: REQUEST_KILL_JOB JobId=45838 uid 548200017
[2022-07-15T20:25:47.417] _slurm_rpc_kill_job: REQUEST_KILL_JOB JobId=45837 uid 548200017
[2022-07-15T20:25:49.466] sched: Allocate JobId=46388 NodeList=cpu05 #CPUs=64 Partition=cpu-opteron
[2022-07-15T20:25:49.500] sched: Allocate JobId=46389 NodeList=cpu01 #CPUs=64 Partition=cpu-opteron
[2022-07-15T20:27:39.870] _slurm_rpc_submit_batch_job: JobId=46390 InitPrio=19194 usec=399
[2022-07-15T20:27:50.712] _slurm_rpc_submit_batch_job: JobId=46391 InitPrio=19194 usec=395
[2022-07-15T20:28:12.838] _slurm_rpc_kill_job: REQUEST_KILL_JOB JobId=45869 uid 548200017
[2022-07-15T20:28:12.839] _slurm_rpc_kill_job: REQUEST_KILL_JOB JobId=45839 uid 548200017
[2022-07-15T20:28:14.836] sched: Allocate JobId=46390 NodeList=cpu11 #CPUs=64 Partition=cpu-opteron
[2022-07-15T20:28:14.889] sched: Allocate JobId=46391 NodeList=cpu08 #CPUs=64 Partition=cpu-opteron
[2022-07-15T20:29:05.281] _slurm_rpc_submit_batch_job: JobId=46392 InitPrio=22630 usec=407
[2022-07-15T20:30:04.616] _slurm_rpc_submit_batch_job: JobId=46393 InitPrio=22562 usec=401
[2022-07-15T20:30:14.930] _slurm_rpc_submit_batch_job: JobId=46394 InitPrio=22562 usec=435
[2022-07-15T20:30:25.316] _slurm_rpc_submit_batch_job: JobId=46395 InitPrio=22562 usec=395
[2022-07-15T20:45:37.152] _slurm_rpc_submit_batch_job: JobId=46396 InitPrio=19605 usec=389
[2022-07-15T20:45:37.817] sched: Allocate JobId=46396 NodeList=cpu12 #CPUs=16 Partition=cpu-epyc
[2022-07-15T20:45:41.191] _job_complete: JobId=46396 WEXITSTATUS 1
[2022-07-15T20:45:41.192] _job_complete: JobId=46396 done
[2022-07-15T20:52:23.067] _slurm_rpc_submit_batch_job: JobId=46397 InitPrio=19605 usec=433
[2022-07-15T20:52:23.493] sched: Allocate JobId=46397 NodeList=cpu12 #CPUs=16 Partition=cpu-epyc
[2022-07-15T20:53:28.610] _slurm_rpc_submit_batch_job: JobId=46398 InitPrio=19605 usec=483
[2022-07-15T20:53:29.859] sched: Allocate JobId=46398 NodeList=cpu14 #CPUs=16 Partition=cpu-epyc
[2022-07-15T21:50:07.023] _job_complete: JobId=46337 WEXITSTATUS 0
[2022-07-15T21:50:07.024] _job_complete: JobId=46337 done
[2022-07-15T21:50:08.903] sched: Allocate JobId=46373 NodeList=cpu13 #CPUs=32 Partition=cpu-epyc
[2022-07-15T22:15:04.949] _job_complete: JobId=46373 WEXITSTATUS 1
[2022-07-15T22:15:04.949] _job_complete: JobId=46373 done
[2022-07-15T22:59:47.551] _job_complete: JobId=46369 WEXITSTATUS 0
[2022-07-15T22:59:47.556] _job_complete: JobId=46369 done
[2022-07-15T22:59:50.505] sched: Allocate JobId=46374 NodeList=gpu04 #CPUs=16 Partition=gpu-k40c
[2022-07-15T23:06:46.334] _job_complete: JobId=46358 WEXITSTATUS 0
[2022-07-15T23:06:46.334] _job_complete: JobId=46358 done
[2022-07-16T00:52:54.739] _job_complete: JobId=46398 WEXITSTATUS 0
[2022-07-16T00:52:54.745] _job_complete: JobId=46398 done
[2022-07-16T01:14:43.804] _job_complete: JobId=46397 WEXITSTATUS 0
[2022-07-16T01:14:43.805] _job_complete: JobId=46397 done
[2022-07-16T03:03:15.235] _job_complete: JobId=46054 WEXITSTATUS 0
[2022-07-16T03:03:15.236] _job_complete: JobId=46054 done
[2022-07-16T03:03:15.718] sched: Allocate JobId=46392 NodeList=cpu10 #CPUs=8 Partition=cpu-opteron
[2022-07-16T03:03:15.719] sched: Allocate JobId=46393 NodeList=cpu10 #CPUs=16 Partition=cpu-opteron
[2022-07-16T03:03:15.720] sched: Allocate JobId=46394 NodeList=cpu10 #CPUs=16 Partition=cpu-opteron
[2022-07-16T03:03:15.721] sched: Allocate JobId=46395 NodeList=cpu10 #CPUs=16 Partition=cpu-opteron
[2022-07-16T03:06:22.024] _job_complete: JobId=46393 WEXITSTATUS 1
[2022-07-16T03:06:22.025] _job_complete: JobId=46393 done
[2022-07-16T03:20:25.611] _job_complete: JobId=46395 WEXITSTATUS 0
[2022-07-16T03:20:25.612] _job_complete: JobId=46395 done
[2022-07-16T03:25:04.261] _slurm_rpc_submit_batch_job: JobId=46399 InitPrio=20274 usec=435
[2022-07-16T03:25:05.029] sched: Allocate JobId=46399 NodeList=cpu13 #CPUs=32 Partition=cpu-epyc
[2022-07-16T03:25:13.490] _job_complete: JobId=46394 WEXITSTATUS 0
[2022-07-16T03:25:13.491] _job_complete: JobId=46394 done
[2022-07-16T03:26:18.380] _slurm_rpc_kill_job: REQUEST_KILL_JOB JobId=46399 uid 548200045
[2022-07-16T03:32:13.516] _slurm_rpc_submit_batch_job: JobId=46400 InitPrio=20274 usec=471
[2022-07-16T03:32:13.698] sched: Allocate JobId=46400 NodeList=cpu13 #CPUs=32 Partition=cpu-epyc
[2022-07-16T04:06:38.990] _job_complete: JobId=46400 WEXITSTATUS 1
[2022-07-16T04:06:38.990] _job_complete: JobId=46400 done
[2022-07-16T05:15:06.543] _slurm_rpc_submit_batch_job: JobId=46401 InitPrio=20274 usec=585
[2022-07-16T05:15:07.334] sched: Allocate JobId=46401 NodeList=cpu13 #CPUs=32 Partition=cpu-epyc
[2022-07-16T08:53:33.833] _slurm_rpc_kill_job: REQUEST_KILL_JOB JobId=45916 uid 548200017
[2022-07-16T08:54:03.951] _slurm_rpc_submit_batch_job: JobId=46402 InitPrio=19331 usec=597
[2022-07-16T08:54:04.889] sched: Allocate JobId=46402 NodeList=cpu14 #CPUs=48 Partition=cpu-epyc
[2022-07-16T09:18:54.816] _slurm_rpc_submit_batch_job: JobId=46403 InitPrio=19605 usec=440
[2022-07-16T09:18:55.777] sched: Allocate JobId=46403 NodeList=cpu12 #CPUs=16 Partition=cpu-epyc
[2022-07-16T13:16:51.781] Time limit exhausted for JobId=46376
[2022-07-16T13:22:59.021] _job_complete: JobId=46392 WEXITSTATUS 0
[2022-07-16T13:22:59.027] _job_complete: JobId=46392 done
[2022-07-16T13:58:51.317] Time limit exhausted for JobId=46377
[2022-07-16T14:29:48.955] _job_complete: JobId=46338 WEXITSTATUS 0
[2022-07-16T14:29:48.961] _job_complete: JobId=46338 done
[2022-07-16T16:48:26.126] _slurm_rpc_submit_batch_job: JobId=46404 InitPrio=19194 usec=571
[2022-07-16T16:48:26.498] sched: Allocate JobId=46404 NodeList=cpu07 #CPUs=64 Partition=cpu-opteron
[2022-07-16T16:48:59.648] _slurm_rpc_submit_batch_job: JobId=46405 InitPrio=22630 usec=421
[2022-07-16T16:49:00.545] sched: Allocate JobId=46405 NodeList=cpu15 #CPUs=8 Partition=cpu-epyc
[2022-07-16T16:49:28.422] _slurm_rpc_kill_job: REQUEST_KILL_JOB JobId=46404 uid 548200017
[2022-07-16T16:53:00.534] _slurm_rpc_submit_batch_job: JobId=46406 InitPrio=22425 usec=404
[2022-07-16T16:53:00.993] sched: Allocate JobId=46406 NodeList=cpu07 #CPUs=32 Partition=cpu-opteron
[2022-07-16T16:53:24.784] _job_complete: JobId=46406 WEXITSTATUS 0
[2022-07-16T16:53:24.784] _job_complete: JobId=46406 done
[2022-07-16T16:55:27.620] _slurm_rpc_submit_batch_job: JobId=46407 InitPrio=22425 usec=393
[2022-07-16T16:55:30.198] sched: Allocate JobId=46407 NodeList=cpu07 #CPUs=32 Partition=cpu-opteron
[2022-07-16T16:55:39.632] _job_complete: JobId=46407 WEXITSTATUS 0
[2022-07-16T16:55:39.633] _job_complete: JobId=46407 done
[2022-07-16T16:56:58.177] _slurm_rpc_submit_batch_job: JobId=46408 InitPrio=22425 usec=387
[2022-07-16T16:56:58.322] sched: Allocate JobId=46408 NodeList=cpu07 #CPUs=32 Partition=cpu-opteron
[2022-07-16T16:57:07.339] _job_complete: JobId=46408 WEXITSTATUS 0
[2022-07-16T16:57:07.340] _job_complete: JobId=46408 done
[2022-07-16T16:58:39.297] _slurm_rpc_submit_batch_job: JobId=46409 InitPrio=22425 usec=374
[2022-07-16T16:58:39.583] sched: Allocate JobId=46409 NodeList=cpu07 #CPUs=32 Partition=cpu-opteron
[2022-07-16T16:58:41.878] _job_complete: JobId=46409 WEXITSTATUS 1
[2022-07-16T16:58:41.878] _job_complete: JobId=46409 done
[2022-07-16T16:59:10.401] _slurm_rpc_submit_batch_job: JobId=46410 InitPrio=22425 usec=466
[2022-07-16T16:59:10.632] sched: Allocate JobId=46410 NodeList=cpu07 #CPUs=32 Partition=cpu-opteron
[2022-07-16T16:59:32.791] _job_complete: JobId=46410 WEXITSTATUS 0
[2022-07-16T16:59:32.792] _job_complete: JobId=46410 done
[2022-07-16T16:59:39.856] _slurm_rpc_submit_batch_job: JobId=46411 InitPrio=22425 usec=423
[2022-07-16T16:59:40.670] sched: Allocate JobId=46411 NodeList=cpu07 #CPUs=32 Partition=cpu-opteron
[2022-07-16T17:00:02.932] _job_complete: JobId=46411 WEXITSTATUS 0
[2022-07-16T17:00:02.932] _job_complete: JobId=46411 done
[2022-07-16T17:01:21.171] _slurm_rpc_submit_batch_job: JobId=46412 InitPrio=22425 usec=392
[2022-07-16T17:01:21.810] sched: Allocate JobId=46412 NodeList=cpu07 #CPUs=32 Partition=cpu-opteron
[2022-07-16T17:01:44.359] _job_complete: JobId=46412 WEXITSTATUS 0
[2022-07-16T17:01:44.360] _job_complete: JobId=46412 done
[2022-07-16T17:03:34.195] _slurm_rpc_submit_batch_job: JobId=46413 InitPrio=22425 usec=421
[2022-07-16T17:03:35.087] sched: Allocate JobId=46413 NodeList=cpu07 #CPUs=32 Partition=cpu-opteron
[2022-07-16T17:03:57.771] _job_complete: JobId=46413 WEXITSTATUS 0
[2022-07-16T17:03:57.772] _job_complete: JobId=46413 done
[2022-07-16T17:06:39.899] _slurm_rpc_submit_batch_job: JobId=46414 InitPrio=19194 usec=501
[2022-07-16T17:06:40.339] sched: Allocate JobId=46414 NodeList=cpu07 #CPUs=64 Partition=cpu-opteron
[2022-07-16T18:03:56.757] _slurm_rpc_submit_batch_job: JobId=46415 InitPrio=22425 usec=477
[2022-07-16T18:03:57.326] sched: Allocate JobId=46415 NodeList=cpu09 #CPUs=32 Partition=cpu-opteron
[2022-07-16T18:04:01.955] _job_complete: JobId=46415 WEXITSTATUS 1
[2022-07-16T18:04:01.955] _job_complete: JobId=46415 done
[2022-07-16T18:07:27.937] _slurm_rpc_submit_batch_job: JobId=46416 InitPrio=22425 usec=434
[2022-07-16T18:07:28.648] sched: Allocate JobId=46416 NodeList=cpu09 #CPUs=32 Partition=cpu-opteron
[2022-07-16T18:07:32.771] _job_complete: JobId=46416 WEXITSTATUS 1
[2022-07-16T18:07:32.772] _job_complete: JobId=46416 done
[2022-07-16T18:10:06.015] _slurm_rpc_submit_batch_job: JobId=46417 InitPrio=22425 usec=435
[2022-07-16T18:10:06.900] sched: Allocate JobId=46417 NodeList=cpu09 #CPUs=32 Partition=cpu-opteron
[2022-07-16T18:10:10.966] _job_complete: JobId=46417 WEXITSTATUS 1
[2022-07-16T18:10:10.966] _job_complete: JobId=46417 done
[2022-07-16T18:12:57.377] _slurm_rpc_submit_batch_job: JobId=46418 InitPrio=22425 usec=403
[2022-07-16T18:12:58.223] sched: Allocate JobId=46418 NodeList=cpu09 #CPUs=32 Partition=cpu-opteron
[2022-07-16T18:13:02.258] _job_complete: JobId=46418 WEXITSTATUS 1
[2022-07-16T18:13:02.258] _job_complete: JobId=46418 done
[2022-07-16T18:25:54.043] _slurm_rpc_submit_batch_job: JobId=46419 InitPrio=22425 usec=457
[2022-07-16T18:25:54.648] sched: Allocate JobId=46419 NodeList=cpu09 #CPUs=32 Partition=cpu-opteron
[2022-07-16T18:27:52.597] _job_complete: JobId=46419 WEXITSTATUS 0
[2022-07-16T18:27:52.597] _job_complete: JobId=46419 done
[2022-07-16T18:28:12.427] _slurm_rpc_submit_batch_job: JobId=46420 InitPrio=22425 usec=560
[2022-07-16T18:28:12.976] sched: Allocate JobId=46420 NodeList=cpu09 #CPUs=32 Partition=cpu-opteron
[2022-07-16T18:29:54.381] _job_complete: JobId=46420 WEXITSTATUS 0
[2022-07-16T18:29:54.381] _job_complete: JobId=46420 done
[2022-07-16T18:30:24.758] _slurm_rpc_submit_batch_job: JobId=46421 InitPrio=22425 usec=434
[2022-07-16T18:30:25.166] sched: Allocate JobId=46421 NodeList=cpu09 #CPUs=32 Partition=cpu-opteron
[2022-07-16T18:32:21.562] _job_complete: JobId=46421 WEXITSTATUS 0
[2022-07-16T18:32:21.563] _job_complete: JobId=46421 done
[2022-07-16T18:33:22.995] _slurm_rpc_submit_batch_job: JobId=46422 InitPrio=22425 usec=446
[2022-07-16T18:33:23.499] sched: Allocate JobId=46422 NodeList=cpu09 #CPUs=32 Partition=cpu-opteron
[2022-07-16T18:33:27.371] _job_complete: JobId=46422 WEXITSTATUS 1
[2022-07-16T18:33:27.372] _job_complete: JobId=46422 done
[2022-07-16T18:36:14.467] _slurm_rpc_submit_batch_job: JobId=46423 InitPrio=22425 usec=364
[2022-07-16T18:36:14.742] sched: Allocate JobId=46423 NodeList=cpu09 #CPUs=32 Partition=cpu-opteron
[2022-07-16T18:38:14.198] _job_complete: JobId=46423 WEXITSTATUS 0
[2022-07-16T18:38:14.198] _job_complete: JobId=46423 done
[2022-07-16T18:39:51.969] _slurm_rpc_submit_batch_job: JobId=46424 InitPrio=22425 usec=392
[2022-07-16T18:39:52.184] sched: Allocate JobId=46424 NodeList=cpu09 #CPUs=32 Partition=cpu-opteron
[2022-07-16T18:41:48.265] _job_complete: JobId=46424 WEXITSTATUS 0
[2022-07-16T18:41:48.266] _job_complete: JobId=46424 done
[2022-07-16T18:57:40.805] _slurm_rpc_submit_batch_job: JobId=46425 InitPrio=22425 usec=407
[2022-07-16T18:57:41.130] sched: Allocate JobId=46425 NodeList=cpu09 #CPUs=32 Partition=cpu-opteron
[2022-07-16T18:58:03.506] _job_complete: JobId=46425 WEXITSTATUS 0
[2022-07-16T18:58:03.506] _job_complete: JobId=46425 done
[2022-07-16T21:18:24.547] _job_complete: JobId=46405 WEXITSTATUS 0
[2022-07-16T21:18:24.552] _job_complete: JobId=46405 done
[2022-07-17T03:51:53.296] _slurm_rpc_submit_batch_job: JobId=46426 InitPrio=22562 usec=1015
[2022-07-17T03:51:53.675] sched: Allocate JobId=46426 NodeList=gpu01 #CPUs=16 Partition=gpu-k10
[2022-07-17T03:57:58.113] _slurm_rpc_submit_batch_job: JobId=46427 InitPrio=22425 usec=419
[2022-07-17T03:57:58.360] sched: Allocate JobId=46427 NodeList=cpu09 #CPUs=32 Partition=cpu-opteron
[2022-07-17T03:58:22.158] _job_complete: JobId=46427 WEXITSTATUS 0
[2022-07-17T03:58:22.159] _job_complete: JobId=46427 done
[2022-07-17T04:02:04.033] _slurm_rpc_submit_batch_job: JobId=46428 InitPrio=22425 usec=402
[2022-07-17T04:02:04.697] sched: Allocate JobId=46428 NodeList=cpu09 #CPUs=32 Partition=cpu-opteron
[2022-07-17T04:02:26.423] _job_complete: JobId=46428 WEXITSTATUS 0
[2022-07-17T04:02:26.424] _job_complete: JobId=46428 done
[2022-07-17T04:05:34.842] _slurm_rpc_submit_batch_job: JobId=46429 InitPrio=22425 usec=454
[2022-07-17T04:05:35.070] sched: Allocate JobId=46429 NodeList=cpu09 #CPUs=32 Partition=cpu-opteron
[2022-07-17T04:05:58.223] _job_complete: JobId=46429 WEXITSTATUS 0
[2022-07-17T04:05:58.223] _job_complete: JobId=46429 done
[2022-07-17T04:10:21.680] _slurm_rpc_submit_batch_job: JobId=46430 InitPrio=22425 usec=474
[2022-07-17T04:10:22.522] sched: Allocate JobId=46430 NodeList=cpu09 #CPUs=32 Partition=cpu-opteron
[2022-07-17T04:10:45.315] _job_complete: JobId=46430 WEXITSTATUS 0
[2022-07-17T04:10:45.316] _job_complete: JobId=46430 done
[2022-07-17T04:13:34.154] _slurm_rpc_submit_batch_job: JobId=46431 InitPrio=22425 usec=431
[2022-07-17T04:13:34.905] sched: Allocate JobId=46431 NodeList=cpu09 #CPUs=32 Partition=cpu-opteron
[2022-07-17T04:13:57.429] _job_complete: JobId=46431 WEXITSTATUS 0
[2022-07-17T04:13:57.429] _job_complete: JobId=46431 done
[2022-07-17T10:39:52.232] _slurm_rpc_submit_batch_job: JobId=46432 InitPrio=25651 usec=550
[2022-07-17T10:39:52.531] sched: Allocate JobId=46432 NodeList=cpu09 #CPUs=32 Partition=cpu-opteron
[2022-07-17T10:40:10.938] _job_complete: JobId=46432 WEXITSTATUS 0
[2022-07-17T10:40:10.939] _job_complete: JobId=46432 done
[2022-07-17T11:00:04.741] _slurm_rpc_submit_batch_job: JobId=46433 InitPrio=25651 usec=458
[2022-07-17T11:00:05.538] sched: Allocate JobId=46433 NodeList=cpu09 #CPUs=32 Partition=cpu-opteron
[2022-07-17T11:01:03.592] _job_complete: JobId=46433 WEXITSTATUS 0
[2022-07-17T11:01:03.592] _job_complete: JobId=46433 done
[2022-07-17T11:14:27.551] _slurm_rpc_submit_batch_job: JobId=46434 InitPrio=25651 usec=534
[2022-07-17T11:14:28.116] sched: Allocate JobId=46434 NodeList=cpu09 #CPUs=32 Partition=cpu-opteron
[2022-07-17T11:15:27.744] _job_complete: JobId=46434 WEXITSTATUS 0
[2022-07-17T11:15:27.744] _job_complete: JobId=46434 done
[2022-07-17T11:32:55.832] _slurm_rpc_submit_batch_job: JobId=46435 InitPrio=25651 usec=451
[2022-07-17T11:32:56.114] sched: Allocate JobId=46435 NodeList=cpu09 #CPUs=32 Partition=cpu-opteron
[2022-07-17T11:46:10.748] _slurm_rpc_submit_batch_job: JobId=46436 InitPrio=25651 usec=582
[2022-07-17T11:46:11.435] sched: Allocate JobId=46436 NodeList=cpu09 #CPUs=32 Partition=cpu-opteron
[2022-07-17T12:02:09.028] _slurm_rpc_submit_batch_job: JobId=46437 InitPrio=25651 usec=542
[2022-07-17T12:02:09.177] sched: Allocate JobId=46437 NodeList=cpu10 #CPUs=32 Partition=cpu-opteron
[2022-07-17T12:02:24.389] _job_complete: JobId=46437 WEXITSTATUS 0
[2022-07-17T12:02:24.389] _job_complete: JobId=46437 done
[2022-07-17T12:19:58.563] _slurm_rpc_submit_batch_job: JobId=46438 InitPrio=25651 usec=604
[2022-07-17T12:19:59.201] sched: Allocate JobId=46438 NodeList=cpu10 #CPUs=32 Partition=cpu-opteron
[2022-07-17T12:20:59.643] _job_complete: JobId=46438 WEXITSTATUS 0
[2022-07-17T12:20:59.643] _job_complete: JobId=46438 done
[2022-07-17T12:37:19.196] _slurm_rpc_submit_batch_job: JobId=46439 InitPrio=25651 usec=485
[2022-07-17T12:37:20.069] sched: Allocate JobId=46439 NodeList=cpu10 #CPUs=32 Partition=cpu-opteron
[2022-07-17T12:38:21.058] _job_complete: JobId=46439 WEXITSTATUS 0
[2022-07-17T12:38:21.058] _job_complete: JobId=46439 done
[2022-07-17T12:53:00.376] _slurm_rpc_submit_batch_job: JobId=46440 InitPrio=25651 usec=507
[2022-07-17T12:53:00.864] sched: Allocate JobId=46440 NodeList=cpu10 #CPUs=32 Partition=cpu-opteron
[2022-07-17T12:57:23.703] _job_complete: JobId=46435 WEXITSTATUS 0
[2022-07-17T12:57:23.703] _job_complete: JobId=46435 done
[2022-07-17T13:11:53.449] _job_complete: JobId=46436 WEXITSTATUS 0
[2022-07-17T13:11:53.450] _job_complete: JobId=46436 done
[2022-07-17T14:15:23.349] _job_complete: JobId=46440 WEXITSTATUS 0
[2022-07-17T14:15:23.349] _job_complete: JobId=46440 done
[2022-07-17T14:41:45.618] _slurm_rpc_submit_batch_job: JobId=46441 InitPrio=25382 usec=522
[2022-07-17T14:41:46.376] sched: Allocate JobId=46441 NodeList=cpu09 #CPUs=32 Partition=cpu-opteron
[2022-07-17T15:07:54.026] _slurm_rpc_submit_batch_job: JobId=46442 InitPrio=25382 usec=583
[2022-07-17T15:07:54.146] sched: Allocate JobId=46442 NodeList=cpu09 #CPUs=32 Partition=cpu-opteron
[2022-07-17T15:08:12.262] _job_complete: JobId=46442 WEXITSTATUS 0
[2022-07-17T15:08:12.262] _job_complete: JobId=46442 done
[2022-07-17T15:41:35.067] _slurm_rpc_submit_batch_job: JobId=46443 InitPrio=25382 usec=568
[2022-07-17T15:41:35.745] sched: Allocate JobId=46443 NodeList=cpu09 #CPUs=32 Partition=cpu-opteron
[2022-07-17T15:42:38.213] _job_complete: JobId=46443 WEXITSTATUS 0
[2022-07-17T15:42:38.213] _job_complete: JobId=46443 done
[2022-07-17T15:46:03.743] _slurm_rpc_submit_batch_job: JobId=46444 InitPrio=25382 usec=472
[2022-07-17T15:46:04.230] sched: Allocate JobId=46444 NodeList=cpu09 #CPUs=32 Partition=cpu-opteron
[2022-07-17T15:47:11.006] _job_complete: JobId=46444 WEXITSTATUS 0
[2022-07-17T15:47:11.006] _job_complete: JobId=46444 done
[2022-07-17T16:04:34.709] _slurm_rpc_submit_batch_job: JobId=46445 InitPrio=25382 usec=458
[2022-07-17T16:04:35.318] sched: Allocate JobId=46445 NodeList=cpu09 #CPUs=32 Partition=cpu-opteron
[2022-07-17T16:06:09.091] _job_complete: JobId=46441 WEXITSTATUS 0
[2022-07-17T16:06:09.091] _job_complete: JobId=46441 done
[2022-07-17T16:11:46.191] _job_complete: JobId=46445 WEXITSTATUS 1
[2022-07-17T16:11:46.191] _job_complete: JobId=46445 done
[2022-07-17T16:17:39.711] _slurm_rpc_submit_batch_job: JobId=46446 InitPrio=25382 usec=561
[2022-07-17T16:17:40.663] sched: Allocate JobId=46446 NodeList=cpu09 #CPUs=32 Partition=cpu-opteron
[2022-07-17T16:30:12.314] _slurm_rpc_kill_job: REQUEST_KILL_JOB JobId=46446 uid 548200084
[2022-07-17T16:58:23.691] _slurm_rpc_submit_batch_job: JobId=46447 InitPrio=25113 usec=619
[2022-07-17T16:58:23.910] sched: Allocate JobId=46447 NodeList=cpu09 #CPUs=32 Partition=cpu-opteron
[2022-07-17T16:58:46.597] _job_complete: JobId=46447 WEXITSTATUS 0
[2022-07-17T16:58:46.597] _job_complete: JobId=46447 done
[2022-07-17T18:34:01.884] _slurm_rpc_submit_batch_job: JobId=46448 InitPrio=25113 usec=516
[2022-07-17T18:34:01.978] sched: Allocate JobId=46448 NodeList=cpu09 #CPUs=32 Partition=cpu-opteron
[2022-07-17T18:34:19.147] _job_complete: JobId=46448 WEXITSTATUS 0
[2022-07-17T18:34:19.148] _job_complete: JobId=46448 done
[2022-07-17T18:51:31.850] _slurm_rpc_submit_batch_job: JobId=46449 InitPrio=25113 usec=446
[2022-07-17T18:51:33.761] sched: Allocate JobId=46449 NodeList=cpu09 #CPUs=32 Partition=cpu-opteron
[2022-07-17T18:51:49.071] _job_complete: JobId=46449 WEXITSTATUS 0
[2022-07-17T18:51:49.071] _job_complete: JobId=46449 done
[2022-07-17T22:31:14.068] _job_complete: JobId=46426 WEXITSTATUS 1
[2022-07-17T22:31:14.074] _job_complete: JobId=46426 done
[2022-07-17T22:44:45.309] _slurm_rpc_submit_batch_job: JobId=46450 InitPrio=19194 usec=629
[2022-07-17T22:44:46.121] sched: Allocate JobId=46450 NodeList=cpu09 #CPUs=64 Partition=cpu-opteron
[2022-07-17T23:27:59.607] _slurm_rpc_submit_batch_job: JobId=46451 InitPrio=25113 usec=522
[2022-07-17T23:27:59.788] sched: Allocate JobId=46451 NodeList=cpu10 #CPUs=32 Partition=cpu-opteron
[2022-07-17T23:28:04.522] _job_complete: JobId=46451 WEXITSTATUS 0
[2022-07-17T23:28:04.522] _job_complete: JobId=46451 done
[2022-07-17T23:46:54.765] _slurm_rpc_submit_batch_job: JobId=46452 InitPrio=25113 usec=454
[2022-07-17T23:46:55.703] sched: Allocate JobId=46452 NodeList=cpu10 #CPUs=32 Partition=cpu-opteron
[2022-07-17T23:47:05.710] _job_complete: JobId=46452 WEXITSTATUS 0
[2022-07-17T23:47:05.710] _job_complete: JobId=46452 done
[2022-07-18T00:12:04.966] _slurm_rpc_submit_batch_job: JobId=46453 InitPrio=25113 usec=571
[2022-07-18T00:12:05.505] sched: Allocate JobId=46453 NodeList=cpu10 #CPUs=32 Partition=cpu-opteron
[2022-07-18T00:12:47.888] _job_complete: JobId=46453 WEXITSTATUS 0
[2022-07-18T00:12:47.888] _job_complete: JobId=46453 done
[2022-07-18T00:32:24.585] _slurm_rpc_submit_batch_job: JobId=46454 InitPrio=25113 usec=496
[2022-07-18T00:32:24.746] sched: Allocate JobId=46454 NodeList=cpu10 #CPUs=32 Partition=cpu-opteron
[2022-07-18T00:33:06.369] _job_complete: JobId=46454 WEXITSTATUS 0
[2022-07-18T00:33:06.369] _job_complete: JobId=46454 done
[2022-07-18T00:51:07.820] _slurm_rpc_submit_batch_job: JobId=46455 InitPrio=25113 usec=538
[2022-07-18T00:51:08.789] sched: Allocate JobId=46455 NodeList=cpu10 #CPUs=32 Partition=cpu-opteron
[2022-07-18T01:40:01.778] _slurm_rpc_submit_batch_job: JobId=46456 InitPrio=25113 usec=698
[2022-07-18T01:40:02.590] sched: Allocate JobId=46456 NodeList=cpu10 #CPUs=32 Partition=cpu-opteron
[2022-07-18T01:40:05.361] _job_complete: JobId=46455 WEXITSTATUS 0
[2022-07-18T01:40:05.361] _job_complete: JobId=46455 done
[2022-07-18T02:29:46.880] _job_complete: JobId=46456 WEXITSTATUS 0
[2022-07-18T02:29:46.880] _job_complete: JobId=46456 done
[2022-07-18T03:52:42.907] _slurm_rpc_kill_job: REQUEST_KILL_JOB JobId=46401 uid 548200045
[2022-07-18T03:55:57.347] _slurm_rpc_submit_batch_job: JobId=46457 InitPrio=20274 usec=666
[2022-07-18T03:55:58.250] sched: Allocate JobId=46457 NodeList=gpu05 #CPUs=32 Partition=gpu-v100s
[2022-07-18T03:56:28.302] _slurm_rpc_kill_job: REQUEST_KILL_JOB JobId=46457 uid 548200045
[2022-07-18T03:57:18.724] _slurm_rpc_submit_batch_job: JobId=46458 InitPrio=20274 usec=412
[2022-07-18T03:57:19.345] sched: Allocate JobId=46458 NodeList=gpu05 #CPUs=32 Partition=gpu-v100s
[2022-07-18T05:49:55.353] _job_complete: JobId=46370 WEXITSTATUS 0
[2022-07-18T05:49:55.359] _job_complete: JobId=46370 done
[2022-07-18T08:06:45.029] _slurm_rpc_submit_batch_job: JobId=46459 InitPrio=25113 usec=668
[2022-07-18T08:06:46.013] sched: Allocate JobId=46459 NodeList=cpu03 #CPUs=32 Partition=cpu-opteron
[2022-07-18T08:06:56.866] _job_complete: JobId=46459 WEXITSTATUS 0
[2022-07-18T08:06:56.866] _job_complete: JobId=46459 done
[2022-07-18T08:15:39.004] _slurm_rpc_kill_job: REQUEST_KILL_JOB JobId=46403 uid 548200017
[2022-07-18T08:15:46.601] _slurm_rpc_submit_batch_job: JobId=46460 InitPrio=19331 usec=487
[2022-07-18T08:15:46.930] sched: Allocate JobId=46460 NodeList=cpu13 #CPUs=48 Partition=cpu-epyc
[2022-07-18T08:18:54.945] _slurm_rpc_submit_batch_job: JobId=46461 InitPrio=25113 usec=490
[2022-07-18T08:18:55.367] sched: Allocate JobId=46461 NodeList=cpu03 #CPUs=32 Partition=cpu-opteron
[2022-07-18T08:19:38.126] _job_complete: JobId=46461 WEXITSTATUS 0
[2022-07-18T08:19:38.126] _job_complete: JobId=46461 done
[2022-07-18T08:30:20.549] _slurm_rpc_submit_batch_job: JobId=46462 InitPrio=25113 usec=448
[2022-07-18T08:30:20.556] sched: Allocate JobId=46462 NodeList=cpu03 #CPUs=32 Partition=cpu-opteron
[2022-07-18T08:31:01.669] _job_complete: JobId=46462 WEXITSTATUS 0
[2022-07-18T08:31:01.670] _job_complete: JobId=46462 done
[2022-07-18T08:39:25.502] _slurm_rpc_submit_batch_job: JobId=46463 InitPrio=25113 usec=472
[2022-07-18T08:39:25.528] sched: Allocate JobId=46463 NodeList=cpu03 #CPUs=32 Partition=cpu-opteron
[2022-07-18T08:39:30.521] _job_complete: JobId=46463 WEXITSTATUS 1
[2022-07-18T08:39:30.521] _job_complete: JobId=46463 done
[2022-07-18T08:39:58.925] _slurm_rpc_submit_batch_job: JobId=46464 InitPrio=25113 usec=365
[2022-07-18T08:39:59.576] sched: Allocate JobId=46464 NodeList=cpu03 #CPUs=32 Partition=cpu-opteron
[2022-07-18T08:40:04.449] _job_complete: JobId=46464 WEXITSTATUS 1
[2022-07-18T08:40:04.449] _job_complete: JobId=46464 done
[2022-07-18T08:46:58.404] _slurm_rpc_submit_batch_job: JobId=46465 InitPrio=25113 usec=525
[2022-07-18T08:46:59.391] sched: Allocate JobId=46465 NodeList=cpu03 #CPUs=32 Partition=cpu-opteron
[2022-07-18T08:55:52.145] _slurm_rpc_submit_batch_job: JobId=46466 InitPrio=25113 usec=487
[2022-07-18T08:55:52.323] sched: Allocate JobId=46466 NodeList=cpu03 #CPUs=32 Partition=cpu-opteron
[2022-07-18T09:16:31.701] _slurm_rpc_submit_batch_job: JobId=46467 InitPrio=25113 usec=471
[2022-07-18T09:16:31.744] sched: Allocate JobId=46467 NodeList=cpu10 #CPUs=32 Partition=cpu-opteron
[2022-07-18T09:16:41.800] _job_complete: JobId=46467 WEXITSTATUS 0
[2022-07-18T09:16:41.801] _job_complete: JobId=46467 done
[2022-07-18T09:30:25.837] _slurm_rpc_submit_batch_job: JobId=46468 InitPrio=25113 usec=574
[2022-07-18T09:30:26.328] sched: Allocate JobId=46468 NodeList=cpu10 #CPUs=32 Partition=cpu-opteron
[2022-07-18T09:31:09.010] _job_complete: JobId=46468 WEXITSTATUS 0
[2022-07-18T09:31:09.010] _job_complete: JobId=46468 done
[2022-07-18T09:37:14.144] _job_complete: JobId=46465 WEXITSTATUS 0
[2022-07-18T09:37:14.144] _job_complete: JobId=46465 done
[2022-07-18T09:39:56.460] _slurm_rpc_submit_batch_job: JobId=46469 InitPrio=25113 usec=465
[2022-07-18T09:39:56.518] sched: Allocate JobId=46469 NodeList=cpu03 #CPUs=32 Partition=cpu-opteron
[2022-07-18T09:40:39.935] _job_complete: JobId=46469 WEXITSTATUS 0
[2022-07-18T09:40:39.935] _job_complete: JobId=46469 done
[2022-07-18T09:47:33.189] _job_complete: JobId=46466 WEXITSTATUS 0
[2022-07-18T09:47:33.189] _job_complete: JobId=46466 done
[2022-07-18T09:50:21.254] _slurm_rpc_submit_batch_job: JobId=46470 InitPrio=25113 usec=444
[2022-07-18T09:50:21.679] sched: Allocate JobId=46470 NodeList=cpu03 #CPUs=32 Partition=cpu-opteron
[2022-07-18T09:54:03.011] _slurm_rpc_submit_batch_job: JobId=46471 InitPrio=23437 usec=515
[2022-07-18T09:54:03.265] sched: Allocate JobId=46471 NodeList=cpu15 #CPUs=8 Partition=cpu-epyc
[2022-07-18T09:55:07.567] _slurm_rpc_kill_job: REQUEST_KILL_JOB JobId=46471 uid 548200036
[2022-07-18T09:55:58.183] _slurm_rpc_submit_batch_job: JobId=46472 InitPrio=23437 usec=439
[2022-07-18T09:55:58.408] sched: Allocate JobId=46472 NodeList=cpu15 #CPUs=8 Partition=cpu-epyc
[2022-07-18T09:56:21.879] _slurm_rpc_submit_batch_job: JobId=46473 InitPrio=23437 usec=466
[2022-07-18T09:56:22.443] sched: Allocate JobId=46473 NodeList=cpu12 #CPUs=8 Partition=cpu-epyc
[2022-07-18T09:56:57.436] _slurm_rpc_kill_job: REQUEST_KILL_JOB JobId=46473 uid 548200036
[2022-07-18T09:57:06.320] _slurm_rpc_submit_batch_job: JobId=46474 InitPrio=23437 usec=509
[2022-07-18T09:57:06.505] sched: Allocate JobId=46474 NodeList=cpu12 #CPUs=8 Partition=cpu-epyc
[2022-07-18T09:57:08.567] _job_complete: JobId=46474 WEXITSTATUS 1
[2022-07-18T09:57:08.567] _job_complete: JobId=46474 done
[2022-07-18T09:58:09.279] _slurm_rpc_submit_batch_job: JobId=46475 InitPrio=23437 usec=411
[2022-07-18T09:58:09.623] sched/backfill: _start_job: Started JobId=46475 in cpu-epyc on cpu12
[2022-07-18T09:58:33.567] _slurm_rpc_submit_batch_job: JobId=46476 InitPrio=25113 usec=478
[2022-07-18T09:58:35.865] sched: Allocate JobId=46476 NodeList=cpu03 #CPUs=32 Partition=cpu-opteron
[2022-07-18T10:00:01.435] _slurm_rpc_submit_batch_job: JobId=46477 InitPrio=23403 usec=478
[2022-07-18T10:00:01.986] sched: Allocate JobId=46477 NodeList=cpu10 #CPUs=12 Partition=cpu-opteron
[2022-07-18T10:00:12.875] _job_complete: JobId=46477 WEXITSTATUS 1
[2022-07-18T10:00:12.875] _job_complete: JobId=46477 done
[2022-07-18T10:01:29.185] _slurm_rpc_submit_batch_job: JobId=46478 InitPrio=23403 usec=417
[2022-07-18T10:01:30.108] sched: Allocate JobId=46478 NodeList=cpu10 #CPUs=12 Partition=cpu-opteron
[2022-07-18T10:01:38.876] _job_complete: JobId=46478 WEXITSTATUS 1
[2022-07-18T10:01:38.877] _job_complete: JobId=46478 done
[2022-07-18T10:07:50.703] _slurm_rpc_submit_batch_job: JobId=46479 InitPrio=23437 usec=542
[2022-07-18T10:07:50.908] sched: Allocate JobId=46479 NodeList=cpu12 #CPUs=8 Partition=cpu-epyc
[2022-07-18T10:07:56.379] _job_complete: JobId=46479 WEXITSTATUS 1
[2022-07-18T10:07:56.379] _job_complete: JobId=46479 done
[2022-07-18T10:09:03.191] _slurm_rpc_submit_batch_job: JobId=46480 InitPrio=23437 usec=533
[2022-07-18T10:09:04.008] sched: Allocate JobId=46480 NodeList=cpu12 #CPUs=8 Partition=cpu-epyc
[2022-07-18T10:09:09.239] _job_complete: JobId=46480 WEXITSTATUS 1
[2022-07-18T10:09:09.239] _job_complete: JobId=46480 done
[2022-07-18T10:17:30.200] _slurm_rpc_submit_batch_job: JobId=46481 InitPrio=23437 usec=540
[2022-07-18T10:17:30.968] sched: Allocate JobId=46481 NodeList=cpu12 #CPUs=8 Partition=cpu-epyc
[2022-07-18T10:17:36.373] _job_complete: JobId=46481 WEXITSTATUS 1
[2022-07-18T10:17:36.373] _job_complete: JobId=46481 done
[2022-07-18T10:23:33.014] _slurm_rpc_submit_batch_job: JobId=46482 InitPrio=23437 usec=505
[2022-07-18T10:23:35.615] sched: Allocate JobId=46482 NodeList=cpu12 #CPUs=8 Partition=cpu-epyc
[2022-07-18T10:23:40.886] _job_complete: JobId=46482 WEXITSTATUS 1
[2022-07-18T10:23:40.886] _job_complete: JobId=46482 done
[2022-07-18T10:25:31.509] _slurm_rpc_submit_batch_job: JobId=46483 InitPrio=23437 usec=452
[2022-07-18T10:25:31.778] sched: Allocate JobId=46483 NodeList=cpu12 #CPUs=8 Partition=cpu-epyc
[2022-07-18T10:25:37.122] _job_complete: JobId=46483 WEXITSTATUS 1
[2022-07-18T10:25:37.122] _job_complete: JobId=46483 done
[2022-07-18T10:26:25.950] _slurm_rpc_submit_batch_job: JobId=46484 InitPrio=23437 usec=461
[2022-07-18T10:26:26.853] sched: Allocate JobId=46484 NodeList=cpu12 #CPUs=8 Partition=cpu-epyc
[2022-07-18T10:26:27.355] _job_complete: JobId=46484 WEXITSTATUS 1
[2022-07-18T10:26:27.356] _job_complete: JobId=46484 done
[2022-07-18T10:26:53.850] _slurm_rpc_submit_batch_job: JobId=46485 InitPrio=23437 usec=519
[2022-07-18T10:26:53.890] sched: Allocate JobId=46485 NodeList=cpu12 #CPUs=8 Partition=cpu-epyc
[2022-07-18T10:34:35.299] _slurm_rpc_submit_batch_job: JobId=46486 InitPrio=23437 usec=434
[2022-07-18T10:35:49.630] _slurm_rpc_submit_batch_job: JobId=46487 InitPrio=23471 usec=400
[2022-07-18T10:35:49.827] sched: Allocate JobId=46487 NodeList=cpu15 #CPUs=4 Partition=cpu-epyc
[2022-07-18T10:36:06.659] _slurm_rpc_kill_job: REQUEST_KILL_JOB JobId=46486 uid 548200036
[2022-07-18T10:40:30.077] _job_complete: JobId=46470 WEXITSTATUS 0
[2022-07-18T10:40:30.078] _job_complete: JobId=46470 done
[2022-07-18T10:50:42.873] _job_complete: JobId=46476 WEXITSTATUS 0
[2022-07-18T10:50:42.874] _job_complete: JobId=46476 done
[2022-07-18T10:56:27.135] Time limit exhausted for JobId=46472
[2022-07-18T10:58:27.427] Time limit exhausted for JobId=46475
[2022-07-18T11:06:05.440] _slurm_rpc_submit_batch_job: JobId=46488 InitPrio=23231 usec=505
[2022-07-18T11:06:25.614] _slurm_rpc_kill_job: REQUEST_KILL_JOB JobId=46488 uid 548200036
[2022-07-18T11:06:58.250] _slurm_rpc_submit_batch_job: JobId=46489 InitPrio=15474 usec=358
[2022-07-18T11:07:24.121] _slurm_rpc_submit_batch_job: JobId=46490 InitPrio=23231 usec=478
[2022-07-18T11:07:24.286] sched: Allocate JobId=46490 NodeList=cpu03 #CPUs=32 Partition=cpu-opteron
[2022-07-18T11:08:28.530] _slurm_rpc_submit_batch_job: JobId=46491 InitPrio=23368 usec=390
[2022-07-18T11:08:29.473] sched: Allocate JobId=46491 NodeList=cpu03 #CPUs=16 Partition=cpu-opteron
[2022-07-18T11:08:48.548] _slurm_rpc_kill_job: REQUEST_KILL_JOB JobId=46489 uid 548200036
[2022-07-18T11:08:56.906] _slurm_rpc_kill_job: REQUEST_KILL_JOB JobId=46491 uid 548200036
[2022-07-18T11:11:53.906] _slurm_rpc_submit_batch_job: JobId=46492 InitPrio=23368 usec=486
[2022-07-18T11:11:54.758] sched: Allocate JobId=46492 NodeList=cpu03 #CPUs=16 Partition=cpu-opteron
[2022-07-18T11:26:57.613] Time limit exhausted for JobId=46485
[2022-07-18T11:35:57.138] Time limit exhausted for JobId=46487
[2022-07-18T11:41:09.698] _slurm_rpc_submit_batch_job: JobId=46493 InitPrio=22293 usec=886
[2022-07-18T11:41:09.720] sched: Allocate JobId=46493 NodeList=gpu01 #CPUs=16 Partition=gpu-k10
[2022-07-18T13:54:54.810] _slurm_rpc_submit_batch_job: JobId=46494 InitPrio=20680 usec=605
[2022-07-18T13:54:55.116] sched: Allocate JobId=46494 NodeList=cpu12 #CPUs=16 Partition=cpu-epyc
[2022-07-18T14:21:08.438] _slurm_rpc_submit_batch_job: JobId=46495 InitPrio=20715 usec=644
[2022-07-18T14:21:08.816] sched: Allocate JobId=46495 NodeList=cpu15 #CPUs=12 Partition=cpu-epyc
[2022-07-18T14:38:31.549] _slurm_rpc_submit_batch_job: JobId=46496 InitPrio=20543 usec=527
[2022-07-18T14:38:31.953] sched: Allocate JobId=46496 NodeList=cpu10 #CPUs=32 Partition=cpu-opteron
[2022-07-18T15:30:38.470] _slurm_rpc_submit_batch_job: JobId=46497 InitPrio=20680 usec=629
[2022-07-18T15:30:39.421] sched: Allocate JobId=46497 NodeList=cpu03 #CPUs=16 Partition=cpu-opteron
[2022-07-18T15:50:14.160] _slurm_rpc_submit_batch_job: JobId=46498 InitPrio=20543 usec=721
[2022-07-18T15:50:14.511] sched: Allocate JobId=46498 NodeList=cpu10 #CPUs=32 Partition=cpu-opteron
[2022-07-18T15:51:49.486] _job_complete: JobId=46493 WEXITSTATUS 1
[2022-07-18T15:51:49.491] _job_complete: JobId=46493 done
[2022-07-18T15:52:34.420] _slurm_rpc_submit_batch_job: JobId=46499 InitPrio=20680 usec=425
[2022-07-18T15:52:35.791] sched: Allocate JobId=46499 NodeList=cpu04 #CPUs=16 Partition=cpu-opteron
[2022-07-18T16:13:37.110] _slurm_rpc_submit_batch_job: JobId=46500 InitPrio=20143 usec=483
[2022-07-18T16:38:43.095] _slurm_rpc_submit_batch_job: JobId=46501 InitPrio=24844 usec=540
[2022-07-18T17:40:01.266] _slurm_rpc_kill_job: REQUEST_KILL_JOB JobId=46211 uid 548200036
[2022-07-18T17:42:06.189] _slurm_rpc_submit_batch_job: JobId=46502 InitPrio=17613 usec=605
[2022-07-18T17:43:23.911] _slurm_rpc_submit_batch_job: JobId=46503 InitPrio=23368 usec=480
[2022-07-18T17:44:01.359] _slurm_rpc_submit_batch_job: JobId=46504 InitPrio=23368 usec=403
[2022-07-18T17:44:30.856] _slurm_rpc_kill_job: REQUEST_KILL_JOB JobId=46504 uid 548200036
[2022-07-18T17:44:30.856] _slurm_rpc_kill_job: REQUEST_KILL_JOB JobId=46502 uid 548200036
[2022-07-18T17:44:30.856] _slurm_rpc_kill_job: REQUEST_KILL_JOB JobId=46503 uid 548200036
[2022-07-18T17:45:28.239] _slurm_rpc_submit_batch_job: JobId=46505 InitPrio=23368 usec=402
[2022-07-18T17:46:50.216] _slurm_rpc_kill_job: REQUEST_KILL_JOB JobId=46506 uid 548200036
[2022-07-18T17:46:50.216] job_str_signal(3): invalid JobId=46506
[2022-07-18T17:46:50.216] _slurm_rpc_kill_job: job_str_signal() uid=548200036 JobId=46506 sig=9 returned: Invalid job id specified
[2022-07-18T17:46:58.833] _slurm_rpc_submit_batch_job: JobId=46506 InitPrio=23368 usec=425
[2022-07-18T17:46:59.828] sched: Allocate JobId=46506 NodeList=cpu04 #CPUs=16 Partition=cpu-opteron
[2022-07-18T17:47:16.528] _slurm_rpc_kill_job: REQUEST_KILL_JOB JobId=46505 uid 548200036
[2022-07-18T18:02:45.265] _slurm_rpc_submit_batch_job: JobId=46507 InitPrio=23368 usec=474
[2022-07-18T18:04:21.751] _slurm_rpc_submit_batch_job: JobId=46508 InitPrio=23368 usec=468
[2022-07-18T18:05:07.075] _slurm_rpc_submit_batch_job: JobId=46509 InitPrio=23368 usec=432
[2022-07-18T18:08:23.919] _slurm_rpc_submit_batch_job: JobId=46510 InitPrio=23368 usec=441
[2022-07-18T18:08:55.676] _slurm_rpc_kill_job: REQUEST_KILL_JOB JobId=46510 uid 548200036
[2022-07-18T18:09:17.481] _slurm_rpc_submit_batch_job: JobId=46511 InitPrio=23368 usec=432
[2022-07-18T18:40:37.595] _job_complete: JobId=46506 WEXITSTATUS 0
[2022-07-18T18:40:37.595] _job_complete: JobId=46506 done
[2022-07-18T20:09:54.341] _slurm_rpc_submit_batch_job: JobId=46512 InitPrio=23368 usec=457
[2022-07-18T20:09:54.557] sched: Allocate JobId=46512 NodeList=cpu04 #CPUs=16 Partition=cpu-opteron
[2022-07-18T20:09:55.307] _job_complete: JobId=46512 WEXITSTATUS 1
[2022-07-18T20:09:55.307] _job_complete: JobId=46512 done
[2022-07-18T20:10:25.269] _slurm_rpc_submit_batch_job: JobId=46513 InitPrio=23368 usec=434
[2022-07-18T20:10:25.586] sched: Allocate JobId=46513 NodeList=cpu04 #CPUs=16 Partition=cpu-opteron
[2022-07-18T20:10:26.416] _job_complete: JobId=46513 WEXITSTATUS 1
[2022-07-18T20:10:26.416] _job_complete: JobId=46513 done
[2022-07-18T20:12:03.999] _slurm_rpc_submit_batch_job: JobId=46514 InitPrio=23368 usec=495
[2022-07-18T20:12:04.724] sched: Allocate JobId=46514 NodeList=cpu04 #CPUs=16 Partition=cpu-opteron
[2022-07-18T20:12:42.307] _slurm_rpc_kill_job: REQUEST_KILL_JOB JobId=46511 uid 548200036
[2022-07-18T20:13:24.904] _slurm_rpc_submit_batch_job: JobId=46515 InitPrio=23368 usec=435
[2022-07-18T20:13:48.523] _slurm_rpc_kill_job: REQUEST_KILL_JOB JobId=46508 uid 548200036
[2022-07-18T20:36:48.023] _job_complete: JobId=46514 WEXITSTATUS 0
[2022-07-18T20:36:48.023] _job_complete: JobId=46514 done
[2022-07-18T20:36:48.453] sched: Allocate JobId=46515 NodeList=cpu04 #CPUs=16 Partition=cpu-opteron
[2022-07-18T20:37:08.808] _job_complete: JobId=46515 WEXITSTATUS 1
[2022-07-18T20:37:08.808] _job_complete: JobId=46515 done
[2022-07-18T21:22:45.017] _slurm_rpc_submit_batch_job: JobId=46516 InitPrio=23368 usec=578
[2022-07-18T21:22:45.236] sched: Allocate JobId=46516 NodeList=cpu04 #CPUs=16 Partition=cpu-opteron
[2022-07-18T21:22:59.426] _job_complete: JobId=46516 WEXITSTATUS 1
[2022-07-18T21:22:59.427] _job_complete: JobId=46516 done
[2022-07-18T21:28:14.213] _slurm_rpc_submit_batch_job: JobId=46517 InitPrio=23368 usec=458
[2022-07-18T21:28:14.811] sched: Allocate JobId=46517 NodeList=cpu04 #CPUs=16 Partition=cpu-opteron
[2022-07-18T21:28:35.746] _job_complete: JobId=46517 WEXITSTATUS 1
[2022-07-18T21:28:35.747] _job_complete: JobId=46517 done
[2022-07-18T21:33:41.110] _slurm_rpc_submit_batch_job: JobId=46518 InitPrio=23368 usec=519
[2022-07-18T21:33:41.385] sched: Allocate JobId=46518 NodeList=cpu04 #CPUs=16 Partition=cpu-opteron
[2022-07-18T21:34:06.272] _slurm_rpc_kill_job: REQUEST_KILL_JOB JobId=46509 uid 548200036
[2022-07-18T21:49:53.365] _slurm_rpc_submit_batch_job: JobId=46519 InitPrio=23368 usec=444
[2022-07-18T21:58:53.126] _job_complete: JobId=46518 WEXITSTATUS 0
[2022-07-18T21:58:53.126] _job_complete: JobId=46518 done
[2022-07-18T21:58:53.539] sched: Allocate JobId=46519 NodeList=cpu04 #CPUs=16 Partition=cpu-opteron
[2022-07-18T21:59:08.458] _job_complete: JobId=46519 WEXITSTATUS 1
[2022-07-18T21:59:08.458] _job_complete: JobId=46519 done
[2022-07-18T22:04:05.797] _slurm_rpc_submit_batch_job: JobId=46520 InitPrio=23368 usec=397
[2022-07-18T22:04:06.576] sched: Allocate JobId=46520 NodeList=cpu04 #CPUs=16 Partition=cpu-opteron
[2022-07-18T22:04:25.430] _job_complete: JobId=46520 WEXITSTATUS 1
[2022-07-18T22:04:25.431] _job_complete: JobId=46520 done
[2022-07-18T22:04:25.749] _slurm_rpc_kill_job: REQUEST_KILL_JOB JobId=46507 uid 548200036
[2022-07-18T22:05:26.681] _slurm_rpc_submit_batch_job: JobId=46521 InitPrio=23368 usec=429
[2022-07-18T22:05:26.686] sched: Allocate JobId=46521 NodeList=cpu04 #CPUs=16 Partition=cpu-opteron
[2022-07-18T22:29:27.343] _job_complete: JobId=46521 WEXITSTATUS 0
[2022-07-18T22:29:27.343] _job_complete: JobId=46521 done
[2022-07-19T01:05:00.567] _slurm_rpc_submit_batch_job: JobId=46522 InitPrio=23368 usec=533
[2022-07-19T01:05:00.941] sched: Allocate JobId=46522 NodeList=cpu04 #CPUs=16 Partition=cpu-opteron
[2022-07-19T01:06:58.807] _slurm_rpc_submit_batch_job: JobId=46523 InitPrio=23368 usec=429
[2022-07-19T01:29:44.728] _job_complete: JobId=46522 WEXITSTATUS 0
[2022-07-19T01:29:44.728] _job_complete: JobId=46522 done
[2022-07-19T01:29:45.239] sched: Allocate JobId=46523 NodeList=cpu04 #CPUs=16 Partition=cpu-opteron
[2022-07-19T01:29:59.531] _job_complete: JobId=46523 WEXITSTATUS 1
[2022-07-19T01:29:59.531] _job_complete: JobId=46523 done
[2022-07-19T08:34:44.633] _slurm_rpc_submit_batch_job: JobId=46524 InitPrio=23368 usec=525
[2022-07-19T08:34:45.297] sched: Allocate JobId=46524 NodeList=cpu04 #CPUs=16 Partition=cpu-opteron
[2022-07-19T08:34:59.951] _job_complete: JobId=46524 WEXITSTATUS 1
[2022-07-19T08:34:59.952] _job_complete: JobId=46524 done
[2022-07-19T08:43:06.133] _slurm_rpc_submit_batch_job: JobId=46525 InitPrio=23368 usec=484
[2022-07-19T08:43:06.259] sched: Allocate JobId=46525 NodeList=cpu04 #CPUs=16 Partition=cpu-opteron
[2022-07-19T09:12:49.266] _job_complete: JobId=46525 WEXITSTATUS 0
[2022-07-19T09:12:49.266] _job_complete: JobId=46525 done
[2022-07-19T09:24:36.872] _slurm_rpc_submit_batch_job: JobId=46526 InitPrio=25050 usec=456
[2022-07-19T09:24:37.576] sched: Allocate JobId=46526 NodeList=cpu04 #CPUs=8 Partition=cpu-opteron
[2022-07-19T09:24:41.722] _job_complete: JobId=46526 WEXITSTATUS 0
[2022-07-19T09:24:41.722] _job_complete: JobId=46526 done
[2022-07-19T09:51:26.548] _slurm_rpc_submit_batch_job: JobId=46527 InitPrio=25050 usec=422
[2022-07-19T09:51:27.546] sched: Allocate JobId=46527 NodeList=cpu04 #CPUs=8 Partition=cpu-opteron
[2022-07-19T09:51:31.554] _job_complete: JobId=46527 WEXITSTATUS 0
[2022-07-19T09:51:31.554] _job_complete: JobId=46527 done
[2022-07-19T10:06:54.451] _slurm_rpc_submit_batch_job: JobId=46528 InitPrio=25050 usec=458
[2022-07-19T10:06:55.358] sched: Allocate JobId=46528 NodeList=cpu04 #CPUs=8 Partition=cpu-opteron
[2022-07-19T10:06:59.336] _job_complete: JobId=46528 WEXITSTATUS 0
[2022-07-19T10:06:59.336] _job_complete: JobId=46528 done
[2022-07-19T10:24:55.471] _slurm_rpc_submit_batch_job: JobId=46529 InitPrio=20949 usec=438
[2022-07-19T10:27:08.224] _job_complete: JobId=45800 WEXITSTATUS 0
[2022-07-19T10:27:08.224] _job_complete: JobId=45800 done
[2022-07-19T10:27:09.241] sched: Allocate JobId=46501 NodeList=cpu04 #CPUs=32 Partition=cpu-opteron
[2022-07-19T10:27:12.225] _job_complete: JobId=46501 WEXITSTATUS 1
[2022-07-19T10:27:12.225] _job_complete: JobId=46501 done
[2022-07-19T10:50:28.006] sched: _slurm_rpc_allocate_resources JobId=46530 NodeList=cpu04 usec=14922
[2022-07-19T11:37:06.596] _job_complete: JobId=46530 WEXITSTATUS 0
[2022-07-19T11:37:06.596] _job_complete: JobId=46530 done
[2022-07-19T12:48:07.439] _slurm_rpc_submit_batch_job: JobId=46531 InitPrio=22024 usec=1143
[2022-07-19T12:48:07.898] sched: Allocate JobId=46531 NodeList=gpu01 #CPUs=16 Partition=gpu-k10
[2022-07-19T12:50:04.628] _slurm_rpc_submit_batch_job: JobId=46532 InitPrio=25050 usec=506
[2022-07-19T12:50:05.067] sched: Allocate JobId=46532 NodeList=cpu04 #CPUs=8 Partition=cpu-opteron
[2022-07-19T12:50:09.703] _job_complete: JobId=46532 WEXITSTATUS 0
[2022-07-19T12:50:09.703] _job_complete: JobId=46532 done
[2022-07-19T13:12:39.067] sched: _slurm_rpc_allocate_resources JobId=46533 NodeList=cpu04 usec=15050
[2022-07-19T13:17:34.633] _slurm_rpc_submit_batch_job: JobId=46534 InitPrio=21887 usec=398
[2022-07-19T13:17:36.246] sched: Allocate JobId=46534 NodeList=cpu04 #CPUs=32 Partition=cpu-opteron
[2022-07-19T13:17:40.038] _job_complete: JobId=46534 WEXITSTATUS 1
[2022-07-19T13:17:40.038] _job_complete: JobId=46534 done
[2022-07-19T13:19:58.241] _slurm_rpc_submit_batch_job: JobId=46535 InitPrio=22024 usec=332
[2022-07-19T13:19:58.486] sched: Allocate JobId=46535 NodeList=cpu04 #CPUs=16 Partition=cpu-opteron
[2022-07-19T13:25:57.286] _slurm_rpc_submit_batch_job: JobId=46536 InitPrio=21887 usec=659
[2022-07-19T13:26:02.097] job_step_signal: JobId=46533 StepId=0 not found
[2022-07-19T13:26:02.099] _job_complete: JobId=46533 WTERMSIG 126
[2022-07-19T13:26:02.099] _job_complete: JobId=46533 cancelled by interactive user
[2022-07-19T13:26:02.099] _job_complete: JobId=46533 done
[2022-07-19T13:26:02.633] sched: Allocate JobId=46536 NodeList=cpu04 #CPUs=32 Partition=cpu-opteron
[2022-07-19T13:26:09.491] _job_complete: JobId=46536 WEXITSTATUS 0
[2022-07-19T13:26:09.492] _job_complete: JobId=46536 done
[2022-07-19T13:26:30.672] sched: _slurm_rpc_allocate_resources JobId=46537 NodeList=cpu04 usec=4417
[2022-07-19T13:36:20.556] _job_complete: JobId=46535 WEXITSTATUS 0
[2022-07-19T13:36:20.556] _job_complete: JobId=46535 done
[2022-07-19T13:46:18.312] _slurm_rpc_submit_batch_job: JobId=46538 InitPrio=25050 usec=451
[2022-07-19T13:46:19.307] sched: Allocate JobId=46538 NodeList=cpu04 #CPUs=8 Partition=cpu-opteron
[2022-07-19T13:46:23.285] _job_complete: JobId=46538 WEXITSTATUS 0
[2022-07-19T13:46:23.285] _job_complete: JobId=46538 done
[2022-07-19T13:54:58.247] Time limit exhausted for JobId=46494
[2022-07-19T14:21:28.656] Time limit exhausted for JobId=46495
[2022-07-19T14:38:58.541] Time limit exhausted for JobId=46496
[2022-07-19T15:19:54.330] _job_complete: JobId=46402 WEXITSTATUS 0
[2022-07-19T15:19:54.335] _job_complete: JobId=46402 done
[2022-07-19T15:24:18.168] _slurm_rpc_submit_batch_job: JobId=46539 InitPrio=21887 usec=430
[2022-07-19T15:24:18.516] sched: Allocate JobId=46539 NodeList=cpu10 #CPUs=32 Partition=cpu-opteron
[2022-07-19T15:24:20.987] _job_complete: JobId=46539 WEXITSTATUS 1
[2022-07-19T15:24:20.987] _job_complete: JobId=46539 done
[2022-07-19T15:26:58.854] _slurm_rpc_submit_batch_job: JobId=46540 InitPrio=22024 usec=419
[2022-07-19T15:26:59.722] sched: Allocate JobId=46540 NodeList=cpu10 #CPUs=16 Partition=cpu-opteron
[2022-07-19T15:28:12.564] _slurm_rpc_submit_batch_job: JobId=46541 InitPrio=21887 usec=405
[2022-07-19T15:28:12.968] sched: Allocate JobId=46541 NodeList=cpu04 #CPUs=32 Partition=cpu-opteron
[2022-07-19T15:28:17.730] _job_complete: JobId=46541 WEXITSTATUS 0
[2022-07-19T15:28:17.731] _job_complete: JobId=46541 done
[2022-07-19T15:30:58.192] Time limit exhausted for JobId=46497
[2022-07-19T15:34:28.770] _job_complete: JobId=46540 WEXITSTATUS 0
[2022-07-19T15:34:28.770] _job_complete: JobId=46540 done
[2022-07-19T15:42:33.129] _slurm_rpc_submit_batch_job: JobId=46542 InitPrio=21887 usec=367
[2022-07-19T15:42:33.401] sched: Allocate JobId=46542 NodeList=cpu10 #CPUs=32 Partition=cpu-opteron
[2022-07-19T15:42:37.984] _job_complete: JobId=46542 WEXITSTATUS 0
[2022-07-19T15:42:37.985] _job_complete: JobId=46542 done
[2022-07-19T15:50:28.191] Time limit exhausted for JobId=46498
[2022-07-19T15:52:58.523] Time limit exhausted for JobId=46499
[2022-07-19T16:06:47.695] _job_complete: JobId=46371 WEXITSTATUS 0
[2022-07-19T16:06:47.696] _job_complete: JobId=46371 done
[2022-07-19T16:46:43.460] _slurm_rpc_submit_batch_job: JobId=46543 InitPrio=22562 usec=463
[2022-07-19T16:46:44.128] sched: Allocate JobId=46543 NodeList=cpu12 #CPUs=16 Partition=cpu-epyc
[2022-07-19T16:51:08.732] _slurm_rpc_submit_batch_job: JobId=46544 InitPrio=22562 usec=396
[2022-07-19T16:51:09.631] sched: Allocate JobId=46544 NodeList=cpu14 #CPUs=16 Partition=cpu-epyc
[2022-07-19T17:19:48.703] _slurm_rpc_submit_batch_job: JobId=46545 InitPrio=24913 usec=439
[2022-07-19T17:19:48.782] sched: Allocate JobId=46545 NodeList=cpu04 #CPUs=24 Partition=cpu-opteron
[2022-07-19T17:19:49.463] _job_complete: JobId=46545 WEXITSTATUS 1
[2022-07-19T17:19:49.463] _job_complete: JobId=46545 done
[2022-07-19T17:21:11.735] _slurm_rpc_submit_batch_job: JobId=46546 InitPrio=24913 usec=529
[2022-07-19T17:21:11.885] sched: Allocate JobId=46546 NodeList=cpu04 #CPUs=24 Partition=cpu-opteron
[2022-07-19T17:21:14.977] _job_complete: JobId=46546 WEXITSTATUS 1
[2022-07-19T17:21:14.977] _job_complete: JobId=46546 done
[2022-07-19T17:25:09.599] _slurm_rpc_submit_batch_job: JobId=46547 InitPrio=24913 usec=432
[2022-07-19T17:25:10.311] sched: Allocate JobId=46547 NodeList=cpu04 #CPUs=24 Partition=cpu-opteron
[2022-07-19T17:25:13.186] _job_complete: JobId=46547 WEXITSTATUS 1
[2022-07-19T17:25:13.186] _job_complete: JobId=46547 done
[2022-07-19T17:27:37.990] _slurm_rpc_submit_batch_job: JobId=46548 InitPrio=24913 usec=665
[2022-07-19T17:27:38.580] sched: Allocate JobId=46548 NodeList=cpu04 #CPUs=24 Partition=cpu-opteron
[2022-07-19T17:27:42.387] _job_complete: JobId=46548 WEXITSTATUS 1
[2022-07-19T17:27:42.387] _job_complete: JobId=46548 done
[2022-07-19T17:28:26.194] _slurm_rpc_submit_batch_job: JobId=46549 InitPrio=24913 usec=566
[2022-07-19T17:28:26.687] sched: Allocate JobId=46549 NodeList=cpu04 #CPUs=24 Partition=cpu-opteron
[2022-07-19T17:28:29.876] _job_complete: JobId=46549 WEXITSTATUS 1
[2022-07-19T17:28:29.876] _job_complete: JobId=46549 done
[2022-07-19T17:32:02.000] _slurm_rpc_submit_batch_job: JobId=46550 InitPrio=24913 usec=503
[2022-07-19T17:32:02.991] sched: Allocate JobId=46550 NodeList=cpu04 #CPUs=24 Partition=cpu-opteron
[2022-07-19T17:32:06.460] _job_complete: JobId=46550 WEXITSTATUS 1
[2022-07-19T17:32:06.460] _job_complete: JobId=46550 done
[2022-07-19T17:33:02.226] _slurm_rpc_submit_batch_job: JobId=46551 InitPrio=24913 usec=442
[2022-07-19T17:33:03.190] sched: Allocate JobId=46551 NodeList=cpu04 #CPUs=24 Partition=cpu-opteron
[2022-07-19T17:33:05.958] _job_complete: JobId=46551 WEXITSTATUS 1
[2022-07-19T17:33:05.958] _job_complete: JobId=46551 done
[2022-07-19T17:33:53.718] _slurm_rpc_submit_batch_job: JobId=46552 InitPrio=24913 usec=581
[2022-07-19T17:33:54.260] sched: Allocate JobId=46552 NodeList=cpu04 #CPUs=24 Partition=cpu-opteron
[2022-07-19T17:33:57.381] _job_complete: JobId=46552 WEXITSTATUS 1
[2022-07-19T17:33:57.381] _job_complete: JobId=46552 done
[2022-07-19T17:34:23.409] _slurm_rpc_submit_batch_job: JobId=46553 InitPrio=24913 usec=418
[2022-07-19T17:34:24.303] sched: Allocate JobId=46553 NodeList=cpu04 #CPUs=24 Partition=cpu-opteron
[2022-07-19T17:34:27.086] _job_complete: JobId=46553 WEXITSTATUS 1
[2022-07-19T17:34:27.086] _job_complete: JobId=46553 done
[2022-07-19T17:35:49.748] _slurm_rpc_submit_batch_job: JobId=46554 InitPrio=24913 usec=436
[2022-07-19T17:35:50.426] sched: Allocate JobId=46554 NodeList=cpu04 #CPUs=24 Partition=cpu-opteron
[2022-07-19T17:35:53.662] _job_complete: JobId=46554 WEXITSTATUS 1
[2022-07-19T17:35:53.662] _job_complete: JobId=46554 done
[2022-07-19T17:36:16.408] _slurm_rpc_submit_batch_job: JobId=46555 InitPrio=24913 usec=423
[2022-07-19T17:36:16.463] sched: Allocate JobId=46555 NodeList=cpu04 #CPUs=24 Partition=cpu-opteron
[2022-07-19T17:36:19.253] _job_complete: JobId=46555 WEXITSTATUS 1
[2022-07-19T17:36:19.253] _job_complete: JobId=46555 done
[2022-07-19T17:36:34.626] _job_complete: JobId=46537 WEXITSTATUS 0
[2022-07-19T17:36:34.627] _job_complete: JobId=46537 done
[2022-07-19T17:41:03.973] _slurm_rpc_kill_job: REQUEST_KILL_JOB JobId=46458 uid 548200045
[2022-07-19T17:41:05.852] sched: Allocate JobId=46500 NodeList=gpu05 #CPUs=16 Partition=gpu-v100s
[2022-07-19T17:41:07.935] _job_complete: JobId=46500 WEXITSTATUS 2
[2022-07-19T17:41:07.935] _job_complete: JobId=46500 done
[2022-07-19T17:43:11.379] _slurm_rpc_submit_batch_job: JobId=46556 InitPrio=20074 usec=407
[2022-07-19T17:43:12.363] sched: Allocate JobId=46556 NodeList=cpu15 #CPUs=24 Partition=cpu-epyc
[2022-07-19T17:45:37.656] _slurm_rpc_submit_batch_job: JobId=46557 InitPrio=19468 usec=449
[2022-07-19T17:47:46.816] _slurm_rpc_submit_batch_job: JobId=46558 InitPrio=19537 usec=369
[2022-07-19T17:47:46.837] sched: Allocate JobId=46558 NodeList=cpu15 #CPUs=24 Partition=cpu-epyc
[2022-07-19T17:49:42.732] _slurm_rpc_kill_job: REQUEST_KILL_JOB JobId=46557 uid 548200017
[2022-07-19T17:49:46.168] _slurm_rpc_submit_batch_job: JobId=46559 InitPrio=19468 usec=426
[2022-07-19T17:49:47.004] sched: Allocate JobId=46559 NodeList=cpu14 #CPUs=32 Partition=cpu-epyc
[2022-07-19T20:21:01.479] _slurm_rpc_submit_batch_job: JobId=46560 InitPrio=20411 usec=413
[2022-07-19T20:21:02.514] sched: Allocate JobId=46560 NodeList=gpu05 #CPUs=16 Partition=gpu-v100s
[2022-07-19T20:21:43.281] _job_complete: JobId=46560 WEXITSTATUS 1
[2022-07-19T20:21:43.282] _job_complete: JobId=46560 done
[2022-07-19T20:23:33.728] _slurm_rpc_submit_batch_job: JobId=46561 InitPrio=20411 usec=356
[2022-07-19T20:23:33.736] sched: Allocate JobId=46561 NodeList=gpu05 #CPUs=16 Partition=gpu-v100s
[2022-07-19T21:22:35.084] _job_complete: JobId=46374 WEXITSTATUS 0
[2022-07-19T21:22:35.089] _job_complete: JobId=46374 done
[2022-07-19T21:22:43.265] sched: Allocate JobId=46529 NodeList=gpu04 #CPUs=16 Partition=gpu-k40c
[2022-07-19T21:25:11.812] _job_complete: JobId=46529 WEXITSTATUS 0
[2022-07-19T21:25:11.813] _job_complete: JobId=46529 done
[2022-07-19T21:28:48.477] _slurm_rpc_submit_batch_job: JobId=46562 InitPrio=20949 usec=425
[2022-07-19T21:28:48.682] sched: Allocate JobId=46562 NodeList=gpu04 #CPUs=16 Partition=gpu-k40c
[2022-07-19T21:31:12.467] _job_complete: JobId=46562 WEXITSTATUS 0
[2022-07-19T21:31:12.468] _job_complete: JobId=46562 done
[2022-07-19T21:33:53.331] _slurm_rpc_submit_batch_job: JobId=46563 InitPrio=20949 usec=406
[2022-07-19T21:33:54.181] sched: Allocate JobId=46563 NodeList=gpu04 #CPUs=16 Partition=gpu-k40c
[2022-07-19T22:17:38.362] _job_complete: JobId=46543 WEXITSTATUS 0
[2022-07-19T22:17:38.363] _job_complete: JobId=46543 done
[2022-07-19T23:12:16.179] _slurm_rpc_submit_batch_job: JobId=46564 InitPrio=23100 usec=554
[2022-07-19T23:12:16.892] sched: Allocate JobId=46564 NodeList=cpu12 #CPUs=16 Partition=cpu-epyc
[2022-07-19T23:16:51.967] _slurm_rpc_submit_batch_job: JobId=46565 InitPrio=22689 usec=576
[2022-07-19T23:16:52.423] sched: Allocate JobId=46565 NodeList=cpu04 #CPUs=64 Partition=cpu-opteron
[2022-07-19T23:18:54.030] _slurm_rpc_kill_job: REQUEST_KILL_JOB JobId=46565 uid 548200036
[2022-07-19T23:20:19.686] _slurm_rpc_submit_batch_job: JobId=46566 InitPrio=22689 usec=485
[2022-07-19T23:20:19.809] sched: Allocate JobId=46566 NodeList=cpu04 #CPUs=64 Partition=cpu-opteron
[2022-07-19T23:20:44.003] _slurm_rpc_submit_batch_job: JobId=46567 InitPrio=22689 usec=508
[2022-07-19T23:20:44.844] sched: Allocate JobId=46567 NodeList=cpu10 #CPUs=64 Partition=cpu-opteron
[2022-07-19T23:40:36.675] _job_complete: JobId=46563 WEXITSTATUS 0
[2022-07-19T23:40:36.680] _job_complete: JobId=46563 done
[2022-07-19T23:43:41.774] _slurm_rpc_submit_batch_job: JobId=46568 InitPrio=20949 usec=575
[2022-07-19T23:43:41.928] sched: Allocate JobId=46568 NodeList=gpu04 #CPUs=16 Partition=gpu-k40c
[2022-07-20T00:12:30.327] Time limit exhausted for JobId=46564
[2022-07-20T00:46:49.875] _slurm_rpc_submit_batch_job: JobId=46569 InitPrio=20680 usec=609
[2022-07-20T00:46:50.750] sched: Allocate JobId=46569 NodeList=cpu03 #CPUs=16 Partition=cpu-opteron
[2022-07-20T00:47:12.785] _slurm_rpc_submit_batch_job: JobId=46570 InitPrio=20680 usec=429
[2022-07-20T00:48:09.580] _slurm_rpc_submit_batch_job: JobId=46571 InitPrio=20680 usec=519
[2022-07-20T01:06:43.026] _job_complete: JobId=46544 WEXITSTATUS 0
[2022-07-20T01:06:43.026] _job_complete: JobId=46544 done
[2022-07-20T01:49:58.408] _job_complete: JobId=46568 WEXITSTATUS 0
[2022-07-20T01:49:58.414] _job_complete: JobId=46568 done
[2022-07-20T02:07:52.723] _slurm_rpc_submit_batch_job: JobId=46572 InitPrio=20949 usec=477
[2022-07-20T02:07:53.412] sched: Allocate JobId=46572 NodeList=gpu04 #CPUs=16 Partition=gpu-k40c
[2022-07-20T08:28:44.426] _job_complete: JobId=46572 WEXITSTATUS 0
[2022-07-20T08:28:44.431] _job_complete: JobId=46572 done
[2022-07-20T11:08:20.240] _slurm_rpc_submit_batch_job: JobId=46573 InitPrio=22831 usec=562
[2022-07-20T11:08:21.251] sched: Allocate JobId=46573 NodeList=cpu12 #CPUs=16 Partition=cpu-epyc
[2022-07-20T11:08:44.917] _slurm_rpc_submit_batch_job: JobId=46574 InitPrio=20949 usec=418
[2022-07-20T11:08:45.285] sched: Allocate JobId=46574 NodeList=gpu04 #CPUs=16 Partition=gpu-k40c
[2022-07-20T12:08:33.600] Time limit exhausted for JobId=46573
[2022-07-20T13:15:37.809] _job_complete: JobId=46574 WEXITSTATUS 0
[2022-07-20T13:15:37.814] _job_complete: JobId=46574 done
[2022-07-20T13:47:20.135] _slurm_rpc_submit_batch_job: JobId=46575 InitPrio=23368 usec=439
[2022-07-20T13:47:20.985] sched: Allocate JobId=46575 NodeList=cpu12 #CPUs=16 Partition=cpu-epyc
[2022-07-20T13:50:19.891] _slurm_rpc_submit_batch_job: JobId=46576 InitPrio=23368 usec=427
[2022-07-20T13:50:20.357] sched: Allocate JobId=46576 NodeList=cpu14 #CPUs=16 Partition=cpu-epyc
[2022-07-20T13:52:19.375] _slurm_rpc_submit_batch_job: JobId=46577 InitPrio=23368 usec=469
[2022-07-20T13:54:05.931] _slurm_rpc_submit_batch_job: JobId=46578 InitPrio=23368 usec=419
[2022-07-20T13:59:35.372] _job_complete: JobId=46576 WEXITSTATUS 1
[2022-07-20T13:59:35.372] _job_complete: JobId=46576 done
[2022-07-20T13:59:35.712] sched: Allocate JobId=46577 NodeList=cpu14 #CPUs=16 Partition=cpu-epyc
[2022-07-20T13:59:36.421] _job_complete: JobId=46577 WEXITSTATUS 1
[2022-07-20T13:59:36.421] _job_complete: JobId=46577 done
[2022-07-20T13:59:36.671] sched: Allocate JobId=46578 NodeList=cpu14 #CPUs=16 Partition=cpu-epyc
[2022-07-20T14:12:47.948] _job_complete: JobId=46578 WEXITSTATUS 0
[2022-07-20T14:12:47.948] _job_complete: JobId=46578 done
[2022-07-20T14:35:07.781] _slurm_rpc_submit_batch_job: JobId=46579 InitPrio=23368 usec=424
[2022-07-20T14:35:08.055] sched: Allocate JobId=46579 NodeList=cpu14 #CPUs=16 Partition=cpu-epyc
[2022-07-20T14:35:55.116] _slurm_rpc_submit_batch_job: JobId=46580 InitPrio=23368 usec=469
[2022-07-20T14:49:44.525] _job_complete: JobId=46579 WEXITSTATUS 0
[2022-07-20T14:49:44.525] _job_complete: JobId=46579 done
[2022-07-20T14:49:44.787] sched: Allocate JobId=46580 NodeList=cpu14 #CPUs=16 Partition=cpu-epyc
[2022-07-20T14:49:52.364] _job_complete: JobId=46580 WEXITSTATUS 1
[2022-07-20T14:49:52.364] _job_complete: JobId=46580 done
[2022-07-20T14:59:12.234] _job_complete: JobId=46575 WEXITSTATUS 1
[2022-07-20T14:59:12.234] _job_complete: JobId=46575 done
[2022-07-20T14:59:50.997] _slurm_rpc_submit_batch_job: JobId=46581 InitPrio=20949 usec=465
[2022-07-20T14:59:51.726] sched: Allocate JobId=46581 NodeList=gpu04 #CPUs=16 Partition=gpu-k40c
[2022-07-20T15:01:06.723] _slurm_rpc_submit_batch_job: JobId=46582 InitPrio=21756 usec=380
[2022-07-20T15:02:14.898] _job_complete: JobId=46581 WEXITSTATUS 0
[2022-07-20T15:02:14.898] _job_complete: JobId=46581 done
[2022-07-20T15:02:53.544] _slurm_rpc_submit_batch_job: JobId=46583 InitPrio=21756 usec=587
[2022-07-20T15:03:28.759] _slurm_rpc_submit_batch_job: JobId=46584 InitPrio=21756 usec=447
[2022-07-20T15:03:59.690] _slurm_rpc_submit_batch_job: JobId=46585 InitPrio=20949 usec=458
[2022-07-20T15:04:00.131] sched: Allocate JobId=46585 NodeList=gpu04 #CPUs=16 Partition=gpu-k40c
[2022-07-20T15:04:32.753] _slurm_rpc_submit_batch_job: JobId=46586 InitPrio=21756 usec=468
[2022-07-20T15:04:51.964] _slurm_rpc_submit_batch_job: JobId=46587 InitPrio=21756 usec=387
[2022-07-20T15:04:59.990] _slurm_rpc_kill_job: REQUEST_KILL_JOB JobId=46587 uid 548200029
[2022-07-20T15:05:29.443] _slurm_rpc_submit_batch_job: JobId=46588 InitPrio=21756 usec=416
[2022-07-20T15:09:14.276] _slurm_rpc_submit_batch_job: JobId=46589 InitPrio=24981 usec=536
[2022-07-20T15:09:59.861] _slurm_rpc_kill_job: REQUEST_KILL_JOB JobId=46589 uid 548200084
[2022-07-20T15:10:37.489] _slurm_rpc_submit_batch_job: JobId=46590 InitPrio=25050 usec=630
[2022-07-20T15:10:52.526] _slurm_rpc_kill_job: REQUEST_KILL_JOB JobId=46590 uid 548200084
[2022-07-20T15:11:24.326] _slurm_rpc_submit_batch_job: JobId=46591 InitPrio=24981 usec=449
[2022-07-20T15:18:07.479] _slurm_rpc_kill_job: REQUEST_KILL_JOB JobId=46591 uid 548200084
[2022-07-20T15:18:27.231] _slurm_rpc_submit_batch_job: JobId=46592 InitPrio=24981 usec=478
[2022-07-20T15:18:27.888] sched: Allocate JobId=46592 NodeList=cpu12 #CPUs=16 Partition=cpu-epyc
[2022-07-20T15:18:29.894] _job_complete: JobId=46592 WEXITSTATUS 1
[2022-07-20T15:18:29.894] _job_complete: JobId=46592 done
[2022-07-20T15:25:38.983] _slurm_rpc_submit_batch_job: JobId=46593 InitPrio=24981 usec=519
[2022-07-20T15:25:52.506] _slurm_rpc_kill_job: REQUEST_KILL_JOB JobId=46593 uid 548200084
[2022-07-20T15:26:13.141] _slurm_rpc_submit_batch_job: JobId=46594 InitPrio=24981 usec=422
[2022-07-20T15:26:13.600] sched: Allocate JobId=46594 NodeList=cpu12 #CPUs=16 Partition=cpu-epyc
[2022-07-20T15:26:14.098] _job_complete: JobId=46594 WEXITSTATUS 1
[2022-07-20T15:26:14.098] _job_complete: JobId=46594 done
[2022-07-20T15:26:54.494] _slurm_rpc_submit_batch_job: JobId=46595 InitPrio=24981 usec=396
[2022-07-20T15:26:54.657] sched: Allocate JobId=46595 NodeList=cpu12 #CPUs=16 Partition=cpu-epyc
[2022-07-20T15:27:17.443] _slurm_rpc_kill_job: REQUEST_KILL_JOB JobId=46595 uid 548200084
[2022-07-20T15:27:35.119] _slurm_rpc_submit_batch_job: JobId=46596 InitPrio=24981 usec=388
[2022-07-20T15:27:35.773] sched: Allocate JobId=46596 NodeList=cpu12 #CPUs=16 Partition=cpu-epyc
[2022-07-20T15:52:29.422] _slurm_rpc_submit_batch_job: JobId=46597 InitPrio=20680 usec=629
[2022-07-20T15:52:29.555] sched: Allocate JobId=46597 NodeList=cpu14 #CPUs=16 Partition=cpu-epyc
[2022-07-20T15:52:45.699] _slurm_rpc_kill_job: REQUEST_KILL_JOB JobId=46571 uid 548200019
[2022-07-20T17:10:44.799] _job_complete: JobId=46585 WEXITSTATUS 0
[2022-07-20T17:10:44.804] _job_complete: JobId=46585 done
[2022-07-20T17:14:30.776] _slurm_rpc_submit_batch_job: JobId=46598 InitPrio=22831 usec=439
[2022-07-20T17:14:47.159] _job_complete: JobId=46597 WEXITSTATUS 0
[2022-07-20T17:14:47.159] _job_complete: JobId=46597 done
[2022-07-20T17:14:48.090] sched: Allocate JobId=46598 NodeList=cpu14 #CPUs=16 Partition=cpu-epyc
[2022-07-20T17:15:38.078] _slurm_rpc_submit_batch_job: JobId=46599 InitPrio=22831 usec=442
[2022-07-20T17:16:18.955] _slurm_rpc_kill_job: REQUEST_KILL_JOB JobId=46599 uid 548200036
[2022-07-20T18:06:06.072] _slurm_rpc_submit_batch_job: JobId=46600 InitPrio=23368 usec=572
[2022-07-20T18:06:24.346] _slurm_rpc_submit_batch_job: JobId=46601 InitPrio=23368 usec=470
[2022-07-20T18:15:04.505] Time limit exhausted for JobId=46598
[2022-07-20T18:15:05.404] sched: Allocate JobId=46600 NodeList=cpu14 #CPUs=16 Partition=cpu-epyc
[2022-07-20T18:24:16.637] _job_complete: JobId=46600 WEXITSTATUS 1
[2022-07-20T18:24:16.637] _job_complete: JobId=46600 done
[2022-07-20T18:24:16.882] sched: Allocate JobId=46601 NodeList=cpu14 #CPUs=16 Partition=cpu-epyc
[2022-07-20T18:42:33.209] _slurm_rpc_submit_batch_job: JobId=46602 InitPrio=20949 usec=421
[2022-07-20T18:42:33.514] sched: Allocate JobId=46602 NodeList=gpu04 #CPUs=16 Partition=gpu-k40c
[2022-07-20T18:44:43.075] _slurm_rpc_kill_job: REQUEST_KILL_JOB JobId=46602 uid 548200053
[2022-07-20T19:13:43.154] _job_complete: JobId=46601 WEXITSTATUS 1
[2022-07-20T19:13:43.154] _job_complete: JobId=46601 done
[2022-07-20T20:46:17.350] _slurm_rpc_submit_batch_job: JobId=46603 InitPrio=20949 usec=527
[2022-07-20T20:46:17.536] sched: Allocate JobId=46603 NodeList=gpu04 #CPUs=16 Partition=gpu-k40c
[2022-07-20T21:29:44.795] _slurm_rpc_kill_job: REQUEST_KILL_JOB JobId=46450 uid 548200017
[2022-07-20T21:29:46.874] sched: Allocate JobId=46582 NodeList=cpu09 #CPUs=16 Partition=cpu-opteron
[2022-07-20T21:29:46.875] sched: Allocate JobId=46583 NodeList=cpu09 #CPUs=16 Partition=cpu-opteron
[2022-07-20T21:29:46.876] sched: Allocate JobId=46584 NodeList=cpu09 #CPUs=16 Partition=cpu-opteron
[2022-07-20T21:29:46.877] sched: Allocate JobId=46586 NodeList=cpu09 #CPUs=16 Partition=cpu-opteron
[2022-07-20T21:31:38.230] _slurm_rpc_submit_batch_job: JobId=46604 InitPrio=23368 usec=519
[2022-07-20T21:31:40.480] sched: Allocate JobId=46604 NodeList=cpu14 #CPUs=16 Partition=cpu-epyc
[2022-07-20T21:36:44.288] _job_complete: JobId=46586 WEXITSTATUS 0
[2022-07-20T21:36:44.289] _job_complete: JobId=46586 done
[2022-07-20T21:36:50.437] _job_complete: JobId=46584 WEXITSTATUS 0
[2022-07-20T21:36:50.438] _job_complete: JobId=46584 done
[2022-07-20T21:37:02.321] _job_complete: JobId=46582 WEXITSTATUS 0
[2022-07-20T21:37:02.321] _job_complete: JobId=46582 done
[2022-07-20T21:37:11.368] sched: Allocate JobId=46588 NodeList=cpu09 #CPUs=16 Partition=cpu-opteron
[2022-07-20T21:37:11.381] sched: Allocate JobId=46570 NodeList=cpu09 #CPUs=16 Partition=cpu-opteron
[2022-07-20T21:40:49.871] _job_complete: JobId=46583 WEXITSTATUS 0
[2022-07-20T21:40:49.872] _job_complete: JobId=46583 done
[2022-07-20T21:43:45.066] _job_complete: JobId=46588 WEXITSTATUS 0
[2022-07-20T21:43:45.066] _job_complete: JobId=46588 done
[2022-07-20T22:52:40.268] _job_complete: JobId=46603 WEXITSTATUS 0
[2022-07-20T22:52:40.273] _job_complete: JobId=46603 done
[2022-07-20T22:58:50.632] _slurm_rpc_submit_batch_job: JobId=46605 InitPrio=20949 usec=699
[2022-07-20T22:58:51.080] sched: Allocate JobId=46605 NodeList=gpu04 #CPUs=16 Partition=gpu-k40c
[2022-07-20T23:44:55.484] _job_complete: JobId=46604 OOM failure
[2022-07-20T23:44:55.484] _job_complete: JobId=46604 done
[2022-07-21T00:31:39.201] _slurm_rpc_submit_batch_job: JobId=46606 InitPrio=23368 usec=572
[2022-07-21T00:31:40.937] sched: Allocate JobId=46606 NodeList=cpu14 #CPUs=16 Partition=cpu-epyc
[2022-07-21T00:47:06.540] Time limit exhausted for JobId=46569
[2022-07-21T02:51:06.748] _job_complete: JobId=46606 WEXITSTATUS 0
[2022-07-21T02:51:06.748] _job_complete: JobId=46606 done
[2022-07-21T05:09:48.297] _job_complete: JobId=46570 WEXITSTATUS 0
[2022-07-21T05:09:48.297] _job_complete: JobId=46570 done
[2022-07-21T05:21:37.266] _job_complete: JobId=46605 WEXITSTATUS 0
[2022-07-21T05:21:37.270] _job_complete: JobId=46605 done
[2022-07-21T05:56:14.921] _slurm_rpc_submit_batch_job: JobId=46607 InitPrio=20949 usec=495
[2022-07-21T05:56:15.343] sched: Allocate JobId=46607 NodeList=gpu04 #CPUs=16 Partition=gpu-k40c
[2022-07-21T08:19:40.055] _slurm_rpc_submit_batch_job: JobId=46608 InitPrio=20949 usec=521
[2022-07-21T08:51:24.008] sched: _slurm_rpc_allocate_resources JobId=46609 NodeList=cpu03 usec=15563
[2022-07-21T09:24:06.679] _slurm_rpc_submit_batch_job: JobId=46610 InitPrio=21756 usec=482
[2022-07-21T09:24:06.769] sched: Allocate JobId=46610 NodeList=cpu14 #CPUs=16 Partition=cpu-epyc
[2022-07-21T09:24:09.100] _job_complete: JobId=46610 WEXITSTATUS 1
[2022-07-21T09:24:09.100] _job_complete: JobId=46610 done
[2022-07-21T09:27:55.593] _slurm_rpc_submit_batch_job: JobId=46611 InitPrio=21756 usec=389
[2022-07-21T09:27:56.356] sched: Allocate JobId=46611 NodeList=cpu14 #CPUs=16 Partition=cpu-epyc
[2022-07-21T09:49:38.564] _slurm_rpc_submit_batch_job: JobId=46612 InitPrio=24295 usec=450
[2022-07-21T09:49:40.651] sched: Allocate JobId=46612 NodeList=gpu02 #CPUs=2 Partition=gpu-titan
[2022-07-21T10:28:07.054] Time limit exhausted for JobId=46611
[2022-07-21T11:16:07.801] _job_complete: JobId=46609 WEXITSTATUS 1
[2022-07-21T11:16:07.801] _job_complete: JobId=46609 done
[2022-07-21T12:14:10.436] _job_complete: JobId=46279 WEXITSTATUS 0
[2022-07-21T12:14:10.436] _job_complete: JobId=46279 done
[2022-07-21T12:15:12.514] _job_complete: JobId=46607 WEXITSTATUS 0
[2022-07-21T12:15:12.519] _job_complete: JobId=46607 done
[2022-07-21T12:15:13.425] sched: Allocate JobId=46608 NodeList=gpu04 #CPUs=16 Partition=gpu-k40c
[2022-07-21T13:02:30.234] _slurm_rpc_submit_batch_job: JobId=46613 InitPrio=24295 usec=693
[2022-07-21T13:02:30.942] sched: Allocate JobId=46613 NodeList=gpu02 #CPUs=2 Partition=gpu-titan
[2022-07-21T13:25:48.505] sched: _slurm_rpc_allocate_resources JobId=46614 NodeList=cpu03 usec=14044
[2022-07-21T14:02:26.855] _slurm_rpc_submit_batch_job: JobId=46615 InitPrio=24295 usec=554
[2022-07-21T14:02:27.295] sched: Allocate JobId=46615 NodeList=gpu02 #CPUs=2 Partition=gpu-titan
[2022-07-21T14:11:27.853] _job_complete: JobId=46614 WEXITSTATUS 0
[2022-07-21T14:11:27.853] _job_complete: JobId=46614 done
[2022-07-21T15:16:48.973] _slurm_rpc_submit_batch_job: JobId=46616 InitPrio=21756 usec=522
[2022-07-21T15:16:49.482] sched: Allocate JobId=46616 NodeList=cpu14 #CPUs=16 Partition=cpu-epyc
[2022-07-21T15:23:24.411] _slurm_rpc_submit_batch_job: JobId=46617 InitPrio=19463 usec=399
[2022-07-21T15:23:24.961] sched: Allocate JobId=46617 NodeList=cpu09 #CPUs=64 Partition=cpu-opteron
[2022-07-21T15:27:27.311] _slurm_rpc_submit_batch_job: JobId=46618 InitPrio=19600 usec=492
[2022-07-21T15:41:04.144] _job_complete: JobId=46612 WEXITSTATUS 0
[2022-07-21T15:41:04.144] _job_complete: JobId=46612 done
[2022-07-21T16:12:56.365] _slurm_rpc_submit_batch_job: JobId=46619 InitPrio=19874 usec=525
[2022-07-21T16:12:56.498] sched: Allocate JobId=46619 NodeList=gpu05 #CPUs=16 Partition=gpu-v100s
[2022-07-21T16:17:08.848] Time limit exhausted for JobId=46616
[2022-07-21T16:22:30.392] _slurm_rpc_submit_batch_job: JobId=46620 InitPrio=19874 usec=458
[2022-07-21T16:22:50.644] _slurm_rpc_kill_job: REQUEST_KILL_JOB JobId=46619 uid 548200021
[2022-07-21T16:22:53.545] sched: Allocate JobId=46620 NodeList=gpu05 #CPUs=16 Partition=gpu-v100s
[2022-07-21T16:28:45.999] _slurm_rpc_submit_batch_job: JobId=46621 InitPrio=19874 usec=438
[2022-07-21T16:43:00.838] _slurm_rpc_submit_batch_job: JobId=46622 InitPrio=19874 usec=475
[2022-07-21T16:43:53.567] _slurm_rpc_submit_batch_job: JobId=46623 InitPrio=19874 usec=494
[2022-07-21T18:24:34.040] _slurm_rpc_submit_batch_job: JobId=46624 InitPrio=23368 usec=489
[2022-07-21T18:24:34.692] sched: Allocate JobId=46624 NodeList=cpu14 #CPUs=16 Partition=cpu-epyc
[2022-07-21T18:34:18.128] _job_complete: JobId=46624 WEXITSTATUS 0
[2022-07-21T18:34:18.128] _job_complete: JobId=46624 done
[2022-07-21T18:35:32.974] _slurm_rpc_submit_batch_job: JobId=46625 InitPrio=23368 usec=445
[2022-07-21T18:35:33.851] sched: Allocate JobId=46625 NodeList=cpu03 #CPUs=16 Partition=cpu-opteron
[2022-07-21T18:35:35.186] _job_complete: JobId=46625 WEXITSTATUS 1
[2022-07-21T18:35:35.187] _job_complete: JobId=46625 done
[2022-07-21T18:37:18.322] _job_complete: JobId=46608 WEXITSTATUS 0
[2022-07-21T18:37:18.326] _job_complete: JobId=46608 done
[2022-07-21T18:38:23.499] _slurm_rpc_submit_batch_job: JobId=46626 InitPrio=23368 usec=614
[2022-07-21T18:38:24.228] sched: Allocate JobId=46626 NodeList=cpu03 #CPUs=16 Partition=cpu-opteron
[2022-07-21T18:55:14.110] _job_complete: JobId=46613 WEXITSTATUS 0
[2022-07-21T18:55:14.111] _job_complete: JobId=46613 done
[2022-07-21T18:59:14.780] _slurm_rpc_submit_batch_job: JobId=46627 InitPrio=20949 usec=477
[2022-07-21T18:59:15.518] sched: Allocate JobId=46627 NodeList=gpu04 #CPUs=16 Partition=gpu-k40c
[2022-07-21T19:18:24.544] _job_complete: JobId=46626 WEXITSTATUS 0
[2022-07-21T19:18:24.544] _job_complete: JobId=46626 done
[2022-07-21T20:31:49.870] _slurm_rpc_submit_batch_job: JobId=46628 InitPrio=20949 usec=529
[2022-07-21T20:31:50.312] sched: Allocate JobId=46628 NodeList=cpu14 #CPUs=16 Partition=cpu-epyc
[2022-07-21T22:08:20.387] _job_complete: JobId=46615 WEXITSTATUS 0
[2022-07-21T22:08:20.387] _job_complete: JobId=46615 done
[2022-07-21T22:30:12.621] _job_complete: JobId=46596 WEXITSTATUS 0
[2022-07-21T22:30:12.622] _job_complete: JobId=46596 done
[2022-07-22T02:03:56.624] _slurm_rpc_submit_batch_job: JobId=46629 InitPrio=19874 usec=461
[2022-07-22T02:03:56.877] sched: Allocate JobId=46629 NodeList=gpu02 #CPUs=16 Partition=gpu-titan
[2022-07-22T03:08:57.823] _slurm_rpc_submit_batch_job: JobId=46630 InitPrio=23757 usec=466
[2022-07-22T03:11:02.133] _slurm_rpc_submit_batch_job: JobId=46631 InitPrio=19874 usec=545
[2022-07-22T03:11:22.966] _slurm_rpc_kill_job: REQUEST_KILL_JOB JobId=46629 uid 548200021
[2022-07-22T03:11:43.918] sched: Allocate JobId=46630 NodeList=gpu02 #CPUs=2 Partition=gpu-titan
[2022-07-22T04:54:45.287] _job_complete: JobId=46531 WEXITSTATUS 0
[2022-07-22T04:54:45.292] _job_complete: JobId=46531 done
[2022-07-22T08:46:44.377] _job_complete: JobId=46630 WEXITSTATUS 0
[2022-07-22T08:46:44.378] _job_complete: JobId=46630 done
[2022-07-22T08:46:44.805] sched: Allocate JobId=46631 NodeList=gpu02 #CPUs=16 Partition=gpu-titan
[2022-07-22T09:35:13.988] _job_complete: JobId=46460 WEXITSTATUS 0
[2022-07-22T09:35:13.992] _job_complete: JobId=46460 done
[2022-07-22T09:35:16.834] sched: Allocate JobId=46618 NodeList=cpu13 #CPUs=48 Partition=cpu-epyc
[2022-07-22T09:46:32.385] _slurm_rpc_submit_batch_job: JobId=46632 InitPrio=19605 usec=456
[2022-07-22T09:46:33.076] sched: Allocate JobId=46632 NodeList=cpu12 #CPUs=16 Partition=cpu-epyc
[2022-07-22T09:56:00.052] _slurm_rpc_submit_batch_job: JobId=46633 InitPrio=21487 usec=490
[2022-07-22T09:56:00.105] sched: Allocate JobId=46633 NodeList=cpu03 #CPUs=16 Partition=cpu-opteron
[2022-07-22T12:46:39.283] _slurm_rpc_submit_batch_job: JobId=46634 InitPrio=23757 usec=402
[2022-07-22T12:53:10.503] _slurm_rpc_submit_batch_job: JobId=46635 InitPrio=26428 usec=456
[2022-07-22T12:53:11.090] sched: Allocate JobId=46635 NodeList=gpu01 #CPUs=4 Partition=gpu-k10
[2022-07-22T13:15:10.927] _slurm_rpc_submit_batch_job: JobId=46636 InitPrio=26454 usec=573
[2022-07-22T13:15:20.508] _slurm_rpc_kill_job: REQUEST_KILL_JOB JobId=46636 uid 548200003
[2022-07-22T13:24:39.932] _slurm_rpc_submit_batch_job: JobId=46637 InitPrio=26454 usec=413
[2022-07-22T13:24:49.156] _slurm_rpc_kill_job: REQUEST_KILL_JOB JobId=46637 uid 548200003
[2022-07-22T13:25:09.519] _slurm_rpc_submit_batch_job: JobId=46638 InitPrio=26454 usec=490
[2022-07-22T13:25:16.959] _slurm_rpc_kill_job: REQUEST_KILL_JOB JobId=46638 uid 548200003
[2022-07-22T13:40:24.358] _slurm_rpc_submit_batch_job: JobId=46639 InitPrio=26454 usec=705
[2022-07-22T13:40:33.759] _slurm_rpc_kill_job: REQUEST_KILL_JOB JobId=46639 uid 548200003
[2022-07-22T13:41:11.527] _slurm_rpc_submit_batch_job: JobId=46640 InitPrio=26454 usec=460
[2022-07-22T13:41:24.333] _slurm_rpc_kill_job: REQUEST_KILL_JOB JobId=46640 uid 548200003
[2022-07-22T13:51:14.486] _slurm_rpc_kill_job: REQUEST_KILL_JOB JobId=46635 uid 548200003
[2022-07-22T15:07:48.695] _slurm_rpc_submit_batch_job: JobId=46641 InitPrio=21487 usec=454
[2022-07-22T15:45:50.549] _slurm_rpc_submit_batch_job: JobId=46642 InitPrio=24175 usec=440
[2022-07-22T15:45:52.477] _slurm_rpc_submit_batch_job: JobId=46643 InitPrio=24175 usec=444
[2022-07-22T15:45:53.869] _slurm_rpc_submit_batch_job: JobId=46644 InitPrio=24175 usec=437
[2022-07-22T15:45:55.237] _slurm_rpc_submit_batch_job: JobId=46645 InitPrio=24175 usec=453
[2022-07-22T15:45:56.637] _slurm_rpc_submit_batch_job: JobId=46646 InitPrio=24175 usec=562
[2022-07-22T15:45:58.045] _slurm_rpc_submit_batch_job: JobId=46647 InitPrio=24175 usec=422
[2022-07-22T15:45:59.454] _slurm_rpc_submit_batch_job: JobId=46648 InitPrio=24175 usec=410
[2022-07-22T15:46:00.798] _slurm_rpc_submit_batch_job: JobId=46649 InitPrio=24175 usec=458
[2022-07-22T15:46:02.173] _slurm_rpc_submit_batch_job: JobId=46650 InitPrio=24175 usec=403
[2022-07-22T15:46:04.099] _slurm_rpc_submit_batch_job: JobId=46651 InitPrio=24175 usec=401
[2022-07-22T15:46:05.781] _slurm_rpc_submit_batch_job: JobId=46652 InitPrio=24175 usec=406
[2022-07-22T15:46:07.189] _slurm_rpc_submit_batch_job: JobId=46653 InitPrio=24175 usec=394
[2022-07-22T15:46:08.741] _slurm_rpc_submit_batch_job: JobId=46654 InitPrio=24175 usec=442
[2022-07-22T15:46:10.197] _slurm_rpc_submit_batch_job: JobId=46655 InitPrio=24175 usec=438
[2022-07-22T15:46:11.605] _slurm_rpc_submit_batch_job: JobId=46656 InitPrio=24175 usec=451
[2022-07-22T15:46:12.973] _slurm_rpc_submit_batch_job: JobId=46657 InitPrio=24175 usec=498
[2022-07-22T15:46:14.430] _slurm_rpc_submit_batch_job: JobId=46658 InitPrio=24175 usec=400
[2022-07-22T15:46:15.869] _slurm_rpc_submit_batch_job: JobId=46659 InitPrio=24175 usec=443
[2022-07-22T15:46:17.357] _slurm_rpc_submit_batch_job: JobId=46660 InitPrio=24175 usec=363
[2022-07-22T15:46:20.484] _slurm_rpc_submit_batch_job: JobId=46661 InitPrio=24175 usec=419
[2022-07-22T15:46:22.621] _slurm_rpc_submit_batch_job: JobId=46662 InitPrio=24175 usec=397
[2022-07-22T15:46:23.981] _slurm_rpc_submit_batch_job: JobId=46663 InitPrio=24175 usec=454
[2022-07-22T15:46:25.693] _slurm_rpc_submit_batch_job: JobId=46664 InitPrio=24175 usec=422
[2022-07-22T15:46:28.413] _slurm_rpc_submit_batch_job: JobId=46665 InitPrio=24175 usec=378
[2022-07-22T16:17:43.081] _slurm_rpc_submit_batch_job: JobId=46666 InitPrio=22562 usec=457
[2022-07-22T16:21:37.115] _slurm_rpc_submit_batch_job: JobId=46667 InitPrio=22562 usec=582
[2022-07-22T16:27:22.413] _slurm_rpc_submit_batch_job: JobId=46668 InitPrio=22562 usec=421
[2022-07-22T17:04:05.658] _slurm_rpc_submit_batch_job: JobId=46669 InitPrio=22562 usec=480
[2022-07-22T17:04:09.336] _slurm_rpc_submit_batch_job: JobId=46670 InitPrio=22562 usec=510
[2022-07-22T20:32:11.996] Time limit exhausted for JobId=46628
[2022-07-22T20:32:13.865] sched: Allocate JobId=46642 NodeList=cpu14 #CPUs=16 Partition=cpu-epyc
[2022-07-22T20:59:45.196] _job_complete: JobId=46642 WEXITSTATUS 0
[2022-07-22T20:59:45.196] _job_complete: JobId=46642 done
[2022-07-22T20:59:45.450] sched: Allocate JobId=46643 NodeList=cpu14 #CPUs=16 Partition=cpu-epyc
[2022-07-22T21:34:37.662] _job_complete: JobId=46643 WEXITSTATUS 0
[2022-07-22T21:34:37.663] _job_complete: JobId=46643 done
[2022-07-22T21:34:37.946] sched: Allocate JobId=46644 NodeList=cpu14 #CPUs=16 Partition=cpu-epyc
[2022-07-22T22:01:29.584] _slurm_rpc_kill_job: REQUEST_KILL_JOB JobId=46631 uid 548200021
[2022-07-22T22:01:34.501] sched: Allocate JobId=46634 NodeList=gpu02 #CPUs=2 Partition=gpu-titan
[2022-07-22T22:07:43.624] _slurm_rpc_submit_batch_job: JobId=46671 InitPrio=19891 usec=517
[2022-07-22T22:07:44.425] sched: Allocate JobId=46671 NodeList=gpu02 #CPUs=14 Partition=gpu-titan
[2022-07-22T22:09:53.727] _slurm_rpc_submit_batch_job: JobId=46672 InitPrio=19891 usec=389
[2022-07-22T22:10:30.957] _job_complete: JobId=46644 WEXITSTATUS 0
[2022-07-22T22:10:30.957] _job_complete: JobId=46644 done
[2022-07-22T22:10:31.224] sched: Allocate JobId=46645 NodeList=cpu14 #CPUs=16 Partition=cpu-epyc
[2022-07-22T22:10:55.792] _slurm_rpc_submit_batch_job: JobId=46673 InitPrio=19891 usec=496
[2022-07-22T22:13:50.082] _job_complete: JobId=46671 WEXITSTATUS 0
[2022-07-22T22:13:50.082] _job_complete: JobId=46671 done
[2022-07-22T22:13:50.400] sched: Allocate JobId=46672 NodeList=gpu02 #CPUs=14 Partition=gpu-titan
[2022-07-22T22:13:56.682] _job_complete: JobId=46672 WEXITSTATUS 1
[2022-07-22T22:13:56.682] _job_complete: JobId=46672 done
[2022-07-22T22:13:56.985] sched: Allocate JobId=46673 NodeList=gpu02 #CPUs=14 Partition=gpu-titan
[2022-07-22T22:15:26.202] _job_complete: JobId=46673 WEXITSTATUS 0
[2022-07-22T22:15:26.202] _job_complete: JobId=46673 done
[2022-07-22T22:37:06.189] _job_complete: JobId=46645 WEXITSTATUS 0
[2022-07-22T22:37:06.189] _job_complete: JobId=46645 done
[2022-07-22T22:37:06.442] sched: Allocate JobId=46646 NodeList=cpu14 #CPUs=16 Partition=cpu-epyc
[2022-07-22T22:38:44.148] _slurm_rpc_submit_batch_job: JobId=46674 InitPrio=20949 usec=555
[2022-07-22T23:01:54.604] _job_complete: JobId=46646 WEXITSTATUS 0
[2022-07-22T23:01:54.605] _job_complete: JobId=46646 done
[2022-07-22T23:01:54.852] sched: Allocate JobId=46647 NodeList=cpu14 #CPUs=16 Partition=cpu-epyc
[2022-07-22T23:29:44.052] _job_complete: JobId=46647 WEXITSTATUS 0
[2022-07-22T23:29:44.052] _job_complete: JobId=46647 done
[2022-07-22T23:29:44.290] sched: Allocate JobId=46648 NodeList=cpu14 #CPUs=16 Partition=cpu-epyc
[2022-07-22T23:55:14.031] _job_complete: JobId=46648 WEXITSTATUS 0
[2022-07-22T23:55:14.031] _job_complete: JobId=46648 done
[2022-07-22T23:55:14.282] sched: Allocate JobId=46649 NodeList=cpu14 #CPUs=16 Partition=cpu-epyc
[2022-07-23T00:21:25.526] _job_complete: JobId=46649 WEXITSTATUS 0
[2022-07-23T00:21:25.526] _job_complete: JobId=46649 done
[2022-07-23T00:21:25.787] sched: Allocate JobId=46650 NodeList=cpu14 #CPUs=16 Partition=cpu-epyc
[2022-07-23T00:48:04.477] _slurm_rpc_submit_batch_job: JobId=46675 InitPrio=21487 usec=448
[2022-07-23T00:58:14.450] _job_complete: JobId=46650 WEXITSTATUS 0
[2022-07-23T00:58:14.450] _job_complete: JobId=46650 done
[2022-07-23T00:58:14.765] sched: Allocate JobId=46651 NodeList=cpu14 #CPUs=16 Partition=cpu-epyc
[2022-07-23T01:27:01.451] _slurm_rpc_submit_batch_job: JobId=46676 InitPrio=19891 usec=502
[2022-07-23T01:27:01.504] sched: Allocate JobId=46676 NodeList=gpu02 #CPUs=14 Partition=gpu-titan
[2022-07-23T01:28:07.837] _slurm_rpc_submit_batch_job: JobId=46677 InitPrio=19891 usec=404
[2022-07-23T01:28:51.122] _slurm_rpc_submit_batch_job: JobId=46678 InitPrio=19891 usec=507
[2022-07-23T01:38:37.854] _job_complete: JobId=46651 WEXITSTATUS 0
[2022-07-23T01:38:37.854] _job_complete: JobId=46651 done
[2022-07-23T01:38:38.104] sched: Allocate JobId=46652 NodeList=cpu14 #CPUs=16 Partition=cpu-epyc
[2022-07-23T01:48:30.101] _slurm_rpc_submit_batch_job: JobId=46679 InitPrio=22024 usec=767
[2022-07-23T01:48:30.844] sched: Allocate JobId=46679 NodeList=gpu01 #CPUs=16 Partition=gpu-k10
[2022-07-23T02:16:47.917] _job_complete: JobId=46652 WEXITSTATUS 0
[2022-07-23T02:16:47.917] _job_complete: JobId=46652 done
[2022-07-23T02:16:48.160] sched: Allocate JobId=46653 NodeList=cpu14 #CPUs=16 Partition=cpu-epyc
[2022-07-23T02:52:01.183] _job_complete: JobId=46653 WEXITSTATUS 0
[2022-07-23T02:52:01.183] _job_complete: JobId=46653 done
[2022-07-23T02:52:01.428] sched: Allocate JobId=46654 NodeList=cpu14 #CPUs=16 Partition=cpu-epyc
[2022-07-23T03:18:34.524] _job_complete: JobId=46654 WEXITSTATUS 0
[2022-07-23T03:18:34.524] _job_complete: JobId=46654 done
[2022-07-23T03:18:34.761] sched: Allocate JobId=46655 NodeList=cpu14 #CPUs=16 Partition=cpu-epyc
[2022-07-23T03:26:28.335] _job_complete: JobId=46634 WEXITSTATUS 0
[2022-07-23T03:26:28.336] _job_complete: JobId=46634 done
[2022-07-23T03:46:28.021] _job_complete: JobId=46655 WEXITSTATUS 0
[2022-07-23T03:46:28.021] _job_complete: JobId=46655 done
[2022-07-23T03:46:28.270] sched: Allocate JobId=46656 NodeList=cpu14 #CPUs=16 Partition=cpu-epyc
[2022-07-23T04:11:37.249] _job_complete: JobId=46656 WEXITSTATUS 0
[2022-07-23T04:11:37.249] _job_complete: JobId=46656 done
[2022-07-23T04:11:37.606] sched: Allocate JobId=46657 NodeList=cpu14 #CPUs=16 Partition=cpu-epyc
[2022-07-23T04:43:18.598] _job_complete: JobId=46657 WEXITSTATUS 0
[2022-07-23T04:43:18.598] _job_complete: JobId=46657 done
[2022-07-23T04:43:18.835] sched: Allocate JobId=46658 NodeList=cpu14 #CPUs=16 Partition=cpu-epyc
[2022-07-23T05:10:09.283] _job_complete: JobId=46658 WEXITSTATUS 0
[2022-07-23T05:10:09.284] _job_complete: JobId=46658 done
[2022-07-23T05:10:09.554] sched: Allocate JobId=46659 NodeList=cpu14 #CPUs=16 Partition=cpu-epyc
[2022-07-23T05:37:08.182] _job_complete: JobId=46659 WEXITSTATUS 0
[2022-07-23T05:37:08.182] _job_complete: JobId=46659 done
[2022-07-23T05:37:08.426] sched: Allocate JobId=46660 NodeList=cpu14 #CPUs=16 Partition=cpu-epyc
[2022-07-23T05:47:37.487] _job_complete: JobId=46676 WEXITSTATUS 1
[2022-07-23T05:47:37.487] _job_complete: JobId=46676 done
[2022-07-23T05:47:37.839] sched: Allocate JobId=46677 NodeList=gpu02 #CPUs=14 Partition=gpu-titan
[2022-07-23T06:04:37.610] _job_complete: JobId=46660 WEXITSTATUS 0
[2022-07-23T06:04:37.610] _job_complete: JobId=46660 done
[2022-07-23T06:04:37.841] sched: Allocate JobId=46661 NodeList=cpu14 #CPUs=16 Partition=cpu-epyc
[2022-07-23T06:31:27.924] _job_complete: JobId=46661 WEXITSTATUS 0
[2022-07-23T06:31:27.924] _job_complete: JobId=46661 done
[2022-07-23T06:31:28.145] sched: Allocate JobId=46662 NodeList=cpu14 #CPUs=16 Partition=cpu-epyc
[2022-07-23T06:59:21.110] _job_complete: JobId=46627 WEXITSTATUS 0
[2022-07-23T06:59:21.117] _job_complete: JobId=46627 done
[2022-07-23T07:05:12.203] _job_complete: JobId=46662 WEXITSTATUS 0
[2022-07-23T07:05:12.203] _job_complete: JobId=46662 done
[2022-07-23T07:05:12.511] sched: Allocate JobId=46663 NodeList=cpu14 #CPUs=16 Partition=cpu-epyc
[2022-07-23T07:30:32.702] _job_complete: JobId=46663 WEXITSTATUS 0
[2022-07-23T07:30:32.702] _job_complete: JobId=46663 done
[2022-07-23T07:30:32.984] sched: Allocate JobId=46664 NodeList=cpu14 #CPUs=16 Partition=cpu-epyc
[2022-07-23T07:31:34.593] _job_complete: JobId=46620 WEXITSTATUS 0
[2022-07-23T07:31:34.593] _job_complete: JobId=46620 done
[2022-07-23T07:31:35.505] sched: Allocate JobId=46621 NodeList=gpu05 #CPUs=16 Partition=gpu-v100s
[2022-07-23T08:11:49.002] _job_complete: JobId=46677 WEXITSTATUS 0
[2022-07-23T08:11:49.002] _job_complete: JobId=46677 done
[2022-07-23T08:11:49.340] sched: Allocate JobId=46678 NodeList=gpu02 #CPUs=14 Partition=gpu-titan
[2022-07-23T08:19:07.839] _job_complete: JobId=46664 WEXITSTATUS 0
[2022-07-23T08:19:07.839] _job_complete: JobId=46664 done
[2022-07-23T08:19:08.102] sched: Allocate JobId=46665 NodeList=cpu14 #CPUs=16 Partition=cpu-epyc
[2022-07-23T08:51:51.583] _job_complete: JobId=46665 WEXITSTATUS 0
[2022-07-23T08:51:51.584] _job_complete: JobId=46665 done
[2022-07-23T08:51:51.840] sched: Allocate JobId=46666 NodeList=cpu14 #CPUs=16 Partition=cpu-epyc
[2022-07-23T12:47:26.345] _slurm_rpc_submit_batch_job: JobId=46680 InitPrio=23757 usec=445
[2022-07-23T12:47:27.075] sched: Allocate JobId=46680 NodeList=gpu02 #CPUs=2 Partition=gpu-titan
[2022-07-23T15:36:54.816] _job_complete: JobId=46678 WEXITSTATUS 0
[2022-07-23T15:36:54.816] _job_complete: JobId=46678 done
[2022-07-23T18:31:37.116] _job_complete: JobId=46680 WEXITSTATUS 0
[2022-07-23T18:31:37.116] _job_complete: JobId=46680 done
[2022-07-23T20:20:40.168] _job_complete: JobId=46633 WEXITSTATUS 0
[2022-07-23T20:20:40.168] _job_complete: JobId=46633 done
[2022-07-23T20:20:40.695] sched: Allocate JobId=46675 NodeList=cpu03 #CPUs=16 Partition=cpu-opteron
[2022-07-23T21:48:29.504] _job_complete: JobId=46666 WEXITSTATUS 0
[2022-07-23T21:48:29.504] _job_complete: JobId=46666 done
[2022-07-23T21:48:29.738] sched: Allocate JobId=46667 NodeList=cpu14 #CPUs=16 Partition=cpu-epyc
[2022-07-24T00:50:05.056] _slurm_rpc_submit_batch_job: JobId=46681 InitPrio=20680 usec=460
[2022-07-24T00:50:05.376] sched: Allocate JobId=46681 NodeList=gpu04 #CPUs=16 Partition=gpu-k40c
[2022-07-24T00:52:28.681] _job_complete: JobId=46681 WEXITSTATUS 0
[2022-07-24T00:52:28.681] _job_complete: JobId=46681 done
[2022-07-24T00:55:08.047] _slurm_rpc_submit_batch_job: JobId=46682 InitPrio=20680 usec=459
[2022-07-24T00:55:08.860] sched: Allocate JobId=46682 NodeList=gpu04 #CPUs=16 Partition=gpu-k40c
[2022-07-24T01:35:27.995] _job_complete: JobId=46618 WEXITSTATUS 0
[2022-07-24T01:35:27.995] _job_complete: JobId=46618 done
[2022-07-24T01:35:28.365] sched: Allocate JobId=46668 NodeList=cpu13 #CPUs=16 Partition=cpu-epyc
[2022-07-24T01:35:28.366] sched: Allocate JobId=46669 NodeList=cpu13 #CPUs=16 Partition=cpu-epyc
[2022-07-24T01:35:28.380] sched: Allocate JobId=46674 NodeList=cpu13 #CPUs=16 Partition=cpu-epyc
[2022-07-24T01:41:22.003] _slurm_rpc_submit_batch_job: JobId=46683 InitPrio=20480 usec=543
[2022-07-24T01:41:22.647] sched: Allocate JobId=46683 NodeList=gpu02 #CPUs=8 Partition=gpu-titan
[2022-07-24T01:42:10.498] _job_complete: JobId=46683 WEXITSTATUS 1
[2022-07-24T01:42:10.498] _job_complete: JobId=46683 done
[2022-07-24T02:36:47.113] _slurm_rpc_submit_batch_job: JobId=46684 InitPrio=20480 usec=464
[2022-07-24T02:36:47.962] sched: Allocate JobId=46684 NodeList=gpu02 #CPUs=8 Partition=gpu-titan
[2022-07-24T03:01:36.265] _job_complete: JobId=46682 WEXITSTATUS 0
[2022-07-24T03:01:36.270] _job_complete: JobId=46682 done
[2022-07-24T04:31:14.134] _job_complete: JobId=46684 WEXITSTATUS 0
[2022-07-24T04:31:14.134] _job_complete: JobId=46684 done
[2022-07-24T07:18:42.945] _slurm_rpc_submit_batch_job: JobId=46685 InitPrio=20480 usec=586
[2022-07-24T07:18:43.359] sched: Allocate JobId=46685 NodeList=gpu02 #CPUs=8 Partition=gpu-titan
[2022-07-24T07:46:03.750] _slurm_rpc_submit_batch_job: JobId=46686 InitPrio=20680 usec=456
[2022-07-24T07:46:04.363] sched: Allocate JobId=46686 NodeList=gpu04 #CPUs=16 Partition=gpu-k40c
[2022-07-24T09:23:52.495] _slurm_rpc_submit_batch_job: JobId=46687 InitPrio=23757 usec=514
[2022-07-24T09:23:52.657] sched: Allocate JobId=46687 NodeList=gpu02 #CPUs=2 Partition=gpu-titan
[2022-07-24T09:33:13.129] _job_complete: JobId=46685 WEXITSTATUS 0
[2022-07-24T09:33:13.129] _job_complete: JobId=46685 done
[2022-07-24T09:52:34.598] _job_complete: JobId=46686 WEXITSTATUS 0
[2022-07-24T09:52:34.603] _job_complete: JobId=46686 done
[2022-07-24T10:34:51.423] _slurm_rpc_submit_batch_job: JobId=46688 InitPrio=20680 usec=416
[2022-07-24T10:34:51.623] sched: Allocate JobId=46688 NodeList=gpu04 #CPUs=16 Partition=gpu-k40c
[2022-07-24T10:49:55.014] _job_complete: JobId=46667 WEXITSTATUS 0
[2022-07-24T10:49:55.014] _job_complete: JobId=46667 done
[2022-07-24T10:49:55.269] sched: Allocate JobId=46670 NodeList=cpu14 #CPUs=16 Partition=cpu-epyc
[2022-07-24T11:04:29.295] _slurm_rpc_submit_batch_job: JobId=46689 InitPrio=23757 usec=602
[2022-07-24T11:04:29.794] sched: Allocate JobId=46689 NodeList=gpu02 #CPUs=2 Partition=gpu-titan
[2022-07-24T14:54:55.045] _job_complete: JobId=46621 WEXITSTATUS 0
[2022-07-24T14:54:55.045] _job_complete: JobId=46621 done
[2022-07-24T14:54:55.949] sched: Allocate JobId=46622 NodeList=gpu05 #CPUs=16 Partition=gpu-v100s
[2022-07-24T15:11:48.808] _job_complete: JobId=46687 WEXITSTATUS 0
[2022-07-24T15:11:48.808] _job_complete: JobId=46687 done
[2022-07-24T15:53:48.512] _job_complete: JobId=46668 WEXITSTATUS 0
[2022-07-24T15:53:48.513] _job_complete: JobId=46668 done
[2022-07-24T15:53:48.761] sched: Allocate JobId=46641 NodeList=cpu13 #CPUs=16 Partition=cpu-epyc
[2022-07-24T15:55:11.326] _slurm_rpc_submit_batch_job: JobId=46690 InitPrio=20480 usec=541
[2022-07-24T15:55:11.991] sched: Allocate JobId=46690 NodeList=gpu02 #CPUs=8 Partition=gpu-titan
[2022-07-24T16:45:00.063] _job_complete: JobId=46689 WEXITSTATUS 0
[2022-07-24T16:45:00.063] _job_complete: JobId=46689 done
[2022-07-24T16:53:54.216] Time limit exhausted for JobId=46641
[2022-07-24T16:58:50.114] _job_complete: JobId=46688 WEXITSTATUS 0
[2022-07-24T16:58:50.120] _job_complete: JobId=46688 done
[2022-07-24T17:09:35.866] _slurm_rpc_submit_batch_job: JobId=46691 InitPrio=20680 usec=538
[2022-07-24T17:09:36.883] sched: Allocate JobId=46691 NodeList=gpu04 #CPUs=16 Partition=gpu-k40c
[2022-07-24T19:05:31.646] _job_complete: JobId=46679 WEXITSTATUS 0
[2022-07-24T19:05:31.652] _job_complete: JobId=46679 done
[2022-07-24T23:22:10.681] _job_complete: JobId=46669 WEXITSTATUS 0
[2022-07-24T23:22:10.682] _job_complete: JobId=46669 done
[2022-07-25T01:35:54.279] Time limit exhausted for JobId=46674
[2022-07-25T06:57:06.456] _job_complete: JobId=46670 WEXITSTATUS 0
[2022-07-25T06:57:06.457] _job_complete: JobId=46670 done
[2022-07-25T08:47:47.204] _slurm_rpc_submit_batch_job: JobId=46692 InitPrio=19331 usec=376
[2022-07-25T08:47:47.622] sched: Allocate JobId=46692 NodeList=cpu13 #CPUs=48 Partition=cpu-epyc
[2022-07-25T08:58:49.187] _job_complete: JobId=46622 WEXITSTATUS 0
[2022-07-25T08:58:49.187] _job_complete: JobId=46622 done
[2022-07-25T08:58:50.095] sched: Allocate JobId=46623 NodeList=gpu05 #CPUs=16 Partition=gpu-v100s
[2022-07-25T11:51:45.896] _slurm_rpc_submit_batch_job: JobId=46693 InitPrio=21887 usec=473
[2022-07-25T13:19:42.245] sched: _slurm_rpc_allocate_resources JobId=46694 NodeList=(null) usec=907
[2022-07-25T13:36:24.576] Processing Reconfiguration Request
[2022-07-25T13:36:24.582] restoring original state of nodes
[2022-07-25T13:36:24.583] select/cons_tres: part_data_create_array: select/cons_tres: preparing for 6 partitions
[2022-07-25T13:36:24.583] read_slurm_conf: backup_controller not specified
[2022-07-25T13:36:24.583] select/cons_tres: select_p_reconfigure: select/cons_tres: reconfigure
[2022-07-25T13:36:24.583] select/cons_tres: part_data_create_array: select/cons_tres: preparing for 6 partitions
[2022-07-25T13:36:24.584] No parameter for mcs plugin, default values set
[2022-07-25T13:36:24.584] mcs: MCSParameters = (null). ondemand set.
[2022-07-25T13:36:24.584] _slurm_rpc_reconfigure_controller: completed usec=8492
[2022-07-25T13:36:25.235] SchedulerParameters=default_queue_depth=100,max_rpc_cnt=0,max_sched_time=2,partition_job_depth=0,sched_max_job_start=0,sched_min_interval=2
[2022-07-25T13:38:02.997] Processing Reconfiguration Request
[2022-07-25T13:38:03.004] restoring original state of nodes
[2022-07-25T13:38:03.004] select/cons_tres: part_data_create_array: select/cons_tres: preparing for 6 partitions
[2022-07-25T13:38:03.005] read_slurm_conf: backup_controller not specified
[2022-07-25T13:38:03.005] select/cons_tres: select_p_reconfigure: select/cons_tres: reconfigure
[2022-07-25T13:38:03.005] select/cons_tres: part_data_create_array: select/cons_tres: preparing for 6 partitions
[2022-07-25T13:38:03.005] No parameter for mcs plugin, default values set
[2022-07-25T13:38:03.005] mcs: MCSParameters = (null). ondemand set.
[2022-07-25T13:38:03.006] _slurm_rpc_reconfigure_controller: completed usec=8280
[2022-07-25T13:38:03.474] SchedulerParameters=default_queue_depth=100,max_rpc_cnt=0,max_sched_time=2,partition_job_depth=0,sched_max_job_start=0,sched_min_interval=2
[2022-07-25T13:40:00.728] _job_complete: JobId=46694 WTERMSIG 126
[2022-07-25T13:40:00.728] _job_complete: JobId=46694 cancelled by interactive user
[2022-07-25T13:40:00.728] _job_complete: JobId=46694 done
[2022-07-25T13:40:00.729] _slurm_rpc_complete_job_allocation: JobId=46694 error Job/step already completing or completed
[2022-07-25T14:15:14.699] sched: _slurm_rpc_allocate_resources JobId=46695 NodeList=(null) usec=983
[2022-07-25T14:16:01.609] _slurm_rpc_submit_batch_job: JobId=46696 InitPrio=21149 usec=477
[2022-07-25T14:16:45.175] _job_complete: JobId=46695 WTERMSIG 126
[2022-07-25T14:16:45.175] _job_complete: JobId=46695 cancelled by interactive user
[2022-07-25T14:16:45.175] _job_complete: JobId=46695 done
[2022-07-25T14:16:45.177] _slurm_rpc_complete_job_allocation: JobId=46695 error Job/step already completing or completed
[2022-07-25T14:20:06.259] sched: _slurm_rpc_allocate_resources JobId=46697 NodeList=(null) usec=893
[2022-07-25T14:25:06.601] _slurm_rpc_submit_batch_job: JobId=46698 InitPrio=21149 usec=685
[2022-07-25T14:57:26.203] sched: _slurm_rpc_allocate_resources JobId=46699 NodeList=(null) usec=863
[2022-07-25T14:57:40.637] _job_complete: JobId=46699 WTERMSIG 126
[2022-07-25T14:57:40.637] _job_complete: JobId=46699 cancelled by interactive user
[2022-07-25T14:57:40.637] _job_complete: JobId=46699 done
[2022-07-25T14:57:57.572] _slurm_rpc_kill_job: REQUEST_KILL_JOB JobId=46699 uid 548300543
[2022-07-25T15:09:13.160] _slurm_rpc_submit_batch_job: JobId=46700 InitPrio=22024 usec=365
[2022-07-25T15:12:06.554] _slurm_rpc_submit_batch_job: JobId=46701 InitPrio=22024 usec=380
[2022-07-25T15:20:56.582] _slurm_rpc_submit_batch_job: JobId=46702 InitPrio=21149 usec=536
[2022-07-25T15:55:28.476] Time limit exhausted for JobId=46690
[2022-07-25T16:54:59.463] _slurm_rpc_submit_batch_job: JobId=46703 InitPrio=21081 usec=561
[2022-07-25T16:55:51.866] _slurm_rpc_submit_batch_job: JobId=46704 InitPrio=21081 usec=440
[2022-07-25T17:50:21.170] _slurm_rpc_submit_batch_job: JobId=46705 InitPrio=24444 usec=530
[2022-07-25T17:50:22.087] sched: Allocate JobId=46705 NodeList=cpu14 #CPUs=16 Partition=cpu-epyc
[2022-07-25T17:52:25.438] _slurm_rpc_submit_batch_job: JobId=46706 InitPrio=24375 usec=532
[2022-07-25T18:12:45.953] _job_complete: JobId=46697 WTERMSIG 126
[2022-07-25T18:12:45.953] _job_complete: JobId=46697 cancelled by interactive user
[2022-07-25T18:12:45.954] _job_complete: JobId=46697 done
[2022-07-25T18:12:45.955] _slurm_rpc_complete_job_allocation: JobId=46697 error Job/step already completing or completed
[2022-07-25T18:43:50.794] _slurm_rpc_submit_batch_job: JobId=46707 InitPrio=24444 usec=492
[2022-07-25T18:59:14.437] _slurm_rpc_submit_batch_job: JobId=46708 InitPrio=24375 usec=445
[2022-07-25T20:00:31.632] _slurm_rpc_kill_job: REQUEST_KILL_JOB JobId=46707 uid 548200084
[2022-07-25T20:00:43.788] _slurm_rpc_submit_batch_job: JobId=46709 InitPrio=24444 usec=475
[2022-07-25T20:07:41.085] _slurm_rpc_submit_batch_job: JobId=46710 InitPrio=20480 usec=475
[2022-07-25T20:07:41.774] sched: Allocate JobId=46710 NodeList=gpu02 #CPUs=8 Partition=gpu-titan
[2022-07-25T20:40:14.620] _slurm_rpc_submit_batch_job: JobId=46711 InitPrio=19874 usec=461
[2022-07-25T20:40:15.345] sched: Allocate JobId=46711 NodeList=gpu01 #CPUs=16 Partition=gpu-k10
[2022-07-25T20:40:19.409] _job_complete: JobId=46711 WEXITSTATUS 1
[2022-07-25T20:40:19.409] _job_complete: JobId=46711 done
[2022-07-25T20:41:20.192] _slurm_rpc_submit_batch_job: JobId=46712 InitPrio=19874 usec=401
[2022-07-25T20:41:20.422] sched: Allocate JobId=46712 NodeList=gpu01 #CPUs=16 Partition=gpu-k10
[2022-07-25T20:41:22.016] _job_complete: JobId=46712 WEXITSTATUS 1
[2022-07-25T20:41:22.017] _job_complete: JobId=46712 done
[2022-07-25T20:42:40.557] _slurm_rpc_submit_batch_job: JobId=46713 InitPrio=19874 usec=438
[2022-07-25T20:42:40.672] sched: Allocate JobId=46713 NodeList=gpu01 #CPUs=16 Partition=gpu-k10
[2022-07-25T20:57:47.897] _job_complete: JobId=46705 WEXITSTATUS 0
[2022-07-25T20:57:47.897] _job_complete: JobId=46705 done
[2022-07-25T20:58:15.501] sched/backfill: _start_job: Started JobId=46709 in cpu-epyc on cpu14
[2022-07-25T20:58:45.823] _job_complete: JobId=46709 WEXITSTATUS 0
[2022-07-25T20:58:45.823] _job_complete: JobId=46709 done
[2022-07-25T21:03:30.823] _slurm_rpc_submit_batch_job: JobId=46714 InitPrio=19874 usec=473
[2022-07-25T21:13:16.867] _job_complete: JobId=46713 WEXITSTATUS 1
[2022-07-25T21:13:16.867] _job_complete: JobId=46713 done
[2022-07-25T21:13:17.782] sched: Allocate JobId=46714 NodeList=gpu01 #CPUs=16 Partition=gpu-k10
[2022-07-25T21:18:53.986] _job_create: exceeded association/QOS limit for user 548200021: QOSMaxWallDurationPerJobLimit
[2022-07-25T21:18:53.986] _slurm_rpc_submit_batch_job: Job violates accounting/QOS policy (job submit limit, user's size and/or time limits)
[2022-07-25T21:19:40.047] _slurm_rpc_submit_batch_job: JobId=46715 InitPrio=19874 usec=472
[2022-07-25T21:21:04.770] _slurm_rpc_submit_batch_job: JobId=46716 InitPrio=19874 usec=484
[2022-07-25T21:21:41.514] _slurm_rpc_submit_batch_job: JobId=46717 InitPrio=19874 usec=555
[2022-07-25T21:39:58.318] _job_complete: JobId=46714 WEXITSTATUS 1
[2022-07-25T21:39:58.319] _job_complete: JobId=46714 done
[2022-07-25T21:39:58.627] sched: Allocate JobId=46715 NodeList=gpu01 #CPUs=16 Partition=gpu-k10
[2022-07-25T21:52:20.312] _slurm_rpc_submit_batch_job: JobId=46718 InitPrio=24307 usec=429
[2022-07-25T23:38:13.768] _slurm_rpc_submit_batch_job: JobId=46719 InitPrio=19874 usec=536
[2022-07-26T05:26:49.699] _job_complete: JobId=46691 WEXITSTATUS 0
[2022-07-26T05:26:49.705] _job_complete: JobId=46691 done
[2022-07-26T09:05:08.512] _job_complete: JobId=46559 WEXITSTATUS 0
[2022-07-26T09:05:08.518] _job_complete: JobId=46559 done
[2022-07-26T09:05:10.390] sched: Allocate JobId=46706 NodeList=cpu14 #CPUs=24 Partition=cpu-epyc
[2022-07-26T09:05:10.390] sched: Allocate JobId=46708 NodeList=cpu14 #CPUs=24 Partition=cpu-epyc
[2022-07-26T09:05:23.745] _job_complete: JobId=46708 WEXITSTATUS 0
[2022-07-26T09:05:23.745] _job_complete: JobId=46708 done
[2022-07-26T10:15:44.582] _slurm_rpc_submit_batch_job: JobId=46720 InitPrio=24375 usec=457
[2022-07-26T11:01:13.028] _job_complete: JobId=46675 WEXITSTATUS 1
[2022-07-26T11:01:13.028] _job_complete: JobId=46675 done
[2022-07-26T11:01:18.102] sched/backfill: _start_job: Started JobId=46700 in cpu-opteron on cpu03
[2022-07-26T11:10:49.746] _slurm_rpc_submit_batch_job: JobId=46721 InitPrio=21218 usec=534
[2022-07-26T11:15:44.060] _job_complete: JobId=46700 WEXITSTATUS 0
[2022-07-26T11:15:44.061] _job_complete: JobId=46700 done
[2022-07-26T11:16:18.146] sched/backfill: _start_job: Started JobId=46701 in cpu-opteron on cpu03
[2022-07-26T11:17:13.765] _job_complete: JobId=46701 WEXITSTATUS 0
[2022-07-26T11:17:13.765] _job_complete: JobId=46701 done
[2022-07-26T11:17:18.166] sched/backfill: _start_job: Started JobId=46721 in cpu-opteron on cpu03
[2022-07-26T11:19:39.676] _job_complete: JobId=46706 WEXITSTATUS 0
[2022-07-26T11:19:39.676] _job_complete: JobId=46706 done
[2022-07-26T11:19:39.939] sched: Allocate JobId=46718 NodeList=cpu14 #CPUs=32 Partition=cpu-epyc
[2022-07-26T11:20:56.737] _job_complete: JobId=46718 WEXITSTATUS 0
[2022-07-26T11:20:56.737] _job_complete: JobId=46718 done
[2022-07-26T11:20:56.979] sched: Allocate JobId=46720 NodeList=cpu14 #CPUs=24 Partition=cpu-epyc
[2022-07-26T11:20:56.980] sched: Allocate JobId=46696 NodeList=cpu14 #CPUs=24 Partition=cpu-epyc
[2022-07-26T11:21:47.021] _job_complete: JobId=46720 WEXITSTATUS 0
[2022-07-26T11:21:47.022] _job_complete: JobId=46720 done
[2022-07-26T11:54:44.465] _slurm_rpc_submit_batch_job: JobId=46722 InitPrio=24444 usec=465
[2022-07-26T11:54:44.601] sched: Allocate JobId=46722 NodeList=cpu14 #CPUs=16 Partition=cpu-epyc
[2022-07-26T12:01:36.179] _slurm_rpc_submit_batch_job: JobId=46723 InitPrio=24375 usec=453
[2022-07-26T12:03:46.761] _slurm_rpc_kill_job: REQUEST_KILL_JOB JobId=46723 uid 548200084
[2022-07-26T12:04:01.822] _slurm_rpc_submit_batch_job: JobId=46724 InitPrio=24478 usec=490
[2022-07-26T13:51:48.183] _slurm_rpc_submit_batch_job: JobId=46725 InitPrio=20949 usec=429
[2022-07-26T13:51:48.253] sched: Allocate JobId=46725 NodeList=gpu04 #CPUs=16 Partition=gpu-k40c
[2022-07-26T14:38:57.835] _slurm_rpc_submit_batch_job: JobId=46726 InitPrio=19874 usec=552
[2022-07-26T14:53:36.857] _slurm_rpc_kill_job: REQUEST_KILL_JOB JobId=46716 uid 548200021
[2022-07-26T14:53:40.547] _slurm_rpc_kill_job: REQUEST_KILL_JOB JobId=46717 uid 548200021
[2022-07-26T14:53:45.618] _slurm_rpc_kill_job: REQUEST_KILL_JOB JobId=46726 uid 548200021
[2022-07-26T14:53:49.470] _slurm_rpc_kill_job: REQUEST_KILL_JOB JobId=46715 uid 548200021
[2022-07-26T14:53:59.324] _slurm_rpc_submit_batch_job: JobId=46727 InitPrio=19891 usec=456
[2022-07-26T14:55:25.577] _slurm_rpc_kill_job: REQUEST_KILL_JOB JobId=46727 uid 548200021
[2022-07-26T14:55:28.721] _slurm_rpc_submit_batch_job: JobId=46728 InitPrio=19874 usec=407
[2022-07-26T14:55:28.976] sched: Allocate JobId=46728 NodeList=gpu01 #CPUs=16 Partition=gpu-k10
[2022-07-26T14:56:35.643] _slurm_rpc_submit_batch_job: JobId=46729 InitPrio=19874 usec=462
[2022-07-26T14:56:38.454] _job_complete: JobId=46722 WEXITSTATUS 0
[2022-07-26T14:56:38.454] _job_complete: JobId=46722 done
[2022-07-26T14:56:38.746] sched: Allocate JobId=46724 NodeList=cpu14 #CPUs=12 Partition=cpu-epyc
[2022-07-26T14:58:55.081] _slurm_rpc_submit_batch_job: JobId=46730 InitPrio=19874 usec=478
[2022-07-26T15:41:05.305] _slurm_rpc_submit_batch_job: JobId=46731 InitPrio=21887 usec=550
[2022-07-26T15:44:37.787] _slurm_rpc_kill_job: REQUEST_KILL_JOB JobId=46724 uid 548200084
[2022-07-26T15:45:28.427] _slurm_rpc_submit_batch_job: JobId=46732 InitPrio=24209 usec=452
[2022-07-26T15:45:29.188] sched: Allocate JobId=46732 NodeList=cpu14 #CPUs=12 Partition=cpu-epyc
[2022-07-26T15:51:13.341] _slurm_rpc_submit_batch_job: JobId=46733 InitPrio=24106 usec=469
[2022-07-26T17:02:30.139] _slurm_rpc_submit_batch_job: JobId=46734 InitPrio=23906 usec=448
[2022-07-26T17:02:33.677] _slurm_rpc_submit_batch_job: JobId=46735 InitPrio=23906 usec=454
[2022-07-26T17:02:36.342] _slurm_rpc_submit_batch_job: JobId=46736 InitPrio=23906 usec=426
[2022-07-26T17:02:38.894] _slurm_rpc_submit_batch_job: JobId=46737 InitPrio=23906 usec=425
[2022-07-26T17:02:41.493] _slurm_rpc_submit_batch_job: JobId=46738 InitPrio=23906 usec=447
[2022-07-26T17:02:44.285] _slurm_rpc_submit_batch_job: JobId=46739 InitPrio=23906 usec=442
[2022-07-26T17:02:47.837] _slurm_rpc_submit_batch_job: JobId=46740 InitPrio=23906 usec=405
[2022-07-26T17:27:49.488] _slurm_rpc_submit_batch_job: JobId=46741 InitPrio=23906 usec=467
[2022-07-26T17:27:52.553] _slurm_rpc_submit_batch_job: JobId=46742 InitPrio=23906 usec=458
[2022-07-26T17:27:55.066] _slurm_rpc_submit_batch_job: JobId=46743 InitPrio=23906 usec=480
[2022-07-26T17:27:58.905] _slurm_rpc_submit_batch_job: JobId=46744 InitPrio=23906 usec=428
[2022-07-26T17:28:01.505] _slurm_rpc_submit_batch_job: JobId=46745 InitPrio=23906 usec=410
[2022-07-26T17:28:04.465] _slurm_rpc_submit_batch_job: JobId=46746 InitPrio=23906 usec=546
[2022-07-26T17:28:07.680] _slurm_rpc_submit_batch_job: JobId=46747 InitPrio=23906 usec=459
[2022-07-26T17:42:20.209] _slurm_rpc_submit_batch_job: JobId=46748 InitPrio=23906 usec=433
[2022-07-26T17:42:22.800] _slurm_rpc_submit_batch_job: JobId=46749 InitPrio=23906 usec=396
[2022-07-26T17:42:25.792] _slurm_rpc_submit_batch_job: JobId=46750 InitPrio=23906 usec=543
[2022-07-26T17:42:28.391] _slurm_rpc_submit_batch_job: JobId=46751 InitPrio=23906 usec=646
[2022-07-26T17:42:30.958] _slurm_rpc_submit_batch_job: JobId=46752 InitPrio=23906 usec=523
[2022-07-26T17:42:35.711] _slurm_rpc_submit_batch_job: JobId=46753 InitPrio=23906 usec=420
[2022-07-26T17:42:40.103] _slurm_rpc_submit_batch_job: JobId=46754 InitPrio=23906 usec=394
[2022-07-26T19:31:34.086] _job_complete: JobId=46623 WEXITSTATUS 0
[2022-07-26T19:31:34.086] _job_complete: JobId=46623 done
[2022-07-26T19:31:35.022] sched: Allocate JobId=46719 NodeList=gpu05 #CPUs=16 Partition=gpu-v100s
[2022-07-26T19:31:37.185] _job_complete: JobId=46719 WEXITSTATUS 2
[2022-07-26T19:31:37.186] _job_complete: JobId=46719 done
[2022-07-26T21:11:46.404] _job_complete: JobId=46728 WEXITSTATUS 0
[2022-07-26T21:11:46.404] _job_complete: JobId=46728 done
[2022-07-26T21:11:46.759] sched: Allocate JobId=46729 NodeList=gpu01 #CPUs=16 Partition=gpu-k10
[2022-07-26T21:43:56.607] _slurm_rpc_kill_job: REQUEST_KILL_JOB JobId=46389 uid 548200017
[2022-07-26T21:43:58.663] sched: Allocate JobId=46693 NodeList=cpu01 #CPUs=32 Partition=cpu-opteron
[2022-07-26T21:43:58.678] sched: Allocate JobId=46698 NodeList=cpu01 #CPUs=24 Partition=cpu-opteron
[2022-07-26T21:46:06.408] _job_complete: JobId=46693 WEXITSTATUS 0
[2022-07-26T21:46:06.409] _job_complete: JobId=46693 done
[2022-07-26T21:46:08.391] sched: Allocate JobId=46702 NodeList=cpu01 #CPUs=24 Partition=cpu-opteron
[2022-07-26T21:51:56.118] _slurm_rpc_kill_job: REQUEST_KILL_JOB JobId=46391 uid 548200017
[2022-07-26T21:51:58.180] sched: Allocate JobId=46703 NodeList=cpu08 #CPUs=32 Partition=cpu-opteron
[2022-07-26T21:51:58.181] sched: Allocate JobId=46704 NodeList=cpu08 #CPUs=32 Partition=cpu-opteron
[2022-07-26T22:13:28.717] _job_complete: JobId=46561 WEXITSTATUS 0
[2022-07-26T22:13:28.722] _job_complete: JobId=46561 done
[2022-07-26T22:16:29.283] _slurm_rpc_kill_job: REQUEST_KILL_JOB JobId=46372 uid 548200017
[2022-07-26T22:16:31.200] sched: Allocate JobId=46733 NodeList=cpu12 #CPUs=24 Partition=cpu-epyc
[2022-07-26T22:37:08.561] _slurm_rpc_submit_batch_job: JobId=46755 InitPrio=19331 usec=566
[2022-07-26T22:58:37.969] _job_complete: JobId=46732 WEXITSTATUS 0
[2022-07-26T22:58:37.969] _job_complete: JobId=46732 done
[2022-07-26T22:58:38.330] sched: Allocate JobId=46734 NodeList=cpu14 #CPUs=16 Partition=cpu-epyc
[2022-07-27T01:08:54.858] sched: _slurm_rpc_allocate_resources JobId=46756 NodeList=(null) usec=935
