[2022-11-01T00:30:02.035] _slurm_rpc_submit_batch_job: JobId=51920 InitPrio=1024 usec=709
[2022-11-01T00:30:02.270] sched: Allocate JobId=51920 NodeList=gpu02 #CPUs=5 Partition=gpu-titan
[2022-11-01T00:30:42.937] _slurm_rpc_submit_batch_job: JobId=51921 InitPrio=1024 usec=549
[2022-11-01T00:30:43.306] sched: Allocate JobId=51921 NodeList=gpu02 #CPUs=5 Partition=gpu-titan
[2022-11-01T01:33:34.227] _slurm_rpc_submit_batch_job: JobId=51922 InitPrio=3278 usec=690
[2022-11-01T01:33:35.130] sched: Allocate JobId=51922 NodeList=cpu04 #CPUs=4 Partition=cpu-opteron
[2022-11-01T02:11:16.335] _job_complete: JobId=51381 WEXITSTATUS 0
[2022-11-01T02:11:16.335] _job_complete: JobId=51381 done
[2022-11-01T02:14:02.369] _job_complete: JobId=51922 WEXITSTATUS 1
[2022-11-01T02:14:02.369] _job_complete: JobId=51922 done
[2022-11-01T02:23:29.453] _slurm_rpc_submit_batch_job: JobId=51923 InitPrio=3278 usec=602
[2022-11-01T02:23:29.675] sched: Allocate JobId=51923 NodeList=cpu04 #CPUs=4 Partition=cpu-opteron
[2022-11-01T03:22:30.103] _job_complete: JobId=51923 WEXITSTATUS 0
[2022-11-01T03:22:30.103] _job_complete: JobId=51923 done
[2022-11-01T04:20:53.006] _job_complete: JobId=51837 WEXITSTATUS 0
[2022-11-01T04:20:53.007] _job_complete: JobId=51837 done
[2022-11-01T04:20:53.389] sched: Allocate JobId=51849 NodeList=cpu12 #CPUs=8 Partition=cpu-epyc
[2022-11-01T05:00:00.208] _job_complete: JobId=51846 WEXITSTATUS 0
[2022-11-01T05:00:00.208] _job_complete: JobId=51846 done
[2022-11-01T05:00:00.830] sched: Allocate JobId=51850 NodeList=cpu14 #CPUs=8 Partition=cpu-epyc
[2022-11-01T05:52:39.109] _job_complete: JobId=51848 WEXITSTATUS 0
[2022-11-01T05:52:39.110] _job_complete: JobId=51848 done
[2022-11-01T05:52:39.685] sched: Allocate JobId=51851 NodeList=cpu14 #CPUs=8 Partition=cpu-epyc
[2022-11-01T06:36:38.949] _job_complete: JobId=51839 WEXITSTATUS 0
[2022-11-01T06:36:38.949] _job_complete: JobId=51839 done
[2022-11-01T06:36:39.406] sched: Allocate JobId=51852 NodeList=cpu12 #CPUs=8 Partition=cpu-epyc
[2022-11-01T06:52:14.814] _job_complete: JobId=51844 WEXITSTATUS 0
[2022-11-01T06:52:14.815] _job_complete: JobId=51844 done
[2022-11-01T06:52:15.119] sched: Allocate JobId=51853 NodeList=cpu14 #CPUs=8 Partition=cpu-epyc
[2022-11-01T07:18:54.389] _slurm_rpc_submit_batch_job: JobId=51924 InitPrio=3278 usec=723
[2022-11-01T07:18:55.228] sched: Allocate JobId=51924 NodeList=cpu04 #CPUs=4 Partition=cpu-opteron
[2022-11-01T07:30:27.780] _job_complete: JobId=51924 WEXITSTATUS 1
[2022-11-01T07:30:27.780] _job_complete: JobId=51924 done
[2022-11-01T08:01:10.724] _slurm_rpc_submit_batch_job: JobId=51925 InitPrio=3278 usec=570
[2022-11-01T08:01:10.788] sched: Allocate JobId=51925 NodeList=cpu04 #CPUs=4 Partition=cpu-opteron
[2022-11-01T08:11:22.018] _job_complete: JobId=51925 WEXITSTATUS 1
[2022-11-01T08:11:22.018] _job_complete: JobId=51925 done
[2022-11-01T08:31:02.184] _slurm_rpc_submit_batch_job: JobId=51926 InitPrio=3278 usec=577
[2022-11-01T08:31:03.094] sched: Allocate JobId=51926 NodeList=cpu04 #CPUs=4 Partition=cpu-opteron
[2022-11-01T08:43:05.823] _job_complete: JobId=51926 WEXITSTATUS 1
[2022-11-01T08:43:05.823] _job_complete: JobId=51926 done
[2022-11-01T09:09:55.446] _slurm_rpc_submit_batch_job: JobId=51927 InitPrio=1844 usec=539
[2022-11-01T09:09:58.213] _slurm_rpc_submit_batch_job: JobId=51928 InitPrio=1844 usec=514
[2022-11-01T09:10:00.781] _slurm_rpc_submit_batch_job: JobId=51929 InitPrio=1844 usec=453
[2022-11-01T09:10:03.317] _slurm_rpc_submit_batch_job: JobId=51930 InitPrio=1844 usec=475
[2022-11-01T09:10:05.782] _slurm_rpc_submit_batch_job: JobId=51931 InitPrio=1844 usec=587
[2022-11-01T09:10:08.317] _slurm_rpc_submit_batch_job: JobId=51932 InitPrio=1844 usec=463
[2022-11-01T09:10:10.766] _slurm_rpc_submit_batch_job: JobId=51933 InitPrio=1844 usec=444
[2022-11-01T09:10:13.389] _slurm_rpc_submit_batch_job: JobId=51934 InitPrio=1844 usec=517
[2022-11-01T09:10:15.893] _slurm_rpc_submit_batch_job: JobId=51935 InitPrio=1844 usec=471
[2022-11-01T09:10:19.117] _slurm_rpc_submit_batch_job: JobId=51936 InitPrio=1844 usec=576
[2022-11-01T09:10:22.261] _slurm_rpc_submit_batch_job: JobId=51937 InitPrio=1844 usec=488
[2022-11-01T09:10:25.542] _slurm_rpc_submit_batch_job: JobId=51938 InitPrio=1844 usec=481
[2022-11-01T09:10:28.214] _slurm_rpc_submit_batch_job: JobId=51939 InitPrio=1844 usec=448
[2022-11-01T09:10:30.822] _slurm_rpc_submit_batch_job: JobId=51940 InitPrio=1844 usec=525
[2022-11-01T09:10:33.288] _slurm_rpc_submit_batch_job: JobId=51941 InitPrio=1844 usec=436
[2022-11-01T09:20:46.048] _job_complete: JobId=51841 WEXITSTATUS 0
[2022-11-01T09:20:46.048] _job_complete: JobId=51841 done
[2022-11-01T09:20:46.461] sched: Allocate JobId=51854 NodeList=cpu12 #CPUs=8 Partition=cpu-epyc
[2022-11-01T10:03:38.493] Requeuing JobId=51772
[2022-11-01T10:03:38.495] sched: Allocate JobId=51889 NodeList=cpu10 #CPUs=8 Partition=cpu-opteron
[2022-11-01T10:03:38.496] sched: Allocate JobId=51890 NodeList=cpu10 #CPUs=8 Partition=cpu-opteron
[2022-11-01T10:03:38.496] sched: Allocate JobId=51891 NodeList=cpu10 #CPUs=8 Partition=cpu-opteron
[2022-11-01T10:03:38.497] sched: Allocate JobId=51892 NodeList=cpu10 #CPUs=8 Partition=cpu-opteron
[2022-11-01T10:03:38.498] sched: Allocate JobId=51893 NodeList=cpu10 #CPUs=8 Partition=cpu-opteron
[2022-11-01T10:03:38.498] sched: Allocate JobId=51894 NodeList=cpu10 #CPUs=8 Partition=cpu-opteron
[2022-11-01T10:03:38.499] sched: Allocate JobId=51895 NodeList=cpu10 #CPUs=8 Partition=cpu-opteron
[2022-11-01T10:03:38.590] Requeuing JobId=51771
[2022-11-01T10:03:38.590] sched: Allocate JobId=51896 NodeList=cpu09 #CPUs=8 Partition=cpu-opteron
[2022-11-01T10:03:38.591] sched: Allocate JobId=51897 NodeList=cpu09 #CPUs=8 Partition=cpu-opteron
[2022-11-01T10:03:38.603] sched: Allocate JobId=51898 NodeList=cpu09 #CPUs=8 Partition=cpu-opteron
[2022-11-01T10:03:38.604] sched: Allocate JobId=51899 NodeList=cpu09 #CPUs=8 Partition=cpu-opteron
[2022-11-01T10:03:38.605] sched: Allocate JobId=51900 NodeList=cpu09 #CPUs=8 Partition=cpu-opteron
[2022-11-01T10:03:38.613] sched: Allocate JobId=51901 NodeList=cpu09 #CPUs=8 Partition=cpu-opteron
[2022-11-01T10:03:38.613] sched: Allocate JobId=51902 NodeList=cpu09 #CPUs=8 Partition=cpu-opteron
[2022-11-01T10:03:38.616] Requeuing JobId=51770
[2022-11-01T10:03:38.617] sched: Allocate JobId=51903 NodeList=cpu08 #CPUs=8 Partition=cpu-opteron
[2022-11-01T10:03:38.618] sched: Allocate JobId=51904 NodeList=cpu08 #CPUs=8 Partition=cpu-opteron
[2022-11-01T10:03:38.619] sched: Allocate JobId=51905 NodeList=cpu08 #CPUs=8 Partition=cpu-opteron
[2022-11-01T11:23:41.443] _slurm_rpc_submit_batch_job: JobId=51942 InitPrio=2235 usec=677
[2022-11-01T11:32:18.891] _slurm_rpc_submit_batch_job: JobId=51943 InitPrio=2235 usec=675
[2022-11-01T11:32:32.159] _slurm_rpc_kill_job: REQUEST_KILL_JOB JobId=51943 uid 548300593
[2022-11-01T11:32:32.160] _slurm_rpc_kill_job: REQUEST_KILL_JOB JobId=51873 uid 548300593
[2022-11-01T11:32:33.034] sched: Allocate JobId=51942 NodeList=cpu07 #CPUs=60 Partition=cpu-opteron
[2022-11-01T11:32:49.732] _slurm_rpc_submit_batch_job: JobId=51944 InitPrio=2235 usec=752
[2022-11-01T11:39:08.590] _slurm_rpc_submit_batch_job: JobId=51945 InitPrio=609 usec=542
[2022-11-01T11:39:49.644] sched/backfill: _start_job: Started JobId=51945 in cpu-opteron on cpu04
[2022-11-01T11:40:51.709] _job_complete: JobId=51945 WEXITSTATUS 0
[2022-11-01T11:40:51.709] _job_complete: JobId=51945 done
[2022-11-01T11:50:18.818] _slurm_rpc_submit_batch_job: JobId=51946 InitPrio=2439 usec=1042
[2022-11-01T11:53:24.168] _slurm_rpc_submit_batch_job: JobId=51947 InitPrio=609 usec=534
[2022-11-01T11:53:45.660] _slurm_rpc_submit_batch_job: JobId=51948 InitPrio=2439 usec=443
[2022-11-01T11:53:46.109] sched: Allocate JobId=51948 NodeList=cpu11 #CPUs=16 Partition=cpu-opteron
[2022-11-01T11:53:49.664] sched/backfill: _start_job: Started JobId=51947 in cpu-opteron on cpu04
[2022-11-01T11:54:47.902] _job_complete: JobId=51947 WEXITSTATUS 0
[2022-11-01T11:54:47.902] _job_complete: JobId=51947 done
[2022-11-01T11:59:30.385] _slurm_rpc_submit_batch_job: JobId=51949 InitPrio=2439 usec=965
[2022-11-01T12:00:23.748] _job_complete: JobId=51840 WEXITSTATUS 0
[2022-11-01T12:00:23.748] _job_complete: JobId=51840 done
[2022-11-01T12:00:24.148] sched: Allocate JobId=51855 NodeList=cpu12 #CPUs=8 Partition=cpu-epyc
[2022-11-01T12:03:35.793] _job_complete: JobId=51948 WEXITSTATUS 0
[2022-11-01T12:03:35.794] _job_complete: JobId=51948 done
[2022-11-01T12:08:20.422] _slurm_rpc_submit_batch_job: JobId=51950 InitPrio=609 usec=537
[2022-11-01T12:08:20.705] sched: Allocate JobId=51950 NodeList=gpu03 #CPUs=16 Partition=gpu-k10
[2022-11-01T12:08:53.741] _job_complete: JobId=51950 WEXITSTATUS 1
[2022-11-01T12:08:53.741] _job_complete: JobId=51950 done
[2022-11-01T12:09:15.238] _slurm_rpc_submit_batch_job: JobId=51951 InitPrio=609 usec=821
[2022-11-01T12:09:15.774] sched: Allocate JobId=51951 NodeList=gpu03 #CPUs=16 Partition=gpu-k10
[2022-11-01T12:09:52.522] _job_complete: JobId=51951 WEXITSTATUS 1
[2022-11-01T12:09:52.522] _job_complete: JobId=51951 done
[2022-11-01T12:12:00.388] _slurm_rpc_submit_batch_job: JobId=51952 InitPrio=2439 usec=425
[2022-11-01T12:12:01.133] sched: Allocate JobId=51952 NodeList=cpu11 #CPUs=16 Partition=cpu-opteron
[2022-11-01T12:12:03.983] _job_complete: JobId=51952 WEXITSTATUS 1
[2022-11-01T12:12:03.983] _job_complete: JobId=51952 done
[2022-11-01T12:20:04.384] _slurm_rpc_submit_batch_job: JobId=51953 InitPrio=609 usec=506
[2022-11-01T12:20:49.704] sched/backfill: _start_job: Started JobId=51953 in cpu-opteron on cpu04
[2022-11-01T12:21:49.277] _job_complete: JobId=51953 WEXITSTATUS 0
[2022-11-01T12:21:49.277] _job_complete: JobId=51953 done
[2022-11-01T12:24:21.359] _slurm_rpc_submit_batch_job: JobId=51954 InitPrio=2439 usec=819
[2022-11-01T12:24:22.276] sched: Allocate JobId=51954 NodeList=gpu03 #CPUs=16 Partition=gpu-k10
[2022-11-01T12:27:18.462] _slurm_rpc_submit_batch_job: JobId=51955 InitPrio=609 usec=548
[2022-11-01T12:28:41.607] _slurm_rpc_submit_batch_job: JobId=51956 InitPrio=609 usec=534
[2022-11-01T12:30:30.265] _slurm_rpc_submit_batch_job: JobId=51957 InitPrio=609 usec=514
[2022-11-01T12:30:30.901] sched: Allocate JobId=51957 NodeList=gpu04 #CPUs=16 Partition=gpu-k40c
[2022-11-01T12:31:27.401] _slurm_rpc_kill_job: REQUEST_KILL_JOB JobId=51955 uid 548200021
[2022-11-01T12:31:31.434] _slurm_rpc_kill_job: REQUEST_KILL_JOB JobId=51956 uid 548200021
[2022-11-01T12:32:35.970] _slurm_rpc_submit_batch_job: JobId=51958 InitPrio=609 usec=571
[2022-11-01T12:47:24.786] _slurm_rpc_submit_batch_job: JobId=51959 InitPrio=609 usec=543
[2022-11-01T12:48:15.621] _job_complete: JobId=51842 WEXITSTATUS 0
[2022-11-01T12:48:15.622] _job_complete: JobId=51842 done
[2022-11-01T12:48:15.988] sched: Allocate JobId=51856 NodeList=cpu12 #CPUs=8 Partition=cpu-epyc
[2022-11-01T12:51:25.379] _job_complete: JobId=51954 WEXITSTATUS 1
[2022-11-01T12:51:25.381] _job_complete: JobId=51954 done
[2022-11-01T12:51:25.934] sched: Allocate JobId=51959 NodeList=gpu03 #CPUs=16 Partition=gpu-k10
[2022-11-01T12:51:25.972] _job_complete: JobId=51838 WEXITSTATUS 0
[2022-11-01T12:51:25.972] _job_complete: JobId=51838 done
[2022-11-01T12:51:26.327] sched: Allocate JobId=51927 NodeList=cpu12 #CPUs=8 Partition=cpu-epyc
[2022-11-01T12:52:02.912] _job_complete: JobId=51959 WEXITSTATUS 1
[2022-11-01T12:52:02.912] _job_complete: JobId=51959 done
[2022-11-01T12:56:37.631] _slurm_rpc_submit_batch_job: JobId=51960 InitPrio=609 usec=591
[2022-11-01T12:59:15.967] _slurm_rpc_submit_batch_job: JobId=51961 InitPrio=609 usec=463
[2022-11-01T13:19:43.726] _job_complete: JobId=51957 WEXITSTATUS 1
[2022-11-01T13:19:43.727] _job_complete: JobId=51957 done
[2022-11-01T14:01:46.654] _slurm_rpc_submit_batch_job: JobId=51962 InitPrio=609 usec=645
[2022-11-01T14:01:49.851] sched/backfill: _start_job: Started JobId=51962 in cpu-opteron on cpu04
[2022-11-01T14:03:47.399] _job_complete: JobId=51962 WEXITSTATUS 0
[2022-11-01T14:03:47.399] _job_complete: JobId=51962 done
[2022-11-01T14:04:53.809] _slurm_rpc_kill_job: REQUEST_KILL_JOB JobId=51958 uid 548200021
[2022-11-01T14:09:07.773] _slurm_rpc_submit_batch_job: JobId=51963 InitPrio=609 usec=508
[2022-11-01T14:09:08.432] sched: Allocate JobId=51963 NodeList=gpu03 #CPUs=16 Partition=gpu-k10
[2022-11-01T14:09:45.264] _job_complete: JobId=51963 WEXITSTATUS 1
[2022-11-01T14:09:45.264] _job_complete: JobId=51963 done
[2022-11-01T14:18:02.556] _slurm_rpc_submit_batch_job: JobId=51964 InitPrio=609 usec=542
[2022-11-01T14:18:03.419] sched: Allocate JobId=51964 NodeList=gpu03 #CPUs=16 Partition=gpu-k10
[2022-11-01T14:19:33.967] _slurm_rpc_kill_job: REQUEST_KILL_JOB JobId=51964 uid 548200021
[2022-11-01T14:20:13.527] _slurm_rpc_submit_batch_job: JobId=51965 InitPrio=609 usec=543
[2022-11-01T14:20:49.879] sched/backfill: _start_job: Started JobId=51965 in cpu-opteron on cpu04
[2022-11-01T14:24:37.439] _job_complete: JobId=51965 WEXITSTATUS 0
[2022-11-01T14:24:37.439] _job_complete: JobId=51965 done
[2022-11-01T14:29:54.420] _slurm_rpc_submit_batch_job: JobId=51966 InitPrio=1219 usec=416
[2022-11-01T14:29:54.585] sched: Allocate JobId=51966 NodeList=gpu04 #CPUs=16 Partition=gpu-k40c
[2022-11-01T14:30:49.874] _slurm_rpc_submit_batch_job: JobId=51967 InitPrio=609 usec=456
[2022-11-01T14:30:49.894] sched/backfill: _start_job: Started JobId=51967 in gpu-k10 on gpu03
[2022-11-01T14:32:45.327] _slurm_rpc_kill_job: REQUEST_KILL_JOB JobId=51967 uid 548200021
[2022-11-01T14:34:24.756] _job_create: exceeded association/QOS limit for user 548200021: QOSMaxWallDurationPerJobLimit
[2022-11-01T14:34:24.756] _slurm_rpc_submit_batch_job: Job violates accounting/QOS policy (job submit limit, user's size and/or time limits)
[2022-11-01T14:34:48.283] _job_create: exceeded association/QOS limit for user 548200021: QOSMaxWallDurationPerJobLimit
[2022-11-01T14:34:48.283] _slurm_rpc_submit_batch_job: Job violates accounting/QOS policy (job submit limit, user's size and/or time limits)
[2022-11-01T14:35:07.907] _slurm_rpc_submit_batch_job: JobId=51968 InitPrio=609 usec=572
[2022-11-01T14:35:08.077] sched: Allocate JobId=51968 NodeList=gpu03 #CPUs=16 Partition=gpu-k10
[2022-11-01T14:41:43.627] _job_complete: JobId=51968 WEXITSTATUS 0
[2022-11-01T14:41:43.627] _job_complete: JobId=51968 done
[2022-11-01T14:47:32.292] _slurm_rpc_submit_batch_job: JobId=51969 InitPrio=609 usec=559
[2022-11-01T14:47:49.920] sched/backfill: _start_job: Started JobId=51969 in cpu-opteron on cpu04
[2022-11-01T14:47:53.921] _job_complete: JobId=51969 WEXITSTATUS 0
[2022-11-01T14:47:53.921] _job_complete: JobId=51969 done
[2022-11-01T14:48:00.409] _slurm_rpc_kill_job: REQUEST_KILL_JOB JobId=51942 uid 548300593
[2022-11-01T14:48:04.773] sched: Allocate JobId=51944 NodeList=cpu07 #CPUs=48 Partition=cpu-opteron
[2022-11-01T14:48:35.495] _job_create: exceeded association/QOS limit for user 548200021: QOSMaxWallDurationPerJobLimit
[2022-11-01T14:48:35.495] _slurm_rpc_submit_batch_job: Job violates accounting/QOS policy (job submit limit, user's size and/or time limits)
[2022-11-01T14:49:07.816] _slurm_rpc_submit_batch_job: JobId=51970 InitPrio=609 usec=608
[2022-11-01T14:49:08.471] sched: Allocate JobId=51970 NodeList=gpu03 #CPUs=16 Partition=gpu-k10
[2022-11-01T14:49:09.856] _slurm_rpc_submit_batch_job: JobId=51971 InitPrio=2235 usec=611
[2022-11-01T14:49:42.212] _slurm_rpc_kill_job: REQUEST_KILL_JOB JobId=51944 uid 548300593
[2022-11-01T14:50:18.586] _slurm_rpc_submit_batch_job: JobId=51972 InitPrio=2235 usec=594
[2022-11-01T14:54:50.330] _slurm_rpc_kill_job: REQUEST_KILL_JOB JobId=51970 uid 548200021
[2022-11-01T14:55:05.147] _slurm_rpc_submit_batch_job: JobId=51973 InitPrio=609 usec=570
[2022-11-01T14:55:08.067] sched: Allocate JobId=51973 NodeList=gpu03 #CPUs=16 Partition=gpu-k10
[2022-11-01T14:55:30.136] _job_complete: JobId=51973 WEXITSTATUS 1
[2022-11-01T14:55:30.136] _job_complete: JobId=51973 done
[2022-11-01T14:57:29.133] _slurm_rpc_submit_batch_job: JobId=51974 InitPrio=609 usec=505
[2022-11-01T14:57:29.365] sched: Allocate JobId=51974 NodeList=gpu03 #CPUs=16 Partition=gpu-k10
[2022-11-01T14:57:51.294] _job_complete: JobId=51974 WEXITSTATUS 1
[2022-11-01T14:57:51.294] _job_complete: JobId=51974 done
[2022-11-01T14:59:13.883] _job_complete: JobId=51845 WEXITSTATUS 0
[2022-11-01T14:59:13.883] _job_complete: JobId=51845 done
[2022-11-01T14:59:14.203] sched: Allocate JobId=51928 NodeList=cpu14 #CPUs=8 Partition=cpu-epyc
[2022-11-01T15:04:21.982] _slurm_rpc_submit_batch_job: JobId=51975 InitPrio=609 usec=692
[2022-11-01T15:04:22.009] sched: Allocate JobId=51975 NodeList=gpu03 #CPUs=16 Partition=gpu-k10
[2022-11-01T15:09:40.354] _job_complete: JobId=51975 WEXITSTATUS 0
[2022-11-01T15:09:40.355] _job_complete: JobId=51975 done
[2022-11-01T15:11:56.367] _slurm_rpc_submit_batch_job: JobId=51976 InitPrio=609 usec=613
[2022-11-01T15:11:56.959] sched: Allocate JobId=51976 NodeList=gpu03 #CPUs=16 Partition=gpu-k10
[2022-11-01T15:12:00.241] _job_complete: JobId=51976 WEXITSTATUS 0
[2022-11-01T15:12:00.241] _job_complete: JobId=51976 done
[2022-11-01T15:13:20.156] _slurm_rpc_submit_batch_job: JobId=51977 InitPrio=609 usec=629
[2022-11-01T15:13:21.062] sched: Allocate JobId=51977 NodeList=gpu03 #CPUs=16 Partition=gpu-k10
[2022-11-01T15:16:50.725] _slurm_rpc_submit_batch_job: JobId=51978 InitPrio=609 usec=536
[2022-11-01T15:17:49.968] sched/backfill: _start_job: Started JobId=51978 in cpu-opteron on cpu04
[2022-11-01T15:17:51.962] _job_complete: JobId=51978 WEXITSTATUS 1
[2022-11-01T15:17:51.962] _job_complete: JobId=51978 done
[2022-11-01T15:18:39.959] _slurm_rpc_submit_batch_job: JobId=51979 InitPrio=609 usec=449
[2022-11-01T15:18:49.970] sched/backfill: _start_job: Started JobId=51979 in cpu-opteron on cpu04
[2022-11-01T15:18:53.458] _job_complete: JobId=51979 WEXITSTATUS 0
[2022-11-01T15:18:53.458] _job_complete: JobId=51979 done
[2022-11-01T15:20:40.666] _slurm_rpc_submit_batch_job: JobId=51980 InitPrio=609 usec=577
[2022-11-01T15:21:01.438] _job_complete: JobId=51755 WEXITSTATUS 0
[2022-11-01T15:21:01.444] _job_complete: JobId=51755 done
[2022-11-01T15:21:02.013] sched: Allocate JobId=51929 NodeList=cpu15 #CPUs=8 Partition=cpu-epyc
[2022-11-01T15:21:02.014] sched: Allocate JobId=51930 NodeList=cpu15 #CPUs=8 Partition=cpu-epyc
[2022-11-01T15:21:02.015] sched: Allocate JobId=51931 NodeList=cpu15 #CPUs=8 Partition=cpu-epyc
[2022-11-01T15:23:37.040] No nodes satisfy requirements for JobId=51981 in partition gpu-titan
[2022-11-01T15:23:37.040] _slurm_rpc_submit_batch_job: Requested node configuration is not available
[2022-11-01T15:24:10.325] _slurm_rpc_submit_batch_job: JobId=51982 InitPrio=609 usec=504
[2022-11-01T15:24:14.193] _job_complete: JobId=51843 WEXITSTATUS 0
[2022-11-01T15:24:14.193] _job_complete: JobId=51843 done
[2022-11-01T15:24:14.523] sched: Allocate JobId=51932 NodeList=cpu14 #CPUs=8 Partition=cpu-epyc
[2022-11-01T15:58:53.192] _slurm_rpc_submit_batch_job: JobId=51983 InitPrio=2439 usec=754
[2022-11-01T16:11:06.985] _slurm_rpc_submit_batch_job: JobId=51984 InitPrio=2439 usec=570
[2022-11-01T16:11:08.023] sched: Allocate JobId=51984 NodeList=cpu11 #CPUs=16 Partition=cpu-opteron
[2022-11-01T16:12:29.294] _job_complete: JobId=51984 WEXITSTATUS 0
[2022-11-01T16:12:29.294] _job_complete: JobId=51984 done
[2022-11-01T16:51:16.027] Time limit exhausted for JobId=51689
[2022-11-01T16:51:18.548] sched: Allocate JobId=51971 NodeList=cpu07 #CPUs=64 Partition=cpu-opteron
[2022-11-01T17:33:30.768] _job_complete: JobId=51847 WEXITSTATUS 0
[2022-11-01T17:33:30.768] _job_complete: JobId=51847 done
[2022-11-01T17:33:31.110] sched: Allocate JobId=51933 NodeList=cpu14 #CPUs=8 Partition=cpu-epyc
[2022-11-01T20:24:21.864] _job_complete: JobId=51849 WEXITSTATUS 0
[2022-11-01T20:24:21.865] _job_complete: JobId=51849 done
[2022-11-01T20:24:22.347] sched: Allocate JobId=51934 NodeList=cpu12 #CPUs=8 Partition=cpu-epyc
[2022-11-01T21:06:00.287] _job_complete: JobId=51820 WEXITSTATUS 0
[2022-11-01T21:06:00.294] _job_complete: JobId=51820 done
[2022-11-01T21:06:01.367] sched: Allocate JobId=51935 NodeList=cpu15 #CPUs=8 Partition=cpu-epyc
[2022-11-01T21:06:01.368] sched: Allocate JobId=51936 NodeList=cpu15 #CPUs=8 Partition=cpu-epyc
[2022-11-01T21:06:01.369] sched: Allocate JobId=51937 NodeList=cpu15 #CPUs=8 Partition=cpu-epyc
[2022-11-01T22:24:26.695] _slurm_rpc_submit_batch_job: JobId=51985 InitPrio=3252 usec=590
[2022-11-01T22:24:27.553] sched: Allocate JobId=51985 NodeList=cpu04 #CPUs=4 Partition=cpu-opteron
[2022-11-01T22:35:35.165] _job_complete: JobId=51985 WEXITSTATUS 1
[2022-11-01T22:35:35.166] _job_complete: JobId=51985 done
[2022-11-02T06:47:06.227] _slurm_rpc_submit_batch_job: JobId=51986 InitPrio=3252 usec=684
[2022-11-02T06:47:08.186] sched: Allocate JobId=51986 NodeList=cpu04 #CPUs=4 Partition=cpu-opteron
[2022-11-02T07:26:50.926] _job_complete: JobId=51986 WEXITSTATUS 0
[2022-11-02T07:26:50.926] _job_complete: JobId=51986 done
[2022-11-02T08:26:13.992] _job_complete: JobId=51854 WEXITSTATUS 0
[2022-11-02T08:26:13.993] _job_complete: JobId=51854 done
[2022-11-02T08:26:51.514] sched/backfill: _start_job: Started JobId=51938 in cpu-epyc on cpu12
[2022-11-02T08:30:48.758] _job_complete: JobId=51927 WEXITSTATUS 0
[2022-11-02T08:30:48.758] _job_complete: JobId=51927 done
[2022-11-02T08:30:51.521] sched/backfill: _start_job: Started JobId=51939 in cpu-epyc on cpu12
[2022-11-02T08:39:34.272] _job_complete: JobId=51930 WEXITSTATUS 0
[2022-11-02T08:39:34.272] _job_complete: JobId=51930 done
[2022-11-02T08:39:51.536] sched/backfill: _start_job: Started JobId=51940 in cpu-epyc on cpu15
[2022-11-02T08:45:24.803] _job_complete: JobId=51929 WEXITSTATUS 0
[2022-11-02T08:45:24.803] _job_complete: JobId=51929 done
[2022-11-02T08:45:51.545] sched/backfill: _start_job: Started JobId=51941 in cpu-epyc on cpu15
[2022-11-02T08:49:52.742] _job_complete: JobId=51931 WEXITSTATUS 0
[2022-11-02T08:49:52.742] _job_complete: JobId=51931 done
[2022-11-02T08:52:27.692] _slurm_rpc_submit_batch_job: JobId=51987 InitPrio=3252 usec=624
[2022-11-02T08:52:27.900] sched: Allocate JobId=51987 NodeList=cpu04 #CPUs=4 Partition=cpu-opteron
[2022-11-02T09:04:15.264] _job_complete: JobId=51987 WEXITSTATUS 1
[2022-11-02T09:04:15.265] _job_complete: JobId=51987 done
[2022-11-02T10:14:13.607] _job_complete: JobId=51928 WEXITSTATUS 0
[2022-11-02T10:14:13.607] _job_complete: JobId=51928 done
[2022-11-02T12:32:05.820] _job_complete: JobId=51805 WEXITSTATUS 0
[2022-11-02T12:32:05.820] _job_complete: JobId=51805 done
[2022-11-02T12:32:07.169] sched: Allocate JobId=51972 NodeList=cpu01 #CPUs=64 Partition=cpu-opteron
[2022-11-02T12:39:55.645] _job_complete: JobId=51966 WEXITSTATUS 1
[2022-11-02T12:39:55.650] _job_complete: JobId=51966 done
[2022-11-02T13:03:49.629] _job_complete: JobId=51853 WEXITSTATUS 0
[2022-11-02T13:03:49.629] _job_complete: JobId=51853 done
[2022-11-02T13:09:09.494] _job_complete: JobId=51856 WEXITSTATUS 0
[2022-11-02T13:09:09.494] _job_complete: JobId=51856 done
[2022-11-02T13:24:42.983] _slurm_rpc_submit_batch_job: JobId=51988 InitPrio=1422 usec=607
[2022-11-02T13:24:43.256] sched: Allocate JobId=51988 NodeList=gpu04 #CPUs=16 Partition=gpu-k40c
[2022-11-02T14:03:32.479] _job_complete: JobId=51852 WEXITSTATUS 0
[2022-11-02T14:03:32.479] _job_complete: JobId=51852 done
[2022-11-02T14:04:19.112] _slurm_rpc_submit_batch_job: JobId=51989 InitPrio=2439 usec=538
[2022-11-02T14:04:19.415] sched: Allocate JobId=51989 NodeList=cpu11 #CPUs=16 Partition=cpu-opteron
[2022-11-02T14:08:28.542] _slurm_rpc_submit_batch_job: JobId=51990 InitPrio=2439 usec=477
[2022-11-02T14:08:28.872] sched: Allocate JobId=51990 NodeList=cpu08 #CPUs=32 Partition=cpu-opteron
[2022-11-02T14:08:36.245] _job_complete: JobId=51990 WEXITSTATUS 0
[2022-11-02T14:08:36.246] _job_complete: JobId=51990 done
[2022-11-02T14:11:02.002] _job_complete: JobId=51935 WEXITSTATUS 0
[2022-11-02T14:11:02.002] _job_complete: JobId=51935 done
[2022-11-02T14:11:30.479] _job_complete: JobId=51936 WEXITSTATUS 0
[2022-11-02T14:11:30.479] _job_complete: JobId=51936 done
[2022-11-02T14:11:30.981] sched: Allocate JobId=51919 NodeList=cpu15 #CPUs=24 Partition=cpu-epyc
[2022-11-02T14:18:12.635] _slurm_rpc_submit_batch_job: JobId=51991 InitPrio=2439 usec=416
[2022-11-02T14:18:12.864] sched: Allocate JobId=51991 NodeList=cpu08 #CPUs=32 Partition=cpu-opteron
[2022-11-02T14:18:33.634] _job_complete: JobId=51991 WEXITSTATUS 0
[2022-11-02T14:18:33.634] _job_complete: JobId=51991 done
[2022-11-02T14:20:11.877] _slurm_rpc_submit_batch_job: JobId=51992 InitPrio=2439 usec=461
[2022-11-02T14:20:12.016] sched: Allocate JobId=51992 NodeList=cpu08 #CPUs=32 Partition=cpu-opteron
[2022-11-02T14:20:55.811] _job_complete: JobId=51992 WEXITSTATUS 0
[2022-11-02T14:20:55.811] _job_complete: JobId=51992 done
[2022-11-02T14:28:52.733] _slurm_rpc_submit_batch_job: JobId=51993 InitPrio=2439 usec=475
[2022-11-02T14:28:53.129] sched: Allocate JobId=51993 NodeList=cpu08 #CPUs=32 Partition=cpu-opteron
[2022-11-02T14:29:47.694] _job_complete: JobId=51993 WEXITSTATUS 1
[2022-11-02T14:29:47.694] _job_complete: JobId=51993 done
[2022-11-02T14:33:41.176] _job_complete: JobId=51989 WEXITSTATUS 0
[2022-11-02T14:33:41.177] _job_complete: JobId=51989 done
[2022-11-02T14:33:41.435] _job_complete: JobId=51971 WEXITSTATUS 0
[2022-11-02T14:33:41.440] _job_complete: JobId=51971 done
[2022-11-02T14:33:44.821] sched: Allocate JobId=51907 NodeList=cpu07 #CPUs=64 Partition=cpu-opteron
[2022-11-02T14:38:51.150] _job_complete: JobId=51851 WEXITSTATUS 0
[2022-11-02T14:38:51.150] _job_complete: JobId=51851 done
[2022-11-02T14:44:35.320] _slurm_rpc_submit_batch_job: JobId=51994 InitPrio=2439 usec=463
[2022-11-02T14:44:35.677] sched: Allocate JobId=51994 NodeList=cpu08 #CPUs=32 Partition=cpu-opteron
[2022-11-02T14:44:38.143] _job_complete: JobId=51994 WEXITSTATUS 1
[2022-11-02T14:44:38.143] _job_complete: JobId=51994 done
[2022-11-02T14:52:28.583] _slurm_rpc_submit_batch_job: JobId=51995 InitPrio=2439 usec=572
[2022-11-02T14:52:29.580] sched: Allocate JobId=51995 NodeList=cpu08 #CPUs=32 Partition=cpu-opteron
[2022-11-02T14:52:32.061] _job_complete: JobId=51995 WEXITSTATUS 1
[2022-11-02T14:52:32.061] _job_complete: JobId=51995 done
[2022-11-02T15:30:24.523] _job_complete: JobId=51921 WEXITSTATUS 0
[2022-11-02T15:30:24.523] _job_complete: JobId=51921 done
[2022-11-02T15:30:25.701] sched: Allocate JobId=51946 NodeList=gpu02 #CPUs=8 Partition=gpu-titan
[2022-11-02T15:30:39.011] _job_complete: JobId=51855 WEXITSTATUS 0
[2022-11-02T15:30:39.011] _job_complete: JobId=51855 done
[2022-11-02T15:35:51.329] _job_complete: JobId=51946 WEXITSTATUS 255
[2022-11-02T15:35:51.330] _job_complete: JobId=51946 done
[2022-11-02T15:35:51.913] sched: Allocate JobId=51949 NodeList=gpu02 #CPUs=8 Partition=gpu-titan
[2022-11-02T15:40:48.867] _job_complete: JobId=51949 WEXITSTATUS 255
[2022-11-02T15:40:48.867] _job_complete: JobId=51949 done
[2022-11-02T16:53:11.231] _job_complete: JobId=51920 WEXITSTATUS 0
[2022-11-02T16:53:11.231] _job_complete: JobId=51920 done
[2022-11-02T16:53:12.549] sched: Allocate JobId=51982 NodeList=gpu02 #CPUs=16 Partition=gpu-titan
[2022-11-02T16:54:10.630] _job_complete: JobId=51937 WEXITSTATUS 0
[2022-11-02T16:54:10.630] _job_complete: JobId=51937 done
[2022-11-02T18:14:40.773] _job_complete: JobId=51932 WEXITSTATUS 0
[2022-11-02T18:14:40.773] _job_complete: JobId=51932 done
[2022-11-02T19:24:19.137] _job_complete: JobId=51934 WEXITSTATUS 0
[2022-11-02T19:24:19.137] _job_complete: JobId=51934 done
[2022-11-02T19:59:34.407] _slurm_rpc_submit_batch_job: JobId=51996 InitPrio=2235 usec=689
[2022-11-02T20:01:26.935] _job_complete: JobId=51933 WEXITSTATUS 0
[2022-11-02T20:01:26.935] _job_complete: JobId=51933 done
[2022-11-02T20:04:37.895] _slurm_rpc_kill_job: REQUEST_KILL_JOB JobId=51972 uid 548300593
[2022-11-02T20:04:39.085] sched: Allocate JobId=51908 NodeList=cpu01 #CPUs=64 Partition=cpu-opteron
[2022-11-02T20:06:33.130] _slurm_rpc_submit_batch_job: JobId=51997 InitPrio=2235 usec=486
[2022-11-02T21:52:24.639] _job_complete: JobId=51977 WEXITSTATUS 1
[2022-11-02T21:52:24.639] _job_complete: JobId=51977 done
[2022-11-02T21:52:28.768] sched: Allocate JobId=51983 NodeList=gpu03 #CPUs=16 Partition=gpu-k10
[2022-11-02T22:55:37.986] _slurm_rpc_submit_batch_job: JobId=51998 InitPrio=3252 usec=614
[2022-11-02T22:55:38.391] sched: Allocate JobId=51998 NodeList=cpu04 #CPUs=4 Partition=cpu-opteron
[2022-11-02T22:56:41.316] sched: _slurm_rpc_allocate_resources JobId=51999 NodeList=(null) usec=1007
[2022-11-02T22:56:53.427] sched/backfill: _start_job: Started JobId=51999 in cpu-opteron on cpu09
[2022-11-02T23:20:30.283] _slurm_rpc_submit_batch_job: JobId=52000 InitPrio=1016 usec=660
[2022-11-02T23:21:02.836] _slurm_rpc_kill_job: REQUEST_KILL_JOB JobId=52000 uid 548200023
[2022-11-02T23:21:28.931] _slurm_rpc_submit_batch_job: JobId=52001 InitPrio=1016 usec=642
[2022-11-02T23:22:13.125] _slurm_rpc_kill_job: REQUEST_KILL_JOB JobId=52001 uid 548200023
[2022-11-02T23:22:34.267] _slurm_rpc_submit_batch_job: JobId=52002 InitPrio=1016 usec=600
[2022-11-02T23:28:44.131] _job_complete: JobId=51999 WEXITSTATUS 0
[2022-11-02T23:28:44.131] _job_complete: JobId=51999 done
[2022-11-02T23:41:02.375] _slurm_rpc_submit_batch_job: JobId=52003 InitPrio=1016 usec=516
[2022-11-02T23:55:07.664] _job_complete: JobId=51998 WEXITSTATUS 0
[2022-11-02T23:55:07.664] _job_complete: JobId=51998 done
[2022-11-03T01:04:22.187] _job_complete: JobId=51810 WEXITSTATUS 0
[2022-11-03T01:04:22.188] _job_complete: JobId=51810 done
[2022-11-03T01:04:23.327] sched: Allocate JobId=51996 NodeList=cpu03 #CPUs=64 Partition=cpu-opteron
[2022-11-03T01:04:23.835] _job_complete: JobId=51996 WEXITSTATUS 1
[2022-11-03T01:04:23.836] _job_complete: JobId=51996 done
[2022-11-03T01:04:24.427] sched: Allocate JobId=51997 NodeList=cpu03 #CPUs=64 Partition=cpu-opteron
[2022-11-03T01:54:06.078] _job_complete: JobId=51940 WEXITSTATUS 0
[2022-11-03T01:54:06.078] _job_complete: JobId=51940 done
[2022-11-03T02:59:49.361] _job_complete: JobId=51938 WEXITSTATUS 0
[2022-11-03T02:59:49.361] _job_complete: JobId=51938 done
[2022-11-03T03:48:19.043] _job_complete: JobId=51939 WEXITSTATUS 0
[2022-11-03T03:48:19.044] _job_complete: JobId=51939 done
[2022-11-03T03:48:19.527] sched: Allocate JobId=51960 NodeList=cpu12 #CPUs=48 Partition=cpu-epyc
[2022-11-03T05:02:37.767] _job_complete: JobId=51907 WEXITSTATUS 0
[2022-11-03T05:02:37.767] _job_complete: JobId=51907 done
[2022-11-03T07:19:00.187] _job_complete: JobId=51941 WEXITSTATUS 0
[2022-11-03T07:19:00.187] _job_complete: JobId=51941 done
[2022-11-03T07:46:18.586] _job_complete: JobId=51960 WEXITSTATUS 0
[2022-11-03T07:46:18.587] _job_complete: JobId=51960 done
[2022-11-03T07:46:19.056] sched: Allocate JobId=51961 NodeList=cpu12 #CPUs=48 Partition=cpu-epyc
[2022-11-03T09:09:21.479] sched: _slurm_rpc_allocate_resources JobId=52004 NodeList=cpu04 usec=85517
[2022-11-03T09:16:29.090] _slurm_rpc_submit_batch_job: JobId=52005 InitPrio=1219 usec=663
[2022-11-03T09:16:29.624] sched: Allocate JobId=52005 NodeList=cpu15 #CPUs=8 Partition=cpu-epyc
[2022-11-03T09:16:31.913] _slurm_rpc_submit_batch_job: JobId=52006 InitPrio=1219 usec=562
[2022-11-03T09:16:32.629] sched: Allocate JobId=52006 NodeList=cpu15 #CPUs=8 Partition=cpu-epyc
[2022-11-03T09:16:34.466] _slurm_rpc_submit_batch_job: JobId=52007 InitPrio=1219 usec=453
[2022-11-03T09:16:35.633] sched: Allocate JobId=52007 NodeList=cpu15 #CPUs=8 Partition=cpu-epyc
[2022-11-03T09:16:37.083] _slurm_rpc_submit_batch_job: JobId=52008 InitPrio=1219 usec=442
[2022-11-03T09:16:38.636] sched: Allocate JobId=52008 NodeList=cpu14 #CPUs=8 Partition=cpu-epyc
[2022-11-03T09:16:40.417] _slurm_rpc_submit_batch_job: JobId=52009 InitPrio=1219 usec=424
[2022-11-03T09:16:41.640] sched: Allocate JobId=52009 NodeList=cpu14 #CPUs=8 Partition=cpu-epyc
[2022-11-03T09:16:43.266] _slurm_rpc_submit_batch_job: JobId=52010 InitPrio=1219 usec=416
[2022-11-03T09:16:44.644] sched: Allocate JobId=52010 NodeList=cpu14 #CPUs=8 Partition=cpu-epyc
[2022-11-03T09:16:46.089] _slurm_rpc_submit_batch_job: JobId=52011 InitPrio=1219 usec=425
[2022-11-03T09:16:47.648] sched: Allocate JobId=52011 NodeList=cpu14 #CPUs=8 Partition=cpu-epyc
[2022-11-03T09:16:48.843] _slurm_rpc_submit_batch_job: JobId=52012 InitPrio=1219 usec=539
[2022-11-03T09:16:50.651] sched: Allocate JobId=52012 NodeList=cpu14 #CPUs=8 Partition=cpu-epyc
[2022-11-03T09:16:51.561] _slurm_rpc_submit_batch_job: JobId=52013 InitPrio=1219 usec=493
[2022-11-03T09:16:54.136] _slurm_rpc_submit_batch_job: JobId=52014 InitPrio=1219 usec=535
[2022-11-03T09:16:56.882] _slurm_rpc_submit_batch_job: JobId=52015 InitPrio=1219 usec=568
[2022-11-03T09:16:59.544] _slurm_rpc_submit_batch_job: JobId=52016 InitPrio=1219 usec=444
[2022-11-03T09:17:02.067] _slurm_rpc_submit_batch_job: JobId=52017 InitPrio=1219 usec=445
[2022-11-03T09:17:04.650] _slurm_rpc_submit_batch_job: JobId=52018 InitPrio=1219 usec=507
[2022-11-03T09:17:07.779] _slurm_rpc_submit_batch_job: JobId=52019 InitPrio=1219 usec=564
[2022-11-03T09:17:10.218] _slurm_rpc_submit_batch_job: JobId=52020 InitPrio=1219 usec=598
[2022-11-03T09:17:12.721] _slurm_rpc_submit_batch_job: JobId=52021 InitPrio=1219 usec=478
[2022-11-03T09:17:15.218] _slurm_rpc_submit_batch_job: JobId=52022 InitPrio=1219 usec=467
[2022-11-03T09:17:17.641] _slurm_rpc_submit_batch_job: JobId=52023 InitPrio=1219 usec=410
[2022-11-03T09:17:20.050] _slurm_rpc_submit_batch_job: JobId=52024 InitPrio=1219 usec=417
[2022-11-03T09:17:22.763] _slurm_rpc_submit_batch_job: JobId=52025 InitPrio=1219 usec=495
[2022-11-03T09:17:25.437] _slurm_rpc_submit_batch_job: JobId=52026 InitPrio=1219 usec=496
[2022-11-03T09:17:28.386] _slurm_rpc_submit_batch_job: JobId=52027 InitPrio=1219 usec=593
[2022-11-03T09:17:31.210] _slurm_rpc_submit_batch_job: JobId=52028 InitPrio=1219 usec=449
[2022-11-03T09:17:34.683] _slurm_rpc_submit_batch_job: JobId=52029 InitPrio=1219 usec=495
[2022-11-03T09:17:37.370] _slurm_rpc_submit_batch_job: JobId=52030 InitPrio=1219 usec=530
[2022-11-03T09:17:40.370] _slurm_rpc_submit_batch_job: JobId=52031 InitPrio=1219 usec=608
[2022-11-03T09:17:43.489] _slurm_rpc_submit_batch_job: JobId=52032 InitPrio=1219 usec=468
[2022-11-03T09:17:46.514] _slurm_rpc_submit_batch_job: JobId=52033 InitPrio=1219 usec=438
[2022-11-03T09:17:49.178] _slurm_rpc_submit_batch_job: JobId=52034 InitPrio=1219 usec=514
[2022-11-03T09:17:58.370] _slurm_rpc_submit_batch_job: JobId=52035 InitPrio=1219 usec=528
[2022-11-03T09:18:01.252] _slurm_rpc_submit_batch_job: JobId=52036 InitPrio=1219 usec=877
[2022-11-03T09:57:55.011] _slurm_rpc_submit_batch_job: JobId=52037 InitPrio=17926 usec=684
[2022-11-03T09:57:55.166] sched: Allocate JobId=52037 NodeList=cpu09 #CPUs=1 Partition=cpu-opteron
[2022-11-03T10:01:26.455] _job_complete: JobId=52037 WEXITSTATUS 0
[2022-11-03T10:01:26.456] _job_complete: JobId=52037 done
[2022-11-03T10:05:09.097] _slurm_rpc_submit_batch_job: JobId=52038 InitPrio=17926 usec=498
[2022-11-03T10:05:09.819] sched: Allocate JobId=52038 NodeList=cpu09 #CPUs=1 Partition=cpu-opteron
[2022-11-03T10:05:24.239] _job_complete: JobId=52038 WEXITSTATUS 1
[2022-11-03T10:05:24.239] _job_complete: JobId=52038 done
[2022-11-03T10:09:24.629] Time limit exhausted for JobId=52004
[2022-11-03T10:13:59.729] _slurm_rpc_submit_batch_job: JobId=52039 InitPrio=17926 usec=581
[2022-11-03T10:14:00.096] sched: Allocate JobId=52039 NodeList=cpu09 #CPUs=1 Partition=cpu-opteron
[2022-11-03T10:14:13.610] _job_complete: JobId=52039 WEXITSTATUS 1
[2022-11-03T10:14:13.610] _job_complete: JobId=52039 done
[2022-11-03T10:14:27.648] cleanup_completing: JobId=52004 completion process took 303 seconds
[2022-11-03T10:25:39.430] _slurm_rpc_submit_batch_job: JobId=52040 InitPrio=17926 usec=829
[2022-11-03T10:25:40.404] sched: Allocate JobId=52040 NodeList=cpu04 #CPUs=1 Partition=cpu-opteron
[2022-11-03T10:26:05.454] _job_complete: JobId=52040 WEXITSTATUS 0
[2022-11-03T10:26:05.454] _job_complete: JobId=52040 done
[2022-11-03T10:27:49.900] _slurm_rpc_submit_batch_job: JobId=52041 InitPrio=17926 usec=577
[2022-11-03T10:27:50.681] sched: Allocate JobId=52041 NodeList=cpu04 #CPUs=1 Partition=cpu-opteron
[2022-11-03T10:28:10.970] _job_complete: JobId=52041 WEXITSTATUS 0
[2022-11-03T10:28:10.970] _job_complete: JobId=52041 done
[2022-11-03T11:37:12.495] _job_complete: JobId=51961 WEXITSTATUS 0
[2022-11-03T11:37:12.495] _job_complete: JobId=51961 done
[2022-11-03T11:37:12.962] sched: Allocate JobId=52013 NodeList=cpu12 #CPUs=8 Partition=cpu-epyc
[2022-11-03T11:37:12.963] sched: Allocate JobId=52014 NodeList=cpu12 #CPUs=8 Partition=cpu-epyc
[2022-11-03T11:37:12.964] sched: Allocate JobId=52015 NodeList=cpu12 #CPUs=8 Partition=cpu-epyc
[2022-11-03T11:37:12.964] sched: Allocate JobId=52016 NodeList=cpu12 #CPUs=8 Partition=cpu-epyc
[2022-11-03T11:37:12.965] sched: Allocate JobId=52017 NodeList=cpu12 #CPUs=8 Partition=cpu-epyc
[2022-11-03T11:37:12.966] sched: Allocate JobId=52018 NodeList=cpu12 #CPUs=8 Partition=cpu-epyc
[2022-11-03T12:33:25.347] _job_complete: JobId=51850 WEXITSTATUS 0
[2022-11-03T12:33:25.347] _job_complete: JobId=51850 done
[2022-11-03T12:33:25.744] sched: Allocate JobId=52019 NodeList=cpu14 #CPUs=8 Partition=cpu-epyc
[2022-11-03T12:35:25.624] _slurm_rpc_kill_job: REQUEST_KILL_JOB JobId=51997 uid 548300593
[2022-11-03T12:46:10.715] sched: _slurm_rpc_allocate_resources JobId=52042 NodeList=(null) usec=1383
[2022-11-03T12:46:11.308] sched: Allocate JobId=52042 NodeList=cpu04 #CPUs=1 Partition=cpu-opteron
[2022-11-03T13:14:14.926] sched: _slurm_rpc_allocate_resources JobId=52043 NodeList=cpu04 usec=22140
[2022-11-03T13:31:09.366] sched: _slurm_rpc_allocate_resources JobId=52044 NodeList=cpu03 usec=2406
[2022-11-03T13:37:53.625] _job_complete: JobId=52044 WEXITSTATUS 0
[2022-11-03T13:37:53.625] _job_complete: JobId=52044 done
[2022-11-03T13:38:03.306] _job_complete: JobId=52043 WEXITSTATUS 0
[2022-11-03T13:38:03.306] _job_complete: JobId=52043 done
[2022-11-03T15:02:03.071] _slurm_rpc_submit_batch_job: JobId=52045 InitPrio=2226 usec=765
[2022-11-03T15:02:03.638] sched: Allocate JobId=52045 NodeList=cpu03 #CPUs=10 Partition=cpu-opteron
[2022-11-03T15:02:48.076] _slurm_rpc_submit_batch_job: JobId=52046 InitPrio=2226 usec=581
[2022-11-03T15:02:48.677] sched: Allocate JobId=52046 NodeList=cpu07 #CPUs=64 Partition=cpu-opteron
[2022-11-03T15:02:49.185] _job_complete: JobId=52046 WEXITSTATUS 1
[2022-11-03T15:02:49.186] _job_complete: JobId=52046 done
[2022-11-03T15:04:59.251] _slurm_rpc_submit_batch_job: JobId=52047 InitPrio=2226 usec=686
[2022-11-03T15:04:59.843] sched: Allocate JobId=52047 NodeList=cpu07 #CPUs=64 Partition=cpu-opteron
[2022-11-03T15:05:00.166] _job_complete: JobId=52047 WEXITSTATUS 1
[2022-11-03T15:05:00.167] _job_complete: JobId=52047 done
[2022-11-03T15:18:47.324] _slurm_rpc_submit_batch_job: JobId=52048 InitPrio=809 usec=483
[2022-11-03T15:21:30.282] _slurm_rpc_submit_batch_job: JobId=52049 InitPrio=2226 usec=455
[2022-11-03T15:21:30.602] sched: Allocate JobId=52049 NodeList=cpu07 #CPUs=64 Partition=cpu-opteron
[2022-11-03T15:21:30.913] _job_complete: JobId=52049 WEXITSTATUS 1
[2022-11-03T15:21:30.913] _job_complete: JobId=52049 done
[2022-11-03T15:21:56.565] _slurm_rpc_kill_job: REQUEST_KILL_JOB JobId=52049 uid 548300593
[2022-11-03T15:22:16.635] _slurm_rpc_submit_batch_job: JobId=52050 InitPrio=2226 usec=652
[2022-11-03T15:22:26.878] _slurm_rpc_kill_job: REQUEST_KILL_JOB JobId=52049 uid 548300593
[2022-11-03T15:22:36.718] _slurm_rpc_kill_job: REQUEST_KILL_JOB JobId=52049 uid 548300593
[2022-11-03T15:22:37.742] _slurm_rpc_kill_job: REQUEST_KILL_JOB JobId=52049 uid 548300593
[2022-11-03T15:26:58.628] cleanup_completing: JobId=52049 completion process took 328 seconds
[2022-11-03T15:26:58.629] sched: Allocate JobId=52050 NodeList=cpu07 #CPUs=64 Partition=cpu-opteron
[2022-11-03T15:27:00.184] _job_complete: JobId=52050 WEXITSTATUS 2
[2022-11-03T15:27:00.185] _job_complete: JobId=52050 done
[2022-11-03T15:49:46.808] _slurm_rpc_submit_batch_job: JobId=52051 InitPrio=1012 usec=494
[2022-11-03T15:49:47.354] sched: Allocate JobId=52051 NodeList=cpu[03-04] #CPUs=2 Partition=cpu-opteron
[2022-11-03T15:49:49.468] _job_complete: JobId=52051 WEXITSTATUS 127
[2022-11-03T15:49:49.468] _job_complete: JobId=52051 done
[2022-11-03T15:50:35.120] _slurm_rpc_submit_batch_job: JobId=52052 InitPrio=1012 usec=464
[2022-11-03T15:50:35.401] sched: Allocate JobId=52052 NodeList=cpu[03-04] #CPUs=2 Partition=cpu-opteron
[2022-11-03T15:50:36.638] _job_complete: JobId=52052 WEXITSTATUS 31
[2022-11-03T15:50:36.638] _job_complete: JobId=52052 done
[2022-11-03T15:51:29.893] _slurm_rpc_submit_batch_job: JobId=52053 InitPrio=1012 usec=553
[2022-11-03T15:51:30.612] sched: Allocate JobId=52053 NodeList=cpu[03-04] #CPUs=2 Partition=cpu-opteron
[2022-11-03T15:51:31.771] _job_complete: JobId=52053 WEXITSTATUS 31
[2022-11-03T15:51:31.771] _job_complete: JobId=52053 done
[2022-11-03T15:53:49.452] _slurm_rpc_submit_batch_job: JobId=52054 InitPrio=1012 usec=484
[2022-11-03T15:53:49.792] sched: Allocate JobId=52054 NodeList=cpu[03-04] #CPUs=2 Partition=cpu-opteron
[2022-11-03T15:54:27.763] _job_complete: JobId=52054 WEXITSTATUS 0
[2022-11-03T15:54:27.763] _job_complete: JobId=52054 done
[2022-11-03T15:56:38.706] _slurm_rpc_submit_batch_job: JobId=52055 InitPrio=1012 usec=561
[2022-11-03T16:25:41.314] _slurm_rpc_submit_batch_job: JobId=52056 InitPrio=607 usec=557
[2022-11-03T16:51:30.683] _slurm_rpc_submit_batch_job: JobId=52057 InitPrio=1214 usec=579
[2022-11-03T16:51:33.632] _slurm_rpc_submit_batch_job: JobId=52058 InitPrio=1214 usec=452
[2022-11-03T16:51:37.497] _slurm_rpc_submit_batch_job: JobId=52059 InitPrio=1214 usec=532
[2022-11-03T16:51:40.584] _slurm_rpc_submit_batch_job: JobId=52060 InitPrio=1214 usec=570
[2022-11-03T16:51:47.049] _slurm_rpc_submit_batch_job: JobId=52061 InitPrio=1214 usec=449
[2022-11-03T16:51:50.056] _slurm_rpc_submit_batch_job: JobId=52062 InitPrio=1214 usec=479
[2022-11-03T16:51:53.232] _slurm_rpc_submit_batch_job: JobId=52063 InitPrio=1214 usec=488
[2022-11-03T16:52:00.400] _slurm_rpc_submit_batch_job: JobId=52064 InitPrio=1214 usec=458
[2022-11-03T16:52:07.097] _slurm_rpc_submit_batch_job: JobId=52065 InitPrio=1214 usec=469
[2022-11-03T16:52:09.985] _slurm_rpc_submit_batch_job: JobId=52066 InitPrio=1214 usec=552
[2022-11-03T16:52:13.233] _slurm_rpc_submit_batch_job: JobId=52067 InitPrio=1214 usec=575
[2022-11-03T16:54:58.461] _slurm_rpc_submit_batch_job: JobId=52068 InitPrio=607 usec=405
[2022-11-03T17:08:02.465] _slurm_rpc_submit_batch_job: JobId=52069 InitPrio=2226 usec=477
[2022-11-03T17:08:03.001] sched: Allocate JobId=52069 NodeList=cpu07 #CPUs=64 Partition=cpu-opteron
[2022-11-03T17:29:09.232] _slurm_rpc_submit_batch_job: JobId=52070 InitPrio=2226 usec=577
[2022-11-03T19:02:28.869] _job_complete: JobId=52042 WEXITSTATUS 0
[2022-11-03T19:02:28.869] _job_complete: JobId=52042 done
[2022-11-03T19:06:49.150] _slurm_rpc_submit_batch_job: JobId=52071 InitPrio=2226 usec=823
[2022-11-03T19:06:53.943] _job_complete: JobId=52045 WEXITSTATUS 0
[2022-11-03T19:06:53.949] _job_complete: JobId=52045 done
[2022-11-03T19:07:00.145] sched: Allocate JobId=52070 NodeList=cpu03 #CPUs=64 Partition=cpu-opteron
[2022-11-03T19:43:29.545] _job_complete: JobId=52070 WEXITSTATUS 0
[2022-11-03T19:43:29.546] _job_complete: JobId=52070 done
[2022-11-03T19:43:31.683] sched: Allocate JobId=52071 NodeList=cpu03 #CPUs=64 Partition=cpu-opteron
[2022-11-03T19:43:51.110] _job_complete: JobId=52071 WEXITSTATUS 1
[2022-11-03T19:43:51.110] _job_complete: JobId=52071 done
[2022-11-03T20:16:31.481] _slurm_rpc_submit_batch_job: JobId=52072 InitPrio=2226 usec=480
[2022-11-03T20:16:31.610] sched: Allocate JobId=52072 NodeList=cpu03 #CPUs=64 Partition=cpu-opteron
[2022-11-03T20:37:01.741] _slurm_rpc_kill_job: REQUEST_KILL_JOB JobId=52072 uid 548300593
[2022-11-03T20:38:13.005] _slurm_rpc_submit_batch_job: JobId=52073 InitPrio=2226 usec=531
[2022-11-03T20:38:13.840] sched: Allocate JobId=52073 NodeList=cpu03 #CPUs=64 Partition=cpu-opteron
[2022-11-04T02:50:52.215] _job_complete: JobId=52017 WEXITSTATUS 0
[2022-11-04T02:50:52.215] _job_complete: JobId=52017 done
[2022-11-04T02:50:52.747] sched: Allocate JobId=52020 NodeList=cpu12 #CPUs=8 Partition=cpu-epyc
[2022-11-04T02:54:16.735] _job_complete: JobId=52016 WEXITSTATUS 0
[2022-11-04T02:54:16.735] _job_complete: JobId=52016 done
[2022-11-04T02:54:17.225] sched: Allocate JobId=52021 NodeList=cpu12 #CPUs=8 Partition=cpu-epyc
[2022-11-04T03:10:17.341] _job_complete: JobId=52018 WEXITSTATUS 0
[2022-11-04T03:10:17.341] _job_complete: JobId=52018 done
[2022-11-04T03:10:17.866] sched: Allocate JobId=52022 NodeList=cpu12 #CPUs=8 Partition=cpu-epyc
[2022-11-04T03:36:12.160] _job_complete: JobId=51982 WEXITSTATUS 0
[2022-11-04T03:36:12.160] _job_complete: JobId=51982 done
[2022-11-04T03:36:12.890] sched: Allocate JobId=52002 NodeList=gpu02 #CPUs=5 Partition=gpu-titan
[2022-11-04T03:36:12.891] sched: Allocate JobId=52003 NodeList=gpu02 #CPUs=5 Partition=gpu-titan
[2022-11-04T03:36:12.892] sched: Allocate JobId=52055 NodeList=gpu02 #CPUs=2 Partition=gpu-titan
[2022-11-04T04:29:01.752] _job_complete: JobId=52009 WEXITSTATUS 0
[2022-11-04T04:29:01.752] _job_complete: JobId=52009 done
[2022-11-04T04:29:02.172] sched: Allocate JobId=52023 NodeList=cpu14 #CPUs=8 Partition=cpu-epyc
[2022-11-04T04:45:03.374] _job_complete: JobId=52011 WEXITSTATUS 0
[2022-11-04T04:45:03.374] _job_complete: JobId=52011 done
[2022-11-04T04:45:03.733] sched: Allocate JobId=52024 NodeList=cpu14 #CPUs=8 Partition=cpu-epyc
[2022-11-04T04:45:05.741] _job_complete: JobId=52010 WEXITSTATUS 0
[2022-11-04T04:45:05.741] _job_complete: JobId=52010 done
[2022-11-04T04:45:06.087] sched: Allocate JobId=52025 NodeList=cpu14 #CPUs=8 Partition=cpu-epyc
[2022-11-04T06:05:55.441] _job_complete: JobId=52015 WEXITSTATUS 0
[2022-11-04T06:05:55.442] _job_complete: JobId=52015 done
[2022-11-04T06:05:55.952] sched: Allocate JobId=52026 NodeList=cpu12 #CPUs=8 Partition=cpu-epyc
[2022-11-04T07:00:05.061] _job_complete: JobId=52019 WEXITSTATUS 0
[2022-11-04T07:00:05.061] _job_complete: JobId=52019 done
[2022-11-04T07:00:05.410] sched: Allocate JobId=52027 NodeList=cpu14 #CPUs=8 Partition=cpu-epyc
[2022-11-04T07:51:45.563] _job_complete: JobId=52012 WEXITSTATUS 0
[2022-11-04T07:51:45.563] _job_complete: JobId=52012 done
[2022-11-04T07:51:45.918] sched: Allocate JobId=52028 NodeList=cpu14 #CPUs=8 Partition=cpu-epyc
[2022-11-04T08:18:24.874] _job_complete: JobId=52006 WEXITSTATUS 0
[2022-11-04T08:18:24.875] _job_complete: JobId=52006 done
[2022-11-04T08:18:25.347] sched: Allocate JobId=52029 NodeList=cpu15 #CPUs=8 Partition=cpu-epyc
[2022-11-04T09:11:36.884] _slurm_rpc_submit_batch_job: JobId=52074 InitPrio=1012 usec=546
[2022-11-04T09:11:37.481] sched: Allocate JobId=52074 NodeList=cpu[08-09] #CPUs=2 Partition=cpu-opteron
[2022-11-04T09:12:14.098] _job_complete: JobId=52074 WEXITSTATUS 0
[2022-11-04T09:12:14.099] _job_complete: JobId=52074 done
[2022-11-04T09:20:03.986] _slurm_rpc_kill_job: REQUEST_KILL_JOB JobId=52003 uid 548200023
[2022-11-04T09:20:20.412] _slurm_rpc_kill_job: REQUEST_KILL_JOB JobId=52002 uid 548200023
[2022-11-04T09:20:42.730] _slurm_rpc_submit_batch_job: JobId=52075 InitPrio=1012 usec=533
[2022-11-04T09:20:43.261] sched: Allocate JobId=52075 NodeList=gpu02 #CPUs=6 Partition=gpu-titan
[2022-11-04T09:22:08.057] _slurm_rpc_kill_job: REQUEST_KILL_JOB JobId=52075 uid 548200023
[2022-11-04T09:22:38.789] _slurm_rpc_submit_batch_job: JobId=52076 InitPrio=1012 usec=563
[2022-11-04T09:22:39.511] sched: Allocate JobId=52076 NodeList=gpu02 #CPUs=5 Partition=gpu-titan
[2022-11-04T09:22:56.218] _slurm_rpc_submit_batch_job: JobId=52077 InitPrio=1012 usec=548
[2022-11-04T09:22:56.531] sched: Allocate JobId=52077 NodeList=gpu02 #CPUs=6 Partition=gpu-titan
[2022-11-04T09:23:25.591] _slurm_rpc_kill_job: REQUEST_KILL_JOB JobId=52076 uid 548200023
[2022-11-04T09:29:38.091] _slurm_rpc_submit_batch_job: JobId=52078 InitPrio=1012 usec=434
[2022-11-04T09:29:38.186] sched: Allocate JobId=52078 NodeList=cpu[08-09] #CPUs=2 Partition=cpu-opteron
[2022-11-04T09:29:43.461] _job_complete: JobId=52078 WEXITSTATUS 0
[2022-11-04T09:29:43.461] _job_complete: JobId=52078 done
[2022-11-04T09:30:53.376] _slurm_rpc_submit_batch_job: JobId=52079 InitPrio=1012 usec=533
[2022-11-04T09:30:54.287] sched: Allocate JobId=52079 NodeList=gpu02 #CPUs=5 Partition=gpu-titan
[2022-11-04T09:31:15.807] _job_complete: JobId=52079 WEXITSTATUS 0
[2022-11-04T09:31:15.807] _job_complete: JobId=52079 done
[2022-11-04T09:31:48.870] _slurm_rpc_submit_batch_job: JobId=52080 InitPrio=1012 usec=527
[2022-11-04T09:31:49.572] sched: Allocate JobId=52080 NodeList=gpu02 #CPUs=5 Partition=gpu-titan
[2022-11-04T09:32:13.467] _job_complete: JobId=52080 WEXITSTATUS 0
[2022-11-04T09:32:13.467] _job_complete: JobId=52080 done
[2022-11-04T09:32:37.425] _job_complete: JobId=52013 WEXITSTATUS 0
[2022-11-04T09:32:37.425] _job_complete: JobId=52013 done
[2022-11-04T09:32:37.871] sched: Allocate JobId=52030 NodeList=cpu12 #CPUs=8 Partition=cpu-epyc
[2022-11-04T09:33:01.864] _slurm_rpc_submit_batch_job: JobId=52081 InitPrio=1012 usec=521
[2022-11-04T09:33:02.668] sched: Allocate JobId=52081 NodeList=cpu[08-09] #CPUs=2 Partition=cpu-opteron
[2022-11-04T09:33:07.996] _job_complete: JobId=52081 WEXITSTATUS 0
[2022-11-04T09:33:07.996] _job_complete: JobId=52081 done
[2022-11-04T09:33:22.247] error: This association 258(account='free', user='noraini', partition='(null)') does not have access to qos long
[2022-11-04T09:33:22.247] _slurm_rpc_allocate_resources: Invalid qos specification 
[2022-11-04T09:33:23.036] _slurm_rpc_submit_batch_job: JobId=52082 InitPrio=1012 usec=479
[2022-11-04T09:33:23.695] sched: Allocate JobId=52082 NodeList=gpu02 #CPUs=5 Partition=gpu-titan
[2022-11-04T09:47:43.541] _job_complete: JobId=52005 WEXITSTATUS 0
[2022-11-04T09:47:43.541] _job_complete: JobId=52005 done
[2022-11-04T09:47:44.063] sched: Allocate JobId=52031 NodeList=cpu15 #CPUs=8 Partition=cpu-epyc
[2022-11-04T09:47:55.673] sched: _slurm_rpc_allocate_resources JobId=52083 NodeList=cpu04 usec=12096
[2022-11-04T09:57:49.524] sched: _slurm_rpc_allocate_resources JobId=52084 NodeList=cpu04 usec=1346
[2022-11-04T10:12:08.066] _job_complete: JobId=52014 WEXITSTATUS 0
[2022-11-04T10:12:08.066] _job_complete: JobId=52014 done
[2022-11-04T10:12:08.530] sched: Allocate JobId=52032 NodeList=cpu12 #CPUs=8 Partition=cpu-epyc
[2022-11-04T10:17:06.859] _slurm_rpc_kill_job: REQUEST_KILL_JOB JobId=52004 uid 548300642
[2022-11-04T10:17:06.859] job_str_signal(3): invalid JobId=52004
[2022-11-04T10:17:06.859] _slurm_rpc_kill_job: job_str_signal() uid=548300642 JobId=52004 sig=9 returned: Invalid job id specified
[2022-11-04T10:23:02.321] _slurm_rpc_kill_job: REQUEST_KILL_JOB JobId=52083 uid 548300642
[2022-11-04T10:24:41.169] _slurm_rpc_submit_batch_job: JobId=52085 InitPrio=1012 usec=536
[2022-11-04T10:28:03.224] cleanup_completing: JobId=52083 completion process took 301 seconds
[2022-11-04T10:32:10.749] _slurm_rpc_submit_batch_job: JobId=52086 InitPrio=17894 usec=634
[2022-11-04T10:32:11.283] sched: Allocate JobId=52086 NodeList=cpu09 #CPUs=1 Partition=cpu-opteron
[2022-11-04T10:32:35.351] _job_complete: JobId=52086 WEXITSTATUS 1
[2022-11-04T10:32:35.351] _job_complete: JobId=52086 done
[2022-11-04T10:38:00.948] _slurm_rpc_submit_batch_job: JobId=52087 InitPrio=17894 usec=649
[2022-11-04T10:38:01.910] sched: Allocate JobId=52087 NodeList=cpu09 #CPUs=1 Partition=cpu-opteron
[2022-11-04T10:38:16.148] _job_complete: JobId=52087 WEXITSTATUS 1
[2022-11-04T10:38:16.148] _job_complete: JobId=52087 done
[2022-11-04T10:46:32.114] _slurm_rpc_submit_batch_job: JobId=52088 InitPrio=14048 usec=454
[2022-11-04T10:46:32.265] sched: Allocate JobId=52088 NodeList=cpu11 #CPUs=8 Partition=cpu-opteron
[2022-11-04T10:52:53.809] _slurm_rpc_delete_reservation complete for gpu_pm_check usec=91
[2022-11-04T10:53:04.151] sched: _slurm_rpc_allocate_resources JobId=52089 NodeList=(null) usec=900
[2022-11-04T10:53:04.931] sched: Allocate JobId=52089 NodeList=cpu04 #CPUs=1 Partition=cpu-opteron
[2022-11-04T10:53:46.236] _job_complete: JobId=52089 WEXITSTATUS 0
[2022-11-04T10:53:46.237] _job_complete: JobId=52089 done
[2022-11-04T10:56:10.264] _slurm_rpc_kill_job: REQUEST_KILL_JOB JobId=52088 uid 548300543
[2022-11-04T10:57:58.569] Time limit exhausted for JobId=52084
[2022-11-04T11:02:59.666] cleanup_completing: JobId=52084 completion process took 301 seconds
[2022-11-04T11:04:18.743] sched: _slurm_rpc_allocate_resources JobId=52090 NodeList=cpu04 usec=2356
[2022-11-04T11:16:52.198] _slurm_rpc_submit_batch_job: JobId=52091 InitPrio=17894 usec=640
[2022-11-04T11:16:52.616] sched: Allocate JobId=52091 NodeList=cpu09 #CPUs=1 Partition=cpu-opteron
[2022-11-04T11:17:20.941] _job_complete: JobId=52091 WEXITSTATUS 0
[2022-11-04T11:17:20.941] _job_complete: JobId=52091 done
[2022-11-04T11:24:56.007] sched: _slurm_rpc_allocate_resources JobId=52092 NodeList=(null) usec=1001
[2022-11-04T11:24:56.514] sched: Allocate JobId=52092 NodeList=cpu04 #CPUs=1 Partition=cpu-opteron
[2022-11-04T11:41:19.811] _job_complete: JobId=51880 WEXITSTATUS 0
[2022-11-04T11:41:19.811] _job_complete: JobId=51880 done
[2022-11-04T11:46:12.757] sched: _slurm_rpc_allocate_resources JobId=52093 NodeList=(null) usec=4001
[2022-11-04T11:46:13.783] sched: Allocate JobId=52093 NodeList=cpu04 #CPUs=1 Partition=cpu-opteron
[2022-11-04T11:48:02.591] _job_complete: JobId=52093 WEXITSTATUS 0
[2022-11-04T11:48:02.591] _job_complete: JobId=52093 done
[2022-11-04T12:04:29.901] Time limit exhausted for JobId=52090
[2022-11-04T12:05:41.678] _slurm_rpc_kill_job: REQUEST_KILL_JOB JobId=52073 uid 548300593
[2022-11-04T12:06:01.951] cleanup_completing: JobId=52090 completion process took 92 seconds
[2022-11-04T12:13:02.896] error: This association 258(account='free', user='noraini', partition='(null)') does not have access to qos long
[2022-11-04T12:13:02.896] _slurm_rpc_allocate_resources: Invalid qos specification 
[2022-11-04T12:14:03.240] error: This association 258(account='free', user='noraini', partition='(null)') does not have access to qos long
[2022-11-04T12:14:03.240] _slurm_rpc_allocate_resources: Invalid qos specification 
[2022-11-04T12:14:13.021] error: This association 258(account='free', user='noraini', partition='(null)') does not have access to qos long
[2022-11-04T12:14:13.021] _slurm_rpc_allocate_resources: Invalid qos specification 
[2022-11-04T12:15:53.646] sched: _slurm_rpc_allocate_resources JobId=52094 NodeList=cpu04 usec=2227
[2022-11-04T12:19:41.192] sched: _slurm_rpc_allocate_resources JobId=52095 NodeList=(null) usec=900
[2022-11-04T12:19:41.484] sched: Allocate JobId=52095 NodeList=cpu11 #CPUs=4 Partition=cpu-opteron
[2022-11-04T12:30:18.653] _slurm_rpc_submit_batch_job: JobId=52096 InitPrio=607 usec=497
[2022-11-04T12:32:04.752] _job_complete: JobId=52095 WEXITSTATUS 0
[2022-11-04T12:32:04.752] _job_complete: JobId=52095 done
[2022-11-04T12:40:32.123] _job_complete: JobId=52008 WEXITSTATUS 0
[2022-11-04T12:40:32.123] _job_complete: JobId=52008 done
[2022-11-04T12:40:32.498] sched: Allocate JobId=52033 NodeList=cpu14 #CPUs=8 Partition=cpu-epyc
[2022-11-04T12:42:12.083] _job_complete: JobId=52007 WEXITSTATUS 0
[2022-11-04T12:42:12.083] _job_complete: JobId=52007 done
[2022-11-04T12:42:12.673] sched: Allocate JobId=52034 NodeList=cpu15 #CPUs=8 Partition=cpu-epyc
[2022-11-04T12:52:03.566] _slurm_rpc_kill_job: REQUEST_KILL_JOB JobId=52069 uid 548300593
[2022-11-04T12:52:26.042] _job_complete: JobId=51881 WEXITSTATUS 0
[2022-11-04T12:52:26.042] _job_complete: JobId=51881 done
[2022-11-04T12:55:12.649] _slurm_rpc_submit_batch_job: JobId=52097 InitPrio=2024 usec=464
[2022-11-04T12:55:13.087] sched: Allocate JobId=52097 NodeList=cpu03 #CPUs=64 Partition=cpu-opteron
[2022-11-04T13:10:29.483] _job_complete: JobId=51919 WEXITSTATUS 0
[2022-11-04T13:10:29.488] _job_complete: JobId=51919 done
[2022-11-04T13:10:30.521] sched: Allocate JobId=52035 NodeList=cpu15 #CPUs=8 Partition=cpu-epyc
[2022-11-04T13:10:30.522] sched: Allocate JobId=52036 NodeList=cpu15 #CPUs=8 Partition=cpu-epyc
[2022-11-04T13:15:59.208] Time limit exhausted for JobId=52094
[2022-11-04T13:21:01.749] cleanup_completing: JobId=52094 completion process took 302 seconds
[2022-11-04T13:40:29.493] _job_complete: JobId=51736 WEXITSTATUS 0
[2022-11-04T13:40:29.498] _job_complete: JobId=51736 done
[2022-11-04T13:40:33.800] sched: Allocate JobId=51864 NodeList=gpu05 #CPUs=8 Partition=gpu-v100s
[2022-11-04T13:40:33.814] sched: Allocate JobId=51868 NodeList=gpu05 #CPUs=16 Partition=gpu-v100s
[2022-11-04T13:43:06.739] _slurm_rpc_submit_batch_job: JobId=52098 InitPrio=2024 usec=641
[2022-11-04T13:43:09.090] sched: Allocate JobId=52098 NodeList=cpu07 #CPUs=10 Partition=cpu-opteron
[2022-11-04T13:48:03.076] _slurm_rpc_submit_batch_job: JobId=52099 InitPrio=2024 usec=594
[2022-11-04T14:11:52.919] _slurm_rpc_kill_job: REQUEST_KILL_JOB JobId=52098 uid 548300593
[2022-11-04T14:11:57.179] sched: Allocate JobId=52099 NodeList=cpu07 #CPUs=64 Partition=cpu-opteron
[2022-11-04T14:12:08.129] _slurm_rpc_submit_batch_job: JobId=52100 InitPrio=2024 usec=524
[2022-11-04T14:14:46.059] _slurm_rpc_kill_job: REQUEST_KILL_JOB JobId=52100 uid 548300593
[2022-11-04T14:15:10.078] _slurm_rpc_submit_batch_job: JobId=52101 InitPrio=2024 usec=604
[2022-11-04T14:29:55.718] sched: _slurm_rpc_allocate_resources JobId=52102 NodeList=cpu04 usec=15484
[2022-11-04T14:30:01.707] _job_complete: JobId=52102 WEXITSTATUS 0
[2022-11-04T14:30:01.707] _job_complete: JobId=52102 done
[2022-11-04T14:30:06.455] _slurm_rpc_submit_batch_job: JobId=52103 InitPrio=17894 usec=547
[2022-11-04T14:30:09.154] sched: Allocate JobId=52103 NodeList=cpu09 #CPUs=1 Partition=cpu-opteron
[2022-11-04T14:30:36.075] _job_complete: JobId=52103 WEXITSTATUS 0
[2022-11-04T14:30:36.075] _job_complete: JobId=52103 done
[2022-11-04T14:34:56.539] _slurm_rpc_submit_batch_job: JobId=52104 InitPrio=17894 usec=547
[2022-11-04T14:34:56.653] sched: Allocate JobId=52104 NodeList=cpu09 #CPUs=1 Partition=cpu-opteron
[2022-11-04T14:39:11.750] _job_complete: JobId=52104 WEXITSTATUS 0
[2022-11-04T14:39:11.751] _job_complete: JobId=52104 done
[2022-11-04T15:47:29.008] _slurm_rpc_submit_batch_job: JobId=52105 InitPrio=17894 usec=598
[2022-11-04T15:47:29.190] sched: Allocate JobId=52105 NodeList=cpu09 #CPUs=1 Partition=cpu-opteron
[2022-11-04T15:47:48.682] _job_complete: JobId=52105 WEXITSTATUS 1
[2022-11-04T15:47:48.682] _job_complete: JobId=52105 done
[2022-11-04T15:55:34.307] _slurm_rpc_submit_batch_job: JobId=52106 InitPrio=17894 usec=603
[2022-11-04T15:55:34.924] sched: Allocate JobId=52106 NodeList=cpu09 #CPUs=1 Partition=cpu-opteron
[2022-11-04T15:56:04.552] _job_complete: JobId=52106 WEXITSTATUS 0
[2022-11-04T15:56:04.553] _job_complete: JobId=52106 done
[2022-11-04T15:58:21.486] _slurm_rpc_submit_batch_job: JobId=52107 InitPrio=17894 usec=601
[2022-11-04T15:58:22.273] sched: Allocate JobId=52107 NodeList=cpu09 #CPUs=1 Partition=cpu-opteron
[2022-11-04T16:03:02.095] Batch JobId=52107 missing from batch node cpu09 (not found BatchStartTime after startup), Requeuing job
[2022-11-04T16:03:02.096] _job_complete: JobId=52107 WTERMSIG 126
[2022-11-04T16:03:02.096] _job_complete: JobId=52107 cancelled by node failure
[2022-11-04T16:03:02.096] _job_complete: requeue JobId=52107 due to node failure
[2022-11-04T16:03:02.096] _job_complete: JobId=52107 done
[2022-11-04T16:06:12.681] _slurm_rpc_submit_batch_job: JobId=52108 InitPrio=7894 usec=537
[2022-11-04T16:06:13.402] sched: Allocate JobId=52108 NodeList=cpu11 #CPUs=1 Partition=cpu-opteron
[2022-11-04T16:07:27.944] _job_complete: JobId=52108 WEXITSTATUS 0
[2022-11-04T16:07:27.944] _job_complete: JobId=52108 done
[2022-11-04T16:09:06.669] Resending TERMINATE_JOB request JobId=52107 Nodelist=cpu09
[2022-11-04T16:09:22.513] cleanup_completing: JobId=52107 completion process took 380 seconds
[2022-11-04T16:09:22.513] Requeuing JobId=52107
[2022-11-04T16:11:56.244] sched/backfill: _start_job: Started JobId=52107 in cpu-opteron on cpu09
[2022-11-04T16:12:44.569] _job_complete: JobId=52107 WEXITSTATUS 0
[2022-11-04T16:12:44.569] _job_complete: JobId=52107 done
[2022-11-04T16:44:08.405] _slurm_rpc_submit_batch_job: JobId=52109 InitPrio=809 usec=526
[2022-11-04T16:46:59.314] _slurm_rpc_submit_batch_job: JobId=52110 InitPrio=809 usec=458
[2022-11-04T17:14:24.723] _job_complete: JobId=51876 WEXITSTATUS 0
[2022-11-04T17:14:24.723] _job_complete: JobId=51876 done
[2022-11-04T18:18:51.258] _job_complete: JobId=51878 WEXITSTATUS 0
[2022-11-04T18:18:51.259] _job_complete: JobId=51878 done
[2022-11-04T19:08:54.710] _job_complete: JobId=51988 WEXITSTATUS 0
[2022-11-04T19:08:54.715] _job_complete: JobId=51988 done
[2022-11-04T19:27:22.220] _job_complete: JobId=52077 WEXITSTATUS 0
[2022-11-04T19:27:22.220] _job_complete: JobId=52077 done
[2022-11-04T19:27:23.313] sched: Allocate JobId=52085 NodeList=gpu02 #CPUs=5 Partition=gpu-titan
[2022-11-04T19:27:50.150] _job_complete: JobId=52085 WEXITSTATUS 0
[2022-11-04T19:27:50.150] _job_complete: JobId=52085 done
[2022-11-04T19:31:25.828] _job_complete: JobId=52092 WEXITSTATUS 0
[2022-11-04T19:31:25.829] _job_complete: JobId=52092 done
[2022-11-04T19:36:26.635] cleanup_completing: JobId=52092 completion process took 301 seconds
[2022-11-04T21:44:47.468] _job_complete: JobId=52021 WEXITSTATUS 0
[2022-11-04T21:44:47.468] _job_complete: JobId=52021 done
[2022-11-04T21:51:41.158] _job_complete: JobId=52020 WEXITSTATUS 0
[2022-11-04T21:51:41.158] _job_complete: JobId=52020 done
[2022-11-04T21:51:41.616] sched: Allocate JobId=52057 NodeList=cpu12 #CPUs=8 Partition=cpu-epyc
[2022-11-04T22:01:30.808] _job_complete: JobId=51877 WEXITSTATUS 0
[2022-11-04T22:01:30.808] _job_complete: JobId=51877 done
[2022-11-04T22:08:41.129] _job_complete: JobId=52027 WEXITSTATUS 0
[2022-11-04T22:08:41.129] _job_complete: JobId=52027 done
[2022-11-04T22:29:20.666] _job_complete: JobId=52022 WEXITSTATUS 0
[2022-11-04T22:29:20.666] _job_complete: JobId=52022 done
[2022-11-04T22:33:58.021] _job_complete: JobId=52023 WEXITSTATUS 0
[2022-11-04T22:33:58.021] _job_complete: JobId=52023 done
[2022-11-04T22:33:58.392] sched: Allocate JobId=52058 NodeList=cpu14 #CPUs=8 Partition=cpu-epyc
[2022-11-04T22:50:42.250] _job_complete: JobId=52028 WEXITSTATUS 0
[2022-11-04T22:50:42.250] _job_complete: JobId=52028 done
[2022-11-04T23:16:24.817] _job_complete: JobId=52029 WEXITSTATUS 0
[2022-11-04T23:16:24.818] _job_complete: JobId=52029 done
[2022-11-04T23:16:25.264] sched: Allocate JobId=52059 NodeList=cpu15 #CPUs=8 Partition=cpu-epyc
[2022-11-04T23:37:03.447] _job_complete: JobId=51883 WEXITSTATUS 0
[2022-11-04T23:37:03.447] _job_complete: JobId=51883 done
[2022-11-05T00:00:44.027] _slurm_rpc_submit_batch_job: JobId=52111 InitPrio=1214 usec=646
[2022-11-05T00:00:45.029] sched: Allocate JobId=52111 NodeList=gpu02 #CPUs=5 Partition=gpu-titan
[2022-11-05T00:01:11.470] _job_complete: JobId=52111 WEXITSTATUS 0
[2022-11-05T00:01:11.470] _job_complete: JobId=52111 done
[2022-11-05T00:01:46.676] _slurm_rpc_submit_batch_job: JobId=52112 InitPrio=1214 usec=569
[2022-11-05T00:01:47.175] sched: Allocate JobId=52112 NodeList=gpu02 #CPUs=5 Partition=gpu-titan
[2022-11-05T00:05:13.339] _slurm_rpc_submit_batch_job: JobId=52113 InitPrio=1214 usec=562
[2022-11-05T00:05:35.614] _slurm_rpc_kill_job: REQUEST_KILL_JOB JobId=52113 uid 548200023
[2022-11-05T00:06:16.675] _slurm_rpc_submit_batch_job: JobId=52114 InitPrio=1214 usec=631
[2022-11-05T00:06:17.671] sched: Allocate JobId=52114 NodeList=gpu04 #CPUs=4 Partition=gpu-k40c
[2022-11-05T00:06:34.076] _job_complete: JobId=52114 WEXITSTATUS 0
[2022-11-05T00:06:34.076] _job_complete: JobId=52114 done
[2022-11-05T00:07:28.473] _slurm_rpc_submit_batch_job: JobId=52115 InitPrio=1214 usec=512
[2022-11-05T00:11:02.333] _slurm_rpc_submit_batch_job: JobId=52116 InitPrio=1214 usec=492
[2022-11-05T00:11:03.077] sched: Allocate JobId=52116 NodeList=gpu04 #CPUs=4 Partition=gpu-k40c
[2022-11-05T00:11:03.812] _job_complete: JobId=52116 WEXITSTATUS 31
[2022-11-05T00:11:03.812] _job_complete: JobId=52116 done
[2022-11-05T00:12:11.187] _slurm_rpc_submit_batch_job: JobId=52117 InitPrio=1214 usec=589
[2022-11-05T00:12:11.305] sched: Allocate JobId=52117 NodeList=gpu04 #CPUs=4 Partition=gpu-k40c
[2022-11-05T00:12:14.802] _job_complete: JobId=52117 WEXITSTATUS 0
[2022-11-05T00:12:14.802] _job_complete: JobId=52117 done
[2022-11-05T00:13:39.676] _slurm_rpc_submit_batch_job: JobId=52118 InitPrio=1214 usec=530
[2022-11-05T00:13:40.416] sched: Allocate JobId=52118 NodeList=gpu04 #CPUs=4 Partition=gpu-k40c
[2022-11-05T00:13:43.916] _job_complete: JobId=52118 WEXITSTATUS 0
[2022-11-05T00:13:43.917] _job_complete: JobId=52118 done
[2022-11-05T00:14:31.285] _job_complete: JobId=51882 WEXITSTATUS 0
[2022-11-05T00:14:31.285] _job_complete: JobId=51882 done
[2022-11-05T00:14:49.842] _slurm_rpc_submit_batch_job: JobId=52119 InitPrio=1214 usec=573
[2022-11-05T00:49:03.284] _job_complete: JobId=51864 WEXITSTATUS 0
[2022-11-05T00:49:03.289] _job_complete: JobId=51864 done
[2022-11-05T00:49:05.432] sched: Allocate JobId=51918 NodeList=gpu05 #CPUs=16 Partition=gpu-v100s
[2022-11-05T03:26:17.478] _job_complete: JobId=52031 WEXITSTATUS 0
[2022-11-05T03:26:17.478] _job_complete: JobId=52031 done
[2022-11-05T03:39:13.578] _job_complete: JobId=52030 WEXITSTATUS 0
[2022-11-05T03:39:13.578] _job_complete: JobId=52030 done
[2022-11-05T03:39:14.100] sched: Allocate JobId=52060 NodeList=cpu12 #CPUs=8 Partition=cpu-epyc
[2022-11-05T03:46:41.662] _job_complete: JobId=52026 WEXITSTATUS 0
[2022-11-05T03:46:41.662] _job_complete: JobId=52026 done
[2022-11-05T04:17:56.465] _job_complete: JobId=52032 WEXITSTATUS 0
[2022-11-05T04:17:56.465] _job_complete: JobId=52032 done
[2022-11-05T04:18:00.136] _job_complete: JobId=52055 WEXITSTATUS 0
[2022-11-05T04:18:00.137] _job_complete: JobId=52055 done
[2022-11-05T04:18:01.172] sched: Allocate JobId=52115 NodeList=gpu02 #CPUs=5 Partition=gpu-titan
[2022-11-05T04:18:30.485] _job_complete: JobId=52115 WEXITSTATUS 0
[2022-11-05T04:18:30.485] _job_complete: JobId=52115 done
[2022-11-05T04:18:30.945] sched: Allocate JobId=52119 NodeList=gpu02 #CPUs=5 Partition=gpu-titan
[2022-11-05T04:19:00.257] _job_complete: JobId=52119 WEXITSTATUS 0
[2022-11-05T04:19:00.257] _job_complete: JobId=52119 done
[2022-11-05T06:21:25.564] _job_complete: JobId=52082 WEXITSTATUS 0
[2022-11-05T06:21:25.565] _job_complete: JobId=52082 done
[2022-11-05T07:13:35.249] _job_complete: JobId=52033 WEXITSTATUS 0
[2022-11-05T07:13:35.249] _job_complete: JobId=52033 done
[2022-11-05T07:13:35.608] sched: Allocate JobId=52061 NodeList=cpu14 #CPUs=8 Partition=cpu-epyc
[2022-11-05T07:56:08.995] _job_complete: JobId=52057 WEXITSTATUS 0
[2022-11-05T07:56:08.995] _job_complete: JobId=52057 done
[2022-11-05T07:56:09.278] sched: Allocate JobId=52062 NodeList=cpu12 #CPUs=8 Partition=cpu-epyc
[2022-11-05T08:22:02.901] _job_complete: JobId=52036 WEXITSTATUS 0
[2022-11-05T08:22:02.902] _job_complete: JobId=52036 done
[2022-11-05T08:22:03.363] sched: Allocate JobId=52063 NodeList=cpu15 #CPUs=8 Partition=cpu-epyc
[2022-11-05T08:45:03.235] _job_complete: JobId=51879 WEXITSTATUS 0
[2022-11-05T08:45:03.235] _job_complete: JobId=51879 done
[2022-11-05T09:14:00.725] _job_complete: JobId=52058 WEXITSTATUS 0
[2022-11-05T09:14:00.726] _job_complete: JobId=52058 done
[2022-11-05T09:14:01.117] sched: Allocate JobId=52064 NodeList=cpu14 #CPUs=8 Partition=cpu-epyc
[2022-11-05T09:39:44.145] _job_complete: JobId=52035 WEXITSTATUS 0
[2022-11-05T09:39:44.145] _job_complete: JobId=52035 done
[2022-11-05T09:43:11.927] _job_complete: JobId=51892 WEXITSTATUS 0
[2022-11-05T09:43:11.927] _job_complete: JobId=51892 done
[2022-11-05T09:53:02.254] _job_complete: JobId=52059 WEXITSTATUS 0
[2022-11-05T09:53:02.255] _job_complete: JobId=52059 done
[2022-11-05T09:53:02.677] sched: Allocate JobId=52065 NodeList=cpu15 #CPUs=8 Partition=cpu-epyc
[2022-11-05T09:53:57.381] sched/backfill: _start_job: Started JobId=52048 in cpu-epyc on cpu15
[2022-11-05T09:54:05.020] _job_complete: JobId=52048 WEXITSTATUS 2
[2022-11-05T09:54:05.020] _job_complete: JobId=52048 done
[2022-11-05T09:54:57.383] sched/backfill: _start_job: Started JobId=52109 in cpu-epyc on cpu15
[2022-11-05T10:00:29.955] _job_complete: JobId=52024 WEXITSTATUS 0
[2022-11-05T10:00:29.955] _job_complete: JobId=52024 done
[2022-11-05T10:00:57.390] sched/backfill: _start_job: Started JobId=52110 in cpu-epyc on cpu14
[2022-11-05T10:01:50.604] _job_complete: JobId=51891 WEXITSTATUS 0
[2022-11-05T10:01:50.605] _job_complete: JobId=51891 done
[2022-11-05T10:08:33.601] _job_complete: JobId=51888 WEXITSTATUS 0
[2022-11-05T10:08:33.601] _job_complete: JobId=51888 done
[2022-11-05T10:08:52.702] _job_complete: JobId=52110 WEXITSTATUS 1
[2022-11-05T10:08:52.704] _job_complete: JobId=52110 done
[2022-11-05T10:14:50.644] _job_complete: JobId=52025 WEXITSTATUS 0
[2022-11-05T10:14:50.644] _job_complete: JobId=52025 done
[2022-11-05T10:49:25.753] _slurm_rpc_submit_batch_job: JobId=52120 InitPrio=1214 usec=689
[2022-11-05T10:49:26.259] sched: Allocate JobId=52120 NodeList=gpu02 #CPUs=5 Partition=gpu-titan
[2022-11-05T10:49:53.723] _slurm_rpc_kill_job: REQUEST_KILL_JOB JobId=52120 uid 548200023
[2022-11-05T10:50:23.462] _slurm_rpc_submit_batch_job: JobId=52121 InitPrio=1214 usec=658
[2022-11-05T10:50:24.320] sched: Allocate JobId=52121 NodeList=gpu02 #CPUs=5 Partition=gpu-titan
[2022-11-05T10:50:49.339] _slurm_rpc_submit_batch_job: JobId=52122 InitPrio=1214 usec=572
[2022-11-05T10:50:49.356] sched: Allocate JobId=52122 NodeList=gpu02 #CPUs=5 Partition=gpu-titan
[2022-11-05T10:52:49.554] _slurm_rpc_submit_batch_job: JobId=52123 InitPrio=1214 usec=543
[2022-11-05T10:52:49.682] sched: Allocate JobId=52123 NodeList=gpu04 #CPUs=4 Partition=gpu-k40c
[2022-11-05T10:53:38.221] _slurm_rpc_submit_batch_job: JobId=52124 InitPrio=1214 usec=486
[2022-11-05T10:53:38.748] sched: Allocate JobId=52124 NodeList=gpu04 #CPUs=4 Partition=gpu-k40c
[2022-11-05T10:53:39.515] _job_complete: JobId=52124 WEXITSTATUS 1
[2022-11-05T10:53:39.515] _job_complete: JobId=52124 done
[2022-11-05T10:54:51.960] _job_complete: JobId=52123 WEXITSTATUS 0
[2022-11-05T10:54:51.961] _job_complete: JobId=52123 done
[2022-11-05T10:55:01.545] _slurm_rpc_submit_batch_job: JobId=52125 InitPrio=1214 usec=458
[2022-11-05T10:55:01.860] sched: Allocate JobId=52125 NodeList=gpu04 #CPUs=4 Partition=gpu-k40c
[2022-11-05T10:56:11.584] _job_complete: JobId=52125 WEXITSTATUS 0
[2022-11-05T10:56:11.584] _job_complete: JobId=52125 done
[2022-11-05T10:58:52.574] _slurm_rpc_submit_batch_job: JobId=52126 InitPrio=1214 usec=525
[2022-11-05T11:25:56.827] _slurm_rpc_submit_batch_job: JobId=52127 InitPrio=4858 usec=650
[2022-11-05T11:56:08.451] _slurm_rpc_submit_batch_job: JobId=52128 InitPrio=1214 usec=539
[2022-11-05T11:56:09.264] sched: Allocate JobId=52128 NodeList=gpu04 #CPUs=8 Partition=gpu-k40c
[2022-11-05T11:56:28.472] _slurm_rpc_submit_batch_job: JobId=52129 InitPrio=1214 usec=450
[2022-11-05T11:56:29.388] sched: Allocate JobId=52129 NodeList=gpu04 #CPUs=8 Partition=gpu-k40c
[2022-11-05T11:56:30.320] _job_complete: JobId=52128 WEXITSTATUS 0
[2022-11-05T11:56:30.320] _job_complete: JobId=52128 done
[2022-11-05T11:56:41.732] _job_complete: JobId=52129 WEXITSTATUS 0
[2022-11-05T11:56:41.732] _job_complete: JobId=52129 done
[2022-11-05T11:56:56.139] _slurm_rpc_submit_batch_job: JobId=52130 InitPrio=1214 usec=486
[2022-11-05T11:56:56.424] sched: Allocate JobId=52130 NodeList=gpu04 #CPUs=8 Partition=gpu-k40c
[2022-11-05T11:57:08.424] _job_complete: JobId=52130 WEXITSTATUS 0
[2022-11-05T11:57:08.424] _job_complete: JobId=52130 done
[2022-11-05T12:01:04.054] _slurm_rpc_submit_batch_job: JobId=52131 InitPrio=1214 usec=600
[2022-11-05T12:01:20.433] _slurm_rpc_submit_batch_job: JobId=52132 InitPrio=1214 usec=519
[2022-11-05T12:01:57.505] sched/backfill: _start_job: Started JobId=52131 in cpu-opteron on cpu04
[2022-11-05T12:01:57.506] sched/backfill: _start_job: Started JobId=52132 in cpu-opteron on cpu04
[2022-11-05T12:02:21.630] _job_complete: JobId=52132 WEXITSTATUS 1
[2022-11-05T12:02:21.630] _job_complete: JobId=52132 done
[2022-11-05T12:13:14.023] _slurm_rpc_submit_batch_job: JobId=52133 InitPrio=1214 usec=560
[2022-11-05T12:13:57.519] sched/backfill: _start_job: Started JobId=52133 in cpu-opteron on cpu04
[2022-11-05T12:16:45.840] _job_complete: JobId=52133 WEXITSTATUS 0
[2022-11-05T12:16:45.840] _job_complete: JobId=52133 done
[2022-11-05T12:26:06.954] _job_complete: JobId=51887 WEXITSTATUS 0
[2022-11-05T12:26:06.955] _job_complete: JobId=51887 done
[2022-11-05T13:08:26.166] _job_complete: JobId=51884 WEXITSTATUS 0
[2022-11-05T13:08:26.166] _job_complete: JobId=51884 done
[2022-11-05T13:12:15.247] _slurm_rpc_submit_batch_job: JobId=52134 InitPrio=1214 usec=533
[2022-11-05T13:12:57.581] sched/backfill: _start_job: Started JobId=52134 in cpu-opteron on cpu04
[2022-11-05T13:12:59.434] _slurm_rpc_kill_job: REQUEST_KILL_JOB JobId=52134 uid 548200023
[2022-11-05T13:13:20.778] _slurm_rpc_submit_batch_job: JobId=52135 InitPrio=1214 usec=549
[2022-11-05T13:13:21.353] sched: Allocate JobId=52135 NodeList=gpu04 #CPUs=8 Partition=gpu-k40c
[2022-11-05T13:13:27.226] _job_complete: JobId=52135 WEXITSTATUS 0
[2022-11-05T13:13:27.226] _job_complete: JobId=52135 done
[2022-11-05T13:14:01.208] _slurm_rpc_submit_batch_job: JobId=52136 InitPrio=1214 usec=486
[2022-11-05T13:14:44.645] _slurm_rpc_submit_batch_job: JobId=52137 InitPrio=1214 usec=632
[2022-11-05T13:14:57.584] sched/backfill: _start_job: Started JobId=52136 in cpu-opteron on cpu04
[2022-11-05T13:14:57.585] sched/backfill: _start_job: Started JobId=52137 in cpu-opteron on cpu04
[2022-11-05T13:15:07.518] _job_complete: JobId=52137 WEXITSTATUS 1
[2022-11-05T13:15:07.518] _job_complete: JobId=52137 done
[2022-11-05T13:16:22.871] _job_complete: JobId=52136 WEXITSTATUS 0
[2022-11-05T13:16:22.871] _job_complete: JobId=52136 done
[2022-11-05T14:14:08.124] _job_complete: JobId=51904 WEXITSTATUS 0
[2022-11-05T14:14:08.124] _job_complete: JobId=51904 done
[2022-11-05T14:23:35.040] _job_complete: JobId=52060 WEXITSTATUS 0
[2022-11-05T14:23:35.040] _job_complete: JobId=52060 done
[2022-11-05T14:23:57.669] sched/backfill: _start_job: Started JobId=52066 in cpu-epyc on cpu12
[2022-11-05T14:32:03.037] _job_complete: JobId=51886 WEXITSTATUS 0
[2022-11-05T14:32:03.037] _job_complete: JobId=51886 done
[2022-11-05T15:12:52.282] _job_complete: JobId=51885 WEXITSTATUS 0
[2022-11-05T15:12:52.283] _job_complete: JobId=51885 done
[2022-11-05T15:24:04.894] _job_complete: JobId=52131 WEXITSTATUS 0
[2022-11-05T15:24:04.894] _job_complete: JobId=52131 done
[2022-11-05T15:24:08.174] sched: Allocate JobId=52101 NodeList=cpu04 #CPUs=10 Partition=cpu-opteron
[2022-11-05T15:45:17.006] _job_complete: JobId=51903 WEXITSTATUS 0
[2022-11-05T15:45:17.006] _job_complete: JobId=51903 done
[2022-11-05T16:04:38.893] _slurm_rpc_submit_batch_job: JobId=52138 InitPrio=7894 usec=565
[2022-11-05T16:04:39.486] sched: Allocate JobId=52138 NodeList=cpu08 #CPUs=1 Partition=cpu-opteron
[2022-11-05T16:07:05.532] _job_complete: JobId=52138 WEXITSTATUS 0
[2022-11-05T16:07:05.533] _job_complete: JobId=52138 done
[2022-11-05T16:07:09.737] _slurm_rpc_submit_batch_job: JobId=52139 InitPrio=1214 usec=500
[2022-11-05T16:07:09.782] sched: Allocate JobId=52139 NodeList=gpu04 #CPUs=4 Partition=gpu-k40c
[2022-11-05T16:09:16.700] _job_complete: JobId=52139 WEXITSTATUS 0
[2022-11-05T16:09:16.700] _job_complete: JobId=52139 done
[2022-11-05T16:11:49.672] _job_complete: JobId=51767 WEXITSTATUS 139
[2022-11-05T16:11:49.678] _job_complete: JobId=51767 done
[2022-11-05T16:11:50.170] sched: Allocate JobId=52127 NodeList=cpu13 #CPUs=24 Partition=cpu-epyc
[2022-11-05T16:11:59.550] _job_complete: JobId=52127 WEXITSTATUS 0
[2022-11-05T16:11:59.550] _job_complete: JobId=52127 done
[2022-11-05T16:12:00.016] sched: Allocate JobId=52067 NodeList=cpu13 #CPUs=8 Partition=cpu-epyc
[2022-11-05T16:20:15.374] _slurm_rpc_submit_batch_job: JobId=52140 InitPrio=1214 usec=675
[2022-11-05T16:20:16.041] sched: Allocate JobId=52140 NodeList=cpu08 #CPUs=16 Partition=cpu-opteron
[2022-11-05T16:37:14.207] _slurm_rpc_submit_batch_job: JobId=52141 InitPrio=404 usec=497
[2022-11-05T16:37:20.345] _slurm_rpc_submit_batch_job: JobId=52142 InitPrio=404 usec=546
[2022-11-05T16:49:05.603] _slurm_rpc_submit_batch_job: JobId=52143 InitPrio=1417 usec=462
[2022-11-05T17:59:21.283] _job_complete: JobId=52061 WEXITSTATUS 0
[2022-11-05T17:59:21.283] _job_complete: JobId=52061 done
[2022-11-05T18:18:16.174] _slurm_rpc_submit_batch_job: JobId=52144 InitPrio=809 usec=523
[2022-11-05T18:18:16.665] sched: Allocate JobId=52144 NodeList=cpu11 #CPUs=64 Partition=cpu-opteron
[2022-11-05T18:18:40.865] _slurm_rpc_kill_job: REQUEST_KILL_JOB JobId=52144 uid 548200017
[2022-11-05T18:19:09.354] _slurm_rpc_submit_batch_job: JobId=52145 InitPrio=809 usec=437
[2022-11-05T18:19:57.895] sched/backfill: _start_job: Started JobId=52145 in cpu-epyc on cpu14
[2022-11-05T18:22:25.303] _job_complete: JobId=52062 WEXITSTATUS 0
[2022-11-05T18:22:25.303] _job_complete: JobId=52062 done
[2022-11-05T18:56:28.499] _job_complete: JobId=52064 WEXITSTATUS 0
[2022-11-05T18:56:28.500] _job_complete: JobId=52064 done
[2022-11-05T19:09:32.379] _job_complete: JobId=52063 WEXITSTATUS 0
[2022-11-05T19:09:32.380] _job_complete: JobId=52063 done
[2022-11-05T19:43:48.685] _slurm_rpc_submit_batch_job: JobId=52146 InitPrio=1821 usec=728
[2022-11-05T19:43:52.838] _job_complete: JobId=52101 WEXITSTATUS 0
[2022-11-05T19:43:52.844] _job_complete: JobId=52101 done
[2022-11-05T19:43:58.174] sched: Allocate JobId=52141 NodeList=cpu04 #CPUs=64 Partition=cpu-opteron
[2022-11-05T19:48:28.510] _job_complete: JobId=51897 WEXITSTATUS 0
[2022-11-05T19:48:28.510] _job_complete: JobId=51897 done
[2022-11-05T20:46:30.358] Reservation request overlaps jobs
[2022-11-05T20:46:30.358] _slurm_rpc_resv_create reservation=ceph_cbt_test: Requested nodes are busy
[2022-11-05T20:46:40.233] sched: Created reservation=ceph_cbt_test users=jitkang nodes=cpu12 cores=48 licenses=(null) tres=cpu=96 watts=4294967294 start=2022-11-05T20:46:40 end=2023-11-05T20:46:40 MaxStartDelay=
[2022-11-05T21:03:33.958] _slurm_rpc_submit_batch_job: JobId=52147 InitPrio=1214 usec=576
[2022-11-05T21:03:52.842] _slurm_rpc_kill_job: REQUEST_KILL_JOB JobId=52147 uid 548200023
[2022-11-05T21:04:12.307] _slurm_rpc_submit_batch_job: JobId=52148 InitPrio=1214 usec=538
[2022-11-05T21:04:58.093] sched/backfill: _start_job: Started JobId=52148 in cpu-opteron on cpu09
[2022-11-05T21:05:51.680] _job_complete: JobId=51899 WEXITSTATUS 0
[2022-11-05T21:05:51.680] _job_complete: JobId=51899 done
[2022-11-05T21:07:25.677] _job_complete: JobId=52065 WEXITSTATUS 0
[2022-11-05T21:07:25.677] _job_complete: JobId=52065 done
[2022-11-05T21:11:00.920] _job_complete: JobId=51898 WEXITSTATUS 0
[2022-11-05T21:11:00.920] _job_complete: JobId=51898 done
[2022-11-05T21:18:27.886] _slurm_rpc_kill_job: REQUEST_KILL_JOB JobId=52109 uid 548200017
[2022-11-05T21:20:02.127] _slurm_rpc_submit_batch_job: JobId=52149 InitPrio=809 usec=480
[2022-11-05T21:20:58.123] sched/backfill: _start_job: Started JobId=52149 in cpu-epyc on cpu14
[2022-11-05T21:27:54.939] _slurm_rpc_submit_batch_job: JobId=52150 InitPrio=809 usec=614
[2022-11-05T21:28:33.739] _slurm_rpc_kill_job: REQUEST_KILL_JOB JobId=52150 uid 548200017
[2022-11-05T21:29:39.564] _slurm_rpc_submit_batch_job: JobId=52151 InitPrio=809 usec=467
[2022-11-05T21:29:58.134] sched/backfill: _start_job: Started JobId=52151 in cpu-opteron on cpu11
[2022-11-05T21:30:01.543] _job_complete: JobId=52151 WEXITSTATUS 1
[2022-11-05T21:30:01.543] _job_complete: JobId=52151 done
[2022-11-05T21:31:22.432] _slurm_rpc_submit_batch_job: JobId=52152 InitPrio=809 usec=483
[2022-11-05T21:31:58.138] sched/backfill: _start_job: Started JobId=52152 in cpu-opteron on cpu11
[2022-11-05T21:31:58.261] _slurm_rpc_kill_job: REQUEST_KILL_JOB JobId=52152 uid 548200017
[2022-11-05T21:32:53.118] _slurm_rpc_submit_batch_job: JobId=52153 InitPrio=809 usec=760
[2022-11-05T22:43:45.549] _slurm_rpc_submit_batch_job: JobId=52154 InitPrio=1821 usec=493
[2022-11-05T22:44:09.430] _slurm_rpc_submit_batch_job: JobId=52155 InitPrio=1821 usec=404
[2022-11-05T23:19:44.261] _slurm_rpc_submit_batch_job: JobId=52156 InitPrio=1821 usec=436
[2022-11-05T23:21:59.350] _job_complete: JobId=52112 WEXITSTATUS 0
[2022-11-05T23:21:59.351] _job_complete: JobId=52112 done
[2022-11-05T23:22:00.414] sched: Allocate JobId=52126 NodeList=gpu02 #CPUs=5 Partition=gpu-titan
[2022-11-05T23:25:26.162] _job_complete: JobId=52099 WEXITSTATUS 0
[2022-11-05T23:25:26.167] _job_complete: JobId=52099 done
[2022-11-06T00:20:08.453] _job_complete: JobId=52066 WEXITSTATUS 0
[2022-11-06T00:20:08.453] _job_complete: JobId=52066 done
[2022-11-06T00:59:08.063] _slurm_rpc_submit_batch_job: JobId=52157 InitPrio=1821 usec=657
[2022-11-06T00:59:58.405] sched/backfill: _start_job: Started JobId=52157 in cpu-opteron on cpu08
[2022-11-06T01:29:08.423] _slurm_rpc_submit_batch_job: JobId=52158 InitPrio=2429 usec=548
[2022-11-06T01:29:09.008] sched: Allocate JobId=52158 NodeList=cpu08 #CPUs=8 Partition=cpu-opteron
[2022-11-06T01:30:14.300] _slurm_rpc_submit_batch_job: JobId=52159 InitPrio=2429 usec=408
[2022-11-06T01:30:15.073] sched: Allocate JobId=52159 NodeList=cpu07 #CPUs=8 Partition=cpu-opteron
[2022-11-06T01:31:21.882] _slurm_rpc_submit_batch_job: JobId=52160 InitPrio=2429 usec=417
[2022-11-06T01:31:22.308] sched: Allocate JobId=52160 NodeList=cpu07 #CPUs=8 Partition=cpu-opteron
[2022-11-06T01:32:26.639] _slurm_rpc_submit_batch_job: JobId=52161 InitPrio=2429 usec=481
[2022-11-06T01:32:27.388] sched: Allocate JobId=52161 NodeList=cpu07 #CPUs=8 Partition=cpu-opteron
[2022-11-06T01:33:02.027] _slurm_rpc_submit_batch_job: JobId=52162 InitPrio=2429 usec=506
[2022-11-06T01:33:02.435] sched: Allocate JobId=52162 NodeList=cpu07 #CPUs=8 Partition=cpu-opteron
[2022-11-06T01:33:40.121] _slurm_rpc_submit_batch_job: JobId=52163 InitPrio=2429 usec=441
[2022-11-06T01:33:40.484] sched: Allocate JobId=52163 NodeList=cpu07 #CPUs=8 Partition=cpu-opteron
[2022-11-06T02:40:46.516] _job_complete: JobId=52067 WEXITSTATUS 0
[2022-11-06T02:40:46.516] _job_complete: JobId=52067 done
[2022-11-06T02:40:47.034] sched: Allocate JobId=52096 NodeList=cpu13 #CPUs=48 Partition=cpu-epyc
[2022-11-06T03:02:00.253] _job_complete: JobId=52159 WEXITSTATUS 0
[2022-11-06T03:02:00.258] _job_complete: JobId=52159 done
[2022-11-06T03:12:56.147] _job_complete: JobId=52096 WEXITSTATUS 1
[2022-11-06T03:12:56.147] _job_complete: JobId=52096 done
[2022-11-06T03:12:56.646] sched: Allocate JobId=52143 NodeList=cpu13 #CPUs=48 Partition=cpu-epyc
[2022-11-06T03:12:56.660] sched: Allocate JobId=52153 NodeList=cpu15 #CPUs=24 Partition=cpu-epyc
[2022-11-06T03:58:41.442] _job_complete: JobId=51895 WEXITSTATUS 0
[2022-11-06T03:58:41.442] _job_complete: JobId=51895 done
[2022-11-06T04:07:07.456] _job_complete: JobId=52158 WEXITSTATUS 0
[2022-11-06T04:07:07.457] _job_complete: JobId=52158 done
[2022-11-06T04:10:35.389] _job_complete: JobId=52160 WEXITSTATUS 0
[2022-11-06T04:10:35.389] _job_complete: JobId=52160 done
[2022-11-06T04:14:46.892] _job_complete: JobId=52161 WEXITSTATUS 0
[2022-11-06T04:14:46.894] _job_complete: JobId=52161 done
[2022-11-06T04:16:30.750] _job_complete: JobId=52163 WEXITSTATUS 0
[2022-11-06T04:16:30.751] _job_complete: JobId=52163 done
[2022-11-06T04:18:47.112] _job_complete: JobId=52162 WEXITSTATUS 0
[2022-11-06T04:18:47.112] _job_complete: JobId=52162 done
[2022-11-06T04:39:24.341] _job_complete: JobId=51905 WEXITSTATUS 0
[2022-11-06T04:39:24.341] _job_complete: JobId=51905 done
[2022-11-06T06:35:41.308] _job_complete: JobId=51894 WEXITSTATUS 0
[2022-11-06T06:35:41.308] _job_complete: JobId=51894 done
[2022-11-06T06:47:53.538] _slurm_rpc_submit_batch_job: JobId=52164 InitPrio=3238 usec=782
[2022-11-06T06:47:53.594] sched: Allocate JobId=52164 NodeList=cpu08 #CPUs=4 Partition=cpu-opteron
[2022-11-06T07:00:26.415] _job_complete: JobId=52121 WEXITSTATUS 0
[2022-11-06T07:00:26.415] _job_complete: JobId=52121 done
[2022-11-06T07:06:57.586] _slurm_rpc_submit_batch_job: JobId=52165 InitPrio=3238 usec=688
[2022-11-06T07:06:57.795] sched: Allocate JobId=52165 NodeList=cpu08 #CPUs=4 Partition=cpu-opteron
[2022-11-06T07:14:26.922] _job_complete: JobId=52153 WEXITSTATUS 0
[2022-11-06T07:14:26.927] _job_complete: JobId=52153 done
[2022-11-06T07:29:07.350] _job_complete: JobId=51890 WEXITSTATUS 0
[2022-11-06T07:29:07.351] _job_complete: JobId=51890 done
[2022-11-06T07:41:57.310] _job_complete: JobId=52165 WEXITSTATUS 0
[2022-11-06T07:41:57.310] _job_complete: JobId=52165 done
[2022-11-06T07:57:57.723] _slurm_rpc_submit_batch_job: JobId=52166 InitPrio=3238 usec=631
[2022-11-06T07:57:57.905] sched: Allocate JobId=52166 NodeList=cpu08 #CPUs=4 Partition=cpu-opteron
[2022-11-06T08:03:24.844] _job_complete: JobId=52164 WEXITSTATUS 0
[2022-11-06T08:03:24.844] _job_complete: JobId=52164 done
[2022-11-06T08:49:44.224] _job_complete: JobId=51896 WEXITSTATUS 0
[2022-11-06T08:49:44.224] _job_complete: JobId=51896 done
[2022-11-06T09:13:35.286] _job_complete: JobId=51889 WEXITSTATUS 0
[2022-11-06T09:13:35.286] _job_complete: JobId=51889 done
[2022-11-06T09:21:45.089] _job_complete: JobId=52166 WEXITSTATUS 1
[2022-11-06T09:21:45.089] _job_complete: JobId=52166 done
[2022-11-06T09:40:15.221] _slurm_rpc_submit_batch_job: JobId=52167 InitPrio=809 usec=480
[2022-11-06T09:40:16.062] sched: Allocate JobId=52167 NodeList=cpu15 #CPUs=24 Partition=cpu-epyc
[2022-11-06T09:41:23.652] _slurm_rpc_kill_job: REQUEST_KILL_JOB JobId=52149 uid 548200017
[2022-11-06T09:42:16.346] _slurm_rpc_submit_batch_job: JobId=52168 InitPrio=809 usec=508
[2022-11-06T09:42:16.379] sched: Allocate JobId=52168 NodeList=cpu14 #CPUs=24 Partition=cpu-epyc
[2022-11-06T09:45:37.269] _slurm_rpc_submit_batch_job: JobId=52169 InitPrio=809 usec=629
[2022-11-06T11:34:55.661] _job_complete: JobId=52122 WEXITSTATUS 0
[2022-11-06T11:34:55.661] _job_complete: JobId=52122 done
[2022-11-06T16:20:34.615] Time limit exhausted for JobId=52140
[2022-11-06T18:11:55.949] _slurm_rpc_kill_job: REQUEST_KILL_JOB JobId=52157 uid 548300593
[2022-11-06T18:11:58.338] sched: Allocate JobId=52146 NodeList=cpu[07-08] #CPUs=64 Partition=cpu-opteron
[2022-11-06T18:14:12.983] _slurm_rpc_kill_job: REQUEST_KILL_JOB JobId=52146 uid 548300593
[2022-11-06T18:14:18.395] sched: Allocate JobId=52154 NodeList=cpu07 #CPUs=64 Partition=cpu-opteron
[2022-11-06T18:14:18.396] sched: Allocate JobId=52155 NodeList=cpu08 #CPUs=64 Partition=cpu-opteron
[2022-11-06T18:15:33.626] _slurm_rpc_submit_batch_job: JobId=52170 InitPrio=1821 usec=564
[2022-11-06T21:05:07.846] Time limit exhausted for JobId=52148
[2022-11-06T22:49:07.082] Time limit exhausted for JobId=51821
[2022-11-06T22:49:16.417] sched: Allocate JobId=52156 NodeList=cpu05 #CPUs=64 Partition=cpu-opteron
[2022-11-06T23:46:17.310] _slurm_rpc_submit_batch_job: JobId=52171 InitPrio=3238 usec=583
[2022-11-06T23:46:18.079] sched: Allocate JobId=52171 NodeList=cpu09 #CPUs=4 Partition=cpu-opteron
[2022-11-06T23:59:33.386] _job_complete: JobId=52171 WEXITSTATUS 1
[2022-11-06T23:59:33.386] _job_complete: JobId=52171 done
[2022-11-07T01:00:29.933] _slurm_rpc_submit_batch_job: JobId=52172 InitPrio=1821 usec=567
[2022-11-07T01:00:59.851] sched/backfill: _start_job: Started JobId=52172 in cpu-opteron on cpu10
[2022-11-07T01:01:03.062] _job_complete: JobId=52172 WEXITSTATUS 1
[2022-11-07T01:01:03.062] _job_complete: JobId=52172 done
[2022-11-07T01:01:03.930] _slurm_rpc_kill_job: REQUEST_KILL_JOB JobId=52172 uid 548300593
[2022-11-07T01:02:01.745] _slurm_rpc_submit_batch_job: JobId=52173 InitPrio=1821 usec=577
[2022-11-07T01:28:10.017] _job_complete: JobId=52141 WEXITSTATUS 0
[2022-11-07T01:28:10.017] _job_complete: JobId=52141 done
[2022-11-07T01:28:10.777] sched: Allocate JobId=52170 NodeList=cpu04 #CPUs=64 Partition=cpu-opteron
[2022-11-07T01:43:44.565] _slurm_rpc_submit_batch_job: JobId=52174 InitPrio=3238 usec=536
[2022-11-07T01:43:44.709] sched: Allocate JobId=52174 NodeList=cpu09 #CPUs=4 Partition=cpu-opteron
[2022-11-07T01:57:01.616] _job_complete: JobId=52174 WEXITSTATUS 1
[2022-11-07T01:57:01.616] _job_complete: JobId=52174 done
[2022-11-07T03:47:25.990] _slurm_rpc_submit_batch_job: JobId=52175 InitPrio=3238 usec=636
[2022-11-07T03:47:26.022] sched: Allocate JobId=52175 NodeList=cpu09 #CPUs=4 Partition=cpu-opteron
[2022-11-07T04:01:28.003] _job_complete: JobId=52175 WEXITSTATUS 1
[2022-11-07T04:01:28.003] _job_complete: JobId=52175 done
[2022-11-07T06:55:14.754] _slurm_rpc_submit_batch_job: JobId=52176 InitPrio=3238 usec=595
[2022-11-07T06:55:15.982] sched: Allocate JobId=52176 NodeList=cpu09 #CPUs=4 Partition=cpu-opteron
[2022-11-07T07:11:12.168] _job_complete: JobId=52176 WEXITSTATUS 1
[2022-11-07T07:11:12.169] _job_complete: JobId=52176 done
[2022-11-07T07:39:46.203] _job_complete: JobId=52034 WEXITSTATUS 0
[2022-11-07T07:39:46.203] _job_complete: JobId=52034 done
[2022-11-07T07:39:46.873] sched: Allocate JobId=52169 NodeList=cpu15 #CPUs=24 Partition=cpu-epyc
[2022-11-07T08:53:39.319] _slurm_rpc_submit_batch_job: JobId=52177 InitPrio=4858 usec=597
[2022-11-07T10:00:55.949] _job_complete: JobId=52126 WEXITSTATUS 0
[2022-11-07T10:00:55.950] _job_complete: JobId=52126 done
[2022-11-07T10:04:36.183] _slurm_rpc_submit_batch_job: JobId=52178 InitPrio=809 usec=712
[2022-11-07T10:04:36.993] sched: Allocate JobId=52178 NodeList=gpu02 #CPUs=5 Partition=gpu-titan
[2022-11-07T10:05:06.865] _slurm_rpc_kill_job: REQUEST_KILL_JOB JobId=52178 uid 548200023
[2022-11-07T10:06:06.078] _slurm_rpc_submit_batch_job: JobId=52179 InitPrio=809 usec=594
[2022-11-07T10:06:06.086] sched: Allocate JobId=52179 NodeList=gpu02 #CPUs=5 Partition=gpu-titan
[2022-11-07T10:06:19.624] _slurm_rpc_submit_batch_job: JobId=52180 InitPrio=809 usec=524
[2022-11-07T10:06:20.380] sched: Allocate JobId=52180 NodeList=gpu02 #CPUs=5 Partition=gpu-titan
[2022-11-07T10:07:54.351] _slurm_rpc_submit_batch_job: JobId=52181 InitPrio=809 usec=532
[2022-11-07T10:07:54.542] sched: Allocate JobId=52181 NodeList=gpu02 #CPUs=5 Partition=gpu-titan
[2022-11-07T10:25:19.713] _slurm_rpc_submit_batch_job: JobId=52182 InitPrio=7287 usec=598
[2022-11-07T10:25:20.342] sched: Allocate JobId=52182 NodeList=cpu12 #CPUs=48 Partition=cpu-epyc
[2022-11-07T10:25:20.530] _job_complete: JobId=52182 WEXITSTATUS 1
[2022-11-07T10:25:20.531] _job_complete: JobId=52182 done
[2022-11-07T10:28:01.695] _slurm_rpc_submit_batch_job: JobId=52183 InitPrio=7287 usec=530
[2022-11-07T10:28:02.631] sched: Allocate JobId=52183 NodeList=cpu12 #CPUs=48 Partition=cpu-epyc
[2022-11-07T10:28:03.370] _job_complete: JobId=52183 WEXITSTATUS 1
[2022-11-07T10:28:03.370] _job_complete: JobId=52183 done
[2022-11-07T10:28:34.880] _slurm_rpc_submit_batch_job: JobId=52184 InitPrio=7287 usec=540
[2022-11-07T10:28:35.675] sched: Allocate JobId=52184 NodeList=cpu12 #CPUs=48 Partition=cpu-epyc
[2022-11-07T10:28:36.978] _job_complete: JobId=52184 WEXITSTATUS 127
[2022-11-07T10:28:36.978] _job_complete: JobId=52184 done
[2022-11-07T10:29:28.074] _slurm_rpc_submit_batch_job: JobId=52185 InitPrio=7287 usec=550
[2022-11-07T10:29:28.741] sched: Allocate JobId=52185 NodeList=cpu12 #CPUs=48 Partition=cpu-epyc
[2022-11-07T10:29:36.618] _job_complete: JobId=52185 WEXITSTATUS 1
[2022-11-07T10:29:36.618] _job_complete: JobId=52185 done
[2022-11-07T10:32:11.169] _slurm_rpc_submit_batch_job: JobId=52186 InitPrio=7287 usec=603
[2022-11-07T10:32:12.072] sched: Allocate JobId=52186 NodeList=cpu12 #CPUs=48 Partition=cpu-epyc
[2022-11-07T10:32:20.077] _job_complete: JobId=52186 WEXITSTATUS 1
[2022-11-07T10:32:20.077] _job_complete: JobId=52186 done
[2022-11-07T10:33:10.528] _slurm_rpc_submit_batch_job: JobId=52187 InitPrio=7287 usec=473
[2022-11-07T10:33:11.146] sched: Allocate JobId=52187 NodeList=cpu12 #CPUs=48 Partition=cpu-epyc
[2022-11-07T10:34:50.999] _slurm_rpc_kill_job: REQUEST_KILL_JOB JobId=52187 uid 548200003
[2022-11-07T10:35:01.616] _slurm_rpc_submit_batch_job: JobId=52188 InitPrio=7287 usec=616
[2022-11-07T10:35:02.282] sched: Allocate JobId=52188 NodeList=cpu12 #CPUs=48 Partition=cpu-epyc
[2022-11-07T11:32:35.322] _slurm_rpc_submit_batch_job: JobId=52189 InitPrio=809 usec=505
[2022-11-07T11:39:34.374] _slurm_rpc_submit_batch_job: JobId=52190 InitPrio=809 usec=592
[2022-11-07T11:39:34.931] sched: Allocate JobId=52190 NodeList=gpu04 #CPUs=16 Partition=gpu-k40c
[2022-11-07T11:39:54.984] _job_complete: JobId=52190 WEXITSTATUS 1
[2022-11-07T11:39:54.984] _job_complete: JobId=52190 done
[2022-11-07T11:40:53.223] _slurm_rpc_submit_batch_job: JobId=52191 InitPrio=809 usec=535
[2022-11-07T11:40:54.015] sched: Allocate JobId=52191 NodeList=gpu04 #CPUs=16 Partition=gpu-k40c
[2022-11-07T11:41:12.730] _job_complete: JobId=52191 WEXITSTATUS 1
[2022-11-07T11:41:12.730] _job_complete: JobId=52191 done
[2022-11-07T11:42:34.683] _slurm_rpc_submit_batch_job: JobId=52192 InitPrio=607 usec=501
[2022-11-07T11:42:52.134] _slurm_rpc_kill_job: REQUEST_KILL_JOB JobId=52192 uid 548200023
[2022-11-07T11:43:11.936] _slurm_rpc_submit_batch_job: JobId=52193 InitPrio=607 usec=519
[2022-11-07T11:43:22.562] _slurm_rpc_kill_job: REQUEST_KILL_JOB JobId=52193 uid 548200023
[2022-11-07T11:43:33.060] _slurm_rpc_submit_batch_job: JobId=52194 InitPrio=607 usec=536
[2022-11-07T11:43:48.935] _slurm_rpc_kill_job: REQUEST_KILL_JOB JobId=52194 uid 548200023
[2022-11-07T11:44:02.855] _slurm_rpc_submit_batch_job: JobId=52195 InitPrio=607 usec=542
[2022-11-07T11:44:11.247] _slurm_rpc_submit_batch_job: JobId=52196 InitPrio=809 usec=534
[2022-11-07T11:44:11.383] sched: Allocate JobId=52196 NodeList=gpu04 #CPUs=16 Partition=gpu-k40c
[2022-11-07T11:45:00.378] sched/backfill: _start_job: Started JobId=52195 in cpu-opteron on cpu[10-11]
[2022-11-07T11:48:27.482] _job_complete: JobId=52196 WEXITSTATUS 0
[2022-11-07T11:48:27.482] _job_complete: JobId=52196 done
[2022-11-07T11:50:50.071] _slurm_rpc_submit_batch_job: JobId=52197 InitPrio=809 usec=542
[2022-11-07T11:50:50.999] sched: Allocate JobId=52197 NodeList=gpu04 #CPUs=16 Partition=gpu-k40c
[2022-11-07T11:54:33.300] _job_complete: JobId=52197 WEXITSTATUS 0
[2022-11-07T11:54:33.300] _job_complete: JobId=52197 done
[2022-11-07T11:56:22.330] _slurm_rpc_submit_batch_job: JobId=52198 InitPrio=809 usec=534
[2022-11-07T11:56:22.743] sched: Allocate JobId=52198 NodeList=gpu04 #CPUs=16 Partition=gpu-k40c
[2022-11-07T12:01:55.122] _job_complete: JobId=52198 WEXITSTATUS 0
[2022-11-07T12:01:55.122] _job_complete: JobId=52198 done
[2022-11-07T12:11:29.704] _slurm_rpc_submit_batch_job: JobId=52199 InitPrio=809 usec=464
[2022-11-07T12:11:30.372] sched: Allocate JobId=52199 NodeList=gpu04 #CPUs=16 Partition=gpu-k40c
[2022-11-07T12:12:13.744] sched: _slurm_rpc_allocate_resources JobId=52200 NodeList=(null) usec=896
[2022-11-07T12:13:00.402] sched/backfill: _start_job: Started JobId=52200 in cpu-opteron on cpu10
[2022-11-07T12:22:12.245] _job_complete: JobId=52199 WEXITSTATUS 0
[2022-11-07T12:22:12.246] _job_complete: JobId=52199 done
[2022-11-07T12:25:02.876] _slurm_rpc_submit_batch_job: JobId=52201 InitPrio=809 usec=592
[2022-11-07T12:25:03.662] sched: Allocate JobId=52201 NodeList=gpu04 #CPUs=16 Partition=gpu-k40c
[2022-11-07T12:25:53.969] _job_complete: JobId=52201 WEXITSTATUS 1
[2022-11-07T12:25:53.970] _job_complete: JobId=52201 done
[2022-11-07T12:50:59.715] _slurm_rpc_submit_batch_job: JobId=52202 InitPrio=809 usec=549
[2022-11-07T13:00:18.154] _slurm_rpc_submit_batch_job: JobId=52203 InitPrio=809 usec=567
[2022-11-07T13:04:52.320] Requeuing JobId=52195
[2022-11-07T13:21:48.597] _slurm_rpc_submit_batch_job: JobId=52204 InitPrio=1012 usec=503
[2022-11-07T13:40:02.486] _slurm_rpc_submit_batch_job: JobId=52205 InitPrio=2429 usec=1002
[2022-11-07T13:41:27.431] _slurm_rpc_kill_job: REQUEST_KILL_JOB JobId=52204 uid 548200021
[2022-11-07T13:41:47.843] sched: _slurm_rpc_allocate_resources JobId=52206 NodeList=(null) usec=1175
[2022-11-07T13:41:48.528] sched: Allocate JobId=52206 NodeList=gpu04 #CPUs=8 Partition=gpu-k40c
[2022-11-07T13:42:02.181] _slurm_rpc_submit_batch_job: JobId=52207 InitPrio=2429 usec=1189
[2022-11-07T13:44:16.324] _slurm_rpc_submit_batch_job: JobId=52208 InitPrio=2429 usec=470
[2022-11-07T13:44:16.730] sched: Allocate JobId=52208 NodeList=cpu09 #CPUs=8 Partition=cpu-opteron
[2022-11-07T13:45:35.742] _slurm_rpc_submit_batch_job: JobId=52209 InitPrio=2429 usec=457
[2022-11-07T13:45:35.806] sched: Allocate JobId=52209 NodeList=cpu09 #CPUs=8 Partition=cpu-opteron
[2022-11-07T13:46:32.135] _slurm_rpc_submit_batch_job: JobId=52210 InitPrio=2429 usec=439
[2022-11-07T13:46:33.014] sched: Allocate JobId=52210 NodeList=cpu09 #CPUs=8 Partition=cpu-opteron
[2022-11-07T13:48:02.727] _slurm_rpc_submit_batch_job: JobId=52211 InitPrio=2429 usec=477
[2022-11-07T13:48:03.132] sched: Allocate JobId=52211 NodeList=cpu09 #CPUs=8 Partition=cpu-opteron
[2022-11-07T13:48:57.910] _slurm_rpc_submit_batch_job: JobId=52212 InitPrio=2429 usec=442
[2022-11-07T13:48:58.200] sched: Allocate JobId=52212 NodeList=cpu09 #CPUs=8 Partition=cpu-opteron
[2022-11-07T13:49:56.449] _slurm_rpc_submit_batch_job: JobId=52213 InitPrio=2429 usec=408
[2022-11-07T13:49:57.277] sched: Allocate JobId=52213 NodeList=cpu10 #CPUs=8 Partition=cpu-opteron
[2022-11-07T13:55:11.767] _job_complete: JobId=52206 WEXITSTATUS 0
[2022-11-07T13:55:11.767] _job_complete: JobId=52206 done
[2022-11-07T13:55:16.027] sched: Allocate JobId=52207 NodeList=gpu04 #CPUs=16 Partition=gpu-k40c
[2022-11-07T13:59:42.624] _slurm_rpc_kill_job: REQUEST_KILL_JOB JobId=52056 uid 548200021
[2022-11-07T14:02:54.759] _slurm_rpc_submit_batch_job: JobId=52214 InitPrio=2429 usec=524
[2022-11-07T14:02:55.701] sched: Allocate JobId=52214 NodeList=cpu10 #CPUs=16 Partition=cpu-opteron
[2022-11-07T14:12:17.457] _job_complete: JobId=52214 WEXITSTATUS 1
[2022-11-07T14:12:17.458] _job_complete: JobId=52214 done
[2022-11-07T14:55:00.651] _job_complete: JobId=52209 WEXITSTATUS 0
[2022-11-07T14:55:00.652] _job_complete: JobId=52209 done
[2022-11-07T15:02:43.687] _slurm_rpc_submit_batch_job: JobId=52215 InitPrio=1214 usec=657
[2022-11-07T15:02:47.404] _slurm_rpc_submit_batch_job: JobId=52216 InitPrio=1214 usec=474
[2022-11-07T15:02:50.724] _slurm_rpc_submit_batch_job: JobId=52217 InitPrio=1214 usec=501
[2022-11-07T15:02:54.524] _slurm_rpc_submit_batch_job: JobId=52218 InitPrio=1214 usec=487
[2022-11-07T15:02:57.477] _slurm_rpc_submit_batch_job: JobId=52219 InitPrio=1214 usec=509
[2022-11-07T15:03:00.308] _slurm_rpc_submit_batch_job: JobId=52220 InitPrio=1214 usec=478
[2022-11-07T15:03:02.964] _slurm_rpc_submit_batch_job: JobId=52221 InitPrio=1214 usec=467
[2022-11-07T15:03:05.868] _slurm_rpc_submit_batch_job: JobId=52222 InitPrio=1214 usec=497
[2022-11-07T15:03:08.749] _slurm_rpc_submit_batch_job: JobId=52223 InitPrio=1214 usec=478
[2022-11-07T15:03:12.180] _slurm_rpc_submit_batch_job: JobId=52224 InitPrio=1214 usec=402
[2022-11-07T15:03:15.253] _slurm_rpc_submit_batch_job: JobId=52225 InitPrio=1214 usec=527
[2022-11-07T15:03:18.077] _slurm_rpc_submit_batch_job: JobId=52226 InitPrio=1214 usec=461
[2022-11-07T15:03:20.724] _slurm_rpc_submit_batch_job: JobId=52227 InitPrio=1214 usec=492
[2022-11-07T15:03:23.164] _slurm_rpc_submit_batch_job: JobId=52228 InitPrio=1214 usec=413
[2022-11-07T15:03:25.935] _slurm_rpc_submit_batch_job: JobId=52229 InitPrio=1214 usec=525
[2022-11-07T15:03:28.508] _slurm_rpc_submit_batch_job: JobId=52230 InitPrio=1214 usec=516
[2022-11-07T15:03:31.036] _slurm_rpc_submit_batch_job: JobId=52231 InitPrio=1214 usec=546
[2022-11-07T15:03:33.509] _slurm_rpc_submit_batch_job: JobId=52232 InitPrio=1214 usec=506
[2022-11-07T15:03:36.119] _slurm_rpc_submit_batch_job: JobId=52233 InitPrio=1214 usec=526
[2022-11-07T15:03:39.620] _slurm_rpc_submit_batch_job: JobId=52234 InitPrio=1214 usec=475
[2022-11-07T15:04:00.581] sched/backfill: _start_job: Started JobId=52230 in cpu-opteron on cpu09
[2022-11-07T15:04:00.581] sched/backfill: _start_job: Started JobId=52231 in cpu-opteron on cpu10
[2022-11-07T15:04:00.582] sched/backfill: _start_job: Started JobId=52232 in cpu-opteron on cpu10
[2022-11-07T15:04:00.583] sched/backfill: _start_job: Started JobId=52233 in cpu-opteron on cpu10
[2022-11-07T15:04:00.584] sched/backfill: _start_job: Started JobId=52234 in cpu-opteron on cpu10
[2022-11-07T15:04:01.665] _job_create: exceeded association/QOS limit for user 548300626: AssocGrpCpuLimit
[2022-11-07T15:04:01.665] _slurm_rpc_submit_batch_job: Job violates accounting/QOS policy (job submit limit, user's size and/or time limits)
[2022-11-07T15:04:49.743] _slurm_rpc_submit_batch_job: JobId=52235 InitPrio=59190 usec=499
[2022-11-07T15:04:50.155] sched: Allocate JobId=52235 NodeList=cpu10 #CPUs=2 Partition=cpu-opteron
[2022-11-07T15:04:51.177] _job_complete: JobId=52235 WEXITSTATUS 127
[2022-11-07T15:04:51.177] _job_complete: JobId=52235 done
[2022-11-07T15:07:13.422] _slurm_rpc_submit_batch_job: JobId=52236 InitPrio=1214 usec=463
[2022-11-07T15:07:16.127] _slurm_rpc_submit_batch_job: JobId=52237 InitPrio=1214 usec=501
[2022-11-07T15:07:18.903] _slurm_rpc_submit_batch_job: JobId=52238 InitPrio=1214 usec=492
[2022-11-07T15:07:21.455] _slurm_rpc_submit_batch_job: JobId=52239 InitPrio=1214 usec=467
[2022-11-07T15:07:23.959] _slurm_rpc_submit_batch_job: JobId=52240 InitPrio=1214 usec=490
[2022-11-07T15:07:26.646] _slurm_rpc_submit_batch_job: JobId=52241 InitPrio=1214 usec=555
[2022-11-07T15:07:29.374] _slurm_rpc_submit_batch_job: JobId=52242 InitPrio=1214 usec=467
[2022-11-07T15:07:31.959] _slurm_rpc_submit_batch_job: JobId=52243 InitPrio=1214 usec=482
[2022-11-07T15:07:34.702] _slurm_rpc_submit_batch_job: JobId=52244 InitPrio=1214 usec=499
[2022-11-07T15:07:38.007] _slurm_rpc_submit_batch_job: JobId=52245 InitPrio=1214 usec=476
[2022-11-07T15:07:40.727] _slurm_rpc_submit_batch_job: JobId=52246 InitPrio=1214 usec=764
[2022-11-07T15:08:00.590] sched/backfill: _start_job: Started JobId=52236 in cpu-opteron on cpu10
[2022-11-07T15:08:00.590] sched/backfill: _start_job: Started JobId=52237 in cpu-opteron on cpu11
[2022-11-07T15:08:00.591] sched/backfill: _start_job: Started JobId=52238 in cpu-opteron on cpu11
[2022-11-07T15:08:00.592] sched/backfill: _start_job: Started JobId=52239 in cpu-opteron on cpu11
[2022-11-07T15:08:00.592] sched/backfill: _start_job: Started JobId=52240 in cpu-opteron on cpu11
[2022-11-07T15:08:00.593] sched/backfill: _start_job: Started JobId=52241 in cpu-opteron on cpu11
[2022-11-07T15:08:00.593] sched/backfill: _start_job: Started JobId=52242 in cpu-opteron on cpu11
[2022-11-07T15:18:39.461] _slurm_rpc_submit_batch_job: JobId=52247 InitPrio=22145 usec=693
[2022-11-07T15:18:39.733] sched: Allocate JobId=52247 NodeList=cpu10 #CPUs=2 Partition=cpu-opteron
[2022-11-07T15:19:00.559] _job_complete: JobId=52247 WEXITSTATUS 0
[2022-11-07T15:19:00.559] _job_complete: JobId=52247 done
[2022-11-07T15:23:17.265] _job_complete: JobId=51983 WEXITSTATUS 0
[2022-11-07T15:23:17.266] _job_complete: JobId=51983 done
[2022-11-07T15:23:19.448] sched: Allocate JobId=51980 NodeList=gpu03 #CPUs=16 Partition=gpu-k10
[2022-11-07T15:26:48.698] _slurm_rpc_submit_batch_job: JobId=52248 InitPrio=2631 usec=578
[2022-11-07T15:37:34.323] _job_complete: JobId=51980 WEXITSTATUS 1
[2022-11-07T15:37:34.323] _job_complete: JobId=51980 done
[2022-11-07T15:52:58.652] _job_complete: JobId=52210 WEXITSTATUS 0
[2022-11-07T15:52:58.654] _job_complete: JobId=52210 done
[2022-11-07T15:53:00.659] sched/backfill: _start_job: Started JobId=52243 in cpu-opteron on cpu09
[2022-11-07T15:54:23.167] _job_complete: JobId=52211 WEXITSTATUS 0
[2022-11-07T15:54:23.168] _job_complete: JobId=52211 done
[2022-11-07T15:55:00.663] sched/backfill: _start_job: Started JobId=52244 in cpu-opteron on cpu09
[2022-11-07T15:56:17.498] _job_complete: JobId=52208 WEXITSTATUS 0
[2022-11-07T15:56:17.499] _job_complete: JobId=52208 done
[2022-11-07T15:59:18.635] _slurm_rpc_submit_batch_job: JobId=52249 InitPrio=1417 usec=602
[2022-11-07T15:59:32.656] _slurm_rpc_kill_job: REQUEST_KILL_JOB JobId=52170 uid 548300593
[2022-11-07T15:59:33.959] sched: Allocate JobId=52142 NodeList=cpu04 #CPUs=64 Partition=cpu-opteron
[2022-11-07T16:00:38.081] _job_complete: JobId=52213 WEXITSTATUS 0
[2022-11-07T16:00:38.081] _job_complete: JobId=52213 done
[2022-11-07T16:01:00.672] sched/backfill: _start_job: Started JobId=52245 in cpu-opteron on cpu10
[2022-11-07T16:07:52.205] _job_complete: JobId=52212 WEXITSTATUS 0
[2022-11-07T16:07:52.206] _job_complete: JobId=52212 done
[2022-11-07T16:08:00.683] sched/backfill: _start_job: Started JobId=52246 in cpu-opteron on cpu09
[2022-11-07T16:25:55.335] _job_complete: JobId=52200 WEXITSTATUS 0
[2022-11-07T16:25:55.335] _job_complete: JobId=52200 done
[2022-11-07T16:43:34.782] _job_complete: JobId=52188 WEXITSTATUS 0
[2022-11-07T16:43:34.783] _job_complete: JobId=52188 done
[2022-11-07T17:18:50.159] sched: _slurm_rpc_allocate_resources JobId=52250 NodeList=cpu09 usec=17137
[2022-11-07T17:28:24.011] _job_complete: JobId=52250 WEXITSTATUS 127
[2022-11-07T17:28:24.011] _job_complete: JobId=52250 done
[2022-11-07T20:15:27.366] _slurm_rpc_submit_batch_job: JobId=52251 InitPrio=19919 usec=848
[2022-11-07T20:15:27.398] sched: Allocate JobId=52251 NodeList=cpu09 #CPUs=4 Partition=cpu-opteron
[2022-11-07T20:38:09.336] _slurm_rpc_submit_batch_job: JobId=52252 InitPrio=19514 usec=644
[2022-11-07T20:39:47.450] _slurm_rpc_kill_job: REQUEST_KILL_JOB JobId=52252 uid 548300630
[2022-11-07T20:47:04.142] _slurm_rpc_submit_batch_job: JobId=52253 InitPrio=19311 usec=643
[2022-11-07T20:49:13.353] _slurm_rpc_kill_job: REQUEST_KILL_JOB JobId=52253 uid 548300630
[2022-11-07T20:59:26.101] _slurm_rpc_submit_batch_job: JobId=52254 InitPrio=19311 usec=543
[2022-11-07T20:59:53.580] _slurm_rpc_kill_job: REQUEST_KILL_JOB JobId=52254 uid 548300630
[2022-11-07T21:05:56.389] _job_complete: JobId=52181 WEXITSTATUS 0
[2022-11-07T21:05:56.389] _job_complete: JobId=52181 done
[2022-11-07T21:15:38.523] Time limit exhausted for JobId=52251
[2022-11-07T21:20:40.358] _slurm_rpc_submit_batch_job: JobId=52255 InitPrio=18502 usec=623
[2022-11-07T21:20:41.065] sched: Allocate JobId=52255 NodeList=gpu02 #CPUs=4 Partition=gpu-titan
[2022-11-07T21:20:42.530] _job_complete: JobId=52255 WEXITSTATUS 2
[2022-11-07T21:20:42.530] _job_complete: JobId=52255 done
[2022-11-07T21:21:31.724] _slurm_rpc_kill_job: REQUEST_KILL_JOB JobId=52255 uid 548300630
[2022-11-07T21:22:45.617] _slurm_rpc_submit_batch_job: JobId=52256 InitPrio=18502 usec=468
[2022-11-07T21:22:46.428] sched: Allocate JobId=52256 NodeList=cpu09 #CPUs=4 Partition=cpu-opteron
[2022-11-07T21:23:01.070] _job_complete: JobId=52256 WEXITSTATUS 1
[2022-11-07T21:23:01.070] _job_complete: JobId=52256 done
[2022-11-07T21:23:01.173] _slurm_rpc_kill_job: REQUEST_KILL_JOB JobId=52256 uid 548300630
[2022-11-07T21:23:41.447] _slurm_rpc_submit_batch_job: JobId=52257 InitPrio=18502 usec=500
[2022-11-07T21:23:41.495] sched: Allocate JobId=52257 NodeList=cpu09 #CPUs=4 Partition=cpu-opteron
[2022-11-07T21:23:55.708] _job_complete: JobId=52257 WEXITSTATUS 1
[2022-11-07T21:23:55.708] _job_complete: JobId=52257 done
[2022-11-07T21:32:41.956] sched: _slurm_rpc_allocate_resources JobId=52258 NodeList=cpu09 usec=16028
[2022-11-07T21:40:23.536] _job_complete: JobId=52258 WEXITSTATUS 0
[2022-11-07T21:40:23.536] _job_complete: JobId=52258 done
[2022-11-07T21:40:50.965] sched: _slurm_rpc_allocate_resources JobId=52259 NodeList=cpu09 usec=1312
[2022-11-07T21:45:34.224] sched: _slurm_rpc_allocate_resources JobId=52260 NodeList=cpu09 usec=17094
[2022-11-07T21:46:29.141] sched: _slurm_rpc_allocate_resources JobId=52261 NodeList=(null) usec=995
[2022-11-07T21:47:01.094] sched/backfill: _start_job: Started JobId=52261 in cpu-opteron on cpu10
[2022-11-07T22:16:12.961] _slurm_rpc_submit_batch_job: JobId=52262 InitPrio=1012 usec=591
[2022-11-07T22:17:01.132] sched/backfill: _start_job: Started JobId=52262 in cpu-opteron on cpu11
[2022-11-07T22:17:03.725] _job_complete: JobId=52262 WEXITSTATUS 0
[2022-11-07T22:17:03.725] _job_complete: JobId=52262 done
[2022-11-07T22:20:48.292] _pick_best_nodes: JobId=52263 never runnable in partition cpu-opteron
[2022-11-07T22:20:48.292] _slurm_rpc_submit_batch_job: Requested node configuration is not available
[2022-11-07T22:24:46.274] sched: _slurm_rpc_allocate_resources JobId=52264 NodeList=cpu10 usec=1968
[2022-11-07T22:39:43.847] sched: _slurm_rpc_allocate_resources JobId=52265 NodeList=cpu11 usec=2029
[2022-11-07T22:41:17.023] _job_complete: JobId=52265 WEXITSTATUS 0
[2022-11-07T22:41:17.023] _job_complete: JobId=52265 done
[2022-11-07T22:41:37.567] _pick_best_nodes: JobId=52266 never runnable in partition cpu-opteron
[2022-11-07T22:41:37.567] _slurm_rpc_submit_batch_job: Requested node configuration is not available
[2022-11-07T22:45:39.990] Time limit exhausted for JobId=52260
[2022-11-07T22:50:54.331] _pick_best_nodes: JobId=52267 never runnable in partition cpu-opteron
[2022-11-07T22:50:54.331] _slurm_rpc_submit_batch_job: Requested node configuration is not available
[2022-11-07T22:51:37.721] _pick_best_nodes: JobId=52268 never runnable in partition cpu-opteron
[2022-11-07T22:51:37.721] _slurm_rpc_submit_batch_job: Requested node configuration is not available
[2022-11-07T22:54:02.111] sched: _slurm_rpc_allocate_resources JobId=52269 NodeList=cpu09 usec=2047
[2022-11-07T22:55:03.002] _job_complete: JobId=52269 WEXITSTATUS 1
[2022-11-07T22:55:03.003] _job_complete: JobId=52269 done
[2022-11-07T23:04:06.676] _slurm_rpc_submit_batch_job: JobId=52270 InitPrio=9514 usec=534
[2022-11-07T23:06:16.144] _slurm_rpc_kill_job: REQUEST_KILL_JOB JobId=52264 uid 548300537
[2022-11-07T23:06:16.145] _slurm_rpc_kill_job: REQUEST_KILL_JOB JobId=52259 uid 548300537
[2022-11-08T00:02:30.299] error: This association 113(account='free', user='hongvin', partition='(null)') does not have access to qos normal
[2022-11-08T00:02:30.299] _slurm_rpc_submit_batch_job: Invalid qos specification
[2022-11-08T00:03:11.386] error: This association 113(account='free', user='hongvin', partition='(null)') does not have access to qos normal
[2022-11-08T00:03:11.386] _slurm_rpc_submit_batch_job: Invalid qos specification
[2022-11-08T00:03:48.988] error: This association 113(account='free', user='hongvin', partition='(null)') does not have access to qos normal
[2022-11-08T00:03:48.988] _slurm_rpc_submit_batch_job: Invalid qos specification
[2022-11-08T00:05:15.238] error: This association 113(account='free', user='hongvin', partition='(null)') does not have access to qos normal
[2022-11-08T00:05:15.238] _slurm_rpc_submit_batch_job: Invalid qos specification
[2022-11-08T00:05:21.888] error: This association 113(account='free', user='hongvin', partition='(null)') does not have access to qos normal
[2022-11-08T00:05:21.888] _slurm_rpc_submit_batch_job: Invalid qos specification
[2022-11-08T00:05:35.900] error: This association 113(account='free', user='hongvin', partition='(null)') does not have access to qos normal
[2022-11-08T00:05:35.901] _slurm_rpc_submit_batch_job: Invalid qos specification
[2022-11-08T00:06:41.391] error: This association 113(account='free', user='hongvin', partition='(null)') does not have access to qos normal
[2022-11-08T00:06:41.391] _slurm_rpc_submit_batch_job: Invalid qos specification
[2022-11-08T00:07:58.601] error: This association 113(account='free', user='hongvin', partition='(null)') does not have access to qos normal
[2022-11-08T00:07:58.601] _slurm_rpc_submit_batch_job: Invalid qos specification
[2022-11-08T00:09:24.749] _job_create: exceeded association/QOS limit for user 548200121: QOSMaxWallDurationPerJobLimit
[2022-11-08T00:09:24.749] _slurm_rpc_allocate_resources: Job violates accounting/QOS policy (job submit limit, user's size and/or time limits) 
[2022-11-08T00:09:46.547] _job_create: exceeded association/QOS limit for user 548200121: QOSMaxWallDurationPerJobLimit
[2022-11-08T00:09:46.547] _slurm_rpc_allocate_resources: Job violates accounting/QOS policy (job submit limit, user's size and/or time limits) 
[2022-11-08T00:12:03.804] _job_create: invalid account or partition for user 548200121, account 'hongvin', and partition 'cpu-opteron'
[2022-11-08T00:12:03.804] _slurm_rpc_allocate_resources: Invalid account or account/partition combination specified 
[2022-11-08T00:12:12.707] _job_create: exceeded association/QOS limit for user 548200121: QOSMaxWallDurationPerJobLimit
[2022-11-08T00:12:12.707] _slurm_rpc_allocate_resources: Job violates accounting/QOS policy (job submit limit, user's size and/or time limits) 
[2022-11-08T01:10:13.269] _job_complete: JobId=52261 WEXITSTATUS 0
[2022-11-08T01:10:13.270] _job_complete: JobId=52261 done
[2022-11-08T01:15:13.977] cleanup_completing: JobId=52261 completion process took 300 seconds
[2022-11-08T01:43:47.816] _slurm_rpc_submit_batch_job: JobId=52271 InitPrio=2429 usec=519
[2022-11-08T01:44:01.427] sched/backfill: _start_job: Started JobId=52271 in cpu-opteron on cpu11
[2022-11-08T01:45:24.864] _slurm_rpc_submit_batch_job: JobId=52272 InitPrio=2429 usec=488
[2022-11-08T01:46:57.872] _slurm_rpc_submit_batch_job: JobId=52273 InitPrio=2429 usec=439
[2022-11-08T01:48:18.181] _slurm_rpc_submit_batch_job: JobId=52274 InitPrio=2429 usec=479
[2022-11-08T01:49:47.501] _slurm_rpc_submit_batch_job: JobId=52275 InitPrio=2429 usec=462
[2022-11-08T01:51:24.833] _slurm_rpc_submit_batch_job: JobId=52276 InitPrio=2429 usec=464
[2022-11-08T04:13:42.255] _job_complete: JobId=52271 WEXITSTATUS 1
[2022-11-08T04:13:42.261] _job_complete: JobId=52271 done
[2022-11-08T04:14:01.755] sched/backfill: _start_job: Started JobId=52272 in cpu-opteron on cpu11
[2022-11-08T05:41:10.281] _job_complete: JobId=52272 WEXITSTATUS 1
[2022-11-08T05:41:10.283] _job_complete: JobId=52272 done
[2022-11-08T05:42:01.890] sched/backfill: _start_job: Started JobId=52273 in cpu-opteron on cpu11
[2022-11-08T06:14:41.492] _job_complete: JobId=52179 WEXITSTATUS 0
[2022-11-08T06:14:41.492] _job_complete: JobId=52179 done
[2022-11-08T06:14:42.603] sched: Allocate JobId=52205 NodeList=gpu02 #CPUs=8 Partition=gpu-titan
[2022-11-08T08:11:10.797] _job_complete: JobId=52273 WEXITSTATUS 1
[2022-11-08T08:11:10.803] _job_complete: JobId=52273 done
[2022-11-08T08:12:02.114] sched/backfill: _start_job: Started JobId=52274 in cpu-opteron on cpu11
[2022-11-08T08:12:35.254] _slurm_rpc_submit_batch_job: JobId=52277 InitPrio=1821 usec=554
[2022-11-08T08:12:36.218] sched: Allocate JobId=52277 NodeList=gpu01 #CPUs=16 Partition=gpu-k10
[2022-11-08T08:12:38.910] _job_complete: JobId=52277 WEXITSTATUS 127
[2022-11-08T08:12:38.910] _job_complete: JobId=52277 done
[2022-11-08T08:15:10.651] _slurm_rpc_submit_batch_job: JobId=52278 InitPrio=1821 usec=449
[2022-11-08T09:02:57.304] sched: _slurm_rpc_allocate_resources JobId=52279 NodeList=(null) usec=1299
[2022-11-08T09:03:23.880] _job_complete: JobId=52279 WTERMSIG 126
[2022-11-08T09:03:23.880] _job_complete: JobId=52279 cancelled by interactive user
[2022-11-08T09:03:23.880] _job_complete: JobId=52279 done
[2022-11-08T09:03:30.935] _slurm_rpc_kill_job: REQUEST_KILL_JOB JobId=52279 uid 548300543
[2022-11-08T09:04:25.928] sched: _slurm_rpc_allocate_resources JobId=52280 NodeList=(null) usec=901
[2022-11-08T09:05:02.216] sched/backfill: _start_job: Started JobId=52280 in cpu-opteron on cpu09
[2022-11-08T09:46:15.338] _slurm_rpc_submit_batch_job: JobId=52281 InitPrio=4655 usec=555
[2022-11-08T09:46:15.792] sched: Allocate JobId=52281 NodeList=cpu12 #CPUs=48 Partition=cpu-epyc
[2022-11-08T09:52:41.487] _job_complete: JobId=52281 WEXITSTATUS 0
[2022-11-08T09:52:41.487] _job_complete: JobId=52281 done
[2022-11-08T09:53:02.430] _slurm_rpc_kill_job: REQUEST_KILL_JOB JobId=52280 uid 548300543
[2022-11-08T09:58:05.791] sched: _slurm_rpc_allocate_resources JobId=52282 NodeList=cpu09 usec=14386
[2022-11-08T10:03:39.649] Time limit exhausted for JobId=51893
[2022-11-08T10:03:39.649] Time limit exhausted for JobId=51900
[2022-11-08T10:03:39.650] Time limit exhausted for JobId=51901
[2022-11-08T10:03:39.650] Time limit exhausted for JobId=51902
[2022-11-08T10:04:02.327] sched/backfill: _start_job: Started JobId=52275 in cpu-opteron on cpu10
[2022-11-08T10:04:02.328] sched/backfill: _start_job: Started JobId=52276 in cpu-opteron on cpu10
[2022-11-08T10:11:33.368] _job_complete: JobId=52282 WEXITSTATUS 0
[2022-11-08T10:11:33.369] _job_complete: JobId=52282 done
[2022-11-08T10:33:16.960] sched: _slurm_rpc_allocate_resources JobId=52283 NodeList=cpu11 usec=1991
[2022-11-08T10:40:46.610] _job_complete: JobId=52274 WEXITSTATUS 1
[2022-11-08T10:40:46.611] _job_complete: JobId=52274 done
[2022-11-08T10:44:15.839] sched: Updated reservation=ceph_cbt_test users=jitkang,yeehengteh nodes=cpu12 cores=48 licenses=(null) tres=cpu=96 watts=4294967294 start=2022-11-05T20:46:40 end=2023-11-05T20:46:40 MaxStartDelay=
[2022-11-08T10:48:48.877] _slurm_rpc_submit_batch_job: JobId=52284 InitPrio=14032 usec=618
[2022-11-08T10:48:49.518] sched: Allocate JobId=52284 NodeList=cpu12 #CPUs=16 Partition=cpu-epyc
[2022-11-08T10:49:18.571] _slurm_rpc_submit_batch_job: JobId=52285 InitPrio=14032 usec=540
[2022-11-08T10:49:19.536] sched: Allocate JobId=52285 NodeList=cpu12 #CPUs=16 Partition=cpu-epyc
[2022-11-08T10:49:40.735] _slurm_rpc_submit_batch_job: JobId=52286 InitPrio=14032 usec=498
[2022-11-08T10:49:41.564] sched: Allocate JobId=52286 NodeList=cpu12 #CPUs=16 Partition=cpu-epyc
[2022-11-08T10:51:33.656] _slurm_rpc_submit_batch_job: JobId=52287 InitPrio=14032 usec=567
[2022-11-08T10:52:20.985] _slurm_rpc_submit_batch_job: JobId=52288 InitPrio=14032 usec=504
[2022-11-08T10:53:05.114] _slurm_rpc_submit_batch_job: JobId=52289 InitPrio=14032 usec=532
[2022-11-08T11:05:15.440] _job_complete: JobId=52283 WEXITSTATUS 0
[2022-11-08T11:05:15.440] _job_complete: JobId=52283 done
[2022-11-08T11:09:49.061] _job_complete: JobId=52284 WEXITSTATUS 0
[2022-11-08T11:09:49.061] _job_complete: JobId=52284 done
[2022-11-08T11:09:49.440] sched: Allocate JobId=52287 NodeList=cpu12 #CPUs=16 Partition=cpu-epyc
[2022-11-08T11:10:05.949] error: This association 242(account='free', user='htt_felicia', partition='(null)') does not have access to qos normal
[2022-11-08T11:10:05.949] _slurm_rpc_submit_batch_job: Invalid qos specification
[2022-11-08T11:10:08.443] _job_complete: JobId=52285 WEXITSTATUS 0
[2022-11-08T11:10:08.443] _job_complete: JobId=52285 done
[2022-11-08T11:10:08.789] sched: Allocate JobId=52288 NodeList=cpu12 #CPUs=16 Partition=cpu-epyc
[2022-11-08T11:10:29.480] _job_complete: JobId=52286 WEXITSTATUS 0
[2022-11-08T11:10:29.480] _job_complete: JobId=52286 done
[2022-11-08T11:10:29.830] sched: Allocate JobId=52289 NodeList=cpu12 #CPUs=16 Partition=cpu-epyc
[2022-11-08T11:13:01.798] _job_complete: JobId=52287 WEXITSTATUS 0
[2022-11-08T11:13:01.798] _job_complete: JobId=52287 done
[2022-11-08T11:13:02.407] error: This association 242(account='free', user='htt_felicia', partition='(null)') does not have access to qos normal
[2022-11-08T11:13:02.407] _slurm_rpc_submit_batch_job: Invalid qos specification
[2022-11-08T11:13:31.812] _job_complete: JobId=52289 WEXITSTATUS 0
[2022-11-08T11:13:31.812] _job_complete: JobId=52289 done
[2022-11-08T11:13:42.250] _job_complete: JobId=52288 WEXITSTATUS 0
[2022-11-08T11:13:42.250] _job_complete: JobId=52288 done
[2022-11-08T11:20:26.302] error: This association 242(account='free', user='htt_felicia', partition='(null)') does not have access to qos normal
[2022-11-08T11:20:26.302] _slurm_rpc_submit_batch_job: Invalid qos specification
[2022-11-08T11:28:00.417] _slurm_rpc_submit_batch_job: JobId=52290 InitPrio=604 usec=561
[2022-11-08T11:28:39.185] error: This association 242(account='free', user='htt_felicia', partition='(null)') does not have access to qos normal
[2022-11-08T11:28:39.185] _slurm_rpc_submit_batch_job: Invalid qos specification
[2022-11-08T11:28:45.725] error: This association 242(account='free', user='htt_felicia', partition='(null)') does not have access to qos normal
[2022-11-08T11:28:45.725] _slurm_rpc_submit_batch_job: Invalid qos specification
[2022-11-08T11:29:30.692] error: This association 242(account='free', user='htt_felicia', partition='(null)') does not have access to qos long
[2022-11-08T11:29:30.692] _slurm_rpc_submit_batch_job: Invalid qos specification
[2022-11-08T11:29:49.932] _job_create: exceeded association/QOS limit for user 548300626: AssocGrpCpuLimit
[2022-11-08T11:29:49.932] _slurm_rpc_submit_batch_job: Job violates accounting/QOS policy (job submit limit, user's size and/or time limits)
[2022-11-08T11:30:23.271] error: This association 242(account='free', user='htt_felicia', partition='(null)') does not have access to qos normal
[2022-11-08T11:30:23.271] _slurm_rpc_submit_batch_job: Invalid qos specification
[2022-11-08T11:38:54.287] error: This association 242(account='free', user='htt_felicia', partition='(null)') does not have access to qos normal
[2022-11-08T11:38:54.287] _slurm_rpc_submit_batch_job: Invalid qos specification
[2022-11-08T11:41:03.478] error: This association 242(account='free', user='htt_felicia', partition='(null)') does not have access to qos normal
[2022-11-08T11:41:03.478] _slurm_rpc_submit_batch_job: Invalid qos specification
[2022-11-08T11:46:48.907] job_step_signal: JobId=52097 StepId=0 not found
[2022-11-08T11:51:34.517] error: This association 242(account='free', user='htt_felicia', partition='(null)') does not have access to qos normal
[2022-11-08T11:51:34.517] _slurm_rpc_submit_batch_job: Invalid qos specification
[2022-11-08T11:53:16.788] error: This association 242(account='free', user='htt_felicia', partition='(null)') does not have access to qos normal
[2022-11-08T11:53:16.788] _slurm_rpc_submit_batch_job: Invalid qos specification
[2022-11-08T12:00:27.497] _slurm_rpc_kill_job: REQUEST_KILL_JOB JobId=52173 uid 548300593
[2022-11-08T12:00:40.929] _slurm_rpc_kill_job: REQUEST_KILL_JOB JobId=52249 uid 548300593
[2022-11-08T12:00:55.805] _slurm_rpc_submit_batch_job: JobId=52291 InitPrio=1411 usec=486
[2022-11-08T12:01:02.496] sched/backfill: _start_job: Started JobId=52291 in cpu-opteron on cpu09
[2022-11-08T12:01:15.447] _slurm_rpc_submit_batch_job: JobId=52292 InitPrio=1411 usec=435
[2022-11-08T12:01:23.417] _job_complete: JobId=52291 WEXITSTATUS 1
[2022-11-08T12:01:23.417] _job_complete: JobId=52291 done
[2022-11-08T12:01:46.132] _slurm_rpc_kill_job: REQUEST_KILL_JOB JobId=52156 uid 548300593
[2022-11-08T12:01:54.467] sched: Allocate JobId=52270 NodeList=cpu05 #CPUs=64 Partition=cpu-opteron
[2022-11-08T12:01:54.469] sched: Allocate JobId=52292 NodeList=cpu09 #CPUs=32 Partition=cpu-opteron
[2022-11-08T12:01:59.019] _job_complete: JobId=52270 WEXITSTATUS 127
[2022-11-08T12:01:59.020] _job_complete: JobId=52270 done
[2022-11-08T12:02:21.735] _slurm_rpc_kill_job: REQUEST_KILL_JOB JobId=52156 uid 548300593
[2022-11-08T12:11:15.333] _slurm_rpc_submit_batch_job: JobId=52293 InitPrio=1411 usec=448
[2022-11-08T12:11:15.766] sched: Allocate JobId=52293 NodeList=cpu05 #CPUs=24 Partition=cpu-opteron
[2022-11-08T12:11:22.188] _job_complete: JobId=52293 WEXITSTATUS 0
[2022-11-08T12:11:22.189] _job_complete: JobId=52293 done
[2022-11-08T12:12:36.310] _slurm_rpc_submit_batch_job: JobId=52294 InitPrio=1411 usec=502
[2022-11-08T12:12:36.913] sched: Allocate JobId=52294 NodeList=cpu05 #CPUs=24 Partition=cpu-opteron
[2022-11-08T12:21:01.076] _slurm_rpc_submit_batch_job: JobId=52295 InitPrio=1411 usec=564
[2022-11-08T12:21:01.710] sched: Allocate JobId=52295 NodeList=cpu05 #CPUs=24 Partition=cpu-opteron
[2022-11-08T12:22:11.233] _job_complete: JobId=52294 WEXITSTATUS 1
[2022-11-08T12:22:11.233] _job_complete: JobId=52294 done
[2022-11-08T12:32:15.383] _slurm_rpc_submit_batch_job: JobId=52296 InitPrio=1411 usec=647
[2022-11-08T12:32:15.895] sched: Allocate JobId=52296 NodeList=cpu05 #CPUs=16 Partition=cpu-opteron
[2022-11-08T12:32:40.684] _slurm_rpc_submit_batch_job: JobId=52297 InitPrio=1411 usec=615
[2022-11-08T12:32:40.926] sched: Allocate JobId=52297 NodeList=cpu05 #CPUs=16 Partition=cpu-opteron
[2022-11-08T12:32:50.656] _slurm_rpc_kill_job: REQUEST_KILL_JOB JobId=52297 uid 548300593
[2022-11-08T12:48:43.218] _job_complete: JobId=52276 WEXITSTATUS 1
[2022-11-08T12:48:43.224] _job_complete: JobId=52276 done
[2022-11-08T12:49:27.273] _job_complete: JobId=52275 WEXITSTATUS 1
[2022-11-08T12:49:27.274] _job_complete: JobId=52275 done
[2022-11-08T13:18:31.340] _slurm_rpc_submit_batch_job: JobId=52298 InitPrio=2217 usec=1054
[2022-11-08T13:18:31.593] sched: Allocate JobId=52298 NodeList=gpu01 #CPUs=16 Partition=gpu-k10
[2022-11-08T13:20:14.081] _slurm_rpc_submit_batch_job: JobId=52299 InitPrio=2217 usec=1011
[2022-11-08T13:20:14.703] sched: Allocate JobId=52299 NodeList=gpu03 #CPUs=16 Partition=gpu-k10
[2022-11-08T13:21:51.859] _slurm_rpc_submit_batch_job: JobId=52300 InitPrio=2217 usec=1148
[2022-11-08T13:27:28.929] _slurm_rpc_submit_batch_job: JobId=52301 InitPrio=2217 usec=976
[2022-11-08T13:29:56.815] _slurm_rpc_submit_batch_job: JobId=52302 InitPrio=2217 usec=1023
[2022-11-08T13:33:01.028] _slurm_rpc_submit_batch_job: JobId=52303 InitPrio=2217 usec=1148
[2022-11-08T13:56:13.589] error: This association 242(account='free', user='htt_felicia', partition='(null)') does not have access to qos normal
[2022-11-08T13:56:13.589] _slurm_rpc_submit_batch_job: Invalid qos specification
[2022-11-08T13:57:17.004] error: This association 242(account='free', user='htt_felicia', partition='(null)') does not have access to qos normal
[2022-11-08T13:57:17.005] _slurm_rpc_submit_batch_job: Invalid qos specification
[2022-11-08T13:58:20.218] _slurm_rpc_submit_batch_job: JobId=52304 InitPrio=7056 usec=537
[2022-11-08T13:58:20.632] sched: Allocate JobId=52304 NodeList=cpu05 #CPUs=16 Partition=cpu-opteron
[2022-11-08T13:59:19.281] error: This association 242(account='free', user='htt_felicia', partition='(null)') does not have access to qos normal
[2022-11-08T13:59:19.281] _slurm_rpc_submit_batch_job: Invalid qos specification
[2022-11-08T14:19:36.031] sched: _slurm_rpc_allocate_resources JobId=52305 NodeList=(null) usec=968
[2022-11-08T14:19:36.911] sched: Allocate JobId=52305 NodeList=cpu05 #CPUs=1 Partition=cpu-opteron
[2022-11-08T14:21:34.501] _slurm_rpc_kill_job: REQUEST_KILL_JOB JobId=52300 uid 548200029
[2022-11-08T14:21:39.137] _slurm_rpc_kill_job: REQUEST_KILL_JOB JobId=52303 uid 548200029
[2022-11-08T14:21:44.294] _slurm_rpc_kill_job: REQUEST_KILL_JOB JobId=52299 uid 548200029
[2022-11-08T14:21:49.351] _slurm_rpc_kill_job: REQUEST_KILL_JOB JobId=52298 uid 548200029
[2022-11-08T14:21:53.970] _slurm_rpc_kill_job: REQUEST_KILL_JOB JobId=52301 uid 548200029
[2022-11-08T14:22:01.011] _slurm_rpc_kill_job: REQUEST_KILL_JOB JobId=52302 uid 548200029
[2022-11-08T14:22:50.522] _slurm_rpc_submit_batch_job: JobId=52306 InitPrio=2217 usec=1058
[2022-11-08T14:22:51.272] sched: Allocate JobId=52306 NodeList=gpu01 #CPUs=16 Partition=gpu-k10
[2022-11-08T14:23:22.143] _slurm_rpc_submit_batch_job: JobId=52307 InitPrio=2217 usec=1030
[2022-11-08T14:23:22.307] sched: Allocate JobId=52307 NodeList=gpu03 #CPUs=16 Partition=gpu-k10
[2022-11-08T14:24:10.031] _slurm_rpc_submit_batch_job: JobId=52308 InitPrio=2217 usec=1087
[2022-11-08T14:24:57.273] _slurm_rpc_submit_batch_job: JobId=52309 InitPrio=2217 usec=1193
[2022-11-08T14:25:29.274] _slurm_rpc_submit_batch_job: JobId=52310 InitPrio=2217 usec=1061
[2022-11-08T14:27:34.416] _slurm_rpc_submit_batch_job: JobId=52311 InitPrio=2217 usec=986
[2022-11-08T15:24:17.126] _slurm_rpc_submit_batch_job: JobId=52312 InitPrio=1411 usec=714
[2022-11-08T15:24:20.698] _job_complete: JobId=52296 WEXITSTATUS 0
[2022-11-08T15:24:20.704] _job_complete: JobId=52296 done
[2022-11-08T15:31:10.105] _slurm_rpc_kill_job: REQUEST_KILL_JOB JobId=52312 uid 548300593
[2022-11-08T15:35:48.848] _slurm_rpc_submit_batch_job: JobId=52313 InitPrio=1411 usec=753
[2022-11-08T15:35:49.083] sched: Allocate JobId=52313 NodeList=cpu05 #CPUs=16 Partition=cpu-opteron
[2022-11-08T15:41:31.769] sched: _slurm_rpc_allocate_resources JobId=52314 NodeList=cpu05 usec=15778
[2022-11-08T15:45:42.167] sched: _slurm_rpc_allocate_resources JobId=52315 NodeList=(null) usec=766
[2022-11-08T15:45:43.148] sched: Allocate JobId=52315 NodeList=cpu10 #CPUs=4 Partition=cpu-opteron
[2022-11-08T15:48:40.666] _job_complete: JobId=52314 WEXITSTATUS 0
[2022-11-08T15:48:40.666] _job_complete: JobId=52314 done
[2022-11-08T15:48:59.423] _slurm_rpc_submit_batch_job: JobId=52316 InitPrio=8870 usec=511
[2022-11-08T15:50:49.637] _slurm_rpc_kill_job: REQUEST_KILL_JOB JobId=52316 uid 548300539
[2022-11-08T15:50:55.290] _slurm_rpc_submit_batch_job: JobId=52317 InitPrio=8870 usec=541
[2022-11-08T15:52:16.494] _slurm_rpc_kill_job: REQUEST_KILL_JOB JobId=52317 uid 548300539
[2022-11-08T15:52:23.516] _slurm_rpc_submit_batch_job: JobId=52318 InitPrio=18870 usec=494
[2022-11-08T15:52:31.716] error: This association 242(account='free', user='htt_felicia', partition='(null)') does not have access to qos normal
[2022-11-08T15:52:31.716] _slurm_rpc_submit_batch_job: Invalid qos specification
[2022-11-08T15:52:39.356] _slurm_rpc_submit_batch_job: JobId=52319 InitPrio=2620 usec=515
[2022-11-08T15:53:36.472] _slurm_rpc_kill_job: REQUEST_KILL_JOB JobId=52318 uid 548300539
[2022-11-08T15:59:25.598] error: This association 242(account='free', user='htt_felicia', partition='(null)') does not have access to qos normal
[2022-11-08T15:59:25.598] _slurm_rpc_submit_batch_job: Invalid qos specification
[2022-11-08T16:07:31.905] _slurm_rpc_submit_batch_job: JobId=52320 InitPrio=18870 usec=547
[2022-11-08T16:11:55.759] _job_complete: JobId=52315 WEXITSTATUS 2
[2022-11-08T16:11:55.760] _job_complete: JobId=52315 done
[2022-11-08T16:18:21.876] error: This association 242(account='free', user='htt_felicia', partition='(null)') does not have access to qos normal
[2022-11-08T16:18:21.876] _slurm_rpc_submit_batch_job: Invalid qos specification
[2022-11-08T16:19:02.623] sched: _slurm_rpc_allocate_resources JobId=52321 NodeList=cpu05 usec=13171
[2022-11-08T16:25:06.293] _job_complete: JobId=52321 WEXITSTATUS 0
[2022-11-08T16:25:06.294] _job_complete: JobId=52321 done
[2022-11-08T16:25:49.384] error: This association 242(account='free', user='htt_felicia', partition='(null)') does not have access to qos normal
[2022-11-08T16:25:49.384] _slurm_rpc_submit_batch_job: Invalid qos specification
[2022-11-08T16:26:50.920] _slurm_rpc_submit_batch_job: JobId=52322 InitPrio=2217 usec=430
[2022-11-08T16:32:54.137] _job_complete: JobId=52304 WEXITSTATUS 0
[2022-11-08T16:32:54.142] _job_complete: JobId=52304 done
[2022-11-08T16:57:30.939] _slurm_rpc_submit_batch_job: JobId=52323 InitPrio=1411 usec=759
[2022-11-08T16:57:34.979] _job_complete: JobId=52313 WEXITSTATUS 0
[2022-11-08T16:57:34.984] _job_complete: JobId=52313 done
[2022-11-08T16:58:02.902] sched/backfill: _start_job: Started JobId=52322 in cpu-opteron on cpu05
[2022-11-08T16:58:29.585] _job_complete: JobId=52322 WEXITSTATUS 0
[2022-11-08T16:58:29.585] _job_complete: JobId=52322 done
[2022-11-08T16:59:02.906] sched/backfill: _start_job: Started JobId=52323 in cpu-opteron on cpu05
[2022-11-08T17:22:47.699] sched: _slurm_rpc_allocate_resources JobId=52324 NodeList=cpu12 usec=21252
[2022-11-08T17:28:32.183] _slurm_rpc_kill_job: REQUEST_KILL_JOB JobId=52324 uid 548300543
[2022-11-08T17:31:01.832] _slurm_rpc_submit_batch_job: JobId=52325 InitPrio=6451 usec=467
[2022-11-08T18:01:04.062] _job_create: exceeded association/QOS limit for user 548200121: QOSMaxWallDurationPerJobLimit
[2022-11-08T18:01:04.062] _slurm_rpc_allocate_resources: Job violates accounting/QOS policy (job submit limit, user's size and/or time limits) 
[2022-11-08T18:08:53.438] _slurm_rpc_submit_batch_job: JobId=52326 InitPrio=18467 usec=623
[2022-11-08T18:09:03.033] sched/backfill: _start_job: Started JobId=52326 in cpu-opteron on cpu05
[2022-11-08T18:09:05.800] _job_complete: JobId=52326 WEXITSTATUS 1
[2022-11-08T18:09:05.800] _job_complete: JobId=52326 done
[2022-11-08T18:12:44.359] _slurm_rpc_submit_batch_job: JobId=52327 InitPrio=18467 usec=525
[2022-11-08T18:13:03.040] sched/backfill: _start_job: Started JobId=52327 in cpu-opteron on cpu05
[2022-11-08T18:13:03.668] _job_complete: JobId=52327 WEXITSTATUS 1
[2022-11-08T18:13:03.668] _job_complete: JobId=52327 done
[2022-11-08T18:25:03.551] _slurm_rpc_submit_batch_job: JobId=52328 InitPrio=18467 usec=568
[2022-11-08T18:26:03.065] sched/backfill: _start_job: Started JobId=52328 in cpu-opteron on cpu05
[2022-11-08T19:26:10.111] Time limit exhausted for JobId=52328
[2022-11-08T19:37:49.235] _slurm_rpc_submit_batch_job: JobId=52329 InitPrio=17862 usec=594
[2022-11-08T19:38:03.192] sched/backfill: _start_job: Started JobId=52329 in cpu-opteron on cpu05
[2022-11-08T19:38:18.605] _job_complete: JobId=52329 WEXITSTATUS 1
[2022-11-08T19:38:18.605] _job_complete: JobId=52329 done
[2022-11-08T19:48:20.479] _slurm_rpc_submit_batch_job: JobId=52330 InitPrio=17862 usec=953
[2022-11-08T19:49:03.212] sched/backfill: _start_job: Started JobId=52330 in cpu-opteron on cpu05
[2022-11-08T20:20:15.817] sched: _slurm_rpc_allocate_resources JobId=52331 NodeList=(null) usec=1299
[2022-11-08T20:21:03.279] sched/backfill: _start_job: Started JobId=52331 in cpu-opteron on cpu05
[2022-11-08T20:22:36.245] _slurm_rpc_kill_job: REQUEST_KILL_JOB JobId=52320 uid 548300539
[2022-11-08T20:22:47.632] _slurm_rpc_submit_batch_job: JobId=52332 InitPrio=18870 usec=592
[2022-11-08T20:37:14.417] _job_complete: JobId=52305 WEXITSTATUS 0
[2022-11-08T20:37:14.418] _job_complete: JobId=52305 done
[2022-11-08T20:42:15.099] cleanup_completing: JobId=52305 completion process took 301 seconds
[2022-11-08T20:49:10.075] Time limit exhausted for JobId=52330
[2022-11-08T20:55:20.936] error: This association 242(account='free', user='htt_felicia', partition='(null)') does not have access to qos normal
[2022-11-08T20:55:20.936] _slurm_rpc_submit_batch_job: Invalid qos specification
[2022-11-08T21:03:15.823] _slurm_rpc_submit_batch_job: JobId=52333 InitPrio=17661 usec=619
[2022-11-08T21:04:03.352] sched/backfill: _start_job: Started JobId=52333 in cpu-opteron on cpu05
[2022-11-08T21:17:39.666] _slurm_rpc_submit_batch_job: JobId=52334 InitPrio=17661 usec=561
[2022-11-08T21:19:06.734] _slurm_rpc_kill_job: REQUEST_KILL_JOB JobId=52334 uid 548300630
[2022-11-08T21:19:57.405] _slurm_rpc_kill_job: REQUEST_KILL_JOB JobId=52333 uid 548300630
[2022-11-08T21:20:07.417] _slurm_rpc_submit_batch_job: JobId=52335 InitPrio=17661 usec=512
[2022-11-08T21:21:03.382] sched/backfill: _start_job: Started JobId=52335 in cpu-opteron on cpu05
[2022-11-08T21:34:58.590] _job_complete: JobId=52331 WEXITSTATUS 0
[2022-11-08T21:34:58.590] _job_complete: JobId=52331 done
[2022-11-08T21:36:47.487] _slurm_rpc_submit_batch_job: JobId=52336 InitPrio=806 usec=591
[2022-11-08T22:21:10.934] Time limit exhausted for JobId=52335
[2022-11-08T22:21:45.136] _slurm_rpc_kill_job: REQUEST_KILL_JOB JobId=52323 uid 548300593
[2022-11-08T22:21:47.525] sched: Allocate JobId=52332 NodeList=cpu05 #CPUs=16 Partition=cpu-opteron
[2022-11-08T22:21:47.540] sched: Allocate JobId=52325 NodeList=cpu05 #CPUs=16 Partition=cpu-opteron
[2022-11-08T22:21:56.082] _job_complete: JobId=52332 WEXITSTATUS 1
[2022-11-08T22:21:56.082] _job_complete: JobId=52332 done
[2022-11-08T22:24:59.809] _get_job_parts: invalid partition specified: cpu-epypc
[2022-11-08T22:24:59.809] _slurm_rpc_allocate_resources: Invalid partition name specified 
[2022-11-08T22:25:06.839] sched: _slurm_rpc_allocate_resources JobId=52337 NodeList=cpu12 usec=20439
[2022-11-08T22:30:46.576] _slurm_rpc_submit_batch_job: JobId=52338 InitPrio=1411 usec=607
[2022-11-08T22:31:32.686] _slurm_rpc_kill_job: REQUEST_KILL_JOB JobId=52337 uid 548300543
[2022-11-08T22:32:17.682] sched: _slurm_rpc_allocate_resources JobId=52339 NodeList=(null) usec=1122
[2022-11-08T22:32:37.871] _job_complete: JobId=52339 WTERMSIG 126
[2022-11-08T22:32:37.871] _job_complete: JobId=52339 cancelled by interactive user
[2022-11-08T22:32:37.871] _job_complete: JobId=52339 done
[2022-11-08T22:32:43.646] _slurm_rpc_kill_job: REQUEST_KILL_JOB JobId=52339 uid 548300543
[2022-11-08T22:32:57.925] sched: _slurm_rpc_allocate_resources JobId=52340 NodeList=cpu12 usec=1326
[2022-11-08T22:41:30.096] _job_complete: JobId=52180 WEXITSTATUS 0
[2022-11-08T22:41:30.096] _job_complete: JobId=52180 done
[2022-11-08T22:41:31.519] sched: Allocate JobId=52308 NodeList=gpu02 #CPUs=8 Partition=gpu-titan
[2022-11-08T23:16:50.848] _slurm_rpc_kill_job: REQUEST_KILL_JOB JobId=52340 uid 548300543
[2022-11-08T23:17:32.454] sched: _slurm_rpc_allocate_resources JobId=52341 NodeList=cpu12 usec=2561
[2022-11-08T23:20:50.830] _slurm_rpc_kill_job: REQUEST_KILL_JOB JobId=52341 uid 548300543
[2022-11-08T23:33:51.245] _job_complete: JobId=52295 WEXITSTATUS 1
[2022-11-08T23:33:51.246] _job_complete: JobId=52295 done
[2022-11-08T23:34:12.534] sched: Allocate JobId=52338 NodeList=cpu05 #CPUs=32 Partition=cpu-opteron
[2022-11-08T23:55:51.690] _job_create: exceeded association/QOS limit for user 548200121: QOSMaxWallDurationPerJobLimit
[2022-11-08T23:55:51.690] _slurm_rpc_allocate_resources: Job violates accounting/QOS policy (job submit limit, user's size and/or time limits) 
[2022-11-09T04:58:27.593] _job_complete: JobId=52307 WEXITSTATUS 1
[2022-11-09T04:58:27.598] _job_complete: JobId=52307 done
[2022-11-09T04:58:28.279] sched: Allocate JobId=52310 NodeList=gpu03 #CPUs=16 Partition=gpu-k10
[2022-11-09T06:18:55.336] _job_complete: JobId=51868 WEXITSTATUS 0
[2022-11-09T06:18:55.336] _job_complete: JobId=51868 done
[2022-11-09T07:39:05.687] _slurm_rpc_submit_batch_job: JobId=52342 InitPrio=17459 usec=667
[2022-11-09T07:39:06.072] sched: Allocate JobId=52342 NodeList=cpu05 #CPUs=4 Partition=cpu-opteron
[2022-11-09T08:24:30.555] _job_complete: JobId=52142 WEXITSTATUS 0
[2022-11-09T08:24:30.555] _job_complete: JobId=52142 done
[2022-11-09T08:39:13.894] Time limit exhausted for JobId=52342
[2022-11-09T08:57:32.160] _slurm_rpc_submit_batch_job: JobId=52343 InitPrio=17459 usec=582
[2022-11-09T08:57:32.984] sched: Allocate JobId=52343 NodeList=cpu10 #CPUs=4 Partition=cpu-opteron
[2022-11-09T09:04:07.343] sched: _slurm_rpc_allocate_resources JobId=52344 NodeList=cpu12 usec=20261
[2022-11-09T09:16:44.000] _slurm_rpc_kill_job: REQUEST_KILL_JOB JobId=52344 uid 548300543
[2022-11-09T09:17:33.596] sched: _slurm_rpc_allocate_resources JobId=52345 NodeList=cpu12 usec=2235
[2022-11-09T09:22:06.538] _slurm_rpc_submit_batch_job: JobId=52346 InitPrio=806 usec=461
[2022-11-09T09:22:39.531] _slurm_rpc_submit_batch_job: JobId=52347 InitPrio=806 usec=500
[2022-11-09T09:33:29.708] _slurm_rpc_kill_job: REQUEST_KILL_JOB JobId=52345 uid 548300543
[2022-11-09T09:57:43.343] Time limit exhausted for JobId=52343
[2022-11-09T10:15:03.933] sched: _slurm_rpc_allocate_resources JobId=52348 NodeList=cpu12 usec=2937
[2022-11-09T10:29:32.941] _slurm_rpc_kill_job: REQUEST_KILL_JOB JobId=52348 uid 548300543
[2022-11-09T10:51:52.473] _job_complete: JobId=52169 WEXITSTATUS 0
[2022-11-09T10:51:52.479] _job_complete: JobId=52169 done
[2022-11-09T10:51:53.300] sched: Allocate JobId=52177 NodeList=cpu15 #CPUs=24 Partition=cpu-epyc
[2022-11-09T10:52:06.364] _job_complete: JobId=52177 WEXITSTATUS 0
[2022-11-09T10:52:06.364] _job_complete: JobId=52177 done
[2022-11-09T10:52:07.075] sched: Allocate JobId=52248 NodeList=cpu15 #CPUs=8 Partition=cpu-epyc
[2022-11-09T10:52:07.075] sched: Allocate JobId=52319 NodeList=cpu15 #CPUs=8 Partition=cpu-epyc
[2022-11-09T10:52:07.086] sched: Allocate JobId=52215 NodeList=cpu15 #CPUs=8 Partition=cpu-epyc
[2022-11-09T10:52:10.692] _job_complete: JobId=52319 WEXITSTATUS 1
[2022-11-09T10:52:10.693] _job_complete: JobId=52319 done
[2022-11-09T10:52:11.197] _job_complete: JobId=52248 WEXITSTATUS 1
[2022-11-09T10:52:11.197] _job_complete: JobId=52248 done
[2022-11-09T10:52:11.939] sched: Allocate JobId=52216 NodeList=cpu15 #CPUs=8 Partition=cpu-epyc
[2022-11-09T10:52:11.940] sched: Allocate JobId=52217 NodeList=cpu15 #CPUs=8 Partition=cpu-epyc
[2022-11-09T11:13:51.244] _job_create: exceeded association/QOS limit for user 548200121: QOSMaxWallDurationPerJobLimit
[2022-11-09T11:13:51.244] _slurm_rpc_allocate_resources: Job violates accounting/QOS policy (job submit limit, user's size and/or time limits) 
[2022-11-09T11:13:58.795] sched: _slurm_rpc_allocate_resources JobId=52349 NodeList=cpu12 usec=2063
[2022-11-09T11:15:37.933] _slurm_rpc_kill_job: REQUEST_KILL_JOB JobId=52349 uid 548300543
[2022-11-09T11:15:40.044] error: This association 113(account='free', user='hongvin', partition='(null)') does not have access to qos normal
[2022-11-09T11:15:40.044] _slurm_rpc_submit_batch_job: Invalid qos specification
[2022-11-09T11:15:58.341] _job_complete: JobId=52205 WEXITSTATUS 1
[2022-11-09T11:15:58.346] _job_complete: JobId=52205 done
[2022-11-09T11:15:59.798] sched: Allocate JobId=52309 NodeList=gpu02 #CPUs=8 Partition=gpu-titan
[2022-11-09T11:16:22.589] sched: _slurm_rpc_allocate_resources JobId=52350 NodeList=cpu12 usec=1183
[2022-11-09T11:17:42.275] _slurm_rpc_kill_job: REQUEST_KILL_JOB JobId=52350 uid 548300543
[2022-11-09T11:18:34.749] sched: _slurm_rpc_allocate_resources JobId=52351 NodeList=cpu12 usec=1440
[2022-11-09T11:46:25.520] _slurm_rpc_submit_batch_job: JobId=52352 InitPrio=604 usec=673
[2022-11-09T11:47:04.686] sched/backfill: _start_job: Started JobId=52352 in gpu-v100s on gpu05
[2022-11-09T11:51:10.239] _job_complete: JobId=52352 WEXITSTATUS 0
[2022-11-09T11:51:10.239] _job_complete: JobId=52352 done
[2022-11-09T11:54:26.850] _job_complete: JobId=52351 WEXITSTATUS 0
[2022-11-09T11:54:26.850] _job_complete: JobId=52351 done
[2022-11-09T11:55:03.613] _slurm_rpc_submit_batch_job: JobId=52353 InitPrio=604 usec=578
[2022-11-09T11:55:22.572] _slurm_rpc_kill_job: REQUEST_KILL_JOB JobId=52353 uid 548200023
[2022-11-09T11:55:42.758] sched: _slurm_rpc_allocate_resources JobId=52354 NodeList=cpu12 usec=20729
[2022-11-09T11:55:48.131] _slurm_rpc_submit_batch_job: JobId=52355 InitPrio=604 usec=430
[2022-11-09T11:57:17.434] _slurm_rpc_kill_job: REQUEST_KILL_JOB JobId=52355 uid 548200023
[2022-11-09T11:57:29.115] _slurm_rpc_submit_batch_job: JobId=52356 InitPrio=604 usec=526
[2022-11-09T11:58:04.706] sched/backfill: _start_job: Started JobId=52356 in gpu-v100s on gpu05
[2022-11-09T11:59:50.559] _slurm_rpc_submit_batch_job: JobId=52357 InitPrio=2620 usec=547
[2022-11-09T11:59:59.939] _slurm_rpc_submit_batch_job: JobId=52358 InitPrio=2620 usec=482
[2022-11-09T12:01:21.415] _job_complete: JobId=52356 WEXITSTATUS 0
[2022-11-09T12:01:21.416] _job_complete: JobId=52356 done
[2022-11-09T12:03:55.416] _slurm_rpc_submit_batch_job: JobId=52359 InitPrio=604 usec=456
[2022-11-09T12:04:04.717] sched/backfill: _start_job: Started JobId=52359 in gpu-v100s on gpu05
[2022-11-09T12:04:06.104] _job_complete: JobId=52359 WEXITSTATUS 0
[2022-11-09T12:04:06.104] _job_complete: JobId=52359 done
[2022-11-09T12:05:17.050] _slurm_rpc_submit_batch_job: JobId=52360 InitPrio=604 usec=455
[2022-11-09T12:28:29.968] _slurm_rpc_submit_batch_job: JobId=52361 InitPrio=1411 usec=609
[2022-11-09T12:28:58.035] _slurm_rpc_kill_job: REQUEST_KILL_JOB JobId=52338 uid 548300593
[2022-11-09T12:29:00.402] sched: Allocate JobId=52290 NodeList=cpu[04-05] #CPUs=32 Partition=cpu-opteron
[2022-11-09T12:29:04.778] sched/backfill: _start_job: Started JobId=52361 in cpu-opteron on cpu04
[2022-11-09T12:47:41.224] Requeuing JobId=52290
[2022-11-09T12:48:04.813] sched/backfill: _start_job: Started JobId=52360 in cpu-opteron on cpu04
[2022-11-09T12:48:11.263] _job_complete: JobId=52360 WEXITSTATUS 1
[2022-11-09T12:48:11.263] _job_complete: JobId=52360 done
[2022-11-09T13:11:22.664] _job_create: exceeded association/QOS limit for user 548200121: QOSMaxWallDurationPerJobLimit
[2022-11-09T13:11:22.664] _slurm_rpc_allocate_resources: Job violates accounting/QOS policy (job submit limit, user's size and/or time limits) 
[2022-11-09T13:14:52.985] _slurm_rpc_submit_batch_job: JobId=52362 InitPrio=806 usec=490
[2022-11-09T13:32:15.523] _job_complete: JobId=52354 WEXITSTATUS 2
[2022-11-09T13:32:15.524] _job_complete: JobId=52354 done
[2022-11-09T14:01:05.126] sched: _slurm_rpc_allocate_resources JobId=52363 NodeList=cpu10 usec=17000
[2022-11-09T14:07:39.299] _job_complete: JobId=52363 WEXITSTATUS 1
[2022-11-09T14:07:39.299] _job_complete: JobId=52363 done
[2022-11-09T14:21:22.141] _slurm_rpc_submit_batch_job: JobId=52364 InitPrio=8064 usec=600
[2022-11-09T14:21:22.553] sched: Allocate JobId=52364 NodeList=cpu10 #CPUs=1 Partition=cpu-opteron
[2022-11-09T14:24:41.460] _job_complete: JobId=52364 WEXITSTATUS 0
[2022-11-09T14:24:41.460] _job_complete: JobId=52364 done
[2022-11-09T14:30:30.422] sched: _slurm_rpc_allocate_resources JobId=52365 NodeList=cpu10 usec=2171
[2022-11-09T14:32:09.608] _slurm_rpc_submit_batch_job: JobId=52366 InitPrio=8064 usec=546
[2022-11-09T14:32:09.883] sched: Allocate JobId=52366 NodeList=cpu10 #CPUs=1 Partition=cpu-opteron
[2022-11-09T14:43:52.403] _job_complete: JobId=52365 WEXITSTATUS 0
[2022-11-09T14:43:52.403] _job_complete: JobId=52365 done
[2022-11-09T14:44:02.256] _slurm_rpc_kill_job: REQUEST_KILL_JOB JobId=52361 uid 548300593
[2022-11-09T14:44:07.103] sched: Allocate JobId=52336 NodeList=cpu04 #CPUs=64 Partition=cpu-opteron
[2022-11-09T14:45:09.727] _slurm_rpc_submit_batch_job: JobId=52367 InitPrio=806 usec=519
[2022-11-09T14:45:35.952] _slurm_rpc_kill_job: REQUEST_KILL_JOB JobId=52346 uid 548200017
[2022-11-09T14:45:52.639] _slurm_rpc_kill_job: REQUEST_KILL_JOB JobId=52347 uid 548200017
[2022-11-09T14:46:23.280] _slurm_rpc_submit_batch_job: JobId=52368 InitPrio=1411 usec=549
[2022-11-09T14:46:23.824] sched: Allocate JobId=52368 NodeList=cpu05 #CPUs=32 Partition=cpu-opteron
[2022-11-09T14:46:38.889] _job_complete: JobId=52366 WEXITSTATUS 0
[2022-11-09T14:46:38.890] _job_complete: JobId=52366 done
[2022-11-09T14:49:48.255] _slurm_rpc_submit_batch_job: JobId=52369 InitPrio=17258 usec=595
[2022-11-09T14:49:49.074] sched: Allocate JobId=52369 NodeList=cpu05 #CPUs=4 Partition=cpu-opteron
[2022-11-09T14:52:49.596] _slurm_rpc_kill_job: REQUEST_KILL_JOB JobId=52367 uid 548200017
[2022-11-09T14:53:20.693] sched: _slurm_rpc_allocate_resources JobId=52370 NodeList=(null) usec=966
[2022-11-09T14:53:21.499] sched: Allocate JobId=52370 NodeList=cpu05 #CPUs=4 Partition=cpu-opteron
[2022-11-09T14:56:48.230] _slurm_rpc_submit_batch_job: JobId=52371 InitPrio=806 usec=564
[2022-11-09T14:59:30.263] _slurm_rpc_submit_batch_job: JobId=52372 InitPrio=806 usec=459
[2022-11-09T15:12:29.889] _slurm_rpc_submit_batch_job: JobId=52373 InitPrio=8064 usec=597
[2022-11-09T15:12:30.678] sched: Allocate JobId=52373 NodeList=cpu05 #CPUs=1 Partition=cpu-opteron
[2022-11-09T15:13:06.535] _slurm_rpc_submit_batch_job: JobId=52374 InitPrio=1209 usec=554
[2022-11-09T15:13:09.879] _slurm_rpc_submit_batch_job: JobId=52375 InitPrio=1209 usec=624
[2022-11-09T15:13:12.815] _slurm_rpc_submit_batch_job: JobId=52376 InitPrio=1209 usec=501
[2022-11-09T15:13:15.848] _slurm_rpc_submit_batch_job: JobId=52377 InitPrio=1209 usec=503
[2022-11-09T15:13:18.872] _slurm_rpc_submit_batch_job: JobId=52378 InitPrio=1209 usec=467
[2022-11-09T15:13:21.863] _slurm_rpc_submit_batch_job: JobId=52379 InitPrio=1209 usec=528
[2022-11-09T15:13:27.247] _slurm_rpc_submit_batch_job: JobId=52380 InitPrio=1209 usec=588
[2022-11-09T15:13:32.119] _slurm_rpc_submit_batch_job: JobId=52381 InitPrio=1209 usec=438
[2022-11-09T15:13:38.227] _job_complete: JobId=52373 WEXITSTATUS 127
[2022-11-09T15:13:38.227] _job_complete: JobId=52373 done
[2022-11-09T15:17:07.493] _slurm_rpc_submit_batch_job: JobId=52382 InitPrio=8064 usec=572
[2022-11-09T15:17:08.391] sched: Allocate JobId=52382 NodeList=cpu05 #CPUs=1 Partition=cpu-opteron
[2022-11-09T15:18:53.740] _job_complete: JobId=52382 WEXITSTATUS 0
[2022-11-09T15:18:53.740] _job_complete: JobId=52382 done
[2022-11-09T15:36:52.181] _slurm_rpc_submit_batch_job: JobId=52383 InitPrio=8064 usec=619
[2022-11-09T15:36:52.496] sched: Allocate JobId=52383 NodeList=cpu05 #CPUs=1 Partition=cpu-opteron
[2022-11-09T15:37:42.944] _job_complete: JobId=52383 WEXITSTATUS 0
[2022-11-09T15:37:42.944] _job_complete: JobId=52383 done
[2022-11-09T15:45:22.650] _job_complete: JobId=52370 WEXITSTATUS 0
[2022-11-09T15:45:22.650] _job_complete: JobId=52370 done
[2022-11-09T15:45:23.428] sched: Allocate JobId=52374 NodeList=cpu05 #CPUs=8 Partition=cpu-opteron
[2022-11-09T15:50:16.682] Time limit exhausted for JobId=52369
[2022-11-09T15:50:54.812] error: This association 246(account='free', user='chiuling', partition='(null)') does not have access to qos long
[2022-11-09T15:50:54.812] _slurm_rpc_submit_batch_job: Invalid qos specification
[2022-11-09T15:52:27.274] error: Invalid qos (normal*)
[2022-11-09T15:52:27.274] _slurm_rpc_submit_batch_job: Invalid qos specification
[2022-11-09T15:54:45.730] _slurm_rpc_submit_batch_job: JobId=52384 InitPrio=18064 usec=651
[2022-11-09T15:54:46.157] sched: Allocate JobId=52384 NodeList=cpu10 #CPUs=1 Partition=cpu-opteron
[2022-11-09T15:55:15.017] _job_complete: JobId=52384 WEXITSTATUS 1
[2022-11-09T15:55:15.017] _job_complete: JobId=52384 done
[2022-11-09T15:58:11.078] _slurm_rpc_submit_batch_job: JobId=52385 InitPrio=18064 usec=608
[2022-11-09T15:58:11.545] sched: Allocate JobId=52385 NodeList=cpu10 #CPUs=1 Partition=cpu-opteron
[2022-11-09T15:58:56.011] _job_complete: JobId=52385 WEXITSTATUS 1
[2022-11-09T15:58:56.012] _job_complete: JobId=52385 done
[2022-11-09T16:03:11.883] _slurm_rpc_submit_batch_job: JobId=52386 InitPrio=18064 usec=575
[2022-11-09T16:03:12.170] sched: Allocate JobId=52386 NodeList=cpu10 #CPUs=1 Partition=cpu-opteron
[2022-11-09T16:03:48.342] _job_complete: JobId=52386 WEXITSTATUS 0
[2022-11-09T16:03:48.342] _job_complete: JobId=52386 done
[2022-11-09T16:07:40.343] sched: _slurm_rpc_allocate_resources JobId=52387 NodeList=(null) usec=863
[2022-11-09T16:07:40.626] sched: Allocate JobId=52387 NodeList=cpu10 #CPUs=4 Partition=cpu-opteron
[2022-11-09T16:10:22.040] _slurm_rpc_submit_batch_job: JobId=52388 InitPrio=18064 usec=581
[2022-11-09T16:10:22.836] sched: Allocate JobId=52388 NodeList=cpu10 #CPUs=1 Partition=cpu-opteron
[2022-11-09T16:10:50.830] _job_complete: JobId=52388 WEXITSTATUS 0
[2022-11-09T16:10:50.830] _job_complete: JobId=52388 done
[2022-11-09T16:14:00.884] _slurm_rpc_submit_batch_job: JobId=52389 InitPrio=18064 usec=644
[2022-11-09T16:14:01.208] sched: Allocate JobId=52389 NodeList=cpu10 #CPUs=1 Partition=cpu-opteron
[2022-11-09T16:14:26.459] _job_complete: JobId=52389 WEXITSTATUS 0
[2022-11-09T16:14:26.459] _job_complete: JobId=52389 done
[2022-11-09T16:17:06.228] _slurm_rpc_submit_batch_job: JobId=52390 InitPrio=18064 usec=525
[2022-11-09T16:17:06.545] sched: Allocate JobId=52390 NodeList=cpu10 #CPUs=1 Partition=cpu-opteron
[2022-11-09T16:17:32.023] _job_complete: JobId=52390 WEXITSTATUS 1
[2022-11-09T16:17:32.023] _job_complete: JobId=52390 done
[2022-11-09T16:20:35.522] _slurm_rpc_submit_batch_job: JobId=52391 InitPrio=18064 usec=525
[2022-11-09T16:20:35.816] sched: Allocate JobId=52391 NodeList=cpu10 #CPUs=1 Partition=cpu-opteron
[2022-11-09T16:21:00.538] _job_complete: JobId=52391 WEXITSTATUS 0
[2022-11-09T16:21:00.538] _job_complete: JobId=52391 done
[2022-11-09T16:21:08.543] _slurm_rpc_submit_batch_job: JobId=52392 InitPrio=1411 usec=687
[2022-11-09T16:21:11.929] _slurm_rpc_kill_job: REQUEST_KILL_JOB JobId=52368 uid 548300593
[2022-11-09T16:21:13.430] sched: Allocate JobId=52392 NodeList=cpu05 #CPUs=32 Partition=cpu-opteron
[2022-11-09T16:28:00.433] _job_complete: JobId=52387 WEXITSTATUS 1
[2022-11-09T16:28:00.433] _job_complete: JobId=52387 done
[2022-11-09T16:28:35.883] _slurm_rpc_submit_batch_job: JobId=52393 InitPrio=18064 usec=664
[2022-11-09T16:28:36.658] sched: Allocate JobId=52393 NodeList=cpu10 #CPUs=1 Partition=cpu-opteron
[2022-11-09T16:29:03.567] _job_complete: JobId=52393 WEXITSTATUS 0
[2022-11-09T16:29:03.568] _job_complete: JobId=52393 done
[2022-11-09T16:33:05.663] _slurm_rpc_submit_batch_job: JobId=52394 InitPrio=14919 usec=515
[2022-11-09T16:33:38.827] _slurm_rpc_kill_job: REQUEST_KILL_JOB JobId=52394 uid 548200121
[2022-11-09T16:34:08.934] _slurm_rpc_submit_batch_job: JobId=52395 InitPrio=14919 usec=484
[2022-11-09T16:34:09.170] sched: Allocate JobId=52395 NodeList=gpu05 #CPUs=4 Partition=gpu-v100s
[2022-11-09T16:45:34.016] _slurm_rpc_submit_batch_job: JobId=52396 InitPrio=18266 usec=676
[2022-11-09T16:45:34.297] sched: Allocate JobId=52396 NodeList=cpu10 #CPUs=1 Partition=cpu-opteron
[2022-11-09T16:51:12.198] _slurm_rpc_submit_batch_job: JobId=52397 InitPrio=19072 usec=602
[2022-11-09T17:20:27.878] _job_complete: JobId=52396 WEXITSTATUS 0
[2022-11-09T17:20:27.879] _job_complete: JobId=52396 done
[2022-11-09T17:56:23.822] _slurm_rpc_submit_batch_job: JobId=52398 InitPrio=8266 usec=674
[2022-11-09T17:57:06.344] sched/backfill: _start_job: Started JobId=52398 in cpu-opteron on cpu10
[2022-11-09T17:57:23.802] _slurm_rpc_submit_batch_job: JobId=52399 InitPrio=18266 usec=528
[2022-11-09T17:57:45.939] _job_complete: JobId=52398 WEXITSTATUS 0
[2022-11-09T17:57:45.939] _job_complete: JobId=52398 done
[2022-11-09T17:57:46.464] _slurm_rpc_kill_job: REQUEST_KILL_JOB JobId=52399 uid 548200013
[2022-11-09T17:58:05.349] _slurm_rpc_submit_batch_job: JobId=52400 InitPrio=18266 usec=658
[2022-11-09T17:58:06.347] sched/backfill: _start_job: Started JobId=52400 in cpu-opteron on cpu10
[2022-11-09T17:58:53.788] _job_complete: JobId=52400 WEXITSTATUS 0
[2022-11-09T17:58:53.788] _job_complete: JobId=52400 done
[2022-11-09T18:20:58.831] _job_complete: JobId=52336 WEXITSTATUS 0
[2022-11-09T18:20:58.840] _job_complete: JobId=52336 done
[2022-11-09T18:21:00.160] sched: Allocate JobId=52397 NodeList=cpu04 #CPUs=16 Partition=cpu-opteron
[2022-11-09T18:21:00.186] sched: Allocate JobId=52375 NodeList=cpu04 #CPUs=8 Partition=cpu-opteron
[2022-11-09T18:21:00.187] sched: Allocate JobId=52376 NodeList=cpu04 #CPUs=8 Partition=cpu-opteron
[2022-11-09T18:26:36.023] _job_complete: JobId=52397 WEXITSTATUS 0
[2022-11-09T18:26:36.023] _job_complete: JobId=52397 done
[2022-11-09T18:26:37.304] sched: Allocate JobId=52377 NodeList=cpu04 #CPUs=8 Partition=cpu-opteron
[2022-11-09T18:54:44.428] _slurm_rpc_submit_batch_job: JobId=52401 InitPrio=806 usec=480
[2022-11-09T18:55:19.365] _slurm_rpc_kill_job: REQUEST_KILL_JOB JobId=52362 uid 548200017
[2022-11-09T18:55:55.863] _slurm_rpc_submit_batch_job: JobId=52402 InitPrio=806 usec=511
[2022-11-09T19:05:38.914] _slurm_rpc_submit_batch_job: JobId=52403 InitPrio=806 usec=517
[2022-11-09T19:51:55.413] _slurm_rpc_submit_batch_job: JobId=52404 InitPrio=4838 usec=508
[2022-11-09T19:52:26.090] _slurm_rpc_kill_job: REQUEST_KILL_JOB JobId=52404 uid 548200121
[2022-11-09T19:56:23.664] _slurm_rpc_submit_batch_job: JobId=52405 InitPrio=4637 usec=464
[2022-11-09T19:56:24.397] sched: Allocate JobId=52405 NodeList=cpu10 #CPUs=4 Partition=cpu-opteron
[2022-11-09T19:59:26.847] _slurm_rpc_kill_job: REQUEST_KILL_JOB JobId=52405 uid 548200121
[2022-11-09T20:04:46.132] Time limit exhausted for JobId=51908
[2022-11-09T20:04:53.530] sched: Allocate JobId=52378 NodeList=cpu01 #CPUs=8 Partition=cpu-opteron
[2022-11-09T20:04:53.531] sched: Allocate JobId=52379 NodeList=cpu01 #CPUs=8 Partition=cpu-opteron
[2022-11-09T20:04:53.532] sched: Allocate JobId=52380 NodeList=cpu01 #CPUs=8 Partition=cpu-opteron
[2022-11-09T20:15:43.041] _job_complete: JobId=51918 WEXITSTATUS 0
[2022-11-09T20:15:43.042] _job_complete: JobId=51918 done
[2022-11-09T20:36:03.826] _slurm_rpc_submit_batch_job: JobId=52406 InitPrio=4233 usec=607
[2022-11-09T20:40:10.119] _slurm_rpc_kill_job: REQUEST_KILL_JOB JobId=52406 uid 548200121
[2022-11-09T20:40:23.065] _slurm_rpc_submit_batch_job: JobId=52407 InitPrio=4233 usec=386
[2022-11-09T20:43:13.058] _slurm_rpc_submit_batch_job: JobId=52408 InitPrio=4233 usec=483
[2022-11-09T20:43:25.876] _slurm_rpc_kill_job: REQUEST_KILL_JOB JobId=52408 uid 548200121
[2022-11-09T20:45:16.287] sched: _slurm_rpc_allocate_resources JobId=52409 NodeList=(null) usec=729
[2022-11-09T20:45:18.322] sched: Allocate JobId=52409 NodeList=cpu01 #CPUs=1 Partition=cpu-opteron
[2022-11-09T20:45:19.140] _job_complete: JobId=52409 WEXITSTATUS 2
[2022-11-09T20:45:19.141] _job_complete: JobId=52409 done
[2022-11-09T20:45:44.483] _slurm_rpc_kill_job: REQUEST_KILL_JOB JobId=52409 uid 548200121
[2022-11-09T20:46:40.073] _slurm_rpc_submit_batch_job: JobId=52410 InitPrio=4233 usec=426
[2022-11-09T20:51:33.980] _slurm_rpc_kill_job: REQUEST_KILL_JOB JobId=52410 uid 548200121
[2022-11-09T21:41:15.249] _slurm_rpc_kill_job: REQUEST_KILL_JOB JobId=51771 uid 548300621
[2022-11-09T21:41:16.452] _slurm_rpc_kill_job: REQUEST_KILL_JOB JobId=51771 uid 548300621
[2022-11-09T21:41:20.213] _slurm_rpc_kill_job: REQUEST_KILL_JOB JobId=51770 uid 548300621
[2022-11-09T21:41:21.447] _slurm_rpc_kill_job: REQUEST_KILL_JOB JobId=51770 uid 548300621
[2022-11-09T21:41:24.873] _slurm_rpc_kill_job: REQUEST_KILL_JOB JobId=51772 uid 548300621
[2022-11-09T21:41:25.843] _slurm_rpc_kill_job: REQUEST_KILL_JOB JobId=51772 uid 548300621
[2022-11-09T22:21:47.081] Time limit exhausted for JobId=52325
[2022-11-09T22:21:50.912] sched: Allocate JobId=52381 NodeList=cpu05 #CPUs=8 Partition=cpu-opteron
[2022-11-10T00:02:13.651] _slurm_rpc_submit_batch_job: JobId=52411 InitPrio=3830 usec=538
[2022-11-10T08:45:35.899] _job_complete: JobId=52217 WEXITSTATUS 0
[2022-11-10T08:45:35.899] _job_complete: JobId=52217 done
[2022-11-10T09:17:01.921] _job_complete: JobId=52216 WEXITSTATUS 0
[2022-11-10T09:17:01.921] _job_complete: JobId=52216 done
[2022-11-10T10:32:45.342] _job_complete: JobId=52215 WEXITSTATUS 0
[2022-11-10T10:32:45.342] _job_complete: JobId=52215 done
[2022-11-10T11:10:19.777] _slurm_rpc_submit_batch_job: JobId=52412 InitPrio=13427 usec=620
[2022-11-10T11:10:20.917] sched: Allocate JobId=52412 NodeList=gpu05 #CPUs=4 Partition=gpu-v100s
[2022-11-10T11:14:26.326] sched: _slurm_rpc_allocate_resources JobId=52413 NodeList=(null) usec=937
[2022-11-10T11:15:08.032] sched/backfill: _start_job: Started JobId=52413 in cpu-opteron on cpu10
[2022-11-10T11:27:01.220] _slurm_rpc_submit_batch_job: JobId=52414 InitPrio=1209 usec=505
[2022-11-10T11:27:11.553] _slurm_rpc_submit_batch_job: JobId=52415 InitPrio=1209 usec=486
[2022-11-10T11:37:19.808] _slurm_rpc_kill_job: REQUEST_KILL_JOB JobId=52392 uid 548300593
[2022-11-10T11:47:08.515] _job_complete: JobId=52143 WEXITSTATUS 139
[2022-11-10T11:47:08.521] _job_complete: JobId=52143 done
[2022-11-10T11:47:09.008] sched: Allocate JobId=52189 NodeList=cpu13 #CPUs=48 Partition=cpu-epyc
[2022-11-10T12:10:21.183] Time limit exhausted for JobId=52412
[2022-11-10T12:30:43.356] _job_complete: JobId=52189 WEXITSTATUS 1
[2022-11-10T12:30:43.356] _job_complete: JobId=52189 done
[2022-11-10T12:30:44.531] sched: Allocate JobId=52202 NodeList=cpu13 #CPUs=48 Partition=cpu-epyc
[2022-11-10T12:31:01.420] _slurm_rpc_submit_batch_job: JobId=52416 InitPrio=1411 usec=673
[2022-11-10T12:31:08.194] sched/backfill: _start_job: Started JobId=52218 in cpu-epyc on cpu15
[2022-11-10T12:31:08.195] sched/backfill: _start_job: Started JobId=52219 in cpu-epyc on cpu15
[2022-11-10T12:31:08.196] sched/backfill: _start_job: Started JobId=52220 in cpu-epyc on cpu15
[2022-11-10T12:31:08.214] sched/backfill: _start_job: Started JobId=52416 in cpu-opteron on cpu05
[2022-11-10T12:34:30.768] _slurm_rpc_kill_job: REQUEST_KILL_JOB JobId=52416 uid 548300593
[2022-11-10T12:34:37.120] _slurm_rpc_submit_batch_job: JobId=52417 InitPrio=1411 usec=543
[2022-11-10T12:34:51.235] _slurm_rpc_submit_batch_job: JobId=52418 InitPrio=1411 usec=603
[2022-11-10T12:35:04.712] _slurm_rpc_kill_job: REQUEST_KILL_JOB JobId=52418 uid 548300593
[2022-11-10T12:35:08.223] sched/backfill: _start_job: Started JobId=52417 in cpu-opteron on cpu05
[2022-11-10T12:50:26.278] _slurm_rpc_kill_job: REQUEST_KILL_JOB JobId=52415 uid 548200021
[2022-11-10T12:51:09.826] _pick_best_nodes: JobId=52419 never runnable in partition cpu-epyc
[2022-11-10T12:51:09.826] _slurm_rpc_submit_batch_job: Requested node configuration is not available
[2022-11-10T12:51:23.528] _pick_best_nodes: JobId=52420 never runnable in partition cpu-epyc
[2022-11-10T12:51:23.528] _slurm_rpc_submit_batch_job: Requested node configuration is not available
[2022-11-10T12:51:40.716] _slurm_rpc_submit_batch_job: JobId=52421 InitPrio=1209 usec=429
[2022-11-10T12:54:46.957] _slurm_rpc_submit_batch_job: JobId=52422 InitPrio=7459 usec=462
[2022-11-10T12:57:18.599] _slurm_rpc_submit_batch_job: JobId=52423 InitPrio=7459 usec=529
[2022-11-10T12:59:05.207] _job_complete: JobId=52413 WEXITSTATUS 0
[2022-11-10T12:59:05.207] _job_complete: JobId=52413 done
[2022-11-10T13:03:00.109] _job_complete: JobId=52202 WEXITSTATUS 1
[2022-11-10T13:03:00.109] _job_complete: JobId=52202 done
[2022-11-10T13:03:00.540] sched: Allocate JobId=52203 NodeList=cpu13 #CPUs=48 Partition=cpu-epyc
[2022-11-10T13:05:56.251] _slurm_rpc_kill_job: REQUEST_KILL_JOB JobId=52422 uid 548300630
[2022-11-10T13:06:18.415] _slurm_rpc_submit_batch_job: JobId=52424 InitPrio=17459 usec=554
[2022-11-10T13:19:53.471] _slurm_rpc_submit_batch_job: JobId=52425 InitPrio=7459 usec=555
[2022-11-10T13:20:08.330] sched/backfill: _start_job: Started JobId=52425 in cpu-opteron on cpu10
[2022-11-10T13:21:08.473] _slurm_rpc_kill_job: REQUEST_KILL_JOB JobId=52424 uid 548300630
[2022-11-10T13:25:28.767] _slurm_rpc_kill_job: REQUEST_KILL_JOB JobId=52223 uid 548300621
[2022-11-10T13:25:28.767] error: Security violation, REQUEST_KILL_JOB RPC for JobId=52223 from uid 548300621
[2022-11-10T13:25:28.767] _slurm_rpc_kill_job: job_str_signal() uid=548300621 JobId=52223 sig=9 returned: Access/permission denied
[2022-11-10T13:27:24.153] _slurm_rpc_submit_batch_job: JobId=52426 InitPrio=17459 usec=677
[2022-11-10T13:27:53.719] _slurm_rpc_kill_job: REQUEST_KILL_JOB JobId=52423 uid 548300630
[2022-11-10T13:30:26.564] _slurm_rpc_submit_batch_job: JobId=52427 InitPrio=201 usec=450
[2022-11-10T13:30:29.275] _slurm_rpc_submit_batch_job: JobId=52428 InitPrio=201 usec=382
[2022-11-10T13:30:31.484] _slurm_rpc_submit_batch_job: JobId=52429 InitPrio=201 usec=499
[2022-11-10T13:30:33.994] _slurm_rpc_submit_batch_job: JobId=52430 InitPrio=201 usec=589
[2022-11-10T13:30:36.219] _slurm_rpc_submit_batch_job: JobId=52431 InitPrio=201 usec=534
[2022-11-10T13:34:59.374] _slurm_rpc_submit_batch_job: JobId=52432 InitPrio=1411 usec=662
[2022-11-10T13:35:02.634] _job_complete: JobId=52417 WEXITSTATUS 0
[2022-11-10T13:35:02.635] _job_complete: JobId=52417 done
[2022-11-10T13:35:06.951] sched: Allocate JobId=52426 NodeList=cpu05 #CPUs=16 Partition=cpu-opteron
[2022-11-10T13:35:22.337] _job_complete: JobId=52203 WEXITSTATUS 1
[2022-11-10T13:35:22.337] _job_complete: JobId=52203 done
[2022-11-10T13:35:22.779] sched: Allocate JobId=52221 NodeList=cpu13 #CPUs=8 Partition=cpu-epyc
[2022-11-10T13:35:22.780] sched: Allocate JobId=52222 NodeList=cpu13 #CPUs=8 Partition=cpu-epyc
[2022-11-10T13:35:22.781] sched: Allocate JobId=52223 NodeList=cpu13 #CPUs=8 Partition=cpu-epyc
[2022-11-10T13:35:22.781] sched: Allocate JobId=52224 NodeList=cpu13 #CPUs=8 Partition=cpu-epyc
[2022-11-10T13:35:22.782] sched: Allocate JobId=52225 NodeList=cpu13 #CPUs=8 Partition=cpu-epyc
[2022-11-10T13:35:22.783] sched: Allocate JobId=52226 NodeList=cpu13 #CPUs=8 Partition=cpu-epyc
[2022-11-10T13:35:23.260] _job_complete: JobId=52426 WEXITSTATUS 1
[2022-11-10T13:35:23.260] _job_complete: JobId=52426 done
[2022-11-10T13:36:08.366] sched/backfill: _start_job: Started JobId=52432 in cpu-opteron on cpu05
[2022-11-10T13:36:35.826] _slurm_rpc_submit_batch_job: JobId=52433 InitPrio=1209 usec=527
[2022-11-10T13:37:56.955] _slurm_rpc_submit_batch_job: JobId=52434 InitPrio=3024 usec=378
[2022-11-10T13:40:04.990] _slurm_rpc_submit_batch_job: JobId=52435 InitPrio=3024 usec=497
[2022-11-10T13:40:08.386] sched/backfill: _start_job: Started JobId=52435 in gpu-v100s on gpu05
[2022-11-10T13:40:46.561] _slurm_rpc_kill_job: REQUEST_KILL_JOB JobId=52435 uid 548200121
[2022-11-10T13:41:01.368] _slurm_rpc_submit_batch_job: JobId=52436 InitPrio=3024 usec=401
[2022-11-10T13:41:24.462] _slurm_rpc_kill_job: REQUEST_KILL_JOB JobId=52436 uid 548200121
[2022-11-10T13:41:35.101] _slurm_rpc_submit_batch_job: JobId=52437 InitPrio=3024 usec=436
[2022-11-10T13:41:45.165] _slurm_rpc_kill_job: REQUEST_KILL_JOB JobId=52437 uid 548200121
[2022-11-10T13:41:54.875] _slurm_rpc_submit_batch_job: JobId=52438 InitPrio=3024 usec=467
[2022-11-10T13:42:27.326] _slurm_rpc_kill_job: REQUEST_KILL_JOB JobId=52438 uid 548200121
[2022-11-10T13:42:57.800] _slurm_rpc_submit_batch_job: JobId=52439 InitPrio=3024 usec=489
[2022-11-10T13:43:08.393] sched/backfill: _start_job: Started JobId=52439 in gpu-v100s on gpu05
[2022-11-10T13:49:50.955] _slurm_rpc_submit_batch_job: JobId=52440 InitPrio=1209 usec=577
[2022-11-10T13:56:29.283] _slurm_rpc_submit_batch_job: JobId=52441 InitPrio=17459 usec=571
[2022-11-10T14:06:30.846] _slurm_rpc_kill_job: REQUEST_KILL_JOB JobId=52439 uid 548200121
[2022-11-10T14:14:48.934] sched: _slurm_rpc_allocate_resources JobId=52442 NodeList=(null) usec=1046
[2022-11-10T14:15:08.475] sched/backfill: _start_job: Started JobId=52442 in cpu-opteron on cpu10
[2022-11-10T14:23:29.466] _slurm_rpc_submit_batch_job: JobId=52443 InitPrio=7459 usec=556
[2022-11-10T14:24:18.185] _slurm_rpc_submit_batch_job: JobId=52444 InitPrio=7459 usec=462
[2022-11-10T14:28:24.168] _slurm_rpc_kill_job: REQUEST_KILL_JOB JobId=52443 uid 548300630
[2022-11-10T14:28:34.774] _slurm_rpc_submit_batch_job: JobId=52445 InitPrio=7459 usec=577
[2022-11-10T14:33:32.795] _pick_best_nodes: JobId=52446 never runnable in partition cpu-opteron
[2022-11-10T14:33:32.795] _slurm_rpc_submit_batch_job: Requested node configuration is not available
[2022-11-10T14:33:52.454] _slurm_rpc_submit_batch_job: JobId=52447 InitPrio=13024 usec=524
[2022-11-10T14:34:08.519] sched/backfill: _start_job: Started JobId=52447 in cpu-opteron on cpu01
[2022-11-10T14:45:20.372] _slurm_rpc_kill_job: REQUEST_KILL_JOB JobId=52447 uid 548200121
[2022-11-10T15:01:19.990] _slurm_rpc_submit_batch_job: JobId=52448 InitPrio=7258 usec=532
[2022-11-10T15:01:57.363] _slurm_rpc_submit_batch_job: JobId=52449 InitPrio=7258 usec=627
[2022-11-10T15:02:08.606] sched/backfill: _start_job: Started JobId=52448 in cpu-opteron on cpu10
[2022-11-10T15:02:08.607] sched/backfill: _start_job: Started JobId=52449 in cpu-opteron on cpu10
[2022-11-10T15:02:11.610] _job_complete: JobId=52449 WEXITSTATUS 1
[2022-11-10T15:02:11.610] _job_complete: JobId=52449 done
[2022-11-10T15:02:17.772] _slurm_rpc_submit_batch_job: JobId=52450 InitPrio=7258 usec=544
[2022-11-10T15:02:19.595] _job_complete: JobId=52448 WEXITSTATUS 1
[2022-11-10T15:02:19.595] _job_complete: JobId=52448 done
[2022-11-10T15:03:08.610] sched/backfill: _start_job: Started JobId=52450 in cpu-opteron on cpu10
[2022-11-10T15:03:19.308] _job_complete: JobId=52450 WEXITSTATUS 1
[2022-11-10T15:03:19.308] _job_complete: JobId=52450 done
[2022-11-10T15:06:43.360] _slurm_rpc_submit_batch_job: JobId=52451 InitPrio=7258 usec=529
[2022-11-10T15:07:08.620] sched/backfill: _start_job: Started JobId=52451 in cpu-opteron on cpu10
[2022-11-10T15:07:19.486] _job_complete: JobId=52451 WEXITSTATUS 1
[2022-11-10T15:07:19.486] _job_complete: JobId=52451 done
[2022-11-10T15:13:11.888] _slurm_rpc_submit_batch_job: JobId=52452 InitPrio=13024 usec=445
[2022-11-10T15:14:08.661] sched/backfill: _start_job: Started JobId=52452 in cpu-opteron on cpu01
[2022-11-10T15:14:56.739] _slurm_rpc_kill_job: REQUEST_KILL_JOB JobId=52432 uid 548300593
[2022-11-10T15:15:05.729] sched: Allocate JobId=52441 NodeList=cpu05 #CPUs=16 Partition=cpu-opteron
[2022-11-10T15:15:22.351] _job_complete: JobId=52441 WEXITSTATUS 1
[2022-11-10T15:15:22.351] _job_complete: JobId=52441 done
[2022-11-10T15:15:23.432] sched: Allocate JobId=52444 NodeList=cpu05 #CPUs=8 Partition=cpu-opteron
[2022-11-10T15:15:23.432] sched: Allocate JobId=52445 NodeList=cpu05 #CPUs=8 Partition=cpu-opteron
[2022-11-10T15:16:16.705] _slurm_rpc_submit_batch_job: JobId=52453 InitPrio=7056 usec=544
[2022-11-10T15:16:17.668] sched: Allocate JobId=52453 NodeList=cpu10 #CPUs=4 Partition=cpu-opteron
[2022-11-10T15:16:20.438] _job_complete: JobId=52453 WEXITSTATUS 1
[2022-11-10T15:16:20.438] _job_complete: JobId=52453 done
[2022-11-10T15:17:33.921] _slurm_rpc_submit_batch_job: JobId=52454 InitPrio=7056 usec=484
[2022-11-10T15:17:34.810] sched: Allocate JobId=52454 NodeList=cpu10 #CPUs=4 Partition=cpu-opteron
[2022-11-10T15:17:37.508] _job_complete: JobId=52454 WEXITSTATUS 1
[2022-11-10T15:17:37.509] _job_complete: JobId=52454 done
[2022-11-10T15:46:51.833] _slurm_rpc_submit_batch_job: JobId=52455 InitPrio=13024 usec=595
[2022-11-10T15:47:42.543] _slurm_rpc_kill_job: REQUEST_KILL_JOB JobId=52455 uid 548200121
[2022-11-10T15:48:07.608] _slurm_rpc_submit_batch_job: JobId=52456 InitPrio=13024 usec=445
[2022-11-10T15:48:07.787] sched: Allocate JobId=52456 NodeList=gpu05 #CPUs=4 Partition=gpu-v100s
[2022-11-10T16:04:43.656] _slurm_rpc_submit_batch_job: JobId=52457 InitPrio=6854 usec=513
[2022-11-10T16:14:21.215] Time limit exhausted for JobId=52452
[2022-11-10T16:34:21.268] Time limit exhausted for JobId=52395
[2022-11-10T16:36:09.673] _slurm_rpc_submit_batch_job: JobId=52458 InitPrio=3024 usec=538
[2022-11-10T16:36:33.429] _slurm_rpc_kill_job: REQUEST_KILL_JOB JobId=52458 uid 548200121
[2022-11-10T16:36:50.371] _slurm_rpc_submit_batch_job: JobId=52459 InitPrio=3024 usec=470
[2022-11-10T16:37:13.005] _slurm_rpc_submit_batch_job: JobId=52460 InitPrio=13024 usec=547
[2022-11-10T16:37:13.822] sched: Allocate JobId=52460 NodeList=gpu05 #CPUs=4 Partition=gpu-v100s
[2022-11-10T16:48:21.945] Time limit exhausted for JobId=52456
[2022-11-10T17:05:15.639] _slurm_rpc_submit_batch_job: JobId=52461 InitPrio=13024 usec=597
[2022-11-10T17:05:16.574] sched: Allocate JobId=52461 NodeList=gpu05 #CPUs=16 Partition=gpu-v100s
[2022-11-10T17:05:20.804] _job_complete: JobId=52461 WEXITSTATUS 1
[2022-11-10T17:05:20.805] _job_complete: JobId=52461 done
[2022-11-10T17:06:15.673] _slurm_rpc_submit_batch_job: JobId=52462 InitPrio=13024 usec=593
[2022-11-10T17:06:15.753] sched: Allocate JobId=52462 NodeList=gpu05 #CPUs=16 Partition=gpu-v100s
[2022-11-10T17:06:22.421] _job_complete: JobId=52462 WEXITSTATUS 1
[2022-11-10T17:06:22.421] _job_complete: JobId=52462 done
[2022-11-10T17:07:12.346] _slurm_rpc_submit_batch_job: JobId=52463 InitPrio=13024 usec=557
[2022-11-10T17:07:12.867] sched: Allocate JobId=52463 NodeList=gpu05 #CPUs=16 Partition=gpu-v100s
[2022-11-10T17:10:05.460] _slurm_rpc_submit_batch_job: JobId=52464 InitPrio=6854 usec=618
[2022-11-10T17:10:22.836] _slurm_rpc_kill_job: REQUEST_KILL_JOB JobId=52457 uid 548300630
[2022-11-10T17:11:41.611] _slurm_rpc_submit_batch_job: JobId=52465 InitPrio=13024 usec=549
[2022-11-10T17:12:09.712] _slurm_rpc_submit_batch_job: JobId=52466 InitPrio=13024 usec=503
[2022-11-10T17:12:15.969] _slurm_rpc_submit_batch_job: JobId=52467 InitPrio=13024 usec=491
[2022-11-10T17:22:22.415] _job_complete: JobId=52445 WEXITSTATUS 1
[2022-11-10T17:22:22.415] _job_complete: JobId=52445 done
[2022-11-10T17:22:23.143] sched: Allocate JobId=52464 NodeList=cpu05 #CPUs=8 Partition=cpu-opteron
[2022-11-10T17:22:39.074] _job_complete: JobId=52464 WEXITSTATUS 1
[2022-11-10T17:22:39.074] _job_complete: JobId=52464 done
[2022-11-10T17:30:52.564] _job_complete: JobId=52425 WEXITSTATUS 0
[2022-11-10T17:30:52.564] _job_complete: JobId=52425 done
[2022-11-10T17:37:22.847] Time limit exhausted for JobId=52460
[2022-11-10T17:37:24.843] sched: Allocate JobId=52465 NodeList=gpu05 #CPUs=16 Partition=gpu-v100s
[2022-11-10T17:37:28.822] _job_complete: JobId=52465 WEXITSTATUS 1
[2022-11-10T17:37:28.823] _job_complete: JobId=52465 done
[2022-11-10T17:37:29.165] sched: Allocate JobId=52466 NodeList=gpu05 #CPUs=16 Partition=gpu-v100s
[2022-11-10T17:37:32.350] _job_complete: JobId=52466 WEXITSTATUS 1
[2022-11-10T17:37:32.351] _job_complete: JobId=52466 done
[2022-11-10T17:37:32.701] sched: Allocate JobId=52467 NodeList=gpu05 #CPUs=16 Partition=gpu-v100s
[2022-11-10T17:37:35.562] _job_complete: JobId=52467 WEXITSTATUS 1
[2022-11-10T17:37:35.562] _job_complete: JobId=52467 done
[2022-11-10T17:44:41.082] _slurm_rpc_kill_job: REQUEST_KILL_JOB JobId=52459 uid 548200121
[2022-11-10T17:44:59.413] _job_create: exceeded association/QOS limit for user 548200121: QOSMaxWallDurationPerJobLimit
[2022-11-10T17:44:59.413] _slurm_rpc_submit_batch_job: Job violates accounting/QOS policy (job submit limit, user's size and/or time limits)
[2022-11-10T17:45:23.458] _slurm_rpc_submit_batch_job: JobId=52468 InitPrio=13024 usec=475
[2022-11-10T17:45:23.530] sched: Allocate JobId=52468 NodeList=gpu05 #CPUs=4 Partition=gpu-v100s
[2022-11-10T17:55:24.097] _slurm_rpc_submit_batch_job: JobId=52469 InitPrio=6854 usec=504
[2022-11-10T17:55:24.544] sched: Allocate JobId=52469 NodeList=cpu05 #CPUs=8 Partition=cpu-opteron
[2022-11-10T17:55:27.645] _job_complete: JobId=52469 WEXITSTATUS 1
[2022-11-10T17:55:27.645] _job_complete: JobId=52469 done
[2022-11-10T17:57:22.095] _slurm_rpc_submit_batch_job: JobId=52470 InitPrio=6854 usec=551
[2022-11-10T17:57:22.839] sched: Allocate JobId=52470 NodeList=cpu05 #CPUs=8 Partition=cpu-opteron
[2022-11-10T17:57:38.387] _job_complete: JobId=52470 WEXITSTATUS 1
[2022-11-10T17:57:38.387] _job_complete: JobId=52470 done
[2022-11-10T18:03:03.179] _slurm_rpc_submit_batch_job: JobId=52471 InitPrio=6854 usec=552
[2022-11-10T18:03:03.348] sched: Allocate JobId=52471 NodeList=cpu05 #CPUs=8 Partition=cpu-opteron
[2022-11-10T18:04:27.992] _slurm_rpc_submit_batch_job: JobId=52472 InitPrio=6854 usec=568
[2022-11-10T18:07:22.851] Time limit exhausted for JobId=52463
[2022-11-10T18:07:42.692] _slurm_rpc_submit_batch_job: JobId=52473 InitPrio=6854 usec=531
[2022-11-10T18:08:09.093] sched/backfill: _start_job: Started JobId=52473 in cpu-opteron on cpu10
[2022-11-10T18:08:11.920] _slurm_rpc_submit_batch_job: JobId=52474 InitPrio=13024 usec=497
[2022-11-10T18:08:12.928] sched: Allocate JobId=52474 NodeList=gpu05 #CPUs=4 Partition=gpu-v100s
[2022-11-10T18:08:19.562] _job_complete: JobId=52473 WEXITSTATUS 1
[2022-11-10T18:08:19.562] _job_complete: JobId=52473 done
[2022-11-10T18:09:35.767] _slurm_rpc_kill_job: REQUEST_KILL_JOB JobId=52473 uid 548300630
[2022-11-10T18:09:48.943] _slurm_rpc_submit_batch_job: JobId=52475 InitPrio=6854 usec=511
[2022-11-10T18:10:09.100] sched/backfill: _start_job: Started JobId=52475 in cpu-opteron on cpu10
[2022-11-10T18:10:19.541] _job_complete: JobId=52475 WEXITSTATUS 1
[2022-11-10T18:10:19.541] _job_complete: JobId=52475 done
[2022-11-10T18:15:37.525] sched: _slurm_rpc_allocate_resources JobId=52476 NodeList=cpu12 usec=22271
[2022-11-10T18:19:15.732] _slurm_rpc_submit_batch_job: JobId=52477 InitPrio=6854 usec=522
[2022-11-10T18:20:09.130] sched/backfill: _start_job: Started JobId=52477 in cpu-opteron on cpu10
[2022-11-10T18:20:19.520] _job_complete: JobId=52477 WEXITSTATUS 1
[2022-11-10T18:20:19.520] _job_complete: JobId=52477 done
[2022-11-10T18:23:29.608] _slurm_rpc_submit_batch_job: JobId=52478 InitPrio=6854 usec=505
[2022-11-10T18:24:09.142] sched/backfill: _start_job: Started JobId=52478 in cpu-opteron on cpu10
[2022-11-10T18:24:20.041] _job_complete: JobId=52478 WEXITSTATUS 1
[2022-11-10T18:24:20.041] _job_complete: JobId=52478 done
[2022-11-10T18:26:42.216] _slurm_rpc_submit_batch_job: JobId=52479 InitPrio=6854 usec=559
[2022-11-10T18:27:09.152] sched/backfill: _start_job: Started JobId=52479 in cpu-opteron on cpu10
[2022-11-10T18:27:11.895] _job_complete: JobId=52479 WEXITSTATUS 1
[2022-11-10T18:27:11.896] _job_complete: JobId=52479 done
[2022-11-10T18:33:16.289] _slurm_rpc_submit_batch_job: JobId=52480 InitPrio=6854 usec=533
[2022-11-10T18:34:09.172] sched/backfill: _start_job: Started JobId=52480 in cpu-opteron on cpu10
[2022-11-10T18:34:19.466] _job_complete: JobId=52480 WEXITSTATUS 1
[2022-11-10T18:34:19.466] _job_complete: JobId=52480 done
[2022-11-10T18:34:58.818] _slurm_rpc_submit_batch_job: JobId=52481 InitPrio=6854 usec=560
[2022-11-10T18:35:09.176] sched/backfill: _start_job: Started JobId=52481 in cpu-opteron on cpu10
[2022-11-10T18:35:19.734] _job_complete: JobId=52481 WEXITSTATUS 1
[2022-11-10T18:35:19.734] _job_complete: JobId=52481 done
[2022-11-10T18:39:47.050] _slurm_rpc_submit_batch_job: JobId=52482 InitPrio=6854 usec=557
[2022-11-10T18:40:09.190] sched/backfill: _start_job: Started JobId=52482 in cpu-opteron on cpu10
[2022-11-10T18:40:19.471] _job_complete: JobId=52482 WEXITSTATUS 1
[2022-11-10T18:40:19.471] _job_complete: JobId=52482 done
[2022-11-10T18:45:07.592] _slurm_rpc_submit_batch_job: JobId=52483 InitPrio=6854 usec=484
[2022-11-10T18:45:09.204] sched/backfill: _start_job: Started JobId=52483 in cpu-opteron on cpu10
[2022-11-10T18:45:19.648] _job_complete: JobId=52483 WEXITSTATUS 1
[2022-11-10T18:45:19.648] _job_complete: JobId=52483 done
[2022-11-10T18:45:52.699] Time limit exhausted for JobId=52468
[2022-11-10T18:45:58.604] _slurm_rpc_submit_batch_job: JobId=52484 InitPrio=6854 usec=521
[2022-11-10T18:46:09.208] sched/backfill: _start_job: Started JobId=52484 in cpu-opteron on cpu10
[2022-11-10T18:46:19.737] _job_complete: JobId=52484 WEXITSTATUS 1
[2022-11-10T18:46:19.738] _job_complete: JobId=52484 done
[2022-11-10T18:46:59.075] _slurm_rpc_submit_batch_job: JobId=52485 InitPrio=13024 usec=503
[2022-11-10T18:46:59.913] sched: Allocate JobId=52485 NodeList=gpu05 #CPUs=4 Partition=gpu-v100s
[2022-11-10T18:47:20.175] _slurm_rpc_submit_batch_job: JobId=52486 InitPrio=6854 usec=500
[2022-11-10T18:48:09.214] sched/backfill: _start_job: Started JobId=52486 in cpu-opteron on cpu10
[2022-11-10T18:48:11.810] _job_complete: JobId=52486 WEXITSTATUS 1
[2022-11-10T18:48:11.811] _job_complete: JobId=52486 done
[2022-11-10T18:55:02.185] _slurm_rpc_submit_batch_job: JobId=52487 InitPrio=6854 usec=511
[2022-11-10T18:55:09.233] sched/backfill: _start_job: Started JobId=52487 in cpu-opteron on cpu10
[2022-11-10T18:55:21.109] _job_complete: JobId=52487 WEXITSTATUS 1
[2022-11-10T18:55:21.110] _job_complete: JobId=52487 done
[2022-11-10T18:58:48.846] _slurm_rpc_submit_batch_job: JobId=52488 InitPrio=6854 usec=579
[2022-11-10T18:59:09.244] sched/backfill: _start_job: Started JobId=52488 in cpu-opteron on cpu10
[2022-11-10T18:59:21.256] _job_complete: JobId=52488 WEXITSTATUS 1
[2022-11-10T18:59:21.256] _job_complete: JobId=52488 done
[2022-11-10T19:01:35.797] _slurm_rpc_submit_batch_job: JobId=52489 InitPrio=6854 usec=445
[2022-11-10T19:02:09.252] sched/backfill: _start_job: Started JobId=52489 in cpu-opteron on cpu10
[2022-11-10T19:02:21.052] _job_complete: JobId=52489 WEXITSTATUS 1
[2022-11-10T19:02:21.053] _job_complete: JobId=52489 done
[2022-11-10T19:04:36.725] _slurm_rpc_submit_batch_job: JobId=52490 InitPrio=6854 usec=527
[2022-11-10T19:05:09.261] sched/backfill: _start_job: Started JobId=52490 in cpu-opteron on cpu10
[2022-11-10T19:05:21.011] _job_complete: JobId=52490 WEXITSTATUS 1
[2022-11-10T19:05:21.011] _job_complete: JobId=52490 done
[2022-11-10T19:08:23.170] Time limit exhausted for JobId=52474
[2022-11-10T19:12:12.086] _job_complete: JobId=52476 WEXITSTATUS 127
[2022-11-10T19:12:12.086] _job_complete: JobId=52476 done
[2022-11-10T19:17:47.362] _slurm_rpc_submit_batch_job: JobId=52491 InitPrio=14032 usec=531
[2022-11-10T19:17:48.215] sched: Allocate JobId=52491 NodeList=cpu12 #CPUs=16 Partition=cpu-epyc
[2022-11-10T19:17:49.348] _job_complete: JobId=52491 WEXITSTATUS 1
[2022-11-10T19:17:49.348] _job_complete: JobId=52491 done
[2022-11-10T19:26:37.630] _slurm_rpc_submit_batch_job: JobId=52492 InitPrio=14032 usec=540
[2022-11-10T19:26:38.163] sched: Allocate JobId=52492 NodeList=cpu12 #CPUs=16 Partition=cpu-epyc
[2022-11-10T19:26:39.347] _job_complete: JobId=52492 WEXITSTATUS 1
[2022-11-10T19:26:39.347] _job_complete: JobId=52492 done
[2022-11-10T19:27:30.937] _slurm_rpc_submit_batch_job: JobId=52493 InitPrio=14032 usec=598
[2022-11-10T19:27:31.229] sched: Allocate JobId=52493 NodeList=cpu12 #CPUs=16 Partition=cpu-epyc
[2022-11-10T19:27:32.047] _job_complete: JobId=52493 WEXITSTATUS 1
[2022-11-10T19:27:32.047] _job_complete: JobId=52493 done
[2022-11-10T19:29:28.429] _slurm_rpc_submit_batch_job: JobId=52494 InitPrio=14032 usec=473
[2022-11-10T19:29:29.372] sched: Allocate JobId=52494 NodeList=cpu12 #CPUs=16 Partition=cpu-epyc
[2022-11-10T19:29:29.764] _job_complete: JobId=52494 WEXITSTATUS 1
[2022-11-10T19:29:29.764] _job_complete: JobId=52494 done
[2022-11-10T19:30:08.297] _slurm_rpc_submit_batch_job: JobId=52495 InitPrio=14032 usec=471
[2022-11-10T19:30:08.419] sched: Allocate JobId=52495 NodeList=cpu12 #CPUs=16 Partition=cpu-epyc
[2022-11-10T19:30:10.893] _job_complete: JobId=52495 WEXITSTATUS 16
[2022-11-10T19:30:10.893] _job_complete: JobId=52495 done
[2022-11-10T19:31:10.203] _slurm_rpc_submit_batch_job: JobId=52496 InitPrio=14032 usec=512
[2022-11-10T19:31:10.498] sched: Allocate JobId=52496 NodeList=cpu12 #CPUs=16 Partition=cpu-epyc
[2022-11-10T19:31:11.602] _job_complete: JobId=52496 WEXITSTATUS 1
[2022-11-10T19:31:11.602] _job_complete: JobId=52496 done
[2022-11-10T19:39:16.086] _slurm_rpc_submit_batch_job: JobId=52497 InitPrio=13024 usec=554
[2022-11-10T19:39:16.389] sched: Allocate JobId=52497 NodeList=gpu05 #CPUs=4 Partition=gpu-v100s
[2022-11-10T19:47:23.261] Time limit exhausted for JobId=52485
[2022-11-10T19:53:02.017] _slurm_rpc_kill_job: REQUEST_KILL_JOB JobId=52497 uid 548200121
[2022-11-10T19:53:07.005] sched: Allocate JobId=51834 NodeList=gpu05 #CPUs=32 Partition=gpu-v100s
[2022-11-10T19:59:24.280] _slurm_rpc_submit_batch_job: JobId=52498 InitPrio=3024 usec=530
[2022-11-10T20:12:21.877] _slurm_rpc_submit_batch_job: JobId=52499 InitPrio=16451 usec=566
[2022-11-10T20:12:22.053] sched: Allocate JobId=52499 NodeList=cpu10 #CPUs=4 Partition=cpu-opteron
[2022-11-10T20:12:32.048] _job_complete: JobId=52499 WEXITSTATUS 1
[2022-11-10T20:12:32.048] _job_complete: JobId=52499 done
[2022-11-10T20:12:43.597] _slurm_rpc_submit_batch_job: JobId=52500 InitPrio=16451 usec=481
[2022-11-10T20:12:44.061] sched: Allocate JobId=52500 NodeList=cpu10 #CPUs=4 Partition=cpu-opteron
[2022-11-10T20:12:54.872] _job_complete: JobId=52500 WEXITSTATUS 1
[2022-11-10T20:12:54.873] _job_complete: JobId=52500 done
[2022-11-10T20:13:18.102] _slurm_rpc_submit_batch_job: JobId=52501 InitPrio=16451 usec=512
[2022-11-10T20:13:20.104] sched: Allocate JobId=52501 NodeList=cpu10 #CPUs=4 Partition=cpu-opteron
[2022-11-10T20:13:30.082] _job_complete: JobId=52501 WEXITSTATUS 1
[2022-11-10T20:13:30.082] _job_complete: JobId=52501 done
[2022-11-10T20:14:38.303] _slurm_rpc_submit_batch_job: JobId=52502 InitPrio=16451 usec=514
[2022-11-10T20:14:39.200] sched: Allocate JobId=52502 NodeList=cpu10 #CPUs=4 Partition=cpu-opteron
[2022-11-10T20:14:49.564] _job_complete: JobId=52502 WEXITSTATUS 1
[2022-11-10T20:14:49.564] _job_complete: JobId=52502 done
[2022-11-10T20:15:31.183] _slurm_rpc_submit_batch_job: JobId=52503 InitPrio=16451 usec=524
[2022-11-10T20:15:31.263] sched: Allocate JobId=52503 NodeList=cpu10 #CPUs=4 Partition=cpu-opteron
[2022-11-10T20:15:41.737] _job_complete: JobId=52503 WEXITSTATUS 1
[2022-11-10T20:15:41.737] _job_complete: JobId=52503 done
[2022-11-10T20:16:24.769] _slurm_rpc_submit_batch_job: JobId=52504 InitPrio=16451 usec=521
[2022-11-10T20:16:25.460] sched: Allocate JobId=52504 NodeList=cpu10 #CPUs=4 Partition=cpu-opteron
[2022-11-10T20:16:35.764] _job_complete: JobId=52504 WEXITSTATUS 1
[2022-11-10T20:16:35.764] _job_complete: JobId=52504 done
[2022-11-10T20:16:50.025] _slurm_rpc_submit_batch_job: JobId=52505 InitPrio=3024 usec=466
[2022-11-10T20:17:09.449] sched/backfill: _start_job: Started JobId=52505 in cpu-opteron on cpu01
[2022-11-10T20:17:24.286] _slurm_rpc_submit_batch_job: JobId=52506 InitPrio=16451 usec=582
[2022-11-10T20:17:24.533] sched: Allocate JobId=52506 NodeList=cpu10 #CPUs=4 Partition=cpu-opteron
[2022-11-10T20:17:35.676] _job_complete: JobId=52506 WEXITSTATUS 1
[2022-11-10T20:17:35.676] _job_complete: JobId=52506 done
[2022-11-10T20:40:46.121] _slurm_rpc_kill_job: REQUEST_KILL_JOB JobId=52403 uid 548200017
[2022-11-10T20:46:28.347] _job_complete: JobId=52097 WEXITSTATUS 1
[2022-11-10T20:46:28.353] _job_complete: JobId=52097 done
[2022-11-10T20:46:31.813] sched: Allocate JobId=52472 NodeList=cpu03 #CPUs=8 Partition=cpu-opteron
[2022-11-10T20:59:17.648] _slurm_rpc_submit_batch_job: JobId=52507 InitPrio=806 usec=468
[2022-11-10T21:01:02.747] _slurm_rpc_kill_job: REQUEST_KILL_JOB JobId=52371 uid 548200017
[2022-11-10T21:02:18.319] _slurm_rpc_kill_job: REQUEST_KILL_JOB JobId=52372 uid 548200017
[2022-11-10T21:02:41.495] _slurm_rpc_submit_batch_job: JobId=52508 InitPrio=806 usec=462
[2022-11-10T21:42:17.633] _job_complete: JobId=52472 WEXITSTATUS 1
[2022-11-10T21:42:17.633] _job_complete: JobId=52472 done
[2022-11-10T21:42:18.285] sched: Allocate JobId=52508 NodeList=cpu03 #CPUs=64 Partition=cpu-opteron
[2022-11-10T21:47:51.609] sched: _slurm_rpc_allocate_resources JobId=52509 NodeList=cpu12 usec=20765
[2022-11-10T21:50:26.506] _job_complete: JobId=52509 WEXITSTATUS 0
[2022-11-10T21:50:26.506] _job_complete: JobId=52509 done
[2022-11-10T21:51:19.416] _slurm_rpc_submit_batch_job: JobId=52510 InitPrio=14032 usec=525
[2022-11-10T21:51:20.888] sched: Allocate JobId=52510 NodeList=cpu12 #CPUs=16 Partition=cpu-epyc
[2022-11-10T21:51:23.517] _job_complete: JobId=52510 WEXITSTATUS 137
[2022-11-10T21:51:23.517] _job_complete: JobId=52510 done
[2022-11-10T21:52:01.052] _slurm_rpc_submit_batch_job: JobId=52511 InitPrio=14032 usec=568
[2022-11-10T21:52:01.981] sched: Allocate JobId=52511 NodeList=cpu12 #CPUs=16 Partition=cpu-epyc
[2022-11-10T21:52:04.928] _job_complete: JobId=52511 WEXITSTATUS 16
[2022-11-10T21:52:04.928] _job_complete: JobId=52511 done
[2022-11-10T21:56:18.324] _slurm_rpc_submit_batch_job: JobId=52512 InitPrio=14032 usec=523
[2022-11-10T21:56:20.386] sched: Allocate JobId=52512 NodeList=cpu12 #CPUs=16 Partition=cpu-epyc
[2022-11-10T21:56:21.403] _job_complete: JobId=52512 WEXITSTATUS 1
[2022-11-10T21:56:21.403] _job_complete: JobId=52512 done
[2022-11-10T21:58:28.348] _slurm_rpc_submit_batch_job: JobId=52513 InitPrio=14032 usec=567
[2022-11-10T21:58:28.621] sched: Allocate JobId=52513 NodeList=cpu12 #CPUs=16 Partition=cpu-epyc
[2022-11-10T21:58:32.414] _job_complete: JobId=52513 WEXITSTATUS 137
[2022-11-10T21:58:32.414] _job_complete: JobId=52513 done
[2022-11-10T21:59:09.494] _slurm_rpc_submit_batch_job: JobId=52514 InitPrio=14032 usec=590
[2022-11-10T21:59:09.671] sched: Allocate JobId=52514 NodeList=cpu12 #CPUs=16 Partition=cpu-epyc
[2022-11-10T21:59:13.180] _job_complete: JobId=52514 WEXITSTATUS 1
[2022-11-10T21:59:13.180] _job_complete: JobId=52514 done
[2022-11-10T22:00:04.854] _slurm_rpc_submit_batch_job: JobId=52515 InitPrio=14032 usec=547
[2022-11-10T22:00:05.744] sched: Allocate JobId=52515 NodeList=cpu12 #CPUs=16 Partition=cpu-epyc
[2022-11-10T22:00:09.438] _job_complete: JobId=52515 WEXITSTATUS 1
[2022-11-10T22:00:09.438] _job_complete: JobId=52515 done
[2022-11-10T22:01:18.899] _slurm_rpc_submit_batch_job: JobId=52516 InitPrio=14032 usec=532
[2022-11-10T22:01:20.942] sched: Allocate JobId=52516 NodeList=cpu12 #CPUs=16 Partition=cpu-epyc
[2022-11-10T22:01:24.817] _job_complete: JobId=52516 WEXITSTATUS 1
[2022-11-10T22:01:24.817] _job_complete: JobId=52516 done
[2022-11-10T22:03:50.043] _slurm_rpc_submit_batch_job: JobId=52517 InitPrio=14032 usec=576
[2022-11-10T22:03:50.159] sched: Allocate JobId=52517 NodeList=cpu12 #CPUs=16 Partition=cpu-epyc
[2022-11-10T22:03:53.739] _job_complete: JobId=52517 WEXITSTATUS 16
[2022-11-10T22:03:53.739] _job_complete: JobId=52517 done
[2022-11-10T22:05:04.467] _slurm_rpc_submit_batch_job: JobId=52518 InitPrio=14032 usec=559
[2022-11-10T22:05:05.257] sched: Allocate JobId=52518 NodeList=cpu12 #CPUs=16 Partition=cpu-epyc
[2022-11-10T22:05:07.938] _job_complete: JobId=52518 WEXITSTATUS 16
[2022-11-10T22:05:07.938] _job_complete: JobId=52518 done
[2022-11-10T22:06:07.738] _slurm_rpc_submit_batch_job: JobId=52519 InitPrio=14032 usec=577
[2022-11-10T22:06:08.335] sched: Allocate JobId=52519 NodeList=cpu12 #CPUs=48 Partition=cpu-epyc
[2022-11-10T22:06:14.977] _job_complete: JobId=52519 WEXITSTATUS 16
[2022-11-10T22:06:14.977] _job_complete: JobId=52519 done
[2022-11-10T22:07:17.545] _slurm_rpc_submit_batch_job: JobId=52520 InitPrio=14032 usec=5464
[2022-11-10T22:07:20.510] sched: Allocate JobId=52520 NodeList=cpu12 #CPUs=48 Partition=cpu-epyc
[2022-11-10T22:07:27.435] _job_complete: JobId=52520 WEXITSTATUS 16
[2022-11-10T22:07:27.435] _job_complete: JobId=52520 done
[2022-11-10T22:10:27.983] _slurm_rpc_submit_batch_job: JobId=52521 InitPrio=14032 usec=525
[2022-11-10T22:10:28.747] sched: Allocate JobId=52521 NodeList=cpu12 #CPUs=48 Partition=cpu-epyc
[2022-11-10T22:10:33.247] _job_complete: JobId=52521 WEXITSTATUS 16
[2022-11-10T22:10:33.247] _job_complete: JobId=52521 done
[2022-11-10T22:11:58.889] _slurm_rpc_submit_batch_job: JobId=52522 InitPrio=14032 usec=553
[2022-11-10T22:11:58.947] sched: Allocate JobId=52522 NodeList=cpu12 #CPUs=48 Partition=cpu-epyc
[2022-11-10T22:12:02.879] _job_complete: JobId=52522 WEXITSTATUS 16
[2022-11-10T22:12:02.879] _job_complete: JobId=52522 done
[2022-11-10T22:13:42.227] _slurm_rpc_submit_batch_job: JobId=52523 InitPrio=14032 usec=535
[2022-11-10T22:13:43.077] sched: Allocate JobId=52523 NodeList=cpu12 #CPUs=48 Partition=cpu-epyc
[2022-11-10T22:13:45.070] _job_complete: JobId=52523 WEXITSTATUS 1
[2022-11-10T22:13:45.070] _job_complete: JobId=52523 done
[2022-11-10T22:20:00.968] sched: _slurm_rpc_allocate_resources JobId=52524 NodeList=cpu12 usec=1083
[2022-11-10T22:30:52.199] _job_complete: JobId=52442 WEXITSTATUS 0
[2022-11-10T22:30:52.200] _job_complete: JobId=52442 done
[2022-11-10T22:35:52.903] cleanup_completing: JobId=52442 completion process took 300 seconds
[2022-11-10T22:37:59.020] _job_complete: JobId=52471 WEXITSTATUS 0
[2022-11-10T22:37:59.020] _job_complete: JobId=52471 done
[2022-11-10T22:37:59.847] _job_complete: JobId=52524 WEXITSTATUS 0
[2022-11-10T22:37:59.847] _job_complete: JobId=52524 done
[2022-11-10T22:38:24.545] sched: _slurm_rpc_allocate_resources JobId=52525 NodeList=cpu12 usec=2511
[2022-11-10T23:02:03.329] _job_complete: JobId=52525 WEXITSTATUS 0
[2022-11-10T23:02:03.330] _job_complete: JobId=52525 done
[2022-11-11T00:36:02.346] _job_complete: JobId=52444 WEXITSTATUS 0
[2022-11-11T00:36:02.346] _job_complete: JobId=52444 done
[2022-11-11T01:20:48.059] _job_complete: JobId=52292 WEXITSTATUS 0
[2022-11-11T01:20:48.064] _job_complete: JobId=52292 done
[2022-11-11T07:33:15.026] _job_complete: JobId=52508 WEXITSTATUS 0
[2022-11-11T07:33:15.032] _job_complete: JobId=52508 done
[2022-11-11T07:33:16.196] sched: Allocate JobId=52427 NodeList=cpu03 #CPUs=64 Partition=cpu-opteron
[2022-11-11T07:38:16.814] sched: _slurm_rpc_allocate_resources JobId=52526 NodeList=cpu12 usec=22230
[2022-11-11T08:12:56.811] _job_complete: JobId=52218 WEXITSTATUS 0
[2022-11-11T08:12:56.811] _job_complete: JobId=52218 done
[2022-11-11T08:12:57.440] sched: Allocate JobId=52227 NodeList=cpu15 #CPUs=8 Partition=cpu-epyc
[2022-11-11T08:27:08.001] _job_complete: JobId=52219 WEXITSTATUS 0
[2022-11-11T08:27:08.002] _job_complete: JobId=52219 done
[2022-11-11T08:27:08.613] sched: Allocate JobId=52228 NodeList=cpu15 #CPUs=8 Partition=cpu-epyc
[2022-11-11T08:30:24.286] sched: _slurm_rpc_allocate_resources JobId=52527 NodeList=cpu01 usec=15570
[2022-11-11T08:47:48.676] _job_complete: JobId=52526 WEXITSTATUS 0
[2022-11-11T08:47:48.676] _job_complete: JobId=52526 done
[2022-11-11T08:49:30.996] sched: _slurm_rpc_allocate_resources JobId=52528 NodeList=cpu12 usec=2819
[2022-11-11T09:03:39.523] _job_complete: JobId=52528 WEXITSTATUS 130
[2022-11-11T09:03:39.524] _job_complete: JobId=52528 done
[2022-11-11T09:07:16.024] _slurm_rpc_submit_batch_job: JobId=52529 InitPrio=14032 usec=635
[2022-11-11T09:07:16.408] sched: Allocate JobId=52529 NodeList=cpu12 #CPUs=24 Partition=cpu-epyc
[2022-11-11T09:07:20.283] _job_complete: JobId=52529 WEXITSTATUS 16
[2022-11-11T09:07:20.283] _job_complete: JobId=52529 done
[2022-11-11T09:16:52.614] _job_complete: JobId=52527 WEXITSTATUS 0
[2022-11-11T09:16:52.615] _job_complete: JobId=52527 done
[2022-11-11T09:21:53.918] cleanup_completing: JobId=52527 completion process took 301 seconds
[2022-11-11T09:32:01.135] sched: _slurm_rpc_allocate_resources JobId=52530 NodeList=(null) usec=1148
[2022-11-11T09:32:01.237] sched: Allocate JobId=52530 NodeList=cpu01 #CPUs=1 Partition=cpu-opteron
[2022-11-11T09:34:46.371] sched: _slurm_rpc_allocate_resources JobId=52531 NodeList=cpu12 usec=2294
[2022-11-11T09:35:02.244] _job_complete: JobId=52531 WEXITSTATUS 0
[2022-11-11T09:35:02.245] _job_complete: JobId=52531 done
[2022-11-11T09:37:59.537] _slurm_rpc_submit_batch_job: JobId=52532 InitPrio=1612 usec=471
[2022-11-11T09:40:02.315] cleanup_completing: JobId=52531 completion process took 300 seconds
[2022-11-11T09:58:15.366] sched: _slurm_rpc_allocate_resources JobId=52533 NodeList=(null) usec=969
[2022-11-11T09:58:16.185] sched: Allocate JobId=52533 NodeList=cpu01 #CPUs=1 Partition=cpu-opteron
[2022-11-11T10:05:29.649] sched: _slurm_rpc_allocate_resources JobId=52534 NodeList=(null) usec=1359
[2022-11-11T10:05:29.932] sched: Allocate JobId=52534 NodeList=cpu01 #CPUs=4 Partition=cpu-opteron
[2022-11-11T10:16:45.040] _job_complete: JobId=52533 WEXITSTATUS 127
[2022-11-11T10:16:45.040] _job_complete: JobId=52533 done
[2022-11-11T10:40:46.062] _job_complete: JobId=52222 WEXITSTATUS 0
[2022-11-11T10:40:46.062] _job_complete: JobId=52222 done
[2022-11-11T10:40:46.545] sched: Allocate JobId=52229 NodeList=cpu13 #CPUs=8 Partition=cpu-epyc
[2022-11-11T10:40:51.924] _slurm_rpc_submit_batch_job: JobId=52535 InitPrio=8467 usec=563
[2022-11-11T10:40:52.936] sched: Allocate JobId=52535 NodeList=cpu01 #CPUs=1 Partition=cpu-opteron
[2022-11-11T10:42:30.958] _job_complete: JobId=52530 WEXITSTATUS 0
[2022-11-11T10:42:30.959] _job_complete: JobId=52530 done
[2022-11-11T10:55:49.075] _slurm_rpc_submit_batch_job: JobId=52536 InitPrio=806 usec=550
[2022-11-11T10:56:28.390] _slurm_rpc_kill_job: REQUEST_KILL_JOB JobId=52145 uid 548200017
[2022-11-11T10:56:33.531] sched: Allocate JobId=52357 NodeList=cpu14 #CPUs=8 Partition=cpu-epyc
[2022-11-11T10:56:33.532] sched: Allocate JobId=52358 NodeList=cpu14 #CPUs=8 Partition=cpu-epyc
[2022-11-11T11:15:39.302] _job_complete: JobId=52535 WEXITSTATUS 0
[2022-11-11T11:15:39.302] _job_complete: JobId=52535 done
[2022-11-11T11:18:22.197] sched: _slurm_rpc_allocate_resources JobId=52537 NodeList=(null) usec=950
[2022-11-11T11:18:23.036] sched: Allocate JobId=52537 NodeList=cpu10 #CPUs=1 Partition=cpu-opteron
[2022-11-11T11:20:42.301] cleanup_completing: JobId=52535 completion process took 303 seconds
[2022-11-11T11:22:55.474] job_time_limit: inactivity time limit reached for JobId=52537
[2022-11-11T11:23:28.320] sched: _slurm_rpc_allocate_resources JobId=52538 NodeList=(null) usec=1032
[2022-11-11T11:23:28.521] sched: Allocate JobId=52538 NodeList=cpu11 #CPUs=1 Partition=cpu-opteron
[2022-11-11T11:27:58.503] cleanup_completing: JobId=52537 completion process took 303 seconds
[2022-11-11T11:34:42.555] _slurm_rpc_submit_batch_job: JobId=52539 InitPrio=1008 usec=472
[2022-11-11T11:34:46.889] _slurm_rpc_submit_batch_job: JobId=52540 InitPrio=1008 usec=478
[2022-11-11T11:34:51.346] _slurm_rpc_submit_batch_job: JobId=52541 InitPrio=1008 usec=488
[2022-11-11T11:34:54.675] _slurm_rpc_submit_batch_job: JobId=52542 InitPrio=1008 usec=552
[2022-11-11T11:36:31.406] sched: _slurm_rpc_allocate_resources JobId=52543 NodeList=cpu12 usec=21086
[2022-11-11T11:50:37.595] _slurm_rpc_submit_batch_job: JobId=52544 InitPrio=14032 usec=776
[2022-11-11T11:50:38.237] sched: Allocate JobId=52544 NodeList=cpu12 #CPUs=24 Partition=cpu-epyc
[2022-11-11T11:50:39.350] _job_complete: JobId=52544 WEXITSTATUS 1
[2022-11-11T11:50:39.350] _job_complete: JobId=52544 done
[2022-11-11T11:52:54.988] _slurm_rpc_submit_batch_job: JobId=52545 InitPrio=14032 usec=802
[2022-11-11T11:52:55.543] sched: Allocate JobId=52545 NodeList=cpu12 #CPUs=24 Partition=cpu-epyc
[2022-11-11T11:53:11.855] _job_complete: JobId=52545 WEXITSTATUS 174
[2022-11-11T11:53:11.856] _job_complete: JobId=52545 done
[2022-11-11T11:53:43.933] _slurm_rpc_submit_batch_job: JobId=52546 InitPrio=14032 usec=623
[2022-11-11T11:53:44.602] sched: Allocate JobId=52546 NodeList=cpu12 #CPUs=24 Partition=cpu-epyc
[2022-11-11T11:53:59.619] _job_complete: JobId=52546 WEXITSTATUS 174
[2022-11-11T11:53:59.619] _job_complete: JobId=52546 done
[2022-11-11T11:54:16.664] _job_complete: JobId=52543 WEXITSTATUS 0
[2022-11-11T11:54:16.664] _job_complete: JobId=52543 done
[2022-11-11T11:54:37.318] _slurm_rpc_submit_batch_job: JobId=52547 InitPrio=14032 usec=513
[2022-11-11T11:54:37.674] sched: Allocate JobId=52547 NodeList=cpu12 #CPUs=24 Partition=cpu-epyc
[2022-11-11T11:54:56.517] _job_complete: JobId=52547 WEXITSTATUS 174
[2022-11-11T11:54:56.517] _job_complete: JobId=52547 done
[2022-11-11T11:55:07.023] _slurm_rpc_submit_batch_job: JobId=52548 InitPrio=14032 usec=572
[2022-11-11T11:55:07.710] sched: Allocate JobId=52548 NodeList=cpu12 #CPUs=24 Partition=cpu-epyc
[2022-11-11T11:55:13.375] _job_complete: JobId=52548 WEXITSTATUS 1
[2022-11-11T11:55:13.375] _job_complete: JobId=52548 done
[2022-11-11T11:55:46.978] _slurm_rpc_submit_batch_job: JobId=52549 InitPrio=14032 usec=598
[2022-11-11T11:55:47.759] sched: Allocate JobId=52549 NodeList=cpu12 #CPUs=24 Partition=cpu-epyc
[2022-11-11T11:55:52.919] _job_complete: JobId=52549 WEXITSTATUS 1
[2022-11-11T11:55:52.919] _job_complete: JobId=52549 done
[2022-11-11T11:57:33.711] sched: _slurm_rpc_allocate_resources JobId=52550 NodeList=(null) usec=728
[2022-11-11T11:57:34.068] sched: Allocate JobId=52550 NodeList=cpu01 #CPUs=1 Partition=cpu-opteron
[2022-11-11T12:04:11.054] _job_complete: JobId=52224 WEXITSTATUS 0
[2022-11-11T12:04:11.054] _job_complete: JobId=52224 done
[2022-11-11T12:18:50.434] _job_complete: JobId=52374 WEXITSTATUS 0
[2022-11-11T12:18:50.434] _job_complete: JobId=52374 done
[2022-11-11T12:32:54.270] _job_complete: JobId=52538 WEXITSTATUS 0
[2022-11-11T12:32:54.272] _job_complete: JobId=52538 done
[2022-11-11T12:35:49.376] _job_complete: JobId=52377 WEXITSTATUS 0
[2022-11-11T12:35:49.376] _job_complete: JobId=52377 done
[2022-11-11T12:37:56.827] cleanup_completing: JobId=52538 completion process took 302 seconds
[2022-11-11T13:08:07.223] _job_complete: JobId=52376 WEXITSTATUS 0
[2022-11-11T13:08:07.223] _job_complete: JobId=52376 done
[2022-11-11T13:09:28.454] _job_complete: JobId=52375 WEXITSTATUS 0
[2022-11-11T13:09:28.454] _job_complete: JobId=52375 done
[2022-11-11T13:09:29.243] sched: Allocate JobId=52428 NodeList=cpu04 #CPUs=64 Partition=cpu-opteron
[2022-11-11T13:09:50.199] _slurm_rpc_submit_batch_job: JobId=52551 InitPrio=403 usec=539
[2022-11-11T13:39:17.094] _slurm_rpc_submit_batch_job: JobId=52552 InitPrio=18467 usec=762
[2022-11-11T13:39:17.856] sched: Allocate JobId=52552 NodeList=cpu01 #CPUs=1 Partition=cpu-opteron
[2022-11-11T13:40:26.355] _job_complete: JobId=52552 WEXITSTATUS 0
[2022-11-11T13:40:26.355] _job_complete: JobId=52552 done
[2022-11-11T13:47:14.270] _job_complete: JobId=52221 WEXITSTATUS 0
[2022-11-11T13:47:14.270] _job_complete: JobId=52221 done
[2022-11-11T13:48:35.333] _job_complete: JobId=52226 WEXITSTATUS 0
[2022-11-11T13:48:35.333] _job_complete: JobId=52226 done
[2022-11-11T13:48:35.822] sched: Allocate JobId=52401 NodeList=cpu13 #CPUs=24 Partition=cpu-epyc
[2022-11-11T13:49:51.699] _slurm_rpc_submit_batch_job: JobId=52553 InitPrio=18467 usec=579
[2022-11-11T13:49:51.886] sched: Allocate JobId=52553 NodeList=cpu01 #CPUs=1 Partition=cpu-opteron
[2022-11-11T13:50:24.724] _job_complete: JobId=52553 WEXITSTATUS 0
[2022-11-11T13:50:24.724] _job_complete: JobId=52553 done
[2022-11-11T13:54:54.474] _slurm_rpc_submit_batch_job: JobId=52554 InitPrio=18467 usec=711
[2022-11-11T13:54:55.432] sched: Allocate JobId=52554 NodeList=cpu01 #CPUs=1 Partition=cpu-opteron
[2022-11-11T13:55:25.351] _job_complete: JobId=52554 WEXITSTATUS 0
[2022-11-11T13:55:25.352] _job_complete: JobId=52554 done
[2022-11-11T14:03:38.091] _job_complete: JobId=52380 WEXITSTATUS 0
[2022-11-11T14:03:38.091] _job_complete: JobId=52380 done
[2022-11-11T14:04:52.217] _slurm_rpc_submit_batch_job: JobId=52555 InitPrio=18467 usec=605
[2022-11-11T14:04:52.504] sched: Allocate JobId=52555 NodeList=cpu01 #CPUs=1 Partition=cpu-opteron
[2022-11-11T14:05:25.827] _job_complete: JobId=52555 WEXITSTATUS 0
[2022-11-11T14:05:25.827] _job_complete: JobId=52555 done
[2022-11-11T14:08:36.243] _slurm_rpc_submit_batch_job: JobId=52556 InitPrio=8467 usec=524
[2022-11-11T14:08:36.884] sched: Allocate JobId=52556 NodeList=cpu01 #CPUs=1 Partition=cpu-opteron
[2022-11-11T14:08:50.090] _job_complete: JobId=52534 WEXITSTATUS 0
[2022-11-11T14:08:50.091] _job_complete: JobId=52534 done
[2022-11-11T14:09:33.129] sched: _slurm_rpc_allocate_resources JobId=52557 NodeList=(null) usec=1017
[2022-11-11T14:09:33.979] sched: Allocate JobId=52557 NodeList=cpu01 #CPUs=8 Partition=cpu-opteron
[2022-11-11T14:33:05.956] sched: _slurm_rpc_allocate_resources JobId=52558 NodeList=(null) usec=1150
[2022-11-11T14:33:06.607] sched: Allocate JobId=52558 NodeList=cpu01 #CPUs=4 Partition=cpu-opteron
[2022-11-11T14:47:16.837] _job_complete: JobId=52223 WEXITSTATUS 0
[2022-11-11T14:47:16.837] _job_complete: JobId=52223 done
[2022-11-11T15:03:49.507] _slurm_rpc_submit_batch_job: JobId=52559 InitPrio=604 usec=526
[2022-11-11T15:04:02.146] _slurm_rpc_kill_job: REQUEST_KILL_JOB JobId=52599 uid 548200023
[2022-11-11T15:04:02.146] job_str_signal(3): invalid JobId=52599
[2022-11-11T15:04:02.146] _slurm_rpc_kill_job: job_str_signal() uid=548200023 JobId=52599 sig=9 returned: Invalid job id specified
[2022-11-11T15:04:11.513] sched/backfill: _start_job: Started JobId=52559 in cpu-opteron on cpu[05,09]
[2022-11-11T15:04:25.602] _slurm_rpc_submit_batch_job: JobId=52560 InitPrio=604 usec=494
[2022-11-11T15:05:11.516] sched/backfill: _start_job: Started JobId=52560 in cpu-opteron on cpu[09-10]
[2022-11-11T15:08:09.058] _slurm_rpc_submit_batch_job: JobId=52561 InitPrio=604 usec=518
[2022-11-11T15:08:11.522] sched/backfill: _start_job: Started JobId=52561 in cpu-opteron on cpu[09-10]
[2022-11-11T15:09:09.645] _job_complete: JobId=52561 WEXITSTATUS 0
[2022-11-11T15:09:09.645] _job_complete: JobId=52561 done
[2022-11-11T15:09:21.469] _slurm_rpc_submit_batch_job: JobId=52562 InitPrio=604 usec=488
[2022-11-11T15:10:11.527] sched/backfill: _start_job: Started JobId=52562 in cpu-opteron on cpu05
[2022-11-11T15:10:30.382] _job_complete: JobId=52562 WEXITSTATUS 1
[2022-11-11T15:10:30.382] _job_complete: JobId=52562 done
[2022-11-11T15:10:34.861] _slurm_rpc_submit_batch_job: JobId=52563 InitPrio=604 usec=476
[2022-11-11T15:11:04.146] _job_complete: JobId=52559 WEXITSTATUS 0
[2022-11-11T15:11:04.146] _job_complete: JobId=52559 done
[2022-11-11T15:11:11.530] sched/backfill: _start_job: Started JobId=52563 in cpu-opteron on cpu[09-10]
[2022-11-11T15:12:13.120] _job_complete: JobId=52563 WEXITSTATUS 0
[2022-11-11T15:12:13.120] _job_complete: JobId=52563 done
[2022-11-11T15:12:21.256] _slurm_rpc_submit_batch_job: JobId=52564 InitPrio=604 usec=503
[2022-11-11T15:12:30.589] _job_complete: JobId=52560 WEXITSTATUS 0
[2022-11-11T15:12:30.589] _job_complete: JobId=52560 done
[2022-11-11T15:13:11.535] sched/backfill: _start_job: Started JobId=52564 in cpu-opteron on cpu01
[2022-11-11T15:13:57.774] _slurm_rpc_submit_batch_job: JobId=52565 InitPrio=604 usec=499
[2022-11-11T15:14:11.538] sched/backfill: _start_job: Started JobId=52565 in cpu-opteron on cpu[09-10]
[2022-11-11T15:16:40.820] _job_complete: JobId=52558 WEXITSTATUS 0
[2022-11-11T15:16:40.820] _job_complete: JobId=52558 done
[2022-11-11T15:20:41.659] _job_complete: JobId=52565 WEXITSTATUS 0
[2022-11-11T15:20:41.659] _job_complete: JobId=52565 done
[2022-11-11T15:24:07.225] _slurm_rpc_submit_batch_job: JobId=52566 InitPrio=18870 usec=622
[2022-11-11T15:24:08.015] sched: Allocate JobId=52566 NodeList=cpu05 #CPUs=16 Partition=cpu-opteron
[2022-11-11T15:24:10.083] _job_complete: JobId=52566 WEXITSTATUS 1
[2022-11-11T15:24:10.083] _job_complete: JobId=52566 done
[2022-11-11T15:24:28.519] sched: _slurm_rpc_allocate_resources JobId=52567 NodeList=(null) usec=960
[2022-11-11T15:24:29.030] sched: Allocate JobId=52567 NodeList=cpu01 #CPUs=1 Partition=cpu-opteron
[2022-11-11T15:24:57.401] _slurm_rpc_submit_batch_job: JobId=52568 InitPrio=604 usec=453
[2022-11-11T15:25:11.559] sched/backfill: _start_job: Started JobId=52568 in cpu-opteron on cpu[09-10]
[2022-11-11T15:25:14.233] _job_complete: JobId=52568 WEXITSTATUS 0
[2022-11-11T15:25:14.233] _job_complete: JobId=52568 done
[2022-11-11T15:28:19.943] _slurm_rpc_submit_batch_job: JobId=52569 InitPrio=604 usec=497
[2022-11-11T15:29:11.567] sched/backfill: _start_job: Started JobId=52569 in cpu-opteron on cpu01
[2022-11-11T15:31:29.275] _job_complete: JobId=52379 WEXITSTATUS 0
[2022-11-11T15:31:29.276] _job_complete: JobId=52379 done
[2022-11-11T15:35:11.514] _slurm_rpc_kill_job: REQUEST_KILL_JOB JobId=52567 uid 548300539
[2022-11-11T15:37:02.172] sched: _slurm_rpc_allocate_resources JobId=52570 NodeList=(null) usec=1021
[2022-11-11T15:37:02.357] sched: Allocate JobId=52570 NodeList=cpu01 #CPUs=1 Partition=cpu-opteron
[2022-11-11T15:38:56.775] _slurm_rpc_submit_batch_job: JobId=52571 InitPrio=604 usec=547
[2022-11-11T15:39:11.585] sched/backfill: _start_job: Started JobId=52571 in cpu-opteron on cpu05
[2022-11-11T15:44:09.526] _slurm_rpc_submit_batch_job: JobId=52572 InitPrio=604 usec=562
[2022-11-11T15:44:28.927] _slurm_rpc_submit_batch_job: JobId=52573 InitPrio=18669 usec=480
[2022-11-11T15:44:29.024] sched: Allocate JobId=52573 NodeList=cpu09 #CPUs=16 Partition=cpu-opteron
[2022-11-11T15:44:31.143] _job_complete: JobId=52573 WEXITSTATUS 1
[2022-11-11T15:44:31.143] _job_complete: JobId=52573 done
[2022-11-11T15:44:51.133] _job_complete: JobId=52570 WEXITSTATUS 0
[2022-11-11T15:44:51.133] _job_complete: JobId=52570 done
[2022-11-11T15:45:42.610] _slurm_rpc_submit_batch_job: JobId=52574 InitPrio=18669 usec=598
[2022-11-11T15:45:43.118] sched: Allocate JobId=52574 NodeList=cpu09 #CPUs=16 Partition=cpu-opteron
[2022-11-11T15:45:44.746] _job_complete: JobId=52574 WEXITSTATUS 1
[2022-11-11T15:45:44.746] _job_complete: JobId=52574 done
[2022-11-11T15:46:39.253] _job_complete: JobId=52564 WEXITSTATUS 0
[2022-11-11T15:46:39.253] _job_complete: JobId=52564 done
[2022-11-11T15:51:02.712] _slurm_rpc_submit_batch_job: JobId=52575 InitPrio=604 usec=499
[2022-11-11T15:51:11.610] sched/backfill: _start_job: Started JobId=52575 in cpu-opteron on cpu[09-10]
[2022-11-11T15:53:16.692] _job_complete: JobId=52575 WEXITSTATUS 0
[2022-11-11T15:53:16.692] _job_complete: JobId=52575 done
[2022-11-11T15:56:04.893] _slurm_rpc_submit_batch_job: JobId=52576 InitPrio=14032 usec=608
[2022-11-11T15:56:05.188] sched: Allocate JobId=52576 NodeList=cpu12 #CPUs=24 Partition=cpu-epyc
[2022-11-11T15:56:27.997] _job_complete: JobId=52576 WEXITSTATUS 0
[2022-11-11T15:56:27.997] _job_complete: JobId=52576 done
[2022-11-11T15:57:07.305]    retry_list retry_list_size:191 msg_type=SRUN_STEP_SIGNAL,SRUN_STEP_SIGNAL,SRUN_STEP_SIGNAL,SRUN_STEP_SIGNAL,SRUN_STEP_SIGNAL
[2022-11-11T15:57:19.776] _job_complete: JobId=52557 WEXITSTATUS 1
[2022-11-11T15:57:19.778] _job_complete: JobId=52557 done
[2022-11-11T15:58:03.343] _slurm_rpc_submit_batch_job: JobId=52577 InitPrio=14032 usec=589
[2022-11-11T15:58:03.410] sched: Allocate JobId=52577 NodeList=cpu12 #CPUs=24 Partition=cpu-epyc
[2022-11-11T15:58:11.625] sched/backfill: _start_job: Started JobId=52572 in cpu-opteron on cpu01
[2022-11-11T15:58:17.378] _job_complete: JobId=52577 WEXITSTATUS 0
[2022-11-11T15:58:17.378] _job_complete: JobId=52577 done
[2022-11-11T15:59:25.197] _job_complete: JobId=52569 WEXITSTATUS 0
[2022-11-11T15:59:25.197] _job_complete: JobId=52569 done
[2022-11-11T15:59:57.984] _job_complete: JobId=52550 WEXITSTATUS 0
[2022-11-11T15:59:57.985] _job_complete: JobId=52550 done
[2022-11-11T16:03:24.354] _slurm_rpc_submit_batch_job: JobId=52578 InitPrio=604 usec=550
[2022-11-11T16:04:11.638] sched/backfill: _start_job: Started JobId=52578 in cpu-opteron on cpu[09-10]
[2022-11-11T16:04:58.523] cleanup_completing: JobId=52550 completion process took 301 seconds
[2022-11-11T16:06:05.882] _job_complete: JobId=52578 WEXITSTATUS 0
[2022-11-11T16:06:05.882] _job_complete: JobId=52578 done
[2022-11-11T16:08:42.403] _slurm_rpc_submit_batch_job: JobId=52579 InitPrio=604 usec=524
[2022-11-11T16:10:07.041] _slurm_rpc_submit_batch_job: JobId=52580 InitPrio=1411 usec=642
[2022-11-11T16:10:07.583] sched: Allocate JobId=52580 NodeList=cpu05 #CPUs=16 Partition=cpu-opteron
[2022-11-11T16:17:47.178] _job_complete: JobId=52556 WEXITSTATUS 0
[2022-11-11T16:17:47.179] _job_complete: JobId=52556 done
[2022-11-11T16:21:29.733] _job_complete: JobId=52358 OOM failure
[2022-11-11T16:21:29.733] _job_complete: JobId=52358 done
[2022-11-11T16:27:14.634] _slurm_rpc_submit_batch_job: JobId=52581 InitPrio=1411 usec=652
[2022-11-11T16:27:36.357] _slurm_rpc_kill_job: REQUEST_KILL_JOB JobId=52581 uid 548300593
[2022-11-11T16:27:57.597] _slurm_rpc_submit_batch_job: JobId=52582 InitPrio=1411 usec=678
[2022-11-11T16:52:40.998] _job_complete: JobId=52378 WEXITSTATUS 0
[2022-11-11T16:52:40.998] _job_complete: JobId=52378 done
[2022-11-11T17:04:56.338] _job_complete: JobId=52225 WEXITSTATUS 0
[2022-11-11T17:04:56.338] _job_complete: JobId=52225 done
[2022-11-11T17:12:17.070] _job_complete: JobId=52571 WEXITSTATUS 0
[2022-11-11T17:12:17.070] _job_complete: JobId=52571 done
[2022-11-11T17:12:17.899] sched: Allocate JobId=52582 NodeList=cpu05 #CPUs=32 Partition=cpu-opteron
[2022-11-11T17:29:34.381] _job_complete: JobId=52572 WEXITSTATUS 0
[2022-11-11T17:29:34.381] _job_complete: JobId=52572 done
[2022-11-11T17:38:38.960] _slurm_rpc_submit_batch_job: JobId=52583 InitPrio=6451 usec=545
[2022-11-11T17:38:39.645] sched: Allocate JobId=52583 NodeList=cpu09 #CPUs=8 Partition=cpu-opteron
[2022-11-11T17:51:22.135] _job_create: exceeded association/QOS limit for user 548200121: QOSMaxWallDurationPerJobLimit
[2022-11-11T17:51:22.135] _slurm_rpc_submit_batch_job: Job violates accounting/QOS policy (job submit limit, user's size and/or time limits)
[2022-11-11T17:51:44.136] _job_create: exceeded association/QOS limit for user 548200121: QOSMaxWallDurationPerJobLimit
[2022-11-11T17:51:44.136] _slurm_rpc_submit_batch_job: Job violates accounting/QOS policy (job submit limit, user's size and/or time limits)
[2022-11-11T17:52:23.225] _slurm_rpc_submit_batch_job: JobId=52584 InitPrio=3024 usec=448
[2022-11-11T18:06:12.077] _job_complete: JobId=52220 WEXITSTATUS 0
[2022-11-11T18:06:12.078] _job_complete: JobId=52220 done
[2022-11-11T18:18:02.405] _slurm_rpc_submit_batch_job: JobId=52585 InitPrio=806 usec=521
[2022-11-11T18:19:36.082] _job_complete: JobId=52381 WEXITSTATUS 0
[2022-11-11T18:19:36.082] _job_complete: JobId=52381 done
[2022-11-11T18:36:03.976] sched: _slurm_rpc_allocate_resources JobId=52586 NodeList=(null) usec=1283
[2022-11-11T18:36:04.788] sched: Allocate JobId=52586 NodeList=cpu05 #CPUs=1 Partition=cpu-opteron
[2022-11-11T18:41:28.267] _slurm_rpc_submit_batch_job: JobId=52587 InitPrio=18669 usec=557
[2022-11-11T18:41:28.401] sched: Allocate JobId=52587 NodeList=cpu01 #CPUs=16 Partition=cpu-opteron
[2022-11-11T18:41:29.997] _job_complete: JobId=52587 WEXITSTATUS 1
[2022-11-11T18:41:29.997] _job_complete: JobId=52587 done
[2022-11-11T18:44:33.385] _slurm_rpc_kill_job: REQUEST_KILL_JOB JobId=52586 uid 548300539
[2022-11-11T18:45:35.139] _slurm_rpc_submit_batch_job: JobId=52588 InitPrio=18669 usec=682
[2022-11-11T18:45:35.702] sched: Allocate JobId=52588 NodeList=cpu01 #CPUs=16 Partition=cpu-opteron
[2022-11-11T18:45:37.203] _job_complete: JobId=52588 WEXITSTATUS 1
[2022-11-11T18:45:37.203] _job_complete: JobId=52588 done
[2022-11-11T18:46:49.804] _slurm_rpc_submit_batch_job: JobId=52589 InitPrio=18669 usec=523
[2022-11-11T18:46:49.925] sched: Allocate JobId=52589 NodeList=cpu01 #CPUs=16 Partition=cpu-opteron
[2022-11-11T18:46:51.261] _job_complete: JobId=52589 WEXITSTATUS 1
[2022-11-11T18:46:51.262] _job_complete: JobId=52589 done
[2022-11-11T18:48:16.227] _slurm_rpc_submit_batch_job: JobId=52590 InitPrio=18669 usec=573
[2022-11-11T18:48:17.031] sched: Allocate JobId=52590 NodeList=cpu01 #CPUs=16 Partition=cpu-opteron
[2022-11-11T18:48:18.732] _job_complete: JobId=52590 WEXITSTATUS 1
[2022-11-11T18:48:18.732] _job_complete: JobId=52590 done
[2022-11-11T18:49:29.768] sched: _slurm_rpc_allocate_resources JobId=52591 NodeList=(null) usec=877
[2022-11-11T18:49:30.125] sched: Allocate JobId=52591 NodeList=cpu05 #CPUs=1 Partition=cpu-opteron
[2022-11-11T18:56:48.677] _slurm_rpc_submit_batch_job: JobId=52592 InitPrio=18669 usec=540
[2022-11-11T18:56:48.935] sched: Allocate JobId=52592 NodeList=cpu01 #CPUs=16 Partition=cpu-opteron
[2022-11-11T19:01:24.570] _slurm_rpc_kill_job: REQUEST_KILL_JOB JobId=52592 uid 548300539
[2022-11-11T19:07:50.619] _slurm_rpc_submit_batch_job: JobId=52593 InitPrio=16451 usec=778
[2022-11-11T19:07:51.214] sched: Allocate JobId=52593 NodeList=cpu05 #CPUs=8 Partition=cpu-opteron
[2022-11-11T19:08:06.331] _job_complete: JobId=52593 WEXITSTATUS 1
[2022-11-11T19:08:06.331] _job_complete: JobId=52593 done
[2022-11-11T19:08:59.955] _slurm_rpc_submit_batch_job: JobId=52594 InitPrio=16451 usec=586
[2022-11-11T19:09:00.301] sched: Allocate JobId=52594 NodeList=cpu05 #CPUs=8 Partition=cpu-opteron
[2022-11-11T19:09:16.084] _job_complete: JobId=52594 WEXITSTATUS 1
[2022-11-11T19:09:16.084] _job_complete: JobId=52594 done
[2022-11-11T19:09:46.323] _slurm_rpc_submit_batch_job: JobId=52595 InitPrio=18669 usec=543
[2022-11-11T19:09:46.357] sched: Allocate JobId=52595 NodeList=cpu01 #CPUs=16 Partition=cpu-opteron
[2022-11-11T19:09:47.890] _job_complete: JobId=52595 WEXITSTATUS 1
[2022-11-11T19:09:47.890] _job_complete: JobId=52595 done
[2022-11-11T19:09:49.162] _slurm_rpc_submit_batch_job: JobId=52596 InitPrio=6451 usec=606
[2022-11-11T19:09:49.359] sched: Allocate JobId=52596 NodeList=cpu05 #CPUs=8 Partition=cpu-opteron
[2022-11-11T19:10:03.951] _job_complete: JobId=52596 WEXITSTATUS 1
[2022-11-11T19:10:03.951] _job_complete: JobId=52596 done
[2022-11-11T19:12:10.343] _slurm_rpc_submit_batch_job: JobId=52597 InitPrio=18669 usec=614
[2022-11-11T19:12:10.750] sched: Allocate JobId=52597 NodeList=cpu01 #CPUs=16 Partition=cpu-opteron
[2022-11-11T19:12:12.434] _job_complete: JobId=52597 WEXITSTATUS 1
[2022-11-11T19:12:12.434] _job_complete: JobId=52597 done
[2022-11-11T19:13:53.195] _slurm_rpc_submit_batch_job: JobId=52598 InitPrio=18669 usec=582
[2022-11-11T19:13:53.877] sched: Allocate JobId=52598 NodeList=cpu01 #CPUs=16 Partition=cpu-opteron
[2022-11-11T19:14:40.373] _job_complete: JobId=52591 WEXITSTATUS 0
[2022-11-11T19:14:40.373] _job_complete: JobId=52591 done
[2022-11-11T19:15:12.408] _job_complete: JobId=52598 WEXITSTATUS 0
[2022-11-11T19:15:12.408] _job_complete: JobId=52598 done
[2022-11-11T19:16:28.197] _slurm_rpc_submit_batch_job: JobId=52599 InitPrio=6451 usec=459
[2022-11-11T19:16:28.457] sched: Allocate JobId=52599 NodeList=cpu05 #CPUs=8 Partition=cpu-opteron
[2022-11-11T19:16:41.915] sched: _slurm_rpc_allocate_resources JobId=52600 NodeList=(null) usec=768
[2022-11-11T19:16:42.474] sched: Allocate JobId=52600 NodeList=cpu05 #CPUs=1 Partition=cpu-opteron
[2022-11-11T19:16:58.347] _slurm_rpc_kill_job: REQUEST_KILL_JOB JobId=52599 uid 548300630
[2022-11-11T19:17:55.381] _job_complete: JobId=52582 WEXITSTATUS 1
[2022-11-11T19:17:55.386] _job_complete: JobId=52582 done
[2022-11-11T19:18:15.086] _slurm_rpc_submit_batch_job: JobId=52601 InitPrio=6451 usec=534
[2022-11-11T19:18:15.595] sched: Allocate JobId=52601 NodeList=cpu09 #CPUs=8 Partition=cpu-opteron
[2022-11-11T19:18:19.801] _job_complete: JobId=52601 WEXITSTATUS 1
[2022-11-11T19:18:19.801] _job_complete: JobId=52601 done
[2022-11-11T19:20:31.330] _slurm_rpc_submit_batch_job: JobId=52602 InitPrio=6451 usec=608
[2022-11-11T19:20:31.765] sched: Allocate JobId=52602 NodeList=cpu09 #CPUs=8 Partition=cpu-opteron
[2022-11-11T19:25:16.255] _slurm_rpc_submit_batch_job: JobId=52603 InitPrio=6451 usec=718
[2022-11-11T19:25:17.243] sched: Allocate JobId=52603 NodeList=cpu05 #CPUs=8 Partition=cpu-opteron
[2022-11-11T19:25:45.756] _job_complete: JobId=52357 OOM failure
[2022-11-11T19:25:45.756] _job_complete: JobId=52357 done
[2022-11-11T19:25:46.218] sched: Allocate JobId=52402 NodeList=cpu14 #CPUs=24 Partition=cpu-epyc
[2022-11-11T19:26:12.030] sched/backfill: _start_job: Started JobId=52579 in cpu-opteron on cpu05
[2022-11-11T19:27:04.491] _slurm_rpc_submit_batch_job: JobId=52604 InitPrio=6451 usec=524
[2022-11-11T19:27:05.479] sched: Allocate JobId=52604 NodeList=cpu01 #CPUs=8 Partition=cpu-opteron
[2022-11-11T19:28:42.975] _slurm_rpc_submit_batch_job: JobId=52605 InitPrio=6451 usec=546
[2022-11-11T19:28:43.603] sched: Allocate JobId=52605 NodeList=cpu01 #CPUs=8 Partition=cpu-opteron
[2022-11-11T19:30:03.273] _slurm_rpc_submit_batch_job: JobId=52606 InitPrio=6451 usec=492
[2022-11-11T19:30:03.701] sched: Allocate JobId=52606 NodeList=cpu01 #CPUs=8 Partition=cpu-opteron
[2022-11-11T19:30:59.317] _slurm_rpc_submit_batch_job: JobId=52607 InitPrio=18467 usec=501
[2022-11-11T19:30:59.774] sched: Allocate JobId=52607 NodeList=cpu01 #CPUs=16 Partition=cpu-opteron
[2022-11-11T19:31:20.784] _slurm_rpc_submit_batch_job: JobId=52608 InitPrio=6451 usec=478
[2022-11-11T19:31:57.992] _job_complete: JobId=52607 WEXITSTATUS 0
[2022-11-11T19:31:57.992] _job_complete: JobId=52607 done
[2022-11-11T19:31:59.775] sched: Allocate JobId=52608 NodeList=cpu01 #CPUs=8 Partition=cpu-opteron
[2022-11-11T19:36:28.449] _slurm_rpc_submit_batch_job: JobId=52609 InitPrio=6451 usec=672
[2022-11-11T19:41:02.220] _slurm_rpc_submit_batch_job: JobId=52610 InitPrio=6451 usec=509
[2022-11-11T19:41:02.799] sched: Allocate JobId=52610 NodeList=cpu13 #CPUs=12 Partition=cpu-epyc
[2022-11-11T19:41:27.991] _slurm_rpc_kill_job: REQUEST_KILL_JOB JobId=52609 uid 548300630
[2022-11-11T19:51:25.566] _job_complete: JobId=52583 WEXITSTATUS 1
[2022-11-11T19:51:25.566] _job_complete: JobId=52583 done
[2022-11-11T19:54:39.629] _slurm_rpc_submit_batch_job: JobId=52611 InitPrio=6250 usec=601
[2022-11-11T19:56:23.983] _slurm_rpc_kill_job: REQUEST_KILL_JOB JobId=52611 uid 548300630
[2022-11-11T19:56:37.678] _get_job_parts: invalid partition specified: cpu-opeteron
[2022-11-11T19:56:37.678] _slurm_rpc_submit_batch_job: Invalid partition name specified
[2022-11-11T19:57:18.597] _slurm_rpc_submit_batch_job: JobId=52612 InitPrio=6048 usec=545
[2022-11-11T19:57:20.512] sched: Allocate JobId=52612 NodeList=cpu09 #CPUs=8 Partition=cpu-opteron
[2022-11-11T19:59:46.734] _job_complete: JobId=52238 WEXITSTATUS 0
[2022-11-11T19:59:46.734] _job_complete: JobId=52238 done
[2022-11-11T20:17:28.696] Time limit exhausted for JobId=52505
[2022-11-11T20:19:09.593] _job_complete: JobId=52600 WEXITSTATUS 0
[2022-11-11T20:19:09.593] _job_complete: JobId=52600 done
[2022-11-11T20:23:58.059] _slurm_rpc_submit_batch_job: JobId=52613 InitPrio=1411 usec=699
[2022-11-11T20:24:02.394] _job_complete: JobId=52580 WEXITSTATUS 0
[2022-11-11T20:24:02.395] _job_complete: JobId=52580 done
[2022-11-11T20:44:20.783] _job_complete: JobId=52237 WEXITSTATUS 0
[2022-11-11T20:44:20.783] _job_complete: JobId=52237 done
[2022-11-11T21:12:23.259] _job_complete: JobId=52579 WEXITSTATUS 0
[2022-11-11T21:12:23.260] _job_complete: JobId=52579 done
[2022-11-11T21:13:12.232] sched/backfill: _start_job: Started JobId=52613 in cpu-opteron on cpu05
[2022-11-11T21:23:43.866] _slurm_rpc_submit_batch_job: JobId=52614 InitPrio=1411 usec=535
[2022-11-11T21:40:28.858] _job_complete: JobId=52239 WEXITSTATUS 0
[2022-11-11T21:40:28.859] _job_complete: JobId=52239 done
[2022-11-11T21:41:12.283] sched/backfill: _start_job: Started JobId=52614 in cpu-opteron on cpu11
[2022-11-11T21:44:42.564] _job_complete: JobId=52234 WEXITSTATUS 0
[2022-11-11T21:44:42.564] _job_complete: JobId=52234 done
[2022-11-11T22:09:39.389] _job_complete: JobId=52612 WEXITSTATUS 1
[2022-11-11T22:09:39.390] _job_complete: JobId=52612 done
[2022-11-11T22:58:21.252] _job_complete: JobId=52245 WEXITSTATUS 0
[2022-11-11T22:58:21.252] _job_complete: JobId=52245 done
[2022-11-11T23:51:55.097] _job_complete: JobId=52614 WEXITSTATUS 0
[2022-11-11T23:51:55.103] _job_complete: JobId=52614 done
[2022-11-11T23:54:33.905] _job_complete: JobId=52603 WEXITSTATUS 0
[2022-11-11T23:54:33.906] _job_complete: JobId=52603 done
[2022-11-12T01:16:46.140] _job_complete: JobId=52240 WEXITSTATUS 0
[2022-11-12T01:16:46.140] _job_complete: JobId=52240 done
[2022-11-12T01:17:23.481] _job_complete: JobId=52233 WEXITSTATUS 0
[2022-11-12T01:17:23.481] _job_complete: JobId=52233 done
[2022-11-12T01:30:51.643] _job_complete: JobId=52243 WEXITSTATUS 0
[2022-11-12T01:30:51.643] _job_complete: JobId=52243 done
[2022-11-12T01:42:08.988] _job_complete: JobId=52610 WEXITSTATUS 0
[2022-11-12T01:42:08.989] _job_complete: JobId=52610 done
[2022-11-12T02:07:20.215] _job_complete: JobId=52246 WEXITSTATUS 0
[2022-11-12T02:07:20.215] _job_complete: JobId=52246 done
[2022-11-12T04:26:42.478] _job_complete: JobId=52236 WEXITSTATUS 0
[2022-11-12T04:26:42.478] _job_complete: JobId=52236 done
[2022-11-12T05:22:13.157] _job_complete: JobId=52602 WEXITSTATUS 0
[2022-11-12T05:22:13.157] _job_complete: JobId=52602 done
[2022-11-12T06:43:57.807] _job_complete: JobId=52227 WEXITSTATUS 0
[2022-11-12T06:43:57.807] _job_complete: JobId=52227 done
[2022-11-12T06:57:30.009] _job_complete: JobId=52244 WEXITSTATUS 0
[2022-11-12T06:57:30.009] _job_complete: JobId=52244 done
[2022-11-12T07:22:15.863] _job_complete: JobId=52228 WEXITSTATUS 0
[2022-11-12T07:22:15.864] _job_complete: JobId=52228 done
[2022-11-12T07:25:34.357] _job_complete: JobId=52242 WEXITSTATUS 0
[2022-11-12T07:25:34.357] _job_complete: JobId=52242 done
[2022-11-12T07:59:47.084] _job_complete: JobId=52605 WEXITSTATUS 0
[2022-11-12T07:59:47.084] _job_complete: JobId=52605 done
[2022-11-12T08:52:25.706] _slurm_rpc_submit_batch_job: JobId=52615 InitPrio=4032 usec=651
[2022-11-12T08:52:26.448] sched: Allocate JobId=52615 NodeList=cpu05 #CPUs=8 Partition=cpu-opteron
[2022-11-12T08:52:31.184] _job_complete: JobId=52615 WEXITSTATUS 1
[2022-11-12T08:52:31.184] _job_complete: JobId=52615 done
[2022-11-12T09:24:00.061] _slurm_rpc_submit_batch_job: JobId=52616 InitPrio=4032 usec=559
[2022-11-12T09:24:00.683] sched: Allocate JobId=52616 NodeList=cpu05 #CPUs=8 Partition=cpu-opteron
[2022-11-12T09:27:08.686] _slurm_rpc_submit_batch_job: JobId=52617 InitPrio=4032 usec=451
[2022-11-12T09:27:09.067] sched: Allocate JobId=52617 NodeList=cpu13 #CPUs=12 Partition=cpu-epyc
[2022-11-12T09:35:14.296] _slurm_rpc_submit_batch_job: JobId=52618 InitPrio=4032 usec=546
[2022-11-12T09:35:14.799] sched: Allocate JobId=52618 NodeList=cpu15 #CPUs=12 Partition=cpu-epyc
[2022-11-12T09:49:21.788] _slurm_rpc_submit_batch_job: JobId=52619 InitPrio=4032 usec=627
[2022-11-12T09:49:22.420] sched: Allocate JobId=52619 NodeList=cpu05 #CPUs=8 Partition=cpu-opteron
[2022-11-12T09:55:05.397] _job_complete: JobId=52619 WEXITSTATUS 0
[2022-11-12T09:55:05.397] _job_complete: JobId=52619 done
[2022-11-12T09:57:17.934] _slurm_rpc_submit_batch_job: JobId=52620 InitPrio=4032 usec=453
[2022-11-12T09:57:18.263] sched: Allocate JobId=52620 NodeList=cpu15 #CPUs=12 Partition=cpu-epyc
[2022-11-12T11:29:19.357] _slurm_rpc_submit_batch_job: JobId=52621 InitPrio=1411 usec=784
[2022-11-12T11:29:26.572] _slurm_rpc_kill_job: REQUEST_KILL_JOB JobId=52613 uid 548300593
[2022-11-12T11:30:14.285] sched/backfill: _start_job: Started JobId=52621 in cpu-opteron on cpu05
[2022-11-12T11:31:12.521] _slurm_rpc_submit_batch_job: JobId=52622 InitPrio=1411 usec=575
[2022-11-12T11:31:14.288] sched/backfill: _start_job: Started JobId=52622 in cpu-opteron on cpu11
[2022-11-12T11:32:05.388] _job_complete: JobId=52622 WEXITSTATUS 1
[2022-11-12T11:32:05.388] _job_complete: JobId=52622 done
[2022-11-12T11:42:04.530] _slurm_rpc_submit_batch_job: JobId=52623 InitPrio=1411 usec=723
[2022-11-12T11:42:14.307] sched/backfill: _start_job: Started JobId=52623 in cpu-opteron on cpu11
[2022-11-12T11:43:06.719] _job_complete: JobId=52623 WEXITSTATUS 0
[2022-11-12T11:43:06.720] _job_complete: JobId=52623 done
[2022-11-12T11:44:29.463] _slurm_rpc_submit_batch_job: JobId=52624 InitPrio=1411 usec=697
[2022-11-12T11:45:14.313] sched/backfill: _start_job: Started JobId=52624 in cpu-opteron on cpu11
[2022-11-12T11:45:17.227] _job_complete: JobId=52624 WEXITSTATUS 1
[2022-11-12T11:45:17.227] _job_complete: JobId=52624 done
[2022-11-12T11:56:14.335] _slurm_rpc_submit_batch_job: JobId=52625 InitPrio=1411 usec=660
[2022-11-12T11:57:14.333] sched/backfill: _start_job: Started JobId=52625 in cpu-opteron on cpu11
[2022-11-12T12:03:13.757] _job_complete: JobId=52620 WEXITSTATUS 0
[2022-11-12T12:03:13.757] _job_complete: JobId=52620 done
[2022-11-12T12:09:41.445] _job_complete: JobId=52621 WEXITSTATUS 127
[2022-11-12T12:09:41.446] _job_complete: JobId=52621 done
[2022-11-12T12:36:03.054] _job_complete: JobId=52617 WEXITSTATUS 0
[2022-11-12T12:36:03.054] _job_complete: JobId=52617 done
[2022-11-12T13:07:09.770] _slurm_rpc_submit_batch_job: JobId=52626 InitPrio=1411 usec=698
[2022-11-12T13:07:14.586] sched/backfill: _start_job: Started JobId=52626 in cpu-opteron on cpu05
[2022-11-12T13:08:03.353] _job_complete: JobId=52626 WEXITSTATUS 255
[2022-11-12T13:08:03.354] _job_complete: JobId=52626 done
[2022-11-12T13:08:34.717] _slurm_rpc_submit_batch_job: JobId=52627 InitPrio=4032 usec=529
[2022-11-12T13:08:34.831] sched: Allocate JobId=52627 NodeList=cpu15 #CPUs=12 Partition=cpu-epyc
[2022-11-12T13:10:05.330] _slurm_rpc_submit_batch_job: JobId=52628 InitPrio=1411 usec=594
[2022-11-12T13:10:14.592] sched/backfill: _start_job: Started JobId=52628 in cpu-opteron on cpu05
[2022-11-12T13:10:50.237] _slurm_rpc_submit_batch_job: JobId=52629 InitPrio=4032 usec=519
[2022-11-12T13:10:50.995] sched: Allocate JobId=52629 NodeList=cpu10 #CPUs=16 Partition=cpu-opteron
[2022-11-12T13:20:40.102] _job_complete: JobId=52608 WEXITSTATUS 0
[2022-11-12T13:20:40.102] _job_complete: JobId=52608 done
[2022-11-12T13:33:35.872] _job_complete: JobId=52628 WEXITSTATUS 255
[2022-11-12T13:33:35.873] _job_complete: JobId=52628 done
[2022-11-12T13:40:54.995] _slurm_rpc_submit_batch_job: JobId=52630 InitPrio=1411 usec=704
[2022-11-12T13:41:14.728] sched/backfill: _start_job: Started JobId=52630 in cpu-opteron on cpu01
[2022-11-12T13:49:38.322] _job_complete: JobId=52627 WEXITSTATUS 1
[2022-11-12T13:49:38.322] _job_complete: JobId=52627 done
[2022-11-12T14:04:08.103] _job_complete: JobId=52604 WEXITSTATUS 0
[2022-11-12T14:04:08.103] _job_complete: JobId=52604 done
[2022-11-12T14:30:36.036] _job_complete: JobId=52630 OOM failure
[2022-11-12T14:30:36.038] _job_complete: JobId=52630 done
[2022-11-12T14:34:55.968] _slurm_rpc_submit_batch_job: JobId=52631 InitPrio=3830 usec=520
[2022-11-12T14:34:56.238] sched: Allocate JobId=52631 NodeList=cpu15 #CPUs=12 Partition=cpu-epyc
[2022-11-12T14:56:32.274] _job_complete: JobId=52629 WEXITSTATUS 1
[2022-11-12T14:56:32.274] _job_complete: JobId=52629 done
[2022-11-12T15:24:02.534] _slurm_rpc_submit_batch_job: JobId=52632 InitPrio=1411 usec=582
[2022-11-12T15:24:14.974] sched/backfill: _start_job: Started JobId=52632 in cpu-opteron on cpu01
[2022-11-12T15:55:06.922] _job_complete: JobId=52632 WEXITSTATUS 0
[2022-11-12T15:55:06.924] _job_complete: JobId=52632 done
[2022-11-12T16:23:01.681] _slurm_rpc_submit_batch_job: JobId=52633 InitPrio=1411 usec=819
[2022-11-12T16:23:15.306] sched/backfill: _start_job: Started JobId=52633 in cpu-opteron on cpu01
[2022-11-12T17:11:51.096] _slurm_rpc_submit_batch_job: JobId=52634 InitPrio=3024 usec=521
[2022-11-12T17:11:52.004] sched: Allocate JobId=52634 NodeList=cpu01 #CPUs=2 Partition=cpu-opteron
[2022-11-12T17:24:59.371] _slurm_rpc_submit_batch_job: JobId=52635 InitPrio=13024 usec=556
[2022-11-12T17:26:55.365] _slurm_rpc_submit_batch_job: JobId=52636 InitPrio=13024 usec=417
[2022-11-12T17:27:05.368] _slurm_rpc_kill_job: REQUEST_KILL_JOB JobId=52635 uid 548200121
[2022-11-12T17:28:57.192] _slurm_rpc_kill_job: REQUEST_KILL_JOB JobId=52636 uid 548200121
[2022-11-12T17:31:02.173] error: sched: Attempt to modify priority for JobId=52407
[2022-11-12T17:31:02.174] _slurm_rpc_update_job: JobId=52407 uid=548200121: Access/permission denied
[2022-11-12T17:31:14.853] _slurm_rpc_top_job for 52407 Access/permission denied
[2022-11-12T17:32:23.392] error: Security violation, JOB_UPDATE RPC from uid 548200121
[2022-11-12T17:32:23.393] _slurm_rpc_update_job: JobId=52068 uid=548200121: Invalid user id
[2022-11-12T17:33:03.228] error: Security violation, JOB_UPDATE RPC from uid 548200121
[2022-11-12T17:33:03.229] _slurm_rpc_update_job: JobId=52068 uid=548200121: Invalid user id
[2022-11-12T17:36:13.370] error: SECURITY VIOLATION: Attempt to suspend job from user 548200121
[2022-11-12T17:36:13.371] _slurm_rpc_suspend(suspend) for 51834 Access/permission denied
[2022-11-12T17:56:03.835] _job_complete: JobId=52616 WEXITSTATUS 0
[2022-11-12T17:56:03.835] _job_complete: JobId=52616 done
[2022-11-12T17:56:05.128] sched: Allocate JobId=52429 NodeList=cpu05 #CPUs=64 Partition=cpu-opteron
[2022-11-12T18:33:25.404] _slurm_rpc_submit_batch_job: JobId=52637 InitPrio=3830 usec=1020
[2022-11-12T18:33:25.928] sched: Allocate JobId=52637 NodeList=cpu13 #CPUs=12 Partition=cpu-epyc
[2022-11-12T18:33:27.748] _job_complete: JobId=52637 WEXITSTATUS 1
[2022-11-12T18:33:27.748] _job_complete: JobId=52637 done
[2022-11-12T18:38:06.449] _slurm_rpc_submit_batch_job: JobId=52638 InitPrio=5443 usec=541
[2022-11-12T18:38:56.665] _job_complete: JobId=52230 WEXITSTATUS 0
[2022-11-12T18:38:56.665] _job_complete: JobId=52230 done
[2022-11-12T18:38:57.351] sched: Allocate JobId=52430 NodeList=cpu09 #CPUs=64 Partition=cpu-opteron
[2022-11-12T18:38:58.519] _slurm_rpc_submit_batch_job: JobId=52639 InitPrio=3830 usec=493
[2022-11-12T18:38:59.410] sched: Allocate JobId=52639 NodeList=cpu10 #CPUs=16 Partition=cpu-opteron
[2022-11-12T18:44:07.514] _slurm_rpc_kill_job: REQUEST_KILL_JOB JobId=52639 uid 548300630
[2022-11-12T18:44:35.603] _slurm_rpc_submit_batch_job: JobId=52640 InitPrio=3830 usec=519
[2022-11-12T18:44:35.970] sched: Allocate JobId=52640 NodeList=cpu10 #CPUs=16 Partition=cpu-opteron
[2022-11-12T19:07:58.549] _slurm_rpc_submit_batch_job: JobId=52641 InitPrio=3830 usec=582
[2022-11-12T19:26:53.694] _job_complete: JobId=52633 WEXITSTATUS 0
[2022-11-12T19:26:53.700] _job_complete: JobId=52633 done
[2022-11-12T19:26:57.915] sched: Allocate JobId=52641 NodeList=cpu01 #CPUs=16 Partition=cpu-opteron
[2022-11-12T19:58:18.823] _job_complete: JobId=52641 WEXITSTATUS 1
[2022-11-12T19:58:18.823] _job_complete: JobId=52641 done
[2022-11-12T23:24:46.661] _slurm_rpc_submit_batch_job: JobId=52642 InitPrio=1411 usec=483
[2022-11-12T23:25:15.954] sched/backfill: _start_job: Started JobId=52642 in cpu-opteron on cpu01
[2022-11-13T01:20:04.897] _slurm_rpc_kill_job: REQUEST_KILL_JOB JobId=52642 uid 548300593
[2022-11-13T01:20:09.345] _slurm_rpc_submit_batch_job: JobId=52643 InitPrio=1411 usec=579
[2022-11-13T01:20:16.138] sched/backfill: _start_job: Started JobId=52643 in cpu-opteron on cpu01
[2022-11-13T01:58:41.881] _job_complete: JobId=52229 WEXITSTATUS 0
[2022-11-13T01:58:41.881] _job_complete: JobId=52229 done
[2022-11-13T02:40:47.601] _slurm_rpc_submit_batch_job: JobId=52644 InitPrio=1612 usec=1000
[2022-11-13T02:44:21.243] _slurm_rpc_submit_batch_job: JobId=52645 InitPrio=1612 usec=555
[2022-11-13T02:45:16.278] sched/backfill: _start_job: Started JobId=52645 in cpu-opteron on cpu01
[2022-11-13T02:46:08.420] _job_complete: JobId=52645 WEXITSTATUS 0
[2022-11-13T02:46:08.420] _job_complete: JobId=52645 done
[2022-11-13T02:55:45.611] _job_complete: JobId=52634 WEXITSTATUS 3
[2022-11-13T02:55:45.617] _job_complete: JobId=52634 done
[2022-11-13T02:58:50.357] _slurm_rpc_submit_batch_job: JobId=52646 InitPrio=1612 usec=464
[2022-11-13T02:59:16.301] sched/backfill: _start_job: Started JobId=52646 in cpu-opteron on cpu10
[2022-11-13T02:59:20.926] _job_complete: JobId=52646 WEXITSTATUS 0
[2022-11-13T02:59:20.926] _job_complete: JobId=52646 done
[2022-11-13T02:59:58.997] _slurm_rpc_submit_batch_job: JobId=52647 InitPrio=1612 usec=420
[2022-11-13T03:00:16.305] sched/backfill: _start_job: Started JobId=52647 in cpu-opteron on cpu10
[2022-11-13T03:00:18.754] _job_complete: JobId=52647 WEXITSTATUS 1
[2022-11-13T03:00:18.755] _job_complete: JobId=52647 done
[2022-11-13T03:00:50.625] _slurm_rpc_submit_batch_job: JobId=52648 InitPrio=1612 usec=483
[2022-11-13T03:01:00.033] _slurm_rpc_submit_batch_job: JobId=52649 InitPrio=1612 usec=378
[2022-11-13T03:01:16.307] sched/backfill: _start_job: Started JobId=52648 in cpu-opteron on cpu10
[2022-11-13T03:01:19.633] _job_complete: JobId=52648 WEXITSTATUS 0
[2022-11-13T03:01:19.634] _job_complete: JobId=52648 done
[2022-11-13T03:02:16.311] sched/backfill: _start_job: Started JobId=52649 in cpu-opteron on cpu10
[2022-11-13T03:02:20.884] _job_complete: JobId=52649 WEXITSTATUS 1
[2022-11-13T03:02:20.885] _job_complete: JobId=52649 done
[2022-11-13T03:34:32.171] _slurm_rpc_submit_batch_job: JobId=52650 InitPrio=1612 usec=609
[2022-11-13T03:35:16.363] sched/backfill: _start_job: Started JobId=52650 in cpu-opteron on cpu10
[2022-11-13T03:35:36.843] _job_complete: JobId=52650 WEXITSTATUS 1
[2022-11-13T03:35:36.843] _job_complete: JobId=52650 done
[2022-11-13T04:04:14.661] _slurm_rpc_submit_batch_job: JobId=52651 InitPrio=1612 usec=507
[2022-11-13T04:04:16.409] sched/backfill: _start_job: Started JobId=52651 in cpu-opteron on cpu10
[2022-11-13T04:04:18.868] _job_complete: JobId=52651 WEXITSTATUS 1
[2022-11-13T04:04:18.868] _job_complete: JobId=52651 done
[2022-11-13T04:05:14.827] _slurm_rpc_submit_batch_job: JobId=52652 InitPrio=1612 usec=486
[2022-11-13T04:05:16.412] sched/backfill: _start_job: Started JobId=52652 in cpu-opteron on cpu10
[2022-11-13T04:05:36.564] _job_complete: JobId=52652 WEXITSTATUS 0
[2022-11-13T04:05:36.564] _job_complete: JobId=52652 done
[2022-11-13T04:07:56.747] _slurm_rpc_submit_batch_job: JobId=52653 InitPrio=1612 usec=468
[2022-11-13T04:08:16.418] sched/backfill: _start_job: Started JobId=52653 in cpu-opteron on cpu10
[2022-11-13T04:08:34.719] _job_complete: JobId=52653 WEXITSTATUS 1
[2022-11-13T04:08:34.719] _job_complete: JobId=52653 done
[2022-11-13T07:13:08.703] _job_complete: JobId=52231 WEXITSTATUS 0
[2022-11-13T07:13:08.704] _job_complete: JobId=52231 done
[2022-11-13T07:38:42.086] _job_complete: JobId=52241 WEXITSTATUS 0
[2022-11-13T07:38:42.086] _job_complete: JobId=52241 done
[2022-11-13T09:40:35.641] Time limit exhausted for JobId=52167
[2022-11-13T09:42:35.918] Time limit exhausted for JobId=52168
[2022-11-13T10:23:27.273] _slurm_rpc_submit_batch_job: JobId=52654 InitPrio=604 usec=539
[2022-11-13T10:55:34.810] _job_complete: JobId=52631 WEXITSTATUS 0
[2022-11-13T10:55:34.810] _job_complete: JobId=52631 done
[2022-11-13T10:56:10.688] _slurm_rpc_kill_job: REQUEST_KILL_JOB JobId=52643 uid 548300593
[2022-11-13T10:56:17.373] _slurm_rpc_submit_batch_job: JobId=52655 InitPrio=1209 usec=453
[2022-11-13T10:57:17.024] sched/backfill: _start_job: Started JobId=52655 in cpu-opteron on cpu01
[2022-11-13T11:17:02.604] _slurm_rpc_kill_job: REQUEST_KILL_JOB JobId=52655 uid 548300593
[2022-11-13T11:17:07.162] _slurm_rpc_submit_batch_job: JobId=52656 InitPrio=1209 usec=562
[2022-11-13T11:17:17.057] sched/backfill: _start_job: Started JobId=52656 in cpu-opteron on cpu01
[2022-11-13T11:54:51.554] _slurm_rpc_kill_job: REQUEST_KILL_JOB JobId=52656 uid 548300593
[2022-11-13T11:55:00.974] _slurm_rpc_submit_batch_job: JobId=52657 InitPrio=1209 usec=554
[2022-11-13T11:55:17.110] sched/backfill: _start_job: Started JobId=52657 in cpu-opteron on cpu01
[2022-11-13T11:56:02.251] _job_complete: JobId=52232 WEXITSTATUS 0
[2022-11-13T11:56:02.251] _job_complete: JobId=52232 done
[2022-11-13T12:30:01.040] _slurm_rpc_kill_job: REQUEST_KILL_JOB JobId=52657 uid 548300593
[2022-11-13T12:30:05.253] _slurm_rpc_submit_batch_job: JobId=52658 InitPrio=1209 usec=514
[2022-11-13T12:30:17.172] sched/backfill: _start_job: Started JobId=52658 in cpu-opteron on cpu10
[2022-11-13T13:05:52.321] _pick_best_nodes: JobId=52659 never runnable in partition cpu-epyc
[2022-11-13T13:05:52.322] _slurm_rpc_submit_batch_job: Requested node configuration is not available
[2022-11-13T13:06:20.959] _slurm_rpc_submit_batch_job: JobId=52660 InitPrio=13024 usec=423
[2022-11-13T13:06:22.148] sched: Allocate JobId=52660 NodeList=cpu13 #CPUs=2 Partition=cpu-epyc
[2022-11-13T13:10:09.971] _slurm_rpc_kill_job: REQUEST_KILL_JOB JobId=52660 uid 548200121
[2022-11-13T13:13:22.355] _slurm_rpc_submit_batch_job: JobId=52661 InitPrio=3225 usec=661
[2022-11-13T13:14:36.284] _slurm_rpc_submit_batch_job: JobId=52662 InitPrio=3225 usec=1011
[2022-11-13T13:14:56.641] _slurm_rpc_kill_job: REQUEST_KILL_JOB JobId=52661 uid 548300630
[2022-11-13T13:15:17.247] sched/backfill: _start_job: Started JobId=52662 in cpu-opteron on cpu01
[2022-11-13T13:18:15.840] _slurm_rpc_submit_batch_job: JobId=52663 InitPrio=3225 usec=645
[2022-11-13T13:26:27.233] _slurm_rpc_submit_batch_job: JobId=52664 InitPrio=3225 usec=548
[2022-11-13T13:26:44.903] _slurm_rpc_submit_batch_job: JobId=52665 InitPrio=3225 usec=509
[2022-11-13T15:49:46.859] _job_complete: JobId=52618 WEXITSTATUS 0
[2022-11-13T15:49:46.859] _job_complete: JobId=52618 done
[2022-11-13T15:49:47.446] sched: Allocate JobId=52414 NodeList=cpu15 #CPUs=48 Partition=cpu-epyc
[2022-11-13T15:53:19.347] _slurm_rpc_submit_batch_job: JobId=52666 InitPrio=3225 usec=706
[2022-11-13T15:53:43.311] _slurm_rpc_kill_job: REQUEST_KILL_JOB JobId=52666 uid 548300630
[2022-11-13T15:54:07.419] _slurm_rpc_submit_batch_job: JobId=52667 InitPrio=3225 usec=520
[2022-11-13T15:55:07.103] _slurm_rpc_kill_job: REQUEST_KILL_JOB JobId=52667 uid 548300630
[2022-11-13T16:26:03.098] _job_complete: JobId=52640 WEXITSTATUS 0
[2022-11-13T16:26:03.098] _job_complete: JobId=52640 done
[2022-11-13T16:26:17.570] sched/backfill: _start_job: Started JobId=52663 in cpu-opteron on cpu10
[2022-11-13T16:26:21.149] _job_complete: JobId=52663 WEXITSTATUS 1
[2022-11-13T16:26:21.149] _job_complete: JobId=52663 done
[2022-11-13T16:27:17.573] sched/backfill: _start_job: Started JobId=52664 in cpu-opteron on cpu10
[2022-11-13T17:18:24.065] _slurm_rpc_submit_batch_job: JobId=52668 InitPrio=3225 usec=612
[2022-11-13T17:20:17.925] _slurm_rpc_kill_job: REQUEST_KILL_JOB JobId=52668 uid 548300630
[2022-11-13T17:20:23.324] _slurm_rpc_submit_batch_job: JobId=52669 InitPrio=3225 usec=458
[2022-11-13T17:59:03.800] _job_complete: JobId=52309 WEXITSTATUS 1
[2022-11-13T17:59:03.805] _job_complete: JobId=52309 done
[2022-11-13T17:59:04.999] sched: Allocate JobId=52411 NodeList=gpu02 #CPUs=4 Partition=gpu-titan
[2022-11-13T18:14:36.100] Time limit exhausted for JobId=52154
[2022-11-13T18:14:36.107] Time limit exhausted for JobId=52155
[2022-11-13T18:14:41.620] sched: Allocate JobId=52431 NodeList=cpu08 #CPUs=64 Partition=cpu-opteron
[2022-11-13T18:15:07.357] sched: Allocate JobId=52665 NodeList=cpu07 #CPUs=16 Partition=cpu-opteron
[2022-11-13T18:15:07.357] sched: Allocate JobId=52669 NodeList=cpu07 #CPUs=16 Partition=cpu-opteron
[2022-11-13T19:31:48.439] _job_complete: JobId=52414 WEXITSTATUS 0
[2022-11-13T19:31:48.439] _job_complete: JobId=52414 done
[2022-11-13T19:31:49.132] sched: Allocate JobId=52421 NodeList=cpu15 #CPUs=48 Partition=cpu-epyc
[2022-11-13T20:25:27.288] _job_complete: JobId=52421 WEXITSTATUS 0
[2022-11-13T20:25:27.289] _job_complete: JobId=52421 done
[2022-11-13T20:25:27.905] sched: Allocate JobId=52433 NodeList=cpu15 #CPUs=48 Partition=cpu-epyc
[2022-11-13T21:16:09.769] _job_complete: JobId=52433 WEXITSTATUS 1
[2022-11-13T21:16:09.770] _job_complete: JobId=52433 done
[2022-11-13T21:16:10.870] sched: Allocate JobId=52440 NodeList=cpu15 #CPUs=48 Partition=cpu-epyc
[2022-11-13T21:16:17.979] sched/backfill: _start_job: Started JobId=52507 in cpu-epyc on cpu14
[2022-11-13T22:19:56.204] _slurm_rpc_submit_batch_job: JobId=52670 InitPrio=1209 usec=555
[2022-11-13T22:20:02.651] _slurm_rpc_submit_batch_job: JobId=52671 InitPrio=1209 usec=430
[2022-11-13T23:27:25.280] _job_complete: JobId=52665 WEXITSTATUS 1
[2022-11-13T23:27:25.280] _job_complete: JobId=52665 done
[2022-11-13T23:28:18.185] sched/backfill: _start_job: Started JobId=52670 in cpu-opteron on cpu07
[2022-11-13T23:44:35.854] _job_complete: JobId=51834 WEXITSTATUS 0
[2022-11-13T23:44:35.860] _job_complete: JobId=51834 done
[2022-11-13T23:44:40.052] sched: Allocate JobId=52068 NodeList=gpu05 #CPUs=32 Partition=gpu-v100s
[2022-11-14T08:11:02.940] _slurm_rpc_submit_batch_job: JobId=52672 InitPrio=3225 usec=546
[2022-11-14T09:15:45.946] _slurm_rpc_kill_job: REQUEST_KILL_JOB JobId=52411 uid 0
[2022-11-14T10:11:24.637] _job_complete: JobId=52662 WEXITSTATUS 0
[2022-11-14T10:11:24.637] _job_complete: JobId=52662 done
[2022-11-14T10:12:19.071] sched/backfill: _start_job: Started JobId=52672 in cpu-opteron on cpu01
[2022-11-14T10:41:41.510] _slurm_rpc_submit_batch_job: JobId=52673 InitPrio=1612 usec=1241
[2022-11-14T10:45:09.489] _slurm_rpc_submit_batch_job: JobId=52674 InitPrio=1612 usec=812
[2022-11-14T10:45:10.231] sched: Allocate JobId=52674 NodeList=gpu02 #CPUs=8 Partition=gpu-titan
[2022-11-14T10:45:32.445] _slurm_rpc_kill_job: REQUEST_KILL_JOB JobId=52673 uid 548200029
[2022-11-14T10:46:30.640] _slurm_rpc_submit_batch_job: JobId=52675 InitPrio=1612 usec=1060
[2022-11-14T11:02:07.883] _slurm_rpc_submit_batch_job: JobId=52676 InitPrio=2620 usec=550
[2022-11-14T12:17:17.893] _slurm_rpc_submit_batch_job: JobId=52677 InitPrio=2822 usec=535
[2022-11-14T12:17:44.465] _slurm_rpc_kill_job: REQUEST_KILL_JOB JobId=52677 uid 548200121
[2022-11-14T12:18:30.681] _slurm_rpc_submit_batch_job: JobId=52678 InitPrio=2822 usec=424
[2022-11-14T12:20:41.740] _slurm_rpc_submit_batch_job: JobId=52679 InitPrio=2822 usec=431
[2022-11-14T12:21:19.280] sched/backfill: _start_job: Started JobId=52679 in cpu-opteron on cpu07
[2022-11-14T12:25:53.922] _slurm_rpc_kill_job: REQUEST_KILL_JOB JobId=52679 uid 548200121
[2022-11-14T12:25:55.764] sched: _slurm_rpc_allocate_resources JobId=52680 NodeList=(null) usec=814
[2022-11-14T12:25:56.259] sched: Allocate JobId=52680 NodeList=cpu07 #CPUs=1 Partition=cpu-opteron
[2022-11-14T12:26:14.643] _slurm_rpc_submit_batch_job: JobId=52681 InitPrio=12822 usec=432
[2022-11-14T12:26:15.661] sched: Allocate JobId=52681 NodeList=cpu07 #CPUs=4 Partition=cpu-opteron
[2022-11-14T12:40:17.085] _slurm_rpc_kill_job: REQUEST_KILL_JOB JobId=52681 uid 548200121
[2022-11-14T13:17:13.461] _slurm_rpc_submit_batch_job: JobId=52682 InitPrio=1209 usec=596
[2022-11-14T13:17:19.380] sched/backfill: _start_job: Started JobId=52682 in cpu-opteron on cpu07
[2022-11-14T13:18:07.233] _job_complete: JobId=52682 WEXITSTATUS 0
[2022-11-14T13:18:07.234] _job_complete: JobId=52682 done
[2022-11-14T13:20:43.099] _slurm_rpc_kill_job: REQUEST_KILL_JOB JobId=52290 uid 548200023
[2022-11-14T13:20:46.749] _slurm_rpc_kill_job: REQUEST_KILL_JOB JobId=52915 uid 548200023
[2022-11-14T13:20:46.749] job_str_signal(3): invalid JobId=52915
[2022-11-14T13:20:46.749] _slurm_rpc_kill_job: job_str_signal() uid=548200023 JobId=52915 sig=9 returned: Invalid job id specified
[2022-11-14T13:20:56.959] _slurm_rpc_kill_job: REQUEST_KILL_JOB JobId=52195 uid 548200023
[2022-11-14T13:22:48.085] _slurm_rpc_submit_batch_job: JobId=52683 InitPrio=1209 usec=560
[2022-11-14T13:23:19.389] sched/backfill: _start_job: Started JobId=52683 in cpu-opteron on cpu07
[2022-11-14T13:24:06.675] _job_complete: JobId=52683 WEXITSTATUS 0
[2022-11-14T13:24:06.675] _job_complete: JobId=52683 done
[2022-11-14T13:40:14.242] _slurm_rpc_submit_batch_job: JobId=52684 InitPrio=1209 usec=561
[2022-11-14T13:48:43.712] _slurm_rpc_submit_batch_job: JobId=52685 InitPrio=1209 usec=530
[2022-11-14T13:49:19.430] sched/backfill: _start_job: Started JobId=52685 in cpu-opteron on cpu07
[2022-11-14T13:53:34.301] _job_complete: JobId=52685 WEXITSTATUS 0
[2022-11-14T13:53:34.301] _job_complete: JobId=52685 done
[2022-11-14T13:55:40.310] Time limit exhausted for JobId=52207
[2022-11-14T13:55:42.548] sched: Allocate JobId=52278 NodeList=gpu04 #CPUs=16 Partition=gpu-k40c
[2022-11-14T14:50:51.034] _slurm_rpc_submit_batch_job: JobId=52686 InitPrio=806 usec=555
[2022-11-14T14:51:19.533] sched/backfill: _start_job: Started JobId=52686 in cpu-opteron on cpu[10-11]
[2022-11-14T14:51:21.946] _job_complete: JobId=52686 WEXITSTATUS 0
[2022-11-14T14:51:21.946] _job_complete: JobId=52686 done
[2022-11-14T14:52:37.270] _slurm_rpc_submit_batch_job: JobId=52687 InitPrio=806 usec=511
[2022-11-14T14:53:19.537] sched/backfill: _start_job: Started JobId=52687 in cpu-opteron on cpu[10-11]
[2022-11-14T14:54:01.954] _job_complete: JobId=52687 WEXITSTATUS 0
[2022-11-14T14:54:01.954] _job_complete: JobId=52687 done
[2022-11-14T14:54:08.286] _job_complete: JobId=52680 WEXITSTATUS 1
[2022-11-14T14:54:08.286] _job_complete: JobId=52680 done
[2022-11-14T14:56:42.113] _slurm_rpc_submit_batch_job: JobId=52688 InitPrio=806 usec=521
[2022-11-14T14:59:29.420] _slurm_rpc_kill_job: REQUEST_KILL_JOB JobId=52688 uid 548200023
[2022-11-14T14:59:46.972] _slurm_rpc_submit_batch_job: JobId=52689 InitPrio=806 usec=548
[2022-11-14T15:04:19.784] _slurm_rpc_kill_job: REQUEST_KILL_JOB JobId=52402 uid 548200017
[2022-11-14T15:05:19.569] sched/backfill: _start_job: Started JobId=52539 in cpu-epyc on cpu14
[2022-11-14T15:05:19.569] sched/backfill: _start_job: Started JobId=52540 in cpu-epyc on cpu14
[2022-11-14T15:05:19.570] sched/backfill: _start_job: Started JobId=52541 in cpu-epyc on cpu14
[2022-11-14T15:14:01.011] _slurm_rpc_submit_batch_job: JobId=52690 InitPrio=1411 usec=780
[2022-11-14T15:16:49.291] _slurm_rpc_submit_batch_job: JobId=52691 InitPrio=1209 usec=558
[2022-11-14T15:17:19.603] sched/backfill: _start_job: Started JobId=52691 in cpu-opteron on cpu07
[2022-11-14T15:17:21.066] _job_complete: JobId=52691 WEXITSTATUS 1
[2022-11-14T15:17:21.066] _job_complete: JobId=52691 done
[2022-11-14T15:19:46.285] _slurm_rpc_submit_batch_job: JobId=52692 InitPrio=1209 usec=401
[2022-11-14T15:20:19.608] sched/backfill: _start_job: Started JobId=52692 in cpu-opteron on cpu07
[2022-11-14T15:20:27.090] _job_complete: JobId=52692 WEXITSTATUS 0
[2022-11-14T15:20:27.090] _job_complete: JobId=52692 done
[2022-11-14T15:29:27.269] _slurm_rpc_submit_batch_job: JobId=52693 InitPrio=1209 usec=415
[2022-11-14T15:30:19.624] sched/backfill: _start_job: Started JobId=52693 in cpu-opteron on cpu07
[2022-11-14T15:30:27.030] _job_complete: JobId=52693 WEXITSTATUS 0
[2022-11-14T15:30:27.030] _job_complete: JobId=52693 done
[2022-11-14T15:30:58.700] _slurm_rpc_submit_batch_job: JobId=52694 InitPrio=1209 usec=465
[2022-11-14T15:31:19.626] sched/backfill: _start_job: Started JobId=52694 in cpu-opteron on cpu07
[2022-11-14T15:31:20.960] _job_complete: JobId=52694 WEXITSTATUS 1
[2022-11-14T15:31:20.960] _job_complete: JobId=52694 done
[2022-11-14T15:33:46.672] _slurm_rpc_submit_batch_job: JobId=52695 InitPrio=1209 usec=502
[2022-11-14T15:33:54.131] sched: _slurm_rpc_allocate_resources JobId=52696 NodeList=(null) usec=1146
[2022-11-14T15:33:54.391] sched: Allocate JobId=52696 NodeList=cpu07 #CPUs=4 Partition=cpu-opteron
[2022-11-14T15:34:05.473] _job_complete: JobId=52539 WEXITSTATUS 0
[2022-11-14T15:34:05.473] _job_complete: JobId=52539 done
[2022-11-14T15:34:12.390] _job_complete: JobId=52540 WEXITSTATUS 0
[2022-11-14T15:34:12.390] _job_complete: JobId=52540 done
[2022-11-14T15:34:19.377] _job_complete: JobId=52541 WEXITSTATUS 0
[2022-11-14T15:34:19.377] _job_complete: JobId=52541 done
[2022-11-14T15:34:19.631] sched/backfill: _start_job: Started JobId=52695 in cpu-opteron on cpu07
[2022-11-14T15:34:21.474] _job_complete: JobId=52695 WEXITSTATUS 1
[2022-11-14T15:34:21.474] _job_complete: JobId=52695 done
[2022-11-14T15:35:19.633] sched/backfill: _start_job: Started JobId=52542 in cpu-epyc on cpu14
[2022-11-14T15:36:34.832] _slurm_rpc_submit_batch_job: JobId=52697 InitPrio=1209 usec=445
[2022-11-14T15:37:19.637] sched/backfill: _start_job: Started JobId=52697 in cpu-opteron on cpu07
[2022-11-14T15:37:27.043] _job_complete: JobId=52697 WEXITSTATUS 0
[2022-11-14T15:37:27.043] _job_complete: JobId=52697 done
[2022-11-14T15:38:46.322] _slurm_rpc_submit_batch_job: JobId=52698 InitPrio=1411 usec=936
[2022-11-14T15:44:40.230] _job_complete: JobId=52696 WEXITSTATUS 1
[2022-11-14T15:44:40.231] _job_complete: JobId=52696 done
[2022-11-14T15:54:57.327] _slurm_rpc_submit_batch_job: JobId=52699 InitPrio=1209 usec=694
[2022-11-14T15:56:22.188] _slurm_rpc_submit_batch_job: JobId=52700 InitPrio=19879 usec=515
[2022-11-14T15:56:22.748] sched: Allocate JobId=52700 NodeList=cpu07 #CPUs=2 Partition=cpu-opteron
[2022-11-14T15:56:30.363] _slurm_rpc_kill_job: REQUEST_KILL_JOB JobId=52700 uid 548300626
[2022-11-14T16:00:06.766] _slurm_rpc_submit_batch_job: JobId=52701 InitPrio=1209 usec=827
[2022-11-14T16:03:29.039] sched: _slurm_rpc_allocate_resources JobId=52702 NodeList=cpu07 usec=1280
[2022-11-14T16:04:05.737] _job_complete: JobId=52542 WEXITSTATUS 0
[2022-11-14T16:04:05.737] _job_complete: JobId=52542 done
[2022-11-14T16:04:19.696] sched/backfill: _start_job: Started JobId=52585 in cpu-epyc on cpu14
[2022-11-14T16:05:44.488] sched: _slurm_rpc_allocate_resources JobId=52703 NodeList=(null) usec=1257
[2022-11-14T16:08:17.604] sched: _slurm_rpc_allocate_resources JobId=52704 NodeList=(null) usec=716
[2022-11-14T16:23:25.229] sched: _slurm_rpc_allocate_resources JobId=52705 NodeList=(null) usec=1190
[2022-11-14T16:24:15.028] sched: _slurm_rpc_allocate_resources JobId=52706 NodeList=(null) usec=964
[2022-11-14T16:27:09.232] _job_complete: JobId=52706 WTERMSIG 126
[2022-11-14T16:27:09.232] _job_complete: JobId=52706 cancelled by interactive user
[2022-11-14T16:27:09.232] _job_complete: JobId=52706 done
[2022-11-14T16:27:09.232] _job_complete: JobId=52704 WTERMSIG 126
[2022-11-14T16:27:09.232] _job_complete: JobId=52704 cancelled by interactive user
[2022-11-14T16:27:09.233] _job_complete: JobId=52704 done
[2022-11-14T16:27:09.233] _job_complete: JobId=52703 WTERMSIG 126
[2022-11-14T16:27:09.233] _job_complete: JobId=52703 cancelled by interactive user
[2022-11-14T16:27:09.233] _job_complete: JobId=52703 done
[2022-11-14T16:27:09.233] _job_complete: JobId=52702 WEXITSTATUS 1
[2022-11-14T16:27:09.233] _job_complete: JobId=52702 done
[2022-11-14T16:27:09.234] _job_complete: JobId=52705 WTERMSIG 126
[2022-11-14T16:27:09.234] _job_complete: JobId=52705 cancelled by interactive user
[2022-11-14T16:27:09.234] _job_complete: JobId=52705 done
[2022-11-14T16:27:20.399] sched: _slurm_rpc_allocate_resources JobId=52707 NodeList=cpu07 usec=2268
[2022-11-14T16:30:45.694] _job_complete: JobId=52707 WEXITSTATUS 2
[2022-11-14T16:30:45.694] _job_complete: JobId=52707 done
[2022-11-14T16:30:50.068] sched: _slurm_rpc_allocate_resources JobId=52708 NodeList=cpu07 usec=973
[2022-11-14T16:31:58.187] _job_complete: JobId=52708 WEXITSTATUS 2
[2022-11-14T16:31:58.187] _job_complete: JobId=52708 done
[2022-11-14T17:35:50.339] sched: _slurm_rpc_allocate_resources JobId=52709 NodeList=cpu12 usec=21160
[2022-11-14T17:39:58.109] _job_complete: JobId=52709 WEXITSTATUS 0
[2022-11-14T17:39:58.110] _job_complete: JobId=52709 done
[2022-11-14T17:42:52.645] _slurm_rpc_submit_batch_job: JobId=52710 InitPrio=14233 usec=583
[2022-11-14T17:42:53.376] sched: Allocate JobId=52710 NodeList=cpu12 #CPUs=24 Partition=cpu-epyc
[2022-11-14T17:43:09.763] _job_complete: JobId=52710 WEXITSTATUS 0
[2022-11-14T17:43:09.763] _job_complete: JobId=52710 done
[2022-11-14T17:51:19.968] _job_complete: JobId=52672 WEXITSTATUS 1
[2022-11-14T17:51:19.968] _job_complete: JobId=52672 done
[2022-11-14T17:51:58.851] _job_complete: JobId=52625 WEXITSTATUS 0
[2022-11-14T17:51:58.856] _job_complete: JobId=52625 done
[2022-11-14T17:52:08.134] sched: Allocate JobId=52536 NodeList=cpu11 #CPUs=64 Partition=cpu-opteron
[2022-11-14T17:52:08.149] sched: Allocate JobId=52671 NodeList=cpu01 #CPUs=32 Partition=cpu-opteron
[2022-11-14T17:52:12.492] _job_complete: JobId=52536 WEXITSTATUS 1
[2022-11-14T17:52:12.493] _job_complete: JobId=52536 done
[2022-11-14T17:52:13.212] sched: Allocate JobId=52690 NodeList=cpu11 #CPUs=32 Partition=cpu-opteron
[2022-11-14T18:04:03.748] _slurm_rpc_delete_reservation complete for ceph_cbt_test usec=61
[2022-11-14T18:04:04.612] sched: Allocate JobId=52532 NodeList=cpu12 #CPUs=48 Partition=cpu-epyc
[2022-11-14T18:04:04.625] sched: Allocate JobId=52676 NodeList=cpu13 #CPUs=16 Partition=cpu-epyc
[2022-11-14T18:38:07.672] _slurm_rpc_submit_batch_job: JobId=52711 InitPrio=604 usec=525
[2022-11-14T19:21:18.246] _slurm_rpc_submit_batch_job: JobId=52712 InitPrio=2822 usec=692
[2022-11-14T19:21:38.343] _slurm_rpc_kill_job: REQUEST_KILL_JOB JobId=52712 uid 548300630
[2022-11-14T19:22:02.126] _slurm_rpc_submit_batch_job: JobId=52713 InitPrio=2822 usec=495
[2022-11-14T19:27:23.649] _slurm_rpc_kill_job: REQUEST_KILL_JOB JobId=52713 uid 548300630
[2022-11-14T19:27:30.147] _slurm_rpc_submit_batch_job: JobId=52714 InitPrio=2822 usec=553
[2022-11-14T19:36:33.054] _job_complete: JobId=52532 WEXITSTATUS 139
[2022-11-14T19:36:33.059] _job_complete: JobId=52532 done
[2022-11-14T19:36:35.695] sched: Allocate JobId=52714 NodeList=cpu12 #CPUs=24 Partition=cpu-epyc
[2022-11-14T19:36:35.712] sched: Allocate JobId=52654 NodeList=cpu12 #CPUs=24 Partition=cpu-epyc
[2022-11-14T19:37:34.807] sched: _slurm_rpc_allocate_resources JobId=52715 NodeList=(null) usec=916
[2022-11-14T19:37:35.299] sched: Allocate JobId=52715 NodeList=cpu07 #CPUs=1 Partition=cpu-opteron
[2022-11-14T19:44:19.523] _slurm_rpc_submit_batch_job: JobId=52716 InitPrio=18467 usec=562
[2022-11-14T19:44:19.909] sched: Allocate JobId=52716 NodeList=cpu01 #CPUs=16 Partition=cpu-opteron
[2022-11-14T19:45:39.537] _job_complete: JobId=52716 WEXITSTATUS 0
[2022-11-14T19:45:39.537] _job_complete: JobId=52716 done
[2022-11-14T19:49:05.087] _job_complete: JobId=52715 WEXITSTATUS 0
[2022-11-14T19:49:05.087] _job_complete: JobId=52715 done
[2022-11-14T20:11:20.496] sched: _slurm_rpc_allocate_resources JobId=52717 NodeList=cpu07 usec=16192
[2022-11-14T20:11:42.826] _slurm_rpc_submit_batch_job: JobId=52718 InitPrio=2822 usec=520
[2022-11-14T20:12:25.298] _slurm_rpc_kill_job: REQUEST_KILL_JOB JobId=52718 uid 548300630
[2022-11-14T20:12:32.352] _slurm_rpc_submit_batch_job: JobId=52719 InitPrio=2822 usec=491
[2022-11-14T20:14:36.656] _job_complete: JobId=52717 WEXITSTATUS 255
[2022-11-14T20:14:36.656] _job_complete: JobId=52717 done
[2022-11-14T20:14:42.529] sched: _slurm_rpc_allocate_resources JobId=52720 NodeList=cpu07 usec=1613
[2022-11-14T20:25:55.361] _job_complete: JobId=52720 WEXITSTATUS 0
[2022-11-14T20:25:55.362] _job_complete: JobId=52720 done
[2022-11-14T20:26:21.315] sched: _slurm_rpc_allocate_resources JobId=52721 NodeList=cpu07 usec=2437
[2022-11-14T20:26:21.807] _job_complete: JobId=52721 WEXITSTATUS 13
[2022-11-14T20:26:21.807] _job_complete: JobId=52721 done
[2022-11-14T20:29:49.293] error: This association 242(account='free', user='htt_felicia', partition='(null)') does not have access to qos normal
[2022-11-14T20:29:49.293] _slurm_rpc_submit_batch_job: Invalid qos specification
[2022-11-14T21:02:31.423] error: This association 242(account='free', user='htt_felicia', partition='(null)') does not have access to qos normal
[2022-11-14T21:02:31.423] _slurm_rpc_submit_batch_job: Invalid qos specification
[2022-11-14T21:58:12.986] _job_complete: JobId=52690 WEXITSTATUS 0
[2022-11-14T21:58:12.992] _job_complete: JobId=52690 done
[2022-11-14T21:58:17.282] sched: Allocate JobId=52698 NodeList=cpu11 #CPUs=32 Partition=cpu-opteron
[2022-11-14T21:58:23.424] _job_complete: JobId=52698 WEXITSTATUS 0
[2022-11-14T21:58:23.425] _job_complete: JobId=52698 done
[2022-11-14T21:58:24.193] sched: Allocate JobId=52711 NodeList=cpu11 #CPUs=64 Partition=cpu-opteron
[2022-11-14T21:58:27.825] _job_complete: JobId=52711 WEXITSTATUS 1
[2022-11-14T21:58:27.825] _job_complete: JobId=52711 done
[2022-11-14T23:40:56.079] _job_complete: JobId=52676 OOM failure
[2022-11-14T23:40:56.080] _job_complete: JobId=52676 done
[2022-11-14T23:40:56.767] sched: Allocate JobId=52719 NodeList=cpu13 #CPUs=24 Partition=cpu-epyc
[2022-11-15T00:51:57.215] _job_complete: JobId=52669 WEXITSTATUS 0
[2022-11-15T00:51:57.215] _job_complete: JobId=52669 done
[2022-11-15T08:17:54.225] _slurm_rpc_submit_batch_job: JobId=52722 InitPrio=604 usec=562
[2022-11-15T08:17:54.813] sched: Allocate JobId=52722 NodeList=cpu11 #CPUs=64 Partition=cpu-opteron
[2022-11-15T08:37:34.205] _job_complete: JobId=52308 WEXITSTATUS 0
[2022-11-15T08:37:34.211] _job_complete: JobId=52308 done
[2022-11-15T08:37:36.446] sched: Allocate JobId=52678 NodeList=gpu02 #CPUs=4 Partition=gpu-titan
[2022-11-15T09:11:22.363] _slurm_rpc_submit_batch_job: JobId=52723 InitPrio=1411 usec=695
[2022-11-15T09:11:31.189] _slurm_rpc_submit_batch_job: JobId=52724 InitPrio=1411 usec=693
[2022-11-15T09:11:59.998] _slurm_rpc_submit_batch_job: JobId=52725 InitPrio=1411 usec=765
[2022-11-15T11:23:37.086] _slurm_rpc_submit_batch_job: JobId=52726 InitPrio=806 usec=693
[2022-11-15T11:24:25.203] _slurm_rpc_submit_batch_job: JobId=52727 InitPrio=806 usec=578
[2022-11-15T11:40:06.595] _slurm_rpc_submit_batch_job: JobId=52728 InitPrio=9274 usec=825
[2022-11-15T11:40:22.785] _slurm_rpc_kill_job: REQUEST_KILL_JOB JobId=52728 uid 548300626
[2022-11-15T11:42:07.639] sched: _slurm_rpc_allocate_resources JobId=52729 NodeList=(null) usec=764
[2022-11-15T11:42:08.196] sched: Allocate JobId=52729 NodeList=cpu10 #CPUs=1 Partition=cpu-opteron
[2022-11-15T11:44:42.645] _job_complete: JobId=52729 WEXITSTATUS 0
[2022-11-15T11:44:42.645] _job_complete: JobId=52729 done
[2022-11-15T11:44:50.399] _slurm_rpc_submit_batch_job: JobId=52730 InitPrio=9274 usec=503
[2022-11-15T11:47:19.479] sched: _slurm_rpc_allocate_resources JobId=52731 NodeList=(null) usec=794
[2022-11-15T11:47:21.014] sched/backfill: _start_job: Started JobId=52731 in cpu-opteron on cpu10
[2022-11-15T11:49:00.545] _job_complete: JobId=52731 WEXITSTATUS 0
[2022-11-15T11:49:00.545] _job_complete: JobId=52731 done
[2022-11-15T14:23:15.706] Time limit exhausted for JobId=52306
[2022-11-15T14:23:22.087] sched: Allocate JobId=52311 NodeList=gpu01 #CPUs=16 Partition=gpu-k10
[2022-11-15T14:42:35.124] _slurm_rpc_submit_batch_job: JobId=52732 InitPrio=2620 usec=584
[2022-11-15T14:43:21.314] sched/backfill: _start_job: Started JobId=52732 in cpu-opteron on cpu07
[2022-11-15T14:43:26.777] _job_complete: JobId=52732 WEXITSTATUS 1
[2022-11-15T14:43:26.777] _job_complete: JobId=52732 done
[2022-11-15T14:46:13.062] _slurm_rpc_submit_batch_job: JobId=52733 InitPrio=2620 usec=597
[2022-11-15T14:46:21.320] sched/backfill: _start_job: Started JobId=52733 in cpu-opteron on cpu07
[2022-11-15T14:49:40.730] _job_complete: JobId=52733 WEXITSTATUS 1
[2022-11-15T14:49:40.730] _job_complete: JobId=52733 done
[2022-11-15T15:41:20.329] _slurm_rpc_submit_batch_job: JobId=52734 InitPrio=1209 usec=548
[2022-11-15T15:41:23.339] _slurm_rpc_submit_batch_job: JobId=52735 InitPrio=1209 usec=472
[2022-11-15T15:41:25.914] _slurm_rpc_submit_batch_job: JobId=52736 InitPrio=1209 usec=500
[2022-11-15T15:41:28.537] _slurm_rpc_submit_batch_job: JobId=52737 InitPrio=1209 usec=542
[2022-11-15T16:03:39.560] _slurm_rpc_submit_batch_job: JobId=52738 InitPrio=1008 usec=675
[2022-11-15T16:04:21.470] sched/backfill: _start_job: Started JobId=52738 in cpu-opteron on cpu[07,10]
[2022-11-15T16:04:22.954] _job_complete: JobId=52738 WEXITSTATUS 0
[2022-11-15T16:04:22.954] _job_complete: JobId=52738 done
[2022-11-15T16:19:43.764] _slurm_rpc_submit_batch_job: JobId=52739 InitPrio=1008 usec=546
[2022-11-15T16:20:21.500] sched/backfill: _start_job: Started JobId=52739 in cpu-opteron on cpu[07,10]
[2022-11-15T16:20:22.831] _job_complete: JobId=52739 WEXITSTATUS 0
[2022-11-15T16:20:22.831] _job_complete: JobId=52739 done
[2022-11-15T16:20:38.282] _slurm_rpc_submit_batch_job: JobId=52740 InitPrio=1008 usec=489
[2022-11-15T16:21:21.503] sched/backfill: _start_job: Started JobId=52740 in cpu-opteron on cpu[07,10]
[2022-11-15T16:21:27.240] _slurm_rpc_submit_batch_job: JobId=52741 InitPrio=1008 usec=488
[2022-11-15T16:21:37.190] _job_complete: JobId=52740 WEXITSTATUS 0
[2022-11-15T16:21:37.191] _job_complete: JobId=52740 done
[2022-11-15T16:22:21.506] sched/backfill: _start_job: Started JobId=52741 in cpu-opteron on cpu[07,10]
[2022-11-15T16:22:37.163] _job_complete: JobId=52741 WEXITSTATUS 0
[2022-11-15T16:22:37.164] _job_complete: JobId=52741 done
[2022-11-15T16:53:09.756] _slurm_rpc_submit_batch_job: JobId=52742 InitPrio=1008 usec=552
[2022-11-15T16:53:21.564] sched/backfill: _start_job: Started JobId=52742 in gpu-titan on gpu02
[2022-11-15T16:53:42.472] _job_complete: JobId=52742 WEXITSTATUS 0
[2022-11-15T16:53:42.472] _job_complete: JobId=52742 done
[2022-11-15T17:11:53.303] _slurm_rpc_kill_job: REQUEST_KILL_JOB JobId=52427 uid 548300621
[2022-11-15T17:11:54.158] _slurm_rpc_kill_job: REQUEST_KILL_JOB JobId=52427 uid 548300621
[2022-11-15T17:11:56.439] _slurm_rpc_kill_job: REQUEST_KILL_JOB JobId=52428 uid 548300621
[2022-11-15T17:11:57.848] _slurm_rpc_kill_job: REQUEST_KILL_JOB JobId=52428 uid 548300621
[2022-11-15T17:11:59.696] sched: Allocate JobId=52730 NodeList=cpu03 #CPUs=64 Partition=cpu-opteron
[2022-11-15T17:12:00.742] _slurm_rpc_kill_job: REQUEST_KILL_JOB JobId=52429 uid 548300621
[2022-11-15T17:12:01.614] _slurm_rpc_kill_job: REQUEST_KILL_JOB JobId=52429 uid 548300621
[2022-11-15T17:12:04.683] sched: Allocate JobId=52723 NodeList=cpu04 #CPUs=32 Partition=cpu-opteron
[2022-11-15T17:12:05.423] _slurm_rpc_kill_job: REQUEST_KILL_JOB JobId=52430 uid 548300621
[2022-11-15T17:12:07.012] sched: Allocate JobId=52724 NodeList=cpu05 #CPUs=32 Partition=cpu-opteron
[2022-11-15T17:12:07.455] _slurm_rpc_kill_job: REQUEST_KILL_JOB JobId=52430 uid 548300621
[2022-11-15T17:12:09.489] _job_complete: JobId=52730 WEXITSTATUS 137
[2022-11-15T17:12:09.489] _job_complete: JobId=52730 done
[2022-11-15T17:12:10.210] sched: Allocate JobId=52725 NodeList=cpu03 #CPUs=32 Partition=cpu-opteron
[2022-11-15T17:12:10.281] _slurm_rpc_kill_job: REQUEST_KILL_JOB JobId=52431 uid 548300621
[2022-11-15T17:12:11.191] _slurm_rpc_kill_job: REQUEST_KILL_JOB JobId=52431 uid 548300621
[2022-11-15T17:12:15.584] _job_complete: JobId=52724 WEXITSTATUS 0
[2022-11-15T17:12:15.585] _job_complete: JobId=52724 done
[2022-11-15T17:20:21.107] _slurm_rpc_submit_batch_job: JobId=52743 InitPrio=2822 usec=484
[2022-11-15T17:20:44.483] _slurm_rpc_submit_batch_job: JobId=52744 InitPrio=201 usec=543
[2022-11-15T17:20:45.423] sched: Allocate JobId=52744 NodeList=cpu05 #CPUs=64 Partition=cpu-opteron
[2022-11-15T17:20:52.338] _slurm_rpc_submit_batch_job: JobId=52745 InitPrio=201 usec=498
[2022-11-15T17:20:52.418] sched: Allocate JobId=52745 NodeList=cpu08 #CPUs=64 Partition=cpu-opteron
[2022-11-15T17:20:54.962] _slurm_rpc_submit_batch_job: JobId=52746 InitPrio=201 usec=675
[2022-11-15T17:20:55.421] sched: Allocate JobId=52746 NodeList=cpu09 #CPUs=64 Partition=cpu-opteron
[2022-11-15T17:20:55.679] _job_complete: JobId=52744 WEXITSTATUS 1
[2022-11-15T17:20:55.679] _job_complete: JobId=52744 done
[2022-11-15T17:20:58.770] _slurm_rpc_submit_batch_job: JobId=52747 InitPrio=201 usec=504
[2022-11-15T17:20:59.427] sched: Allocate JobId=52747 NodeList=cpu05 #CPUs=64 Partition=cpu-opteron
[2022-11-15T17:21:00.271] _job_complete: JobId=52747 WEXITSTATUS 1
[2022-11-15T17:21:00.271] _job_complete: JobId=52747 done
[2022-11-15T17:21:00.901] _slurm_rpc_submit_batch_job: JobId=52748 InitPrio=201 usec=606
[2022-11-15T17:21:00.913] sched: Allocate JobId=52748 NodeList=cpu05 #CPUs=64 Partition=cpu-opteron
[2022-11-15T17:21:03.251] _job_complete: JobId=52745 WEXITSTATUS 1
[2022-11-15T17:21:03.251] _job_complete: JobId=52745 done
[2022-11-15T17:21:04.438] _slurm_rpc_submit_batch_job: JobId=52749 InitPrio=201 usec=513
[2022-11-15T17:21:05.435] sched: Allocate JobId=52749 NodeList=cpu08 #CPUs=64 Partition=cpu-opteron
[2022-11-15T17:21:06.314] _job_complete: JobId=52749 WEXITSTATUS 1
[2022-11-15T17:21:06.315] _job_complete: JobId=52749 done
[2022-11-15T17:21:07.747] _slurm_rpc_submit_batch_job: JobId=52750 InitPrio=201 usec=494
[2022-11-15T17:21:08.442] sched: Allocate JobId=52750 NodeList=cpu08 #CPUs=64 Partition=cpu-opteron
[2022-11-15T17:21:10.794] _slurm_rpc_submit_batch_job: JobId=52751 InitPrio=201 usec=578
[2022-11-15T17:21:17.834] _slurm_rpc_submit_batch_job: JobId=52752 InitPrio=201 usec=537
[2022-11-15T17:21:20.483] _slurm_rpc_submit_batch_job: JobId=52753 InitPrio=201 usec=525
[2022-11-15T17:22:52.638] _slurm_rpc_kill_job: REQUEST_KILL_JOB JobId=52751 uid 548300621
[2022-11-15T17:22:58.427] _slurm_rpc_kill_job: REQUEST_KILL_JOB JobId=52753 uid 548300621
[2022-11-15T17:23:06.156] _slurm_rpc_kill_job: REQUEST_KILL_JOB JobId=52750 uid 548300621
[2022-11-15T17:23:08.375] sched: Allocate JobId=52752 NodeList=cpu08 #CPUs=64 Partition=cpu-opteron
[2022-11-15T17:23:12.028] _slurm_rpc_kill_job: REQUEST_KILL_JOB JobId=52748 uid 548300621
[2022-11-15T17:23:16.452] _slurm_rpc_kill_job: REQUEST_KILL_JOB JobId=52746 uid 548300621
[2022-11-15T17:23:26.692] _slurm_rpc_kill_job: REQUEST_KILL_JOB JobId=52752 uid 548300621
[2022-11-15T17:23:28.419] _slurm_rpc_kill_job: REQUEST_KILL_JOB JobId=52752 uid 548300621
[2022-11-15T17:23:48.919] _slurm_rpc_submit_batch_job: JobId=52754 InitPrio=201 usec=548
[2022-11-15T17:23:49.716] sched: Allocate JobId=52754 NodeList=cpu05 #CPUs=64 Partition=cpu-opteron
[2022-11-15T17:23:58.256] _slurm_rpc_submit_batch_job: JobId=52755 InitPrio=201 usec=450
[2022-11-15T17:23:58.729] sched: Allocate JobId=52755 NodeList=cpu08 #CPUs=64 Partition=cpu-opteron
[2022-11-15T17:23:59.362] _job_complete: JobId=52754 WEXITSTATUS 1
[2022-11-15T17:23:59.362] _job_complete: JobId=52754 done
[2022-11-15T17:24:08.847] _job_complete: JobId=52755 WEXITSTATUS 1
[2022-11-15T17:24:08.847] _job_complete: JobId=52755 done
[2022-11-15T17:24:43.931] _slurm_rpc_kill_job: REQUEST_KILL_JOB JobId=52755 uid 548300621
[2022-11-15T17:28:37.630] _slurm_rpc_submit_batch_job: JobId=52756 InitPrio=201 usec=524
[2022-11-15T17:28:38.293] sched: Allocate JobId=52756 NodeList=cpu05 #CPUs=64 Partition=cpu-opteron
[2022-11-15T17:28:48.537] _job_complete: JobId=52756 WEXITSTATUS 1
[2022-11-15T17:28:48.537] _job_complete: JobId=52756 done
[2022-11-15T17:34:57.358] _slurm_rpc_submit_batch_job: JobId=52757 InitPrio=201 usec=459
[2022-11-15T17:34:57.957] sched: Allocate JobId=52757 NodeList=cpu05 #CPUs=64 Partition=cpu-opteron
[2022-11-15T17:35:10.978] _slurm_rpc_submit_batch_job: JobId=52758 InitPrio=201 usec=456
[2022-11-15T17:35:11.973] sched: Allocate JobId=52758 NodeList=cpu08 #CPUs=64 Partition=cpu-opteron
[2022-11-15T17:35:12.843] _slurm_rpc_submit_batch_job: JobId=52759 InitPrio=201 usec=487
[2022-11-15T17:35:14.976] sched: Allocate JobId=52759 NodeList=cpu09 #CPUs=64 Partition=cpu-opteron
[2022-11-15T17:35:15.994] _slurm_rpc_submit_batch_job: JobId=52760 InitPrio=201 usec=514
[2022-11-15T17:35:18.402] _slurm_rpc_submit_batch_job: JobId=52761 InitPrio=201 usec=524
[2022-11-15T17:35:20.211] _slurm_rpc_submit_batch_job: JobId=52762 InitPrio=201 usec=485
[2022-11-15T17:35:23.155] _slurm_rpc_submit_batch_job: JobId=52763 InitPrio=201 usec=474
[2022-11-15T17:35:25.618] _slurm_rpc_submit_batch_job: JobId=52764 InitPrio=201 usec=422
[2022-11-15T17:35:28.282] _slurm_rpc_submit_batch_job: JobId=52765 InitPrio=201 usec=439
[2022-11-15T17:35:31.117] _slurm_rpc_submit_batch_job: JobId=52766 InitPrio=201 usec=421
[2022-11-15T17:35:59.491] _slurm_rpc_submit_batch_job: JobId=52767 InitPrio=1008 usec=501
[2022-11-15T17:36:21.650] sched/backfill: _start_job: Started JobId=52767 in gpu-titan on gpu02
[2022-11-15T17:36:41.947] _job_complete: JobId=52767 WEXITSTATUS 0
[2022-11-15T17:36:41.947] _job_complete: JobId=52767 done
[2022-11-15T17:39:12.731] _slurm_rpc_submit_batch_job: JobId=52768 InitPrio=1008 usec=519
[2022-11-15T17:39:13.433] sched: Allocate JobId=52768 NodeList=cpu10 #CPUs=2 Partition=cpu-opteron
[2022-11-15T17:39:15.629] _job_complete: JobId=52768 WEXITSTATUS 0
[2022-11-15T17:39:15.629] _job_complete: JobId=52768 done
[2022-11-15T17:47:58.085] _slurm_rpc_submit_batch_job: JobId=52769 InitPrio=1008 usec=507
[2022-11-15T17:47:58.365] sched: Allocate JobId=52769 NodeList=cpu[01,03] #CPUs=2 Partition=cpu-opteron
[2022-11-15T17:48:14.490] _job_complete: JobId=52769 WEXITSTATUS 0
[2022-11-15T17:48:14.490] _job_complete: JobId=52769 done
[2022-11-15T17:55:58.234] _slurm_rpc_submit_batch_job: JobId=52770 InitPrio=1008 usec=551
[2022-11-15T17:55:59.071] sched: Allocate JobId=52770 NodeList=cpu10 #CPUs=4 Partition=cpu-opteron
[2022-11-15T17:56:00.991] _job_complete: JobId=52770 WEXITSTATUS 0
[2022-11-15T17:56:00.991] _job_complete: JobId=52770 done
[2022-11-15T17:57:10.236] _slurm_rpc_submit_batch_job: JobId=52771 InitPrio=1008 usec=528
[2022-11-15T17:57:10.306] sched: Allocate JobId=52771 NodeList=cpu[01,03] #CPUs=2 Partition=cpu-opteron
[2022-11-15T17:57:26.496] _job_complete: JobId=52771 WEXITSTATUS 0
[2022-11-15T17:57:26.496] _job_complete: JobId=52771 done
[2022-11-15T17:59:18.892] _slurm_rpc_submit_batch_job: JobId=52772 InitPrio=1008 usec=532
[2022-11-15T17:59:58.725] _slurm_rpc_submit_batch_job: JobId=52773 InitPrio=1008 usec=589
[2022-11-15T18:01:13.708] _slurm_rpc_submit_batch_job: JobId=52774 InitPrio=1008 usec=475
[2022-11-15T18:01:21.696] sched/backfill: _start_job: Started JobId=52774 in gpu-titan on gpu02
[2022-11-15T18:02:06.495] _job_complete: JobId=52774 WEXITSTATUS 0
[2022-11-15T18:02:06.495] _job_complete: JobId=52774 done
[2022-11-15T18:05:50.872] _slurm_rpc_submit_batch_job: JobId=52775 InitPrio=1008 usec=542
[2022-11-15T18:05:51.159] sched: Allocate JobId=52775 NodeList=cpu10 #CPUs=4 Partition=cpu-opteron
[2022-11-15T18:05:54.259] _job_complete: JobId=52775 WEXITSTATUS 0
[2022-11-15T18:05:54.259] _job_complete: JobId=52775 done
[2022-11-15T18:07:37.357] _slurm_rpc_submit_batch_job: JobId=52776 InitPrio=1008 usec=525
[2022-11-15T18:07:37.452] sched: Allocate JobId=52776 NodeList=cpu[01,03] #CPUs=2 Partition=cpu-opteron
[2022-11-15T18:08:21.274] _job_complete: JobId=52776 WEXITSTATUS 0
[2022-11-15T18:08:21.274] _job_complete: JobId=52776 done
[2022-11-15T18:10:22.885] _slurm_rpc_submit_batch_job: JobId=52777 InitPrio=1008 usec=575
[2022-11-15T18:14:32.636] _pick_best_nodes: JobId=52778 never runnable in partition cpu-opteron
[2022-11-15T18:14:32.636] _slurm_rpc_submit_batch_job: Requested node configuration is not available
[2022-11-15T18:14:45.184] _slurm_rpc_submit_batch_job: JobId=52779 InitPrio=1008 usec=496
[2022-11-15T18:14:46.166] sched: Allocate JobId=52779 NodeList=cpu10 #CPUs=2 Partition=cpu-opteron
[2022-11-15T18:19:05.915] _job_complete: JobId=52779 WEXITSTATUS 0
[2022-11-15T18:19:05.915] _job_complete: JobId=52779 done
[2022-11-15T18:28:36.399] _job_complete: JobId=52664 WEXITSTATUS 0
[2022-11-15T18:28:36.399] _job_complete: JobId=52664 done
[2022-11-15T19:58:30.262] _slurm_rpc_submit_batch_job: JobId=52780 InitPrio=9072 usec=709
[2022-11-15T19:58:57.998] _slurm_rpc_kill_job: REQUEST_KILL_JOB JobId=52780 uid 548300626
[2022-11-15T20:02:31.131] _slurm_rpc_submit_batch_job: JobId=52781 InitPrio=9072 usec=434
[2022-11-15T20:47:07.116] _job_complete: JobId=52719 WEXITSTATUS 1
[2022-11-15T20:47:07.116] _job_complete: JobId=52719 done
[2022-11-15T20:47:07.810] sched: Allocate JobId=52743 NodeList=cpu13 #CPUs=16 Partition=cpu-epyc
[2022-11-15T20:47:07.824] sched: Allocate JobId=52734 NodeList=cpu13 #CPUs=8 Partition=cpu-epyc
[2022-11-15T21:07:28.546] _slurm_rpc_submit_batch_job: JobId=52782 InitPrio=2620 usec=701
[2022-11-15T21:16:53.213] _slurm_rpc_kill_job: REQUEST_KILL_JOB JobId=52782 uid 548300630
[2022-11-15T21:17:24.311] _slurm_rpc_submit_batch_job: JobId=52783 InitPrio=2620 usec=548
[2022-11-15T21:41:28.091] _slurm_rpc_kill_job: REQUEST_KILL_JOB JobId=52783 uid 548300630
[2022-11-15T21:41:58.263] _slurm_rpc_submit_batch_job: JobId=52784 InitPrio=2620 usec=545
[2022-11-15T22:07:40.258] _slurm_rpc_submit_batch_job: JobId=52785 InitPrio=3024 usec=532
[2022-11-16T00:49:03.545] _slurm_rpc_submit_batch_job: JobId=52786 InitPrio=3024 usec=949
[2022-11-16T00:49:22.424] sched/backfill: _start_job: Started JobId=52786 in cpu-opteron on cpu07
[2022-11-16T02:15:26.916] _job_complete: JobId=52786 WEXITSTATUS 0
[2022-11-16T02:15:26.917] _job_complete: JobId=52786 done
[2022-11-16T02:24:12.915] _job_complete: JobId=52743 OOM failure
[2022-11-16T02:24:12.915] _job_complete: JobId=52743 done
[2022-11-16T02:24:22.608] sched/backfill: _start_job: Started JobId=52735 in cpu-epyc on cpu13
[2022-11-16T02:24:22.609] sched/backfill: _start_job: Started JobId=52736 in cpu-epyc on cpu13
[2022-11-16T03:03:44.676] _slurm_rpc_submit_batch_job: JobId=52787 InitPrio=1612 usec=740
[2022-11-16T03:05:06.240] _slurm_rpc_submit_batch_job: JobId=52788 InitPrio=1612 usec=911
[2022-11-16T04:58:49.483] Time limit exhausted for JobId=52310
[2022-11-16T04:58:56.683] sched: Allocate JobId=52644 NodeList=gpu03 #CPUs=16 Partition=gpu-k10
[2022-11-16T06:01:18.323] _job_complete: JobId=52725 WEXITSTATUS 0
[2022-11-16T06:01:18.329] _job_complete: JobId=52725 done
[2022-11-16T06:01:23.680] sched: Allocate JobId=52781 NodeList=cpu03 #CPUs=64 Partition=cpu-opteron
[2022-11-16T06:01:38.991] _job_complete: JobId=52781 WEXITSTATUS 0
[2022-11-16T06:01:38.991] _job_complete: JobId=52781 done
[2022-11-16T06:01:39.630] sched: Allocate JobId=52760 NodeList=cpu03 #CPUs=64 Partition=cpu-opteron
[2022-11-16T06:25:31.526] _job_complete: JobId=52440 WEXITSTATUS 0
[2022-11-16T06:25:31.527] _job_complete: JobId=52440 done
[2022-11-16T06:25:32.676] sched: Allocate JobId=52784 NodeList=cpu15 #CPUs=48 Partition=cpu-epyc
[2022-11-16T07:17:24.691] _slurm_rpc_submit_batch_job: JobId=52789 InitPrio=9072 usec=558
[2022-11-16T08:27:47.297] _job_complete: JobId=52784 WEXITSTATUS 0
[2022-11-16T08:27:47.298] _job_complete: JobId=52784 done
[2022-11-16T08:27:47.902] sched: Allocate JobId=52737 NodeList=cpu15 #CPUs=8 Partition=cpu-epyc
[2022-11-16T08:51:03.384] error: _find_node_record: lookup failure for node "cpu02"
[2022-11-16T08:51:03.384] error: node_name2bitmap: invalid node specified: "cpu02"
[2022-11-16T08:51:03.384] error: _find_node_record: lookup failure for node "cpu06"
[2022-11-16T08:51:03.384] error: node_name2bitmap: invalid node specified: "cpu06"
[2022-11-16T08:51:03.384] _slurm_rpc_resv_create reservation=storage_maintenance: Invalid node name specified
[2022-11-16T08:51:46.852] sched: Created reservation=storage_upgrade_maintenance users=jitkang nodes=cpu[01,03-05,07-15],gpu[01-05],umhpc cores=880 licenses=(null) tres=cpu=1168 watts=4294967294 start=2022-11-26T00:00:00 end=2023-11-26T00:00:00 MaxStartDelay=
[2022-11-16T10:01:30.841] _slurm_rpc_kill_job: REQUEST_KILL_JOB JobId=52606 uid 548300630
[2022-11-16T10:03:07.098] _slurm_rpc_submit_batch_job: JobId=52790 InitPrio=2822 usec=571
[2022-11-16T10:03:07.345] sched: Allocate JobId=52790 NodeList=cpu15 #CPUs=8 Partition=cpu-epyc
[2022-11-16T10:31:08.442] _job_complete: JobId=52790 OOM failure
[2022-11-16T10:31:08.442] _job_complete: JobId=52790 done
[2022-11-16T10:41:22.661] sched: _slurm_rpc_allocate_resources JobId=52791 NodeList=(null) usec=1197
[2022-11-16T10:41:23.505] sched/backfill: _start_job: Started JobId=52791 in cpu-opteron on cpu01
[2022-11-16T10:47:23.161] _slurm_rpc_submit_batch_job: JobId=52792 InitPrio=2822 usec=495
[2022-11-16T10:47:23.517] sched/backfill: _start_job: Started JobId=52792 in cpu-epyc on cpu15
[2022-11-16T11:09:44.121] _job_complete: JobId=52791 WEXITSTATUS 0
[2022-11-16T11:09:44.121] _job_complete: JobId=52791 done
[2022-11-16T11:15:27.220] _job_complete: JobId=52792 OOM failure
[2022-11-16T11:15:27.220] _job_complete: JobId=52792 done
[2022-11-16T11:45:50.623] _slurm_rpc_submit_batch_job: JobId=52793 InitPrio=2822 usec=637
[2022-11-16T11:45:50.797] sched: Allocate JobId=52793 NodeList=cpu15 #CPUs=8 Partition=cpu-epyc
[2022-11-16T12:13:57.784] _job_complete: JobId=52793 OOM failure
[2022-11-16T12:13:57.785] _job_complete: JobId=52793 done
[2022-11-16T12:32:54.450] _job_complete: JobId=52723 WEXITSTATUS 0
[2022-11-16T12:32:54.456] _job_complete: JobId=52723 done
[2022-11-16T12:33:00.747] sched: Allocate JobId=52789 NodeList=cpu04 #CPUs=64 Partition=cpu-opteron
[2022-11-16T12:37:13.348] _build_node_list: No nodes satisfy JobId=52794 requirements in partition cpu-epyc
[2022-11-16T12:37:13.348] _slurm_rpc_submit_batch_job: Requested node configuration is not available
[2022-11-16T12:45:57.760] _slurm_rpc_submit_batch_job: JobId=52795 InitPrio=13024 usec=657
[2022-11-16T12:45:57.870] sched: Allocate JobId=52795 NodeList=cpu01 #CPUs=2 Partition=cpu-opteron
[2022-11-16T12:49:53.114] _slurm_rpc_submit_batch_job: JobId=52796 InitPrio=3427 usec=588
[2022-11-16T12:49:53.307] sched: Allocate JobId=52796 NodeList=cpu01 #CPUs=16 Partition=cpu-opteron
[2022-11-16T12:49:56.837] _job_complete: JobId=52796 WEXITSTATUS 1
[2022-11-16T12:49:56.838] _job_complete: JobId=52796 done
[2022-11-16T12:51:29.451] _slurm_rpc_submit_batch_job: JobId=52797 InitPrio=3427 usec=508
[2022-11-16T12:51:29.588] sched: Allocate JobId=52797 NodeList=cpu01 #CPUs=16 Partition=cpu-opteron
[2022-11-16T12:51:32.936] _job_complete: JobId=52797 WEXITSTATUS 1
[2022-11-16T12:51:32.936] _job_complete: JobId=52797 done
[2022-11-16T12:51:56.431] _slurm_rpc_kill_job: REQUEST_KILL_JOB JobId=52795 uid 548200121
[2022-11-16T12:56:19.852] _slurm_rpc_submit_batch_job: JobId=52798 InitPrio=13024 usec=488
[2022-11-16T12:56:20.057] sched: Allocate JobId=52798 NodeList=cpu01 #CPUs=2 Partition=cpu-opteron
[2022-11-16T13:03:19.752] Time limit exhausted for JobId=52789
[2022-11-16T13:03:26.015] sched: Allocate JobId=52761 NodeList=cpu04 #CPUs=64 Partition=cpu-opteron
[2022-11-16T13:04:54.593] _slurm_rpc_submit_batch_job: JobId=52799 InitPrio=3427 usec=615
[2022-11-16T13:04:54.877] sched: Allocate JobId=52799 NodeList=cpu01 #CPUs=16 Partition=cpu-opteron
[2022-11-16T13:04:57.931] _job_complete: JobId=52799 WEXITSTATUS 1
[2022-11-16T13:04:57.931] _job_complete: JobId=52799 done
[2022-11-16T13:06:00.566] _slurm_rpc_submit_batch_job: JobId=52800 InitPrio=3427 usec=584
[2022-11-16T13:06:00.957] sched: Allocate JobId=52800 NodeList=cpu01 #CPUs=16 Partition=cpu-opteron
[2022-11-16T13:06:04.262] _job_complete: JobId=52800 WEXITSTATUS 1
[2022-11-16T13:06:04.262] _job_complete: JobId=52800 done
[2022-11-16T13:06:39.930] _slurm_rpc_submit_batch_job: JobId=52801 InitPrio=3427 usec=494
[2022-11-16T13:06:39.989] sched: Allocate JobId=52801 NodeList=cpu01 #CPUs=16 Partition=cpu-opteron
[2022-11-16T13:06:42.999] _job_complete: JobId=52801 WEXITSTATUS 1
[2022-11-16T13:06:42.999] _job_complete: JobId=52801 done
[2022-11-16T13:08:50.713] _slurm_rpc_submit_batch_job: JobId=52802 InitPrio=3427 usec=529
[2022-11-16T13:08:51.149] sched: Allocate JobId=52802 NodeList=cpu01 #CPUs=16 Partition=cpu-opteron
[2022-11-16T13:09:04.328] _job_complete: JobId=52802 WEXITSTATUS 1
[2022-11-16T13:09:04.329] _job_complete: JobId=52802 done
[2022-11-16T13:11:06.351] _slurm_rpc_submit_batch_job: JobId=52803 InitPrio=3427 usec=540
[2022-11-16T13:11:07.314] sched: Allocate JobId=52803 NodeList=cpu01 #CPUs=16 Partition=cpu-opteron
[2022-11-16T13:11:20.539] _job_complete: JobId=52803 WEXITSTATUS 1
[2022-11-16T13:11:20.539] _job_complete: JobId=52803 done
[2022-11-16T13:13:05.440] _slurm_rpc_submit_batch_job: JobId=52804 InitPrio=2822 usec=524
[2022-11-16T13:14:21.355] _slurm_rpc_submit_batch_job: JobId=52805 InitPrio=7258 usec=435
[2022-11-16T13:18:54.994] _slurm_rpc_kill_job: REQUEST_KILL_JOB JobId=52798 uid 548200121
[2022-11-16T13:19:50.550] _slurm_rpc_submit_batch_job: JobId=52806 InitPrio=806 usec=480
[2022-11-16T13:20:23.814] sched/backfill: _start_job: Started JobId=52806 in cpu-opteron on cpu01
[2022-11-16T13:21:16.659] _job_complete: JobId=52806 WEXITSTATUS 0
[2022-11-16T13:21:16.659] _job_complete: JobId=52806 done
[2022-11-16T13:23:10.764] _slurm_rpc_submit_batch_job: JobId=52807 InitPrio=2620 usec=494
[2022-11-16T13:23:23.834] sched/backfill: _start_job: Started JobId=52807 in cpu-opteron on cpu01
[2022-11-16T13:28:07.653] _job_complete: JobId=52807 WEXITSTATUS 1
[2022-11-16T13:28:07.654] _job_complete: JobId=52807 done
[2022-11-16T13:30:40.304] _slurm_rpc_submit_batch_job: JobId=52808 InitPrio=7258 usec=479
[2022-11-16T13:34:18.781] _slurm_rpc_kill_job: REQUEST_KILL_JOB JobId=52808 uid 548300626
[2022-11-16T13:34:59.351] _slurm_rpc_submit_batch_job: JobId=52809 InitPrio=7258 usec=442
[2022-11-16T13:50:01.117] sched: _slurm_rpc_allocate_resources JobId=52810 NodeList=(null) usec=928
[2022-11-16T13:50:23.892] sched/backfill: _start_job: Started JobId=52810 in cpu-opteron on cpu01
[2022-11-16T13:52:29.095] _slurm_rpc_submit_batch_job: JobId=52811 InitPrio=3024 usec=401
[2022-11-16T14:08:39.620] sched: _slurm_rpc_allocate_resources JobId=52812 NodeList=(null) usec=857
[2022-11-16T14:08:40.385] sched: Allocate JobId=52812 NodeList=cpu01 #CPUs=1 Partition=cpu-opteron
[2022-11-16T14:26:04.003] sched: _slurm_rpc_allocate_resources JobId=52813 NodeList=(null) usec=1025
[2022-11-16T14:26:23.968] sched/backfill: _start_job: Started JobId=52813 in cpu-opteron on cpu01
[2022-11-16T14:34:46.039] _job_complete: JobId=52812 WEXITSTATUS 1
[2022-11-16T14:34:46.039] _job_complete: JobId=52812 done
[2022-11-16T14:36:38.457] sched: _slurm_rpc_allocate_resources JobId=52814 NodeList=(null) usec=1015
[2022-11-16T14:36:39.418] sched: Allocate JobId=52814 NodeList=cpu01 #CPUs=1 Partition=cpu-opteron
[2022-11-16T14:44:10.709] _job_complete: JobId=52814 WEXITSTATUS 1
[2022-11-16T14:44:10.709] _job_complete: JobId=52814 done
[2022-11-16T14:44:28.928] sched: _slurm_rpc_allocate_resources JobId=52815 NodeList=(null) usec=1219
[2022-11-16T14:44:29.120] sched: Allocate JobId=52815 NodeList=cpu01 #CPUs=1 Partition=cpu-opteron
[2022-11-16T14:45:00.778] _job_complete: JobId=52813 WEXITSTATUS 127
[2022-11-16T14:45:00.778] _job_complete: JobId=52813 done
[2022-11-16T14:53:58.239] _job_complete: JobId=52815 WEXITSTATUS 1
[2022-11-16T14:53:58.239] _job_complete: JobId=52815 done
[2022-11-16T15:03:09.438] _slurm_rpc_submit_batch_job: JobId=52816 InitPrio=806 usec=608
[2022-11-16T15:03:24.068] sched/backfill: _start_job: Started JobId=52816 in cpu-opteron on cpu01
[2022-11-16T15:04:06.260] _job_complete: JobId=52816 WEXITSTATUS 1
[2022-11-16T15:04:06.260] _job_complete: JobId=52816 done
[2022-11-16T15:06:54.942] _slurm_rpc_submit_batch_job: JobId=52817 InitPrio=806 usec=521
[2022-11-16T15:07:24.077] sched/backfill: _start_job: Started JobId=52817 in cpu-opteron on cpu01
[2022-11-16T15:08:12.955] _job_complete: JobId=52817 WEXITSTATUS 0
[2022-11-16T15:08:12.955] _job_complete: JobId=52817 done
[2022-11-16T15:09:56.476] _job_complete: JobId=52810 WEXITSTATUS 0
[2022-11-16T15:09:56.476] _job_complete: JobId=52810 done
[2022-11-16T15:13:35.313] sched: _slurm_rpc_allocate_resources JobId=52818 NodeList=(null) usec=1011
[2022-11-16T15:13:35.459] sched: Allocate JobId=52818 NodeList=cpu07 #CPUs=1 Partition=cpu-opteron
[2022-11-16T15:14:57.103] cleanup_completing: JobId=52810 completion process took 301 seconds
[2022-11-16T15:42:40.182] sched: _slurm_rpc_allocate_resources JobId=52819 NodeList=(null) usec=1549
[2022-11-16T15:43:24.165] sched/backfill: _start_job: Started JobId=52819 in cpu-opteron on cpu07
[2022-11-16T16:03:05.149] _job_complete: JobId=52674 WEXITSTATUS 1
[2022-11-16T16:03:05.156] _job_complete: JobId=52674 done
[2022-11-16T16:03:07.413] sched: Allocate JobId=52675 NodeList=gpu02 #CPUs=8 Partition=gpu-titan
[2022-11-16T16:03:07.434] sched: Allocate JobId=52785 NodeList=gpu02 #CPUs=4 Partition=gpu-titan
[2022-11-16T16:16:34.670] _slurm_rpc_submit_batch_job: JobId=52820 InitPrio=2822 usec=569
[2022-11-16T16:17:24.256] sched/backfill: _start_job: Started JobId=52820 in cpu-epyc on cpu15
[2022-11-16T16:18:01.436] _job_complete: JobId=52820 OOM failure
[2022-11-16T16:18:01.436] _job_complete: JobId=52820 done
[2022-11-16T16:20:12.599] sched: _slurm_rpc_allocate_resources JobId=52821 NodeList=(null) usec=709
[2022-11-16T16:20:12.954] sched: Allocate JobId=52821 NodeList=cpu07 #CPUs=1 Partition=cpu-opteron
[2022-11-16T16:20:40.946] sched: _slurm_rpc_allocate_resources JobId=52822 NodeList=(null) usec=881
[2022-11-16T16:21:24.268] sched/backfill: _start_job: Started JobId=52822 in cpu-opteron on cpu07
[2022-11-16T17:22:53.958] _job_complete: JobId=52734 WEXITSTATUS 0
[2022-11-16T17:22:53.958] _job_complete: JobId=52734 done
[2022-11-16T17:50:20.157] _job_complete: JobId=52818 WEXITSTATUS 0
[2022-11-16T17:50:20.157] _job_complete: JobId=52818 done
[2022-11-16T18:22:06.015] _job_complete: JobId=52278 WEXITSTATUS 0
[2022-11-16T18:22:06.020] _job_complete: JobId=52278 done
[2022-11-16T18:22:11.469] sched: Allocate JobId=52689 NodeList=gpu04 #CPUs=1 Partition=gpu-k40c
[2022-11-16T18:23:14.149] _job_complete: JobId=52689 WEXITSTATUS 0
[2022-11-16T18:23:14.149] _job_complete: JobId=52689 done
[2022-11-16T18:31:31.649] job_step_signal: JobId=52821 StepId=0 not found
[2022-11-16T18:31:31.651] _job_complete: JobId=52821 WTERMSIG 126
[2022-11-16T18:31:31.651] _job_complete: JobId=52821 cancelled by interactive user
[2022-11-16T18:31:31.651] _job_complete: JobId=52821 done
[2022-11-16T18:35:53.660] _job_complete: JobId=52735 WEXITSTATUS 0
[2022-11-16T18:35:53.661] _job_complete: JobId=52735 done
[2022-11-16T18:41:03.770] _slurm_rpc_submit_batch_job: JobId=52823 InitPrio=2016 usec=509
[2022-11-16T18:41:04.734] sched: Allocate JobId=52823 NodeList=gpu04 #CPUs=16 Partition=gpu-k40c
[2022-11-16T19:10:06.216] _job_complete: JobId=52736 WEXITSTATUS 0
[2022-11-16T19:10:06.216] _job_complete: JobId=52736 done
[2022-11-16T20:38:45.228] _job_complete: JobId=52585 WEXITSTATUS 1
[2022-11-16T20:38:45.233] _job_complete: JobId=52585 done
[2022-11-16T20:57:27.378] sched: _slurm_rpc_allocate_resources JobId=52824 NodeList=(null) usec=1038
[2022-11-16T20:57:28.041] sched: Allocate JobId=52824 NodeList=cpu07 #CPUs=1 Partition=cpu-opteron
[2022-11-16T21:02:53.517] _slurm_rpc_submit_batch_job: JobId=52825 InitPrio=3024 usec=404
[2022-11-16T21:03:22.265] _slurm_rpc_submit_batch_job: JobId=52826 InitPrio=604 usec=453
[2022-11-16T21:03:24.870] sched/backfill: _start_job: Started JobId=52826 in cpu-epyc on cpu15
[2022-11-16T21:36:06.872] _slurm_rpc_submit_batch_job: JobId=52827 InitPrio=10483 usec=540
[2022-11-16T21:46:16.084] _slurm_rpc_kill_job: REQUEST_KILL_JOB JobId=52827 uid 548300604
[2022-11-16T21:46:26.811] _slurm_rpc_kill_job: REQUEST_KILL_JOB JobId=52824 uid 548300604
[2022-11-16T21:48:24.485] _slurm_rpc_submit_batch_job: JobId=52828 InitPrio=10483 usec=609
[2022-11-16T22:23:56.419] _job_complete: JobId=52819 WEXITSTATUS 0
[2022-11-16T22:23:56.420] _job_complete: JobId=52819 done
[2022-11-16T22:24:12.799] _job_complete: JobId=52822 WEXITSTATUS 0
[2022-11-16T22:24:12.800] _job_complete: JobId=52822 done
[2022-11-16T22:28:56.942] cleanup_completing: JobId=52819 completion process took 300 seconds
[2022-11-16T22:29:13.373] cleanup_completing: JobId=52822 completion process took 301 seconds
[2022-11-16T23:08:53.748] _job_complete: JobId=52737 WEXITSTATUS 0
[2022-11-16T23:08:53.748] _job_complete: JobId=52737 done
[2022-11-17T09:10:42.076] sched: _slurm_rpc_allocate_resources JobId=52829 NodeList=(null) usec=1410
[2022-11-17T09:11:26.410] sched/backfill: _start_job: Started JobId=52829 in cpu-opteron on cpu01
[2022-11-17T10:53:54.191] _slurm_rpc_submit_batch_job: JobId=52830 InitPrio=1209 usec=735
[2022-11-17T10:53:58.129] _slurm_rpc_submit_batch_job: JobId=52831 InitPrio=1209 usec=591
[2022-11-17T10:54:01.624] _slurm_rpc_submit_batch_job: JobId=52832 InitPrio=1209 usec=416
[2022-11-17T10:54:05.588] _slurm_rpc_submit_batch_job: JobId=52833 InitPrio=1209 usec=523
[2022-11-17T10:54:09.918] _slurm_rpc_submit_batch_job: JobId=52834 InitPrio=1209 usec=484
[2022-11-17T10:54:13.454] _slurm_rpc_submit_batch_job: JobId=52835 InitPrio=1209 usec=432
[2022-11-17T10:54:17.270] _slurm_rpc_submit_batch_job: JobId=52836 InitPrio=1209 usec=643
[2022-11-17T10:54:23.629] _slurm_rpc_submit_batch_job: JobId=52837 InitPrio=1209 usec=594
[2022-11-17T10:54:26.650] sched/backfill: _start_job: Started JobId=52830 in cpu-epyc on cpu15
[2022-11-17T10:54:26.651] sched/backfill: _start_job: Started JobId=52831 in cpu-epyc on cpu15
[2022-11-17T10:54:28.078] _slurm_rpc_submit_batch_job: JobId=52838 InitPrio=1209 usec=527
[2022-11-17T10:58:49.007] sched: _slurm_rpc_allocate_resources JobId=52839 NodeList=(null) usec=819
[2022-11-17T10:59:26.677] sched/backfill: _start_job: Started JobId=52839 in cpu-opteron on cpu07
[2022-11-17T11:01:12.556] _slurm_rpc_submit_batch_job: JobId=52840 InitPrio=1209 usec=540
[2022-11-17T11:01:15.649] _slurm_rpc_submit_batch_job: JobId=52841 InitPrio=1209 usec=485
[2022-11-17T11:01:18.817] _slurm_rpc_submit_batch_job: JobId=52842 InitPrio=1209 usec=518
[2022-11-17T11:01:21.777] _slurm_rpc_submit_batch_job: JobId=52843 InitPrio=1209 usec=491
[2022-11-17T11:01:24.776] _slurm_rpc_submit_batch_job: JobId=52844 InitPrio=1209 usec=485
[2022-11-17T11:01:32.043] _slurm_rpc_submit_batch_job: JobId=52845 InitPrio=1209 usec=450
[2022-11-17T11:01:35.068] _slurm_rpc_submit_batch_job: JobId=52846 InitPrio=1209 usec=527
[2022-11-17T11:01:38.082] _slurm_rpc_submit_batch_job: JobId=52847 InitPrio=1209 usec=518
[2022-11-17T11:01:41.283] _slurm_rpc_submit_batch_job: JobId=52848 InitPrio=1209 usec=564
[2022-11-17T11:01:44.229] _slurm_rpc_submit_batch_job: JobId=52849 InitPrio=1209 usec=411
[2022-11-17T11:01:47.754] _slurm_rpc_submit_batch_job: JobId=52850 InitPrio=1209 usec=491
[2022-11-17T11:01:52.233] _slurm_rpc_submit_batch_job: JobId=52851 InitPrio=1209 usec=464
[2022-11-17T11:01:55.218] _slurm_rpc_submit_batch_job: JobId=52852 InitPrio=1209 usec=534
[2022-11-17T11:01:58.729] _slurm_rpc_submit_batch_job: JobId=52853 InitPrio=1209 usec=488
[2022-11-17T11:02:01.890] _slurm_rpc_submit_batch_job: JobId=52854 InitPrio=1209 usec=537
[2022-11-17T11:47:31.822] _job_complete: JobId=52839 WEXITSTATUS 130
[2022-11-17T11:47:31.823] _job_complete: JobId=52839 done
[2022-11-17T13:00:33.745] _slurm_rpc_submit_batch_job: JobId=52855 InitPrio=1209 usec=605
[2022-11-17T13:00:36.277] _slurm_rpc_submit_batch_job: JobId=52856 InitPrio=1209 usec=562
[2022-11-17T13:00:39.564] _slurm_rpc_submit_batch_job: JobId=52857 InitPrio=1209 usec=458
[2022-11-17T13:00:42.321] _slurm_rpc_submit_batch_job: JobId=52858 InitPrio=1209 usec=431
[2022-11-17T13:00:44.812] _slurm_rpc_submit_batch_job: JobId=52859 InitPrio=1209 usec=529
[2022-11-17T13:00:48.261] _slurm_rpc_submit_batch_job: JobId=52860 InitPrio=1209 usec=496
[2022-11-17T13:00:51.124] _slurm_rpc_submit_batch_job: JobId=52861 InitPrio=1209 usec=505
[2022-11-17T13:00:53.620] _slurm_rpc_submit_batch_job: JobId=52862 InitPrio=1209 usec=456
[2022-11-17T13:00:56.140] _slurm_rpc_submit_batch_job: JobId=52863 InitPrio=1209 usec=516
[2022-11-17T13:00:58.893] _slurm_rpc_submit_batch_job: JobId=52864 InitPrio=1209 usec=621
[2022-11-17T13:01:06.125] _slurm_rpc_submit_batch_job: JobId=52865 InitPrio=1209 usec=463
[2022-11-17T14:47:28.171] _slurm_rpc_submit_batch_job: JobId=52866 InitPrio=806 usec=569
[2022-11-17T14:47:28.352] sched/backfill: _start_job: Started JobId=52866 in cpu-opteron on cpu07
[2022-11-17T14:47:32.122] _job_complete: JobId=52866 WEXITSTATUS 0
[2022-11-17T14:47:32.122] _job_complete: JobId=52866 done
[2022-11-17T15:00:27.271] _slurm_rpc_submit_batch_job: JobId=52867 InitPrio=806 usec=564
[2022-11-17T15:00:28.398] sched/backfill: _start_job: Started JobId=52867 in cpu-opteron on cpu07
[2022-11-17T15:00:32.035] _job_complete: JobId=52867 WEXITSTATUS 0
[2022-11-17T15:00:32.036] _job_complete: JobId=52867 done
[2022-11-17T15:10:07.048] _slurm_rpc_submit_batch_job: JobId=52868 InitPrio=806 usec=554
[2022-11-17T15:10:28.435] sched/backfill: _start_job: Started JobId=52868 in cpu-opteron on cpu07
[2022-11-17T15:10:32.067] _job_complete: JobId=52868 WEXITSTATUS 0
[2022-11-17T15:10:32.067] _job_complete: JobId=52868 done
[2022-11-17T15:35:53.751] _slurm_rpc_kill_job: REQUEST_KILL_JOB JobId=52828 uid 548300604
[2022-11-17T15:36:28.536] sched/backfill: _start_job: Started JobId=52855 in cpu-opteron on cpu07
[2022-11-17T15:36:28.537] sched/backfill: _start_job: Started JobId=52856 in cpu-opteron on cpu07
[2022-11-17T15:36:28.538] sched/backfill: _start_job: Started JobId=52857 in cpu-opteron on cpu07
[2022-11-17T15:36:32.899] sched: _slurm_rpc_allocate_resources JobId=52869 NodeList=(null) usec=894
[2022-11-17T15:36:47.793] _slurm_rpc_submit_batch_job: JobId=52870 InitPrio=1209 usec=551
[2022-11-17T15:36:50.136] _slurm_rpc_submit_batch_job: JobId=52871 InitPrio=1209 usec=498
[2022-11-17T15:36:52.825] _slurm_rpc_submit_batch_job: JobId=52872 InitPrio=1209 usec=523
[2022-11-17T15:36:55.176] _slurm_rpc_submit_batch_job: JobId=52873 InitPrio=1209 usec=509
[2022-11-17T15:36:57.512] _slurm_rpc_submit_batch_job: JobId=52874 InitPrio=1209 usec=520
[2022-11-17T15:36:59.944] _slurm_rpc_submit_batch_job: JobId=52875 InitPrio=1209 usec=490
[2022-11-17T15:37:02.320] _slurm_rpc_submit_batch_job: JobId=52876 InitPrio=1209 usec=533
[2022-11-17T15:37:04.752] _slurm_rpc_submit_batch_job: JobId=52877 InitPrio=1209 usec=516
[2022-11-17T15:37:07.192] _slurm_rpc_submit_batch_job: JobId=52878 InitPrio=1209 usec=498
[2022-11-17T15:38:16.654] sched: _slurm_rpc_allocate_resources JobId=52879 NodeList=(null) usec=1032
[2022-11-17T15:40:21.543] _slurm_rpc_kill_job: REQUEST_KILL_JOB JobId=52828 uid 548300604
[2022-11-17T15:40:30.577] _slurm_rpc_kill_job: REQUEST_KILL_JOB JobId=52879 uid 548300604
[2022-11-17T15:40:47.037] _slurm_rpc_kill_job: REQUEST_KILL_JOB JobId=52869 uid 548300604
[2022-11-17T15:45:52.182] _job_complete: JobId=52758 WEXITSTATUS 0
[2022-11-17T15:45:52.182] _job_complete: JobId=52758 done
[2022-11-17T15:45:53.473] sched: Allocate JobId=52805 NodeList=cpu08 #CPUs=64 Partition=cpu-opteron
[2022-11-17T15:48:37.298] sched: _slurm_rpc_allocate_resources JobId=52880 NodeList=(null) usec=1087
[2022-11-17T15:49:28.585] sched/backfill: _start_job: Started JobId=52880 in cpu-opteron on cpu07
[2022-11-17T15:50:28.588] sched/backfill: _start_job: Started JobId=52858 in cpu-opteron on cpu10
[2022-11-17T15:50:28.589] sched/backfill: _start_job: Started JobId=52859 in cpu-opteron on cpu10
[2022-11-17T15:50:28.589] sched/backfill: _start_job: Started JobId=52860 in cpu-opteron on cpu10
[2022-11-17T16:07:27.005] job_complete: invalid JobId=52879
[2022-11-17T16:07:27.005] _slurm_rpc_complete_job_allocation: JobId=52879 error Invalid job id specified
[2022-11-17T16:07:27.006] job_complete: invalid JobId=52869
[2022-11-17T16:07:27.006] _slurm_rpc_complete_job_allocation: JobId=52869 error Invalid job id specified
[2022-11-17T16:07:27.007] job_complete: invalid JobId=52879
[2022-11-17T16:07:27.007] _slurm_rpc_complete_job_allocation: JobId=52879 error Invalid job id specified
[2022-11-17T16:07:27.008] job_complete: invalid JobId=52869
[2022-11-17T16:07:27.008] _slurm_rpc_complete_job_allocation: JobId=52869 error Invalid job id specified
[2022-11-17T16:07:27.010] job_complete: invalid JobId=52869
[2022-11-17T16:07:27.010] _slurm_rpc_complete_job_allocation: JobId=52869 error Invalid job id specified
[2022-11-17T16:07:27.011] job_complete: invalid JobId=52879
[2022-11-17T16:07:27.011] _slurm_rpc_complete_job_allocation: JobId=52879 error Invalid job id specified
[2022-11-17T16:12:45.483] _job_complete: JobId=52671 WEXITSTATUS 1
[2022-11-17T16:12:45.488] _job_complete: JobId=52671 done
[2022-11-17T16:17:06.624] _job_complete: JobId=52805 WEXITSTATUS 0
[2022-11-17T16:17:06.625] _job_complete: JobId=52805 done
[2022-11-17T16:17:07.874] sched: Allocate JobId=52809 NodeList=cpu08 #CPUs=64 Partition=cpu-opteron
[2022-11-17T16:17:08.663] _slurm_rpc_submit_batch_job: JobId=52881 InitPrio=806 usec=536
[2022-11-17T16:17:28.661] sched/backfill: _start_job: Started JobId=52881 in cpu-opteron on cpu07
[2022-11-17T16:17:35.466] _job_complete: JobId=52881 WEXITSTATUS 127
[2022-11-17T16:17:35.466] _job_complete: JobId=52881 done
[2022-11-17T16:24:42.780] _slurm_rpc_submit_batch_job: JobId=52882 InitPrio=806 usec=515
[2022-11-17T16:25:28.679] sched/backfill: _start_job: Started JobId=52882 in cpu-opteron on cpu07
[2022-11-17T16:25:30.420] _job_complete: JobId=52882 WEXITSTATUS 2
[2022-11-17T16:25:30.420] _job_complete: JobId=52882 done
[2022-11-17T16:26:15.468] _slurm_rpc_submit_batch_job: JobId=52883 InitPrio=10806 usec=547
[2022-11-17T16:26:16.448] sched: Allocate JobId=52883 NodeList=cpu07 #CPUs=1 Partition=cpu-opteron
[2022-11-17T16:26:25.136] _job_complete: JobId=52880 WEXITSTATUS 0
[2022-11-17T16:26:25.136] _job_complete: JobId=52880 done
[2022-11-17T16:26:28.156] _job_complete: JobId=52883 WEXITSTATUS 0
[2022-11-17T16:26:28.156] _job_complete: JobId=52883 done
[2022-11-17T16:40:21.573] _slurm_rpc_submit_batch_job: JobId=52884 InitPrio=10806 usec=471
[2022-11-17T16:40:21.879] sched: Allocate JobId=52884 NodeList=cpu07 #CPUs=1 Partition=cpu-opteron
[2022-11-17T16:40:23.805] _job_complete: JobId=52884 WEXITSTATUS 1
[2022-11-17T16:40:23.805] _job_complete: JobId=52884 done
[2022-11-17T16:48:21.594] _job_complete: JobId=52809 WEXITSTATUS 0
[2022-11-17T16:48:21.595] _job_complete: JobId=52809 done
[2022-11-17T16:48:22.383] sched: Allocate JobId=52762 NodeList=cpu08 #CPUs=64 Partition=cpu-opteron
[2022-11-17T16:48:29.833] _slurm_rpc_submit_batch_job: JobId=52885 InitPrio=10806 usec=545
[2022-11-17T16:48:30.764] sched: Allocate JobId=52885 NodeList=cpu07 #CPUs=1 Partition=cpu-opteron
[2022-11-17T16:48:32.441] _job_complete: JobId=52885 WEXITSTATUS 1
[2022-11-17T16:48:32.441] _job_complete: JobId=52885 done
[2022-11-17T16:52:09.810] _slurm_rpc_submit_batch_job: JobId=52886 InitPrio=10806 usec=554
[2022-11-17T16:52:10.137] sched: Allocate JobId=52886 NodeList=cpu07 #CPUs=1 Partition=cpu-opteron
[2022-11-17T16:52:11.986] _job_complete: JobId=52886 WEXITSTATUS 1
[2022-11-17T16:52:11.986] _job_complete: JobId=52886 done
[2022-11-17T16:53:47.402] _slurm_rpc_submit_batch_job: JobId=52887 InitPrio=10806 usec=548
[2022-11-17T16:53:48.260] sched: Allocate JobId=52887 NodeList=cpu07 #CPUs=1 Partition=cpu-opteron
[2022-11-17T16:53:51.230] _job_complete: JobId=52887 WEXITSTATUS 0
[2022-11-17T16:53:51.230] _job_complete: JobId=52887 done
[2022-11-17T16:58:52.792] _slurm_rpc_submit_batch_job: JobId=52888 InitPrio=10806 usec=573
[2022-11-17T16:58:53.720] sched: Allocate JobId=52888 NodeList=cpu07 #CPUs=1 Partition=cpu-opteron
[2022-11-17T16:58:55.707] _job_complete: JobId=52888 WEXITSTATUS 1
[2022-11-17T16:58:55.707] _job_complete: JobId=52888 done
[2022-11-17T16:59:55.841] _slurm_rpc_submit_batch_job: JobId=52889 InitPrio=10806 usec=515
[2022-11-17T16:59:56.800] sched: Allocate JobId=52889 NodeList=cpu07 #CPUs=1 Partition=cpu-opteron
[2022-11-17T17:00:00.103] _job_complete: JobId=52889 WEXITSTATUS 0
[2022-11-17T17:00:00.103] _job_complete: JobId=52889 done
[2022-11-17T17:02:21.937] _slurm_rpc_submit_batch_job: JobId=52890 InitPrio=10806 usec=572
[2022-11-17T17:02:22.073] sched: Allocate JobId=52890 NodeList=cpu07 #CPUs=1 Partition=cpu-opteron
[2022-11-17T17:02:25.419] _job_complete: JobId=52890 WEXITSTATUS 0
[2022-11-17T17:02:25.419] _job_complete: JobId=52890 done
[2022-11-17T17:04:37.205] _slurm_rpc_submit_batch_job: JobId=52891 InitPrio=10806 usec=474
[2022-11-17T17:04:37.243] sched: Allocate JobId=52891 NodeList=cpu07 #CPUs=1 Partition=cpu-opteron
[2022-11-17T17:04:39.673] _job_complete: JobId=52891 WEXITSTATUS 0
[2022-11-17T17:04:39.673] _job_complete: JobId=52891 done
[2022-11-17T17:08:57.539] _slurm_rpc_kill_job: REQUEST_KILL_JOB JobId=52829 uid 548300642
[2022-11-17T17:14:06.465] cleanup_completing: JobId=52829 completion process took 309 seconds
[2022-11-17T17:14:06.467] sched: Allocate JobId=52763 NodeList=cpu01 #CPUs=64 Partition=cpu-opteron
[2022-11-17T17:16:05.474] _slurm_rpc_submit_batch_job: JobId=52892 InitPrio=604 usec=555
[2022-11-17T18:17:56.999] _job_complete: JobId=52855 WEXITSTATUS 0
[2022-11-17T18:17:56.999] _job_complete: JobId=52855 done
[2022-11-17T18:18:28.926] sched/backfill: _start_job: Started JobId=52861 in cpu-opteron on cpu07
[2022-11-17T18:18:39.812] _job_complete: JobId=52856 WEXITSTATUS 0
[2022-11-17T18:18:39.812] _job_complete: JobId=52856 done
[2022-11-17T18:19:28.929] sched/backfill: _start_job: Started JobId=52862 in cpu-opteron on cpu07
[2022-11-17T18:32:33.488] _job_complete: JobId=52857 WEXITSTATUS 0
[2022-11-17T18:32:33.489] _job_complete: JobId=52857 done
[2022-11-17T18:33:28.959] sched/backfill: _start_job: Started JobId=52863 in cpu-opteron on cpu07
[2022-11-17T18:39:01.737] _job_complete: JobId=52858 WEXITSTATUS 0
[2022-11-17T18:39:01.737] _job_complete: JobId=52858 done
[2022-11-17T18:39:28.973] sched/backfill: _start_job: Started JobId=52864 in cpu-opteron on cpu10
[2022-11-17T18:47:17.505] _job_complete: JobId=52860 WEXITSTATUS 0
[2022-11-17T18:47:17.505] _job_complete: JobId=52860 done
[2022-11-17T18:47:28.990] sched/backfill: _start_job: Started JobId=52865 in cpu-opteron on cpu10
[2022-11-17T20:15:37.375] _slurm_rpc_submit_batch_job: JobId=52893 InitPrio=2419 usec=640
[2022-11-17T20:33:22.368] _job_complete: JobId=52859 WEXITSTATUS 0
[2022-11-17T20:33:22.369] _job_complete: JobId=52859 done
[2022-11-17T20:33:29.213] sched/backfill: _start_job: Started JobId=52870 in cpu-opteron on cpu10
[2022-11-17T20:54:00.409] _job_complete: JobId=52862 WEXITSTATUS 0
[2022-11-17T20:54:00.409] _job_complete: JobId=52862 done
[2022-11-17T20:54:29.256] sched/backfill: _start_job: Started JobId=52871 in cpu-opteron on cpu07
[2022-11-17T21:03:31.180] _job_complete: JobId=52830 WEXITSTATUS 0
[2022-11-17T21:03:31.180] _job_complete: JobId=52830 done
[2022-11-17T21:11:26.451] _job_complete: JobId=52863 WEXITSTATUS 0
[2022-11-17T21:11:26.451] _job_complete: JobId=52863 done
[2022-11-17T21:11:29.289] sched/backfill: _start_job: Started JobId=52872 in cpu-opteron on cpu07
[2022-11-17T21:14:02.275] _job_complete: JobId=52861 WEXITSTATUS 0
[2022-11-17T21:14:02.275] _job_complete: JobId=52861 done
[2022-11-17T21:14:29.296] sched/backfill: _start_job: Started JobId=52873 in cpu-opteron on cpu07
[2022-11-17T21:16:34.070] _job_complete: JobId=52759 WEXITSTATUS 0
[2022-11-17T21:16:34.070] _job_complete: JobId=52759 done
[2022-11-17T21:16:35.473] sched: Allocate JobId=52764 NodeList=cpu09 #CPUs=64 Partition=cpu-opteron
[2022-11-17T21:17:25.269] _job_complete: JobId=52864 WEXITSTATUS 0
[2022-11-17T21:17:25.269] _job_complete: JobId=52864 done
[2022-11-17T21:17:29.302] sched/backfill: _start_job: Started JobId=52874 in cpu-opteron on cpu10
[2022-11-17T21:24:48.986] _job_complete: JobId=52831 WEXITSTATUS 0
[2022-11-17T21:24:48.986] _job_complete: JobId=52831 done
[2022-11-17T21:49:13.462] _job_complete: JobId=52865 WEXITSTATUS 0
[2022-11-17T21:49:13.463] _job_complete: JobId=52865 done
[2022-11-17T21:49:29.362] sched/backfill: _start_job: Started JobId=52875 in cpu-opteron on cpu10
[2022-11-17T23:16:23.255] _job_complete: JobId=52870 WEXITSTATUS 0
[2022-11-17T23:16:23.256] _job_complete: JobId=52870 done
[2022-11-17T23:16:29.519] sched/backfill: _start_job: Started JobId=52876 in cpu-opteron on cpu10
[2022-11-17T23:33:50.152] _job_complete: JobId=52871 WEXITSTATUS 0
[2022-11-17T23:33:50.152] _job_complete: JobId=52871 done
[2022-11-17T23:34:29.550] sched/backfill: _start_job: Started JobId=52877 in cpu-opteron on cpu07
[2022-11-17T23:56:17.626] _job_complete: JobId=52872 WEXITSTATUS 0
[2022-11-17T23:56:17.626] _job_complete: JobId=52872 done
[2022-11-17T23:56:29.588] sched/backfill: _start_job: Started JobId=52878 in cpu-opteron on cpu07
[2022-11-17T23:59:03.898] _job_complete: JobId=52874 WEXITSTATUS 0
[2022-11-17T23:59:03.898] _job_complete: JobId=52874 done
[2022-11-18T00:03:19.921] _job_complete: JobId=52873 WEXITSTATUS 0
[2022-11-18T00:03:19.921] _job_complete: JobId=52873 done
[2022-11-18T00:41:02.472] _job_complete: JobId=52875 WEXITSTATUS 0
[2022-11-18T00:41:02.472] _job_complete: JobId=52875 done
[2022-11-18T00:42:46.322] _job_complete: JobId=52670 WEXITSTATUS 1
[2022-11-18T00:42:46.327] _job_complete: JobId=52670 done
[2022-11-18T01:57:20.000] _job_complete: JobId=52876 WEXITSTATUS 0
[2022-11-18T01:57:20.000] _job_complete: JobId=52876 done
[2022-11-18T02:18:08.931] _job_complete: JobId=52877 WEXITSTATUS 0
[2022-11-18T02:18:08.932] _job_complete: JobId=52877 done
[2022-11-18T02:41:49.610] _job_complete: JobId=52878 WEXITSTATUS 0
[2022-11-18T02:41:49.610] _job_complete: JobId=52878 done
[2022-11-18T02:41:50.442] sched: Allocate JobId=52765 NodeList=cpu07 #CPUs=64 Partition=cpu-opteron
[2022-11-18T04:51:09.697] _job_complete: JobId=52658 WEXITSTATUS 0
[2022-11-18T04:51:09.702] _job_complete: JobId=52658 done
[2022-11-18T08:27:31.427] sched: _slurm_rpc_allocate_resources JobId=52894 NodeList=(null) usec=1119
[2022-11-18T08:27:32.385] sched: Allocate JobId=52894 NodeList=cpu10 #CPUs=32 Partition=cpu-opteron
[2022-11-18T09:03:55.878] _slurm_rpc_submit_batch_job: JobId=52895 InitPrio=2419 usec=608
[2022-11-18T09:09:10.884] _slurm_rpc_kill_job: REQUEST_KILL_JOB JobId=52895 uid 548300630
[2022-11-18T09:39:37.424] _job_complete: JobId=52894 WEXITSTATUS 0
[2022-11-18T09:39:37.424] _job_complete: JobId=52894 done
[2022-11-18T10:01:24.084] _slurm_rpc_submit_batch_job: JobId=52896 InitPrio=2419 usec=588
[2022-11-18T10:01:24.920] sched: Allocate JobId=52896 NodeList=cpu10 #CPUs=32 Partition=cpu-opteron
[2022-11-18T10:01:59.101] _slurm_rpc_kill_job: REQUEST_KILL_JOB JobId=52893 uid 548300630
[2022-11-18T10:02:30.447] sched/backfill: _start_job: Started JobId=52832 in cpu-epyc on cpu15
[2022-11-18T10:02:30.448] sched/backfill: _start_job: Started JobId=52833 in cpu-epyc on cpu15
[2022-11-18T13:37:55.024] _slurm_rpc_submit_batch_job: JobId=52897 InitPrio=2822 usec=574
[2022-11-18T13:38:45.326] _slurm_rpc_kill_job: REQUEST_KILL_JOB JobId=52897 uid 548200121
[2022-11-18T13:48:07.495] _slurm_rpc_submit_batch_job: JobId=52898 InitPrio=18870 usec=691
[2022-11-18T13:48:08.460] sched: Allocate JobId=52898 NodeList=cpu10 #CPUs=1 Partition=cpu-opteron
[2022-11-18T13:48:56.506] Time limit exhausted for JobId=52401
[2022-11-18T13:49:01.540] sched: Allocate JobId=52804 NodeList=cpu13 #CPUs=8 Partition=cpu-epyc
[2022-11-18T13:49:44.551] _job_complete: JobId=52898 WEXITSTATUS 0
[2022-11-18T13:49:44.551] _job_complete: JobId=52898 done
[2022-11-18T13:55:20.569] _slurm_rpc_submit_batch_job: JobId=52899 InitPrio=18870 usec=581
[2022-11-18T13:55:21.138] sched: Allocate JobId=52899 NodeList=cpu10 #CPUs=1 Partition=cpu-opteron
[2022-11-18T13:57:58.567] _job_complete: JobId=52899 WEXITSTATUS 0
[2022-11-18T13:57:58.567] _job_complete: JobId=52899 done
[2022-11-18T14:05:20.389] _slurm_rpc_submit_batch_job: JobId=52900 InitPrio=8870 usec=653
[2022-11-18T14:05:21.172] sched: Allocate JobId=52900 NodeList=cpu10 #CPUs=1 Partition=cpu-opteron
[2022-11-18T14:05:32.097] _job_complete: JobId=52900 WEXITSTATUS 1
[2022-11-18T14:05:32.097] _job_complete: JobId=52900 done
[2022-11-18T14:08:47.918] _slurm_rpc_submit_batch_job: JobId=52901 InitPrio=8870 usec=555
[2022-11-18T14:08:48.608] sched: Allocate JobId=52901 NodeList=cpu10 #CPUs=1 Partition=cpu-opteron
[2022-11-18T14:17:33.081] _job_complete: JobId=52804 OOM failure
[2022-11-18T14:17:33.081] _job_complete: JobId=52804 done
[2022-11-18T14:17:33.417] sched: Allocate JobId=52726 NodeList=cpu13 #CPUs=48 Partition=cpu-epyc
[2022-11-18T15:18:59.789] _job_complete: JobId=52714 WEXITSTATUS 1
[2022-11-18T15:18:59.790] _job_complete: JobId=52714 done
[2022-11-18T15:19:30.870] sched/backfill: _start_job: Started JobId=52834 in cpu-epyc on cpu12
[2022-11-18T15:19:30.871] sched/backfill: _start_job: Started JobId=52835 in cpu-epyc on cpu12
[2022-11-18T15:42:08.989] _job_complete: JobId=52901 WEXITSTATUS 0
[2022-11-18T15:42:08.990] _job_complete: JobId=52901 done
[2022-11-18T15:44:30.563] _slurm_rpc_submit_batch_job: JobId=52902 InitPrio=18433 usec=736
[2022-11-18T15:44:30.917] sched/backfill: _start_job: Started JobId=52902 in cpu-opteron on cpu10
[2022-11-18T15:46:02.412] _job_complete: JobId=52902 WEXITSTATUS 0
[2022-11-18T15:46:02.412] _job_complete: JobId=52902 done
[2022-11-18T15:49:40.494] _slurm_rpc_submit_batch_job: JobId=52903 InitPrio=8433 usec=626
[2022-11-18T15:49:40.496] sched: Allocate JobId=52903 NodeList=cpu10 #CPUs=1 Partition=cpu-opteron
[2022-11-18T15:51:29.075] _slurm_rpc_submit_batch_job: JobId=52904 InitPrio=2811 usec=472
[2022-11-18T15:52:04.098] _slurm_rpc_kill_job: REQUEST_KILL_JOB JobId=52904 uid 548200121
[2022-11-18T15:52:16.121] _slurm_rpc_submit_batch_job: JobId=52905 InitPrio=2811 usec=402
[2022-11-18T15:53:06.482] _slurm_rpc_kill_job: REQUEST_KILL_JOB JobId=52905 uid 548200121
[2022-11-18T15:53:20.359] _slurm_rpc_submit_batch_job: JobId=52906 InitPrio=2811 usec=452
[2022-11-18T15:56:01.008] _slurm_rpc_kill_job: REQUEST_KILL_JOB JobId=52906 uid 548200121
[2022-11-18T15:56:28.569] _slurm_rpc_submit_batch_job: JobId=52907 InitPrio=2811 usec=465
[2022-11-18T15:57:06.653] _slurm_rpc_kill_job: REQUEST_KILL_JOB JobId=52907 uid 548200121
[2022-11-18T16:01:41.282] _slurm_rpc_submit_batch_job: JobId=52908 InitPrio=2811 usec=480
[2022-11-18T16:02:22.359] _slurm_rpc_submit_batch_job: JobId=52909 InitPrio=2811 usec=414
[2022-11-18T16:02:23.116] sched: Allocate JobId=52909 NodeList=cpu10 #CPUs=16 Partition=cpu-opteron
[2022-11-18T16:02:30.943] sched/backfill: _start_job: Started JobId=52908 in cpu-epyc on cpu12
[2022-11-18T16:37:10.775] _job_complete: JobId=52903 WEXITSTATUS 0
[2022-11-18T16:37:10.775] _job_complete: JobId=52903 done
[2022-11-18T16:39:15.790] _slurm_rpc_submit_batch_job: JobId=52910 InitPrio=18433 usec=643
[2022-11-18T16:39:15.821] sched: Allocate JobId=52910 NodeList=cpu10 #CPUs=1 Partition=cpu-opteron
[2022-11-18T16:40:47.911] _job_complete: JobId=52910 WEXITSTATUS 0
[2022-11-18T16:40:47.911] _job_complete: JobId=52910 done
[2022-11-18T16:44:35.996] _slurm_rpc_submit_batch_job: JobId=52911 InitPrio=8433 usec=518
[2022-11-18T16:44:36.300] sched: Allocate JobId=52911 NodeList=cpu10 #CPUs=1 Partition=cpu-opteron
[2022-11-18T17:30:02.407] _job_complete: JobId=52911 WEXITSTATUS 0
[2022-11-18T17:30:02.407] _job_complete: JobId=52911 done
[2022-11-18T17:32:59.877] _slurm_rpc_submit_batch_job: JobId=52912 InitPrio=18433 usec=610
[2022-11-18T17:33:00.332] sched: Allocate JobId=52912 NodeList=cpu10 #CPUs=1 Partition=cpu-opteron
[2022-11-18T17:34:31.134] _job_complete: JobId=52912 WEXITSTATUS 0
[2022-11-18T17:34:31.134] _job_complete: JobId=52912 done
[2022-11-18T17:37:49.540] _slurm_rpc_submit_batch_job: JobId=52913 InitPrio=18433 usec=609
[2022-11-18T17:37:49.779] sched: Allocate JobId=52913 NodeList=cpu10 #CPUs=1 Partition=cpu-opteron
[2022-11-18T18:32:57.671] Time limit exhausted for JobId=52913
[2022-11-18T19:56:09.403] _slurm_rpc_submit_batch_job: JobId=52914 InitPrio=1405 usec=583
[2022-11-18T20:12:36.549] _job_complete: JobId=52833 WEXITSTATUS 0
[2022-11-18T20:12:36.550] _job_complete: JobId=52833 done
[2022-11-18T20:13:04.887] _job_complete: JobId=52832 WEXITSTATUS 0
[2022-11-18T20:13:04.887] _job_complete: JobId=52832 done
[2022-11-18T20:13:31.324] sched/backfill: _start_job: Started JobId=52836 in cpu-epyc on cpu15
[2022-11-18T20:13:31.325] sched/backfill: _start_job: Started JobId=52837 in cpu-epyc on cpu15
[2022-11-18T20:22:38.794] _slurm_rpc_kill_job: REQUEST_KILL_JOB JobId=52914 uid 548300593
[2022-11-18T20:22:41.998] _slurm_rpc_submit_batch_job: JobId=52915 InitPrio=602 usec=493
[2022-11-18T20:23:03.629] _slurm_rpc_kill_job: REQUEST_KILL_JOB JobId=52892 uid 548200017
[2022-11-18T20:28:58.060] _slurm_rpc_submit_batch_job: JobId=52916 InitPrio=1405 usec=456
[2022-11-18T21:40:21.108] _slurm_rpc_submit_batch_job: JobId=52917 InitPrio=2811 usec=593
[2022-11-18T22:49:42.416] _job_complete: JobId=52823 WEXITSTATUS 0
[2022-11-18T22:49:42.422] _job_complete: JobId=52823 done
[2022-11-18T23:22:57.435] _slurm_rpc_submit_batch_job: JobId=52918 InitPrio=1606 usec=1046
[2022-11-18T23:24:16.975] _slurm_rpc_submit_batch_job: JobId=52919 InitPrio=1606 usec=783
[2022-11-18T23:24:17.414] sched: Allocate JobId=52919 NodeList=gpu04 #CPUs=16 Partition=gpu-k40c
[2022-11-18T23:35:27.191] _slurm_rpc_submit_batch_job: JobId=52920 InitPrio=1405 usec=631
[2022-11-19T00:01:09.054] _slurm_rpc_kill_job: REQUEST_KILL_JOB JobId=52675 uid 548200029
[2022-11-19T00:01:16.736] _slurm_rpc_submit_batch_job: JobId=52921 InitPrio=1606 usec=1241
[2022-11-19T00:03:24.368] _slurm_rpc_submit_batch_job: JobId=52922 InitPrio=1606 usec=1184
[2022-11-19T00:06:28.671] _slurm_rpc_submit_batch_job: JobId=52923 InitPrio=1606 usec=648
[2022-11-19T01:35:24.687] _job_complete: JobId=52835 WEXITSTATUS 0
[2022-11-19T01:35:24.688] _job_complete: JobId=52835 done
[2022-11-19T01:45:27.404] _job_complete: JobId=52834 WEXITSTATUS 0
[2022-11-19T01:45:27.404] _job_complete: JobId=52834 done
[2022-11-19T02:13:00.547] _slurm_rpc_submit_batch_job: JobId=52924 InitPrio=18433 usec=679
[2022-11-19T02:13:01.213] sched: Allocate JobId=52924 NodeList=cpu10 #CPUs=1 Partition=cpu-opteron
[2022-11-19T02:13:13.814] _job_complete: JobId=52924 WEXITSTATUS 1
[2022-11-19T02:13:13.814] _job_complete: JobId=52924 done
[2022-11-19T02:15:00.672] _slurm_rpc_submit_batch_job: JobId=52925 InitPrio=8433 usec=581
[2022-11-19T06:14:12.006] _job_complete: JobId=52837 WEXITSTATUS 0
[2022-11-19T06:14:12.007] _job_complete: JobId=52837 done
[2022-11-19T06:15:47.653] _job_complete: JobId=52836 WEXITSTATUS 0
[2022-11-19T06:15:47.653] _job_complete: JobId=52836 done
[2022-11-19T07:26:16.721] _job_complete: JobId=52764 WEXITSTATUS 0
[2022-11-19T07:26:16.721] _job_complete: JobId=52764 done
[2022-11-19T07:26:18.012] sched: Allocate JobId=52925 NodeList=cpu09 #CPUs=1 Partition=cpu-opteron
[2022-11-19T08:22:09.623] _job_complete: JobId=52925 WEXITSTATUS 0
[2022-11-19T08:22:09.623] _job_complete: JobId=52925 done
[2022-11-19T08:39:26.924] _slurm_rpc_submit_batch_job: JobId=52926 InitPrio=8232 usec=738
[2022-11-19T08:39:27.046] sched: Allocate JobId=52926 NodeList=cpu09 #CPUs=1 Partition=cpu-opteron
[2022-11-19T09:04:46.012] _slurm_rpc_kill_job: REQUEST_KILL_JOB JobId=52926 uid 548200013
[2022-11-19T09:06:09.883] _slurm_rpc_submit_batch_job: JobId=52927 InitPrio=18232 usec=716
[2022-11-19T09:06:10.761] sched: Allocate JobId=52927 NodeList=cpu09 #CPUs=1 Partition=cpu-opteron
[2022-11-19T09:08:13.810] _job_complete: JobId=52927 WEXITSTATUS 0
[2022-11-19T09:08:13.811] _job_complete: JobId=52927 done
[2022-11-19T09:22:05.702] _slurm_rpc_submit_batch_job: JobId=52928 InitPrio=18232 usec=665
[2022-11-19T09:22:06.559] sched: Allocate JobId=52928 NodeList=cpu09 #CPUs=1 Partition=cpu-opteron
[2022-11-19T09:22:31.007] _job_complete: JobId=52928 WEXITSTATUS 0
[2022-11-19T09:22:31.007] _job_complete: JobId=52928 done
[2022-11-19T09:33:13.656] _slurm_rpc_submit_batch_job: JobId=52929 InitPrio=18232 usec=601
[2022-11-19T09:33:13.853] sched: Allocate JobId=52929 NodeList=cpu09 #CPUs=1 Partition=cpu-opteron
[2022-11-19T09:35:09.627] _job_complete: JobId=52929 WEXITSTATUS 0
[2022-11-19T09:35:09.627] _job_complete: JobId=52929 done
[2022-11-19T09:43:23.343] _slurm_rpc_submit_batch_job: JobId=52930 InitPrio=18232 usec=661
[2022-11-19T09:43:23.382] sched: Allocate JobId=52930 NodeList=cpu09 #CPUs=1 Partition=cpu-opteron
[2022-11-19T09:43:44.134] _job_complete: JobId=52930 WEXITSTATUS 0
[2022-11-19T09:43:44.134] _job_complete: JobId=52930 done
[2022-11-19T09:46:35.242] _slurm_rpc_submit_batch_job: JobId=52931 InitPrio=18232 usec=519
[2022-11-19T09:46:35.786] sched: Allocate JobId=52931 NodeList=cpu09 #CPUs=1 Partition=cpu-opteron
[2022-11-19T09:48:09.573] _job_complete: JobId=52931 WEXITSTATUS 0
[2022-11-19T09:48:09.574] _job_complete: JobId=52931 done
[2022-11-19T09:52:28.573] _slurm_rpc_submit_batch_job: JobId=52932 InitPrio=18232 usec=618
[2022-11-19T09:52:29.432] sched: Allocate JobId=52932 NodeList=cpu09 #CPUs=1 Partition=cpu-opteron
[2022-11-19T09:52:50.083] _job_complete: JobId=52932 WEXITSTATUS 0
[2022-11-19T09:52:50.083] _job_complete: JobId=52932 done
[2022-11-19T09:55:54.932] _slurm_rpc_submit_batch_job: JobId=52933 InitPrio=18232 usec=597
[2022-11-19T09:55:55.678] sched: Allocate JobId=52933 NodeList=cpu09 #CPUs=1 Partition=cpu-opteron
[2022-11-19T09:57:26.895] _job_complete: JobId=52933 WEXITSTATUS 0
[2022-11-19T09:57:26.895] _job_complete: JobId=52933 done
[2022-11-19T10:06:47.814] _slurm_rpc_submit_batch_job: JobId=52934 InitPrio=18232 usec=677
[2022-11-19T10:06:47.961] sched: Allocate JobId=52934 NodeList=cpu09 #CPUs=1 Partition=cpu-opteron
[2022-11-19T10:09:27.615] _job_complete: JobId=52934 WEXITSTATUS 0
[2022-11-19T10:09:27.616] _job_complete: JobId=52934 done
[2022-11-19T10:15:53.494] _slurm_rpc_submit_batch_job: JobId=52935 InitPrio=18232 usec=779
[2022-11-19T10:15:53.866] sched: Allocate JobId=52935 NodeList=cpu09 #CPUs=1 Partition=cpu-opteron
[2022-11-19T10:16:13.664] _job_complete: JobId=52935 WEXITSTATUS 127
[2022-11-19T10:16:13.664] _job_complete: JobId=52935 done
[2022-11-19T10:20:34.184] _slurm_rpc_submit_batch_job: JobId=52936 InitPrio=18232 usec=640
[2022-11-19T10:20:34.288] sched: Allocate JobId=52936 NodeList=cpu09 #CPUs=1 Partition=cpu-opteron
[2022-11-19T10:20:53.663] _job_complete: JobId=52936 WEXITSTATUS 127
[2022-11-19T10:20:53.663] _job_complete: JobId=52936 done
[2022-11-19T10:23:32.143] _slurm_rpc_submit_batch_job: JobId=52937 InitPrio=18232 usec=574
[2022-11-19T10:23:32.685] sched: Allocate JobId=52937 NodeList=cpu09 #CPUs=1 Partition=cpu-opteron
[2022-11-19T10:23:51.949] _job_complete: JobId=52937 WEXITSTATUS 127
[2022-11-19T10:23:51.949] _job_complete: JobId=52937 done
[2022-11-19T10:29:45.505] _slurm_rpc_submit_batch_job: JobId=52938 InitPrio=18232 usec=601
[2022-11-19T10:29:46.299] sched: Allocate JobId=52938 NodeList=cpu09 #CPUs=1 Partition=cpu-opteron
[2022-11-19T10:31:54.176] _job_complete: JobId=52938 WEXITSTATUS 0
[2022-11-19T10:31:54.176] _job_complete: JobId=52938 done
[2022-11-19T10:34:24.187] _slurm_rpc_submit_batch_job: JobId=52939 InitPrio=18232 usec=703
[2022-11-19T10:34:24.777] sched: Allocate JobId=52939 NodeList=cpu09 #CPUs=1 Partition=cpu-opteron
[2022-11-19T10:43:57.904] _job_complete: JobId=52939 WEXITSTATUS 0
[2022-11-19T10:43:57.904] _job_complete: JobId=52939 done
[2022-11-19T10:54:49.869] _slurm_rpc_submit_batch_job: JobId=52940 InitPrio=18232 usec=579
[2022-11-19T10:54:50.860] sched: Allocate JobId=52940 NodeList=cpu09 #CPUs=1 Partition=cpu-opteron
[2022-11-19T10:55:14.593] _job_complete: JobId=52940 WEXITSTATUS 0
[2022-11-19T10:55:14.593] _job_complete: JobId=52940 done
[2022-11-19T11:09:57.216] _slurm_rpc_submit_batch_job: JobId=52941 InitPrio=18232 usec=665
[2022-11-19T11:09:57.479] sched: Allocate JobId=52941 NodeList=cpu09 #CPUs=1 Partition=cpu-opteron
[2022-11-19T11:10:22.876] _job_complete: JobId=52941 WEXITSTATUS 1
[2022-11-19T11:10:22.876] _job_complete: JobId=52941 done
[2022-11-19T11:15:38.993] _job_complete: JobId=52068 WEXITSTATUS 0
[2022-11-19T11:15:38.993] _job_complete: JobId=52068 done
[2022-11-19T11:15:40.087] sched: Allocate JobId=52638 NodeList=gpu05 #CPUs=16 Partition=gpu-v100s
[2022-11-19T11:15:40.148] sched: Allocate JobId=52434 NodeList=gpu05 #CPUs=4 Partition=gpu-v100s
[2022-11-19T11:32:48.245] _slurm_rpc_submit_batch_job: JobId=52942 InitPrio=18232 usec=631
[2022-11-19T11:32:48.948] sched: Allocate JobId=52942 NodeList=cpu09 #CPUs=1 Partition=cpu-opteron
[2022-11-19T11:33:11.490] _job_complete: JobId=52942 WEXITSTATUS 0
[2022-11-19T11:33:11.491] _job_complete: JobId=52942 done
[2022-11-19T11:36:59.054] _slurm_rpc_submit_batch_job: JobId=52943 InitPrio=18232 usec=639
[2022-11-19T11:36:59.411] sched: Allocate JobId=52943 NodeList=cpu09 #CPUs=1 Partition=cpu-opteron
[2022-11-19T11:37:34.387] _job_complete: JobId=52943 WEXITSTATUS 0
[2022-11-19T11:37:34.387] _job_complete: JobId=52943 done
[2022-11-19T11:44:12.411] _slurm_rpc_submit_batch_job: JobId=52944 InitPrio=18232 usec=626
[2022-11-19T11:44:13.024] sched: Allocate JobId=52944 NodeList=cpu10 #CPUs=1 Partition=cpu-opteron
[2022-11-19T11:44:35.953] _job_complete: JobId=52944 WEXITSTATUS 0
[2022-11-19T11:44:35.954] _job_complete: JobId=52944 done
[2022-11-19T11:45:42.811] _slurm_rpc_submit_batch_job: JobId=52945 InitPrio=18232 usec=549
[2022-11-19T11:45:43.130] sched: Allocate JobId=52945 NodeList=cpu10 #CPUs=1 Partition=cpu-opteron
[2022-11-19T11:46:03.227] _job_complete: JobId=52945 WEXITSTATUS 0
[2022-11-19T11:46:03.227] _job_complete: JobId=52945 done
[2022-11-19T11:47:36.328] _slurm_rpc_submit_batch_job: JobId=52946 InitPrio=18232 usec=602
[2022-11-19T11:47:36.410] sched: Allocate JobId=52946 NodeList=cpu10 #CPUs=1 Partition=cpu-opteron
[2022-11-19T11:48:00.722] _job_complete: JobId=52946 WEXITSTATUS 0
[2022-11-19T11:48:00.723] _job_complete: JobId=52946 done
[2022-11-19T11:51:35.357] _slurm_rpc_submit_batch_job: JobId=52947 InitPrio=18232 usec=551
[2022-11-19T11:51:35.809] sched: Allocate JobId=52947 NodeList=cpu10 #CPUs=1 Partition=cpu-opteron
[2022-11-19T11:51:58.339] _job_complete: JobId=52947 WEXITSTATUS 0
[2022-11-19T11:51:58.339] _job_complete: JobId=52947 done
[2022-11-19T11:59:12.405] _slurm_rpc_submit_batch_job: JobId=52948 InitPrio=18232 usec=542
[2022-11-19T11:59:12.481] sched: Allocate JobId=52948 NodeList=cpu10 #CPUs=1 Partition=cpu-opteron
[2022-11-19T11:59:55.890] _job_complete: JobId=52948 WEXITSTATUS 0
[2022-11-19T11:59:55.891] _job_complete: JobId=52948 done
[2022-11-19T12:14:04.084] _slurm_rpc_submit_batch_job: JobId=52949 InitPrio=18232 usec=605
[2022-11-19T12:14:04.304] sched: Allocate JobId=52949 NodeList=cpu10 #CPUs=1 Partition=cpu-opteron
[2022-11-19T12:14:31.048] _job_complete: JobId=52949 WEXITSTATUS 0
[2022-11-19T12:14:31.048] _job_complete: JobId=52949 done
[2022-11-19T12:22:23.048] _slurm_rpc_submit_batch_job: JobId=52950 InitPrio=18232 usec=640
[2022-11-19T12:22:23.612] sched: Allocate JobId=52950 NodeList=cpu10 #CPUs=1 Partition=cpu-opteron
[2022-11-19T12:23:06.512] _job_complete: JobId=52950 WEXITSTATUS 0
[2022-11-19T12:23:06.513] _job_complete: JobId=52950 done
[2022-11-19T12:48:07.796] _slurm_rpc_submit_batch_job: JobId=52951 InitPrio=8232 usec=643
[2022-11-19T12:48:08.269] sched: Allocate JobId=52951 NodeList=cpu09 #CPUs=1 Partition=cpu-opteron
[2022-11-19T12:48:35.090] _job_complete: JobId=52951 WEXITSTATUS 1
[2022-11-19T12:48:35.090] _job_complete: JobId=52951 done
[2022-11-19T12:51:22.373] _slurm_rpc_submit_batch_job: JobId=52952 InitPrio=8232 usec=568
[2022-11-19T12:51:22.591] sched: Allocate JobId=52952 NodeList=cpu09 #CPUs=1 Partition=cpu-opteron
[2022-11-19T13:15:37.075] _job_complete: JobId=52952 WEXITSTATUS 0
[2022-11-19T13:15:37.075] _job_complete: JobId=52952 done
[2022-11-19T13:20:26.684] _slurm_rpc_submit_batch_job: JobId=52953 InitPrio=18232 usec=621
[2022-11-19T13:20:27.360] sched: Allocate JobId=52953 NodeList=cpu10 #CPUs=1 Partition=cpu-opteron
[2022-11-19T13:20:46.849] _job_complete: JobId=52953 WEXITSTATUS 1
[2022-11-19T13:20:46.849] _job_complete: JobId=52953 done
[2022-11-19T13:21:44.610] _slurm_rpc_submit_batch_job: JobId=52954 InitPrio=18232 usec=573
[2022-11-19T13:21:45.577] sched: Allocate JobId=52954 NodeList=cpu10 #CPUs=1 Partition=cpu-opteron
[2022-11-19T13:22:16.955] _job_complete: JobId=52954 WEXITSTATUS 0
[2022-11-19T13:22:16.955] _job_complete: JobId=52954 done
[2022-11-19T15:03:10.887] _slurm_rpc_submit_batch_job: JobId=52955 InitPrio=2409 usec=506
[2022-11-19T15:03:11.805] sched: Allocate JobId=52955 NodeList=gpu02 #CPUs=4 Partition=gpu-titan
[2022-11-19T15:36:30.670] _job_complete: JobId=52638 WEXITSTATUS 0
[2022-11-19T15:36:30.677] _job_complete: JobId=52638 done
[2022-11-19T16:50:13.061] _slurm_rpc_submit_batch_job: JobId=52956 InitPrio=602 usec=587
[2022-11-20T11:16:03.535] Time limit exhausted for JobId=52434
[2022-11-20T11:18:39.963] _slurm_rpc_submit_batch_job: JobId=52957 InitPrio=2208 usec=495
[2022-11-20T11:20:03.686] _slurm_rpc_submit_batch_job: JobId=52958 InitPrio=2208 usec=400
[2022-11-20T11:20:03.955] sched: Allocate JobId=52958 NodeList=gpu05 #CPUs=8 Partition=gpu-v100s
[2022-11-20T11:33:47.701] _slurm_rpc_submit_batch_job: JobId=52959 InitPrio=2208 usec=439
[2022-11-20T11:33:48.413] sched: Allocate JobId=52959 NodeList=gpu05 #CPUs=8 Partition=gpu-v100s
[2022-11-20T11:55:26.627] _slurm_rpc_kill_job: REQUEST_KILL_JOB JobId=52959 uid 548200121
[2022-11-20T11:55:41.186] _slurm_rpc_submit_batch_job: JobId=52960 InitPrio=2208 usec=561
[2022-11-20T11:55:41.562] sched: Allocate JobId=52960 NodeList=gpu05 #CPUs=16 Partition=gpu-v100s
[2022-11-20T12:53:02.063] _slurm_rpc_submit_batch_job: JobId=52961 InitPrio=1606 usec=481
[2022-11-20T12:55:04.452] _slurm_rpc_submit_batch_job: JobId=52962 InitPrio=1606 usec=569
[2022-11-20T13:10:18.149] _slurm_rpc_kill_job: REQUEST_KILL_JOB JobId=52961 uid 548200029
[2022-11-20T13:10:27.619] _slurm_rpc_kill_job: REQUEST_KILL_JOB JobId=52962 uid 548200029
[2022-11-20T13:11:10.368] _slurm_rpc_submit_batch_job: JobId=52963 InitPrio=1606 usec=567
[2022-11-20T13:11:23.623] _slurm_rpc_submit_batch_job: JobId=52964 InitPrio=1606 usec=507
[2022-11-20T13:14:03.207] _slurm_rpc_submit_batch_job: JobId=52965 InitPrio=1606 usec=795
[2022-11-20T15:03:37.879] Time limit exhausted for JobId=52955
[2022-11-20T15:03:43.633] sched: Allocate JobId=52957 NodeList=gpu02 #CPUs=8 Partition=gpu-titan
[2022-11-20T18:17:03.793] _job_complete: JobId=52757 WEXITSTATUS 1
[2022-11-20T18:17:03.794] _job_complete: JobId=52757 done
[2022-11-20T21:16:38.686] Time limit exhausted for JobId=52507
[2022-11-21T05:51:52.800] _job_complete: JobId=52726 WEXITSTATUS 0
[2022-11-21T05:51:52.801] _job_complete: JobId=52726 done
[2022-11-21T08:11:31.474] _slurm_rpc_kill_job: REQUEST_KILL_JOB JobId=52960 uid 548200121
[2022-11-21T08:11:39.643] _slurm_rpc_submit_batch_job: JobId=52966 InitPrio=1807 usec=581
[2022-11-21T08:11:40.189] sched: Allocate JobId=52966 NodeList=gpu05 #CPUs=16 Partition=gpu-v100s
[2022-11-21T08:14:00.325] _slurm_rpc_kill_job: REQUEST_KILL_JOB JobId=52958 uid 548200121
[2022-11-21T08:14:07.774] _slurm_rpc_submit_batch_job: JobId=52967 InitPrio=1807 usec=446
[2022-11-21T08:16:09.819] _slurm_rpc_submit_batch_job: JobId=52968 InitPrio=1807 usec=403
[2022-11-21T08:16:16.577] _slurm_rpc_kill_job: REQUEST_KILL_JOB JobId=52967 uid 548200121
[2022-11-21T08:16:34.367] _slurm_rpc_kill_job: REQUEST_KILL_JOB JobId=52968 uid 548200121
[2022-11-21T08:16:54.249] _slurm_rpc_submit_batch_job: JobId=52969 InitPrio=1807 usec=347
[2022-11-21T08:17:37.929] _slurm_rpc_kill_job: REQUEST_KILL_JOB JobId=52969 uid 548200121
[2022-11-21T08:17:54.584] _slurm_rpc_submit_batch_job: JobId=52970 InitPrio=1807 usec=413
[2022-11-21T08:17:54.812] sched: Allocate JobId=52970 NodeList=gpu05 #CPUs=8 Partition=gpu-v100s
[2022-11-21T09:02:12.978] sched: _slurm_rpc_allocate_resources JobId=52971 NodeList=cpu05 usec=99418
[2022-11-21T10:02:12.028] _job_complete: JobId=52971 WEXITSTATUS 0
[2022-11-21T10:02:12.028] _job_complete: JobId=52971 done
[2022-11-21T10:38:47.283] sched: _slurm_rpc_allocate_resources JobId=52972 NodeList=cpu05 usec=96088
[2022-11-21T10:47:35.065] sched: _slurm_rpc_allocate_resources JobId=52973 NodeList=cpu05 usec=30117
[2022-11-21T10:59:54.878] _slurm_rpc_kill_job: REQUEST_KILL_JOB JobId=52916 uid 548300593
[2022-11-21T10:59:56.899] _slurm_rpc_kill_job: REQUEST_KILL_JOB JobId=52920 uid 548300593
[2022-11-21T11:00:11.928] _slurm_rpc_submit_batch_job: JobId=52974 InitPrio=1405 usec=521
[2022-11-21T11:00:16.756] _slurm_rpc_submit_batch_job: JobId=52975 InitPrio=1405 usec=431
[2022-11-21T11:06:03.539] _slurm_rpc_submit_batch_job: JobId=52976 InitPrio=602 usec=515
[2022-11-21T13:34:56.944] sched: _slurm_rpc_allocate_resources JobId=52977 NodeList=cpu05 usec=18623
[2022-11-21T14:11:22.703] _slurm_rpc_submit_batch_job: JobId=52978 InitPrio=1807 usec=397
[2022-11-21T15:04:11.139] Time limit exhausted for JobId=52957
[2022-11-21T15:04:12.992] sched: Allocate JobId=52978 NodeList=gpu02 #CPUs=8 Partition=gpu-titan
[2022-11-21T16:11:10.931] _job_complete: JobId=52977 WEXITSTATUS 0
[2022-11-21T16:11:10.931] _job_complete: JobId=52977 done
[2022-11-21T16:11:45.717] sched: _slurm_rpc_allocate_resources JobId=52979 NodeList=cpu05 usec=18433
[2022-11-21T17:12:57.111] _job_complete: JobId=52979 WEXITSTATUS 0
[2022-11-21T17:12:57.112] _job_complete: JobId=52979 done
[2022-11-21T17:17:57.586] cleanup_completing: JobId=52979 completion process took 300 seconds
[2022-11-21T17:24:43.483] _job_complete: JobId=52973 WEXITSTATUS 0
[2022-11-21T17:24:43.484] _job_complete: JobId=52973 done
[2022-11-21T17:44:26.548] sched: _slurm_rpc_allocate_resources JobId=52980 NodeList=cpu05 usec=18968
[2022-11-21T18:32:25.282] _slurm_rpc_submit_batch_job: JobId=52981 InitPrio=401 usec=666
[2022-11-21T18:32:26.279] sched: Allocate JobId=52981 NodeList=cpu05 #CPUs=4 Partition=cpu-opteron
[2022-11-21T18:33:48.791] _slurm_rpc_kill_job: REQUEST_KILL_JOB JobId=52981 uid 548200021
[2022-11-21T18:34:28.534] _job_complete: JobId=52980 WEXITSTATUS 0
[2022-11-21T18:34:28.534] _job_complete: JobId=52980 done
[2022-11-21T18:34:39.039] _slurm_rpc_submit_batch_job: JobId=52982 InitPrio=401 usec=468
[2022-11-21T18:34:39.443] sched: Allocate JobId=52982 NodeList=cpu05 #CPUs=8 Partition=cpu-opteron
[2022-11-21T18:58:48.481] _job_complete: JobId=52982 WEXITSTATUS 0
[2022-11-21T18:58:48.481] _job_complete: JobId=52982 done
[2022-11-21T19:36:44.004] Time limit exhausted for JobId=52654
[2022-11-21T21:03:44.641] _job_complete: JobId=52972 WEXITSTATUS 0
[2022-11-21T21:03:44.642] _job_complete: JobId=52972 done
[2022-11-21T21:08:45.088] cleanup_completing: JobId=52972 completion process took 301 seconds
[2022-11-21T21:27:28.324] sched: _slurm_rpc_allocate_resources JobId=52983 NodeList=cpu05 usec=19840
[2022-11-21T22:20:41.511] _slurm_rpc_submit_batch_job: JobId=52984 InitPrio=1807 usec=480
[2022-11-21T22:20:54.458] _slurm_rpc_submit_batch_job: JobId=52985 InitPrio=1807 usec=492
[2022-11-21T22:21:45.147] _slurm_rpc_submit_batch_job: JobId=52986 InitPrio=1807 usec=344
[2022-11-21T22:51:14.333] _job_complete: JobId=52983 WEXITSTATUS 0
[2022-11-21T22:51:14.333] _job_complete: JobId=52983 done
[2022-11-21T22:51:24.677] _slurm_rpc_submit_batch_job: JobId=52987 InitPrio=602 usec=586
[2022-11-21T22:51:24.769] sched: Allocate JobId=52987 NodeList=cpu05 #CPUs=8 Partition=cpu-opteron
[2022-11-21T22:54:52.210] _slurm_rpc_submit_batch_job: JobId=52988 InitPrio=602 usec=460
[2022-11-21T22:54:53.149] sched: Allocate JobId=52988 NodeList=cpu05 #CPUs=8 Partition=cpu-opteron
[2022-11-21T22:56:34.411] _job_complete: JobId=52987 WEXITSTATUS 0
[2022-11-21T22:56:34.412] _job_complete: JobId=52987 done
[2022-11-21T23:00:00.670] _job_complete: JobId=52988 WEXITSTATUS 0
[2022-11-21T23:00:00.671] _job_complete: JobId=52988 done
[2022-11-22T08:04:54.624] _job_complete: JobId=52644 WEXITSTATUS 0
[2022-11-22T08:04:54.629] _job_complete: JobId=52644 done
[2022-11-22T08:11:45.020] Time limit exhausted for JobId=52966
[2022-11-22T08:12:06.290] sched: Allocate JobId=52984 NodeList=gpu05 #CPUs=8 Partition=gpu-v100s
[2022-11-22T08:18:15.597] Time limit exhausted for JobId=52722
[2022-11-22T08:18:15.603] Time limit exhausted for JobId=52970
[2022-11-22T08:18:24.615] sched: Allocate JobId=52985 NodeList=gpu05 #CPUs=8 Partition=gpu-v100s
[2022-11-22T08:37:45.625] Time limit exhausted for JobId=52678
[2022-11-22T08:37:54.339] sched: Allocate JobId=52986 NodeList=gpu02 #CPUs=4 Partition=gpu-titan
[2022-11-22T08:48:54.080] sched: _slurm_rpc_allocate_resources JobId=52989 NodeList=cpu05 usec=17625
[2022-11-22T08:49:18.354] _job_complete: JobId=52896 WEXITSTATUS 0
[2022-11-22T08:49:18.354] _job_complete: JobId=52896 done
[2022-11-22T11:25:18.852] _slurm_rpc_kill_job: REQUEST_KILL_JOB JobId=52908 uid 548300543
[2022-11-22T11:25:18.853] error: Security violation, REQUEST_KILL_JOB RPC for JobId=52908 from uid 548300543
[2022-11-22T11:25:18.853] _slurm_rpc_kill_job: job_str_signal() uid=548300543 JobId=52908 sig=9 returned: Access/permission denied
[2022-11-22T11:25:57.809] _slurm_rpc_kill_job: REQUEST_KILL_JOB JobId=52908 uid 548300543
[2022-11-22T11:25:57.809] error: Security violation, REQUEST_KILL_JOB RPC for JobId=52908 from uid 548300543
[2022-11-22T11:25:57.809] _slurm_rpc_kill_job: job_str_signal() uid=548300543 JobId=52908 sig=9 returned: Access/permission denied
[2022-11-22T11:30:57.877] _slurm_rpc_kill_job: REQUEST_KILL_JOB JobId=52908 uid 548300543
[2022-11-22T11:31:24.222] _slurm_rpc_kill_job: REQUEST_KILL_JOB JobId=52909 uid 548300543
[2022-11-22T11:53:01.017] _job_complete: JobId=52760 WEXITSTATUS 0
[2022-11-22T11:53:01.017] _job_complete: JobId=52760 done
[2022-11-22T13:01:13.062] _slurm_rpc_submit_batch_job: JobId=52990 InitPrio=18232 usec=694
[2022-11-22T13:01:13.858] sched: Allocate JobId=52990 NodeList=cpu05 #CPUs=1 Partition=cpu-opteron
[2022-11-22T13:02:16.664] _job_complete: JobId=52990 WEXITSTATUS 0
[2022-11-22T13:02:16.664] _job_complete: JobId=52990 done
[2022-11-22T13:09:40.239] _slurm_rpc_submit_batch_job: JobId=52991 InitPrio=18232 usec=630
[2022-11-22T13:09:40.622] sched: Allocate JobId=52991 NodeList=cpu05 #CPUs=1 Partition=cpu-opteron
[2022-11-22T13:09:51.660] _job_complete: JobId=52991 WEXITSTATUS 1
[2022-11-22T13:09:51.660] _job_complete: JobId=52991 done
[2022-11-22T13:14:28.982] _slurm_rpc_submit_batch_job: JobId=52992 InitPrio=18232 usec=743
[2022-11-22T13:14:29.155] sched: Allocate JobId=52992 NodeList=cpu05 #CPUs=1 Partition=cpu-opteron
[2022-11-22T13:14:39.788] _job_complete: JobId=52992 WEXITSTATUS 1
[2022-11-22T13:14:39.788] _job_complete: JobId=52992 done
[2022-11-22T13:16:06.411] _slurm_rpc_submit_batch_job: JobId=52993 InitPrio=18232 usec=560
[2022-11-22T13:16:07.270] sched: Allocate JobId=52993 NodeList=cpu05 #CPUs=1 Partition=cpu-opteron
[2022-11-22T13:16:31.661] _job_complete: JobId=52993 WEXITSTATUS 0
[2022-11-22T13:16:31.661] _job_complete: JobId=52993 done
[2022-11-22T13:24:15.360] _slurm_rpc_submit_batch_job: JobId=52994 InitPrio=18232 usec=578
[2022-11-22T13:24:16.082] sched: Allocate JobId=52994 NodeList=cpu05 #CPUs=1 Partition=cpu-opteron
[2022-11-22T13:24:52.381] _job_complete: JobId=52994 WEXITSTATUS 1
[2022-11-22T13:24:52.381] _job_complete: JobId=52994 done
[2022-11-22T13:26:28.548] _slurm_rpc_submit_batch_job: JobId=52995 InitPrio=18232 usec=575
[2022-11-22T13:26:29.374] sched: Allocate JobId=52995 NodeList=cpu05 #CPUs=1 Partition=cpu-opteron
[2022-11-22T13:27:16.719] _job_complete: JobId=52995 WEXITSTATUS 0
[2022-11-22T13:27:16.720] _job_complete: JobId=52995 done
[2022-11-22T13:56:12.316] _slurm_rpc_submit_batch_job: JobId=52996 InitPrio=18232 usec=625
[2022-11-22T13:56:12.746] sched: Allocate JobId=52996 NodeList=cpu05 #CPUs=1 Partition=cpu-opteron
[2022-11-22T13:57:28.812] _job_complete: JobId=52996 WEXITSTATUS 0
[2022-11-22T13:57:28.812] _job_complete: JobId=52996 done
[2022-11-22T14:04:41.008] _slurm_rpc_submit_batch_job: JobId=52997 InitPrio=18232 usec=717
[2022-11-22T14:04:41.545] sched: Allocate JobId=52997 NodeList=cpu05 #CPUs=1 Partition=cpu-opteron
[2022-11-22T14:05:00.791] _job_complete: JobId=52997 WEXITSTATUS 127
[2022-11-22T14:05:00.791] _job_complete: JobId=52997 done
[2022-11-22T14:12:45.412] _slurm_rpc_submit_batch_job: JobId=52998 InitPrio=18232 usec=697
[2022-11-22T14:12:45.479] sched: Allocate JobId=52998 NodeList=cpu05 #CPUs=1 Partition=cpu-opteron
[2022-11-22T14:13:05.373] _job_complete: JobId=52998 WEXITSTATUS 127
[2022-11-22T14:13:05.373] _job_complete: JobId=52998 done
[2022-11-22T14:13:21.058] sched: _slurm_rpc_allocate_resources JobId=52999 NodeList=cpu15 usec=17853
[2022-11-22T14:16:26.299] sched: _slurm_rpc_allocate_resources JobId=53000 NodeList=cpu05 usec=18096
[2022-11-22T14:21:12.674] _slurm_rpc_submit_batch_job: JobId=53001 InitPrio=18232 usec=543
[2022-11-22T14:21:13.234] sched: Allocate JobId=53001 NodeList=cpu03 #CPUs=1 Partition=cpu-opteron
[2022-11-22T14:23:18.119] _job_complete: JobId=53001 WEXITSTATUS 0
[2022-11-22T14:23:18.119] _job_complete: JobId=53001 done
[2022-11-22T14:23:45.601] Time limit exhausted for JobId=52311
[2022-11-22T15:04:16.374] Time limit exhausted for JobId=52978
[2022-11-22T15:04:16.756] sched: _slurm_rpc_allocate_resources JobId=53002 NodeList=cpu03 usec=2790
[2022-11-22T15:40:38.663] _job_complete: JobId=53000 WEXITSTATUS 0
[2022-11-22T15:40:38.664] _job_complete: JobId=53000 done
[2022-11-22T15:46:42.589] _job_complete: JobId=52989 WEXITSTATUS 0
[2022-11-22T15:46:42.589] _job_complete: JobId=52989 done
[2022-11-22T15:57:22.631] _job_complete: JobId=53002 WEXITSTATUS 0
[2022-11-22T15:57:22.632] _job_complete: JobId=53002 done
[2022-11-22T16:16:14.213] _slurm_rpc_submit_batch_job: JobId=53003 InitPrio=1807 usec=396
[2022-11-22T16:16:14.706] sched: Allocate JobId=53003 NodeList=gpu02 #CPUs=4 Partition=gpu-titan
[2022-11-22T17:31:17.387] _slurm_rpc_submit_batch_job: JobId=53004 InitPrio=18232 usec=650
[2022-11-22T17:31:17.515] sched: Allocate JobId=53004 NodeList=cpu03 #CPUs=1 Partition=cpu-opteron
[2022-11-22T17:31:37.985] _job_complete: JobId=53004 WEXITSTATUS 1
[2022-11-22T17:31:37.985] _job_complete: JobId=53004 done
[2022-11-22T17:32:50.042] _slurm_rpc_submit_batch_job: JobId=53005 InitPrio=18232 usec=636
[2022-11-22T17:32:50.710] sched: Allocate JobId=53005 NodeList=cpu03 #CPUs=1 Partition=cpu-opteron
[2022-11-22T17:33:15.064] _job_complete: JobId=53005 WEXITSTATUS 0
[2022-11-22T17:33:15.064] _job_complete: JobId=53005 done
[2022-11-22T17:36:52.954] _slurm_rpc_submit_batch_job: JobId=53006 InitPrio=18232 usec=578
[2022-11-22T17:36:53.079] sched: Allocate JobId=53006 NodeList=cpu03 #CPUs=1 Partition=cpu-opteron
[2022-11-22T17:37:17.799] _job_complete: JobId=53006 WEXITSTATUS 0
[2022-11-22T17:37:17.799] _job_complete: JobId=53006 done
[2022-11-22T17:38:37.996] _slurm_rpc_submit_batch_job: JobId=53007 InitPrio=18232 usec=587
[2022-11-22T17:38:38.204] sched: Allocate JobId=53007 NodeList=cpu03 #CPUs=1 Partition=cpu-opteron
[2022-11-22T17:39:15.583] _job_complete: JobId=53007 WEXITSTATUS 0
[2022-11-22T17:39:15.583] _job_complete: JobId=53007 done
[2022-11-22T18:46:08.263] _job_complete: JobId=52999 WEXITSTATUS 0
[2022-11-22T18:46:08.264] _job_complete: JobId=52999 done
[2022-11-22T18:51:08.559] cleanup_completing: JobId=52999 completion process took 300 seconds
[2022-11-22T19:32:24.214] sched: _slurm_rpc_allocate_resources JobId=53008 NodeList=cpu03 usec=42449
[2022-11-22T19:32:29.037] _job_complete: JobId=53008 WEXITSTATUS 0
[2022-11-22T19:32:29.037] _job_complete: JobId=53008 done
[2022-11-22T19:40:19.144] _slurm_rpc_submit_batch_job: JobId=53009 InitPrio=2409 usec=665
[2022-11-22T23:35:40.538] _slurm_rpc_submit_batch_job: JobId=53010 InitPrio=1807 usec=507
[2022-11-22T23:35:48.580] _slurm_rpc_kill_job: REQUEST_KILL_JOB JobId=52985 uid 548200121
[2022-11-22T23:35:49.131] sched: Allocate JobId=53010 NodeList=gpu05 #CPUs=8 Partition=gpu-v100s
[2022-11-22T23:37:59.150] _slurm_rpc_submit_batch_job: JobId=53011 InitPrio=1807 usec=406
[2022-11-22T23:38:08.085] _slurm_rpc_kill_job: REQUEST_KILL_JOB JobId=52984 uid 548200121
[2022-11-22T23:38:09.169] sched: Allocate JobId=53011 NodeList=gpu05 #CPUs=8 Partition=gpu-v100s
[2022-11-23T01:43:40.387] _slurm_rpc_submit_batch_job: JobId=53012 InitPrio=8433 usec=426
[2022-11-23T01:44:15.448] _slurm_rpc_kill_job: REQUEST_KILL_JOB JobId=53012 uid 548300513
[2022-11-23T08:35:18.364] sched: _slurm_rpc_allocate_resources JobId=53013 NodeList=cpu03 usec=17424
[2022-11-23T08:38:17.574] Time limit exhausted for JobId=52986
[2022-11-23T08:42:04.367] sched: _slurm_rpc_allocate_resources JobId=53014 NodeList=cpu03 usec=1715
[2022-11-23T09:25:39.504] _job_complete: JobId=53014 WEXITSTATUS 0
[2022-11-23T09:25:39.505] _job_complete: JobId=53014 done
[2022-11-23T09:26:26.603] _job_complete: JobId=53013 WEXITSTATUS 0
[2022-11-23T09:26:26.604] _job_complete: JobId=53013 done
[2022-11-23T09:31:00.425] cleanup_completing: JobId=53014 completion process took 321 seconds
[2022-11-23T09:31:47.431] cleanup_completing: JobId=53013 completion process took 321 seconds
[2022-11-23T09:36:33.140] sched: _slurm_rpc_allocate_resources JobId=53015 NodeList=cpu03 usec=2481
[2022-11-23T09:40:49.607] sched: _slurm_rpc_allocate_resources JobId=53016 NodeList=cpu03 usec=1134
[2022-11-23T10:34:03.661] _job_complete: JobId=53016 WEXITSTATUS 0
[2022-11-23T10:34:03.662] _job_complete: JobId=53016 done
[2022-11-23T10:35:00.504] _job_complete: JobId=53015 WEXITSTATUS 0
[2022-11-23T10:35:00.505] _job_complete: JobId=53015 done
[2022-11-23T10:39:24.499] cleanup_completing: JobId=53016 completion process took 321 seconds
[2022-11-23T10:41:21.576] sched: _slurm_rpc_allocate_resources JobId=53017 NodeList=cpu03 usec=17256
[2022-11-23T10:44:12.653] sched: _slurm_rpc_allocate_resources JobId=53018 NodeList=cpu03 usec=1302
[2022-11-23T11:49:12.387] sched: _slurm_rpc_allocate_resources JobId=53019 NodeList=cpu15 usec=18907
[2022-11-23T11:53:12.850] _slurm_rpc_submit_batch_job: JobId=53020 InitPrio=400 usec=460
[2022-11-23T11:56:43.559] _slurm_rpc_submit_batch_job: JobId=53021 InitPrio=400 usec=669
[2022-11-23T12:10:42.655] _slurm_rpc_kill_job: REQUEST_KILL_JOB JobId=53017 uid 548300642
[2022-11-23T12:11:06.485] _slurm_rpc_kill_job: REQUEST_KILL_JOB JobId=53018 uid 548300642
[2022-11-23T12:12:21.888] sched: _slurm_rpc_allocate_resources JobId=53022 NodeList=cpu05 usec=18288
[2022-11-23T12:14:01.143] sched: _slurm_rpc_allocate_resources JobId=53023 NodeList=cpu05 usec=1197
[2022-11-23T12:15:34.323] _slurm_rpc_kill_job: REQUEST_KILL_JOB JobId=53010 uid 548200121
[2022-11-23T12:15:38.672] _slurm_rpc_submit_batch_job: JobId=53024 InitPrio=1400 usec=429
[2022-11-23T12:15:39.060] sched: Allocate JobId=53024 NodeList=gpu05 #CPUs=8 Partition=gpu-v100s
[2022-11-23T12:15:43.537] cleanup_completing: JobId=53017 completion process took 301 seconds
[2022-11-23T12:16:07.320] cleanup_completing: JobId=53018 completion process took 301 seconds
[2022-11-23T12:52:10.888] _job_complete: JobId=53022 WEXITSTATUS 0
[2022-11-23T12:52:10.889] _job_complete: JobId=53022 done
[2022-11-23T12:57:21.904] cleanup_completing: JobId=53022 completion process took 311 seconds
[2022-11-23T13:03:47.828] Time limit exhausted for JobId=52761
[2022-11-23T13:04:39.553] _slurm_rpc_kill_job: REQUEST_KILL_JOB JobId=53023 uid 548300642
[2022-11-23T13:05:19.109] sched: _slurm_rpc_allocate_resources JobId=53025 NodeList=cpu03 usec=3108
[2022-11-23T13:09:41.527] cleanup_completing: JobId=53023 completion process took 302 seconds
[2022-11-23T13:30:40.651] sched: _slurm_rpc_allocate_resources JobId=53026 NodeList=cpu03 usec=2321
[2022-11-23T14:06:04.069] _slurm_rpc_submit_batch_job: JobId=53027 InitPrio=5600 usec=729
[2022-11-23T14:06:05.028] sched: Allocate JobId=53027 NodeList=cpu12 #CPUs=48 Partition=cpu-epyc
[2022-11-23T14:06:05.824] _job_complete: JobId=53027 WEXITSTATUS 1
[2022-11-23T14:06:05.825] _job_complete: JobId=53027 done
[2022-11-23T14:06:45.795] _slurm_rpc_submit_batch_job: JobId=53028 InitPrio=5600 usec=656
[2022-11-23T14:06:45.972] sched: Allocate JobId=53028 NodeList=cpu12 #CPUs=48 Partition=cpu-epyc
[2022-11-23T14:25:07.438] _slurm_rpc_kill_job: REQUEST_KILL_JOB JobId=53025 uid 548300642
[2022-11-23T14:25:09.584] _slurm_rpc_kill_job: REQUEST_KILL_JOB JobId=53026 uid 548300642
[2022-11-23T14:30:13.292] cleanup_completing: JobId=53025 completion process took 306 seconds
[2022-11-23T14:30:15.422] cleanup_completing: JobId=53026 completion process took 306 seconds
[2022-11-23T14:35:00.261] sched: _slurm_rpc_allocate_resources JobId=53029 NodeList=cpu03 usec=2302
[2022-11-23T15:10:17.657] _job_complete: JobId=53019 WEXITSTATUS 0
[2022-11-23T15:10:17.658] _job_complete: JobId=53019 done
[2022-11-23T15:15:18.067] cleanup_completing: JobId=53019 completion process took 301 seconds
[2022-11-23T16:03:17.944] Time limit exhausted for JobId=52785
[2022-11-23T16:16:17.710] Time limit exhausted for JobId=53003
[2022-11-23T16:26:06.441] _slurm_rpc_submit_batch_job: JobId=53030 InitPrio=1000 usec=529
[2022-11-23T16:26:06.760] sched: Allocate JobId=53030 NodeList=gpu02 #CPUs=4 Partition=gpu-titan
[2022-11-23T16:26:13.965] _slurm_rpc_submit_batch_job: JobId=53031 InitPrio=1000 usec=425
[2022-11-23T16:26:14.747] sched: Allocate JobId=53031 NodeList=gpu02 #CPUs=4 Partition=gpu-titan
[2022-11-23T16:26:34.590] _slurm_rpc_submit_batch_job: JobId=53032 InitPrio=1000 usec=387
[2022-11-23T16:26:34.856] sched: Allocate JobId=53032 NodeList=gpu02 #CPUs=4 Partition=gpu-titan
[2022-11-23T16:34:42.356] sched: _slurm_rpc_allocate_resources JobId=53033 NodeList=cpu03 usec=17525
[2022-11-23T18:15:44.169] _job_complete: JobId=53033 WEXITSTATUS 0
[2022-11-23T18:15:44.169] _job_complete: JobId=53033 done
[2022-11-23T18:19:52.456] _job_complete: JobId=53029 WEXITSTATUS 0
[2022-11-23T18:19:52.456] _job_complete: JobId=53029 done
[2022-11-23T21:03:47.219] Time limit exhausted for JobId=52826
[2022-11-23T21:13:49.117] _slurm_rpc_submit_batch_job: JobId=53034 InitPrio=400 usec=606
[2022-11-23T23:05:38.915] _slurm_rpc_submit_batch_job: JobId=53035 InitPrio=9200 usec=653
[2022-11-23T23:05:39.030] sched: Allocate JobId=53035 NodeList=cpu03 #CPUs=1 Partition=cpu-opteron
[2022-11-23T23:17:43.165] _job_complete: JobId=53035 WEXITSTATUS 0
[2022-11-23T23:17:43.165] _job_complete: JobId=53035 done
[2022-11-23T23:21:44.557] _slurm_rpc_submit_batch_job: JobId=53036 InitPrio=600 usec=603
[2022-11-23T23:21:44.768] sched: Allocate JobId=53036 NodeList=cpu13 #CPUs=2 Partition=cpu-epyc
[2022-11-23T23:38:17.334] Time limit exhausted for JobId=53011
[2022-11-23T23:43:47.390] _slurm_rpc_submit_batch_job: JobId=53037 InitPrio=1000 usec=413
[2022-11-23T23:43:47.852] sched: Allocate JobId=53037 NodeList=gpu05 #CPUs=7 Partition=gpu-v100s
[2022-11-24T02:29:48.806] _job_complete: JobId=52919 WEXITSTATUS 1
[2022-11-24T02:29:48.812] _job_complete: JobId=52919 done
[2022-11-24T05:23:53.781] _job_complete: JobId=53036 WEXITSTATUS 0
[2022-11-24T05:23:53.781] _job_complete: JobId=53036 done
[2022-11-24T08:35:59.359] _slurm_rpc_kill_job: REQUEST_KILL_JOB JobId=53024 uid 548200121
[2022-11-24T08:36:08.355] _slurm_rpc_submit_batch_job: JobId=53038 InitPrio=1000 usec=457
[2022-11-24T08:36:09.428] sched: Allocate JobId=53038 NodeList=gpu05 #CPUs=7 Partition=gpu-v100s
[2022-11-24T08:42:26.416] sched: _slurm_rpc_allocate_resources JobId=53039 NodeList=cpu03 usec=14311
[2022-11-24T09:38:46.837] sched: _slurm_rpc_allocate_resources JobId=53040 NodeList=cpu03 usec=2330
[2022-11-24T10:43:46.685] _slurm_rpc_kill_job: REQUEST_KILL_JOB JobId=52788 uid 548200029
[2022-11-24T10:45:54.474] _slurm_rpc_submit_batch_job: JobId=53041 InitPrio=1200 usec=729
[2022-11-24T10:47:05.364] _slurm_rpc_submit_batch_job: JobId=53042 InitPrio=1200 usec=913
[2022-11-24T10:53:37.665] _job_complete: JobId=52762 WEXITSTATUS 0
[2022-11-24T10:53:37.666] _job_complete: JobId=52762 done
[2022-11-24T11:12:10.520] _slurm_rpc_submit_batch_job: JobId=53043 InitPrio=6200 usec=812
[2022-11-24T11:12:10.649] sched: Allocate JobId=53043 NodeList=cpu13 #CPUs=48 Partition=cpu-epyc
[2022-11-24T11:12:11.502] _job_complete: JobId=53043 WEXITSTATUS 0
[2022-11-24T11:12:11.502] _job_complete: JobId=53043 done
[2022-11-24T11:18:25.989] _slurm_rpc_submit_batch_job: JobId=53044 InitPrio=6200 usec=799
[2022-11-24T11:18:26.092] sched: Allocate JobId=53044 NodeList=cpu13 #CPUs=48 Partition=cpu-epyc
[2022-11-24T11:18:27.300] _job_complete: JobId=53044 WEXITSTATUS 0
[2022-11-24T11:18:27.300] _job_complete: JobId=53044 done
[2022-11-24T11:21:41.987] _slurm_rpc_submit_batch_job: JobId=53045 InitPrio=6200 usec=762
[2022-11-24T11:21:42.431] sched: Allocate JobId=53045 NodeList=cpu13 #CPUs=48 Partition=cpu-epyc
[2022-11-24T11:21:44.094] _job_complete: JobId=53045 WEXITSTATUS 0
[2022-11-24T11:21:44.094] _job_complete: JobId=53045 done
[2022-11-24T11:22:46.985] _slurm_rpc_submit_batch_job: JobId=53046 InitPrio=6200 usec=743
[2022-11-24T11:22:47.510] sched: Allocate JobId=53046 NodeList=cpu13 #CPUs=48 Partition=cpu-epyc
[2022-11-24T11:31:22.985] _job_complete: JobId=53046 WEXITSTATUS 0
[2022-11-24T11:31:22.985] _job_complete: JobId=53046 done
[2022-11-24T11:34:58.968] _slurm_rpc_submit_batch_job: JobId=53047 InitPrio=6200 usec=750
[2022-11-24T11:34:59.581] sched: Allocate JobId=53047 NodeList=cpu13 #CPUs=48 Partition=cpu-epyc
[2022-11-24T11:37:07.612] _slurm_rpc_kill_job: REQUEST_KILL_JOB JobId=53047 uid 548300534
[2022-11-24T11:37:43.084] _slurm_rpc_submit_batch_job: JobId=53048 InitPrio=6200 usec=611
[2022-11-24T11:37:43.854] sched: Allocate JobId=53048 NodeList=cpu13 #CPUs=48 Partition=cpu-epyc
[2022-11-24T11:38:29.749] _slurm_rpc_kill_job: REQUEST_KILL_JOB JobId=53048 uid 548300534
[2022-11-24T11:46:33.152] _slurm_rpc_submit_batch_job: JobId=53049 InitPrio=6200 usec=778
[2022-11-24T11:46:33.916] sched: Allocate JobId=53049 NodeList=cpu13 #CPUs=48 Partition=cpu-epyc
[2022-11-24T11:47:43.803] _slurm_rpc_kill_job: REQUEST_KILL_JOB JobId=53049 uid 548300534
[2022-11-24T11:49:03.374] _slurm_rpc_submit_batch_job: JobId=53050 InitPrio=6200 usec=746
[2022-11-24T11:49:04.094] sched: Allocate JobId=53050 NodeList=cpu13 #CPUs=48 Partition=cpu-epyc
[2022-11-24T11:49:44.899] _slurm_rpc_kill_job: REQUEST_KILL_JOB JobId=53050 uid 548300534
[2022-11-24T11:49:56.191] _slurm_rpc_submit_batch_job: JobId=53051 InitPrio=6200 usec=718
[2022-11-24T11:49:57.153] sched: Allocate JobId=53051 NodeList=cpu13 #CPUs=48 Partition=cpu-epyc
[2022-11-24T13:03:22.970] sched: _update_job: setting time_limit to 20160 for JobId=53028
[2022-11-24T13:03:22.970] _update_job: updating accounting
[2022-11-24T13:03:22.970] _slurm_rpc_update_job: complete JobId=53028 uid=548200003 usec=1097
[2022-11-24T13:13:01.694] _job_complete: JobId=53039 WEXITSTATUS 0
[2022-11-24T13:13:01.695] _job_complete: JobId=53039 done
[2022-11-24T13:18:07.601] cleanup_completing: JobId=53039 completion process took 306 seconds
[2022-11-24T13:23:26.399] _slurm_rpc_kill_job: REQUEST_KILL_JOB JobId=53040 uid 548300642
[2022-11-24T13:28:31.610] cleanup_completing: JobId=53040 completion process took 305 seconds
[2022-11-24T13:58:44.890] _slurm_rpc_submit_batch_job: JobId=53052 InitPrio=2400 usec=662
[2022-11-24T13:58:45.937] sched: Allocate JobId=53052 NodeList=cpu14 #CPUs=48 Partition=cpu-epyc
[2022-11-24T13:59:10.213] _slurm_rpc_submit_batch_job: JobId=53053 InitPrio=2400 usec=579
[2022-11-24T13:59:10.806] sched: Allocate JobId=53053 NodeList=cpu15 #CPUs=48 Partition=cpu-epyc
[2022-11-24T14:01:06.543] _slurm_rpc_submit_batch_job: JobId=53054 InitPrio=2400 usec=623
[2022-11-24T14:01:37.039] _slurm_rpc_kill_job: REQUEST_KILL_JOB JobId=53054 uid 548300630
[2022-11-24T14:21:24.089] _job_complete: JobId=53053 WEXITSTATUS 0
[2022-11-24T14:21:24.090] _job_complete: JobId=53053 done
[2022-11-24T14:32:10.730] sched: _slurm_rpc_allocate_resources JobId=53055 NodeList=cpu03 usec=14925
[2022-11-24T14:36:57.456] sched: _slurm_rpc_allocate_resources JobId=53056 NodeList=cpu03 usec=1375
[2022-11-24T15:00:11.631] _job_complete: JobId=53052 WEXITSTATUS 0
[2022-11-24T15:00:11.631] _job_complete: JobId=53052 done
[2022-11-24T16:22:45.330] _slurm_rpc_kill_job: REQUEST_KILL_JOB JobId=53056 uid 548300642
[2022-11-24T16:26:19.313] Time limit exhausted for JobId=53030
[2022-11-24T16:26:19.318] Time limit exhausted for JobId=53031
[2022-11-24T16:26:49.447] Time limit exhausted for JobId=53032
[2022-11-24T16:27:52.261] cleanup_completing: JobId=53056 completion process took 307 seconds
[2022-11-24T16:30:15.553] _job_complete: JobId=53055 WEXITSTATUS 0
[2022-11-24T16:30:15.553] _job_complete: JobId=53055 done
[2022-11-24T16:35:26.461] cleanup_completing: JobId=53055 completion process took 311 seconds
[2022-11-24T16:50:15.024] sched: _slurm_rpc_allocate_resources JobId=53057 NodeList=cpu03 usec=17721
[2022-11-24T16:51:48.289] sched: _slurm_rpc_allocate_resources JobId=53058 NodeList=cpu03 usec=964
[2022-11-24T17:14:19.193] Time limit exhausted for JobId=52763
[2022-11-24T17:34:34.267] _job_complete: JobId=53057 WEXITSTATUS 0
[2022-11-24T17:34:34.267] _job_complete: JobId=53057 done
[2022-11-24T17:34:50.344] _job_complete: JobId=53058 WEXITSTATUS 0
[2022-11-24T17:34:50.344] _job_complete: JobId=53058 done
[2022-11-24T19:06:22.838] _slurm_rpc_submit_batch_job: JobId=53059 InitPrio=2400 usec=648
[2022-11-24T19:06:22.855] sched: Allocate JobId=53059 NodeList=cpu14 #CPUs=48 Partition=cpu-epyc
[2022-11-24T19:16:51.015] _slurm_rpc_submit_batch_job: JobId=53060 InitPrio=2400 usec=539
[2022-11-24T19:16:51.816] sched/backfill: _start_job: Started JobId=53060 in cpu-opteron on cpu01
[2022-11-24T19:17:13.632] _slurm_rpc_submit_batch_job: JobId=53061 InitPrio=2400 usec=448
[2022-11-24T19:17:13.961] sched: Allocate JobId=53061 NodeList=cpu03 #CPUs=32 Partition=cpu-opteron
[2022-11-24T19:20:47.857] _slurm_rpc_submit_batch_job: JobId=53062 InitPrio=2400 usec=553
[2022-11-24T19:20:48.227] sched: Allocate JobId=53062 NodeList=cpu04 #CPUs=32 Partition=cpu-opteron
[2022-11-24T19:21:30.584] _slurm_rpc_submit_batch_job: JobId=53063 InitPrio=2400 usec=501
[2022-11-24T19:21:31.419] sched: Allocate JobId=53063 NodeList=cpu15 #CPUs=48 Partition=cpu-epyc
[2022-11-24T20:35:11.442] _slurm_rpc_submit_batch_job: JobId=53064 InitPrio=2400 usec=692
[2022-11-24T20:35:35.601] _slurm_rpc_kill_job: REQUEST_KILL_JOB JobId=53063 uid 548300630
[2022-11-24T20:35:37.796] sched: Allocate JobId=53064 NodeList=cpu15 #CPUs=48 Partition=cpu-epyc
[2022-11-24T20:36:11.924] _slurm_rpc_kill_job: REQUEST_KILL_JOB JobId=53059 uid 548300630
[2022-11-24T20:37:29.188] _slurm_rpc_submit_batch_job: JobId=53065 InitPrio=2400 usec=532
[2022-11-24T20:37:29.390] sched: Allocate JobId=53065 NodeList=cpu14 #CPUs=48 Partition=cpu-epyc
[2022-11-24T21:08:27.934] _slurm_rpc_submit_batch_job: JobId=53066 InitPrio=59200 usec=641
[2022-11-24T21:08:28.826] sched: Allocate JobId=53066 NodeList=cpu01 #CPUs=4 Partition=cpu-opteron
[2022-11-24T21:09:01.830] _job_complete: JobId=53066 WEXITSTATUS 1
[2022-11-24T21:09:01.831] _job_complete: JobId=53066 done
[2022-11-24T21:20:22.005] sched: _slurm_rpc_allocate_resources JobId=53067 NodeList=(null) usec=1015
[2022-11-24T21:20:55.777] _slurm_rpc_submit_batch_job: JobId=53068 InitPrio=21600 usec=499
[2022-11-24T21:20:55.781] sched: Allocate JobId=53068 NodeList=cpu01 #CPUs=4 Partition=cpu-opteron
[2022-11-24T21:21:30.583] _job_complete: JobId=53067 WTERMSIG 126
[2022-11-24T21:21:30.583] _job_complete: JobId=53067 cancelled by interactive user
[2022-11-24T21:21:30.583] _job_complete: JobId=53067 done
[2022-11-24T21:21:30.585] _slurm_rpc_complete_job_allocation: JobId=53067 error Job/step already completing or completed
[2022-11-24T21:21:47.025] sched: _slurm_rpc_allocate_resources JobId=53069 NodeList=cpu01 usec=18094
[2022-11-24T21:21:55.120] _job_complete: JobId=53068 WEXITSTATUS 0
[2022-11-24T21:21:55.120] _job_complete: JobId=53068 done
[2022-11-24T21:25:04.839] _job_complete: JobId=53069 WEXITSTATUS 0
[2022-11-24T21:25:04.840] _job_complete: JobId=53069 done
[2022-11-24T21:26:58.076] sched: _slurm_rpc_allocate_resources JobId=53070 NodeList=(null) usec=942
[2022-11-24T21:27:34.720] _job_complete: JobId=53070 WTERMSIG 126
[2022-11-24T21:27:34.720] _job_complete: JobId=53070 cancelled by interactive user
[2022-11-24T21:27:34.720] _job_complete: JobId=53070 done
[2022-11-24T21:27:34.722] _slurm_rpc_complete_job_allocation: JobId=53070 error Job/step already completing or completed
[2022-11-24T21:27:50.699] sched: _slurm_rpc_allocate_resources JobId=53071 NodeList=cpu03 usec=1444
[2022-11-24T21:30:05.570] cleanup_completing: JobId=53069 completion process took 301 seconds
[2022-11-24T21:41:10.709] _slurm_rpc_submit_batch_job: JobId=53072 InitPrio=1000 usec=477
[2022-11-24T21:41:11.559] sched: Allocate JobId=53072 NodeList=gpu02 #CPUs=4 Partition=gpu-titan
[2022-11-24T21:41:40.348] _slurm_rpc_kill_job: REQUEST_KILL_JOB JobId=53037 uid 548200121
[2022-11-24T21:41:55.603] _slurm_rpc_submit_batch_job: JobId=53073 InitPrio=1000 usec=449
[2022-11-24T21:41:56.429] sched: Allocate JobId=53073 NodeList=gpu05 #CPUs=4 Partition=gpu-v100s
[2022-11-24T21:42:15.622] _slurm_rpc_kill_job: REQUEST_KILL_JOB JobId=53038 uid 548200121
[2022-11-24T21:42:20.506] _slurm_rpc_submit_batch_job: JobId=53074 InitPrio=1000 usec=647
[2022-11-24T21:42:21.458] sched: Allocate JobId=53074 NodeList=gpu05 #CPUs=4 Partition=gpu-v100s
[2022-11-24T22:18:14.280] _job_complete: JobId=53064 WEXITSTATUS 1
[2022-11-24T22:18:14.280] _job_complete: JobId=53064 done
[2022-11-24T22:18:27.008] _slurm_rpc_submit_batch_job: JobId=53075 InitPrio=10800 usec=518
[2022-11-24T22:18:27.435] sched: Allocate JobId=53075 NodeList=cpu03 #CPUs=20 Partition=cpu-opteron
[2022-11-24T23:19:57.511] _job_complete: JobId=53065 WEXITSTATUS 0
[2022-11-24T23:19:57.512] _job_complete: JobId=53065 done
[2022-11-24T23:46:49.193] sched: _slurm_rpc_allocate_resources JobId=53076 NodeList=cpu03 usec=19747
[2022-11-24T23:54:37.538] _slurm_rpc_submit_batch_job: JobId=53077 InitPrio=600 usec=571
[2022-11-24T23:54:40.491] sched: Allocate JobId=53077 NodeList=cpu14 #CPUs=48 Partition=cpu-epyc
[2022-11-24T23:54:49.467] _job_complete: JobId=53077 WEXITSTATUS 1
[2022-11-24T23:54:49.467] _job_complete: JobId=53077 done
[2022-11-24T23:54:54.392] _job_complete: JobId=53076 WEXITSTATUS 0
[2022-11-24T23:54:54.393] _job_complete: JobId=53076 done
[2022-11-24T23:58:26.661] _slurm_rpc_submit_batch_job: JobId=53078 InitPrio=600 usec=538
[2022-11-24T23:58:26.868] sched: Allocate JobId=53078 NodeList=cpu14 #CPUs=48 Partition=cpu-epyc
[2022-11-24T23:58:34.269] _job_complete: JobId=53078 WEXITSTATUS 1
[2022-11-24T23:58:34.269] _job_complete: JobId=53078 done
[2022-11-24T23:59:04.171] _slurm_rpc_submit_batch_job: JobId=53079 InitPrio=600 usec=549
[2022-11-24T23:59:04.912] sched: Allocate JobId=53079 NodeList=cpu14 #CPUs=48 Partition=cpu-epyc
[2022-11-24T23:59:07.085] _job_complete: JobId=53079 WEXITSTATUS 1
[2022-11-24T23:59:07.085] _job_complete: JobId=53079 done
[2022-11-24T23:59:56.795] cleanup_completing: JobId=53076 completion process took 302 seconds
[2022-11-25T00:02:28.645] sched: _slurm_rpc_allocate_resources JobId=53080 NodeList=(null) usec=1350
[2022-11-25T00:08:26.765] sched: _slurm_rpc_allocate_resources JobId=53081 NodeList=(null) usec=1235
[2022-11-25T00:11:42.073] sched: _slurm_rpc_allocate_resources JobId=53082 NodeList=(null) usec=838
[2022-11-25T00:12:39.386] _job_complete: JobId=53081 WTERMSIG 126
[2022-11-25T00:12:39.386] _job_complete: JobId=53081 cancelled by interactive user
[2022-11-25T00:12:39.386] _job_complete: JobId=53081 done
[2022-11-25T00:12:39.388] _slurm_rpc_complete_job_allocation: JobId=53081 error Job/step already completing or completed
[2022-11-25T00:13:57.953] _job_complete: JobId=53082 WTERMSIG 126
[2022-11-25T00:13:57.953] _job_complete: JobId=53082 cancelled by interactive user
[2022-11-25T00:13:57.953] _job_complete: JobId=53082 done
[2022-11-25T00:13:57.955] _slurm_rpc_complete_job_allocation: JobId=53082 error Job/step already completing or completed
[2022-11-25T00:14:19.068] sched: _slurm_rpc_allocate_resources JobId=53083 NodeList=cpu03 usec=2126
[2022-11-25T00:20:40.023] _slurm_rpc_submit_batch_job: JobId=53084 InitPrio=4000 usec=582
[2022-11-25T00:20:56.451] _slurm_rpc_submit_batch_job: JobId=53085 InitPrio=600 usec=460
[2022-11-25T00:20:57.420] sched: Allocate JobId=53085 NodeList=cpu14 #CPUs=48 Partition=cpu-epyc
[2022-11-25T00:20:57.962] _job_complete: JobId=53085 WEXITSTATUS 127
[2022-11-25T00:20:57.962] _job_complete: JobId=53085 done
[2022-11-25T00:21:44.734] _slurm_rpc_submit_batch_job: JobId=53086 InitPrio=600 usec=507
[2022-11-25T00:21:45.666] sched: Allocate JobId=53086 NodeList=cpu14 #CPUs=48 Partition=cpu-epyc
[2022-11-25T00:21:47.943] _job_complete: JobId=53086 WEXITSTATUS 1
[2022-11-25T00:21:47.943] _job_complete: JobId=53086 done
[2022-11-25T00:36:03.221] _slurm_rpc_submit_batch_job: JobId=53087 InitPrio=600 usec=535
[2022-11-25T00:36:03.357] sched: Allocate JobId=53087 NodeList=cpu14 #CPUs=48 Partition=cpu-epyc
[2022-11-25T00:36:03.910] _job_complete: JobId=53087 WEXITSTATUS 127
[2022-11-25T00:36:03.910] _job_complete: JobId=53087 done
[2022-11-25T00:36:56.491] _slurm_rpc_submit_batch_job: JobId=53088 InitPrio=600 usec=484
[2022-11-25T00:36:56.530] sched: Allocate JobId=53088 NodeList=cpu14 #CPUs=48 Partition=cpu-epyc
[2022-11-25T00:39:59.601] _job_complete: JobId=53083 WEXITSTATUS 0
[2022-11-25T00:39:59.602] _job_complete: JobId=53083 done
[2022-11-25T00:41:46.459] _job_complete: JobId=53088 WEXITSTATUS 0
[2022-11-25T00:41:46.459] _job_complete: JobId=53088 done
[2022-11-25T00:44:56.837] sched: _slurm_rpc_allocate_resources JobId=53089 NodeList=cpu14 usec=1343
[2022-11-25T00:45:01.718] cleanup_completing: JobId=53083 completion process took 302 seconds
[2022-11-25T02:08:59.609] _job_complete: JobId=53089 WEXITSTATUS 0
[2022-11-25T02:08:59.610] _job_complete: JobId=53089 done
[2022-11-25T02:14:00.459] cleanup_completing: JobId=53089 completion process took 301 seconds
[2022-11-25T02:16:46.854] _job_complete: JobId=53080 WTERMSIG 126
[2022-11-25T02:16:46.854] _job_complete: JobId=53080 cancelled by interactive user
[2022-11-25T02:16:46.854] _job_complete: JobId=53080 done
[2022-11-25T02:16:46.856] _slurm_rpc_complete_job_allocation: JobId=53080 error Job/step already completing or completed
[2022-11-25T02:17:09.177] _job_complete: JobId=53071 WEXITSTATUS 0
[2022-11-25T02:17:09.178] _job_complete: JobId=53071 done
[2022-11-25T02:22:12.557] cleanup_completing: JobId=53071 completion process took 303 seconds
[2022-11-25T02:41:51.864] Time limit exhausted for JobId=52765
[2022-11-25T02:42:08.837] _job_complete: JobId=53061 WEXITSTATUS 0
[2022-11-25T02:42:08.837] _job_complete: JobId=53061 done
[2022-11-25T04:25:55.737] _job_complete: JobId=53062 WEXITSTATUS 0
[2022-11-25T04:25:55.737] _job_complete: JobId=53062 done
[2022-11-25T08:33:22.603] sched: _slurm_rpc_allocate_resources JobId=53090 NodeList=(null) usec=1234
[2022-11-25T08:36:09.928] _slurm_rpc_submit_batch_job: JobId=53091 InitPrio=2400 usec=536
[2022-11-25T08:36:44.055] _slurm_rpc_kill_job: REQUEST_KILL_JOB JobId=53091 uid 548300630
[2022-11-25T08:37:07.495] _slurm_rpc_submit_batch_job: JobId=53092 InitPrio=12400 usec=531
[2022-11-25T08:37:07.860] sched: Allocate JobId=53092 NodeList=cpu14 #CPUs=48 Partition=cpu-epyc
[2022-11-25T08:38:23.850] _job_complete: JobId=53090 WTERMSIG 126
[2022-11-25T08:38:23.850] _job_complete: JobId=53090 cancelled by interactive user
[2022-11-25T08:38:23.850] _job_complete: JobId=53090 done
[2022-11-25T08:38:36.220] sched: _slurm_rpc_allocate_resources JobId=53093 NodeList=(null) usec=955
[2022-11-25T08:49:03.561] _job_complete: JobId=53092 WEXITSTATUS 0
[2022-11-25T08:49:03.561] _job_complete: JobId=53092 done
[2022-11-25T08:51:04.445] sched: _slurm_rpc_allocate_resources JobId=53094 NodeList=(null) usec=1195
[2022-11-25T09:01:24.941] _slurm_rpc_submit_batch_job: JobId=53095 InitPrio=12400 usec=581
[2022-11-25T09:01:25.423] sched: Allocate JobId=53095 NodeList=cpu14 #CPUs=48 Partition=cpu-epyc
[2022-11-25T09:22:48.926] _job_complete: JobId=53094 WTERMSIG 126
[2022-11-25T09:22:48.926] _job_complete: JobId=53094 cancelled by interactive user
[2022-11-25T09:22:48.926] _job_complete: JobId=53094 done
[2022-11-25T09:24:26.793] _job_complete: JobId=53060 WEXITSTATUS 0
[2022-11-25T09:24:26.793] _job_complete: JobId=53060 done
[2022-11-25T09:27:26.436] sched: _slurm_rpc_allocate_resources JobId=53096 NodeList=(null) usec=1383
[2022-11-25T09:31:02.718] sched: _slurm_rpc_allocate_resources JobId=53097 NodeList=(null) usec=734
[2022-11-25T09:34:43.324] _slurm_rpc_kill_job: REQUEST_KILL_JOB JobId=53093 uid 548300642
[2022-11-25T09:34:46.871] _slurm_rpc_kill_job: REQUEST_KILL_JOB JobId=53096 uid 548300642
[2022-11-25T09:50:19.735] _job_complete: JobId=53097 WTERMSIG 126
[2022-11-25T09:50:19.735] _job_complete: JobId=53097 cancelled by interactive user
[2022-11-25T09:50:19.736] _job_complete: JobId=53097 done
[2022-11-25T10:01:52.633] Time limit exhausted for JobId=53095
[2022-11-25T10:11:10.205] _slurm_rpc_kill_job: REQUEST_KILL_JOB JobId=53009 uid 548300630
[2022-11-25T10:11:44.697] _slurm_rpc_submit_batch_job: JobId=53098 InitPrio=2400 usec=638
[2022-11-25T10:25:46.034] sched: _slurm_rpc_allocate_resources JobId=53099 NodeList=(null) usec=1056
[2022-11-25T10:48:48.284] sched: _slurm_rpc_allocate_resources JobId=53100 NodeList=cpu14 usec=23183
[2022-11-25T10:55:34.688] _job_complete: JobId=53099 WTERMSIG 126
[2022-11-25T10:55:34.688] _job_complete: JobId=53099 cancelled by interactive user
[2022-11-25T10:55:34.688] _job_complete: JobId=53099 done
[2022-11-25T10:55:39.779] sched: _slurm_rpc_allocate_resources JobId=53101 NodeList=(null) usec=1148
[2022-11-25T10:55:50.721] _job_complete: JobId=53101 WTERMSIG 126
[2022-11-25T10:55:50.721] _job_complete: JobId=53101 cancelled by interactive user
[2022-11-25T10:55:50.721] _job_complete: JobId=53101 done
[2022-11-25T10:55:54.279] sched: _slurm_rpc_allocate_resources JobId=53102 NodeList=(null) usec=811
[2022-11-25T11:08:38.024] sched: _slurm_rpc_allocate_resources JobId=53103 NodeList=(null) usec=742
[2022-11-25T11:09:51.508] _job_complete: JobId=53103 WTERMSIG 126
[2022-11-25T11:09:51.509] _job_complete: JobId=53103 cancelled by interactive user
[2022-11-25T11:09:51.509] _job_complete: JobId=53103 done
[2022-11-25T11:32:21.896] sched: _slurm_rpc_allocate_resources JobId=53104 NodeList=cpu03 usec=304847
[2022-11-25T11:39:21.575] _job_complete: JobId=53104 WEXITSTATUS 1
[2022-11-25T11:39:21.575] _job_complete: JobId=53104 done
[2022-11-25T11:39:31.077] sched: _slurm_rpc_allocate_resources JobId=53105 NodeList=cpu03 usec=1291
[2022-11-25T11:42:15.232] _job_complete: JobId=53105 WEXITSTATUS 1
[2022-11-25T11:42:15.232] _job_complete: JobId=53105 done
[2022-11-25T11:42:19.394] sched: _slurm_rpc_allocate_resources JobId=53106 NodeList=cpu03 usec=1644
[2022-11-25T11:43:38.261] _job_complete: JobId=53106 WEXITSTATUS 0
[2022-11-25T11:43:38.261] _job_complete: JobId=53106 done
[2022-11-25T11:43:42.508] sched: _slurm_rpc_allocate_resources JobId=53107 NodeList=cpu03 usec=1268
[2022-11-25T11:48:33.691] _job_complete: JobId=53107 WEXITSTATUS 1
[2022-11-25T11:48:33.691] _job_complete: JobId=53107 done
[2022-11-25T11:48:35.474] sched: _slurm_rpc_allocate_resources JobId=53108 NodeList=cpu03 usec=1262
[2022-11-25T11:50:22.614] Time limit exhausted for JobId=53051
[2022-11-25T11:56:17.444] _job_complete: JobId=53108 WEXITSTATUS 1
[2022-11-25T11:56:17.445] _job_complete: JobId=53108 done
[2022-11-25T11:56:19.073] sched: _slurm_rpc_allocate_resources JobId=53109 NodeList=cpu03 usec=2277
[2022-11-25T12:10:08.171] _job_complete: JobId=53109 WEXITSTATUS 130
[2022-11-25T12:10:08.171] _job_complete: JobId=53109 done
[2022-11-25T12:10:15.669] sched: _slurm_rpc_allocate_resources JobId=53110 NodeList=cpu03 usec=2213
[2022-11-25T12:10:32.434] _job_complete: JobId=53110 WEXITSTATUS 0
[2022-11-25T12:10:32.434] _job_complete: JobId=53110 done
[2022-11-25T12:10:37.052] sched: _slurm_rpc_allocate_resources JobId=53111 NodeList=cpu01 usec=1138
[2022-11-25T12:13:19.808] _slurm_rpc_submit_batch_job: JobId=53112 InitPrio=2400 usec=536
[2022-11-25T12:13:52.683] _slurm_rpc_kill_job: REQUEST_KILL_JOB JobId=53112 uid 548300630
[2022-11-25T12:21:36.012] _job_complete: JobId=53111 WEXITSTATUS 130
[2022-11-25T12:21:36.014] _job_complete: JobId=53111 done
[2022-11-25T12:21:40.020] sched: _slurm_rpc_allocate_resources JobId=53113 NodeList=cpu01 usec=2029
[2022-11-25T12:23:30.837] _job_complete: JobId=53113 WEXITSTATUS 127
[2022-11-25T12:23:30.837] _job_complete: JobId=53113 done
[2022-11-25T12:23:32.623] sched: _slurm_rpc_allocate_resources JobId=53114 NodeList=cpu01 usec=1317
[2022-11-25T12:37:39.156] _slurm_rpc_submit_batch_job: JobId=53115 InitPrio=800 usec=500
[2022-11-25T13:07:18.709] _job_complete: JobId=53102 WTERMSIG 126
[2022-11-25T13:07:18.709] _job_complete: JobId=53102 cancelled by interactive user
[2022-11-25T13:07:18.709] _job_complete: JobId=53102 done
[2022-11-25T13:07:18.711] _slurm_rpc_complete_job_allocation: JobId=53102 error Job/step already completing or completed
[2022-11-25T13:14:13.568] _slurm_rpc_submit_batch_job: JobId=53116 InitPrio=12400 usec=561
[2022-11-25T13:14:14.143] sched: Allocate JobId=53116 NodeList=cpu13 #CPUs=48 Partition=cpu-epyc
[2022-11-25T13:14:18.739] _job_complete: JobId=53116 WEXITSTATUS 134
[2022-11-25T13:14:18.739] _job_complete: JobId=53116 done
[2022-11-25T13:23:53.210] Time limit exhausted for JobId=53114
[2022-11-25T13:28:54.112] cleanup_completing: JobId=53114 completion process took 301 seconds
[2022-11-25T13:39:35.086] _slurm_rpc_submit_batch_job: JobId=53117 InitPrio=12400 usec=562
[2022-11-25T13:39:35.374] sched: Allocate JobId=53117 NodeList=cpu13 #CPUs=48 Partition=cpu-epyc
[2022-11-25T13:39:36.046] _job_complete: JobId=53117 WEXITSTATUS 1
[2022-11-25T13:39:36.046] _job_complete: JobId=53117 done
[2022-11-25T13:43:51.843] _slurm_rpc_submit_batch_job: JobId=53118 InitPrio=12400 usec=582
[2022-11-25T13:43:51.867] sched: Allocate JobId=53118 NodeList=cpu14 #CPUs=24 Partition=cpu-epyc
[2022-11-25T13:43:53.871] _job_complete: JobId=53118 WEXITSTATUS 0
[2022-11-25T13:43:53.871] _job_complete: JobId=53118 done
[2022-11-25T14:40:39.420] sched: _slurm_rpc_allocate_resources JobId=53119 NodeList=cpu01 usec=25985
[2022-11-25T14:47:53.320] Time limit exhausted for JobId=53100
[2022-11-25T14:52:14.994] _slurm_rpc_submit_batch_job: JobId=53120 InitPrio=12400 usec=693
[2022-11-25T14:52:15.812] sched: Allocate JobId=53120 NodeList=cpu13 #CPUs=24 Partition=cpu-epyc
[2022-11-25T14:52:17.435] _job_complete: JobId=53120 WEXITSTATUS 0
[2022-11-25T14:52:17.435] _job_complete: JobId=53120 done
[2022-11-25T14:52:22.540] _job_complete: JobId=53075 WEXITSTATUS 0
[2022-11-25T14:52:22.546] _job_complete: JobId=53075 done
[2022-11-25T14:52:53.566] cleanup_completing: JobId=53100 completion process took 300 seconds
[2022-11-25T14:57:43.186] _slurm_rpc_submit_batch_job: JobId=53121 InitPrio=12400 usec=613
[2022-11-25T14:57:43.269] sched: Allocate JobId=53121 NodeList=cpu13 #CPUs=24 Partition=cpu-epyc
[2022-11-25T14:57:44.652] _job_complete: JobId=53121 WEXITSTATUS 0
[2022-11-25T14:57:44.652] _job_complete: JobId=53121 done
[2022-11-25T14:58:54.458] _slurm_rpc_submit_batch_job: JobId=53122 InitPrio=12400 usec=571
[2022-11-25T14:58:55.345] sched: Allocate JobId=53122 NodeList=cpu13 #CPUs=24 Partition=cpu-epyc
[2022-11-25T14:58:56.876] _job_complete: JobId=53122 WEXITSTATUS 0
[2022-11-25T14:58:56.876] _job_complete: JobId=53122 done
[2022-11-25T14:59:41.339] _slurm_rpc_submit_batch_job: JobId=53123 InitPrio=12400 usec=646
[2022-11-25T14:59:41.396] sched: Allocate JobId=53123 NodeList=cpu13 #CPUs=24 Partition=cpu-epyc
[2022-11-25T14:59:43.693] _job_complete: JobId=53123 WEXITSTATUS 0
[2022-11-25T14:59:43.694] _job_complete: JobId=53123 done
[2022-11-25T15:00:16.379] _slurm_rpc_submit_batch_job: JobId=53124 InitPrio=12400 usec=583
[2022-11-25T15:00:16.437] sched: Allocate JobId=53124 NodeList=cpu13 #CPUs=24 Partition=cpu-epyc
[2022-11-25T15:00:17.301] _job_complete: JobId=53124 WEXITSTATUS 0
[2022-11-25T15:00:17.301] _job_complete: JobId=53124 done
[2022-11-25T15:29:50.518] _slurm_rpc_submit_batch_job: JobId=53125 InitPrio=12400 usec=752
[2022-11-25T15:29:51.479] sched: Allocate JobId=53125 NodeList=cpu13 #CPUs=24 Partition=cpu-epyc
[2022-11-25T15:29:54.231] _job_complete: JobId=53125 WEXITSTATUS 0
[2022-11-25T15:29:54.231] _job_complete: JobId=53125 done
[2022-11-25T15:30:19.301] _slurm_rpc_submit_batch_job: JobId=53126 InitPrio=12400 usec=1540
[2022-11-25T15:30:19.512] sched: Allocate JobId=53126 NodeList=cpu13 #CPUs=24 Partition=cpu-epyc
[2022-11-25T15:30:20.692] _job_complete: JobId=53126 WEXITSTATUS 0
[2022-11-25T15:30:20.692] _job_complete: JobId=53126 done
[2022-11-25T15:30:48.131] _slurm_rpc_submit_batch_job: JobId=53127 InitPrio=12400 usec=514
[2022-11-25T15:30:48.547] sched: Allocate JobId=53127 NodeList=cpu13 #CPUs=24 Partition=cpu-epyc
[2022-11-25T15:30:50.109] _job_complete: JobId=53127 WEXITSTATUS 0
[2022-11-25T15:30:50.109] _job_complete: JobId=53127 done
[2022-11-25T15:31:18.413] _slurm_rpc_submit_batch_job: JobId=53128 InitPrio=12400 usec=530
[2022-11-25T15:31:18.587] sched: Allocate JobId=53128 NodeList=cpu13 #CPUs=24 Partition=cpu-epyc
[2022-11-25T15:31:19.775] _job_complete: JobId=53128 WEXITSTATUS 0
[2022-11-25T15:31:19.775] _job_complete: JobId=53128 done
[2022-11-25T15:31:44.563] _slurm_rpc_submit_batch_job: JobId=53129 InitPrio=12400 usec=487
[2022-11-25T15:31:44.693] sched: Allocate JobId=53129 NodeList=cpu13 #CPUs=24 Partition=cpu-epyc
[2022-11-25T15:31:46.576] _job_complete: JobId=53129 WEXITSTATUS 0
[2022-11-25T15:31:46.576] _job_complete: JobId=53129 done
[2022-11-25T15:31:59.936] sched: _slurm_rpc_allocate_resources JobId=53130 NodeList=cpu13 usec=20840
[2022-11-25T15:32:10.677] _slurm_rpc_submit_batch_job: JobId=53131 InitPrio=12400 usec=626
[2022-11-25T15:32:10.725] sched: Allocate JobId=53131 NodeList=cpu13 #CPUs=24 Partition=cpu-epyc
[2022-11-25T15:32:13.465] _job_complete: JobId=53131 WEXITSTATUS 0
[2022-11-25T15:32:13.466] _job_complete: JobId=53131 done
[2022-11-25T15:40:53.635] Time limit exhausted for JobId=53119
[2022-11-25T15:40:53.680]    retry_list retry_list_size:101 msg_type=SRUN_TIMEOUT,SRUN_TIMEOUT,SRUN_TIMEOUT,SRUN_TIMEOUT,SRUN_TIMEOUT
[2022-11-25T15:45:54.555] cleanup_completing: JobId=53119 completion process took 301 seconds
[2022-11-25T15:45:54.579]    retry_list retry_list_size:101 msg_type=SRUN_STEP_SIGNAL,SRUN_STEP_SIGNAL,SRUN_STEP_SIGNAL,SRUN_STEP_SIGNAL,SRUN_STEP_SIGNAL
[2022-11-25T15:47:22.566] _slurm_rpc_submit_batch_job: JobId=53132 InitPrio=12400 usec=584
[2022-11-25T15:47:22.964] sched: Allocate JobId=53132 NodeList=cpu13 #CPUs=24 Partition=cpu-epyc
[2022-11-25T15:47:25.740] _job_complete: JobId=53132 WEXITSTATUS 0
[2022-11-25T15:47:25.740] _job_complete: JobId=53132 done
[2022-11-25T15:57:09.587] _slurm_rpc_submit_batch_job: JobId=53133 InitPrio=600 usec=620
[2022-11-25T15:57:10.003] sched: Allocate JobId=53133 NodeList=cpu14 #CPUs=48 Partition=cpu-epyc
[2022-11-25T15:57:12.183] _job_complete: JobId=53133 WEXITSTATUS 1
[2022-11-25T15:57:12.183] _job_complete: JobId=53133 done
[2022-11-25T15:57:35.195] _slurm_rpc_submit_batch_job: JobId=53134 InitPrio=600 usec=585
[2022-11-25T15:57:36.035] sched: Allocate JobId=53134 NodeList=cpu14 #CPUs=48 Partition=cpu-epyc
[2022-11-25T16:05:46.342] _job_complete: JobId=53134 WEXITSTATUS 0
[2022-11-25T16:05:46.343] _job_complete: JobId=53134 done
[2022-11-25T16:13:55.866] _slurm_rpc_submit_batch_job: JobId=53135 InitPrio=600 usec=541
[2022-11-25T16:13:56.605] sched: Allocate JobId=53135 NodeList=cpu14 #CPUs=48 Partition=cpu-epyc
[2022-11-25T16:33:02.859] _job_complete: JobId=53130 WEXITSTATUS 0
[2022-11-25T16:33:02.859] _job_complete: JobId=53130 done
[2022-11-25T16:46:25.672] _job_complete: JobId=53135 WEXITSTATUS 0
[2022-11-25T16:46:25.672] _job_complete: JobId=53135 done
[2022-11-25T17:55:23.306] _slurm_rpc_kill_job: REQUEST_KILL_JOB JobId=52766 uid 548300621
[2022-11-25T17:55:24.114] _slurm_rpc_kill_job: REQUEST_KILL_JOB JobId=52766 uid 548300621
[2022-11-25T17:55:43.576] _slurm_rpc_submit_batch_job: JobId=53136 InitPrio=200 usec=583
[2022-11-25T17:55:47.212] _slurm_rpc_submit_batch_job: JobId=53137 InitPrio=200 usec=542
[2022-11-25T17:55:51.989] _slurm_rpc_submit_batch_job: JobId=53138 InitPrio=200 usec=535
[2022-11-25T17:55:58.810] _slurm_rpc_submit_batch_job: JobId=53139 InitPrio=200 usec=524
[2022-11-25T17:56:07.116] _slurm_rpc_submit_batch_job: JobId=53140 InitPrio=200 usec=495
[2022-11-25T21:41:24.659] Time limit exhausted for JobId=53072
[2022-11-25T21:42:24.865] Time limit exhausted for JobId=53073
[2022-11-25T21:42:24.865] Time limit exhausted for JobId=53074
[2022-11-25T23:31:02.585] _slurm_rpc_kill_job: REQUEST_KILL_JOB JobId=53028 uid 548200003
[2022-11-26T00:24:39.749] error: Nodes cpu[08,10] not responding, setting DOWN
[2022-11-26T00:24:40.750] sched: Updated reservation=storage_upgrade_maintenance users=jitkang nodes=cpu[01,03-05,07-15],gpu[01-05],umhpc cores=880 licenses=(null) tres=cpu=1168 watts=4294967294 start=2022-11-26T00:00:00 end=2023-11-26T00:00:00 MaxStartDelay=
[2022-11-26T00:25:59.849] error: Nodes cpu11 not responding, setting DOWN
[2022-11-26T00:26:00.850] sched: Updated reservation=storage_upgrade_maintenance users=jitkang nodes=cpu[01,03-05,07-15],gpu[01-05],umhpc cores=880 licenses=(null) tres=cpu=1168 watts=4294967294 start=2022-11-26T00:00:00 end=2023-11-26T00:00:00 MaxStartDelay=
[2022-11-26T00:41:19.364] error: Nodes cpu13 not responding
[2022-11-26T00:41:19.364] error: Nodes cpu13 not responding, setting DOWN
[2022-11-26T00:41:20.384] sched: Updated reservation=storage_upgrade_maintenance users=jitkang nodes=cpu[01,03-05,07-15],gpu[01-05],umhpc cores=880 licenses=(null) tres=cpu=1168 watts=4294967294 start=2022-11-26T00:00:00 end=2023-11-26T00:00:00 MaxStartDelay=
[2022-11-26T00:42:39.524] error: Nodes cpu14 not responding, setting DOWN
[2022-11-26T00:42:40.526] sched: Updated reservation=storage_upgrade_maintenance users=jitkang nodes=cpu[01,03-05,07-15],gpu[01-05],umhpc cores=880 licenses=(null) tres=cpu=1168 watts=4294967294 start=2022-11-26T00:00:00 end=2023-11-26T00:00:00 MaxStartDelay=
[2022-11-26T00:57:20.058] Node cpu08 now responding
[2022-11-26T00:57:20.058] node cpu08 returned to service
[2022-11-26T00:59:58.030] Node cpu10 now responding
[2022-11-26T00:59:58.030] node cpu10 returned to service
[2022-11-26T01:13:22.887] Node cpu11 now responding
[2022-11-26T01:13:22.887] node cpu11 returned to service
[2022-11-26T01:38:59.751] Node cpu13 now responding
[2022-11-26T01:38:59.751] node cpu13 returned to service
[2022-11-26T01:40:59.720] error: Nodes cpu13 not responding, setting DOWN
[2022-11-26T01:41:00.722] sched: Updated reservation=storage_upgrade_maintenance users=jitkang nodes=cpu[01,03-05,07-15],gpu[01-05],umhpc cores=880 licenses=(null) tres=cpu=1168 watts=4294967294 start=2022-11-26T00:00:00 end=2023-11-26T00:00:00 MaxStartDelay=
[2022-11-26T01:43:25.678] Node cpu14 now responding
[2022-11-26T01:43:25.678] node cpu14 returned to service
[2022-11-26T01:57:14.837] Node cpu13 now responding
[2022-11-26T01:57:14.837] node cpu13 returned to service
[2022-11-26T09:27:53.602] _slurm_rpc_delete_reservation complete for storage_upgrade_maintenance usec=149
[2022-11-26T09:27:54.294] sched: Allocate JobId=51867 NodeList=gpu05 #CPUs=12 Partition=gpu-v100s
[2022-11-26T09:27:54.309] sched: Allocate JobId=52407 NodeList=gpu05 #CPUs=4 Partition=gpu-v100s
[2022-11-26T09:27:54.325] sched: Allocate JobId=52684 NodeList=gpu03 #CPUs=16 Partition=gpu-k10
[2022-11-26T09:27:54.352] sched: Allocate JobId=52772 NodeList=gpu02 #CPUs=6 Partition=gpu-titan
[2022-11-26T09:27:54.353] sched: Allocate JobId=52773 NodeList=gpu02 #CPUs=5 Partition=gpu-titan
[2022-11-26T09:27:54.354] sched: Allocate JobId=52727 NodeList=cpu12 #CPUs=48 Partition=cpu-epyc
[2022-11-26T09:27:54.373] sched: Allocate JobId=52787 NodeList=gpu01 #CPUs=16 Partition=gpu-k10
[2022-11-26T09:27:54.378] sched: Allocate JobId=52811 NodeList=gpu02 #CPUs=4 Partition=gpu-titan
[2022-11-26T09:27:54.393] sched: Allocate JobId=52838 NodeList=cpu13 #CPUs=8 Partition=cpu-epyc
[2022-11-26T09:27:54.394] sched: Allocate JobId=52840 NodeList=cpu13 #CPUs=8 Partition=cpu-epyc
[2022-11-26T09:27:54.395] sched: Allocate JobId=52841 NodeList=cpu13 #CPUs=8 Partition=cpu-epyc
[2022-11-26T09:27:54.395] sched: Allocate JobId=52842 NodeList=cpu14 #CPUs=8 Partition=cpu-epyc
[2022-11-26T09:27:54.396] sched: Allocate JobId=52843 NodeList=cpu14 #CPUs=8 Partition=cpu-epyc
[2022-11-26T09:27:54.397] sched: Allocate JobId=52844 NodeList=cpu14 #CPUs=8 Partition=cpu-epyc
[2022-11-26T09:27:54.397] sched: Allocate JobId=52845 NodeList=cpu15 #CPUs=8 Partition=cpu-epyc
[2022-11-26T09:27:54.398] sched: Allocate JobId=52846 NodeList=cpu15 #CPUs=8 Partition=cpu-epyc
[2022-11-26T09:27:54.399] sched: Allocate JobId=52847 NodeList=cpu15 #CPUs=8 Partition=cpu-epyc
[2022-11-26T09:27:54.400] sched: Allocate JobId=52963 NodeList=cpu01 #CPUs=16 Partition=cpu-opteron
[2022-11-26T09:27:54.401] sched: Allocate JobId=52964 NodeList=cpu01 #CPUs=16 Partition=cpu-opteron
[2022-11-26T09:27:54.438] sched: Allocate JobId=52974 NodeList=cpu01 #CPUs=32 Partition=cpu-opteron
[2022-11-26T09:27:54.439] sched: Allocate JobId=52975 NodeList=cpu03 #CPUs=32 Partition=cpu-opteron
[2022-11-26T09:27:54.495] sched: Allocate JobId=53084 NodeList=cpu03 #CPUs=4 Partition=cpu-opteron
[2022-11-26T09:27:54.525] sched: Allocate JobId=53021 NodeList=cpu04 #CPUs=64 Partition=cpu-opteron
[2022-11-26T09:27:54.551] sched: Allocate JobId=53136 NodeList=cpu05 #CPUs=64 Partition=cpu-opteron
[2022-11-26T09:27:54.552] sched: Allocate JobId=53137 NodeList=cpu07 #CPUs=64 Partition=cpu-opteron
[2022-11-26T09:27:54.553] sched: Allocate JobId=53138 NodeList=cpu08 #CPUs=64 Partition=cpu-opteron
[2022-11-26T09:27:54.553] sched: Allocate JobId=53139 NodeList=cpu09 #CPUs=64 Partition=cpu-opteron
[2022-11-26T09:27:54.554] sched: Allocate JobId=53140 NodeList=cpu10 #CPUs=64 Partition=cpu-opteron
[2022-11-26T09:28:04.985] _job_complete: JobId=52963 WEXITSTATUS 0
[2022-11-26T09:28:04.986] _job_complete: JobId=52963 done
[2022-11-26T09:28:08.754] _job_complete: JobId=52975 WEXITSTATUS 1
[2022-11-26T09:28:08.755] _job_complete: JobId=52975 done
[2022-11-26T09:28:11.686] _job_complete: JobId=52727 WEXITSTATUS 120
[2022-11-26T09:28:11.686] _job_complete: JobId=52727 done
[2022-11-26T09:28:11.877] _job_complete: JobId=52684 WEXITSTATUS 120
[2022-11-26T09:28:11.877] _job_complete: JobId=52684 done
[2022-11-26T09:28:11.982] sched: Allocate JobId=52848 NodeList=cpu12 #CPUs=8 Partition=cpu-epyc
[2022-11-26T09:28:11.983] sched: Allocate JobId=52849 NodeList=cpu12 #CPUs=8 Partition=cpu-epyc
[2022-11-26T09:28:11.984] sched: Allocate JobId=52850 NodeList=cpu12 #CPUs=8 Partition=cpu-epyc
[2022-11-26T09:28:12.495] sched: Allocate JobId=52699 NodeList=gpu03 #CPUs=16 Partition=gpu-k10
[2022-11-26T09:28:13.623] _job_complete: JobId=52699 WEXITSTATUS 127
[2022-11-26T09:28:13.623] _job_complete: JobId=52699 done
[2022-11-26T09:28:14.244] sched: Allocate JobId=52701 NodeList=gpu03 #CPUs=16 Partition=gpu-k10
[2022-11-26T09:28:15.361] _job_complete: JobId=52701 WEXITSTATUS 126
[2022-11-26T09:28:15.361] _job_complete: JobId=52701 done
[2022-11-26T09:28:15.975] sched: Allocate JobId=52923 NodeList=gpu03 #CPUs=16 Partition=gpu-k10
[2022-11-26T09:28:30.018] _job_complete: JobId=52964 WEXITSTATUS 0
[2022-11-26T09:28:30.019] _job_complete: JobId=52964 done
[2022-11-26T10:00:20.505] _job_complete: JobId=53084 WEXITSTATUS 1
[2022-11-26T10:00:20.505] _job_complete: JobId=53084 done
[2022-11-26T10:00:53.990] _job_complete: JobId=52847 WEXITSTATUS 0
[2022-11-26T10:00:53.990] _job_complete: JobId=52847 done
[2022-11-26T10:00:55.204] sched: Allocate JobId=52851 NodeList=cpu15 #CPUs=8 Partition=cpu-epyc
[2022-11-26T10:00:57.796] sched/backfill: _start_job: Started JobId=52915 in cpu-epyc on cpu15
[2022-11-26T10:11:44.461] _slurm_rpc_submit_batch_job: JobId=53141 InitPrio=600 usec=771
[2022-11-26T10:11:45.074] sched: Allocate JobId=53141 NodeList=gpu04 #CPUs=16 Partition=gpu-k40c
[2022-11-26T10:11:46.634] _job_complete: JobId=53141 WEXITSTATUS 126
[2022-11-26T10:11:46.634] _job_complete: JobId=53141 done
[2022-11-26T10:14:14.760] _slurm_rpc_submit_batch_job: JobId=53142 InitPrio=600 usec=528
[2022-11-26T10:14:15.261] sched: Allocate JobId=53142 NodeList=gpu04 #CPUs=16 Partition=gpu-k40c
[2022-11-26T10:14:15.740] _job_complete: JobId=53142 WEXITSTATUS 126
[2022-11-26T10:14:15.740] _job_complete: JobId=53142 done
[2022-11-26T10:16:11.608] _slurm_rpc_submit_batch_job: JobId=53143 InitPrio=600 usec=477
[2022-11-26T10:16:12.404] sched: Allocate JobId=53143 NodeList=gpu04 #CPUs=16 Partition=gpu-k40c
[2022-11-26T10:16:41.466] _job_complete: JobId=53143 WEXITSTATUS 1
[2022-11-26T10:16:41.466] _job_complete: JobId=53143 done
[2022-11-26T10:18:13.560] sched: _slurm_rpc_allocate_resources JobId=53144 NodeList=(null) usec=811
[2022-11-26T10:18:13.660] sched: Allocate JobId=53144 NodeList=cpu11 #CPUs=32 Partition=cpu-opteron
[2022-11-26T10:18:22.945] _slurm_rpc_submit_batch_job: JobId=53145 InitPrio=600 usec=492
[2022-11-26T10:18:23.654] sched: Allocate JobId=53145 NodeList=gpu04 #CPUs=16 Partition=gpu-k40c
[2022-11-26T10:18:24.305] _job_complete: JobId=53145 WEXITSTATUS 126
[2022-11-26T10:18:24.305] _job_complete: JobId=53145 done
[2022-11-26T10:19:21.192] _slurm_rpc_submit_batch_job: JobId=53146 InitPrio=600 usec=570
[2022-11-26T10:19:21.730] sched: Allocate JobId=53146 NodeList=gpu04 #CPUs=16 Partition=gpu-k40c
[2022-11-26T10:19:22.351] _job_complete: JobId=53146 WEXITSTATUS 126
[2022-11-26T10:19:22.352] _job_complete: JobId=53146 done
[2022-11-26T10:22:01.555] sched: _slurm_rpc_allocate_resources JobId=53147 NodeList=(null) usec=997
[2022-11-26T10:22:02.072] sched: Allocate JobId=53147 NodeList=cpu11 #CPUs=32 Partition=cpu-opteron
[2022-11-26T10:22:09.690] _slurm_rpc_submit_batch_job: JobId=53148 InitPrio=600 usec=479
[2022-11-26T10:22:10.083] sched: Allocate JobId=53148 NodeList=gpu04 #CPUs=16 Partition=gpu-k40c
[2022-11-26T10:22:10.649] _job_complete: JobId=53148 WEXITSTATUS 127
[2022-11-26T10:22:10.650] _job_complete: JobId=53148 done
[2022-11-26T10:24:58.043] _slurm_rpc_submit_batch_job: JobId=53149 InitPrio=600 usec=604
[2022-11-26T10:24:58.302] sched: Allocate JobId=53149 NodeList=gpu04 #CPUs=16 Partition=gpu-k40c
[2022-11-26T10:25:16.842] _job_complete: JobId=53149 WEXITSTATUS 1
[2022-11-26T10:25:16.842] _job_complete: JobId=53149 done
[2022-11-26T10:25:22.199] _slurm_rpc_submit_batch_job: JobId=53150 InitPrio=600 usec=518
[2022-11-26T10:25:22.332] sched: Allocate JobId=53150 NodeList=gpu04 #CPUs=16 Partition=gpu-k40c
[2022-11-26T10:25:41.517] _job_complete: JobId=53150 WEXITSTATUS 1
[2022-11-26T10:25:41.518] _job_complete: JobId=53150 done
[2022-11-26T10:29:15.375] _slurm_rpc_submit_batch_job: JobId=53151 InitPrio=600 usec=602
[2022-11-26T10:29:15.732] sched: Allocate JobId=53151 NodeList=cpu01 #CPUs=1 Partition=cpu-opteron
[2022-11-26T10:30:33.631] _job_complete: JobId=53151 WEXITSTATUS 0
[2022-11-26T10:30:33.631] _job_complete: JobId=53151 done
[2022-11-26T10:30:35.781] _slurm_rpc_submit_batch_job: JobId=53152 InitPrio=600 usec=581
[2022-11-26T10:30:35.833] sched: Allocate JobId=53152 NodeList=gpu04 #CPUs=16 Partition=gpu-k40c
[2022-11-26T10:30:37.360] _job_complete: JobId=53152 WEXITSTATUS 126
[2022-11-26T10:30:37.361] _job_complete: JobId=53152 done
[2022-11-26T10:33:09.144] _slurm_rpc_submit_batch_job: JobId=53153 InitPrio=600 usec=522
[2022-11-26T10:33:09.155] sched: Allocate JobId=53153 NodeList=gpu04 #CPUs=16 Partition=gpu-k40c
[2022-11-26T10:34:02.021] _slurm_rpc_kill_job: REQUEST_KILL_JOB JobId=53153 uid 548200021
[2022-11-26T10:34:43.494] _slurm_rpc_submit_batch_job: JobId=53154 InitPrio=600 usec=587
[2022-11-26T10:34:44.275] sched: Allocate JobId=53154 NodeList=gpu04 #CPUs=16 Partition=gpu-k40c
[2022-11-26T10:34:44.790] _job_complete: JobId=53154 WEXITSTATUS 127
[2022-11-26T10:34:44.790] _job_complete: JobId=53154 done
[2022-11-26T10:36:04.831] _slurm_rpc_submit_batch_job: JobId=53155 InitPrio=600 usec=543
[2022-11-26T10:36:05.377] sched: Allocate JobId=53155 NodeList=gpu04 #CPUs=16 Partition=gpu-k40c
[2022-11-26T10:36:07.057] _job_complete: JobId=53155 WEXITSTATUS 126
[2022-11-26T10:36:07.057] _job_complete: JobId=53155 done
[2022-11-26T10:36:34.428] _slurm_rpc_submit_batch_job: JobId=53156 InitPrio=600 usec=559
[2022-11-26T10:36:34.556] sched: Allocate JobId=53156 NodeList=gpu04 #CPUs=16 Partition=gpu-k40c
[2022-11-26T10:36:35.139] _job_complete: JobId=53156 WEXITSTATUS 127
[2022-11-26T10:36:35.139] _job_complete: JobId=53156 done
[2022-11-26T10:37:48.234] _slurm_rpc_submit_batch_job: JobId=53157 InitPrio=600 usec=588
[2022-11-26T10:37:48.647] sched: Allocate JobId=53157 NodeList=gpu04 #CPUs=16 Partition=gpu-k40c
[2022-11-26T10:38:10.782] _job_complete: JobId=53157 WEXITSTATUS 1
[2022-11-26T10:38:10.782] _job_complete: JobId=53157 done
[2022-11-26T10:40:26.643] _slurm_rpc_submit_batch_job: JobId=53158 InitPrio=600 usec=801
[2022-11-26T10:40:26.850] sched: Allocate JobId=53158 NodeList=gpu04 #CPUs=16 Partition=gpu-k40c
[2022-11-26T10:44:44.087] _slurm_rpc_submit_batch_job: JobId=53159 InitPrio=600 usec=622
[2022-11-26T10:52:11.359] _job_complete: JobId=53158 WEXITSTATUS 0
[2022-11-26T10:52:11.359] _job_complete: JobId=53158 done
[2022-11-26T10:52:11.800] sched: Allocate JobId=53159 NodeList=gpu04 #CPUs=16 Partition=gpu-k40c
[2022-11-26T10:52:30.619] _job_complete: JobId=53159 WEXITSTATUS 1
[2022-11-26T10:52:30.619] _job_complete: JobId=53159 done
[2022-11-26T12:00:05.157] _slurm_rpc_submit_batch_job: JobId=53160 InitPrio=400 usec=520
[2022-11-26T12:00:05.960] sched: Allocate JobId=53160 NodeList=cpu03 #CPUs=64 Partition=cpu-opteron
[2022-11-26T12:09:31.925] _slurm_rpc_submit_batch_job: JobId=53161 InitPrio=400 usec=525
[2022-11-26T14:25:38.545] _slurm_rpc_submit_batch_job: JobId=53162 InitPrio=600 usec=626
[2022-11-26T14:25:39.005] sched: Allocate JobId=53162 NodeList=cpu01 #CPUs=1 Partition=cpu-opteron
[2022-11-26T14:27:44.788] _job_complete: JobId=53162 WEXITSTATUS 0
[2022-11-26T14:27:44.788] _job_complete: JobId=53162 done
[2022-11-26T15:22:54.237] _job_complete: JobId=53144 WEXITSTATUS 0
[2022-11-26T15:22:54.237] _job_complete: JobId=53144 done
[2022-11-26T15:37:26.192] _job_complete: JobId=53147 WEXITSTATUS 0
[2022-11-26T15:37:26.192] _job_complete: JobId=53147 done
[2022-11-26T15:37:32.307] sched: Allocate JobId=53161 NodeList=cpu11 #CPUs=64 Partition=cpu-opteron
[2022-11-26T16:25:32.226] _slurm_rpc_submit_batch_job: JobId=53163 InitPrio=600 usec=835
[2022-11-26T16:25:32.534] sched: Allocate JobId=53163 NodeList=gpu04 #CPUs=16 Partition=gpu-k40c
[2022-11-26T16:27:02.124] _slurm_rpc_submit_batch_job: JobId=53164 InitPrio=600 usec=556
[2022-11-26T16:27:15.927] _slurm_rpc_kill_job: REQUEST_KILL_JOB JobId=53163 uid 548200021
[2022-11-26T16:27:18.089] sched: Allocate JobId=53164 NodeList=gpu04 #CPUs=16 Partition=gpu-k40c
[2022-11-26T16:27:20.803] _job_complete: JobId=53164 WEXITSTATUS 127
[2022-11-26T16:27:20.803] _job_complete: JobId=53164 done
[2022-11-26T16:28:04.290] _slurm_rpc_submit_batch_job: JobId=53165 InitPrio=600 usec=488
[2022-11-26T16:28:04.448] sched: Allocate JobId=53165 NodeList=gpu04 #CPUs=16 Partition=gpu-k40c
[2022-11-26T16:28:05.452] _job_complete: JobId=53165 WEXITSTATUS 127
[2022-11-26T16:28:05.452] _job_complete: JobId=53165 done
[2022-11-26T16:28:46.254] _slurm_rpc_submit_batch_job: JobId=53166 InitPrio=600 usec=631
[2022-11-26T16:28:46.500] sched: Allocate JobId=53166 NodeList=gpu04 #CPUs=16 Partition=gpu-k40c
[2022-11-26T16:28:47.254] _job_complete: JobId=53166 WEXITSTATUS 127
[2022-11-26T16:28:47.254] _job_complete: JobId=53166 done
[2022-11-26T16:29:18.477] _slurm_rpc_submit_batch_job: JobId=53167 InitPrio=600 usec=532
[2022-11-26T16:29:18.538] sched: Allocate JobId=53167 NodeList=gpu04 #CPUs=16 Partition=gpu-k40c
[2022-11-26T16:29:28.750] _job_complete: JobId=53167 WEXITSTATUS 127
[2022-11-26T16:29:28.751] _job_complete: JobId=53167 done
[2022-11-26T16:30:05.933] _slurm_rpc_submit_batch_job: JobId=53168 InitPrio=600 usec=576
[2022-11-26T16:30:06.596] sched: Allocate JobId=53168 NodeList=gpu04 #CPUs=16 Partition=gpu-k40c
[2022-11-26T16:30:07.708] _job_complete: JobId=53168 WEXITSTATUS 127
[2022-11-26T16:30:07.708] _job_complete: JobId=53168 done
[2022-11-26T16:31:11.558] _slurm_rpc_submit_batch_job: JobId=53169 InitPrio=600 usec=491
[2022-11-26T16:31:11.674] sched: Allocate JobId=53169 NodeList=gpu04 #CPUs=16 Partition=gpu-k40c
[2022-11-26T16:31:12.267] _job_complete: JobId=53169 WEXITSTATUS 126
[2022-11-26T16:31:12.267] _job_complete: JobId=53169 done
[2022-11-26T16:31:40.485] _slurm_rpc_submit_batch_job: JobId=53170 InitPrio=600 usec=585
[2022-11-26T16:31:40.924] sched: Allocate JobId=53170 NodeList=gpu04 #CPUs=16 Partition=gpu-k40c
[2022-11-26T16:31:41.412] _job_complete: JobId=53170 WEXITSTATUS 127
[2022-11-26T16:31:41.412] _job_complete: JobId=53170 done
[2022-11-26T16:32:56.700] _slurm_rpc_submit_batch_job: JobId=53171 InitPrio=600 usec=519
[2022-11-26T16:32:57.016] sched: Allocate JobId=53171 NodeList=gpu04 #CPUs=16 Partition=gpu-k40c
[2022-11-26T16:32:59.247] _job_complete: JobId=53171 WEXITSTATUS 127
[2022-11-26T16:32:59.247] _job_complete: JobId=53171 done
[2022-11-26T16:34:38.188] _slurm_rpc_submit_batch_job: JobId=53172 InitPrio=600 usec=503
[2022-11-26T16:34:39.142] sched: Allocate JobId=53172 NodeList=gpu04 #CPUs=16 Partition=gpu-k40c
[2022-11-26T16:34:39.644] _job_complete: JobId=53172 WEXITSTATUS 127
[2022-11-26T16:34:39.645] _job_complete: JobId=53172 done
[2022-11-26T16:36:23.298] _slurm_rpc_submit_batch_job: JobId=53173 InitPrio=600 usec=525
[2022-11-26T16:36:23.515] sched: Allocate JobId=53173 NodeList=gpu04 #CPUs=16 Partition=gpu-k40c
[2022-11-26T16:36:24.012] _job_complete: JobId=53173 WEXITSTATUS 127
[2022-11-26T16:36:24.012] _job_complete: JobId=53173 done
[2022-11-26T16:47:31.054] sched: _slurm_rpc_allocate_resources JobId=53174 NodeList=(null) usec=970
[2022-11-26T16:47:58.357] sched/backfill: _start_job: Started JobId=53174 in cpu-epyc on cpu12
[2022-11-26T16:47:59.400] _job_complete: JobId=53174 WTERMSIG 126
[2022-11-26T16:47:59.400] _job_complete: JobId=53174 cancelled by interactive user
[2022-11-26T16:47:59.400] _job_complete: JobId=53174 done
[2022-11-26T16:47:59.402] _slurm_rpc_complete_job_allocation: JobId=53174 error Job/step already completing or completed
[2022-11-26T16:48:20.650] sched: _slurm_rpc_allocate_resources JobId=53175 NodeList=(null) usec=1122
[2022-11-26T16:48:55.978] sched: _slurm_rpc_allocate_resources JobId=53176 NodeList=(null) usec=699
[2022-11-26T16:48:56.785] sched: Allocate JobId=53176 NodeList=cpu01 #CPUs=2 Partition=cpu-opteron
[2022-11-26T16:48:58.359] sched/backfill: _start_job: Started JobId=53175 in cpu-epyc on cpu12
[2022-11-26T16:49:09.629] _job_complete: JobId=53176 WEXITSTATUS 0
[2022-11-26T16:49:09.629] _job_complete: JobId=53176 done
[2022-11-26T17:24:34.470] _job_complete: JobId=53175 WEXITSTATUS 0
[2022-11-26T17:24:34.470] _job_complete: JobId=53175 done
[2022-11-26T20:27:33.052] _slurm_rpc_submit_batch_job: JobId=53177 InitPrio=2400 usec=649
[2022-11-26T20:54:19.209] _slurm_rpc_submit_batch_job: JobId=53178 InitPrio=800 usec=499
[2022-11-26T21:24:04.755] _job_complete: JobId=52844 WEXITSTATUS 0
[2022-11-26T21:24:04.755] _job_complete: JobId=52844 done
[2022-11-26T21:24:05.521] sched: Allocate JobId=52852 NodeList=cpu14 #CPUs=8 Partition=cpu-epyc
[2022-11-26T21:24:58.734] sched/backfill: _start_job: Started JobId=52956 in cpu-epyc on cpu14
[2022-11-26T21:25:08.440] _job_complete: JobId=52956 WEXITSTATUS 1
[2022-11-26T21:25:08.441] _job_complete: JobId=52956 done
[2022-11-26T21:25:58.737] sched/backfill: _start_job: Started JobId=52976 in cpu-epyc on cpu14
[2022-11-26T21:26:58.690] _job_complete: JobId=52976 WEXITSTATUS 134
[2022-11-26T21:26:58.691] _job_complete: JobId=52976 done
[2022-11-26T21:27:58.742] sched/backfill: _start_job: Started JobId=53020 in cpu-epyc on cpu14
[2022-11-26T21:31:23.131] _job_complete: JobId=52843 WEXITSTATUS 1
[2022-11-26T21:31:23.131] _job_complete: JobId=52843 done
[2022-11-26T21:31:24.066] sched: Allocate JobId=52853 NodeList=cpu14 #CPUs=8 Partition=cpu-epyc
[2022-11-26T21:31:24.730] _job_complete: JobId=53020 WEXITSTATUS 2
[2022-11-26T21:31:24.731] _job_complete: JobId=53020 done
[2022-11-26T21:31:25.585] _job_complete: JobId=52848 WEXITSTATUS 0
[2022-11-26T21:31:25.585] _job_complete: JobId=52848 done
[2022-11-26T21:31:26.453] sched: Allocate JobId=52854 NodeList=cpu12 #CPUs=8 Partition=cpu-epyc
[2022-11-26T21:31:30.402] _job_complete: JobId=52850 WEXITSTATUS 0
[2022-11-26T21:31:30.402] _job_complete: JobId=52850 done
[2022-11-26T21:31:58.749] sched/backfill: _start_job: Started JobId=53034 in cpu-epyc on cpu14
[2022-11-26T21:34:34.333] _job_complete: JobId=52838 WEXITSTATUS 0
[2022-11-26T21:34:34.333] _job_complete: JobId=52838 done
[2022-11-26T21:34:34.607] _job_complete: JobId=52842 WEXITSTATUS 1
[2022-11-26T21:34:34.607] _job_complete: JobId=52842 done
[2022-11-26T21:36:05.241] _job_complete: JobId=53034 WEXITSTATUS 2
[2022-11-26T21:36:05.242] _job_complete: JobId=53034 done
[2022-11-26T21:40:41.899] _job_complete: JobId=52849 WEXITSTATUS 0
[2022-11-26T21:40:41.899] _job_complete: JobId=52849 done
[2022-11-26T21:41:10.597] _job_complete: JobId=52846 WEXITSTATUS 0
[2022-11-26T21:41:10.597] _job_complete: JobId=52846 done
[2022-11-26T21:47:56.889] _job_complete: JobId=52841 WEXITSTATUS 0
[2022-11-26T21:47:56.889] _job_complete: JobId=52841 done
[2022-11-26T21:56:17.052] _slurm_rpc_kill_job: REQUEST_KILL_JOB JobId=53177 uid 548300630
[2022-11-26T21:56:42.914] _slurm_rpc_submit_batch_job: JobId=53179 InitPrio=2400 usec=662
[2022-11-26T22:06:12.266] _job_complete: JobId=52840 WEXITSTATUS 0
[2022-11-26T22:06:12.266] _job_complete: JobId=52840 done
[2022-11-26T22:06:12.549] sched: Allocate JobId=53098 NodeList=cpu13 #CPUs=48 Partition=cpu-epyc
[2022-11-26T22:10:14.497] _job_complete: JobId=52851 WEXITSTATUS 0
[2022-11-26T22:10:14.498] _job_complete: JobId=52851 done
[2022-11-26T22:11:08.446] _slurm_rpc_submit_batch_job: JobId=53180 InitPrio=400 usec=550
[2022-11-26T22:11:09.281] sched: Allocate JobId=53180 NodeList=cpu14 #CPUs=24 Partition=cpu-epyc
[2022-11-26T22:12:17.724] _slurm_rpc_submit_batch_job: JobId=53181 InitPrio=400 usec=486
[2022-11-26T22:12:18.726] sched: Allocate JobId=53181 NodeList=cpu12 #CPUs=24 Partition=cpu-epyc
[2022-11-26T22:13:44.543] _slurm_rpc_submit_batch_job: JobId=53182 InitPrio=400 usec=490
[2022-11-26T22:14:50.389] _job_complete: JobId=53180 WEXITSTATUS 2
[2022-11-26T22:14:50.389] _job_complete: JobId=53180 done
[2022-11-26T22:14:51.293] sched: Allocate JobId=53182 NodeList=cpu14 #CPUs=24 Partition=cpu-epyc
[2022-11-26T22:17:01.717] _job_complete: JobId=53182 WEXITSTATUS 1
[2022-11-26T22:17:01.718] _job_complete: JobId=53182 done
[2022-11-26T22:27:43.134] _job_complete: JobId=52845 WEXITSTATUS 0
[2022-11-26T22:27:43.134] _job_complete: JobId=52845 done
[2022-11-26T22:27:58.312] _slurm_rpc_submit_batch_job: JobId=53183 InitPrio=400 usec=486
[2022-11-26T22:33:44.838] _slurm_rpc_kill_job: REQUEST_KILL_JOB JobId=53181 uid 548200017
[2022-11-26T22:44:30.117] _slurm_rpc_kill_job: REQUEST_KILL_JOB JobId=52915 uid 548200017
[2022-11-26T22:44:36.043] sched: Allocate JobId=53183 NodeList=cpu15 #CPUs=48 Partition=cpu-epyc
[2022-11-26T22:52:15.559] _slurm_rpc_submit_batch_job: JobId=53184 InitPrio=400 usec=505
[2022-11-26T22:52:16.151] sched: Allocate JobId=53184 NodeList=cpu14 #CPUs=24 Partition=cpu-epyc
[2022-11-26T22:52:52.414] _job_complete: JobId=53184 WEXITSTATUS 1
[2022-11-26T22:52:52.415] _job_complete: JobId=53184 done
[2022-11-26T22:53:25.695] _slurm_rpc_submit_batch_job: JobId=53185 InitPrio=400 usec=507
[2022-11-26T22:53:26.238] sched: Allocate JobId=53185 NodeList=cpu14 #CPUs=24 Partition=cpu-epyc
[2022-11-26T22:53:30.556] _job_complete: JobId=53185 WEXITSTATUS 134
[2022-11-26T22:53:30.556] _job_complete: JobId=53185 done
[2022-11-26T23:03:29.006] _slurm_rpc_submit_batch_job: JobId=53186 InitPrio=400 usec=548
[2022-11-26T23:03:29.378] sched: Allocate JobId=53186 NodeList=cpu14 #CPUs=24 Partition=cpu-epyc
[2022-11-26T23:05:06.298] _slurm_rpc_submit_batch_job: JobId=53187 InitPrio=400 usec=413
[2022-11-26T23:05:06.492] sched: Allocate JobId=53187 NodeList=cpu12 #CPUs=24 Partition=cpu-epyc
[2022-11-26T23:08:03.826] _slurm_rpc_submit_batch_job: JobId=53188 InitPrio=400 usec=508
[2022-11-26T23:42:35.712] _job_complete: JobId=52853 WEXITSTATUS 1
[2022-11-26T23:42:35.712] _job_complete: JobId=52853 done
[2022-11-26T23:42:42.572] _job_complete: JobId=52852 WEXITSTATUS 1
[2022-11-26T23:42:42.572] _job_complete: JobId=52852 done
[2022-11-27T03:22:18.910] _job_complete: JobId=52772 WEXITSTATUS 0
[2022-11-27T03:22:18.910] _job_complete: JobId=52772 done
