[2022-10-01T00:39:18.383] _slurm_rpc_submit_batch_job: JobId=49996 InitPrio=49333 usec=598
[2022-10-01T00:39:19.207] sched: Allocate JobId=49996 NodeList=cpu15 #CPUs=48 Partition=cpu-epyc
[2022-10-01T03:03:50.295] _slurm_rpc_submit_batch_job: JobId=49997 InitPrio=1111 usec=561
[2022-10-01T03:03:50.359] sched: Allocate JobId=49997 NodeList=cpu03 #CPUs=64 Partition=cpu-opteron
[2022-10-01T03:04:13.636] _job_complete: JobId=49997 WEXITSTATUS 1
[2022-10-01T03:04:13.636] _job_complete: JobId=49997 done
[2022-10-01T03:04:15.915] _slurm_rpc_kill_job: REQUEST_KILL_JOB JobId=49997 uid 548300621
[2022-10-01T03:04:16.763] _slurm_rpc_kill_job: REQUEST_KILL_JOB JobId=49997 uid 548300621
[2022-10-01T03:14:26.226] _slurm_rpc_submit_batch_job: JobId=49998 InitPrio=1111 usec=549
[2022-10-01T03:14:26.444] sched: Allocate JobId=49998 NodeList=cpu03 #CPUs=64 Partition=cpu-opteron
[2022-10-01T03:14:41.607] _slurm_rpc_submit_batch_job: JobId=49999 InitPrio=1111 usec=485
[2022-10-01T03:14:42.461] sched: Allocate JobId=49999 NodeList=cpu07 #CPUs=64 Partition=cpu-opteron
[2022-10-01T03:15:31.226] _slurm_rpc_kill_job: REQUEST_KILL_JOB JobId=49999 uid 548300621
[2022-10-01T03:15:35.447] _slurm_rpc_kill_job: REQUEST_KILL_JOB JobId=49998 uid 548300621
[2022-10-01T03:18:01.859] _slurm_rpc_submit_batch_job: JobId=50000 InitPrio=1111 usec=710
[2022-10-01T03:18:02.040] sched: Allocate JobId=50000 NodeList=cpu03 #CPUs=64 Partition=cpu-opteron
[2022-10-01T03:18:06.484] _slurm_rpc_submit_batch_job: JobId=50001 InitPrio=1111 usec=439
[2022-10-01T03:18:06.707] sched/backfill: _start_job: Started JobId=50001 in cpu-opteron on cpu07
[2022-10-01T03:19:34.665] _job_complete: JobId=50000 WEXITSTATUS 1
[2022-10-01T03:19:34.665] _job_complete: JobId=50000 done
[2022-10-01T03:20:04.255] _job_complete: JobId=50001 WEXITSTATUS 1
[2022-10-01T03:20:04.255] _job_complete: JobId=50001 done
[2022-10-01T03:24:43.692] _slurm_rpc_submit_batch_job: JobId=50002 InitPrio=1111 usec=592
[2022-10-01T03:24:44.647] sched: Allocate JobId=50002 NodeList=cpu03 #CPUs=64 Partition=cpu-opteron
[2022-10-01T03:24:45.785] _slurm_rpc_submit_batch_job: JobId=50003 InitPrio=1111 usec=454
[2022-10-01T03:24:47.646] sched: Allocate JobId=50003 NodeList=cpu07 #CPUs=64 Partition=cpu-opteron
[2022-10-01T03:26:18.655] _job_complete: JobId=50002 WEXITSTATUS 1
[2022-10-01T03:26:18.656] _job_complete: JobId=50002 done
[2022-10-01T03:26:46.727] _job_complete: JobId=50003 WEXITSTATUS 1
[2022-10-01T03:26:46.727] _job_complete: JobId=50003 done
[2022-10-01T03:30:02.170] _slurm_rpc_submit_batch_job: JobId=50004 InitPrio=1111 usec=485
[2022-10-01T03:30:03.145] sched: Allocate JobId=50004 NodeList=cpu03 #CPUs=64 Partition=cpu-opteron
[2022-10-01T03:30:04.115] _slurm_rpc_submit_batch_job: JobId=50005 InitPrio=1111 usec=655
[2022-10-01T03:30:06.148] sched: Allocate JobId=50005 NodeList=cpu07 #CPUs=64 Partition=cpu-opteron
[2022-10-01T05:26:21.921] _job_complete: JobId=50005 WEXITSTATUS 0
[2022-10-01T05:26:21.922] _job_complete: JobId=50005 done
[2022-10-01T06:08:22.090] _job_complete: JobId=49933 WEXITSTATUS 0
[2022-10-01T06:08:22.096] _job_complete: JobId=49933 done
[2022-10-01T06:08:23.127] sched: Allocate JobId=49929 NodeList=gpu05 #CPUs=16 Partition=gpu-v100s
[2022-10-01T06:55:55.344] _job_complete: JobId=50004 WEXITSTATUS 0
[2022-10-01T06:55:55.344] _job_complete: JobId=50004 done
[2022-10-01T06:56:50.392] _job_complete: JobId=49994 WEXITSTATUS 0
[2022-10-01T06:56:50.392] _job_complete: JobId=49994 done
[2022-10-01T06:56:50.963] sched: Allocate JobId=49995 NodeList=gpu02 #CPUs=8 Partition=gpu-titan
[2022-10-01T07:13:22.524] _job_complete: JobId=49924 WEXITSTATUS 0
[2022-10-01T07:13:22.529] _job_complete: JobId=49924 done
[2022-10-01T07:43:19.168] _job_complete: JobId=49993 WEXITSTATUS 0
[2022-10-01T07:43:19.169] _job_complete: JobId=49993 done
[2022-10-01T07:45:44.975] _job_complete: JobId=49995 WEXITSTATUS 1
[2022-10-01T07:45:44.975] _job_complete: JobId=49995 done
[2022-10-01T08:00:57.559] _job_complete: JobId=49996 WEXITSTATUS 0
[2022-10-01T08:00:57.559] _job_complete: JobId=49996 done
[2022-10-01T08:11:28.034] Time limit exhausted for JobId=49959
[2022-10-01T08:12:52.796] _slurm_rpc_submit_batch_job: JobId=50006 InitPrio=3111 usec=584
[2022-10-01T08:12:53.166] sched: Allocate JobId=50006 NodeList=cpu11 #CPUs=4 Partition=cpu-opteron
[2022-10-01T08:12:58.157] Time limit exhausted for JobId=49960
[2022-10-01T08:13:21.544] _slurm_rpc_submit_batch_job: JobId=50007 InitPrio=3111 usec=434
[2022-10-01T08:13:22.189] sched: Allocate JobId=50007 NodeList=cpu11 #CPUs=4 Partition=cpu-opteron
[2022-10-01T08:13:28.197] Time limit exhausted for JobId=49961
[2022-10-01T08:13:34.682] _slurm_rpc_kill_job: REQUEST_KILL_JOB JobId=50007 uid 548200110
[2022-10-01T08:15:53.740] _slurm_rpc_kill_job: REQUEST_KILL_JOB JobId=50006 uid 548200110
[2022-10-01T08:16:36.906] _slurm_rpc_submit_batch_job: JobId=50008 InitPrio=3111 usec=659
[2022-10-01T08:16:37.580] sched: Allocate JobId=50008 NodeList=cpu11 #CPUs=4 Partition=cpu-opteron
[2022-10-01T08:17:27.427] _slurm_rpc_submit_batch_job: JobId=50009 InitPrio=3111 usec=464
[2022-10-01T08:17:27.653] sched: Allocate JobId=50009 NodeList=cpu11 #CPUs=4 Partition=cpu-opteron
[2022-10-01T08:18:59.152] _slurm_rpc_submit_batch_job: JobId=50010 InitPrio=3111 usec=529
[2022-10-01T08:18:59.780] sched: Allocate JobId=50010 NodeList=cpu11 #CPUs=8 Partition=cpu-opteron
[2022-10-01T13:18:29.633] _job_complete: JobId=49822 WEXITSTATUS 0
[2022-10-01T13:18:29.633] _job_complete: JobId=49822 done
[2022-10-01T13:18:31.086] sched: Allocate JobId=49966 NodeList=gpu01 #CPUs=16 Partition=gpu-k10
[2022-10-01T14:16:20.060] _job_complete: JobId=49819 WEXITSTATUS 0
[2022-10-01T14:16:20.060] _job_complete: JobId=49819 done
[2022-10-01T14:21:04.382] sched: _slurm_rpc_allocate_resources JobId=50011 NodeList=(null) usec=789
[2022-10-01T14:22:26.960] _job_complete: JobId=50011 WTERMSIG 126
[2022-10-01T14:22:26.960] _job_complete: JobId=50011 cancelled by interactive user
[2022-10-01T14:22:26.960] _job_complete: JobId=50011 done
[2022-10-01T14:22:59.299] _pick_best_nodes: JobId=50012 never runnable in partition cpu-opteron
[2022-10-01T14:22:59.299] _slurm_rpc_allocate_resources: Requested node configuration is not available 
[2022-10-01T14:23:26.172] sched: _slurm_rpc_allocate_resources JobId=50013 NodeList=(null) usec=813
[2022-10-01T14:23:27.091] sched: Allocate JobId=50013 NodeList=gpu02 #CPUs=4 Partition=gpu-titan
[2022-10-01T14:35:29.331] _job_complete: JobId=50013 WEXITSTATUS 130
[2022-10-01T14:35:29.331] _job_complete: JobId=50013 done
[2022-10-01T14:40:04.231] _slurm_rpc_submit_batch_job: JobId=50014 InitPrio=2888 usec=454
[2022-10-01T14:59:00.073] _job_complete: JobId=49929 WEXITSTATUS 0
[2022-10-01T14:59:00.074] _job_complete: JobId=49929 done
[2022-10-01T14:59:00.536] sched: Allocate JobId=50014 NodeList=gpu05 #CPUs=8 Partition=gpu-v100s
[2022-10-01T15:06:23.773] _job_complete: JobId=50014 WEXITSTATUS 1
[2022-10-01T15:06:23.774] _job_complete: JobId=50014 done
[2022-10-01T15:06:24.830] sched: Allocate JobId=49965 NodeList=gpu05 #CPUs=16 Partition=gpu-v100s
[2022-10-01T15:16:52.802] _slurm_rpc_submit_batch_job: JobId=50015 InitPrio=2888 usec=555
[2022-10-01T15:20:03.628] _slurm_rpc_submit_batch_job: JobId=50016 InitPrio=1111 usec=500
[2022-10-01T15:20:04.084] sched: Allocate JobId=50016 NodeList=cpu03 #CPUs=64 Partition=cpu-opteron
[2022-10-01T15:41:45.701] _job_complete: JobId=50016 WEXITSTATUS 0
[2022-10-01T15:41:45.702] _job_complete: JobId=50016 done
[2022-10-01T15:44:18.202] _job_complete: JobId=49721 WEXITSTATUS 0
[2022-10-01T15:44:18.202] _job_complete: JobId=49721 done
[2022-10-01T15:44:18.836] sched: Allocate JobId=49726 NodeList=cpu13 #CPUs=16 Partition=cpu-epyc
[2022-10-01T16:02:34.974] _job_complete: JobId=49965 WEXITSTATUS 0
[2022-10-01T16:02:34.974] _job_complete: JobId=49965 done
[2022-10-01T16:02:35.405] sched: Allocate JobId=50015 NodeList=gpu05 #CPUs=12 Partition=gpu-v100s
[2022-10-01T16:10:03.479] _job_complete: JobId=50015 WEXITSTATUS 1
[2022-10-01T16:10:03.480] _job_complete: JobId=50015 done
[2022-10-01T16:34:11.706] _slurm_rpc_submit_batch_job: JobId=50017 InitPrio=2888 usec=533
[2022-10-01T16:34:12.200] sched: Allocate JobId=50017 NodeList=gpu05 #CPUs=12 Partition=gpu-v100s
[2022-10-01T21:02:18.601] _slurm_rpc_submit_batch_job: JobId=50018 InitPrio=666 usec=508
[2022-10-01T21:02:20.983] sched: Allocate JobId=50018 NodeList=cpu01 #CPUs=32 Partition=cpu-opteron
[2022-10-01T21:02:30.218] _job_complete: JobId=50018 WEXITSTATUS 0
[2022-10-01T21:02:30.218] _job_complete: JobId=50018 done
[2022-10-01T21:23:28.755] _slurm_rpc_submit_batch_job: JobId=50019 InitPrio=444 usec=458
[2022-10-01T21:23:29.161] sched: Allocate JobId=50019 NodeList=gpu02 #CPUs=8 Partition=gpu-titan
[2022-10-01T21:23:32.755] _job_complete: JobId=50019 WEXITSTATUS 1
[2022-10-01T21:23:32.755] _job_complete: JobId=50019 done
[2022-10-01T21:24:03.573] _slurm_rpc_submit_batch_job: JobId=50020 InitPrio=444 usec=480
[2022-10-01T21:24:04.191] sched: Allocate JobId=50020 NodeList=gpu02 #CPUs=8 Partition=gpu-titan
[2022-10-01T21:27:43.866] _slurm_rpc_submit_batch_job: JobId=50021 InitPrio=666 usec=399
[2022-10-01T21:27:44.582] sched: Allocate JobId=50021 NodeList=cpu01 #CPUs=32 Partition=cpu-opteron
[2022-10-01T21:27:45.733] _job_complete: JobId=50021 WEXITSTATUS 1
[2022-10-01T21:27:45.733] _job_complete: JobId=50021 done
[2022-10-01T21:29:40.458] _slurm_rpc_submit_batch_job: JobId=50022 InitPrio=666 usec=649
[2022-10-01T21:29:40.739] sched: Allocate JobId=50022 NodeList=cpu01 #CPUs=32 Partition=cpu-opteron
[2022-10-01T21:29:41.725] _job_complete: JobId=50022 WEXITSTATUS 0
[2022-10-01T21:29:41.725] _job_complete: JobId=50022 done
[2022-10-01T21:37:29.400] _slurm_rpc_submit_batch_job: JobId=50023 InitPrio=666 usec=404
[2022-10-01T21:37:29.586] sched: Allocate JobId=50023 NodeList=cpu01 #CPUs=32 Partition=cpu-opteron
[2022-10-01T21:37:30.673] _job_complete: JobId=50023 WEXITSTATUS 0
[2022-10-01T21:37:30.673] _job_complete: JobId=50023 done
[2022-10-01T21:41:35.312] _slurm_rpc_submit_batch_job: JobId=50024 InitPrio=666 usec=482
[2022-10-01T21:41:36.151] sched: Allocate JobId=50024 NodeList=cpu01 #CPUs=32 Partition=cpu-opteron
[2022-10-01T21:41:40.878] _job_complete: JobId=50024 WEXITSTATUS 1
[2022-10-01T21:41:40.878] _job_complete: JobId=50024 done
[2022-10-01T21:44:00.473] _slurm_rpc_submit_batch_job: JobId=50025 InitPrio=666 usec=524
[2022-10-01T21:44:01.351] sched: Allocate JobId=50025 NodeList=cpu01 #CPUs=32 Partition=cpu-opteron
[2022-10-01T21:44:03.407] _job_complete: JobId=50025 WEXITSTATUS 1
[2022-10-01T21:44:03.407] _job_complete: JobId=50025 done
[2022-10-01T21:47:26.144] _slurm_rpc_submit_batch_job: JobId=50026 InitPrio=666 usec=499
[2022-10-01T21:47:26.749] sched: Allocate JobId=50026 NodeList=cpu01 #CPUs=32 Partition=cpu-opteron
[2022-10-01T21:55:02.216] _slurm_rpc_submit_batch_job: JobId=50027 InitPrio=666 usec=502
[2022-10-01T21:55:02.469] sched: Allocate JobId=50027 NodeList=cpu03 #CPUs=32 Partition=cpu-opteron
[2022-10-01T21:55:18.834] _slurm_rpc_kill_job: REQUEST_KILL_JOB JobId=50026 uid 548200023
[2022-10-01T21:56:04.447] _slurm_rpc_kill_job: REQUEST_KILL_JOB JobId=50027 uid 548200023
[2022-10-01T21:56:28.108] _slurm_rpc_submit_batch_job: JobId=50028 InitPrio=666 usec=489
[2022-10-01T21:56:28.696] sched: Allocate JobId=50028 NodeList=cpu01 #CPUs=32 Partition=cpu-opteron
[2022-10-01T22:37:03.124] _job_complete: JobId=50020 WEXITSTATUS 0
[2022-10-01T22:37:03.124] _job_complete: JobId=50020 done
[2022-10-01T23:13:52.867] _job_complete: JobId=49756 WEXITSTATUS 0
[2022-10-01T23:13:52.867] _job_complete: JobId=49756 done
[2022-10-01T23:34:33.221] _slurm_rpc_submit_batch_job: JobId=50029 InitPrio=666 usec=628
[2022-10-01T23:34:33.926] sched: Allocate JobId=50029 NodeList=cpu03 #CPUs=32 Partition=cpu-opteron
[2022-10-01T23:34:35.241] _job_complete: JobId=50029 WEXITSTATUS 1
[2022-10-01T23:34:35.241] _job_complete: JobId=50029 done
[2022-10-01T23:39:37.289] _slurm_rpc_submit_batch_job: JobId=50030 InitPrio=666 usec=432
[2022-10-01T23:39:37.550] sched: Allocate JobId=50030 NodeList=cpu03 #CPUs=32 Partition=cpu-opteron
[2022-10-01T23:39:45.910] _job_complete: JobId=50030 WEXITSTATUS 1
[2022-10-01T23:39:45.910] _job_complete: JobId=50030 done
[2022-10-01T23:40:25.534] _slurm_rpc_submit_batch_job: JobId=50031 InitPrio=666 usec=410
[2022-10-01T23:40:25.615] sched: Allocate JobId=50031 NodeList=cpu03 #CPUs=32 Partition=cpu-opteron
[2022-10-01T23:42:14.370] _job_complete: JobId=50031 WEXITSTATUS 1
[2022-10-01T23:42:14.371] _job_complete: JobId=50031 done
[2022-10-01T23:53:23.915] _slurm_rpc_submit_batch_job: JobId=50032 InitPrio=666 usec=502
[2022-10-01T23:53:23.991] sched: Allocate JobId=50032 NodeList=cpu03 #CPUs=32 Partition=cpu-opteron
[2022-10-02T00:09:09.144] _slurm_rpc_submit_batch_job: JobId=50033 InitPrio=444 usec=630
[2022-10-02T00:09:09.245] sched: Allocate JobId=50033 NodeList=gpu02 #CPUs=8 Partition=gpu-titan
[2022-10-02T00:09:15.598] _job_complete: JobId=50033 WEXITSTATUS 1
[2022-10-02T00:09:15.598] _job_complete: JobId=50033 done
[2022-10-02T00:13:38.801] _job_complete: JobId=50032 WEXITSTATUS 1
[2022-10-02T00:13:38.802] _job_complete: JobId=50032 done
[2022-10-02T01:10:56.711] _slurm_rpc_submit_batch_job: JobId=50034 InitPrio=444 usec=519
[2022-10-02T01:10:57.078] sched: Allocate JobId=50034 NodeList=gpu02 #CPUs=8 Partition=gpu-titan
[2022-10-02T01:15:59.101] _slurm_rpc_kill_job: REQUEST_KILL_JOB JobId=49966 uid 548200029
[2022-10-02T01:16:03.932] sched: Allocate JobId=49969 NodeList=gpu01 #CPUs=16 Partition=gpu-k10
[2022-10-02T02:05:52.499] _job_complete: JobId=49725 WEXITSTATUS 0
[2022-10-02T02:05:52.499] _job_complete: JobId=49725 done
[2022-10-02T02:05:53.109] sched: Allocate JobId=49727 NodeList=cpu14 #CPUs=16 Partition=cpu-epyc
[2022-10-02T02:30:50.245] _job_complete: JobId=50034 WEXITSTATUS 0
[2022-10-02T02:30:50.245] _job_complete: JobId=50034 done
[2022-10-02T04:40:17.729] _job_complete: JobId=50008 WEXITSTATUS 1
[2022-10-02T04:40:17.729] _job_complete: JobId=50008 done
[2022-10-02T05:17:31.750] _job_complete: JobId=50028 OOM failure
[2022-10-02T05:17:31.750] _job_complete: JobId=50028 done
[2022-10-02T08:17:31.547] Time limit exhausted for JobId=50009
[2022-10-02T08:19:01.672] Time limit exhausted for JobId=50010
[2022-10-02T08:19:18.668] _slurm_rpc_submit_batch_job: JobId=50035 InitPrio=3111 usec=537
[2022-10-02T08:19:18.712] sched: Allocate JobId=50035 NodeList=cpu01 #CPUs=4 Partition=cpu-opteron
[2022-10-02T08:20:24.577] _slurm_rpc_submit_batch_job: JobId=50036 InitPrio=3111 usec=486
[2022-10-02T08:20:24.784] sched: Allocate JobId=50036 NodeList=cpu01 #CPUs=8 Partition=cpu-opteron
[2022-10-02T09:20:44.425] _get_job_parts: invalid partition specified: titanx
[2022-10-02T09:20:44.426] _slurm_rpc_submit_batch_job: Invalid partition name specified
[2022-10-02T09:21:43.197] _get_job_parts: invalid partition specified: gpu-titanx
[2022-10-02T09:21:43.198] _slurm_rpc_submit_batch_job: Invalid partition name specified
[2022-10-02T09:22:10.196] _pick_best_nodes: JobId=50037 never runnable in partition gpu-titan
[2022-10-02T09:22:10.202] _slurm_rpc_submit_batch_job: Requested node configuration is not available
[2022-10-02T09:22:38.338] _slurm_rpc_submit_batch_job: JobId=50038 InitPrio=2444 usec=482
[2022-10-02T09:22:38.570] sched: Allocate JobId=50038 NodeList=gpu02 #CPUs=8 Partition=gpu-titan
[2022-10-02T09:23:14.344] _job_complete: JobId=50038 WEXITSTATUS 1
[2022-10-02T09:23:14.344] _job_complete: JobId=50038 done
[2022-10-02T09:24:09.030] _slurm_rpc_submit_batch_job: JobId=50039 InitPrio=2444 usec=409
[2022-10-02T09:24:09.670] sched: Allocate JobId=50039 NodeList=gpu02 #CPUs=8 Partition=gpu-titan
[2022-10-02T09:34:57.945] _job_complete: JobId=50039 WEXITSTATUS 0
[2022-10-02T09:34:57.945] _job_complete: JobId=50039 done
[2022-10-02T09:36:37.675] _slurm_rpc_submit_batch_job: JobId=50040 InitPrio=2444 usec=478
[2022-10-02T09:36:38.100] sched: Allocate JobId=50040 NodeList=gpu02 #CPUs=8 Partition=gpu-titan
[2022-10-02T09:37:11.270] _job_complete: JobId=50040 WEXITSTATUS 1
[2022-10-02T09:37:11.271] _job_complete: JobId=50040 done
[2022-10-02T09:40:01.502] _slurm_rpc_submit_batch_job: JobId=50041 InitPrio=2444 usec=454
[2022-10-02T09:40:02.384] sched: Allocate JobId=50041 NodeList=gpu02 #CPUs=8 Partition=gpu-titan
[2022-10-02T09:40:44.559] _job_complete: JobId=50041 WEXITSTATUS 1
[2022-10-02T09:40:44.560] _job_complete: JobId=50041 done
[2022-10-02T10:30:20.534] _slurm_rpc_kill_job: REQUEST_KILL_JOB JobId=49825 uid 548300534
[2022-10-02T11:15:35.986] _job_complete: JobId=50017 WEXITSTATUS 0
[2022-10-02T11:15:35.991] _job_complete: JobId=50017 done
[2022-10-02T11:28:23.134] _slurm_rpc_submit_batch_job: JobId=50042 InitPrio=444 usec=563
[2022-10-02T11:28:23.795] sched: Allocate JobId=50042 NodeList=gpu02 #CPUs=8 Partition=gpu-titan
[2022-10-02T11:34:29.813] _slurm_rpc_submit_batch_job: JobId=50043 InitPrio=444 usec=578
[2022-10-02T11:34:54.500] _slurm_rpc_kill_job: REQUEST_KILL_JOB JobId=50042 uid 548200021
[2022-10-02T11:34:56.594] sched: Allocate JobId=50043 NodeList=gpu02 #CPUs=8 Partition=gpu-titan
[2022-10-02T12:15:10.686] _slurm_rpc_submit_batch_job: JobId=50044 InitPrio=2444 usec=628
[2022-10-02T12:15:11.529] sched: Allocate JobId=50044 NodeList=gpu02 #CPUs=8 Partition=gpu-titan
[2022-10-02T12:15:25.479] _slurm_rpc_submit_batch_job: JobId=50045 InitPrio=2444 usec=525
[2022-10-02T12:15:43.018] _slurm_rpc_kill_job: REQUEST_KILL_JOB JobId=50045 uid 548300564
[2022-10-02T12:21:41.920] _slurm_rpc_kill_job: REQUEST_KILL_JOB JobId=50044 uid 548300564
[2022-10-02T12:22:26.387] _slurm_rpc_submit_batch_job: JobId=50046 InitPrio=2444 usec=409
[2022-10-02T12:22:27.337] sched: Allocate JobId=50046 NodeList=gpu02 #CPUs=8 Partition=gpu-titan
[2022-10-02T12:24:31.591] _job_complete: JobId=50043 WEXITSTATUS 0
[2022-10-02T12:24:31.591] _job_complete: JobId=50043 done
[2022-10-02T12:35:29.144] _slurm_rpc_submit_batch_job: JobId=50047 InitPrio=888 usec=423
[2022-10-02T12:35:29.615] sched: Allocate JobId=50047 NodeList=cpu03 #CPUs=64 Partition=cpu-opteron
[2022-10-02T12:36:26.899] _job_complete: JobId=50046 WEXITSTATUS 0
[2022-10-02T12:36:26.899] _job_complete: JobId=50046 done
[2022-10-02T12:42:27.599] _slurm_rpc_kill_job: REQUEST_KILL_JOB JobId=49991 uid 548200023
[2022-10-02T12:45:33.066] _slurm_rpc_submit_batch_job: JobId=50048 InitPrio=2444 usec=472
[2022-10-02T12:45:33.652] sched: Allocate JobId=50048 NodeList=gpu02 #CPUs=8 Partition=gpu-titan
[2022-10-02T12:59:11.624] _job_complete: JobId=50048 WEXITSTATUS 0
[2022-10-02T12:59:11.625] _job_complete: JobId=50048 done
[2022-10-02T13:01:39.688] _slurm_rpc_submit_batch_job: JobId=50049 InitPrio=444 usec=589
[2022-10-02T13:01:40.418] sched: Allocate JobId=50049 NodeList=gpu05 #CPUs=16 Partition=gpu-v100s
[2022-10-02T13:03:54.048] _slurm_rpc_submit_batch_job: JobId=50050 InitPrio=444 usec=431
[2022-10-02T13:09:45.875] _slurm_rpc_submit_batch_job: JobId=50051 InitPrio=2444 usec=464
[2022-10-02T13:16:53.977] _slurm_rpc_submit_batch_job: JobId=50052 InitPrio=444 usec=414
[2022-10-02T13:16:54.048] sched: Allocate JobId=50052 NodeList=gpu02 #CPUs=16 Partition=gpu-titan
[2022-10-02T13:27:43.290] _slurm_rpc_kill_job: REQUEST_KILL_JOB JobId=49850 uid 548200021
[2022-10-02T13:27:45.299] sched: Allocate JobId=50051 NodeList=gpu05 #CPUs=8 Partition=gpu-v100s
[2022-10-02T13:37:27.106] _slurm_rpc_submit_batch_job: JobId=50053 InitPrio=444 usec=456
[2022-10-02T13:43:19.353] _job_complete: JobId=50047 WEXITSTATUS 1
[2022-10-02T13:43:19.353] _job_complete: JobId=50047 done
[2022-10-02T14:32:45.440] _slurm_rpc_submit_batch_job: JobId=50054 InitPrio=49361 usec=560
[2022-10-02T14:32:46.386] sched: Allocate JobId=50054 NodeList=cpu15 #CPUs=48 Partition=cpu-epyc
[2022-10-02T17:14:08.169] _slurm_rpc_submit_batch_job: JobId=50055 InitPrio=851 usec=530
[2022-10-02T17:14:08.518] sched/backfill: _start_job: Started JobId=50055 in cpu-opteron on cpu03
[2022-10-02T17:28:47.251] _slurm_rpc_submit_batch_job: JobId=50056 InitPrio=851 usec=536
[2022-10-02T17:28:48.236] sched: Allocate JobId=50056 NodeList=cpu11 #CPUs=32 Partition=cpu-opteron
[2022-10-02T17:31:48.519] _job_complete: JobId=50056 WEXITSTATUS 1
[2022-10-02T17:31:48.520] _job_complete: JobId=50056 done
[2022-10-02T17:34:31.224] _slurm_rpc_submit_batch_job: JobId=50057 InitPrio=851 usec=484
[2022-10-02T17:34:31.834] sched: Allocate JobId=50057 NodeList=cpu11 #CPUs=32 Partition=cpu-opteron
[2022-10-02T17:35:54.227] _job_complete: JobId=50057 WEXITSTATUS 0
[2022-10-02T17:35:54.227] _job_complete: JobId=50057 done
[2022-10-02T17:38:48.880] _slurm_rpc_kill_job: REQUEST_KILL_JOB JobId=50055 uid 548200023
[2022-10-02T17:39:34.448] _slurm_rpc_submit_batch_job: JobId=50058 InitPrio=851 usec=446
[2022-10-02T17:39:35.350] sched: Allocate JobId=50058 NodeList=cpu03 #CPUs=64 Partition=cpu-opteron
[2022-10-02T17:39:55.986] _job_complete: JobId=50058 WEXITSTATUS 1
[2022-10-02T17:39:55.987] _job_complete: JobId=50058 done
[2022-10-02T17:40:09.876] _slurm_rpc_submit_batch_job: JobId=50059 InitPrio=851 usec=413
[2022-10-02T17:40:10.392] sched: Allocate JobId=50059 NodeList=cpu11 #CPUs=32 Partition=cpu-opteron
[2022-10-02T17:40:41.215] _slurm_rpc_submit_batch_job: JobId=50060 InitPrio=851 usec=492
[2022-10-02T17:40:41.436] sched: Allocate JobId=50060 NodeList=cpu03 #CPUs=64 Partition=cpu-opteron
[2022-10-02T17:41:01.268] _job_complete: JobId=50060 WEXITSTATUS 1
[2022-10-02T17:41:01.268] _job_complete: JobId=50060 done
[2022-10-02T17:41:35.047] _job_complete: JobId=50059 WEXITSTATUS 0
[2022-10-02T17:41:35.047] _job_complete: JobId=50059 done
[2022-10-02T17:42:12.068] _slurm_rpc_submit_batch_job: JobId=50061 InitPrio=851 usec=500
[2022-10-02T17:42:12.665] sched: Allocate JobId=50061 NodeList=cpu03 #CPUs=64 Partition=cpu-opteron
[2022-10-02T18:02:11.150] _job_complete: JobId=50061 WEXITSTATUS 0
[2022-10-02T18:02:11.150] _job_complete: JobId=50061 done
[2022-10-02T21:01:27.882] _job_complete: JobId=49724 WEXITSTATUS 0
[2022-10-02T21:01:27.882] _job_complete: JobId=49724 done
[2022-10-02T21:01:28.827] sched: Allocate JobId=49728 NodeList=cpu12 #CPUs=16 Partition=cpu-epyc
[2022-10-03T00:09:19.243] _slurm_rpc_submit_batch_job: JobId=50062 InitPrio=851 usec=693
[2022-10-03T00:09:22.027] sched: Allocate JobId=50062 NodeList=cpu01 #CPUs=32 Partition=cpu-opteron
[2022-10-03T00:09:30.370] _job_complete: JobId=50062 WEXITSTATUS 0
[2022-10-03T00:09:30.370] _job_complete: JobId=50062 done
[2022-10-03T00:28:12.390] _slurm_rpc_submit_batch_job: JobId=50063 InitPrio=851 usec=643
[2022-10-03T00:28:13.028] sched: Allocate JobId=50063 NodeList=cpu01 #CPUs=32 Partition=cpu-opteron
[2022-10-03T02:01:23.170] _slurm_rpc_submit_batch_job: JobId=50064 InitPrio=7446 usec=482
[2022-10-03T02:03:12.992] _slurm_rpc_kill_job: REQUEST_KILL_JOB JobId=50064 uid 548300544
[2022-10-03T02:03:54.391] _slurm_rpc_submit_batch_job: JobId=50065 InitPrio=17446 usec=469
[2022-10-03T04:32:14.475] _job_complete: JobId=50036 WEXITSTATUS 1
[2022-10-03T04:32:14.475] _job_complete: JobId=50036 done
[2022-10-03T06:19:09.579] _job_complete: JobId=49969 WEXITSTATUS 1
[2022-10-03T06:19:09.584] _job_complete: JobId=49969 done
[2022-10-03T07:44:53.750] _slurm_rpc_kill_job: REQUEST_KILL_JOB JobId=50054 uid 548200003
[2022-10-03T07:45:03.762] error: slurm_receive_msgs: [[cpu15.dicc.um.edu.my]:6818] failed: Socket timed out on send/recv operation
[2022-10-03T07:45:14.317] Node cpu15 now responding
[2022-10-03T07:45:58.371] error: Nodes cpu15 not responding
[2022-10-03T07:47:54.745] cleanup_completing: JobId=50054 completion process took 146 seconds
[2022-10-03T07:47:54.746] error: Nodes cpu15 not responding, setting DOWN
[2022-10-03T07:50:05.407] Node cpu15 now responding
[2022-10-03T07:50:05.407] node cpu15 returned to service
[2022-10-03T07:52:20.515] _job_complete: JobId=50063 OOM failure
[2022-10-03T07:52:20.515] _job_complete: JobId=50063 done
[2022-10-03T08:14:56.014] sched: _slurm_rpc_allocate_resources JobId=50066 NodeList=(null) usec=1280
[2022-10-03T08:15:41.051] _job_complete: JobId=50066 WTERMSIG 126
[2022-10-03T08:15:41.051] _job_complete: JobId=50066 cancelled by interactive user
[2022-10-03T08:15:41.051] _job_complete: JobId=50066 done
[2022-10-03T08:16:02.899] sched: _slurm_rpc_allocate_resources JobId=50067 NodeList=(null) usec=804
[2022-10-03T08:16:03.065] sched: Allocate JobId=50067 NodeList=gpu01 #CPUs=8 Partition=gpu-k10
[2022-10-03T08:18:34.145] _job_complete: JobId=50067 WEXITSTATUS 0
[2022-10-03T08:18:34.145] _job_complete: JobId=50067 done
[2022-10-03T08:19:37.335] Time limit exhausted for JobId=50035
[2022-10-03T09:12:25.370] _slurm_rpc_submit_batch_job: JobId=50068 InitPrio=2978 usec=507
[2022-10-03T09:12:26.203] sched: Allocate JobId=50068 NodeList=cpu11 #CPUs=4 Partition=cpu-opteron
[2022-10-03T09:54:33.129] _slurm_rpc_submit_batch_job: JobId=50069 InitPrio=851 usec=481
[2022-10-03T09:54:33.890] sched: Allocate JobId=50069 NodeList=cpu01 #CPUs=64 Partition=cpu-opteron
[2022-10-03T09:59:03.624] sched: _slurm_rpc_allocate_resources JobId=50070 NodeList=(null) usec=914
[2022-10-03T09:59:04.486] sched: Allocate JobId=50070 NodeList=gpu01 #CPUs=4 Partition=gpu-k10
[2022-10-03T10:03:28.622] _job_complete: JobId=50070 WEXITSTATUS 1
[2022-10-03T10:03:28.622] _job_complete: JobId=50070 done
[2022-10-03T11:35:19.967] _slurm_rpc_kill_job: REQUEST_KILL_JOB JobId=50051 uid 548300564
[2022-10-03T11:35:40.954] _slurm_rpc_submit_batch_job: JobId=50071 InitPrio=2127 usec=559
[2022-10-03T11:35:41.646] sched: Allocate JobId=50071 NodeList=gpu05 #CPUs=8 Partition=gpu-v100s
[2022-10-03T12:08:06.272] _slurm_rpc_submit_batch_job: JobId=50072 InitPrio=851 usec=495
[2022-10-03T12:08:07.077] sched: Allocate JobId=50072 NodeList=cpu11 #CPUs=4 Partition=cpu-opteron
[2022-10-03T12:08:08.310] _job_complete: JobId=50072 WEXITSTATUS 0
[2022-10-03T12:08:08.310] _job_complete: JobId=50072 done
[2022-10-03T12:28:21.119] _job_complete: JobId=49834 WEXITSTATUS 1
[2022-10-03T12:28:21.124] _job_complete: JobId=49834 done
[2022-10-03T14:02:57.631] _job_complete: JobId=50069 WEXITSTATUS 1
[2022-10-03T14:02:57.631] _job_complete: JobId=50069 done
[2022-10-03T15:27:48.885] sched: _slurm_rpc_allocate_resources JobId=50073 NodeList=(null) usec=888
[2022-10-03T15:28:05.707] _job_complete: JobId=50073 WTERMSIG 126
[2022-10-03T15:28:05.707] _job_complete: JobId=50073 cancelled by interactive user
[2022-10-03T15:28:05.707] _job_complete: JobId=50073 done
[2022-10-03T15:28:13.014] sched: _slurm_rpc_allocate_resources JobId=50074 NodeList=(null) usec=996
[2022-10-03T15:28:25.840] _job_complete: JobId=50074 WTERMSIG 126
[2022-10-03T15:28:25.840] _job_complete: JobId=50074 cancelled by interactive user
[2022-10-03T15:28:25.840] _job_complete: JobId=50074 done
[2022-10-03T15:29:01.772] sched: _slurm_rpc_allocate_resources JobId=50075 NodeList=(null) usec=726
[2022-10-03T15:29:07.372] _job_complete: JobId=50075 WTERMSIG 126
[2022-10-03T15:29:07.372] _job_complete: JobId=50075 cancelled by interactive user
[2022-10-03T15:29:07.372] _job_complete: JobId=50075 done
[2022-10-03T15:29:21.984] sched: _slurm_rpc_allocate_resources JobId=50076 NodeList=(null) usec=803
[2022-10-03T15:29:22.191] sched: Allocate JobId=50076 NodeList=cpu01 #CPUs=32 Partition=cpu-opteron
[2022-10-03T15:47:56.108] _slurm_rpc_submit_batch_job: JobId=50077 InitPrio=851 usec=904
[2022-10-03T15:47:57.131] sched: Allocate JobId=50077 NodeList=cpu03 #CPUs=64 Partition=cpu-opteron
[2022-10-03T15:49:55.436] _slurm_rpc_submit_batch_job: JobId=50078 InitPrio=851 usec=406
[2022-10-03T15:49:56.273] sched: Allocate JobId=50078 NodeList=cpu07 #CPUs=64 Partition=cpu-opteron
[2022-10-03T15:51:21.108] _job_complete: JobId=50078 WEXITSTATUS 0
[2022-10-03T15:51:21.108] _job_complete: JobId=50078 done
[2022-10-03T16:07:41.150] _slurm_rpc_submit_batch_job: JobId=50079 InitPrio=638 usec=497
[2022-10-03T16:07:42.157] sched: Allocate JobId=50079 NodeList=cpu07 #CPUs=64 Partition=cpu-opteron
[2022-10-03T16:08:01.758] _job_complete: JobId=50077 WEXITSTATUS 0
[2022-10-03T16:08:01.758] _job_complete: JobId=50077 done
[2022-10-03T16:10:32.620] _slurm_rpc_submit_batch_job: JobId=50080 InitPrio=851 usec=433
[2022-10-03T16:10:33.379] sched: Allocate JobId=50080 NodeList=cpu11 #CPUs=32 Partition=cpu-opteron
[2022-10-03T16:10:34.710] _job_complete: JobId=50080 WEXITSTATUS 1
[2022-10-03T16:10:34.710] _job_complete: JobId=50080 done
[2022-10-03T16:13:11.268] _slurm_rpc_submit_batch_job: JobId=50081 InitPrio=851 usec=425
[2022-10-03T16:13:11.945] sched: Allocate JobId=50081 NodeList=cpu11 #CPUs=16 Partition=cpu-opteron
[2022-10-03T16:13:13.507] _job_complete: JobId=50081 WEXITSTATUS 1
[2022-10-03T16:13:13.507] _job_complete: JobId=50081 done
[2022-10-03T16:14:38.676] _slurm_rpc_submit_batch_job: JobId=50082 InitPrio=851 usec=399
[2022-10-03T16:14:39.065] sched: Allocate JobId=50082 NodeList=cpu11 #CPUs=8 Partition=cpu-opteron
[2022-10-03T16:14:40.413] _job_complete: JobId=50082 WEXITSTATUS 1
[2022-10-03T16:14:40.413] _job_complete: JobId=50082 done
[2022-10-03T16:14:57.527] _slurm_rpc_submit_batch_job: JobId=50083 InitPrio=851 usec=468
[2022-10-03T16:14:58.091] sched: Allocate JobId=50083 NodeList=cpu11 #CPUs=8 Partition=cpu-opteron
[2022-10-03T16:14:59.113] _job_complete: JobId=50083 WEXITSTATUS 1
[2022-10-03T16:14:59.113] _job_complete: JobId=50083 done
[2022-10-03T16:15:58.524] _slurm_rpc_submit_batch_job: JobId=50084 InitPrio=638 usec=687
[2022-10-03T16:15:59.275] sched: Allocate JobId=50084 NodeList=cpu03 #CPUs=64 Partition=cpu-opteron
[2022-10-03T16:16:14.847] _slurm_rpc_kill_job: REQUEST_KILL_JOB JobId=50084 uid 548200019
[2022-10-03T16:16:26.760] _slurm_rpc_submit_batch_job: JobId=50085 InitPrio=851 usec=442
[2022-10-03T16:16:27.354] sched: Allocate JobId=50085 NodeList=cpu11 #CPUs=32 Partition=cpu-opteron
[2022-10-03T16:16:32.081] _job_complete: JobId=50085 WEXITSTATUS 0
[2022-10-03T16:16:32.081] _job_complete: JobId=50085 done
[2022-10-03T16:16:37.270] _slurm_rpc_kill_job: REQUEST_KILL_JOB JobId=50079 uid 548200019
[2022-10-03T16:16:40.827] _slurm_rpc_submit_batch_job: JobId=50086 InitPrio=638 usec=644
[2022-10-03T16:16:41.373] sched: Allocate JobId=50086 NodeList=cpu03 #CPUs=64 Partition=cpu-opteron
[2022-10-03T16:17:33.787] _slurm_rpc_submit_batch_job: JobId=50087 InitPrio=638 usec=590
[2022-10-03T16:17:34.448] sched: Allocate JobId=50087 NodeList=cpu07 #CPUs=64 Partition=cpu-opteron
[2022-10-03T16:26:50.058] _slurm_rpc_submit_batch_job: JobId=50088 InitPrio=851 usec=575
[2022-10-03T16:26:50.448] sched: Allocate JobId=50088 NodeList=cpu01 #CPUs=8 Partition=cpu-opteron
[2022-10-03T16:28:26.330] _slurm_rpc_submit_batch_job: JobId=50089 InitPrio=851 usec=486
[2022-10-03T16:28:26.575] sched: Allocate JobId=50089 NodeList=cpu11 #CPUs=32 Partition=cpu-opteron
[2022-10-03T16:28:27.548] _job_complete: JobId=50089 WEXITSTATUS 1
[2022-10-03T16:28:27.548] _job_complete: JobId=50089 done
[2022-10-03T16:28:51.904] _slurm_rpc_submit_batch_job: JobId=50090 InitPrio=851 usec=443
[2022-10-03T16:28:52.611] sched: Allocate JobId=50090 NodeList=cpu11 #CPUs=32 Partition=cpu-opteron
[2022-10-03T16:28:57.587] _job_complete: JobId=50090 WEXITSTATUS 0
[2022-10-03T16:28:57.587] _job_complete: JobId=50090 done
[2022-10-03T16:29:38.678] Time limit exhausted for JobId=50076
[2022-10-03T16:30:16.450] _job_complete: JobId=50088 WEXITSTATUS 0
[2022-10-03T16:30:16.450] _job_complete: JobId=50088 done
[2022-10-03T16:30:27.335] _slurm_rpc_submit_batch_job: JobId=50091 InitPrio=851 usec=435
[2022-10-03T16:30:27.747] sched: Allocate JobId=50091 NodeList=cpu11 #CPUs=8 Partition=cpu-opteron
[2022-10-03T16:32:39.470] _slurm_rpc_submit_batch_job: JobId=50092 InitPrio=851 usec=451
[2022-10-03T16:32:40.043] sched: Allocate JobId=50092 NodeList=cpu08 #CPUs=32 Partition=cpu-opteron
[2022-10-03T16:32:44.121] _job_complete: JobId=50092 WEXITSTATUS 0
[2022-10-03T16:32:44.121] _job_complete: JobId=50092 done
[2022-10-03T16:34:13.206] _job_complete: JobId=50091 WEXITSTATUS 0
[2022-10-03T16:34:13.206] _job_complete: JobId=50091 done
[2022-10-03T16:34:44.580] cleanup_completing: JobId=50076 completion process took 306 seconds
[2022-10-03T16:35:26.121] _slurm_rpc_submit_batch_job: JobId=50093 InitPrio=851 usec=464
[2022-10-03T16:35:26.271] sched: Allocate JobId=50093 NodeList=cpu11 #CPUs=8 Partition=cpu-opteron
[2022-10-03T16:39:09.073] _job_complete: JobId=50093 WEXITSTATUS 0
[2022-10-03T16:39:09.073] _job_complete: JobId=50093 done
[2022-10-03T16:44:51.747] sched: _slurm_rpc_allocate_resources JobId=50094 NodeList=(null) usec=979
[2022-10-03T16:44:52.274] sched: Allocate JobId=50094 NodeList=cpu01 #CPUs=64 Partition=cpu-opteron
[2022-10-03T16:44:55.288] _job_complete: JobId=50094 WEXITSTATUS 1
[2022-10-03T16:44:55.288] _job_complete: JobId=50094 done
[2022-10-03T16:45:33.063] sched: _slurm_rpc_allocate_resources JobId=50095 NodeList=(null) usec=819
[2022-10-03T16:45:33.329] sched: Allocate JobId=50095 NodeList=cpu01 #CPUs=64 Partition=cpu-opteron
[2022-10-03T16:47:40.280] _job_complete: JobId=50086 WEXITSTATUS 0
[2022-10-03T16:47:40.280] _job_complete: JobId=50086 done
[2022-10-03T17:02:20.878] _slurm_rpc_submit_batch_job: JobId=50096 InitPrio=638 usec=464
[2022-10-03T17:02:22.206] sched: Allocate JobId=50096 NodeList=cpu03 #CPUs=64 Partition=cpu-opteron
[2022-10-03T17:03:34.068] _slurm_rpc_kill_job: REQUEST_KILL_JOB JobId=50095 uid 548300543
[2022-10-03T17:04:18.312] sched: _slurm_rpc_allocate_resources JobId=50097 NodeList=(null) usec=939
[2022-10-03T17:04:18.365] sched: Allocate JobId=50097 NodeList=cpu01 #CPUs=64 Partition=cpu-opteron
[2022-10-03T17:08:10.488] _job_complete: JobId=50087 WEXITSTATUS 0
[2022-10-03T17:08:10.489] _job_complete: JobId=50087 done
[2022-10-03T17:10:14.251] _slurm_rpc_submit_batch_job: JobId=50098 InitPrio=1914 usec=590
[2022-10-03T17:10:14.970] sched: Allocate JobId=50098 NodeList=gpu01 #CPUs=16 Partition=gpu-k10
[2022-10-03T17:11:32.457] _slurm_rpc_submit_batch_job: JobId=50099 InitPrio=1914 usec=943
[2022-10-03T17:11:33.143] sched: Allocate JobId=50099 NodeList=gpu03 #CPUs=16 Partition=gpu-k10
[2022-10-03T17:12:04.371] _slurm_rpc_kill_job: REQUEST_KILL_JOB JobId=50098 uid 548200029
[2022-10-03T17:13:11.144] _slurm_rpc_submit_batch_job: JobId=50100 InitPrio=1914 usec=939
[2022-10-03T17:13:11.268] sched: Allocate JobId=50100 NodeList=gpu01 #CPUs=16 Partition=gpu-k10
[2022-10-03T17:21:08.605] _slurm_rpc_submit_batch_job: JobId=50101 InitPrio=638 usec=570
[2022-10-03T17:21:09.194] sched: Allocate JobId=50101 NodeList=cpu07 #CPUs=64 Partition=cpu-opteron
[2022-10-03T17:56:47.330] _job_complete: JobId=50096 WEXITSTATUS 0
[2022-10-03T17:56:47.330] _job_complete: JobId=50096 done
[2022-10-03T19:07:58.099] _job_complete: JobId=50101 WEXITSTATUS 0
[2022-10-03T19:07:58.099] _job_complete: JobId=50101 done
[2022-10-03T19:50:06.009] _slurm_rpc_kill_job: REQUEST_KILL_JOB JobId=50097 uid 548300543
[2022-10-03T21:45:05.626] _job_complete: JobId=49757 WEXITSTATUS 0
[2022-10-03T21:45:05.626] _job_complete: JobId=49757 done
[2022-10-03T22:33:37.267] _slurm_rpc_submit_batch_job: JobId=50102 InitPrio=7446 usec=521
[2022-10-03T22:33:37.794] sched: Allocate JobId=50102 NodeList=cpu01 #CPUs=64 Partition=cpu-opteron
[2022-10-03T22:33:57.330] _slurm_rpc_kill_job: REQUEST_KILL_JOB JobId=50065 uid 548300544
[2022-10-03T22:36:30.637] _slurm_rpc_submit_batch_job: JobId=50103 InitPrio=638 usec=460
[2022-10-03T22:36:31.150] sched: Allocate JobId=50103 NodeList=cpu03 #CPUs=64 Partition=cpu-opteron
[2022-10-03T22:37:51.119] _job_complete: JobId=50103 WEXITSTATUS 1
[2022-10-03T22:37:51.119] _job_complete: JobId=50103 done
[2022-10-03T22:39:17.414] _slurm_rpc_submit_batch_job: JobId=50104 InitPrio=638 usec=458
[2022-10-03T22:39:18.370] sched: Allocate JobId=50104 NodeList=cpu03 #CPUs=64 Partition=cpu-opteron
[2022-10-03T22:50:37.160] _job_complete: JobId=50104 WEXITSTATUS 0
[2022-10-03T22:50:37.161] _job_complete: JobId=50104 done
[2022-10-03T23:02:12.830] _slurm_rpc_submit_batch_job: JobId=50105 InitPrio=638 usec=751
[2022-10-03T23:02:12.845] sched: Allocate JobId=50105 NodeList=cpu03 #CPUs=64 Partition=cpu-opteron
[2022-10-03T23:02:45.248] _job_complete: JobId=50105 WEXITSTATUS 0
[2022-10-03T23:02:45.249] _job_complete: JobId=50105 done
[2022-10-03T23:18:14.474] _slurm_rpc_submit_batch_job: JobId=50106 InitPrio=851 usec=475
[2022-10-03T23:18:14.589] sched: Allocate JobId=50106 NodeList=cpu11 #CPUs=32 Partition=cpu-opteron
[2022-10-03T23:18:19.185] _job_complete: JobId=50106 WEXITSTATUS 0
[2022-10-03T23:18:19.185] _job_complete: JobId=50106 done
[2022-10-03T23:20:14.803] _slurm_rpc_submit_batch_job: JobId=50107 InitPrio=851 usec=506
[2022-10-03T23:20:15.734] sched: Allocate JobId=50107 NodeList=cpu11 #CPUs=8 Partition=cpu-opteron
[2022-10-03T23:21:29.821] _slurm_rpc_submit_batch_job: JobId=50108 InitPrio=851 usec=460
[2022-10-03T23:22:18.436] _slurm_rpc_submit_batch_job: JobId=50109 InitPrio=851 usec=439
[2022-10-03T23:22:18.980] sched: Allocate JobId=50109 NodeList=cpu11 #CPUs=16 Partition=cpu-opteron
[2022-10-03T23:22:19.989] _job_complete: JobId=50109 WEXITSTATUS 1
[2022-10-03T23:22:19.989] _job_complete: JobId=50109 done
[2022-10-03T23:22:35.486] _slurm_rpc_kill_job: REQUEST_KILL_JOB JobId=50108 uid 548200023
[2022-10-03T23:23:05.828] _slurm_rpc_submit_batch_job: JobId=50110 InitPrio=851 usec=624
[2022-10-03T23:23:06.047] sched: Allocate JobId=50110 NodeList=cpu11 #CPUs=16 Partition=cpu-opteron
[2022-10-03T23:23:10.735] _job_complete: JobId=50110 WEXITSTATUS 0
[2022-10-03T23:23:10.736] _job_complete: JobId=50110 done
[2022-10-03T23:24:04.260] _job_complete: JobId=50107 WEXITSTATUS 0
[2022-10-03T23:24:04.260] _job_complete: JobId=50107 done
[2022-10-03T23:25:49.031] _slurm_rpc_submit_batch_job: JobId=50111 InitPrio=851 usec=470
[2022-10-03T23:25:49.272] sched: Allocate JobId=50111 NodeList=cpu11 #CPUs=8 Partition=cpu-opteron
[2022-10-03T23:26:19.946] _slurm_rpc_submit_batch_job: JobId=50112 InitPrio=638 usec=453
[2022-10-03T23:26:22.396] sched: Allocate JobId=50112 NodeList=cpu03 #CPUs=64 Partition=cpu-opteron
[2022-10-03T23:26:24.917] _job_complete: JobId=50112 WEXITSTATUS 1
[2022-10-03T23:26:24.918] _job_complete: JobId=50112 done
[2022-10-03T23:27:27.861] _slurm_rpc_submit_batch_job: JobId=50113 InitPrio=638 usec=459
[2022-10-03T23:27:28.483] sched: Allocate JobId=50113 NodeList=cpu03 #CPUs=64 Partition=cpu-opteron
[2022-10-03T23:29:35.163] _job_complete: JobId=50111 WEXITSTATUS 0
[2022-10-03T23:29:35.163] _job_complete: JobId=50111 done
[2022-10-03T23:36:24.451] _slurm_rpc_submit_batch_job: JobId=50114 InitPrio=851 usec=423
[2022-10-03T23:36:24.613] sched: Allocate JobId=50114 NodeList=cpu05 #CPUs=64 Partition=cpu-opteron
[2022-10-03T23:36:29.677] _job_complete: JobId=50114 WEXITSTATUS 1
[2022-10-03T23:36:29.677] _job_complete: JobId=50114 done
[2022-10-03T23:36:36.861] _slurm_rpc_kill_job: REQUEST_KILL_JOB JobId=50113 uid 548200019
[2022-10-03T23:36:55.241] _slurm_rpc_submit_batch_job: JobId=50115 InitPrio=638 usec=529
[2022-10-03T23:36:55.657] sched: Allocate JobId=50115 NodeList=cpu03 #CPUs=64 Partition=cpu-opteron
[2022-10-03T23:36:58.098] _slurm_rpc_submit_batch_job: JobId=50116 InitPrio=851 usec=488
[2022-10-03T23:36:58.658] sched: Allocate JobId=50116 NodeList=cpu05 #CPUs=64 Partition=cpu-opteron
[2022-10-03T23:37:02.824] _job_complete: JobId=50116 WEXITSTATUS 1
[2022-10-03T23:37:02.824] _job_complete: JobId=50116 done
[2022-10-03T23:37:30.983] _slurm_rpc_submit_batch_job: JobId=50117 InitPrio=851 usec=420
[2022-10-03T23:37:31.705] sched: Allocate JobId=50117 NodeList=cpu05 #CPUs=64 Partition=cpu-opteron
[2022-10-03T23:37:45.709] _job_complete: JobId=50117 WEXITSTATUS 1
[2022-10-03T23:37:45.709] _job_complete: JobId=50117 done
[2022-10-03T23:39:38.280] _slurm_rpc_submit_batch_job: JobId=50118 InitPrio=851 usec=389
[2022-10-03T23:39:38.880] sched: Allocate JobId=50118 NodeList=cpu05 #CPUs=64 Partition=cpu-opteron
[2022-10-03T23:40:58.279] _slurm_rpc_submit_batch_job: JobId=50119 InitPrio=851 usec=438
[2022-10-03T23:40:59.059] sched: Allocate JobId=50119 NodeList=cpu07 #CPUs=64 Partition=cpu-opteron
[2022-10-03T23:40:59.439] _slurm_rpc_kill_job: REQUEST_KILL_JOB JobId=50115 uid 548200019
[2022-10-03T23:41:49.678] _slurm_rpc_submit_batch_job: JobId=50120 InitPrio=638 usec=407
[2022-10-03T23:41:50.185] sched: Allocate JobId=50120 NodeList=cpu03 #CPUs=64 Partition=cpu-opteron
[2022-10-03T23:42:44.499] _slurm_rpc_submit_batch_job: JobId=50121 InitPrio=851 usec=452
[2022-10-03T23:44:09.991] _slurm_rpc_submit_batch_job: JobId=50122 InitPrio=851 usec=456
[2022-10-03T23:44:10.049] sched/backfill: _start_job: Started JobId=50122 in cpu-opteron on cpu08
[2022-10-03T23:44:24.272] _job_complete: JobId=50122 WEXITSTATUS 1
[2022-10-03T23:44:24.272] _job_complete: JobId=50122 done
[2022-10-03T23:45:23.199] _slurm_rpc_submit_batch_job: JobId=50123 InitPrio=851 usec=483
[2022-10-03T23:45:23.491] sched: Allocate JobId=50123 NodeList=cpu08 #CPUs=64 Partition=cpu-opteron
[2022-10-03T23:47:15.277] _job_complete: JobId=50120 OOM failure
[2022-10-03T23:47:15.277] _job_complete: JobId=50120 done
[2022-10-04T01:02:00.036] _job_complete: JobId=50102 WEXITSTATUS 0
[2022-10-04T01:02:00.042] _job_complete: JobId=50102 done
[2022-10-04T01:03:01.174] cleanup_completing: JobId=50102 completion process took 61 seconds
[2022-10-04T09:37:25.874] _job_complete: JobId=49861 WEXITSTATUS 0
[2022-10-04T09:37:25.875] _job_complete: JobId=49861 done
[2022-10-04T09:44:34.650] _job_complete: JobId=49727 WEXITSTATUS 0
[2022-10-04T09:44:34.650] _job_complete: JobId=49727 done
[2022-10-04T09:44:35.253] sched: Allocate JobId=49729 NodeList=cpu14 #CPUs=16 Partition=cpu-epyc
[2022-10-04T10:38:16.687] _slurm_rpc_submit_batch_job: JobId=50124 InitPrio=1882 usec=471
[2022-10-04T11:52:59.524] _slurm_rpc_submit_batch_job: JobId=50125 InitPrio=1464 usec=462
[2022-10-04T11:52:59.778] sched: Allocate JobId=50125 NodeList=cpu11 #CPUs=16 Partition=cpu-opteron
[2022-10-04T11:53:03.416] _job_complete: JobId=50125 WEXITSTATUS 1
[2022-10-04T11:53:03.416] _job_complete: JobId=50125 done
[2022-10-04T11:53:14.043] _slurm_rpc_submit_batch_job: JobId=50126 InitPrio=1464 usec=455
[2022-10-04T11:53:14.780] sched: Allocate JobId=50126 NodeList=cpu11 #CPUs=16 Partition=cpu-opteron
[2022-10-04T11:53:17.392] _job_complete: JobId=50126 WEXITSTATUS 1
[2022-10-04T11:53:17.393] _job_complete: JobId=50126 done
[2022-10-04T11:54:35.546] _slurm_rpc_kill_job: REQUEST_KILL_JOB JobId=50125 uid 548200029
[2022-10-04T11:54:40.175] _slurm_rpc_kill_job: REQUEST_KILL_JOB JobId=50126 uid 548200029
[2022-10-04T11:55:42.613] _slurm_rpc_submit_batch_job: JobId=50127 InitPrio=1464 usec=437
[2022-10-04T11:55:42.982] sched: Allocate JobId=50127 NodeList=cpu11 #CPUs=16 Partition=cpu-opteron
[2022-10-04T11:55:46.716] _job_complete: JobId=50127 WEXITSTATUS 1
[2022-10-04T11:55:46.717] _job_complete: JobId=50127 done
[2022-10-04T11:56:53.829] _slurm_rpc_submit_batch_job: JobId=50128 InitPrio=1464 usec=404
[2022-10-04T11:56:54.181] sched: Allocate JobId=50128 NodeList=cpu11 #CPUs=16 Partition=cpu-opteron
[2022-10-04T11:56:57.294] _job_complete: JobId=50128 WEXITSTATUS 1
[2022-10-04T11:56:57.295] _job_complete: JobId=50128 done
[2022-10-04T11:58:18.717] _slurm_rpc_kill_job: REQUEST_KILL_JOB JobId=50127 uid 548200029
[2022-10-04T11:58:26.200] _slurm_rpc_submit_batch_job: JobId=50129 InitPrio=1464 usec=393
[2022-10-04T11:58:26.312] sched: Allocate JobId=50129 NodeList=cpu11 #CPUs=16 Partition=cpu-opteron
[2022-10-04T11:58:29.373] _job_complete: JobId=50129 WEXITSTATUS 1
[2022-10-04T11:58:29.373] _job_complete: JobId=50129 done
[2022-10-04T11:58:50.288] _slurm_rpc_submit_batch_job: JobId=50130 InitPrio=1464 usec=420
[2022-10-04T11:58:50.346] sched: Allocate JobId=50130 NodeList=cpu11 #CPUs=16 Partition=cpu-opteron
[2022-10-04T11:59:26.504] _slurm_rpc_kill_job: REQUEST_KILL_JOB JobId=50130 uid 548200029
[2022-10-04T11:59:36.971] _slurm_rpc_submit_batch_job: JobId=50131 InitPrio=1464 usec=505
[2022-10-04T11:59:37.409] sched: Allocate JobId=50131 NodeList=cpu11 #CPUs=16 Partition=cpu-opteron
[2022-10-04T12:00:00.885] _job_complete: JobId=50131 WEXITSTATUS 0
[2022-10-04T12:00:00.886] _job_complete: JobId=50131 done
[2022-10-04T12:11:44.876] _slurm_rpc_submit_batch_job: JobId=50132 InitPrio=1464 usec=376
[2022-10-04T12:11:45.769] sched: Allocate JobId=50132 NodeList=cpu11 #CPUs=16 Partition=cpu-opteron
[2022-10-04T12:12:01.902] _job_complete: JobId=50132 WEXITSTATUS 0
[2022-10-04T12:12:01.902] _job_complete: JobId=50132 done
[2022-10-04T12:13:07.285] _slurm_rpc_submit_batch_job: JobId=50133 InitPrio=1464 usec=467
[2022-10-04T12:13:07.874] sched: Allocate JobId=50133 NodeList=cpu11 #CPUs=16 Partition=cpu-opteron
[2022-10-04T12:13:10.869] _job_complete: JobId=50133 WEXITSTATUS 1
[2022-10-04T12:13:10.869] _job_complete: JobId=50133 done
[2022-10-04T12:14:29.530] _slurm_rpc_submit_batch_job: JobId=50134 InitPrio=1464 usec=430
[2022-10-04T12:14:29.985] sched: Allocate JobId=50134 NodeList=cpu11 #CPUs=16 Partition=cpu-opteron
[2022-10-04T12:14:33.094] _job_complete: JobId=50134 WEXITSTATUS 1
[2022-10-04T12:14:33.094] _job_complete: JobId=50134 done
[2022-10-04T13:06:53.806] _slurm_rpc_submit_batch_job: JobId=50135 InitPrio=1464 usec=487
[2022-10-04T13:06:54.551] sched: Allocate JobId=50135 NodeList=cpu11 #CPUs=16 Partition=cpu-opteron
[2022-10-04T13:06:57.754] _job_complete: JobId=50135 WEXITSTATUS 1
[2022-10-04T13:06:57.754] _job_complete: JobId=50135 done
[2022-10-04T13:07:24.833] _slurm_rpc_submit_batch_job: JobId=50136 InitPrio=1464 usec=378
[2022-10-04T13:07:25.589] sched: Allocate JobId=50136 NodeList=cpu11 #CPUs=16 Partition=cpu-opteron
[2022-10-04T13:07:28.648] _job_complete: JobId=50136 WEXITSTATUS 1
[2022-10-04T13:07:28.649] _job_complete: JobId=50136 done
[2022-10-04T13:09:52.328] _job_complete: JobId=50119 WEXITSTATUS 1
[2022-10-04T13:09:52.328] _job_complete: JobId=50119 done
[2022-10-04T13:15:21.694] _slurm_rpc_submit_batch_job: JobId=50137 InitPrio=49372 usec=448
[2022-10-04T13:15:24.386] sched: Allocate JobId=50137 NodeList=cpu15 #CPUs=48 Partition=cpu-epyc
[2022-10-04T13:15:26.877] _job_complete: JobId=50137 WEXITSTATUS 1
[2022-10-04T13:15:26.877] _job_complete: JobId=50137 done
[2022-10-04T13:16:49.672] _slurm_rpc_submit_batch_job: JobId=50138 InitPrio=49372 usec=467
[2022-10-04T13:16:50.579] sched: Allocate JobId=50138 NodeList=cpu15 #CPUs=48 Partition=cpu-epyc
[2022-10-04T13:26:02.191] _slurm_rpc_submit_batch_job: JobId=50139 InitPrio=2928 usec=461
[2022-10-04T13:27:42.733] _slurm_rpc_submit_batch_job: JobId=50140 InitPrio=627 usec=509
[2022-10-04T13:27:42.792] sched: Allocate JobId=50140 NodeList=cpu07 #CPUs=64 Partition=cpu-opteron
[2022-10-04T14:08:54.104] _slurm_rpc_submit_batch_job: JobId=50141 InitPrio=1464 usec=440
[2022-10-04T14:08:54.965] sched: Allocate JobId=50141 NodeList=cpu11 #CPUs=16 Partition=cpu-opteron
[2022-10-04T14:08:58.979] _job_complete: JobId=50141 WEXITSTATUS 1
[2022-10-04T14:08:58.980] _job_complete: JobId=50141 done
[2022-10-04T14:09:18.253] _slurm_rpc_submit_batch_job: JobId=50142 InitPrio=1464 usec=383
[2022-10-04T14:09:18.993] sched: Allocate JobId=50142 NodeList=cpu11 #CPUs=16 Partition=cpu-opteron
[2022-10-04T14:09:22.811] _job_complete: JobId=50142 WEXITSTATUS 1
[2022-10-04T14:09:22.811] _job_complete: JobId=50142 done
[2022-10-04T14:17:37.244] _slurm_rpc_submit_batch_job: JobId=50143 InitPrio=1464 usec=430
[2022-10-04T14:17:37.891] sched: Allocate JobId=50143 NodeList=cpu11 #CPUs=16 Partition=cpu-opteron
[2022-10-04T14:17:48.253] _job_complete: JobId=50143 WEXITSTATUS 0
[2022-10-04T14:17:48.253] _job_complete: JobId=50143 done
[2022-10-04T14:19:47.506] _slurm_rpc_submit_batch_job: JobId=50144 InitPrio=1464 usec=492
[2022-10-04T14:19:48.078] sched: Allocate JobId=50144 NodeList=cpu11 #CPUs=16 Partition=cpu-opteron
[2022-10-04T14:19:51.458] _job_complete: JobId=50144 WEXITSTATUS 1
[2022-10-04T14:19:51.459] _job_complete: JobId=50144 done
[2022-10-04T14:20:05.990] _slurm_rpc_submit_batch_job: JobId=50145 InitPrio=1464 usec=463
[2022-10-04T14:20:06.098] sched: Allocate JobId=50145 NodeList=cpu11 #CPUs=16 Partition=cpu-opteron
[2022-10-04T14:20:10.069] _job_complete: JobId=50145 WEXITSTATUS 1
[2022-10-04T14:20:10.069] _job_complete: JobId=50145 done
[2022-10-04T14:23:42.029] _slurm_rpc_submit_batch_job: JobId=50146 InitPrio=1464 usec=450
[2022-10-04T14:23:42.525] sched: Allocate JobId=50146 NodeList=cpu11 #CPUs=16 Partition=cpu-opteron
[2022-10-04T14:23:47.667] _job_complete: JobId=50146 WEXITSTATUS 0
[2022-10-04T14:23:47.667] _job_complete: JobId=50146 done
[2022-10-04T14:26:51.636] _slurm_rpc_submit_batch_job: JobId=50147 InitPrio=1464 usec=509
[2022-10-04T14:26:51.969] sched: Allocate JobId=50147 NodeList=cpu11 #CPUs=16 Partition=cpu-opteron
[2022-10-04T14:26:57.003] _job_complete: JobId=50147 WEXITSTATUS 0
[2022-10-04T14:26:57.004] _job_complete: JobId=50147 done
[2022-10-04T14:41:41.081] _job_complete: JobId=50140 WEXITSTATUS 0
[2022-10-04T14:41:41.081] _job_complete: JobId=50140 done
[2022-10-04T15:12:59.117] sched: _slurm_rpc_allocate_resources JobId=50148 NodeList=(null) usec=836
[2022-10-04T15:12:59.747] sched: Allocate JobId=50148 NodeList=cpu11 #CPUs=1 Partition=cpu-opteron
[2022-10-04T15:14:07.392] _job_complete: JobId=50148 WEXITSTATUS 0
[2022-10-04T15:14:07.392] _job_complete: JobId=50148 done
[2022-10-04T15:15:04.907] error: This association 254(account='free', user='ongkuanhung', partition='(null)') does not have access to qos normal
[2022-10-04T15:15:04.907] _slurm_rpc_submit_batch_job: Invalid qos specification
[2022-10-04T15:30:38.215] _slurm_rpc_submit_batch_job: JobId=50149 InitPrio=15020 usec=485
[2022-10-04T15:30:38.489] sched: Allocate JobId=50149 NodeList=cpu11 #CPUs=16 Partition=cpu-opteron
[2022-10-04T15:30:40.884] _job_complete: JobId=50149 WEXITSTATUS 0
[2022-10-04T15:30:40.884] _job_complete: JobId=50149 done
[2022-10-04T15:31:27.215] _slurm_rpc_submit_batch_job: JobId=50150 InitPrio=836 usec=415
[2022-10-04T15:32:34.082] _slurm_rpc_submit_batch_job: JobId=50151 InitPrio=836 usec=470
[2022-10-04T15:32:39.933] sched: _slurm_rpc_allocate_resources JobId=50152 NodeList=(null) usec=1110
[2022-10-04T15:32:40.752] sched: Allocate JobId=50152 NodeList=cpu11 #CPUs=8 Partition=cpu-opteron
[2022-10-04T15:33:05.986] _slurm_rpc_kill_job: REQUEST_KILL_JOB JobId=50123 uid 548200023
[2022-10-04T15:33:09.653] _slurm_rpc_kill_job: REQUEST_KILL_JOB JobId=50118 uid 548200023
[2022-10-04T15:48:25.635] _job_complete: JobId=50152 WEXITSTATUS 0
[2022-10-04T15:48:25.635] _job_complete: JobId=50152 done
[2022-10-04T15:53:09.846] sched: _slurm_rpc_allocate_resources JobId=50153 NodeList=(null) usec=1395
[2022-10-04T15:53:09.868] sched: Allocate JobId=50153 NodeList=cpu11 #CPUs=16 Partition=cpu-opteron
[2022-10-04T15:57:19.481] _slurm_rpc_kill_job: REQUEST_KILL_JOB JobId=50153 uid 548300543
[2022-10-04T16:40:22.483] error: This association 246(account='free', user='chiuling', partition='(null)') does not have access to qos long
[2022-10-04T16:40:22.483] _slurm_rpc_submit_batch_job: Invalid qos specification
[2022-10-04T16:41:26.353] _slurm_rpc_submit_batch_job: JobId=50154 InitPrio=59163 usec=553
[2022-10-04T16:41:27.228] sched: Allocate JobId=50154 NodeList=cpu11 #CPUs=4 Partition=cpu-opteron
[2022-10-04T16:41:28.148] _job_complete: JobId=50154 WEXITSTATUS 2
[2022-10-04T16:41:28.148] _job_complete: JobId=50154 done
[2022-10-04T16:44:17.873] _slurm_rpc_submit_batch_job: JobId=50155 InitPrio=59163 usec=605
[2022-10-04T16:44:18.364] sched: Allocate JobId=50155 NodeList=cpu11 #CPUs=4 Partition=cpu-opteron
[2022-10-04T16:50:12.345] _slurm_rpc_kill_job: REQUEST_KILL_JOB JobId=50155 uid 548300630
[2022-10-04T16:52:23.523] _slurm_rpc_submit_batch_job: JobId=50156 InitPrio=20041 usec=463
[2022-10-04T16:52:24.258] sched: Allocate JobId=50156 NodeList=cpu11 #CPUs=4 Partition=cpu-opteron
[2022-10-04T16:59:28.569] _job_complete: JobId=50156 WEXITSTATUS 0
[2022-10-04T16:59:28.569] _job_complete: JobId=50156 done
[2022-10-04T17:28:11.915] _slurm_rpc_submit_batch_job: JobId=50157 InitPrio=1046 usec=452
[2022-10-04T17:28:11.992] sched: Allocate JobId=50157 NodeList=cpu01 #CPUs=64 Partition=cpu-opteron
[2022-10-04T17:50:49.477] _slurm_rpc_submit_batch_job: JobId=50158 InitPrio=627 usec=601
[2022-10-04T17:50:50.288] sched: Allocate JobId=50158 NodeList=cpu03 #CPUs=64 Partition=cpu-opteron
[2022-10-04T21:14:03.139] _job_complete: JobId=50158 WEXITSTATUS 0
[2022-10-04T21:14:03.139] _job_complete: JobId=50158 done
[2022-10-04T21:36:44.506] _job_complete: JobId=50138 WEXITSTATUS 0
[2022-10-04T21:36:44.506] _job_complete: JobId=50138 done
[2022-10-04T21:57:00.101] _slurm_rpc_submit_batch_job: JobId=50159 InitPrio=627 usec=586
[2022-10-04T21:57:00.318] sched: Allocate JobId=50159 NodeList=cpu03 #CPUs=64 Partition=cpu-opteron
[2022-10-04T22:03:38.863] _job_complete: JobId=49726 WEXITSTATUS 0
[2022-10-04T22:03:38.863] _job_complete: JobId=49726 done
[2022-10-04T22:03:40.300] sched: Allocate JobId=49730 NodeList=cpu13 #CPUs=16 Partition=cpu-epyc
[2022-10-04T22:35:55.881] _slurm_rpc_submit_batch_job: JobId=50160 InitPrio=2510 usec=506
[2022-10-04T22:35:56.215] sched: Allocate JobId=50160 NodeList=cpu11 #CPUs=4 Partition=cpu-opteron
[2022-10-04T22:39:24.814] _job_complete: JobId=50159 WEXITSTATUS 0
[2022-10-04T22:39:24.814] _job_complete: JobId=50159 done
[2022-10-04T22:43:09.297] _slurm_rpc_submit_batch_job: JobId=50161 InitPrio=2510 usec=535
[2022-10-04T22:43:09.960] sched: Allocate JobId=50161 NodeList=cpu11 #CPUs=2 Partition=cpu-opteron
[2022-10-04T23:07:07.143] _slurm_rpc_submit_batch_job: JobId=50162 InitPrio=209 usec=646
[2022-10-04T23:07:07.448] sched: Allocate JobId=50162 NodeList=cpu03 #CPUs=64 Partition=cpu-opteron
[2022-10-04T23:07:20.297] _slurm_rpc_submit_batch_job: JobId=50163 InitPrio=209 usec=440
[2022-10-04T23:11:07.999] _slurm_rpc_submit_batch_job: JobId=50164 InitPrio=209 usec=383
[2022-10-04T23:11:08.026] sched: Allocate JobId=50164 NodeList=cpu04 #CPUs=64 Partition=cpu-opteron
[2022-10-04T23:12:49.856] _slurm_rpc_kill_job: REQUEST_KILL_JOB JobId=50162 uid 548200017
[2022-10-04T23:13:51.642] _slurm_rpc_submit_batch_job: JobId=50165 InitPrio=209 usec=669
[2022-10-04T23:13:52.253] sched: Allocate JobId=50165 NodeList=cpu03 #CPUs=64 Partition=cpu-opteron
[2022-10-04T23:14:30.612] _slurm_rpc_kill_job: REQUEST_KILL_JOB JobId=50164 uid 548200017
[2022-10-04T23:14:51.302] _slurm_rpc_submit_batch_job: JobId=50166 InitPrio=209 usec=486
[2022-10-04T23:14:51.336] sched: Allocate JobId=50166 NodeList=cpu04 #CPUs=64 Partition=cpu-opteron
[2022-10-04T23:19:57.676] _slurm_rpc_kill_job: REQUEST_KILL_JOB JobId=50166 uid 548200017
[2022-10-04T23:20:22.717] _slurm_rpc_submit_batch_job: JobId=50167 InitPrio=209 usec=517
[2022-10-04T23:20:22.981] sched: Allocate JobId=50167 NodeList=cpu04 #CPUs=64 Partition=cpu-opteron
[2022-10-05T00:16:13.252] _job_complete: JobId=50161 WEXITSTATUS 0
[2022-10-05T00:16:13.253] _job_complete: JobId=50161 done
[2022-10-05T00:47:45.114] _job_complete: JobId=50157 WEXITSTATUS 0
[2022-10-05T00:47:45.114] _job_complete: JobId=50157 done
[2022-10-05T01:21:02.499] _slurm_rpc_submit_batch_job: JobId=50168 InitPrio=627 usec=637
[2022-10-05T01:21:02.666] sched: Allocate JobId=50168 NodeList=cpu01 #CPUs=64 Partition=cpu-opteron
[2022-10-05T01:22:18.831] _slurm_rpc_submit_batch_job: JobId=50169 InitPrio=627 usec=555
[2022-10-05T01:22:19.758] sched: Allocate JobId=50169 NodeList=cpu05 #CPUs=64 Partition=cpu-opteron
[2022-10-05T01:23:48.687] _job_complete: JobId=50168 WEXITSTATUS 0
[2022-10-05T01:23:48.687] _job_complete: JobId=50168 done
[2022-10-05T01:39:03.575] _slurm_rpc_submit_batch_job: JobId=50170 InitPrio=1464 usec=436
[2022-10-05T01:39:04.389] sched: Allocate JobId=50170 NodeList=cpu01 #CPUs=8 Partition=cpu-opteron
[2022-10-05T01:47:00.334] _slurm_rpc_kill_job: REQUEST_KILL_JOB JobId=50169 uid 548200019
[2022-10-05T01:47:26.940] _slurm_rpc_submit_batch_job: JobId=50171 InitPrio=627 usec=509
[2022-10-05T01:47:27.238] sched: Allocate JobId=50171 NodeList=cpu05 #CPUs=64 Partition=cpu-opteron
[2022-10-05T02:36:38.034] _job_complete: JobId=50171 WEXITSTATUS 0
[2022-10-05T02:36:38.034] _job_complete: JobId=50171 done
[2022-10-05T02:42:12.351] _slurm_rpc_submit_batch_job: JobId=50172 InitPrio=627 usec=583
[2022-10-05T02:42:13.141] sched: Allocate JobId=50172 NodeList=cpu05 #CPUs=64 Partition=cpu-opteron
[2022-10-05T02:45:06.655] _job_complete: JobId=50170 WEXITSTATUS 0
[2022-10-05T02:45:06.656] _job_complete: JobId=50170 done
[2022-10-05T02:47:30.516] _slurm_rpc_submit_batch_job: JobId=50173 InitPrio=1046 usec=532
[2022-10-05T02:47:30.809] sched: Allocate JobId=50173 NodeList=cpu01 #CPUs=64 Partition=cpu-opteron
[2022-10-05T04:28:43.434] Time limit exhausted for JobId=49836
[2022-10-05T04:38:27.295] _job_complete: JobId=50172 WEXITSTATUS 0
[2022-10-05T04:38:27.295] _job_complete: JobId=50172 done
[2022-10-05T05:07:48.486] _job_complete: JobId=49728 WEXITSTATUS 0
[2022-10-05T05:07:48.486] _job_complete: JobId=49728 done
[2022-10-05T05:07:48.955] sched: Allocate JobId=49731 NodeList=cpu12 #CPUs=16 Partition=cpu-epyc
[2022-10-05T05:10:11.600] _slurm_rpc_submit_batch_job: JobId=50174 InitPrio=2510 usec=549
[2022-10-05T05:10:11.771] sched: Allocate JobId=50174 NodeList=cpu11 #CPUs=2 Partition=cpu-opteron
[2022-10-05T05:30:27.522] _job_complete: JobId=50174 WEXITSTATUS 0
[2022-10-05T05:30:27.522] _job_complete: JobId=50174 done
[2022-10-05T06:51:25.159] _job_complete: JobId=50173 WEXITSTATUS 0
[2022-10-05T06:51:25.159] _job_complete: JobId=50173 done
[2022-10-05T07:29:39.164] _slurm_rpc_submit_batch_job: JobId=50175 InitPrio=1464 usec=550
[2022-10-05T07:29:39.530] sched: Allocate JobId=50175 NodeList=cpu01 #CPUs=8 Partition=cpu-opteron
[2022-10-05T07:29:45.360] _job_complete: JobId=50175 WEXITSTATUS 1
[2022-10-05T07:29:45.361] _job_complete: JobId=50175 done
[2022-10-05T07:34:50.733] _slurm_rpc_submit_batch_job: JobId=50176 InitPrio=1464 usec=419
[2022-10-05T07:34:51.034] sched: Allocate JobId=50176 NodeList=cpu01 #CPUs=8 Partition=cpu-opteron
[2022-10-05T07:35:01.824] _job_complete: JobId=50176 WEXITSTATUS 2
[2022-10-05T07:35:01.825] _job_complete: JobId=50176 done
[2022-10-05T07:42:08.059] _slurm_rpc_submit_batch_job: JobId=50177 InitPrio=1464 usec=477
[2022-10-05T07:42:08.142] sched: Allocate JobId=50177 NodeList=cpu01 #CPUs=8 Partition=cpu-opteron
[2022-10-05T07:42:19.509] _job_complete: JobId=50177 WEXITSTATUS 2
[2022-10-05T07:42:19.510] _job_complete: JobId=50177 done
[2022-10-05T07:43:45.213] _slurm_rpc_submit_batch_job: JobId=50178 InitPrio=1464 usec=490
[2022-10-05T07:43:45.270] sched: Allocate JobId=50178 NodeList=cpu01 #CPUs=8 Partition=cpu-opteron
[2022-10-05T07:47:05.558] _slurm_rpc_submit_batch_job: JobId=50179 InitPrio=1464 usec=484
[2022-10-05T07:47:05.692] sched: Allocate JobId=50179 NodeList=cpu01 #CPUs=8 Partition=cpu-opteron
[2022-10-05T08:07:01.615] _job_complete: JobId=50167 WEXITSTATUS 0
[2022-10-05T08:07:01.620] _job_complete: JobId=50167 done
[2022-10-05T08:24:43.594] _slurm_rpc_submit_batch_job: JobId=50180 InitPrio=2092 usec=534
[2022-10-05T09:11:03.346] _job_complete: JobId=50178 WEXITSTATUS 1
[2022-10-05T09:11:03.351] _job_complete: JobId=50178 done
[2022-10-05T09:18:32.501] _slurm_rpc_kill_job: REQUEST_KILL_JOB JobId=49565 uid 548200003
[2022-10-05T09:18:34.513] _slurm_rpc_kill_job: REQUEST_KILL_JOB JobId=49564 uid 548200003
[2022-10-05T09:24:14.177] _slurm_rpc_submit_batch_job: JobId=50181 InitPrio=49372 usec=517
[2022-10-05T09:24:14.402] sched: Allocate JobId=50181 NodeList=cpu15 #CPUs=48 Partition=cpu-epyc
[2022-10-05T09:25:32.218] _job_complete: JobId=50179 WEXITSTATUS 0
[2022-10-05T09:25:32.219] _job_complete: JobId=50179 done
[2022-10-05T09:56:41.117] _slurm_rpc_submit_batch_job: JobId=50182 InitPrio=1464 usec=1024
[2022-10-05T09:57:15.421] _slurm_rpc_kill_job: REQUEST_KILL_JOB JobId=50099 uid 548200029
[2022-10-05T09:57:19.795] sched: Allocate JobId=50182 NodeList=gpu03 #CPUs=16 Partition=gpu-k10
[2022-10-05T10:34:13.018] Time limit exhausted for JobId=49846
[2022-10-05T11:32:29.054] _slurm_rpc_submit_batch_job: JobId=50183 InitPrio=627 usec=546
[2022-10-05T11:32:29.802] sched: Allocate JobId=50183 NodeList=cpu01 #CPUs=64 Partition=cpu-opteron
[2022-10-05T11:44:05.692] _slurm_rpc_kill_job: REQUEST_KILL_JOB JobId=50183 uid 548200019
[2022-10-05T11:44:21.650] _slurm_rpc_submit_batch_job: JobId=50184 InitPrio=627 usec=540
[2022-10-05T11:44:22.239] sched: Allocate JobId=50184 NodeList=cpu01 #CPUs=64 Partition=cpu-opteron
[2022-10-05T12:41:57.205] _slurm_rpc_submit_batch_job: JobId=50185 InitPrio=1464 usec=468
[2022-10-05T12:41:57.806] sched: Allocate JobId=50185 NodeList=cpu11 #CPUs=8 Partition=cpu-opteron
[2022-10-05T12:42:06.417] _job_complete: JobId=50185 WEXITSTATUS 1
[2022-10-05T12:42:06.418] _job_complete: JobId=50185 done
[2022-10-05T12:48:12.436] _job_complete: JobId=50184 WEXITSTATUS 0
[2022-10-05T12:48:12.437] _job_complete: JobId=50184 done
[2022-10-05T14:26:18.388] _job_complete: JobId=50100 WEXITSTATUS 1
[2022-10-05T14:26:18.395] _job_complete: JobId=50100 done
[2022-10-05T15:20:33.566] _job_complete: JobId=50071 WEXITSTATUS 0
[2022-10-05T15:20:33.572] _job_complete: JobId=50071 done
[2022-10-05T15:21:50.750] _slurm_rpc_submit_batch_job: JobId=50186 InitPrio=627 usec=590
[2022-10-05T15:21:51.738] sched: Allocate JobId=50186 NodeList=cpu01 #CPUs=64 Partition=cpu-opteron
[2022-10-05T15:26:14.176] _slurm_rpc_submit_batch_job: JobId=50187 InitPrio=1255 usec=507
[2022-10-05T17:54:35.541] _job_complete: JobId=50186 WEXITSTATUS 0
[2022-10-05T17:54:35.541] _job_complete: JobId=50186 done
[2022-10-05T18:12:34.119] _slurm_rpc_submit_batch_job: JobId=50188 InitPrio=627 usec=678
[2022-10-05T18:12:34.280] sched: Allocate JobId=50188 NodeList=cpu01 #CPUs=64 Partition=cpu-opteron
[2022-10-05T18:40:53.806] _slurm_rpc_kill_job: REQUEST_KILL_JOB JobId=50181 uid 548200003
[2022-10-05T18:41:03.815] error: slurm_receive_msgs: [[cpu15.dicc.um.edu.my]:6818] failed: Socket timed out on send/recv operation
[2022-10-05T18:41:11.687] Node cpu15 now responding
[2022-10-05T18:44:31.952] cleanup_completing: JobId=50181 completion process took 211 seconds
[2022-10-05T18:44:31.952] error: Nodes cpu15 not responding, setting DOWN
[2022-10-05T18:46:30.785] Node cpu15 now responding
[2022-10-05T18:46:30.785] node cpu15 returned to service
[2022-10-05T18:52:30.425] _job_complete: JobId=50188 WEXITSTATUS 0
[2022-10-05T18:52:30.425] _job_complete: JobId=50188 done
[2022-10-05T20:27:09.347] _slurm_rpc_submit_batch_job: JobId=50189 InitPrio=627 usec=832
[2022-10-05T20:27:09.609] sched: Allocate JobId=50189 NodeList=cpu01 #CPUs=64 Partition=cpu-opteron
[2022-10-05T20:29:43.576] _job_complete: JobId=50189 WEXITSTATUS 0
[2022-10-05T20:29:43.576] _job_complete: JobId=50189 done
[2022-10-05T22:26:53.622] _slurm_rpc_submit_batch_job: JobId=50190 InitPrio=2510 usec=743
[2022-10-05T22:26:54.413] sched: Allocate JobId=50190 NodeList=cpu01 #CPUs=8 Partition=cpu-opteron
[2022-10-05T22:29:57.989] _slurm_rpc_submit_batch_job: JobId=50191 InitPrio=2510 usec=443
[2022-10-05T22:29:58.655] sched: Allocate JobId=50191 NodeList=cpu01 #CPUs=8 Partition=cpu-opteron
[2022-10-05T22:46:29.203] _slurm_rpc_submit_batch_job: JobId=50192 InitPrio=627 usec=444
[2022-10-05T22:46:29.714] sched: Allocate JobId=50192 NodeList=cpu04 #CPUs=64 Partition=cpu-opteron
[2022-10-06T00:22:14.197] _slurm_rpc_submit_batch_job: JobId=50193 InitPrio=836 usec=529
[2022-10-06T00:22:14.864] sched: Allocate JobId=50193 NodeList=cpu01 #CPUs=32 Partition=cpu-opteron
[2022-10-06T00:24:19.659] _job_complete: JobId=50193 WEXITSTATUS 0
[2022-10-06T00:24:19.659] _job_complete: JobId=50193 done
[2022-10-06T00:32:50.356] _slurm_rpc_submit_batch_job: JobId=50194 InitPrio=836 usec=520
[2022-10-06T00:32:50.902] sched: Allocate JobId=50194 NodeList=cpu01 #CPUs=32 Partition=cpu-opteron
[2022-10-06T00:34:43.676] _job_complete: JobId=50194 WEXITSTATUS 0
[2022-10-06T00:34:43.676] _job_complete: JobId=50194 done
[2022-10-06T00:41:47.233] _slurm_rpc_submit_batch_job: JobId=50195 InitPrio=836 usec=413
[2022-10-06T00:41:47.985] sched: Allocate JobId=50195 NodeList=cpu01 #CPUs=32 Partition=cpu-opteron
[2022-10-06T00:46:18.486] _slurm_rpc_submit_batch_job: JobId=50196 InitPrio=836 usec=423
[2022-10-06T00:46:19.449] sched: Allocate JobId=50196 NodeList=cpu11 #CPUs=32 Partition=cpu-opteron
[2022-10-06T00:48:22.544] _job_complete: JobId=50196 WEXITSTATUS 0
[2022-10-06T00:48:22.544] _job_complete: JobId=50196 done
[2022-10-06T00:51:55.923] _slurm_rpc_submit_batch_job: JobId=50197 InitPrio=836 usec=680
[2022-10-06T00:51:55.996] sched: Allocate JobId=50197 NodeList=cpu11 #CPUs=32 Partition=cpu-opteron
[2022-10-06T01:32:34.261] _slurm_rpc_kill_job: REQUEST_KILL_JOB JobId=50192 uid 548200019
[2022-10-06T01:33:03.880] _slurm_rpc_submit_batch_job: JobId=50198 InitPrio=627 usec=659
[2022-10-06T01:33:03.990] sched: Allocate JobId=50198 NodeList=cpu04 #CPUs=64 Partition=cpu-opteron
[2022-10-06T01:44:21.805] _slurm_rpc_submit_batch_job: JobId=50199 InitPrio=627 usec=495
[2022-10-06T01:44:22.091] sched: Allocate JobId=50199 NodeList=cpu05 #CPUs=64 Partition=cpu-opteron
[2022-10-06T02:15:21.201] _job_complete: JobId=50195 WEXITSTATUS 0
[2022-10-06T02:15:21.201] _job_complete: JobId=50195 done
[2022-10-06T02:26:42.571] _job_complete: JobId=50199 WEXITSTATUS 0
[2022-10-06T02:26:42.571] _job_complete: JobId=50199 done
[2022-10-06T02:32:58.070] _job_complete: JobId=50197 WEXITSTATUS 0
[2022-10-06T02:32:58.070] _job_complete: JobId=50197 done
[2022-10-06T02:33:35.668] _slurm_rpc_submit_batch_job: JobId=50200 InitPrio=627 usec=550
[2022-10-06T02:33:36.424] sched: Allocate JobId=50200 NodeList=cpu05 #CPUs=64 Partition=cpu-opteron
[2022-10-06T02:35:17.854] _job_complete: JobId=50200 WEXITSTATUS 0
[2022-10-06T02:35:17.855] _job_complete: JobId=50200 done
[2022-10-06T02:42:30.208] _job_complete: JobId=50182 WEXITSTATUS 1
[2022-10-06T02:42:30.214] _job_complete: JobId=50182 done
[2022-10-06T03:40:31.907] _slurm_rpc_submit_batch_job: JobId=50201 InitPrio=627 usec=731
[2022-10-06T03:40:32.640] sched: Allocate JobId=50201 NodeList=cpu05 #CPUs=64 Partition=cpu-opteron
[2022-10-06T03:48:37.506] _job_complete: JobId=50198 WEXITSTATUS 2
[2022-10-06T03:48:37.506] _job_complete: JobId=50198 done
[2022-10-06T04:23:02.861] _job_complete: JobId=50201 WEXITSTATUS 0
[2022-10-06T04:23:02.861] _job_complete: JobId=50201 done
[2022-10-06T04:51:17.132] _slurm_rpc_submit_batch_job: JobId=50202 InitPrio=627 usec=486
[2022-10-06T04:51:17.190] sched: Allocate JobId=50202 NodeList=cpu04 #CPUs=64 Partition=cpu-opteron
[2022-10-06T04:53:56.227] _job_complete: JobId=50202 WEXITSTATUS 0
[2022-10-06T04:53:56.227] _job_complete: JobId=50202 done
[2022-10-06T07:19:35.288] _slurm_rpc_submit_batch_job: JobId=50203 InitPrio=1255 usec=488
[2022-10-06T07:19:36.250] sched: Allocate JobId=50203 NodeList=cpu01 #CPUs=8 Partition=cpu-opteron
[2022-10-06T07:59:01.708] _slurm_rpc_submit_batch_job: JobId=50204 InitPrio=2510 usec=478
[2022-10-06T07:59:02.585] sched: Allocate JobId=50204 NodeList=cpu01 #CPUs=4 Partition=cpu-opteron
[2022-10-06T08:11:32.926] _job_complete: JobId=50203 WEXITSTATUS 1
[2022-10-06T08:11:32.927] _job_complete: JobId=50203 done
[2022-10-06T08:40:33.831] _job_complete: JobId=50165 WEXITSTATUS 0
[2022-10-06T08:40:33.837] _job_complete: JobId=50165 done
[2022-10-06T08:50:17.974] Time limit exhausted for JobId=49875
[2022-10-06T09:29:17.373] _job_complete: JobId=50160 WEXITSTATUS 1
[2022-10-06T09:29:17.373] _job_complete: JobId=50160 done
[2022-10-06T12:13:24.033] _slurm_rpc_submit_batch_job: JobId=50205 InitPrio=1255 usec=441
[2022-10-06T12:13:24.370] sched: Allocate JobId=50205 NodeList=cpu01 #CPUs=16 Partition=cpu-opteron
[2022-10-06T12:13:27.106] _job_complete: JobId=50205 WEXITSTATUS 1
[2022-10-06T12:13:27.107] _job_complete: JobId=50205 done
[2022-10-06T12:23:22.791] _slurm_rpc_submit_batch_job: JobId=50206 InitPrio=1255 usec=567
[2022-10-06T12:23:23.365] sched: Allocate JobId=50206 NodeList=cpu01 #CPUs=8 Partition=cpu-opteron
[2022-10-06T12:50:13.661] error: User 548300548 not found
[2022-10-06T12:50:13.661] _job_create: invalid account or partition for user 548300548, account '(null)', and partition 'gpu-k10'
[2022-10-06T12:50:13.661] _slurm_rpc_allocate_resources: Invalid account or account/partition combination specified 
[2022-10-06T12:51:54.239] error: User 548300548 not found
[2022-10-06T12:51:54.239] _job_create: invalid account or partition for user 548300548, account '(null)', and partition 'gpu-k10'
[2022-10-06T12:51:54.239] _slurm_rpc_allocate_resources: Invalid account or account/partition combination specified 
[2022-10-06T12:52:48.957] error: User 548300548 not found
[2022-10-06T12:52:48.957] _job_create: invalid account or partition for user 548300548, account '(null)', and partition 'cpu-opteron'
[2022-10-06T12:52:48.957] _slurm_rpc_allocate_resources: Invalid account or account/partition combination specified 
[2022-10-06T12:53:29.274] error: User 548300548 not found
[2022-10-06T12:53:29.274] _job_create: invalid account or partition for user 548300548, account '(null)', and partition 'gpu-k10'
[2022-10-06T12:53:29.274] _slurm_rpc_allocate_resources: Invalid account or account/partition combination specified 
[2022-10-06T12:53:37.809] error: User 548300548 not found
[2022-10-06T12:53:37.809] _job_create: invalid account or partition for user 548300548, account '(null)', and partition 'gpu-k10'
[2022-10-06T12:53:37.809] _slurm_rpc_allocate_resources: Invalid account or account/partition combination specified 
[2022-10-06T12:53:41.946] error: User 548300548 not found
[2022-10-06T12:53:41.946] _job_create: invalid account or partition for user 548300548, account '(null)', and partition 'gpu-k10'
[2022-10-06T12:53:41.946] _slurm_rpc_allocate_resources: Invalid account or account/partition combination specified 
[2022-10-06T12:54:15.093] error: User 548300548 not found
[2022-10-06T12:54:15.093] _job_create: invalid account or partition for user 548300548, account '(null)', and partition 'gpu-k10'
[2022-10-06T12:54:15.093] _slurm_rpc_allocate_resources: Invalid account or account/partition combination specified 
[2022-10-06T12:55:17.546] error: User 548300548 not found
[2022-10-06T12:55:17.546] _job_create: invalid account or partition for user 548300548, account '(null)', and partition 'gpu-k10'
[2022-10-06T12:55:17.546] _slurm_rpc_allocate_resources: Invalid account or account/partition combination specified 
[2022-10-06T12:55:52.524] error: User 548300548 not found
[2022-10-06T12:55:52.525] _job_create: invalid account or partition for user 548300548, account '(null)', and partition 'gpu-k40c'
[2022-10-06T12:55:52.525] _slurm_rpc_allocate_resources: Invalid account or account/partition combination specified 
[2022-10-06T12:56:03.558] error: User 548300548 not found
[2022-10-06T12:56:03.558] _job_create: invalid account or partition for user 548300548, account '(null)', and partition 'cpu-opteron'
[2022-10-06T12:56:03.558] _slurm_rpc_allocate_resources: Invalid account or account/partition combination specified 
[2022-10-06T12:57:27.601] error: User 548300548 not found
[2022-10-06T12:57:27.601] _job_create: invalid account or partition for user 548300548, account '(null)', and partition 'gpu-k10'
[2022-10-06T12:57:27.601] _slurm_rpc_allocate_resources: Invalid account or account/partition combination specified 
[2022-10-06T12:58:03.663] error: User 548300548 not found
[2022-10-06T12:58:03.663] _job_create: invalid account or partition for user 548300548, account '(null)', and partition 'cpu-opteron'
[2022-10-06T12:58:03.663] _slurm_rpc_allocate_resources: Invalid account or account/partition combination specified 
[2022-10-06T12:58:41.873] error: User 548300548 not found
[2022-10-06T12:58:41.873] _job_create: invalid account or partition for user 548300548, account '(null)', and partition 'gpu-k10'
[2022-10-06T12:58:41.873] _slurm_rpc_allocate_resources: Invalid account or account/partition combination specified 
[2022-10-06T12:58:54.823] error: User 548300548 not found
[2022-10-06T12:58:54.823] _job_create: invalid account or partition for user 548300548, account '(null)', and partition 'cpu-opteron'
[2022-10-06T12:58:54.823] _slurm_rpc_allocate_resources: Invalid account or account/partition combination specified 
[2022-10-06T12:58:56.684] error: User 548300548 not found
[2022-10-06T12:58:56.684] _job_create: invalid account or partition for user 548300548, account '(null)', and partition 'gpu-k10'
[2022-10-06T12:58:56.684] _slurm_rpc_allocate_resources: Invalid account or account/partition combination specified 
[2022-10-06T13:13:33.104] _slurm_rpc_submit_batch_job: JobId=50207 InitPrio=627 usec=566
[2022-10-06T13:13:33.740] sched: Allocate JobId=50207 NodeList=cpu03 #CPUs=64 Partition=cpu-opteron
[2022-10-06T13:17:03.533] error: User 548300548 not found
[2022-10-06T13:17:03.533] _job_create: invalid account or partition for user 548300548, account '(null)', and partition 'gpu-k10'
[2022-10-06T13:17:03.533] _slurm_rpc_allocate_resources: Invalid account or account/partition combination specified 
[2022-10-06T13:17:04.675] error: User 548300548 not found
[2022-10-06T13:17:04.675] _job_create: invalid account or partition for user 548300548, account '(null)', and partition 'gpu-k10'
[2022-10-06T13:17:04.675] _slurm_rpc_allocate_resources: Invalid account or account/partition combination specified 
[2022-10-06T13:17:07.495] error: User 548300548 not found
[2022-10-06T13:17:07.495] _job_create: invalid account or partition for user 548300548, account '(null)', and partition 'gpu-k40c'
[2022-10-06T13:17:07.495] _slurm_rpc_allocate_resources: Invalid account or account/partition combination specified 
[2022-10-06T13:26:43.491] error: User 548300548 not found
[2022-10-06T13:26:43.491] _job_create: invalid account or partition for user 548300548, account '(null)', and partition 'gpu-k40c'
[2022-10-06T13:26:43.491] _slurm_rpc_allocate_resources: Invalid account or account/partition combination specified 
[2022-10-06T13:26:49.912] error: User 548300548 not found
[2022-10-06T13:26:49.912] _job_create: invalid account or partition for user 548300548, account '(null)', and partition 'cpu-opteron'
[2022-10-06T13:26:49.912] _slurm_rpc_allocate_resources: Invalid account or account/partition combination specified 
[2022-10-06T13:28:48.126] error: User 548300548 not found
[2022-10-06T13:28:48.126] _job_create: invalid account or partition for user 548300548, account '(null)', and partition 'gpu-k40c'
[2022-10-06T13:28:48.126] _slurm_rpc_allocate_resources: Invalid account or account/partition combination specified 
[2022-10-06T13:29:03.733] error: User 548300548 not found
[2022-10-06T13:29:03.733] _job_create: invalid account or partition for user 548300548, account '(null)', and partition 'cpu-opteron'
[2022-10-06T13:29:03.733] _slurm_rpc_allocate_resources: Invalid account or account/partition combination specified 
[2022-10-06T13:29:20.571] error: User 548300548 not found
[2022-10-06T13:29:20.571] _job_create: invalid account or partition for user 548300548, account '(null)', and partition 'gpu-k10'
[2022-10-06T13:29:20.571] _slurm_rpc_allocate_resources: Invalid account or account/partition combination specified 
[2022-10-06T13:29:48.890] error: User 548300548 not found
[2022-10-06T13:29:48.890] _job_create: invalid account or partition for user 548300548, account '(null)', and partition 'cpu-opteron'
[2022-10-06T13:29:48.890] _slurm_rpc_allocate_resources: Invalid account or account/partition combination specified 
[2022-10-06T13:54:42.950] _slurm_rpc_submit_batch_job: JobId=50208 InitPrio=1255 usec=417
[2022-10-06T13:54:43.032] sched: Allocate JobId=50208 NodeList=cpu01 #CPUs=16 Partition=cpu-opteron
[2022-10-06T13:56:39.945] _job_complete: JobId=50208 WEXITSTATUS 0
[2022-10-06T13:56:39.945] _job_complete: JobId=50208 done
[2022-10-06T14:46:20.379] _slurm_rpc_kill_job: REQUEST_KILL_JOB JobId=50049 uid 548200021
[2022-10-06T14:46:24.457] sched: Allocate JobId=50050 NodeList=gpu05 #CPUs=32 Partition=gpu-v100s
[2022-10-06T14:46:37.290] error: User 548300548 not found
[2022-10-06T14:46:37.290] _job_create: invalid account or partition for user 548300548, account '(null)', and partition 'cpu-opteron'
[2022-10-06T14:46:37.290] _slurm_rpc_allocate_resources: Invalid account or account/partition combination specified 
[2022-10-06T14:46:48.445] _slurm_rpc_submit_batch_job: JobId=50209 InitPrio=418 usec=511
[2022-10-06T14:49:49.997] error: User 548300548 not found
[2022-10-06T14:49:49.997] _job_create: invalid account or partition for user 548300548, account '(null)', and partition 'gpu-k10'
[2022-10-06T14:49:49.997] _slurm_rpc_submit_batch_job: Invalid account or account/partition combination specified
[2022-10-06T14:50:37.544] error: User 548300548 not found
[2022-10-06T14:50:37.544] _job_create: invalid account or partition for user 548300548, account '(null)', and partition 'gpu-k10'
[2022-10-06T14:50:37.544] _slurm_rpc_submit_batch_job: Invalid account or account/partition combination specified
[2022-10-06T14:52:18.275] error: User 548300548 not found
[2022-10-06T14:52:18.275] _job_create: invalid account or partition for user 548300548, account '(null)', and partition 'gpu-k10'
[2022-10-06T14:52:18.275] _slurm_rpc_submit_batch_job: Invalid account or account/partition combination specified
[2022-10-06T14:57:20.301] _slurm_rpc_submit_batch_job: JobId=50210 InitPrio=836 usec=417
[2022-10-06T14:57:20.444] sched: Allocate JobId=50210 NodeList=cpu01 #CPUs=32 Partition=cpu-opteron
[2022-10-06T14:58:26.964] _slurm_rpc_submit_batch_job: JobId=50211 InitPrio=836 usec=470
[2022-10-06T14:58:28.519] sched: Allocate JobId=50211 NodeList=cpu11 #CPUs=32 Partition=cpu-opteron
[2022-10-06T14:58:58.203] _slurm_rpc_submit_batch_job: JobId=50212 InitPrio=836 usec=369
[2022-10-06T14:58:58.561] sched: Allocate JobId=50212 NodeList=cpu04 #CPUs=32 Partition=cpu-opteron
[2022-10-06T14:59:12.000] _job_complete: JobId=50210 WEXITSTATUS 0
[2022-10-06T14:59:12.001] _job_complete: JobId=50210 done
[2022-10-06T15:00:10.145] _job_complete: JobId=50204 WEXITSTATUS 1
[2022-10-06T15:00:10.145] _job_complete: JobId=50204 done
[2022-10-06T15:00:13.338] _job_complete: JobId=50211 WEXITSTATUS 0
[2022-10-06T15:00:13.338] _job_complete: JobId=50211 done
[2022-10-06T15:00:44.529] _job_complete: JobId=50212 WEXITSTATUS 0
[2022-10-06T15:00:44.529] _job_complete: JobId=50212 done
[2022-10-06T15:01:26.042] _slurm_rpc_submit_batch_job: JobId=50213 InitPrio=418 usec=464
[2022-10-06T15:08:20.670] error: User 548300548 not found
[2022-10-06T15:08:20.670] _job_create: invalid account or partition for user 548300548, account '(null)', and partition 'gpu-k10'
[2022-10-06T15:08:20.670] _slurm_rpc_submit_batch_job: Invalid account or account/partition combination specified
[2022-10-06T15:09:47.331] error: User 548300548 not found
[2022-10-06T15:09:47.331] _job_create: invalid account or partition for user 548300548, account '(null)', and partition 'gpu-k10'
[2022-10-06T15:09:47.331] _slurm_rpc_submit_batch_job: Invalid account or account/partition combination specified
[2022-10-06T15:11:37.810] error: User 548300548 not found
[2022-10-06T15:11:37.810] _job_create: invalid account or partition for user 548300548, account '(null)', and partition 'gpu-k10'
[2022-10-06T15:11:37.810] _slurm_rpc_submit_batch_job: Invalid account or account/partition combination specified
[2022-10-06T15:22:35.138] _slurm_rpc_submit_batch_job: JobId=50214 InitPrio=418 usec=464
[2022-10-06T15:22:43.772] _slurm_rpc_kill_job: REQUEST_KILL_JOB JobId=50050 uid 548200021
[2022-10-06T15:22:47.858] sched: Allocate JobId=50053 NodeList=gpu05 #CPUs=32 Partition=gpu-v100s
[2022-10-06T15:22:50.734] _job_complete: JobId=50053 WEXITSTATUS 1
[2022-10-06T15:22:50.735] _job_complete: JobId=50053 done
[2022-10-06T15:22:51.206] sched: Allocate JobId=50180 NodeList=gpu05 #CPUs=8 Partition=gpu-v100s
[2022-10-06T15:22:51.225] sched: Allocate JobId=50187 NodeList=gpu05 #CPUs=8 Partition=gpu-v100s
[2022-10-06T15:23:19.212] _slurm_rpc_kill_job: REQUEST_KILL_JOB JobId=50214 uid 548200021
[2022-10-06T15:25:06.630] No nodes satisfy requirements for JobId=50215 in partition gpu-k10
[2022-10-06T15:25:06.630] _slurm_rpc_submit_batch_job: Requested node configuration is not available
[2022-10-06T15:26:00.534] _slurm_rpc_submit_batch_job: JobId=50216 InitPrio=418 usec=518
[2022-10-06T15:26:01.357] sched: Allocate JobId=50216 NodeList=gpu01 #CPUs=16 Partition=gpu-k10
[2022-10-06T15:34:07.471] _slurm_rpc_submit_batch_job: JobId=50217 InitPrio=1255 usec=364
[2022-10-06T15:34:08.182] sched: Allocate JobId=50217 NodeList=cpu01 #CPUs=16 Partition=cpu-opteron
[2022-10-06T15:34:57.622] _job_complete: JobId=50217 WEXITSTATUS 0
[2022-10-06T15:34:57.623] _job_complete: JobId=50217 done
[2022-10-06T15:37:31.682] _slurm_rpc_submit_batch_job: JobId=50218 InitPrio=1255 usec=1076
[2022-10-06T15:37:32.516] sched: Allocate JobId=50218 NodeList=gpu03 #CPUs=16 Partition=gpu-k10
[2022-10-06T15:51:24.475] _job_complete: JobId=50180 WEXITSTATUS 1
[2022-10-06T15:51:24.476] _job_complete: JobId=50180 done
[2022-10-06T15:51:25.572] sched: Allocate JobId=50209 NodeList=gpu05 #CPUs=16 Partition=gpu-v100s
[2022-10-06T15:51:46.594] _job_complete: JobId=50209 WEXITSTATUS 1
[2022-10-06T15:51:46.594] _job_complete: JobId=50209 done
[2022-10-06T15:51:47.222] sched: Allocate JobId=50213 NodeList=gpu05 #CPUs=16 Partition=gpu-v100s
[2022-10-06T15:52:03.584] _job_complete: JobId=50213 WEXITSTATUS 1
[2022-10-06T15:52:03.584] _job_complete: JobId=50213 done
[2022-10-06T15:59:36.022] _slurm_rpc_submit_batch_job: JobId=50219 InitPrio=418 usec=518
[2022-10-06T15:59:55.669] _slurm_rpc_kill_job: REQUEST_KILL_JOB JobId=50216 uid 548200021
[2022-10-06T16:00:03.509] sched: Allocate JobId=50219 NodeList=gpu01 #CPUs=16 Partition=gpu-k10
[2022-10-06T16:01:27.947] _slurm_rpc_submit_batch_job: JobId=50220 InitPrio=418 usec=466
[2022-10-06T16:01:28.056] sched: Allocate JobId=50220 NodeList=gpu05 #CPUs=8 Partition=gpu-v100s
[2022-10-06T16:04:07.523] _slurm_rpc_submit_batch_job: JobId=50221 InitPrio=1255 usec=395
[2022-10-06T16:04:08.276] sched: Allocate JobId=50221 NodeList=cpu01 #CPUs=16 Partition=cpu-opteron
[2022-10-06T16:06:04.922] _slurm_rpc_kill_job: REQUEST_KILL_JOB JobId=50220 uid 548200021
[2022-10-06T16:06:08.787] _job_complete: JobId=50221 WEXITSTATUS 0
[2022-10-06T16:06:08.788] _job_complete: JobId=50221 done
[2022-10-06T16:06:55.301] _slurm_rpc_submit_batch_job: JobId=50222 InitPrio=1255 usec=421
[2022-10-06T16:06:55.599] sched: Allocate JobId=50222 NodeList=cpu01 #CPUs=32 Partition=cpu-opteron
[2022-10-06T16:07:08.030] _job_complete: JobId=50222 WEXITSTATUS 0
[2022-10-06T16:07:08.031] _job_complete: JobId=50222 done
[2022-10-06T16:18:22.356] _slurm_rpc_submit_batch_job: JobId=50223 InitPrio=2092 usec=441
[2022-10-06T16:19:03.172] _slurm_rpc_kill_job: REQUEST_KILL_JOB JobId=50223 uid 548300564
[2022-10-06T16:19:39.903] _slurm_rpc_submit_batch_job: JobId=50224 InitPrio=2092 usec=526
[2022-10-06T16:19:40.810] sched: Allocate JobId=50224 NodeList=gpu05 #CPUs=8 Partition=gpu-v100s
[2022-10-06T16:47:22.488] error: This association 222(account='free', user='fairus', partition='(null)') does not have access to qos normal
[2022-10-06T16:47:22.488] _slurm_rpc_submit_batch_job: Invalid qos specification
[2022-10-06T16:47:25.717] _slurm_rpc_submit_batch_job: JobId=50225 InitPrio=1464 usec=407
[2022-10-06T17:30:43.488] _job_complete: JobId=50207 WEXITSTATUS 2
[2022-10-06T17:30:43.488] _job_complete: JobId=50207 done
[2022-10-06T17:38:15.445] sched: _slurm_rpc_allocate_resources JobId=50226 NodeList=(null) usec=811
[2022-10-06T17:38:28.343] _job_complete: JobId=50226 WTERMSIG 126
[2022-10-06T17:38:28.344] _job_complete: JobId=50226 cancelled by interactive user
[2022-10-06T17:38:28.344] _job_complete: JobId=50226 done
[2022-10-06T17:46:11.703] _slurm_rpc_submit_batch_job: JobId=50227 InitPrio=836 usec=454
[2022-10-06T17:46:12.372] sched: Allocate JobId=50227 NodeList=cpu01 #CPUs=32 Partition=cpu-opteron
[2022-10-06T17:53:03.701] _slurm_rpc_submit_batch_job: JobId=50228 InitPrio=2092 usec=463
[2022-10-06T18:14:43.970] _slurm_rpc_submit_batch_job: JobId=50229 InitPrio=7322 usec=381
[2022-10-06T18:14:58.956] _slurm_rpc_submit_batch_job: JobId=50230 InitPrio=7322 usec=423
[2022-10-06T18:34:27.251] _job_complete: JobId=50219 WEXITSTATUS 1
[2022-10-06T18:34:27.251] _job_complete: JobId=50219 done
[2022-10-06T18:44:03.497] _job_complete: JobId=50227 WEXITSTATUS 0
[2022-10-06T18:44:03.497] _job_complete: JobId=50227 done
[2022-10-06T19:21:58.307] error: User 548300548 not found
[2022-10-06T19:21:58.307] _job_create: invalid account or partition for user 548300548, account '(null)', and partition 'gpu-k10'
[2022-10-06T19:21:58.307] _slurm_rpc_submit_batch_job: Invalid account or account/partition combination specified
[2022-10-06T19:22:06.965] error: User 548300548 not found
[2022-10-06T19:22:06.965] _job_create: invalid account or partition for user 548300548, account '(null)', and partition 'gpu-k10'
[2022-10-06T19:22:06.965] _slurm_rpc_submit_batch_job: Invalid account or account/partition combination specified
[2022-10-06T19:22:38.056] _slurm_rpc_kill_job: REQUEST_KILL_JOB JobId=50224 uid 548300564
[2022-10-06T19:22:40.198] sched: Allocate JobId=50228 NodeList=gpu05 #CPUs=8 Partition=gpu-v100s
[2022-10-06T19:23:30.190] _job_complete: JobId=50228 WEXITSTATUS 1
[2022-10-06T19:23:30.191] _job_complete: JobId=50228 done
[2022-10-06T19:23:30.849] sched: Allocate JobId=50225 NodeList=gpu05 #CPUs=8 Partition=gpu-v100s
[2022-10-06T19:23:38.247] _job_complete: JobId=50225 WEXITSTATUS 1
[2022-10-06T19:23:38.247] _job_complete: JobId=50225 done
[2022-10-06T19:24:15.691] _slurm_rpc_submit_batch_job: JobId=50231 InitPrio=2092 usec=535
[2022-10-06T19:24:15.911] sched: Allocate JobId=50231 NodeList=gpu05 #CPUs=8 Partition=gpu-v100s
[2022-10-06T19:27:04.913] error: User 548300548 not found
[2022-10-06T19:27:04.913] _job_create: invalid account or partition for user 548300548, account '(null)', and partition 'gpu-k10'
[2022-10-06T19:27:04.913] _slurm_rpc_allocate_resources: Invalid account or account/partition combination specified 
[2022-10-06T19:27:51.109] error: User 548300548 not found
[2022-10-06T19:27:51.109] _job_create: invalid account or partition for user 548300548, account '(null)', and partition 'cpu-opteron'
[2022-10-06T19:27:51.109] _slurm_rpc_allocate_resources: Invalid account or account/partition combination specified 
[2022-10-06T19:29:46.027] _slurm_rpc_submit_batch_job: JobId=50232 InitPrio=2092 usec=472
[2022-10-06T19:30:10.960] _job_complete: JobId=50231 WEXITSTATUS 1
[2022-10-06T19:30:10.960] _job_complete: JobId=50231 done
[2022-10-06T19:30:11.447] sched: Allocate JobId=50232 NodeList=gpu05 #CPUs=8 Partition=gpu-v100s
[2022-10-06T19:30:40.028] _job_complete: JobId=50232 WEXITSTATUS 1
[2022-10-06T19:30:40.029] _job_complete: JobId=50232 done
[2022-10-06T19:30:49.654] _slurm_rpc_submit_batch_job: JobId=50233 InitPrio=2092 usec=420
[2022-10-06T19:30:50.524] sched: Allocate JobId=50233 NodeList=gpu05 #CPUs=8 Partition=gpu-v100s
[2022-10-06T19:31:12.154] error: User 548300548 not found
[2022-10-06T19:31:12.154] _job_create: invalid account or partition for user 548300548, account '(null)', and partition 'gpu-k10'
[2022-10-06T19:31:12.154] _slurm_rpc_submit_batch_job: Invalid account or account/partition combination specified
[2022-10-06T19:31:26.612] _job_complete: JobId=50233 WEXITSTATUS 1
[2022-10-06T19:31:26.613] _job_complete: JobId=50233 done
[2022-10-06T19:31:29.279] _slurm_rpc_submit_batch_job: JobId=50234 InitPrio=2092 usec=510
[2022-10-06T19:31:29.717] sched: Allocate JobId=50234 NodeList=gpu05 #CPUs=8 Partition=gpu-v100s
[2022-10-06T19:32:44.139] error: User 548300548 not found
[2022-10-06T19:32:44.139] _job_create: invalid account or partition for user 548300548, account '(null)', and partition 'gpu-k10'
[2022-10-06T19:32:44.139] _slurm_rpc_submit_batch_job: Invalid account or account/partition combination specified
[2022-10-06T19:37:06.025] error: User 548300548 not found
[2022-10-06T19:37:06.025] _job_create: invalid account or partition for user 548300548, account '(null)', and partition 'gpu-k10'
[2022-10-06T19:37:06.025] _slurm_rpc_submit_batch_job: Invalid account or account/partition combination specified
[2022-10-06T19:38:32.001] error: User 548300548 not found
[2022-10-06T19:38:32.001] _job_create: invalid account or partition for user 548300548, account '(null)', and partition 'gpu-k10'
[2022-10-06T19:38:32.001] _slurm_rpc_submit_batch_job: Invalid account or account/partition combination specified
[2022-10-06T19:38:55.965] error: User 548300548 not found
[2022-10-06T19:38:55.965] _job_create: invalid account or partition for user 548300548, account '(null)', and partition 'gpu-k10'
[2022-10-06T19:38:55.965] _slurm_rpc_submit_batch_job: Invalid account or account/partition combination specified
[2022-10-06T19:39:39.252] error: User 548300548 not found
[2022-10-06T19:39:39.252] _job_create: invalid account or partition for user 548300548, account '(null)', and partition 'gpu-k10'
[2022-10-06T19:39:39.252] _slurm_rpc_submit_batch_job: Invalid account or account/partition combination specified
[2022-10-06T19:43:00.866] _job_complete: JobId=50234 WEXITSTATUS 0
[2022-10-06T19:43:00.866] _job_complete: JobId=50234 done
[2022-10-06T20:00:39.535] _slurm_rpc_submit_batch_job: JobId=50235 InitPrio=2092 usec=474
[2022-10-06T20:00:39.854] sched: Allocate JobId=50235 NodeList=gpu05 #CPUs=8 Partition=gpu-v100s
[2022-10-06T20:01:15.881] _job_complete: JobId=50206 WEXITSTATUS 1
[2022-10-06T20:01:15.885] _job_complete: JobId=50206 done
[2022-10-06T21:12:59.658] error: User 548300548 not found
[2022-10-06T21:12:59.658] _job_create: invalid account or partition for user 548300548, account '(null)', and partition 'gpu-k10'
[2022-10-06T21:12:59.658] _slurm_rpc_submit_batch_job: Invalid account or account/partition combination specified
[2022-10-06T21:13:25.795] error: User 548300548 not found
[2022-10-06T21:13:25.795] _job_create: invalid account or partition for user 548300548, account '(null)', and partition 'gpu-k10'
[2022-10-06T21:13:25.795] _slurm_rpc_submit_batch_job: Invalid account or account/partition combination specified
[2022-10-06T21:13:32.169] error: User 548300548 not found
[2022-10-06T21:13:32.170] _job_create: invalid account or partition for user 548300548, account '(null)', and partition 'gpu-k10'
[2022-10-06T21:13:32.170] _slurm_rpc_submit_batch_job: Invalid account or account/partition combination specified
[2022-10-06T21:16:15.061] error: User 548300548 not found
[2022-10-06T21:16:15.061] _job_create: invalid account or partition for user 548300548, account '(null)', and partition 'gpu-k10'
[2022-10-06T21:16:15.061] _slurm_rpc_submit_batch_job: Invalid account or account/partition combination specified
[2022-10-06T21:17:23.539] error: User 548300548 not found
[2022-10-06T21:17:23.539] _job_create: invalid account or partition for user 548300548, account '(null)', and partition 'gpu-k10'
[2022-10-06T21:17:23.539] _slurm_rpc_submit_batch_job: Invalid account or account/partition combination specified
[2022-10-06T21:18:21.580] error: User 548300548 not found
[2022-10-06T21:18:21.580] _job_create: invalid account or partition for user 548300548, account '(null)', and partition 'gpu-k10'
[2022-10-06T21:18:21.580] _slurm_rpc_submit_batch_job: Invalid account or account/partition combination specified
[2022-10-06T21:58:23.928] _slurm_rpc_submit_batch_job: JobId=50236 InitPrio=1255 usec=502
[2022-10-06T21:58:24.601] sched: Allocate JobId=50236 NodeList=cpu01 #CPUs=8 Partition=cpu-opteron
[2022-10-06T21:58:28.480] _job_complete: JobId=50236 WEXITSTATUS 1
[2022-10-06T21:58:28.481] _job_complete: JobId=50236 done
[2022-10-06T22:01:26.046] _job_complete: JobId=50218 WEXITSTATUS 1
[2022-10-06T22:01:26.047] _job_complete: JobId=50218 done
[2022-10-06T22:04:37.032] _slurm_rpc_submit_batch_job: JobId=50237 InitPrio=1255 usec=416
[2022-10-06T22:04:37.170] sched: Allocate JobId=50237 NodeList=cpu01 #CPUs=8 Partition=cpu-opteron
[2022-10-06T22:04:39.364] _job_complete: JobId=50237 WEXITSTATUS 1
[2022-10-06T22:04:39.364] _job_complete: JobId=50237 done
[2022-10-06T22:12:08.644] _slurm_rpc_submit_batch_job: JobId=50238 InitPrio=1255 usec=388
[2022-10-06T22:12:08.957] sched: Allocate JobId=50238 NodeList=cpu01 #CPUs=8 Partition=cpu-opteron
[2022-10-06T22:12:12.330] _job_complete: JobId=50238 WEXITSTATUS 1
[2022-10-06T22:12:12.331] _job_complete: JobId=50238 done
[2022-10-06T22:18:49.636] Time limit exhausted for JobId=49835
[2022-10-06T22:18:52.802] sched: Allocate JobId=50124 NodeList=gpu04 #CPUs=16 Partition=gpu-k40c
[2022-10-06T22:19:27.600] _slurm_rpc_submit_batch_job: JobId=50239 InitPrio=2510 usec=465
[2022-10-06T22:19:28.703] sched: Allocate JobId=50239 NodeList=cpu01 #CPUs=4 Partition=cpu-opteron
[2022-10-06T22:41:01.500] _job_complete: JobId=50239 WEXITSTATUS 1
[2022-10-06T22:41:01.500] _job_complete: JobId=50239 done
[2022-10-06T23:26:19.615] _slurm_rpc_submit_batch_job: JobId=50240 InitPrio=627 usec=580
[2022-10-06T23:26:19.838] sched: Allocate JobId=50240 NodeList=cpu03 #CPUs=64 Partition=cpu-opteron
[2022-10-07T02:06:42.000] _job_complete: JobId=50240 WEXITSTATUS 0
[2022-10-07T02:06:42.000] _job_complete: JobId=50240 done
[2022-10-07T02:41:55.077] _slurm_rpc_submit_batch_job: JobId=50241 InitPrio=2510 usec=597
[2022-10-07T02:41:56.020] sched: Allocate JobId=50241 NodeList=cpu01 #CPUs=4 Partition=cpu-opteron
[2022-10-07T03:03:28.797] _slurm_rpc_submit_batch_job: JobId=50242 InitPrio=15439 usec=460
[2022-10-07T03:03:31.734] _slurm_rpc_submit_batch_job: JobId=50243 InitPrio=15439 usec=392
[2022-10-07T03:03:34.240] _slurm_rpc_submit_batch_job: JobId=50244 InitPrio=15439 usec=425
[2022-10-07T03:03:37.021] _slurm_rpc_submit_batch_job: JobId=50245 InitPrio=15439 usec=519
[2022-10-07T03:03:41.158] _slurm_rpc_submit_batch_job: JobId=50246 InitPrio=15439 usec=503
[2022-10-07T07:23:30.819] _job_complete: JobId=50068 WEXITSTATUS 0
[2022-10-07T07:23:30.820] _job_complete: JobId=50068 done
[2022-10-07T09:53:20.083] _job_complete: JobId=50235 WEXITSTATUS 0
[2022-10-07T09:53:20.089] _job_complete: JobId=50235 done
[2022-10-07T09:53:22.238] sched: Allocate JobId=50242 NodeList=gpu05 #CPUs=8 Partition=gpu-v100s
[2022-10-07T09:53:47.042] _job_complete: JobId=50242 WEXITSTATUS 1
[2022-10-07T09:53:47.042] _job_complete: JobId=50242 done
[2022-10-07T09:53:47.721] sched: Allocate JobId=50243 NodeList=gpu05 #CPUs=8 Partition=gpu-v100s
[2022-10-07T09:54:08.313] _job_complete: JobId=50243 WEXITSTATUS 1
[2022-10-07T09:54:08.314] _job_complete: JobId=50243 done
[2022-10-07T09:54:08.820] sched: Allocate JobId=50244 NodeList=gpu05 #CPUs=8 Partition=gpu-v100s
[2022-10-07T09:54:28.955] _job_complete: JobId=50244 WEXITSTATUS 1
[2022-10-07T09:54:28.956] _job_complete: JobId=50244 done
[2022-10-07T09:54:29.530] sched: Allocate JobId=50245 NodeList=gpu05 #CPUs=8 Partition=gpu-v100s
[2022-10-07T09:54:50.347] _job_complete: JobId=50245 WEXITSTATUS 1
[2022-10-07T09:54:50.348] _job_complete: JobId=50245 done
[2022-10-07T09:54:50.848] sched: Allocate JobId=50246 NodeList=gpu05 #CPUs=8 Partition=gpu-v100s
[2022-10-07T09:55:10.859] _job_complete: JobId=50246 WEXITSTATUS 1
[2022-10-07T09:55:10.860] _job_complete: JobId=50246 done
[2022-10-07T10:11:54.425] _slurm_rpc_submit_batch_job: JobId=50247 InitPrio=15020 usec=583
[2022-10-07T10:11:54.436] _slurm_rpc_submit_batch_job: JobId=50248 InitPrio=15020 usec=706
[2022-10-07T10:11:54.447] _slurm_rpc_submit_batch_job: JobId=50249 InitPrio=15020 usec=518
[2022-10-07T10:11:54.457] _slurm_rpc_submit_batch_job: JobId=50250 InitPrio=15020 usec=387
[2022-10-07T10:11:54.467] _slurm_rpc_submit_batch_job: JobId=50251 InitPrio=15020 usec=332
[2022-10-07T10:11:54.478] _slurm_rpc_submit_batch_job: JobId=50252 InitPrio=15020 usec=332
[2022-10-07T10:11:54.487] _slurm_rpc_submit_batch_job: JobId=50253 InitPrio=15020 usec=342
[2022-10-07T10:11:54.497] _slurm_rpc_submit_batch_job: JobId=50254 InitPrio=15020 usec=367
[2022-10-07T10:11:54.507] _slurm_rpc_submit_batch_job: JobId=50255 InitPrio=15020 usec=396
[2022-10-07T10:11:54.517] _slurm_rpc_submit_batch_job: JobId=50256 InitPrio=15020 usec=353
[2022-10-07T10:11:55.422] sched: Allocate JobId=50247 NodeList=cpu01 #CPUs=8 Partition=cpu-opteron
[2022-10-07T10:11:55.423] sched: Allocate JobId=50248 NodeList=cpu01 #CPUs=8 Partition=cpu-opteron
[2022-10-07T10:11:55.424] sched: Allocate JobId=50249 NodeList=cpu01 #CPUs=8 Partition=cpu-opteron
[2022-10-07T10:11:55.424] sched: Allocate JobId=50250 NodeList=cpu01 #CPUs=8 Partition=cpu-opteron
[2022-10-07T10:11:55.425] sched: Allocate JobId=50251 NodeList=cpu01 #CPUs=8 Partition=cpu-opteron
[2022-10-07T10:11:55.426] sched: Allocate JobId=50252 NodeList=cpu03 #CPUs=8 Partition=cpu-opteron
[2022-10-07T10:11:55.426] sched: Allocate JobId=50253 NodeList=cpu03 #CPUs=8 Partition=cpu-opteron
[2022-10-07T10:11:55.427] sched: Allocate JobId=50254 NodeList=cpu03 #CPUs=8 Partition=cpu-opteron
[2022-10-07T10:11:55.427] sched: Allocate JobId=50255 NodeList=cpu03 #CPUs=8 Partition=cpu-opteron
[2022-10-07T10:11:55.428] sched: Allocate JobId=50256 NodeList=cpu03 #CPUs=8 Partition=cpu-opteron
[2022-10-07T10:12:55.771] _slurm_rpc_submit_batch_job: JobId=50257 InitPrio=1255 usec=447
[2022-10-07T10:12:56.505] sched: Allocate JobId=50257 NodeList=gpu05 #CPUs=8 Partition=gpu-v100s
[2022-10-07T10:13:01.919] _job_complete: JobId=50257 WEXITSTATUS 1
[2022-10-07T10:13:01.919] _job_complete: JobId=50257 done
[2022-10-07T10:17:12.205] _slurm_rpc_submit_batch_job: JobId=50258 InitPrio=1255 usec=420
[2022-10-07T10:17:12.941] sched: Allocate JobId=50258 NodeList=gpu05 #CPUs=8 Partition=gpu-v100s
[2022-10-07T10:17:15.398] _job_complete: JobId=50258 WEXITSTATUS 1
[2022-10-07T10:17:15.399] _job_complete: JobId=50258 done
[2022-10-07T10:17:19.905] _slurm_rpc_kill_job: REQUEST_KILL_JOB JobId=50256 uid 548300543
[2022-10-07T10:17:45.900] _slurm_rpc_submit_batch_job: JobId=50259 InitPrio=1255 usec=616
[2022-10-07T10:17:45.984] sched: Allocate JobId=50259 NodeList=gpu05 #CPUs=8 Partition=gpu-v100s
[2022-10-07T10:17:48.326] _job_complete: JobId=50259 WEXITSTATUS 1
[2022-10-07T10:17:48.326] _job_complete: JobId=50259 done
[2022-10-07T10:18:48.607] _slurm_rpc_submit_batch_job: JobId=50260 InitPrio=1255 usec=414
[2022-10-07T10:18:49.069] sched: Allocate JobId=50260 NodeList=gpu05 #CPUs=8 Partition=gpu-v100s
[2022-10-07T10:19:23.293] _slurm_rpc_submit_batch_job: JobId=50261 InitPrio=15020 usec=408
[2022-10-07T10:19:24.114] sched: Allocate JobId=50261 NodeList=cpu03 #CPUs=8 Partition=cpu-opteron
[2022-10-07T10:24:36.499] _slurm_rpc_submit_batch_job: JobId=50262 InitPrio=15020 usec=450
[2022-10-07T10:24:36.616] sched: Allocate JobId=50262 NodeList=cpu01 #CPUs=4 Partition=cpu-opteron
[2022-10-07T10:24:40.944] _job_complete: JobId=50262 WEXITSTATUS 0
[2022-10-07T10:24:40.944] _job_complete: JobId=50262 done
[2022-10-07T10:25:46.672] _slurm_rpc_kill_job: REQUEST_KILL_JOB JobId=50260 uid 548300547
[2022-10-07T10:25:53.009] _slurm_rpc_submit_batch_job: JobId=50263 InitPrio=1255 usec=518
[2022-10-07T10:25:53.720] sched: Allocate JobId=50263 NodeList=gpu05 #CPUs=8 Partition=gpu-v100s
[2022-10-07T10:28:25.662] _slurm_rpc_kill_job: REQUEST_KILL_JOB JobId=50263 uid 548300547
[2022-10-07T10:28:31.654] _slurm_rpc_submit_batch_job: JobId=50264 InitPrio=1255 usec=528
[2022-10-07T10:28:32.023] sched: Allocate JobId=50264 NodeList=gpu05 #CPUs=8 Partition=gpu-v100s
[2022-10-07T10:38:11.870] _slurm_rpc_submit_batch_job: JobId=50265 InitPrio=627 usec=587
[2022-10-07T10:38:12.060] sched: Allocate JobId=50265 NodeList=cpu04 #CPUs=64 Partition=cpu-opteron
[2022-10-07T10:45:59.213] _slurm_rpc_kill_job: REQUEST_KILL_JOB JobId=50265 uid 548200019
[2022-10-07T10:46:08.258] _slurm_rpc_submit_batch_job: JobId=50266 InitPrio=627 usec=478
[2022-10-07T10:46:09.064] sched: Allocate JobId=50266 NodeList=cpu04 #CPUs=64 Partition=cpu-opteron
[2022-10-07T10:48:14.256] _slurm_rpc_submit_batch_job: JobId=50267 InitPrio=418 usec=606
[2022-10-07T10:48:15.249] sched: Allocate JobId=50267 NodeList=gpu01 #CPUs=16 Partition=gpu-k10
[2022-10-07T10:49:08.917] _slurm_rpc_submit_batch_job: JobId=50268 InitPrio=15439 usec=398
[2022-10-07T10:49:14.372] _slurm_rpc_submit_batch_job: JobId=50269 InitPrio=15439 usec=440
[2022-10-07T10:49:16.855] _slurm_rpc_submit_batch_job: JobId=50270 InitPrio=15439 usec=429
[2022-10-07T10:49:19.070] _slurm_rpc_submit_batch_job: JobId=50271 InitPrio=15439 usec=516
[2022-10-07T10:49:21.945] _slurm_rpc_submit_batch_job: JobId=50272 InitPrio=15439 usec=440
[2022-10-07T10:55:35.907] error: User 548300548 not found
[2022-10-07T10:55:35.907] _job_create: invalid account or partition for user 548300548, account '(null)', and partition 'gpu-k10'
[2022-10-07T10:55:35.907] _slurm_rpc_submit_batch_job: Invalid account or account/partition combination specified
[2022-10-07T10:55:46.122] error: User 548300548 not found
[2022-10-07T10:55:46.122] _job_create: invalid account or partition for user 548300548, account '(null)', and partition 'gpu-k10'
[2022-10-07T10:55:46.123] _slurm_rpc_submit_batch_job: Invalid account or account/partition combination specified
[2022-10-07T10:58:55.207] _slurm_rpc_kill_job: REQUEST_KILL_JOB JobId=50264 uid 548300547
[2022-10-07T10:58:57.335] sched: Allocate JobId=50268 NodeList=gpu05 #CPUs=8 Partition=gpu-v100s
[2022-10-07T11:02:14.972] _slurm_rpc_submit_batch_job: JobId=50273 InitPrio=1250 usec=426
[2022-10-07T11:07:47.228] error: User 548300548 not found
[2022-10-07T11:07:47.228] _job_create: invalid account or partition for user 548300548, account '(null)', and partition 'cpu-opteron'
[2022-10-07T11:07:47.228] _slurm_rpc_allocate_resources: Invalid account or account/partition combination specified 
[2022-10-07T11:12:22.758] Time limit exhausted for JobId=50247
[2022-10-07T11:12:22.758] Time limit exhausted for JobId=50248
[2022-10-07T11:12:22.758] Time limit exhausted for JobId=50249
[2022-10-07T11:12:22.758] Time limit exhausted for JobId=50250
[2022-10-07T11:12:22.758] Time limit exhausted for JobId=50251
[2022-10-07T11:12:22.759] Time limit exhausted for JobId=50252
[2022-10-07T11:12:22.759] Time limit exhausted for JobId=50253
[2022-10-07T11:12:22.759] Time limit exhausted for JobId=50254
[2022-10-07T11:12:22.759] Time limit exhausted for JobId=50255
[2022-10-07T11:13:08.979] _slurm_rpc_submit_batch_job: JobId=50274 InitPrio=10000 usec=624
[2022-10-07T11:13:09.911] sched: Allocate JobId=50274 NodeList=gpu03 #CPUs=4 Partition=gpu-k10
[2022-10-07T11:13:14.862] _job_complete: JobId=50274 WEXITSTATUS 127
[2022-10-07T11:13:14.863] _job_complete: JobId=50274 done
[2022-10-07T11:14:53.034] _slurm_rpc_kill_job: REQUEST_KILL_JOB JobId=50261 uid 548300543
[2022-10-07T11:16:19.155] _job_complete: JobId=50268 WEXITSTATUS 0
[2022-10-07T11:16:19.157] _job_complete: JobId=50268 done
[2022-10-07T11:16:19.802] sched: Allocate JobId=50269 NodeList=gpu05 #CPUs=8 Partition=gpu-v100s
[2022-10-07T11:16:52.690] _slurm_rpc_submit_batch_job: JobId=50275 InitPrio=20995 usec=583
[2022-10-07T11:16:53.220] sched: Allocate JobId=50275 NodeList=gpu03 #CPUs=4 Partition=gpu-k10
[2022-10-07T11:16:56.170] _job_complete: JobId=50275 WEXITSTATUS 127
[2022-10-07T11:16:56.170] _job_complete: JobId=50275 done
[2022-10-07T11:17:19.937] _job_complete: JobId=50266 WEXITSTATUS 0
[2022-10-07T11:17:19.937] _job_complete: JobId=50266 done
[2022-10-07T11:18:15.910] sched: _slurm_rpc_allocate_resources JobId=50276 NodeList=gpu03 usec=1067
[2022-10-07T11:18:18.624] _slurm_rpc_submit_batch_job: JobId=50277 InitPrio=622 usec=448
[2022-10-07T11:18:19.342] sched: Allocate JobId=50277 NodeList=cpu03 #CPUs=64 Partition=cpu-opteron
[2022-10-07T11:20:58.133] _job_complete: JobId=50277 WEXITSTATUS 0
[2022-10-07T11:20:58.133] _job_complete: JobId=50277 done
[2022-10-07T11:23:10.766] _slurm_rpc_submit_batch_job: JobId=50278 InitPrio=59170 usec=7344
[2022-10-07T11:23:10.940] sched: Allocate JobId=50278 NodeList=cpu01 #CPUs=4 Partition=cpu-opteron
[2022-10-07T11:23:42.401] _slurm_rpc_submit_batch_job: JobId=50279 InitPrio=15394 usec=445
[2022-10-07T11:23:47.407] _slurm_rpc_submit_batch_job: JobId=50280 InitPrio=15394 usec=464
[2022-10-07T11:23:51.141] _slurm_rpc_submit_batch_job: JobId=50281 InitPrio=15394 usec=466
[2022-10-07T11:23:53.664] _slurm_rpc_submit_batch_job: JobId=50282 InitPrio=15394 usec=416
[2022-10-07T11:23:55.997] _slurm_rpc_submit_batch_job: JobId=50283 InitPrio=15394 usec=453
[2022-10-07T11:28:44.400] _slurm_rpc_kill_job: REQUEST_KILL_JOB JobId=50278 uid 548300602
[2022-10-07T11:33:39.009] _job_complete: JobId=50269 WEXITSTATUS 0
[2022-10-07T11:33:39.009] _job_complete: JobId=50269 done
[2022-10-07T11:33:39.629] sched: Allocate JobId=50270 NodeList=gpu05 #CPUs=8 Partition=gpu-v100s
[2022-10-07T11:51:03.406] _job_complete: JobId=50270 WEXITSTATUS 0
[2022-10-07T11:51:03.407] _job_complete: JobId=50270 done
[2022-10-07T11:51:04.027] sched: Allocate JobId=50271 NodeList=gpu05 #CPUs=8 Partition=gpu-v100s
[2022-10-07T12:08:31.425] _job_complete: JobId=50271 WEXITSTATUS 0
[2022-10-07T12:08:31.426] _job_complete: JobId=50271 done
[2022-10-07T12:08:32.040] sched: Allocate JobId=50272 NodeList=gpu05 #CPUs=8 Partition=gpu-v100s
[2022-10-07T12:18:22.795] Time limit exhausted for JobId=50276
[2022-10-07T12:20:54.265] cleanup_completing: JobId=50276 completion process took 152 seconds
[2022-10-07T12:25:53.466] _job_complete: JobId=50272 WEXITSTATUS 0
[2022-10-07T12:25:53.467] _job_complete: JobId=50272 done
[2022-10-07T12:25:54.077] sched: Allocate JobId=50279 NodeList=gpu05 #CPUs=8 Partition=gpu-v100s
[2022-10-07T12:25:58.926] _job_complete: JobId=50279 WEXITSTATUS 2
[2022-10-07T12:25:58.927] _job_complete: JobId=50279 done
[2022-10-07T12:25:59.469] sched: Allocate JobId=50280 NodeList=gpu05 #CPUs=8 Partition=gpu-v100s
[2022-10-07T12:26:02.133] _job_complete: JobId=50280 WEXITSTATUS 2
[2022-10-07T12:26:02.134] _job_complete: JobId=50280 done
[2022-10-07T12:26:02.639] sched: Allocate JobId=50281 NodeList=gpu05 #CPUs=8 Partition=gpu-v100s
[2022-10-07T12:26:05.340] _job_complete: JobId=50281 WEXITSTATUS 2
[2022-10-07T12:26:05.340] _job_complete: JobId=50281 done
[2022-10-07T12:26:05.832] sched: Allocate JobId=50282 NodeList=gpu05 #CPUs=8 Partition=gpu-v100s
[2022-10-07T12:26:08.479] _job_complete: JobId=50282 WEXITSTATUS 2
[2022-10-07T12:26:08.479] _job_complete: JobId=50282 done
[2022-10-07T12:26:09.022] sched: Allocate JobId=50283 NodeList=gpu05 #CPUs=8 Partition=gpu-v100s
[2022-10-07T12:26:11.820] _job_complete: JobId=50283 WEXITSTATUS 2
[2022-10-07T12:26:11.821] _job_complete: JobId=50283 done
[2022-10-07T12:26:12.355] sched: Allocate JobId=50273 NodeList=gpu05 #CPUs=8 Partition=gpu-v100s
[2022-10-07T12:26:14.462] _job_complete: JobId=50273 WEXITSTATUS 1
[2022-10-07T12:26:14.462] _job_complete: JobId=50273 done
[2022-10-07T12:29:59.270] _slurm_rpc_submit_batch_job: JobId=50284 InitPrio=15186 usec=590
[2022-10-07T12:29:59.915] sched: Allocate JobId=50284 NodeList=gpu05 #CPUs=8 Partition=gpu-v100s
[2022-10-07T12:30:03.162] _slurm_rpc_submit_batch_job: JobId=50285 InitPrio=15186 usec=394
[2022-10-07T12:30:13.101] _slurm_rpc_submit_batch_job: JobId=50286 InitPrio=15186 usec=426
[2022-10-07T12:30:19.467] _slurm_rpc_submit_batch_job: JobId=50287 InitPrio=15186 usec=424
[2022-10-07T12:41:27.735] _job_complete: JobId=49729 WEXITSTATUS 0
[2022-10-07T12:41:27.735] _job_complete: JobId=49729 done
[2022-10-07T12:41:28.318] sched: Allocate JobId=49732 NodeList=cpu14 #CPUs=16 Partition=cpu-epyc
[2022-10-07T12:42:13.901] sched/backfill: _start_job: Started JobId=49786 in cpu-epyc on cpu14
[2022-10-07T12:45:27.753] _slurm_rpc_submit_batch_job: JobId=50288 InitPrio=15186 usec=492
[2022-10-07T12:45:29.981] _slurm_rpc_submit_batch_job: JobId=50289 InitPrio=15186 usec=400
[2022-10-07T12:45:31.718] _slurm_rpc_submit_batch_job: JobId=50290 InitPrio=15186 usec=512
[2022-10-07T12:45:33.635] _slurm_rpc_submit_batch_job: JobId=50291 InitPrio=15186 usec=413
[2022-10-07T12:45:36.893] _slurm_rpc_submit_batch_job: JobId=50292 InitPrio=15186 usec=419
[2022-10-07T12:47:15.477] _job_complete: JobId=50284 WEXITSTATUS 0
[2022-10-07T12:47:15.478] _job_complete: JobId=50284 done
[2022-10-07T12:47:16.149] sched: Allocate JobId=50285 NodeList=gpu05 #CPUs=8 Partition=gpu-v100s
[2022-10-07T13:04:31.125] _job_complete: JobId=50285 WEXITSTATUS 0
[2022-10-07T13:04:31.126] _job_complete: JobId=50285 done
[2022-10-07T13:04:31.783] sched: Allocate JobId=50286 NodeList=gpu05 #CPUs=8 Partition=gpu-v100s
[2022-10-07T13:21:48.152] _job_complete: JobId=50286 WEXITSTATUS 0
[2022-10-07T13:21:48.153] _job_complete: JobId=50286 done
[2022-10-07T13:21:48.761] sched: Allocate JobId=50287 NodeList=gpu05 #CPUs=8 Partition=gpu-v100s
[2022-10-07T13:39:02.024] _job_complete: JobId=50287 WEXITSTATUS 0
[2022-10-07T13:39:02.025] _job_complete: JobId=50287 done
[2022-10-07T13:39:02.659] sched: Allocate JobId=50288 NodeList=gpu05 #CPUs=8 Partition=gpu-v100s
[2022-10-07T13:45:55.999] _slurm_rpc_submit_batch_job: JobId=50293 InitPrio=14979 usec=487
[2022-10-07T13:45:58.052] _slurm_rpc_submit_batch_job: JobId=50294 InitPrio=14979 usec=354
[2022-10-07T13:46:00.498] _slurm_rpc_submit_batch_job: JobId=50295 InitPrio=14979 usec=479
[2022-10-07T13:46:03.011] _slurm_rpc_submit_batch_job: JobId=50296 InitPrio=14979 usec=470
[2022-10-07T13:46:05.999] _slurm_rpc_submit_batch_job: JobId=50297 InitPrio=14979 usec=430
[2022-10-07T13:56:17.092] _job_complete: JobId=50288 WEXITSTATUS 0
[2022-10-07T13:56:17.093] _job_complete: JobId=50288 done
[2022-10-07T13:56:17.729] sched: Allocate JobId=50289 NodeList=gpu05 #CPUs=8 Partition=gpu-v100s
[2022-10-07T14:13:33.933] _job_complete: JobId=50289 WEXITSTATUS 0
[2022-10-07T14:13:33.934] _job_complete: JobId=50289 done
[2022-10-07T14:13:34.620] sched: Allocate JobId=50290 NodeList=gpu05 #CPUs=8 Partition=gpu-v100s
[2022-10-07T14:30:51.230] _job_complete: JobId=50290 WEXITSTATUS 0
[2022-10-07T14:30:51.231] _job_complete: JobId=50290 done
[2022-10-07T14:30:51.840] sched: Allocate JobId=50291 NodeList=gpu05 #CPUs=8 Partition=gpu-v100s
[2022-10-07T14:40:10.250] _slurm_rpc_submit_batch_job: JobId=50298 InitPrio=829 usec=592
[2022-10-07T14:40:10.991] sched: Allocate JobId=50298 NodeList=cpu01 #CPUs=32 Partition=cpu-opteron
[2022-10-07T14:40:12.570] _job_complete: JobId=50298 WEXITSTATUS 1
[2022-10-07T14:40:12.570] _job_complete: JobId=50298 done
[2022-10-07T14:40:41.459] _slurm_rpc_submit_batch_job: JobId=50299 InitPrio=829 usec=584
[2022-10-07T14:40:42.011] sched: Allocate JobId=50299 NodeList=cpu01 #CPUs=32 Partition=cpu-opteron
[2022-10-07T14:40:42.980] _job_complete: JobId=50299 WEXITSTATUS 1
[2022-10-07T14:40:42.980] _job_complete: JobId=50299 done
[2022-10-07T14:42:04.172] _slurm_rpc_submit_batch_job: JobId=50300 InitPrio=829 usec=488
[2022-10-07T14:42:04.213] sched: Allocate JobId=50300 NodeList=cpu01 #CPUs=32 Partition=cpu-opteron
[2022-10-07T14:43:00.463] _job_complete: JobId=50300 WEXITSTATUS 0
[2022-10-07T14:43:00.463] _job_complete: JobId=50300 done
[2022-10-07T14:48:06.047] _job_complete: JobId=50291 WEXITSTATUS 0
[2022-10-07T14:48:06.048] _job_complete: JobId=50291 done
[2022-10-07T14:48:06.892] sched: Allocate JobId=50292 NodeList=gpu05 #CPUs=8 Partition=gpu-v100s
[2022-10-07T14:50:30.169] _slurm_rpc_submit_batch_job: JobId=50301 InitPrio=829 usec=485
[2022-10-07T14:50:30.990] sched: Allocate JobId=50301 NodeList=cpu01 #CPUs=32 Partition=cpu-opteron
[2022-10-07T14:50:32.015] _job_complete: JobId=50301 WEXITSTATUS 1
[2022-10-07T14:50:32.016] _job_complete: JobId=50301 done
[2022-10-07T14:55:55.813] _job_complete: JobId=49786 WEXITSTATUS 0
[2022-10-07T14:55:55.813] _job_complete: JobId=49786 done
[2022-10-07T14:59:38.657] _slurm_rpc_submit_batch_job: JobId=50302 InitPrio=829 usec=502
[2022-10-07T14:59:38.891] sched: Allocate JobId=50302 NodeList=cpu01 #CPUs=32 Partition=cpu-opteron
[2022-10-07T15:00:31.417] _job_complete: JobId=50302 WEXITSTATUS 0
[2022-10-07T15:00:31.417] _job_complete: JobId=50302 done
[2022-10-07T15:05:22.173] _job_complete: JobId=50292 WEXITSTATUS 0
[2022-10-07T15:05:22.174] _job_complete: JobId=50292 done
[2022-10-07T15:05:22.780] sched: Allocate JobId=50293 NodeList=gpu05 #CPUs=8 Partition=gpu-v100s
[2022-10-07T15:10:31.493] _slurm_rpc_submit_batch_job: JobId=50303 InitPrio=829 usec=418
[2022-10-07T15:10:31.950] sched: Allocate JobId=50303 NodeList=cpu01 #CPUs=32 Partition=cpu-opteron
[2022-10-07T15:10:45.790] _job_complete: JobId=50303 WEXITSTATUS 1
[2022-10-07T15:10:45.790] _job_complete: JobId=50303 done
[2022-10-07T15:11:47.741] _slurm_rpc_submit_batch_job: JobId=50304 InitPrio=829 usec=485
[2022-10-07T15:11:48.167] sched: Allocate JobId=50304 NodeList=cpu01 #CPUs=32 Partition=cpu-opteron
[2022-10-07T15:17:43.756] sched: _slurm_rpc_allocate_resources JobId=50305 NodeList=(null) usec=1078
[2022-10-07T15:17:44.753] sched: Allocate JobId=50305 NodeList=gpu03 #CPUs=4 Partition=gpu-k10
[2022-10-07T15:19:56.252] _slurm_rpc_submit_batch_job: JobId=50306 InitPrio=14564 usec=485
[2022-10-07T15:20:05.081] _slurm_rpc_submit_batch_job: JobId=50307 InitPrio=14564 usec=404
[2022-10-07T15:20:07.750] _slurm_rpc_submit_batch_job: JobId=50308 InitPrio=14564 usec=429
[2022-10-07T15:20:10.110] _slurm_rpc_submit_batch_job: JobId=50309 InitPrio=14564 usec=486
[2022-10-07T15:20:13.638] _slurm_rpc_submit_batch_job: JobId=50310 InitPrio=14564 usec=461
[2022-10-07T15:21:30.268] _slurm_rpc_submit_batch_job: JobId=50311 InitPrio=829 usec=451
[2022-10-07T15:21:31.175] sched: Allocate JobId=50311 NodeList=cpu03 #CPUs=32 Partition=cpu-opteron
[2022-10-07T15:22:29.290] _job_complete: JobId=50311 WEXITSTATUS 0
[2022-10-07T15:22:29.290] _job_complete: JobId=50311 done
[2022-10-07T15:22:43.875] _job_complete: JobId=50293 WEXITSTATUS 0
[2022-10-07T15:22:43.876] _job_complete: JobId=50293 done
[2022-10-07T15:22:44.844] sched: Allocate JobId=50294 NodeList=gpu05 #CPUs=8 Partition=gpu-v100s
[2022-10-07T15:23:05.493] _slurm_rpc_submit_batch_job: JobId=50312 InitPrio=1867 usec=423
[2022-10-07T15:27:32.282] _slurm_rpc_submit_batch_job: JobId=50313 InitPrio=829 usec=430
[2022-10-07T15:27:32.787] sched: Allocate JobId=50313 NodeList=cpu03 #CPUs=32 Partition=cpu-opteron
[2022-10-07T15:28:25.959] _job_complete: JobId=50313 WEXITSTATUS 0
[2022-10-07T15:28:25.960] _job_complete: JobId=50313 done
[2022-10-07T15:34:17.031] _slurm_rpc_submit_batch_job: JobId=50314 InitPrio=829 usec=724
[2022-10-07T15:34:17.444] sched: Allocate JobId=50314 NodeList=cpu03 #CPUs=32 Partition=cpu-opteron
[2022-10-07T15:34:18.264] _job_complete: JobId=50314 WEXITSTATUS 1
[2022-10-07T15:34:18.264] _job_complete: JobId=50314 done
[2022-10-07T15:35:05.711] _slurm_rpc_submit_batch_job: JobId=50315 InitPrio=829 usec=442
[2022-10-07T15:35:06.511] sched: Allocate JobId=50315 NodeList=cpu03 #CPUs=32 Partition=cpu-opteron
[2022-10-07T15:35:07.285] _job_complete: JobId=50315 WEXITSTATUS 1
[2022-10-07T15:35:07.286] _job_complete: JobId=50315 done
[2022-10-07T15:36:32.875] _slurm_rpc_submit_batch_job: JobId=50316 InitPrio=829 usec=515
[2022-10-07T15:36:32.887] sched: Allocate JobId=50316 NodeList=cpu03 #CPUs=32 Partition=cpu-opteron
[2022-10-07T15:37:28.173] _job_complete: JobId=50316 WEXITSTATUS 0
[2022-10-07T15:37:28.173] _job_complete: JobId=50316 done
[2022-10-07T15:38:23.533] _job_complete: JobId=50305 WEXITSTATUS 1
[2022-10-07T15:38:23.533] _job_complete: JobId=50305 done
[2022-10-07T15:40:08.248] _job_complete: JobId=50294 WEXITSTATUS 0
[2022-10-07T15:40:08.249] _job_complete: JobId=50294 done
[2022-10-07T15:40:08.889] sched: Allocate JobId=50295 NodeList=gpu05 #CPUs=8 Partition=gpu-v100s
[2022-10-07T15:52:11.538] _slurm_rpc_submit_batch_job: JobId=50317 InitPrio=829 usec=614
[2022-10-07T15:52:12.487] sched: Allocate JobId=50317 NodeList=cpu03 #CPUs=64 Partition=cpu-opteron
[2022-10-07T15:52:17.147] _job_complete: JobId=50317 WEXITSTATUS 1
[2022-10-07T15:52:17.147] _job_complete: JobId=50317 done
[2022-10-07T15:53:37.899] _slurm_rpc_submit_batch_job: JobId=50318 InitPrio=829 usec=551
[2022-10-07T15:53:38.596] sched: Allocate JobId=50318 NodeList=cpu03 #CPUs=64 Partition=cpu-opteron
[2022-10-07T15:57:29.859] _job_complete: JobId=50295 WEXITSTATUS 0
[2022-10-07T15:57:29.860] _job_complete: JobId=50295 done
[2022-10-07T15:57:30.416] sched: Allocate JobId=50296 NodeList=gpu05 #CPUs=8 Partition=gpu-v100s
[2022-10-07T16:07:26.146] _job_complete: JobId=50304 WEXITSTATUS 0
[2022-10-07T16:07:26.147] _job_complete: JobId=50304 done
[2022-10-07T16:14:49.277] _job_complete: JobId=50296 WEXITSTATUS 0
[2022-10-07T16:14:49.278] _job_complete: JobId=50296 done
[2022-10-07T16:14:49.899] sched: Allocate JobId=50297 NodeList=gpu05 #CPUs=8 Partition=gpu-v100s
[2022-10-07T16:32:06.811] _job_complete: JobId=50297 WEXITSTATUS 0
[2022-10-07T16:32:06.812] _job_complete: JobId=50297 done
[2022-10-07T16:32:07.431] sched: Allocate JobId=50306 NodeList=gpu05 #CPUs=8 Partition=gpu-v100s
[2022-10-07T16:36:19.504] sched: _slurm_rpc_allocate_resources JobId=50319 NodeList=(null) usec=1334
[2022-10-07T16:36:20.220] sched: Allocate JobId=50319 NodeList=gpu03 #CPUs=4 Partition=gpu-k10
[2022-10-07T16:37:34.151] _job_complete: JobId=50319 WEXITSTATUS 127
[2022-10-07T16:37:34.151] _job_complete: JobId=50319 done
[2022-10-07T16:38:18.826] _get_job_parts: invalid partition specified: gpu-v100
[2022-10-07T16:38:18.826] _slurm_rpc_submit_batch_job: Invalid partition name specified
[2022-10-07T16:38:36.429] _slurm_rpc_submit_batch_job: JobId=50320 InitPrio=6016 usec=363
[2022-10-07T16:38:51.289] _slurm_rpc_submit_batch_job: JobId=50321 InitPrio=6016 usec=364
[2022-10-07T16:39:13.354] _slurm_rpc_kill_job: REQUEST_KILL_JOB JobId=50320 uid 548300576
[2022-10-07T16:39:19.488] _slurm_rpc_kill_job: REQUEST_KILL_JOB JobId=50321 uid 548300576
[2022-10-07T16:39:48.878] _pick_best_nodes: JobId=50322 never runnable in partition gpu-v100s
[2022-10-07T16:39:48.878] _slurm_rpc_submit_batch_job: Requested node configuration is not available
[2022-10-07T16:40:04.566] _slurm_rpc_submit_batch_job: JobId=50323 InitPrio=6016 usec=392
[2022-10-07T16:40:17.706] _slurm_rpc_submit_batch_job: JobId=50324 InitPrio=6016 usec=317
[2022-10-07T16:49:25.015] _job_complete: JobId=50306 WEXITSTATUS 0
[2022-10-07T16:49:25.016] _job_complete: JobId=50306 done
[2022-10-07T16:49:25.649] sched: Allocate JobId=50307 NodeList=gpu05 #CPUs=8 Partition=gpu-v100s
[2022-10-07T16:56:13.771] _job_complete: JobId=50318 WEXITSTATUS 0
[2022-10-07T16:56:13.771] _job_complete: JobId=50318 done
[2022-10-07T17:06:44.218] _job_complete: JobId=50307 WEXITSTATUS 0
[2022-10-07T17:06:44.219] _job_complete: JobId=50307 done
[2022-10-07T17:06:44.839] sched: Allocate JobId=50308 NodeList=gpu05 #CPUs=8 Partition=gpu-v100s
[2022-10-07T17:24:02.823] _job_complete: JobId=50308 WEXITSTATUS 0
[2022-10-07T17:24:02.824] _job_complete: JobId=50308 done
[2022-10-07T17:24:03.443] sched: Allocate JobId=50309 NodeList=gpu05 #CPUs=8 Partition=gpu-v100s
[2022-10-07T17:41:34.817] _job_complete: JobId=50309 WEXITSTATUS 0
[2022-10-07T17:41:34.818] _job_complete: JobId=50309 done
[2022-10-07T17:41:35.508] sched: Allocate JobId=50310 NodeList=gpu05 #CPUs=8 Partition=gpu-v100s
[2022-10-07T17:59:19.984] _job_complete: JobId=50310 WEXITSTATUS 0
[2022-10-07T17:59:19.985] _job_complete: JobId=50310 done
[2022-10-07T17:59:20.635] sched: Allocate JobId=50312 NodeList=gpu05 #CPUs=8 Partition=gpu-v100s
[2022-10-07T18:02:29.177] _job_complete: JobId=50312 WEXITSTATUS 1
[2022-10-07T18:02:29.177] _job_complete: JobId=50312 done
[2022-10-07T18:33:33.903] _slurm_rpc_submit_batch_job: JobId=50325 InitPrio=14356 usec=489
[2022-10-07T18:33:34.402] sched: Allocate JobId=50325 NodeList=gpu05 #CPUs=8 Partition=gpu-v100s
[2022-10-07T18:33:38.550] _slurm_rpc_submit_batch_job: JobId=50326 InitPrio=14356 usec=490
[2022-10-07T18:33:40.967] _slurm_rpc_submit_batch_job: JobId=50327 InitPrio=14356 usec=418
[2022-10-07T18:33:45.458] _slurm_rpc_submit_batch_job: JobId=50328 InitPrio=14356 usec=376
[2022-10-07T18:33:51.785] _slurm_rpc_submit_batch_job: JobId=50329 InitPrio=14356 usec=458
[2022-10-07T18:50:53.257] _job_complete: JobId=50325 WEXITSTATUS 0
[2022-10-07T18:50:53.258] _job_complete: JobId=50325 done
[2022-10-07T18:50:53.874] sched: Allocate JobId=50326 NodeList=gpu05 #CPUs=8 Partition=gpu-v100s
[2022-10-07T19:08:13.546] _job_complete: JobId=50326 WEXITSTATUS 0
[2022-10-07T19:08:13.547] _job_complete: JobId=50326 done
[2022-10-07T19:08:14.111] sched: Allocate JobId=50327 NodeList=gpu05 #CPUs=8 Partition=gpu-v100s
[2022-10-07T19:10:54.538] _slurm_rpc_submit_batch_job: JobId=50330 InitPrio=1867 usec=499
[2022-10-07T19:25:44.557] _job_complete: JobId=50327 WEXITSTATUS 0
[2022-10-07T19:25:44.558] _job_complete: JobId=50327 done
[2022-10-07T19:25:45.186] sched: Allocate JobId=50328 NodeList=gpu05 #CPUs=8 Partition=gpu-v100s
[2022-10-07T19:43:54.600] _job_complete: JobId=50328 WEXITSTATUS 0
[2022-10-07T19:43:54.601] _job_complete: JobId=50328 done
[2022-10-07T19:43:55.708] sched: Allocate JobId=50329 NodeList=gpu05 #CPUs=8 Partition=gpu-v100s
[2022-10-07T20:03:04.868] _job_complete: JobId=50329 WEXITSTATUS 0
[2022-10-07T20:03:04.869] _job_complete: JobId=50329 done
[2022-10-07T20:03:05.488] sched: Allocate JobId=50330 NodeList=gpu05 #CPUs=8 Partition=gpu-v100s
[2022-10-07T20:13:22.157] _slurm_rpc_submit_batch_job: JobId=50331 InitPrio=1867 usec=553
[2022-10-07T21:33:52.645] _slurm_rpc_submit_batch_job: JobId=50332 InitPrio=8713 usec=426
[2022-10-07T21:33:52.862] sched: Allocate JobId=50332 NodeList=cpu01 #CPUs=8 Partition=cpu-opteron
[2022-10-07T21:33:57.269] _job_complete: JobId=50332 WEXITSTATUS 1
[2022-10-07T21:33:57.270] _job_complete: JobId=50332 done
[2022-10-07T21:37:48.387] _slurm_rpc_submit_batch_job: JobId=50333 InitPrio=8713 usec=421
[2022-10-07T21:37:49.270] sched: Allocate JobId=50333 NodeList=cpu01 #CPUs=8 Partition=cpu-opteron
[2022-10-07T21:37:50.963] _job_complete: JobId=50333 WEXITSTATUS 1
[2022-10-07T21:37:50.963] _job_complete: JobId=50333 done
[2022-10-07T21:38:50.742] _slurm_rpc_submit_batch_job: JobId=50334 InitPrio=8713 usec=455
[2022-10-07T21:38:51.353] sched: Allocate JobId=50334 NodeList=cpu01 #CPUs=8 Partition=cpu-opteron
[2022-10-07T21:38:53.135] _job_complete: JobId=50334 WEXITSTATUS 1
[2022-10-07T21:38:53.136] _job_complete: JobId=50334 done
[2022-10-07T21:39:47.110] _slurm_rpc_submit_batch_job: JobId=50335 InitPrio=8713 usec=444
[2022-10-07T21:39:47.429] sched: Allocate JobId=50335 NodeList=cpu01 #CPUs=8 Partition=cpu-opteron
[2022-10-07T21:39:49.214] _job_complete: JobId=50335 WEXITSTATUS 1
[2022-10-07T21:39:49.215] _job_complete: JobId=50335 done
[2022-10-07T21:50:54.425] _slurm_rpc_submit_batch_job: JobId=50336 InitPrio=8713 usec=456
[2022-10-07T21:50:54.554] sched: Allocate JobId=50336 NodeList=cpu01 #CPUs=8 Partition=cpu-opteron
[2022-10-07T21:50:56.573] _job_complete: JobId=50336 WEXITSTATUS 1
[2022-10-07T21:50:56.573] _job_complete: JobId=50336 done
[2022-10-07T21:53:56.997] _slurm_rpc_submit_batch_job: JobId=50337 InitPrio=8713 usec=512
[2022-10-07T21:53:57.887] sched: Allocate JobId=50337 NodeList=cpu01 #CPUs=8 Partition=cpu-opteron
[2022-10-07T21:53:59.587] _job_complete: JobId=50337 WEXITSTATUS 1
[2022-10-07T21:53:59.588] _job_complete: JobId=50337 done
[2022-10-07T21:54:30.131] _slurm_rpc_submit_batch_job: JobId=50338 InitPrio=8713 usec=471
[2022-10-07T21:54:30.935] sched: Allocate JobId=50338 NodeList=cpu01 #CPUs=8 Partition=cpu-opteron
[2022-10-07T21:57:05.654] _slurm_rpc_kill_job: REQUEST_KILL_JOB JobId=50337 uid 548300548
[2022-10-07T21:58:17.163] _slurm_rpc_kill_job: REQUEST_KILL_JOB JobId=50337 uid 548300548
[2022-10-07T21:59:42.271] _slurm_rpc_kill_job: REQUEST_KILL_JOB JobId=50336 uid 548300548
[2022-10-07T22:01:43.727] _slurm_rpc_kill_job: REQUEST_KILL_JOB JobId=50338 uid 548300548
[2022-10-07T22:05:49.706] _slurm_rpc_submit_batch_job: JobId=50339 InitPrio=8713 usec=526
[2022-10-07T22:05:50.033] sched: Allocate JobId=50339 NodeList=cpu01 #CPUs=8 Partition=cpu-opteron
[2022-10-07T22:07:11.072] _job_complete: JobId=49730 WEXITSTATUS 0
[2022-10-07T22:07:11.072] _job_complete: JobId=49730 done
[2022-10-07T22:07:11.776] sched: Allocate JobId=49733 NodeList=cpu13 #CPUs=16 Partition=cpu-epyc
[2022-10-07T22:21:04.675] _slurm_rpc_submit_batch_job: JobId=50340 InitPrio=829 usec=506
[2022-10-07T22:21:05.685] sched: Allocate JobId=50340 NodeList=cpu03 #CPUs=64 Partition=cpu-opteron
[2022-10-07T22:26:30.861] _slurm_rpc_submit_batch_job: JobId=50341 InitPrio=829 usec=413
[2022-10-07T22:26:31.206] sched: Allocate JobId=50341 NodeList=cpu04 #CPUs=64 Partition=cpu-opteron
[2022-10-07T22:47:55.554] _slurm_rpc_submit_batch_job: JobId=50342 InitPrio=829 usec=605
[2022-10-07T22:47:56.360] sched: Allocate JobId=50342 NodeList=cpu01 #CPUs=8 Partition=cpu-opteron
[2022-10-07T22:47:58.439] _job_complete: JobId=50342 WEXITSTATUS 127
[2022-10-07T22:47:58.439] _job_complete: JobId=50342 done
[2022-10-07T22:48:45.695] _slurm_rpc_submit_batch_job: JobId=50343 InitPrio=829 usec=453
[2022-10-07T22:48:46.423] sched: Allocate JobId=50343 NodeList=cpu01 #CPUs=8 Partition=cpu-opteron
[2022-10-07T22:48:54.226] _job_complete: JobId=50343 WEXITSTATUS 0
[2022-10-07T22:48:54.227] _job_complete: JobId=50343 done
[2022-10-07T22:55:43.678] _slurm_rpc_submit_batch_job: JobId=50344 InitPrio=829 usec=447
[2022-10-07T22:55:44.112] sched: Allocate JobId=50344 NodeList=cpu05 #CPUs=64 Partition=cpu-opteron
[2022-10-07T22:55:46.779] _job_complete: JobId=50344 WEXITSTATUS 127
[2022-10-07T22:55:46.779] _job_complete: JobId=50344 done
[2022-10-07T22:56:36.218] _slurm_rpc_submit_batch_job: JobId=50345 InitPrio=829 usec=496
[2022-10-07T22:56:36.258] sched: Allocate JobId=50345 NodeList=cpu05 #CPUs=64 Partition=cpu-opteron
[2022-10-07T22:56:38.233] _job_complete: JobId=50345 WEXITSTATUS 0
[2022-10-07T22:56:38.233] _job_complete: JobId=50345 done
[2022-10-07T22:56:48.818] _slurm_rpc_submit_batch_job: JobId=50346 InitPrio=1244 usec=472
[2022-10-07T22:57:44.117] _slurm_rpc_submit_batch_job: JobId=50347 InitPrio=829 usec=521
[2022-10-07T22:57:44.351] sched: Allocate JobId=50347 NodeList=cpu01 #CPUs=8 Partition=cpu-opteron
[2022-10-07T22:57:45.832] _job_complete: JobId=50347 WEXITSTATUS 1
[2022-10-07T22:57:45.832] _job_complete: JobId=50347 done
[2022-10-07T22:59:44.134] _slurm_rpc_submit_batch_job: JobId=50348 InitPrio=1244 usec=552
[2022-10-07T23:01:42.922] _slurm_rpc_submit_batch_job: JobId=50349 InitPrio=829 usec=438
[2022-10-07T23:01:43.729] sched: Allocate JobId=50349 NodeList=cpu01 #CPUs=8 Partition=cpu-opteron
[2022-10-07T23:01:46.716] _job_complete: JobId=50349 WEXITSTATUS 0
[2022-10-07T23:01:46.716] _job_complete: JobId=50349 done
[2022-10-07T23:02:31.577] _slurm_rpc_submit_batch_job: JobId=50350 InitPrio=829 usec=495
[2022-10-07T23:02:31.794] sched: Allocate JobId=50350 NodeList=cpu05 #CPUs=64 Partition=cpu-opteron
[2022-10-07T23:02:33.047] _job_complete: JobId=50350 WEXITSTATUS 0
[2022-10-07T23:02:33.047] _job_complete: JobId=50350 done
[2022-10-08T02:10:15.855] _slurm_rpc_submit_batch_job: JobId=50351 InitPrio=13941 usec=539
[2022-10-08T02:10:19.039] _slurm_rpc_submit_batch_job: JobId=50352 InitPrio=13941 usec=447
[2022-10-08T02:10:21.254] _slurm_rpc_submit_batch_job: JobId=50353 InitPrio=13941 usec=385
[2022-10-08T02:10:24.115] _slurm_rpc_submit_batch_job: JobId=50354 InitPrio=13941 usec=513
[2022-10-08T02:10:27.193] _slurm_rpc_submit_batch_job: JobId=50355 InitPrio=13941 usec=414
[2022-10-08T02:30:08.194] _slurm_rpc_submit_batch_job: JobId=50356 InitPrio=2489 usec=519
[2022-10-08T02:30:08.835] sched: Allocate JobId=50356 NodeList=cpu01 #CPUs=12 Partition=cpu-opteron
[2022-10-08T07:27:40.648] _job_complete: JobId=49731 WEXITSTATUS 0
[2022-10-08T07:27:40.649] _job_complete: JobId=49731 done
[2022-10-08T07:27:41.332] sched: Allocate JobId=49734 NodeList=cpu12 #CPUs=16 Partition=cpu-epyc
[2022-10-08T13:16:39.955] _slurm_rpc_submit_batch_job: JobId=50357 InitPrio=1244 usec=602
[2022-10-08T13:59:26.458] _job_complete: JobId=50330 WEXITSTATUS 0
[2022-10-08T13:59:26.464] _job_complete: JobId=50330 done
[2022-10-08T13:59:27.141] sched: Allocate JobId=50351 NodeList=gpu05 #CPUs=8 Partition=gpu-v100s
[2022-10-08T14:16:47.254] _job_complete: JobId=50351 WEXITSTATUS 0
[2022-10-08T14:16:47.255] _job_complete: JobId=50351 done
[2022-10-08T14:16:47.837] sched: Allocate JobId=50352 NodeList=gpu05 #CPUs=8 Partition=gpu-v100s
[2022-10-08T14:34:03.159] _job_complete: JobId=50352 WEXITSTATUS 0
[2022-10-08T14:34:03.160] _job_complete: JobId=50352 done
[2022-10-08T14:34:03.769] sched: Allocate JobId=50353 NodeList=gpu05 #CPUs=8 Partition=gpu-v100s
[2022-10-08T14:51:47.171] _job_complete: JobId=50353 WEXITSTATUS 0
[2022-10-08T14:51:47.172] _job_complete: JobId=50353 done
[2022-10-08T14:51:47.822] sched: Allocate JobId=50354 NodeList=gpu05 #CPUs=8 Partition=gpu-v100s
[2022-10-08T15:10:56.320] _job_complete: JobId=50354 WEXITSTATUS 0
[2022-10-08T15:10:56.322] _job_complete: JobId=50354 done
[2022-10-08T15:10:56.924] sched: Allocate JobId=50355 NodeList=gpu05 #CPUs=8 Partition=gpu-v100s
[2022-10-08T15:33:10.401] _job_complete: JobId=50355 WEXITSTATUS 0
[2022-10-08T15:33:10.403] _job_complete: JobId=50355 done
[2022-10-08T15:33:11.559] sched: Allocate JobId=50331 NodeList=gpu05 #CPUs=8 Partition=gpu-v100s
[2022-10-08T15:34:22.531] _job_complete: JobId=50331 WEXITSTATUS 1
[2022-10-08T15:34:22.531] _job_complete: JobId=50331 done
[2022-10-08T15:34:23.004] sched: Allocate JobId=50346 NodeList=gpu05 #CPUs=8 Partition=gpu-v100s
[2022-10-08T15:34:35.052] _job_complete: JobId=50346 WEXITSTATUS 1
[2022-10-08T15:34:35.052] _job_complete: JobId=50346 done
[2022-10-08T15:37:54.524] _slurm_rpc_submit_batch_job: JobId=50358 InitPrio=13734 usec=545
[2022-10-08T15:37:55.469] sched: Allocate JobId=50358 NodeList=gpu05 #CPUs=8 Partition=gpu-v100s
[2022-10-08T15:37:56.566] _slurm_rpc_submit_batch_job: JobId=50359 InitPrio=13734 usec=510
[2022-10-08T15:37:58.561] _slurm_rpc_submit_batch_job: JobId=50360 InitPrio=13734 usec=431
[2022-10-08T15:38:02.495] _slurm_rpc_submit_batch_job: JobId=50361 InitPrio=13734 usec=474
[2022-10-08T15:38:04.252] _slurm_rpc_submit_batch_job: JobId=50362 InitPrio=13734 usec=371
[2022-10-08T15:53:58.451] _slurm_rpc_submit_batch_job: JobId=50363 InitPrio=1659 usec=501
[2022-10-08T15:55:16.136] _job_complete: JobId=50358 WEXITSTATUS 0
[2022-10-08T15:55:16.137] _job_complete: JobId=50358 done
[2022-10-08T15:55:16.807] sched: Allocate JobId=50359 NodeList=gpu05 #CPUs=8 Partition=gpu-v100s
[2022-10-08T16:12:36.023] _job_complete: JobId=50359 WEXITSTATUS 0
[2022-10-08T16:12:36.024] _job_complete: JobId=50359 done
[2022-10-08T16:12:36.770] sched: Allocate JobId=50360 NodeList=gpu05 #CPUs=8 Partition=gpu-v100s
[2022-10-08T16:30:36.525] _job_complete: JobId=50360 WEXITSTATUS 0
[2022-10-08T16:30:36.526] _job_complete: JobId=50360 done
[2022-10-08T16:30:37.135] sched: Allocate JobId=50361 NodeList=gpu05 #CPUs=8 Partition=gpu-v100s
[2022-10-08T16:51:28.456] _job_complete: JobId=50361 WEXITSTATUS 0
[2022-10-08T16:51:28.457] _job_complete: JobId=50361 done
[2022-10-08T16:51:29.085] sched: Allocate JobId=50362 NodeList=gpu05 #CPUs=8 Partition=gpu-v100s
[2022-10-08T17:19:09.237] _job_complete: JobId=50362 WEXITSTATUS 0
[2022-10-08T17:19:09.239] _job_complete: JobId=50362 done
[2022-10-08T22:05:57.446] Time limit exhausted for JobId=50339
[2022-10-08T23:08:14.090] _slurm_rpc_submit_batch_job: JobId=50364 InitPrio=13734 usec=472
[2022-10-08T23:08:14.984] sched: Allocate JobId=50364 NodeList=gpu05 #CPUs=8 Partition=gpu-v100s
[2022-10-08T23:08:16.436] _slurm_rpc_submit_batch_job: JobId=50365 InitPrio=13734 usec=519
[2022-10-08T23:08:18.938] _slurm_rpc_submit_batch_job: JobId=50366 InitPrio=13734 usec=398
[2022-10-08T23:08:21.905] _slurm_rpc_submit_batch_job: JobId=50367 InitPrio=13734 usec=406
[2022-10-08T23:08:25.453] _slurm_rpc_submit_batch_job: JobId=50368 InitPrio=13734 usec=391
[2022-10-08T23:15:30.107] _job_complete: JobId=50187 WEXITSTATUS 0
[2022-10-08T23:15:30.113] _job_complete: JobId=50187 done
[2022-10-08T23:15:35.185] sched: Allocate JobId=50365 NodeList=gpu05 #CPUs=8 Partition=gpu-v100s
[2022-10-08T23:25:21.620] _job_complete: JobId=50364 WEXITSTATUS 0
[2022-10-08T23:25:21.621] _job_complete: JobId=50364 done
[2022-10-08T23:25:22.241] sched: Allocate JobId=50366 NodeList=gpu05 #CPUs=8 Partition=gpu-v100s
[2022-10-08T23:32:30.293] _job_complete: JobId=50365 WEXITSTATUS 0
[2022-10-08T23:32:30.294] _job_complete: JobId=50365 done
[2022-10-08T23:32:30.799] sched: Allocate JobId=50367 NodeList=gpu05 #CPUs=8 Partition=gpu-v100s
[2022-10-08T23:43:10.124] _job_complete: JobId=50366 WEXITSTATUS 0
[2022-10-08T23:43:10.124] _job_complete: JobId=50366 done
[2022-10-08T23:43:10.623] sched: Allocate JobId=50368 NodeList=gpu05 #CPUs=8 Partition=gpu-v100s
[2022-10-08T23:54:12.357] _job_complete: JobId=50367 WEXITSTATUS 0
[2022-10-08T23:54:12.357] _job_complete: JobId=50367 done
[2022-10-09T00:21:29.083] _job_complete: JobId=50368 WEXITSTATUS 0
[2022-10-09T00:21:29.084] _job_complete: JobId=50368 done
[2022-10-09T00:21:30.138] sched: Allocate JobId=50348 NodeList=gpu05 #CPUs=8 Partition=gpu-v100s
[2022-10-09T00:22:26.465] _job_complete: JobId=50348 OOM failure
[2022-10-09T00:22:26.466] _job_complete: JobId=50348 done
[2022-10-09T00:22:28.474] sched: Allocate JobId=50363 NodeList=gpu05 #CPUs=8 Partition=gpu-v100s
[2022-10-09T02:57:34.589] _job_complete: JobId=50124 WEXITSTATUS 0
[2022-10-09T02:57:34.595] _job_complete: JobId=50124 done
[2022-10-09T03:20:01.599] _slurm_rpc_submit_batch_job: JobId=50369 InitPrio=1037 usec=591
[2022-10-09T03:20:02.420] sched: Allocate JobId=50369 NodeList=cpu05 #CPUs=64 Partition=cpu-opteron
[2022-10-09T13:17:03.606] Time limit exhausted for JobId=50052
[2022-10-09T13:17:06.918] sched: Allocate JobId=50229 NodeList=gpu02 #CPUs=10 Partition=gpu-titan
[2022-10-09T15:15:23.671] _slurm_rpc_submit_batch_job: JobId=50370 InitPrio=9336 usec=460
[2022-10-09T15:15:24.157] sched: Allocate JobId=50370 NodeList=cpu01 #CPUs=1 Partition=cpu-opteron
[2022-10-09T15:15:25.704] _job_complete: JobId=50370 WEXITSTATUS 2
[2022-10-09T15:15:25.704] _job_complete: JobId=50370 done
[2022-10-09T15:15:46.195] _slurm_rpc_submit_batch_job: JobId=50371 InitPrio=9336 usec=465
[2022-10-09T15:15:47.160] sched: Allocate JobId=50371 NodeList=cpu01 #CPUs=1 Partition=cpu-opteron
[2022-10-09T15:15:50.569] _job_complete: JobId=50371 WEXITSTATUS 1
[2022-10-09T15:15:50.570] _job_complete: JobId=50371 done
[2022-10-09T15:16:27.556] _slurm_rpc_submit_batch_job: JobId=50372 InitPrio=9336 usec=374
[2022-10-09T15:16:29.325] sched: Allocate JobId=50372 NodeList=cpu01 #CPUs=1 Partition=cpu-opteron
[2022-10-09T15:17:31.615] _slurm_rpc_kill_job: REQUEST_KILL_JOB JobId=50369 uid 548300621
[2022-10-09T15:17:34.798] _slurm_rpc_kill_job: REQUEST_KILL_JOB JobId=50369 uid 548300621
[2022-10-09T15:17:46.941] _slurm_rpc_submit_batch_job: JobId=50373 InitPrio=1037 usec=428
[2022-10-09T15:17:47.449] sched: Allocate JobId=50373 NodeList=cpu05 #CPUs=64 Partition=cpu-opteron
[2022-10-09T15:18:18.372] _slurm_rpc_submit_batch_job: JobId=50374 InitPrio=1037 usec=431
[2022-10-09T15:18:18.477] sched: Allocate JobId=50374 NodeList=cpu07 #CPUs=64 Partition=cpu-opteron
[2022-10-09T15:18:21.241] _slurm_rpc_submit_batch_job: JobId=50375 InitPrio=1037 usec=436
[2022-10-09T15:18:21.481] sched: Allocate JobId=50375 NodeList=cpu08 #CPUs=64 Partition=cpu-opteron
[2022-10-09T15:18:52.388] _slurm_rpc_submit_batch_job: JobId=50376 InitPrio=1244 usec=425
[2022-10-09T15:19:59.841] _slurm_rpc_submit_batch_job: JobId=50377 InitPrio=1244 usec=479
[2022-10-09T15:20:46.823] _slurm_rpc_kill_job: REQUEST_KILL_JOB JobId=50376 uid 548300547
[2022-10-09T15:21:08.132] _slurm_rpc_submit_batch_job: JobId=50378 InitPrio=9336 usec=372
[2022-10-09T15:21:08.864] sched: Allocate JobId=50378 NodeList=cpu01 #CPUs=1 Partition=cpu-opteron
[2022-10-09T15:21:17.136] _slurm_rpc_submit_batch_job: JobId=50379 InitPrio=1244 usec=492
[2022-10-09T15:22:13.380] _slurm_rpc_kill_job: REQUEST_KILL_JOB JobId=50372 uid 548200009
[2022-10-09T15:28:40.019] _slurm_rpc_submit_batch_job: JobId=50380 InitPrio=9336 usec=439
[2022-10-09T15:28:40.608] sched: Allocate JobId=50380 NodeList=cpu01 #CPUs=1 Partition=cpu-opteron
[2022-10-09T15:31:38.714] _slurm_rpc_kill_job: REQUEST_KILL_JOB JobId=50380 uid 548200009
[2022-10-09T15:31:44.511] _slurm_rpc_submit_batch_job: JobId=50381 InitPrio=9336 usec=554
[2022-10-09T15:31:44.931] sched: Allocate JobId=50381 NodeList=cpu01 #CPUs=1 Partition=cpu-opteron
[2022-10-09T15:32:13.013] _slurm_rpc_kill_job: REQUEST_KILL_JOB JobId=50378 uid 548200009
[2022-10-09T15:47:35.488] _job_complete: JobId=50191 WEXITSTATUS 1
[2022-10-09T15:47:35.488] _job_complete: JobId=50191 done
[2022-10-09T16:00:06.120] _job_complete: JobId=50229 WEXITSTATUS 0
[2022-10-09T16:00:06.126] _job_complete: JobId=50229 done
[2022-10-09T16:00:10.392] sched: Allocate JobId=50230 NodeList=gpu02 #CPUs=10 Partition=gpu-titan
[2022-10-09T16:26:13.356] _slurm_rpc_submit_batch_job: JobId=50382 InitPrio=1867 usec=418
[2022-10-09T16:26:13.887] sched: Allocate JobId=50382 NodeList=gpu04 #CPUs=16 Partition=gpu-k40c
[2022-10-09T17:08:20.618] _job_complete: JobId=50363 WEXITSTATUS 0
[2022-10-09T17:08:20.623] _job_complete: JobId=50363 done
[2022-10-09T17:08:21.780] sched: Allocate JobId=50357 NodeList=gpu05 #CPUs=8 Partition=gpu-v100s
[2022-10-09T17:09:31.012] _job_complete: JobId=50357 OOM failure
[2022-10-09T17:09:31.012] _job_complete: JobId=50357 done
[2022-10-09T17:09:32.143] sched: Allocate JobId=50377 NodeList=gpu05 #CPUs=8 Partition=gpu-v100s
[2022-10-09T17:09:40.525] _job_complete: JobId=50377 WEXITSTATUS 1
[2022-10-09T17:09:40.526] _job_complete: JobId=50377 done
[2022-10-09T17:09:41.628] sched: Allocate JobId=50379 NodeList=gpu05 #CPUs=8 Partition=gpu-v100s
[2022-10-09T17:10:31.430] _job_complete: JobId=50379 OOM failure
[2022-10-09T17:10:31.431] _job_complete: JobId=50379 done
[2022-10-09T18:43:57.093] _slurm_rpc_submit_batch_job: JobId=50383 InitPrio=1037 usec=485
[2022-10-09T18:43:57.242] sched: Allocate JobId=50383 NodeList=cpu09 #CPUs=64 Partition=cpu-opteron
[2022-10-09T19:03:48.573] _slurm_rpc_submit_batch_job: JobId=50384 InitPrio=1659 usec=511
[2022-10-09T19:03:48.629] sched: Allocate JobId=50384 NodeList=gpu05 #CPUs=8 Partition=gpu-v100s
[2022-10-09T19:06:35.088] _slurm_rpc_submit_batch_job: JobId=50385 InitPrio=1659 usec=549
[2022-10-09T19:06:36.069] sched: Allocate JobId=50385 NodeList=gpu05 #CPUs=8 Partition=gpu-v100s
[2022-10-09T19:06:46.532] _slurm_rpc_kill_job: REQUEST_KILL_JOB JobId=50385 uid 548300564
[2022-10-09T19:06:49.182] _slurm_rpc_kill_job: REQUEST_KILL_JOB JobId=50384 uid 548300564
[2022-10-09T19:06:55.534] _slurm_rpc_submit_batch_job: JobId=50386 InitPrio=1659 usec=416
[2022-10-09T19:06:56.095] sched: Allocate JobId=50386 NodeList=gpu05 #CPUs=8 Partition=gpu-v100s
[2022-10-09T19:18:01.509] _job_complete: JobId=50230 WEXITSTATUS 0
[2022-10-09T19:18:01.515] _job_complete: JobId=50230 done
[2022-10-09T21:55:49.330] _job_complete: JobId=50356 WEXITSTATUS 1
[2022-10-09T21:55:49.330] _job_complete: JobId=50356 done
[2022-10-10T00:05:00.260] _slurm_rpc_submit_batch_job: JobId=50387 InitPrio=1244 usec=591
[2022-10-10T00:05:00.621] sched: Allocate JobId=50387 NodeList=gpu05 #CPUs=8 Partition=gpu-v100s
[2022-10-10T00:05:07.726] _job_complete: JobId=50387 WEXITSTATUS 1
[2022-10-10T00:05:07.727] _job_complete: JobId=50387 done
[2022-10-10T00:06:31.548] _slurm_rpc_submit_batch_job: JobId=50388 InitPrio=1244 usec=538
[2022-10-10T00:06:32.052] sched: Allocate JobId=50388 NodeList=gpu05 #CPUs=8 Partition=gpu-v100s
[2022-10-10T00:06:38.472] _job_complete: JobId=50388 WEXITSTATUS 1
[2022-10-10T00:06:38.472] _job_complete: JobId=50388 done
[2022-10-10T00:07:53.204] _slurm_rpc_submit_batch_job: JobId=50389 InitPrio=1244 usec=509
[2022-10-10T00:07:54.160] sched: Allocate JobId=50389 NodeList=gpu05 #CPUs=8 Partition=gpu-v100s
[2022-10-10T00:08:01.091] _job_complete: JobId=50389 WEXITSTATUS 1
[2022-10-10T00:08:01.091] _job_complete: JobId=50389 done
[2022-10-10T00:08:31.883] _slurm_rpc_submit_batch_job: JobId=50390 InitPrio=1244 usec=527
[2022-10-10T00:08:32.210] sched: Allocate JobId=50390 NodeList=gpu05 #CPUs=8 Partition=gpu-v100s
[2022-10-10T00:08:42.043] _job_complete: JobId=50390 WEXITSTATUS 1
[2022-10-10T00:08:42.043] _job_complete: JobId=50390 done
[2022-10-10T00:09:58.004] _slurm_rpc_submit_batch_job: JobId=50391 InitPrio=1244 usec=465
[2022-10-10T00:09:58.329] sched: Allocate JobId=50391 NodeList=gpu05 #CPUs=8 Partition=gpu-v100s
[2022-10-10T00:11:31.123] _slurm_rpc_submit_batch_job: JobId=50392 InitPrio=1244 usec=458
[2022-10-10T00:12:01.302] _slurm_rpc_submit_batch_job: JobId=50393 InitPrio=1244 usec=624
[2022-10-10T00:30:23.312] _slurm_rpc_kill_job: REQUEST_KILL_JOB JobId=50391 uid 548300547
[2022-10-10T00:32:07.105] _slurm_rpc_submit_batch_job: JobId=50394 InitPrio=1244 usec=458
[2022-10-10T00:32:50.866] _slurm_rpc_kill_job: REQUEST_KILL_JOB JobId=50394 uid 548300547
[2022-10-10T00:33:10.940] _slurm_rpc_submit_batch_job: JobId=50395 InitPrio=1244 usec=513
[2022-10-10T03:40:38.666] _job_complete: JobId=50386 WEXITSTATUS 1
[2022-10-10T03:40:38.671] _job_complete: JobId=50386 done
[2022-10-10T03:40:39.160] sched: Allocate JobId=50392 NodeList=gpu05 #CPUs=8 Partition=gpu-v100s
[2022-10-10T04:09:51.200] _job_complete: JobId=50392 OOM failure
[2022-10-10T04:09:51.201] _job_complete: JobId=50392 done
[2022-10-10T04:09:53.097] sched: Allocate JobId=50393 NodeList=gpu05 #CPUs=8 Partition=gpu-v100s
[2022-10-10T04:38:38.868] _job_complete: JobId=50393 OOM failure
[2022-10-10T04:38:38.869] _job_complete: JobId=50393 done
[2022-10-10T04:38:40.775] sched: Allocate JobId=50395 NodeList=gpu05 #CPUs=8 Partition=gpu-v100s
[2022-10-10T04:38:50.709] _job_complete: JobId=50395 WEXITSTATUS 1
[2022-10-10T04:38:50.710] _job_complete: JobId=50395 done
[2022-10-10T07:58:25.205] _slurm_rpc_submit_batch_job: JobId=50396 InitPrio=1452 usec=523
[2022-10-10T07:58:26.214] sched: Allocate JobId=50396 NodeList=gpu05 #CPUs=8 Partition=gpu-v100s
[2022-10-10T09:04:45.644] _job_complete: JobId=50396 WEXITSTATUS 0
[2022-10-10T09:04:45.645] _job_complete: JobId=50396 done
[2022-10-10T10:28:17.935] _slurm_rpc_submit_batch_job: JobId=50397 InitPrio=1244 usec=621
[2022-10-10T10:28:18.904] sched: Allocate JobId=50397 NodeList=gpu05 #CPUs=8 Partition=gpu-v100s
[2022-10-10T10:29:23.436] _slurm_rpc_submit_batch_job: JobId=50398 InitPrio=1244 usec=452
[2022-10-10T10:29:42.165] _slurm_rpc_kill_job: REQUEST_KILL_JOB JobId=50397 uid 548300547
[2022-10-10T10:29:44.155] sched: Allocate JobId=50398 NodeList=gpu05 #CPUs=8 Partition=gpu-v100s
[2022-10-10T10:30:48.005] _slurm_rpc_kill_job: REQUEST_KILL_JOB JobId=50398 uid 548300547
[2022-10-10T10:31:12.270] _slurm_rpc_submit_batch_job: JobId=50399 InitPrio=1244 usec=474
[2022-10-10T10:31:13.272] sched: Allocate JobId=50399 NodeList=gpu05 #CPUs=8 Partition=gpu-v100s
[2022-10-10T10:31:56.625] _job_complete: JobId=50399 OOM failure
[2022-10-10T10:31:56.626] _job_complete: JobId=50399 done
[2022-10-10T10:33:08.707] _slurm_rpc_submit_batch_job: JobId=50400 InitPrio=1244 usec=521
[2022-10-10T10:33:09.431] sched: Allocate JobId=50400 NodeList=gpu05 #CPUs=8 Partition=gpu-v100s
[2022-10-10T10:35:26.902] _slurm_rpc_submit_batch_job: JobId=50401 InitPrio=1244 usec=524
[2022-10-10T10:35:43.718] _slurm_rpc_submit_batch_job: JobId=50402 InitPrio=1244 usec=444
[2022-10-10T11:04:37.029] _job_complete: JobId=50400 OOM failure
[2022-10-10T11:04:37.030] _job_complete: JobId=50400 done
[2022-10-10T11:04:38.036] sched: Allocate JobId=50401 NodeList=gpu05 #CPUs=8 Partition=gpu-v100s
[2022-10-10T11:12:05.904] _slurm_rpc_submit_batch_job: JobId=50403 InitPrio=1244 usec=530
[2022-10-10T11:12:14.786] _slurm_rpc_kill_job: REQUEST_KILL_JOB JobId=50401 uid 548300547
[2022-10-10T11:12:14.786] _slurm_rpc_kill_job: REQUEST_KILL_JOB JobId=50402 uid 548300547
[2022-10-10T11:12:21.761] sched: Allocate JobId=50403 NodeList=gpu05 #CPUs=16 Partition=gpu-v100s
[2022-10-10T11:12:43.261] _slurm_rpc_submit_batch_job: JobId=50404 InitPrio=1244 usec=436
[2022-10-10T11:16:32.680] _slurm_rpc_kill_job: REQUEST_KILL_JOB JobId=50404 uid 548300547
[2022-10-10T11:16:32.680] _slurm_rpc_kill_job: REQUEST_KILL_JOB JobId=50403 uid 548300547
[2022-10-10T11:17:12.189] _slurm_rpc_submit_batch_job: JobId=50405 InitPrio=1244 usec=511
[2022-10-10T11:17:12.916] sched: Allocate JobId=50405 NodeList=gpu05 #CPUs=16 Partition=gpu-v100s
[2022-10-10T11:17:16.494] _job_complete: JobId=50405 WEXITSTATUS 1
[2022-10-10T11:17:16.495] _job_complete: JobId=50405 done
[2022-10-10T11:18:02.034] _slurm_rpc_submit_batch_job: JobId=50406 InitPrio=1244 usec=493
[2022-10-10T11:18:02.978] sched: Allocate JobId=50406 NodeList=gpu05 #CPUs=16 Partition=gpu-v100s
[2022-10-10T11:18:34.255] _job_complete: JobId=50406 OOM failure
[2022-10-10T11:18:34.256] _job_complete: JobId=50406 done
[2022-10-10T11:19:45.833] _slurm_rpc_submit_batch_job: JobId=50407 InitPrio=1244 usec=436
[2022-10-10T11:19:46.114] sched: Allocate JobId=50407 NodeList=gpu05 #CPUs=16 Partition=gpu-v100s
[2022-10-10T11:22:06.750] _slurm_rpc_submit_batch_job: JobId=50408 InitPrio=1244 usec=552
[2022-10-10T11:22:11.666] _slurm_rpc_kill_job: REQUEST_KILL_JOB JobId=50407 uid 548300547
[2022-10-10T11:22:32.717] sched: Allocate JobId=50408 NodeList=gpu05 #CPUs=32 Partition=gpu-v100s
[2022-10-10T11:24:12.154] _job_complete: JobId=50408 WEXITSTATUS 1
[2022-10-10T11:24:12.154] _job_complete: JobId=50408 done
[2022-10-10T11:24:37.315] _slurm_rpc_submit_batch_job: JobId=50409 InitPrio=1244 usec=452
[2022-10-10T11:24:37.618] sched: Allocate JobId=50409 NodeList=gpu05 #CPUs=32 Partition=gpu-v100s
[2022-10-10T11:26:37.287] _slurm_rpc_submit_batch_job: JobId=50410 InitPrio=1452 usec=533
[2022-10-10T11:27:42.873] _slurm_rpc_submit_batch_job: JobId=50411 InitPrio=1244 usec=458
[2022-10-10T11:28:05.019] _slurm_rpc_submit_batch_job: JobId=50412 InitPrio=1244 usec=472
[2022-10-10T12:09:26.737] _job_complete: JobId=49732 WEXITSTATUS 0
[2022-10-10T12:09:26.737] _job_complete: JobId=49732 done
[2022-10-10T12:09:27.554] sched: Allocate JobId=49723 NodeList=cpu14 #CPUs=16 Partition=cpu-epyc
[2022-10-10T12:43:07.067] _slurm_rpc_submit_batch_job: JobId=50413 InitPrio=7676 usec=514
[2022-10-10T12:43:08.027] sched: Allocate JobId=50413 NodeList=cpu01 #CPUs=1 Partition=cpu-opteron
[2022-10-10T13:36:28.502] _job_complete: JobId=50382 WEXITSTATUS 0
[2022-10-10T13:36:28.507] _job_complete: JobId=50382 done
[2022-10-10T13:39:44.723] _job_complete: JobId=50383 WEXITSTATUS 1
[2022-10-10T13:39:44.723] _job_complete: JobId=50383 done
[2022-10-10T14:04:55.832] _job_complete: JobId=50413 WEXITSTATUS 0
[2022-10-10T14:04:55.833] _job_complete: JobId=50413 done
[2022-10-10T14:42:00.844] _slurm_rpc_submit_batch_job: JobId=50414 InitPrio=1867 usec=495
[2022-10-10T14:42:01.768] sched: Allocate JobId=50414 NodeList=gpu04 #CPUs=16 Partition=gpu-k40c
[2022-10-10T15:52:11.447] _job_complete: JobId=50267 WEXITSTATUS 0
[2022-10-10T15:52:11.447] _job_complete: JobId=50267 done
[2022-10-10T16:12:45.706] _slurm_rpc_submit_batch_job: JobId=50415 InitPrio=7676 usec=422
[2022-10-10T16:12:46.253] sched: Allocate JobId=50415 NodeList=cpu01 #CPUs=1 Partition=cpu-opteron
[2022-10-10T16:13:11.490] _job_complete: JobId=50415 WEXITSTATUS 1
[2022-10-10T16:13:11.491] _job_complete: JobId=50415 done
[2022-10-10T16:15:31.968] _slurm_rpc_submit_batch_job: JobId=50416 InitPrio=7676 usec=484
[2022-10-10T16:15:32.458] sched: Allocate JobId=50416 NodeList=cpu01 #CPUs=1 Partition=cpu-opteron
[2022-10-10T16:40:18.314] _job_complete: JobId=50416 WEXITSTATUS 0
[2022-10-10T16:40:18.315] _job_complete: JobId=50416 done
[2022-10-10T16:46:18.619] _slurm_rpc_submit_batch_job: JobId=50417 InitPrio=1452 usec=488
[2022-10-10T16:50:55.307] _slurm_rpc_submit_batch_job: JobId=50418 InitPrio=7676 usec=508
[2022-10-10T16:50:56.160] sched: Allocate JobId=50418 NodeList=cpu01 #CPUs=1 Partition=cpu-opteron
[2022-10-10T16:51:19.514] _job_complete: JobId=50418 WEXITSTATUS 1
[2022-10-10T16:51:19.514] _job_complete: JobId=50418 done
[2022-10-10T16:52:10.042] _slurm_rpc_submit_batch_job: JobId=50419 InitPrio=7676 usec=393
[2022-10-10T16:52:10.359] sched: Allocate JobId=50419 NodeList=cpu01 #CPUs=1 Partition=cpu-opteron
[2022-10-10T17:40:40.876] _slurm_rpc_submit_batch_job: JobId=50420 InitPrio=1037 usec=519
[2022-10-10T17:40:41.664] sched: Allocate JobId=50420 NodeList=cpu09 #CPUs=64 Partition=cpu-opteron
[2022-10-10T17:58:16.531] _job_complete: JobId=50419 WEXITSTATUS 0
[2022-10-10T17:58:16.532] _job_complete: JobId=50419 done
[2022-10-10T21:33:49.552] _job_complete: JobId=49733 WEXITSTATUS 0
[2022-10-10T21:33:49.552] _job_complete: JobId=49733 done
[2022-10-10T21:33:50.304] sched: Allocate JobId=50139 NodeList=cpu13 #CPUs=48 Partition=cpu-epyc
[2022-10-10T22:43:33.927] _job_complete: JobId=50139 WEXITSTATUS 139
[2022-10-10T22:43:33.928] _job_complete: JobId=50139 done
[2022-10-10T22:43:35.910] sched: Allocate JobId=50121 NodeList=cpu13 #CPUs=48 Partition=cpu-epyc
[2022-10-10T22:43:51.947] _job_complete: JobId=50121 WEXITSTATUS 1
[2022-10-10T22:43:51.947] _job_complete: JobId=50121 done
[2022-10-10T22:43:52.483] sched: Allocate JobId=50150 NodeList=cpu13 #CPUs=48 Partition=cpu-epyc
[2022-10-11T03:34:09.243] _job_complete: JobId=50420 WEXITSTATUS 0
[2022-10-11T03:34:09.244] _job_complete: JobId=50420 done
[2022-10-11T07:00:13.222] _job_complete: JobId=49734 WEXITSTATUS 0
[2022-10-11T07:00:13.222] _job_complete: JobId=49734 done
[2022-10-11T07:00:15.980] sched: Allocate JobId=50151 NodeList=cpu12 #CPUs=48 Partition=cpu-epyc
[2022-10-11T08:02:16.118] _job_complete: JobId=50241 WEXITSTATUS 1
[2022-10-11T08:02:16.118] _job_complete: JobId=50241 done
[2022-10-11T09:01:59.168] _slurm_rpc_submit_batch_job: JobId=50421 InitPrio=5809 usec=644
[2022-10-11T09:01:59.577] sched: Allocate JobId=50421 NodeList=cpu01 #CPUs=8 Partition=cpu-opteron
[2022-10-11T10:34:25.409] _slurm_rpc_submit_batch_job: JobId=50422 InitPrio=414 usec=505
[2022-10-11T10:34:26.369] sched: Allocate JobId=50422 NodeList=gpu02 #CPUs=16 Partition=gpu-titan
[2022-10-11T10:39:36.148] _slurm_rpc_submit_batch_job: JobId=50423 InitPrio=414 usec=509
[2022-10-11T10:39:36.921] sched: Allocate JobId=50423 NodeList=gpu03 #CPUs=16 Partition=gpu-k10
[2022-10-11T10:41:13.593] _job_complete: JobId=50422 WEXITSTATUS 0
[2022-10-11T10:41:13.593] _job_complete: JobId=50422 done
[2022-10-11T10:55:17.972] _slurm_rpc_submit_batch_job: JobId=50424 InitPrio=414 usec=427
[2022-10-11T10:55:17.977] sched/backfill: _start_job: Started JobId=50424 in gpu-titan on gpu02
[2022-10-11T10:55:25.855] _job_complete: JobId=50424 WEXITSTATUS 1
[2022-10-11T10:55:25.855] _job_complete: JobId=50424 done
[2022-10-11T10:56:12.515] _slurm_rpc_submit_batch_job: JobId=50425 InitPrio=1867 usec=837
[2022-10-11T10:56:12.758] sched: Allocate JobId=50425 NodeList=gpu01 #CPUs=16 Partition=gpu-k10
[2022-10-11T11:09:36.413] _job_complete: JobId=50151 WEXITSTATUS 1
[2022-10-11T11:09:36.414] _job_complete: JobId=50151 done
[2022-10-11T11:09:36.729] sched: Allocate JobId=50163 NodeList=cpu12 #CPUs=48 Partition=cpu-epyc
[2022-10-11T11:10:17.673] _slurm_rpc_submit_batch_job: JobId=50426 InitPrio=1867 usec=576
[2022-10-11T11:10:17.990] sched/backfill: _start_job: Started JobId=50426 in cpu-opteron on cpu01
[2022-10-11T11:10:44.892] _slurm_rpc_submit_batch_job: JobId=50427 InitPrio=622 usec=551
[2022-10-11T11:10:45.235] sched: Allocate JobId=50427 NodeList=cpu09 #CPUs=64 Partition=cpu-opteron
[2022-10-11T11:38:52.552] _slurm_rpc_submit_batch_job: JobId=50428 InitPrio=414 usec=446
[2022-10-11T11:38:53.303] sched: Allocate JobId=50428 NodeList=gpu02 #CPUs=16 Partition=gpu-titan
[2022-10-11T11:47:42.289] _slurm_rpc_submit_batch_job: JobId=50429 InitPrio=2074 usec=446
[2022-10-11T11:47:43.269] sched: Allocate JobId=50429 NodeList=cpu14 #CPUs=8 Partition=cpu-epyc
[2022-10-11T11:47:45.580] _slurm_rpc_submit_batch_job: JobId=50430 InitPrio=2074 usec=545
[2022-10-11T11:47:46.260] sched: Allocate JobId=50430 NodeList=cpu14 #CPUs=8 Partition=cpu-epyc
[2022-10-11T11:47:47.837] _slurm_rpc_submit_batch_job: JobId=50431 InitPrio=2074 usec=446
[2022-10-11T11:47:49.264] sched: Allocate JobId=50431 NodeList=cpu14 #CPUs=8 Partition=cpu-epyc
[2022-10-11T11:47:50.757] _slurm_rpc_submit_batch_job: JobId=50432 InitPrio=2074 usec=389
[2022-10-11T11:47:52.268] sched: Allocate JobId=50432 NodeList=cpu14 #CPUs=8 Partition=cpu-epyc
[2022-10-11T11:47:52.680] _slurm_rpc_submit_batch_job: JobId=50433 InitPrio=2074 usec=445
[2022-10-11T11:47:54.517] _slurm_rpc_submit_batch_job: JobId=50434 InitPrio=2074 usec=428
[2022-10-11T11:47:56.397] _slurm_rpc_submit_batch_job: JobId=50435 InitPrio=2074 usec=576
[2022-10-11T11:48:01.846] _slurm_rpc_submit_batch_job: JobId=50436 InitPrio=2074 usec=594
[2022-10-11T11:48:04.414] _slurm_rpc_submit_batch_job: JobId=50437 InitPrio=2074 usec=501
[2022-10-11T11:48:14.519] _slurm_rpc_submit_batch_job: JobId=50438 InitPrio=2074 usec=454
[2022-10-11T11:48:16.190] _slurm_rpc_submit_batch_job: JobId=50439 InitPrio=2074 usec=444
[2022-10-11T11:48:17.814] _slurm_rpc_submit_batch_job: JobId=50440 InitPrio=2074 usec=477
[2022-10-11T11:48:19.741] _slurm_rpc_submit_batch_job: JobId=50441 InitPrio=2074 usec=459
[2022-10-11T11:48:21.638] _slurm_rpc_submit_batch_job: JobId=50442 InitPrio=2074 usec=509
[2022-10-11T11:48:23.582] _slurm_rpc_submit_batch_job: JobId=50443 InitPrio=2074 usec=449
[2022-10-11T11:48:25.437] _slurm_rpc_submit_batch_job: JobId=50444 InitPrio=2074 usec=417
[2022-10-11T11:48:28.851] _slurm_rpc_submit_batch_job: JobId=50445 InitPrio=622 usec=391
[2022-10-11T11:48:29.322] sched: Allocate JobId=50445 NodeList=cpu10 #CPUs=64 Partition=cpu-opteron
[2022-10-11T11:48:29.494] _slurm_rpc_submit_batch_job: JobId=50446 InitPrio=2074 usec=557
[2022-10-11T11:48:30.753] _job_complete: JobId=50445 WEXITSTATUS 0
[2022-10-11T11:48:30.753] _job_complete: JobId=50445 done
[2022-10-11T11:48:31.318] _slurm_rpc_submit_batch_job: JobId=50447 InitPrio=2074 usec=428
[2022-10-11T11:48:34.191] _slurm_rpc_submit_batch_job: JobId=50448 InitPrio=2074 usec=419
[2022-10-11T11:48:36.141] _slurm_rpc_submit_batch_job: JobId=50449 InitPrio=2074 usec=506
[2022-10-11T11:48:37.749] _slurm_rpc_submit_batch_job: JobId=50450 InitPrio=2074 usec=520
[2022-10-11T11:48:39.542] _slurm_rpc_submit_batch_job: JobId=50451 InitPrio=2074 usec=413
[2022-10-11T11:48:41.486] _slurm_rpc_submit_batch_job: JobId=50452 InitPrio=2074 usec=543
[2022-10-11T11:48:43.374] _slurm_rpc_submit_batch_job: JobId=50453 InitPrio=2074 usec=462
[2022-10-11T11:48:45.350] _slurm_rpc_submit_batch_job: JobId=50454 InitPrio=2074 usec=476
[2022-10-11T11:48:47.478] _slurm_rpc_submit_batch_job: JobId=50455 InitPrio=2074 usec=432
[2022-10-11T11:48:52.534] _slurm_rpc_submit_batch_job: JobId=50456 InitPrio=2074 usec=500
[2022-10-11T11:48:54.822] _slurm_rpc_submit_batch_job: JobId=50457 InitPrio=2074 usec=477
[2022-10-11T11:48:57.902] _slurm_rpc_submit_batch_job: JobId=50458 InitPrio=2074 usec=524
[2022-10-11T11:49:00.021] _slurm_rpc_submit_batch_job: JobId=50459 InitPrio=2074 usec=457
[2022-10-11T11:50:51.176] _slurm_rpc_submit_batch_job: JobId=50460 InitPrio=622 usec=396
[2022-10-11T11:50:51.516] sched: Allocate JobId=50460 NodeList=cpu10 #CPUs=64 Partition=cpu-opteron
[2022-10-11T11:50:52.495] _job_complete: JobId=50460 WEXITSTATUS 0
[2022-10-11T11:50:52.495] _job_complete: JobId=50460 done
[2022-10-11T11:52:22.637] _slurm_rpc_submit_batch_job: JobId=50461 InitPrio=622 usec=458
[2022-10-11T11:52:23.191] sched: Allocate JobId=50461 NodeList=cpu10 #CPUs=64 Partition=cpu-opteron
[2022-10-11T11:52:24.487] _job_complete: JobId=50461 WEXITSTATUS 0
[2022-10-11T11:52:24.487] _job_complete: JobId=50461 done
[2022-10-11T11:53:27.128] _slurm_rpc_submit_batch_job: JobId=50462 InitPrio=622 usec=559
[2022-10-11T11:53:27.279] sched: Allocate JobId=50462 NodeList=cpu10 #CPUs=64 Partition=cpu-opteron
[2022-10-11T11:53:28.297] _job_complete: JobId=50462 WEXITSTATUS 0
[2022-10-11T11:53:28.297] _job_complete: JobId=50462 done
[2022-10-11T11:54:03.454] _job_complete: JobId=50414 WEXITSTATUS 0
[2022-10-11T11:54:03.459] _job_complete: JobId=50414 done
[2022-10-11T12:00:00.730] _slurm_rpc_submit_batch_job: JobId=50463 InitPrio=622 usec=462
[2022-10-11T12:00:00.921] sched: Allocate JobId=50463 NodeList=cpu01 #CPUs=32 Partition=cpu-opteron
[2022-10-11T12:00:02.009] _job_complete: JobId=50463 WEXITSTATUS 41
[2022-10-11T12:00:02.009] _job_complete: JobId=50463 done
[2022-10-11T12:00:31.939] _slurm_rpc_submit_batch_job: JobId=50464 InitPrio=622 usec=423
[2022-10-11T12:00:32.961] sched: Allocate JobId=50464 NodeList=cpu01 #CPUs=32 Partition=cpu-opteron
[2022-10-11T12:00:34.293] _job_complete: JobId=50464 WEXITSTATUS 0
[2022-10-11T12:00:34.294] _job_complete: JobId=50464 done
[2022-10-11T12:56:23.814] _slurm_rpc_submit_batch_job: JobId=50465 InitPrio=622 usec=555
[2022-10-11T12:56:23.876] sched: Allocate JobId=50465 NodeList=cpu01 #CPUs=1 Partition=cpu-opteron
[2022-10-11T12:56:24.932] _job_complete: JobId=50465 WEXITSTATUS 127
[2022-10-11T12:56:24.932] _job_complete: JobId=50465 done
[2022-10-11T12:59:22.081] _slurm_rpc_submit_batch_job: JobId=50466 InitPrio=622 usec=471
[2022-10-11T12:59:22.102] sched: Allocate JobId=50466 NodeList=cpu01 #CPUs=1 Partition=cpu-opteron
[2022-10-11T12:59:24.009] _job_complete: JobId=50466 WEXITSTATUS 127
[2022-10-11T12:59:24.009] _job_complete: JobId=50466 done
[2022-10-11T13:01:22.000] _slurm_rpc_submit_batch_job: JobId=50467 InitPrio=622 usec=460
[2022-10-11T13:01:22.345] sched: Allocate JobId=50467 NodeList=cpu01 #CPUs=1 Partition=cpu-opteron
[2022-10-11T13:01:23.502] _job_complete: JobId=50467 WEXITSTATUS 0
[2022-10-11T13:01:23.502] _job_complete: JobId=50467 done
[2022-10-11T13:03:56.741] _slurm_rpc_submit_batch_job: JobId=50468 InitPrio=622 usec=503
[2022-10-11T13:03:57.555] sched: Allocate JobId=50468 NodeList=cpu01 #CPUs=1 Partition=cpu-opteron
[2022-10-11T13:03:58.527] _job_complete: JobId=50468 WEXITSTATUS 0
[2022-10-11T13:03:58.527] _job_complete: JobId=50468 done
[2022-10-11T13:04:15.509] _slurm_rpc_submit_batch_job: JobId=50469 InitPrio=622 usec=531
[2022-10-11T13:04:15.579] sched: Allocate JobId=50469 NodeList=cpu01 #CPUs=1 Partition=cpu-opteron
[2022-10-11T13:04:16.454] _job_complete: JobId=50469 WEXITSTATUS 0
[2022-10-11T13:04:16.454] _job_complete: JobId=50469 done
[2022-10-11T13:06:09.938] _slurm_rpc_submit_batch_job: JobId=50470 InitPrio=622 usec=669
[2022-10-11T13:06:10.813] sched: Allocate JobId=50470 NodeList=cpu01 #CPUs=32 Partition=cpu-opteron
[2022-10-11T13:06:11.681] _job_complete: JobId=50470 WEXITSTATUS 41
[2022-10-11T13:06:11.681] _job_complete: JobId=50470 done
[2022-10-11T13:06:31.943] _slurm_rpc_submit_batch_job: JobId=50471 InitPrio=622 usec=450
[2022-10-11T13:06:32.851] sched: Allocate JobId=50471 NodeList=cpu01 #CPUs=32 Partition=cpu-opteron
[2022-10-11T13:06:35.182] _job_complete: JobId=50471 WEXITSTATUS 0
[2022-10-11T13:06:35.182] _job_complete: JobId=50471 done
[2022-10-11T13:28:07.075] _slurm_rpc_submit_batch_job: JobId=50472 InitPrio=414 usec=578
[2022-10-11T13:28:21.542] _slurm_rpc_kill_job: REQUEST_KILL_JOB JobId=50428 uid 548200021
[2022-10-11T13:28:29.696] sched: Allocate JobId=50472 NodeList=gpu02 #CPUs=16 Partition=gpu-titan
[2022-10-11T13:32:44.238] _slurm_rpc_submit_batch_job: JobId=50473 InitPrio=622 usec=502
[2022-10-11T13:32:44.469] sched: Allocate JobId=50473 NodeList=cpu10 #CPUs=64 Partition=cpu-opteron
[2022-10-11T13:33:48.314] _slurm_rpc_submit_batch_job: JobId=50474 InitPrio=622 usec=537
[2022-10-11T13:34:02.816] _slurm_rpc_kill_job: REQUEST_KILL_JOB JobId=50341 uid 548200023
[2022-10-11T13:34:05.303] sched: Allocate JobId=50474 NodeList=cpu04 #CPUs=64 Partition=cpu-opteron
[2022-10-11T13:34:05.571] _slurm_rpc_kill_job: REQUEST_KILL_JOB JobId=50340 uid 548200023
[2022-10-11T13:34:23.868] _slurm_rpc_kill_job: REQUEST_KILL_JOB JobId=50150 uid 548200023
[2022-10-11T13:34:25.808] sched: Allocate JobId=50433 NodeList=cpu13 #CPUs=8 Partition=cpu-epyc
[2022-10-11T13:34:25.809] sched: Allocate JobId=50434 NodeList=cpu13 #CPUs=8 Partition=cpu-epyc
[2022-10-11T13:34:25.809] sched: Allocate JobId=50435 NodeList=cpu13 #CPUs=8 Partition=cpu-epyc
[2022-10-11T13:34:25.810] sched: Allocate JobId=50436 NodeList=cpu13 #CPUs=8 Partition=cpu-epyc
[2022-10-11T13:34:25.811] sched: Allocate JobId=50437 NodeList=cpu13 #CPUs=8 Partition=cpu-epyc
[2022-10-11T13:34:25.812] sched: Allocate JobId=50438 NodeList=cpu13 #CPUs=8 Partition=cpu-epyc
[2022-10-11T13:49:47.930] _job_complete: JobId=50474 WEXITSTATUS 0
[2022-10-11T13:49:47.930] _job_complete: JobId=50474 done
[2022-10-11T14:15:15.306] _job_complete: JobId=50432 WEXITSTATUS 0
[2022-10-11T14:15:15.306] _job_complete: JobId=50432 done
[2022-10-11T14:15:16.334] sched: Allocate JobId=50439 NodeList=cpu14 #CPUs=8 Partition=cpu-epyc
[2022-10-11T14:15:52.729] _job_complete: JobId=50431 WEXITSTATUS 0
[2022-10-11T14:15:52.730] _job_complete: JobId=50431 done
[2022-10-11T14:15:53.345] sched: Allocate JobId=50440 NodeList=cpu14 #CPUs=8 Partition=cpu-epyc
[2022-10-11T14:22:25.755] _job_complete: JobId=50430 WEXITSTATUS 0
[2022-10-11T14:22:25.755] _job_complete: JobId=50430 done
[2022-10-11T14:22:26.348] sched: Allocate JobId=50441 NodeList=cpu14 #CPUs=8 Partition=cpu-epyc
[2022-10-11T14:27:40.967] _job_complete: JobId=50163 OOM failure
[2022-10-11T14:27:40.972] _job_complete: JobId=50163 done
[2022-10-11T14:27:42.874] sched: Allocate JobId=50442 NodeList=cpu12 #CPUs=8 Partition=cpu-epyc
[2022-10-11T14:27:42.875] sched: Allocate JobId=50443 NodeList=cpu12 #CPUs=8 Partition=cpu-epyc
[2022-10-11T14:27:42.876] sched: Allocate JobId=50444 NodeList=cpu12 #CPUs=8 Partition=cpu-epyc
[2022-10-11T14:27:42.877] sched: Allocate JobId=50446 NodeList=cpu12 #CPUs=8 Partition=cpu-epyc
[2022-10-11T14:27:42.877] sched: Allocate JobId=50447 NodeList=cpu12 #CPUs=8 Partition=cpu-epyc
[2022-10-11T14:27:42.878] sched: Allocate JobId=50448 NodeList=cpu12 #CPUs=8 Partition=cpu-epyc
[2022-10-11T14:27:48.866] _slurm_rpc_submit_batch_job: JobId=50475 InitPrio=1659 usec=542
[2022-10-11T14:27:49.066] sched: Allocate JobId=50475 NodeList=gpu04 #CPUs=16 Partition=gpu-k40c
[2022-10-11T14:38:14.167] _job_complete: JobId=50429 WEXITSTATUS 0
[2022-10-11T14:38:14.167] _job_complete: JobId=50429 done
[2022-10-11T14:38:14.756] sched: Allocate JobId=50449 NodeList=cpu14 #CPUs=8 Partition=cpu-epyc
[2022-10-11T15:15:28.243] _job_complete: JobId=50473 WEXITSTATUS 0
[2022-10-11T15:15:28.244] _job_complete: JobId=50473 done
[2022-10-11T15:21:21.341] _slurm_rpc_kill_job: REQUEST_KILL_JOB JobId=50375 uid 548300621
[2022-10-11T15:21:23.908] _slurm_rpc_kill_job: REQUEST_KILL_JOB JobId=50374 uid 548300621
[2022-10-11T15:21:26.501] _slurm_rpc_kill_job: REQUEST_KILL_JOB JobId=50373 uid 548300621
[2022-10-11T15:29:46.996] _slurm_rpc_submit_batch_job: JobId=50476 InitPrio=1037 usec=482
[2022-10-11T15:29:47.448] sched: Allocate JobId=50476 NodeList=cpu10 #CPUs=64 Partition=cpu-opteron
[2022-10-11T15:29:49.038] _slurm_rpc_submit_batch_job: JobId=50477 InitPrio=1037 usec=471
[2022-10-11T15:29:50.437] sched: Allocate JobId=50477 NodeList=cpu03 #CPUs=64 Partition=cpu-opteron
[2022-10-11T15:29:50.992] _slurm_rpc_submit_batch_job: JobId=50478 InitPrio=1037 usec=650
[2022-10-11T15:29:53.441] sched: Allocate JobId=50478 NodeList=cpu04 #CPUs=64 Partition=cpu-opteron
[2022-10-11T15:37:55.075] _slurm_rpc_submit_batch_job: JobId=50479 InitPrio=622 usec=456
[2022-10-11T15:37:55.281] sched: Allocate JobId=50479 NodeList=cpu01 #CPUs=8 Partition=cpu-opteron
[2022-10-11T15:37:56.669] _job_complete: JobId=50479 WEXITSTATUS 1
[2022-10-11T15:37:56.669] _job_complete: JobId=50479 done
[2022-10-11T15:45:23.084] _slurm_rpc_submit_batch_job: JobId=50480 InitPrio=622 usec=476
[2022-10-11T15:45:23.963] sched: Allocate JobId=50480 NodeList=cpu05 #CPUs=64 Partition=cpu-opteron
[2022-10-11T15:47:46.657] _slurm_rpc_submit_batch_job: JobId=50481 InitPrio=622 usec=467
[2022-10-11T15:47:47.255] sched: Allocate JobId=50481 NodeList=cpu07 #CPUs=64 Partition=cpu-opteron
[2022-10-11T15:49:09.760] _job_complete: JobId=50437 WEXITSTATUS 0
[2022-10-11T15:49:09.760] _job_complete: JobId=50437 done
[2022-10-11T15:49:10.138] sched: Allocate JobId=50450 NodeList=cpu13 #CPUs=8 Partition=cpu-epyc
[2022-10-11T15:49:36.675] _job_complete: JobId=50481 WEXITSTATUS 0
[2022-10-11T15:49:36.675] _job_complete: JobId=50481 done
[2022-10-11T15:50:33.006] _job_complete: JobId=50433 WEXITSTATUS 0
[2022-10-11T15:50:33.006] _job_complete: JobId=50433 done
[2022-10-11T15:50:33.291] sched: Allocate JobId=50451 NodeList=cpu13 #CPUs=8 Partition=cpu-epyc
[2022-10-11T15:51:51.025] _job_complete: JobId=50480 WEXITSTATUS 0
[2022-10-11T15:51:51.025] _job_complete: JobId=50480 done
[2022-10-11T15:58:03.256] _job_complete: JobId=50438 WEXITSTATUS 0
[2022-10-11T15:58:03.256] _job_complete: JobId=50438 done
[2022-10-11T15:58:03.618] sched: Allocate JobId=50452 NodeList=cpu13 #CPUs=8 Partition=cpu-epyc
[2022-10-11T15:59:45.270] _slurm_rpc_submit_batch_job: JobId=50482 InitPrio=622 usec=412
[2022-10-11T15:59:45.496] sched: Allocate JobId=50482 NodeList=cpu01 #CPUs=8 Partition=cpu-opteron
[2022-10-11T15:59:49.039] _job_complete: JobId=50482 WEXITSTATUS 0
[2022-10-11T15:59:49.039] _job_complete: JobId=50482 done
[2022-10-11T16:00:28.784] _slurm_rpc_submit_batch_job: JobId=50483 InitPrio=622 usec=860
[2022-10-11T16:00:29.552] sched: Allocate JobId=50483 NodeList=cpu01 #CPUs=8 Partition=cpu-opteron
[2022-10-11T16:00:31.802] _job_complete: JobId=50483 WEXITSTATUS 0
[2022-10-11T16:00:31.802] _job_complete: JobId=50483 done
[2022-10-11T16:20:40.383] _slurm_rpc_submit_batch_job: JobId=50484 InitPrio=622 usec=575
[2022-10-11T16:20:40.820] sched: Allocate JobId=50484 NodeList=cpu05 #CPUs=64 Partition=cpu-opteron
[2022-10-11T16:20:42.870] _job_complete: JobId=50484 WEXITSTATUS 0
[2022-10-11T16:20:42.870] _job_complete: JobId=50484 done
[2022-10-11T16:35:00.074] _slurm_rpc_submit_batch_job: JobId=50485 InitPrio=622 usec=501
[2022-10-11T16:35:00.282] sched: Allocate JobId=50485 NodeList=cpu05 #CPUs=64 Partition=cpu-opteron
[2022-10-11T16:35:01.238] _job_complete: JobId=50485 WEXITSTATUS 0
[2022-10-11T16:35:01.238] _job_complete: JobId=50485 done
[2022-10-11T16:36:29.756] _slurm_rpc_submit_batch_job: JobId=50486 InitPrio=622 usec=470
[2022-10-11T16:36:30.535] sched: Allocate JobId=50486 NodeList=cpu05 #CPUs=64 Partition=cpu-opteron
[2022-10-11T16:36:31.504] _job_complete: JobId=50486 WEXITSTATUS 0
[2022-10-11T16:36:31.504] _job_complete: JobId=50486 done
[2022-10-11T16:37:01.389] _slurm_rpc_submit_batch_job: JobId=50487 InitPrio=622 usec=471
[2022-10-11T16:37:01.578] sched: Allocate JobId=50487 NodeList=cpu05 #CPUs=64 Partition=cpu-opteron
[2022-10-11T16:37:02.883] _job_complete: JobId=50487 WEXITSTATUS 0
[2022-10-11T16:37:02.883] _job_complete: JobId=50487 done
[2022-10-11T16:37:32.127] _slurm_rpc_submit_batch_job: JobId=50488 InitPrio=622 usec=464
[2022-10-11T16:37:33.622] sched: Allocate JobId=50488 NodeList=cpu05 #CPUs=64 Partition=cpu-opteron
[2022-10-11T16:37:34.478] _job_complete: JobId=50488 WEXITSTATUS 0
[2022-10-11T16:37:34.478] _job_complete: JobId=50488 done
[2022-10-11T16:39:36.273] _slurm_rpc_submit_batch_job: JobId=50489 InitPrio=622 usec=439
[2022-10-11T16:39:36.787] sched: Allocate JobId=50489 NodeList=cpu01 #CPUs=32 Partition=cpu-opteron
[2022-10-11T16:39:38.613] _job_complete: JobId=50489 WEXITSTATUS 31
[2022-10-11T16:39:38.613] _job_complete: JobId=50489 done
[2022-10-11T16:41:02.311] _slurm_rpc_submit_batch_job: JobId=50490 InitPrio=622 usec=431
[2022-10-11T16:41:02.943] sched: Allocate JobId=50490 NodeList=cpu01 #CPUs=32 Partition=cpu-opteron
[2022-10-11T16:41:04.638] _job_complete: JobId=50490 WEXITSTATUS 1
[2022-10-11T16:41:04.638] _job_complete: JobId=50490 done
[2022-10-11T16:42:31.611] _job_complete: JobId=50447 WEXITSTATUS 0
[2022-10-11T16:42:31.611] _job_complete: JobId=50447 done
[2022-10-11T16:42:31.887] sched: Allocate JobId=50453 NodeList=cpu12 #CPUs=8 Partition=cpu-epyc
[2022-10-11T16:44:36.322] _job_complete: JobId=50439 WEXITSTATUS 0
[2022-10-11T16:44:36.322] _job_complete: JobId=50439 done
[2022-10-11T16:44:37.118] sched: Allocate JobId=50454 NodeList=cpu14 #CPUs=8 Partition=cpu-epyc
[2022-10-11T16:46:30.966] _job_complete: JobId=50448 WEXITSTATUS 0
[2022-10-11T16:46:30.966] _job_complete: JobId=50448 done
[2022-10-11T16:46:31.281] sched: Allocate JobId=50455 NodeList=cpu12 #CPUs=8 Partition=cpu-epyc
[2022-10-11T16:46:46.322] _slurm_rpc_submit_batch_job: JobId=50491 InitPrio=622 usec=462
[2022-10-11T16:46:46.583] sched: Allocate JobId=50491 NodeList=cpu01 #CPUs=32 Partition=cpu-opteron
[2022-10-11T16:46:48.597] _job_complete: JobId=50491 WEXITSTATUS 0
[2022-10-11T16:46:48.597] _job_complete: JobId=50491 done
[2022-10-11T16:51:18.155] _job_complete: JobId=50441 WEXITSTATUS 0
[2022-10-11T16:51:18.156] _job_complete: JobId=50441 done
[2022-10-11T16:51:20.313] sched: Allocate JobId=50456 NodeList=cpu14 #CPUs=8 Partition=cpu-epyc
[2022-10-11T16:52:36.650] _job_complete: JobId=50446 WEXITSTATUS 0
[2022-10-11T16:52:36.651] _job_complete: JobId=50446 done
[2022-10-11T16:52:36.967] sched: Allocate JobId=50457 NodeList=cpu12 #CPUs=8 Partition=cpu-epyc
[2022-10-11T16:53:42.157] _job_complete: JobId=50443 WEXITSTATUS 0
[2022-10-11T16:53:42.158] _job_complete: JobId=50443 done
[2022-10-11T16:53:42.458] sched: Allocate JobId=50458 NodeList=cpu12 #CPUs=8 Partition=cpu-epyc
[2022-10-11T16:55:40.047] _job_complete: JobId=50434 WEXITSTATUS 0
[2022-10-11T16:55:40.047] _job_complete: JobId=50434 done
[2022-10-11T16:55:40.379] sched: Allocate JobId=50459 NodeList=cpu13 #CPUs=8 Partition=cpu-epyc
[2022-10-11T16:56:14.762] _job_complete: JobId=50440 WEXITSTATUS 0
[2022-10-11T16:56:14.762] _job_complete: JobId=50440 done
[2022-10-11T16:56:22.252] _job_complete: JobId=50442 WEXITSTATUS 0
[2022-10-11T16:56:22.252] _job_complete: JobId=50442 done
[2022-10-11T16:57:28.959] _job_complete: JobId=50444 WEXITSTATUS 0
[2022-10-11T16:57:28.959] _job_complete: JobId=50444 done
[2022-10-11T17:19:51.300] _slurm_rpc_submit_batch_job: JobId=50492 InitPrio=622 usec=470
[2022-10-11T17:19:52.038] sched: Allocate JobId=50492 NodeList=cpu01 #CPUs=32 Partition=cpu-opteron
[2022-10-11T17:19:53.700] _job_complete: JobId=50492 WEXITSTATUS 1
[2022-10-11T17:19:53.700] _job_complete: JobId=50492 done
[2022-10-11T17:31:29.775] _job_complete: JobId=50449 WEXITSTATUS 0
[2022-10-11T17:31:29.775] _job_complete: JobId=50449 done
[2022-10-11T17:31:53.686] _job_complete: JobId=50435 WEXITSTATUS 0
[2022-10-11T17:31:53.686] _job_complete: JobId=50435 done
[2022-10-11T17:58:10.572] _job_complete: JobId=50436 WEXITSTATUS 0
[2022-10-11T17:58:10.572] _job_complete: JobId=50436 done
[2022-10-11T18:01:31.880] _slurm_rpc_submit_batch_job: JobId=50493 InitPrio=622 usec=500
[2022-10-11T18:01:33.511] sched: Allocate JobId=50493 NodeList=cpu01 #CPUs=32 Partition=cpu-opteron
[2022-10-11T18:01:35.245] _job_complete: JobId=50493 WEXITSTATUS 1
[2022-10-11T18:01:35.245] _job_complete: JobId=50493 done
[2022-10-11T18:11:09.875] _slurm_rpc_submit_batch_job: JobId=50494 InitPrio=622 usec=557
[2022-10-11T18:11:10.496] sched: Allocate JobId=50494 NodeList=cpu01 #CPUs=32 Partition=cpu-opteron
[2022-10-11T18:11:12.190] _job_complete: JobId=50494 WEXITSTATUS 1
[2022-10-11T18:11:12.190] _job_complete: JobId=50494 done
[2022-10-11T18:18:47.500] _job_complete: JobId=50450 WEXITSTATUS 0
[2022-10-11T18:18:47.500] _job_complete: JobId=50450 done
[2022-10-11T18:41:03.406] _job_complete: JobId=50472 WEXITSTATUS 1
[2022-10-11T18:41:03.407] _job_complete: JobId=50472 done
[2022-10-11T18:55:56.518] _job_complete: JobId=50454 WEXITSTATUS 0
[2022-10-11T18:55:56.518] _job_complete: JobId=50454 done
[2022-10-11T19:06:36.061] _job_complete: JobId=50459 WEXITSTATUS 0
[2022-10-11T19:06:36.061] _job_complete: JobId=50459 done
[2022-10-11T19:06:45.217] _job_complete: JobId=50453 WEXITSTATUS 0
[2022-10-11T19:06:45.217] _job_complete: JobId=50453 done
[2022-10-11T19:08:13.209] _job_complete: JobId=50456 WEXITSTATUS 0
[2022-10-11T19:08:13.209] _job_complete: JobId=50456 done
[2022-10-11T19:10:49.591] _job_complete: JobId=50457 WEXITSTATUS 0
[2022-10-11T19:10:49.591] _job_complete: JobId=50457 done
[2022-10-11T19:12:29.113] _job_complete: JobId=50458 WEXITSTATUS 0
[2022-10-11T19:12:29.113] _job_complete: JobId=50458 done
[2022-10-11T19:28:22.082] _job_complete: JobId=50452 WEXITSTATUS 0
[2022-10-11T19:28:22.082] _job_complete: JobId=50452 done
[2022-10-11T19:38:54.229] _job_complete: JobId=50451 WEXITSTATUS 0
[2022-10-11T19:38:54.229] _job_complete: JobId=50451 done
[2022-10-11T20:13:55.143] _job_complete: JobId=50455 WEXITSTATUS 0
[2022-10-11T20:13:55.143] _job_complete: JobId=50455 done
[2022-10-11T20:40:40.867] _job_complete: JobId=50426 WEXITSTATUS 0
[2022-10-11T20:40:40.872] _job_complete: JobId=50426 done
[2022-10-11T21:18:27.034] _slurm_rpc_submit_batch_job: JobId=50495 InitPrio=414 usec=760
[2022-10-11T21:18:27.354] sched: Allocate JobId=50495 NodeList=gpu02 #CPUs=16 Partition=gpu-titan
[2022-10-11T22:20:24.049] _slurm_rpc_submit_batch_job: JobId=50496 InitPrio=7468 usec=424
[2022-10-11T22:20:24.884] sched: Allocate JobId=50496 NodeList=cpu01 #CPUs=1 Partition=cpu-opteron
[2022-10-11T22:30:04.566] _slurm_rpc_submit_batch_job: JobId=50497 InitPrio=622 usec=458
[2022-10-11T22:30:04.840] sched: Allocate JobId=50497 NodeList=cpu05 #CPUs=64 Partition=cpu-opteron
[2022-10-11T22:32:50.781] _job_complete: JobId=50497 WEXITSTATUS 0
[2022-10-11T22:32:50.781] _job_complete: JobId=50497 done
[2022-10-11T22:36:26.770] _job_complete: JobId=50496 WEXITSTATUS 0
[2022-10-11T22:36:26.771] _job_complete: JobId=50496 done
[2022-10-11T23:08:14.389] _slurm_rpc_submit_batch_job: JobId=50498 InitPrio=622 usec=510
[2022-10-11T23:08:14.801] sched: Allocate JobId=50498 NodeList=cpu05 #CPUs=64 Partition=cpu-opteron
[2022-10-11T23:08:15.741] _job_complete: JobId=50498 WEXITSTATUS 0
[2022-10-11T23:08:15.741] _job_complete: JobId=50498 done
[2022-10-11T23:08:27.061] _slurm_rpc_submit_batch_job: JobId=50499 InitPrio=622 usec=503
[2022-10-11T23:08:27.814] sched: Allocate JobId=50499 NodeList=cpu05 #CPUs=64 Partition=cpu-opteron
[2022-10-11T23:08:28.882] _job_complete: JobId=50499 WEXITSTATUS 0
[2022-10-11T23:08:28.882] _job_complete: JobId=50499 done
[2022-10-11T23:10:33.295] _slurm_rpc_submit_batch_job: JobId=50500 InitPrio=622 usec=411
[2022-10-11T23:10:33.983] sched: Allocate JobId=50500 NodeList=cpu01 #CPUs=32 Partition=cpu-opteron
[2022-10-11T23:10:36.025] _job_complete: JobId=50500 WEXITSTATUS 0
[2022-10-11T23:10:36.025] _job_complete: JobId=50500 done
[2022-10-11T23:24:25.204] _job_complete: JobId=50190 OOM failure
[2022-10-11T23:24:25.204] _job_complete: JobId=50190 done
[2022-10-11T23:33:11.140] _slurm_rpc_submit_batch_job: JobId=50501 InitPrio=622 usec=686
[2022-10-11T23:33:11.358] sched: Allocate JobId=50501 NodeList=cpu01 #CPUs=32 Partition=cpu-opteron
[2022-10-11T23:33:13.460] _job_complete: JobId=50501 WEXITSTATUS 0
[2022-10-11T23:33:13.460] _job_complete: JobId=50501 done
[2022-10-11T23:59:17.409] _slurm_rpc_submit_batch_job: JobId=50502 InitPrio=1867 usec=1018
[2022-10-11T23:59:28.079] _slurm_rpc_kill_job: REQUEST_KILL_JOB JobId=50425 uid 548200029
[2022-10-11T23:59:32.964] sched: Allocate JobId=50502 NodeList=gpu01 #CPUs=16 Partition=gpu-k10
[2022-10-12T02:33:17.960] _job_complete: JobId=50502 WEXITSTATUS 1
[2022-10-12T02:33:17.966] _job_complete: JobId=50502 done
[2022-10-12T04:59:59.902] _job_complete: JobId=50427 WEXITSTATUS 1
[2022-10-12T04:59:59.903] _job_complete: JobId=50427 done
[2022-10-12T08:57:25.064] _job_complete: JobId=50477 WEXITSTATUS 0
[2022-10-12T08:57:25.064] _job_complete: JobId=50477 done
[2022-10-12T09:12:42.275] _slurm_rpc_submit_batch_job: JobId=50503 InitPrio=2074 usec=1036
[2022-10-12T09:12:42.845] sched: Allocate JobId=50503 NodeList=gpu01 #CPUs=16 Partition=gpu-k10
[2022-10-12T09:27:46.102] _slurm_rpc_submit_batch_job: JobId=50504 InitPrio=622 usec=894
[2022-10-12T09:27:46.374] sched: Allocate JobId=50504 NodeList=cpu12 #CPUs=48 Partition=cpu-epyc
[2022-10-12T09:29:44.517] _slurm_rpc_submit_batch_job: JobId=50505 InitPrio=622 usec=451
[2022-10-12T09:29:45.509] sched: Allocate JobId=50505 NodeList=cpu13 #CPUs=48 Partition=cpu-epyc
[2022-10-12T09:31:22.381] _slurm_rpc_submit_batch_job: JobId=50506 InitPrio=622 usec=422
[2022-10-12T09:33:03.167] _slurm_rpc_submit_batch_job: JobId=50507 InitPrio=622 usec=472
[2022-10-12T09:33:41.316] _slurm_rpc_submit_batch_job: JobId=50508 InitPrio=622 usec=481
[2022-10-12T09:54:52.009] _slurm_rpc_kill_job: REQUEST_KILL_JOB JobId=50495 uid 548200021
[2022-10-12T09:54:57.809] _slurm_rpc_kill_job: REQUEST_KILL_JOB JobId=50495 uid 548200021
[2022-10-12T09:56:01.296] _pick_best_nodes: JobId=50509 never runnable in partition gpu-titan
[2022-10-12T09:56:01.296] _slurm_rpc_submit_batch_job: Requested node configuration is not available
[2022-10-12T09:56:56.628] _slurm_rpc_submit_batch_job: JobId=50510 InitPrio=414 usec=447
[2022-10-12T09:56:57.213] sched: Allocate JobId=50510 NodeList=gpu02 #CPUs=16 Partition=gpu-titan
[2022-10-12T10:08:32.039] _job_complete: JobId=50421 WEXITSTATUS 0
[2022-10-12T10:08:32.045] _job_complete: JobId=50421 done
[2022-10-12T10:23:05.208] _slurm_rpc_submit_batch_job: JobId=50511 InitPrio=2074 usec=455
[2022-10-12T10:23:05.974] sched: Allocate JobId=50511 NodeList=cpu11 #CPUs=16 Partition=cpu-opteron
[2022-10-12T10:23:09.278] _job_complete: JobId=50511 WEXITSTATUS 1
[2022-10-12T10:23:09.279] _job_complete: JobId=50511 done
[2022-10-12T10:26:51.451] _slurm_rpc_submit_batch_job: JobId=50512 InitPrio=49377 usec=560
[2022-10-12T10:26:52.379] sched: Allocate JobId=50512 NodeList=cpu15 #CPUs=48 Partition=cpu-epyc
[2022-10-12T10:27:46.744] _slurm_rpc_submit_batch_job: JobId=50513 InitPrio=49377 usec=451
[2022-10-12T10:28:25.474] _slurm_rpc_submit_batch_job: JobId=50514 InitPrio=49377 usec=525
[2022-10-12T10:37:31.675] _slurm_rpc_submit_batch_job: JobId=50515 InitPrio=2074 usec=424
[2022-10-12T10:37:33.481] sched: Allocate JobId=50515 NodeList=cpu11 #CPUs=16 Partition=cpu-opteron
[2022-10-12T10:37:39.244] _job_complete: JobId=50515 WEXITSTATUS 0
[2022-10-12T10:37:39.245] _job_complete: JobId=50515 done
[2022-10-12T10:41:54.922] _slurm_rpc_submit_batch_job: JobId=50516 InitPrio=4356 usec=506
[2022-10-12T10:41:54.981] sched: Allocate JobId=50516 NodeList=cpu11 #CPUs=16 Partition=cpu-opteron
[2022-10-12T10:41:56.559] _job_complete: JobId=50516 WEXITSTATUS 0
[2022-10-12T10:41:56.559] _job_complete: JobId=50516 done
[2022-10-12T10:52:59.325] _slurm_rpc_submit_batch_job: JobId=50517 InitPrio=4356 usec=639
[2022-10-12T10:53:00.125] sched: Allocate JobId=50517 NodeList=cpu11 #CPUs=16 Partition=cpu-opteron
[2022-10-12T10:53:01.359] _job_complete: JobId=50517 WEXITSTATUS 0
[2022-10-12T10:53:01.359] _job_complete: JobId=50517 done
[2022-10-12T10:56:21.746] _slurm_rpc_submit_batch_job: JobId=50518 InitPrio=2074 usec=705
[2022-10-12T10:56:22.563] sched: Allocate JobId=50518 NodeList=cpu11 #CPUs=16 Partition=cpu-opteron
[2022-10-12T10:56:24.243] _job_complete: JobId=50518 WEXITSTATUS 2
[2022-10-12T10:56:24.244] _job_complete: JobId=50518 done
[2022-10-12T11:13:46.140] _slurm_rpc_submit_batch_job: JobId=50519 InitPrio=2074 usec=451
[2022-10-12T11:13:46.277] sched: Allocate JobId=50519 NodeList=cpu11 #CPUs=16 Partition=cpu-opteron
[2022-10-12T11:13:50.193] _job_complete: JobId=50519 WEXITSTATUS 0
[2022-10-12T11:13:50.193] _job_complete: JobId=50519 done
[2022-10-12T11:16:51.941] _slurm_rpc_submit_batch_job: JobId=50520 InitPrio=2074 usec=466
[2022-10-12T11:16:52.610] sched: Allocate JobId=50520 NodeList=cpu11 #CPUs=32 Partition=cpu-opteron
[2022-10-12T11:16:56.590] _job_complete: JobId=50520 WEXITSTATUS 0
[2022-10-12T11:16:56.591] _job_complete: JobId=50520 done
[2022-10-12T11:22:37.915] _slurm_rpc_submit_batch_job: JobId=50521 InitPrio=622 usec=455
[2022-10-12T11:22:59.645] _slurm_rpc_kill_job: REQUEST_KILL_JOB JobId=50521 uid 548200023
[2022-10-12T11:23:31.513] _slurm_rpc_submit_batch_job: JobId=50522 InitPrio=622 usec=550
[2022-10-12T11:23:33.274] sched: Allocate JobId=50522 NodeList=cpu11 #CPUs=4 Partition=cpu-opteron
[2022-10-12T11:23:34.802] _job_complete: JobId=50522 WEXITSTATUS 0
[2022-10-12T11:23:34.803] _job_complete: JobId=50522 done
[2022-10-12T11:24:15.027] _slurm_rpc_submit_batch_job: JobId=50523 InitPrio=622 usec=472
[2022-10-12T11:24:15.310] sched: Allocate JobId=50523 NodeList=cpu11 #CPUs=4 Partition=cpu-opteron
[2022-10-12T11:24:58.867] _job_complete: JobId=50523 WEXITSTATUS 0
[2022-10-12T11:24:58.867] _job_complete: JobId=50523 done
[2022-10-12T11:25:41.084] _slurm_rpc_submit_batch_job: JobId=50524 InitPrio=622 usec=460
[2022-10-12T11:26:18.248] _slurm_rpc_kill_job: REQUEST_KILL_JOB JobId=50524 uid 548200023
[2022-10-12T11:26:32.455] _slurm_rpc_submit_batch_job: JobId=50525 InitPrio=622 usec=445
[2022-10-12T11:27:45.997] _slurm_rpc_kill_job: REQUEST_KILL_JOB JobId=50525 uid 548200023
[2022-10-12T11:28:00.615] _slurm_rpc_submit_batch_job: JobId=50526 InitPrio=622 usec=487
[2022-10-12T11:28:31.600] _slurm_rpc_kill_job: REQUEST_KILL_JOB JobId=50526 uid 548200023
[2022-10-12T11:28:50.948] _slurm_rpc_submit_batch_job: JobId=50527 InitPrio=622 usec=419
[2022-10-12T11:32:08.816] _slurm_rpc_submit_batch_job: JobId=50528 InitPrio=622 usec=471
[2022-10-12T11:32:09.140] sched: Allocate JobId=50528 NodeList=cpu03 #CPUs=64 Partition=cpu-opteron
[2022-10-12T11:32:11.019] _job_complete: JobId=50528 WEXITSTATUS 0
[2022-10-12T11:32:11.019] _job_complete: JobId=50528 done
[2022-10-12T11:32:19.137] _slurm_rpc_submit_batch_job: JobId=50529 InitPrio=622 usec=625
[2022-10-12T11:32:19.151] sched: Allocate JobId=50529 NodeList=cpu03 #CPUs=64 Partition=cpu-opteron
[2022-10-12T11:32:20.103] _job_complete: JobId=50529 WEXITSTATUS 0
[2022-10-12T11:32:20.103] _job_complete: JobId=50529 done
[2022-10-12T11:33:38.049] _slurm_rpc_submit_batch_job: JobId=50530 InitPrio=622 usec=560
[2022-10-12T11:33:38.258] sched: Allocate JobId=50530 NodeList=cpu11 #CPUs=32 Partition=cpu-opteron
[2022-10-12T11:33:40.335] _job_complete: JobId=50530 WEXITSTATUS 0
[2022-10-12T11:33:40.335] _job_complete: JobId=50530 done
[2022-10-12T11:33:49.708] _job_complete: JobId=50475 WEXITSTATUS 0
[2022-10-12T11:33:49.714] _job_complete: JobId=50475 done
[2022-10-12T11:34:48.527] _slurm_rpc_submit_batch_job: JobId=50531 InitPrio=622 usec=478
[2022-10-12T11:34:49.351] sched: Allocate JobId=50531 NodeList=cpu11 #CPUs=32 Partition=cpu-opteron
[2022-10-12T11:34:50.971] _job_complete: JobId=50531 WEXITSTATUS 0
[2022-10-12T11:34:50.971] _job_complete: JobId=50531 done
[2022-10-12T11:51:14.782] _slurm_rpc_submit_batch_job: JobId=50532 InitPrio=622 usec=480
[2022-10-12T11:51:15.167] sched: Allocate JobId=50532 NodeList=cpu11 #CPUs=32 Partition=cpu-opteron
[2022-10-12T11:51:16.845] _job_complete: JobId=50532 WEXITSTATUS 1
[2022-10-12T11:51:16.845] _job_complete: JobId=50532 done
[2022-10-12T12:45:35.431] _slurm_rpc_submit_batch_job: JobId=50533 InitPrio=2904 usec=453
[2022-10-12T12:51:59.851] _slurm_rpc_submit_batch_job: JobId=50534 InitPrio=1452 usec=464
[2022-10-12T12:52:00.639] sched: Allocate JobId=50534 NodeList=gpu04 #CPUs=16 Partition=gpu-k40c
[2022-10-12T12:53:34.644] _slurm_rpc_submit_batch_job: JobId=50535 InitPrio=622 usec=517
[2022-10-12T12:53:34.755] sched: Allocate JobId=50535 NodeList=cpu03 #CPUs=64 Partition=cpu-opteron
[2022-10-12T13:50:26.599] _job_complete: JobId=50535 WEXITSTATUS 0
[2022-10-12T13:50:26.599] _job_complete: JobId=50535 done
[2022-10-12T15:47:52.223] _job_complete: JobId=50503 WEXITSTATUS 1
[2022-10-12T15:47:52.228] _job_complete: JobId=50503 done
[2022-10-12T15:54:31.287] _slurm_rpc_submit_batch_job: JobId=50536 InitPrio=622 usec=637
[2022-10-12T15:54:31.766] sched: Allocate JobId=50536 NodeList=cpu11 #CPUs=8 Partition=cpu-opteron
[2022-10-12T15:54:40.994] _job_complete: JobId=50536 WEXITSTATUS 0
[2022-10-12T15:54:40.994] _job_complete: JobId=50536 done
[2022-10-12T15:54:54.847] _slurm_rpc_submit_batch_job: JobId=50537 InitPrio=622 usec=505
[2022-10-12T15:54:55.779] sched: Allocate JobId=50537 NodeList=cpu03 #CPUs=64 Partition=cpu-opteron
[2022-10-12T15:54:57.738] _job_complete: JobId=50537 WEXITSTATUS 0
[2022-10-12T15:54:57.738] _job_complete: JobId=50537 done
[2022-10-12T15:55:47.909] _slurm_rpc_submit_batch_job: JobId=50538 InitPrio=622 usec=435
[2022-10-12T15:55:48.854] sched: Allocate JobId=50538 NodeList=cpu03 #CPUs=64 Partition=cpu-opteron
[2022-10-12T15:55:49.673] _job_complete: JobId=50538 WEXITSTATUS 0
[2022-10-12T15:55:49.673] _job_complete: JobId=50538 done
[2022-10-12T15:57:09.791] _slurm_rpc_submit_batch_job: JobId=50539 InitPrio=622 usec=531
[2022-10-12T15:57:10.080] sched: Allocate JobId=50539 NodeList=cpu11 #CPUs=1 Partition=cpu-opteron
[2022-10-12T15:57:11.474] _job_complete: JobId=50539 WEXITSTATUS 0
[2022-10-12T15:57:11.474] _job_complete: JobId=50539 done
[2022-10-12T16:01:54.765] _slurm_rpc_submit_batch_job: JobId=50540 InitPrio=622 usec=508
[2022-10-12T16:01:55.620] sched: Allocate JobId=50540 NodeList=cpu11 #CPUs=32 Partition=cpu-opteron
[2022-10-12T16:01:57.576] _job_complete: JobId=50540 WEXITSTATUS 0
[2022-10-12T16:01:57.576] _job_complete: JobId=50540 done
[2022-10-12T16:04:44.147] _slurm_rpc_submit_batch_job: JobId=50541 InitPrio=622 usec=557
[2022-10-12T16:04:44.858] sched: Allocate JobId=50541 NodeList=cpu11 #CPUs=32 Partition=cpu-opteron
[2022-10-12T16:04:47.403] _job_complete: JobId=50541 WEXITSTATUS 0
[2022-10-12T16:04:47.403] _job_complete: JobId=50541 done
[2022-10-12T16:05:57.347] _slurm_rpc_submit_batch_job: JobId=50542 InitPrio=622 usec=427
[2022-10-12T16:05:57.955] sched: Allocate JobId=50542 NodeList=cpu11 #CPUs=32 Partition=cpu-opteron
[2022-10-12T16:05:59.932] _job_complete: JobId=50542 WEXITSTATUS 0
[2022-10-12T16:05:59.932] _job_complete: JobId=50542 done
[2022-10-12T16:19:22.444] _slurm_rpc_submit_batch_job: JobId=50543 InitPrio=2074 usec=947
[2022-10-12T16:19:23.368] sched: Allocate JobId=50543 NodeList=gpu01 #CPUs=16 Partition=gpu-k10
[2022-10-12T17:28:33.608] _slurm_rpc_kill_job: REQUEST_KILL_JOB JobId=50543 uid 548200029
[2022-10-12T17:29:22.484] _slurm_rpc_submit_batch_job: JobId=50544 InitPrio=2074 usec=796
[2022-10-12T17:29:22.533] sched: Allocate JobId=50544 NodeList=gpu01 #CPUs=16 Partition=gpu-k10
[2022-10-12T17:30:23.616] _slurm_rpc_submit_batch_job: JobId=50545 InitPrio=2074 usec=383
[2022-10-12T17:30:24.611] sched: Allocate JobId=50545 NodeList=cpu11 #CPUs=16 Partition=cpu-opteron
[2022-10-12T17:31:01.470] _job_complete: JobId=50545 WEXITSTATUS 0
[2022-10-12T17:31:01.471] _job_complete: JobId=50545 done
[2022-10-12T17:31:44.740] _slurm_rpc_submit_batch_job: JobId=50546 InitPrio=2074 usec=463
[2022-10-12T17:31:44.821] sched: Allocate JobId=50546 NodeList=cpu11 #CPUs=16 Partition=cpu-opteron
[2022-10-12T17:31:50.709] _job_complete: JobId=50546 WEXITSTATUS 0
[2022-10-12T17:31:50.710] _job_complete: JobId=50546 done
[2022-10-12T17:32:20.120] _slurm_rpc_submit_batch_job: JobId=50547 InitPrio=2074 usec=465
[2022-10-12T17:32:20.873] sched: Allocate JobId=50547 NodeList=cpu11 #CPUs=32 Partition=cpu-opteron
[2022-10-12T17:32:27.018] _job_complete: JobId=50547 WEXITSTATUS 0
[2022-10-12T17:32:27.018] _job_complete: JobId=50547 done
[2022-10-12T18:17:01.789] _job_complete: JobId=50512 WEXITSTATUS 0
[2022-10-12T18:17:01.789] _job_complete: JobId=50512 done
[2022-10-12T18:17:02.286] sched: Allocate JobId=50513 NodeList=cpu15 #CPUs=48 Partition=cpu-epyc
[2022-10-12T19:40:36.506] _slurm_rpc_submit_batch_job: JobId=50548 InitPrio=1867 usec=693
[2022-10-12T20:01:32.320] _job_complete: JobId=50478 WEXITSTATUS 0
[2022-10-12T20:01:32.320] _job_complete: JobId=50478 done
[2022-10-12T20:14:31.012] sched: _slurm_rpc_allocate_resources JobId=50549 NodeList=(null) usec=1057
[2022-10-12T20:14:31.951] sched: Allocate JobId=50549 NodeList=cpu11 #CPUs=16 Partition=cpu-opteron
[2022-10-12T20:19:07.745] _job_complete: JobId=50549 WEXITSTATUS 0
[2022-10-12T20:19:07.745] _job_complete: JobId=50549 done
[2022-10-12T22:44:55.331] _slurm_rpc_submit_batch_job: JobId=50550 InitPrio=13734 usec=482
[2022-10-12T22:44:57.612] _slurm_rpc_submit_batch_job: JobId=50551 InitPrio=13734 usec=435
[2022-10-12T22:44:59.634] _slurm_rpc_submit_batch_job: JobId=50552 InitPrio=13734 usec=452
[2022-10-12T22:45:01.409] _slurm_rpc_submit_batch_job: JobId=50553 InitPrio=13734 usec=398
[2022-10-12T22:45:03.068] _slurm_rpc_submit_batch_job: JobId=50554 InitPrio=13734 usec=391
[2022-10-12T22:45:05.165] _slurm_rpc_submit_batch_job: JobId=50555 InitPrio=13734 usec=476
[2022-10-12T22:45:07.763] _slurm_rpc_submit_batch_job: JobId=50556 InitPrio=13734 usec=438
[2022-10-12T22:58:18.674] _slurm_rpc_submit_batch_job: JobId=50557 InitPrio=13734 usec=401
[2022-10-12T23:20:58.101] _slurm_rpc_kill_job: REQUEST_KILL_JOB JobId=50476 uid 548300621
[2022-10-12T23:20:59.005] _slurm_rpc_kill_job: REQUEST_KILL_JOB JobId=50476 uid 548300621
[2022-10-12T23:21:31.742] _slurm_rpc_submit_batch_job: JobId=50558 InitPrio=829 usec=539
[2022-10-12T23:21:32.703] sched: Allocate JobId=50558 NodeList=cpu03 #CPUs=64 Partition=cpu-opteron
[2022-10-12T23:21:35.307] _slurm_rpc_submit_batch_job: JobId=50559 InitPrio=829 usec=483
[2022-10-12T23:21:35.689] sched: Allocate JobId=50559 NodeList=cpu04 #CPUs=64 Partition=cpu-opteron
[2022-10-12T23:21:41.599] _slurm_rpc_submit_batch_job: JobId=50560 InitPrio=829 usec=459
[2022-10-12T23:21:41.697] sched: Allocate JobId=50560 NodeList=cpu05 #CPUs=64 Partition=cpu-opteron
[2022-10-13T02:29:01.817] _job_complete: JobId=50513 WEXITSTATUS 0
[2022-10-13T02:29:01.818] _job_complete: JobId=50513 done
[2022-10-13T02:29:02.191] sched: Allocate JobId=50514 NodeList=cpu15 #CPUs=48 Partition=cpu-epyc
[2022-10-13T02:29:03.375] _job_complete: JobId=50514 WEXITSTATUS 1
[2022-10-13T02:29:03.376] _job_complete: JobId=50514 done
[2022-10-13T04:17:14.977] _job_complete: JobId=50409 WEXITSTATUS 0
[2022-10-13T04:17:14.987] _job_complete: JobId=50409 done
[2022-10-13T04:17:19.069] sched: Allocate JobId=50550 NodeList=gpu05 #CPUs=8 Partition=gpu-v100s
[2022-10-13T04:17:19.070] sched: Allocate JobId=50551 NodeList=gpu05 #CPUs=8 Partition=gpu-v100s
[2022-10-13T05:17:21.277] Time limit exhausted for JobId=50550
[2022-10-13T05:17:21.279] Time limit exhausted for JobId=50551
[2022-10-13T05:17:24.402] sched: Allocate JobId=50552 NodeList=gpu05 #CPUs=8 Partition=gpu-v100s
[2022-10-13T05:17:24.403] sched: Allocate JobId=50553 NodeList=gpu05 #CPUs=8 Partition=gpu-v100s
[2022-10-13T06:17:52.790] Time limit exhausted for JobId=50552
[2022-10-13T06:17:52.791] Time limit exhausted for JobId=50553
[2022-10-13T06:17:54.992] sched: Allocate JobId=50554 NodeList=gpu05 #CPUs=8 Partition=gpu-v100s
[2022-10-13T06:17:54.993] sched: Allocate JobId=50555 NodeList=gpu05 #CPUs=8 Partition=gpu-v100s
[2022-10-13T07:18:23.636] Time limit exhausted for JobId=50554
[2022-10-13T07:18:23.637] Time limit exhausted for JobId=50555
[2022-10-13T07:18:25.839] sched: Allocate JobId=50556 NodeList=gpu05 #CPUs=8 Partition=gpu-v100s
[2022-10-13T07:18:25.840] sched: Allocate JobId=50557 NodeList=gpu05 #CPUs=8 Partition=gpu-v100s
[2022-10-13T08:04:39.176] _slurm_rpc_submit_batch_job: JobId=50561 InitPrio=49377 usec=633
[2022-10-13T08:04:39.998] sched: Allocate JobId=50561 NodeList=cpu15 #CPUs=48 Partition=cpu-epyc
[2022-10-13T08:05:39.144] _slurm_rpc_submit_batch_job: JobId=50562 InitPrio=1452 usec=739
[2022-10-13T08:12:39.448] _slurm_rpc_submit_batch_job: JobId=50563 InitPrio=13112 usec=681
[2022-10-13T08:13:38.160] _slurm_rpc_submit_batch_job: JobId=50564 InitPrio=13112 usec=375
[2022-10-13T08:18:53.535] Time limit exhausted for JobId=50556
[2022-10-13T08:18:53.536] Time limit exhausted for JobId=50557
[2022-10-13T08:18:55.729] sched: Allocate JobId=50563 NodeList=gpu05 #CPUs=8 Partition=gpu-v100s
[2022-10-13T08:18:55.731] sched: Allocate JobId=50564 NodeList=gpu05 #CPUs=8 Partition=gpu-v100s
[2022-10-13T08:19:22.837] _slurm_rpc_submit_batch_job: JobId=50565 InitPrio=13112 usec=496
[2022-10-13T08:19:24.661] _slurm_rpc_submit_batch_job: JobId=50566 InitPrio=13112 usec=508
[2022-10-13T08:19:26.445] _slurm_rpc_submit_batch_job: JobId=50567 InitPrio=13112 usec=430
[2022-10-13T08:19:28.276] _slurm_rpc_submit_batch_job: JobId=50568 InitPrio=13112 usec=467
[2022-10-13T08:19:30.457] _slurm_rpc_submit_batch_job: JobId=50569 InitPrio=13112 usec=388
[2022-10-13T08:19:32.384] _slurm_rpc_submit_batch_job: JobId=50570 InitPrio=13112 usec=415
[2022-10-13T08:19:34.264] _slurm_rpc_submit_batch_job: JobId=50571 InitPrio=13112 usec=414
[2022-10-13T08:19:36.572] _slurm_rpc_submit_batch_job: JobId=50572 InitPrio=13112 usec=375
[2022-10-13T08:19:39.562] _slurm_rpc_submit_batch_job: JobId=50573 InitPrio=13112 usec=406
[2022-10-13T08:19:41.953] _slurm_rpc_submit_batch_job: JobId=50574 InitPrio=13112 usec=483
[2022-10-13T09:05:13.108] _job_complete: JobId=50563 WEXITSTATUS 0
[2022-10-13T09:05:13.110] _job_complete: JobId=50563 done
[2022-10-13T09:05:13.482] sched: Allocate JobId=50565 NodeList=gpu05 #CPUs=8 Partition=gpu-v100s
[2022-10-13T09:05:16.404] _job_complete: JobId=50564 WEXITSTATUS 0
[2022-10-13T09:05:16.404] _job_complete: JobId=50564 done
[2022-10-13T09:05:16.813] sched: Allocate JobId=50566 NodeList=gpu05 #CPUs=8 Partition=gpu-v100s
[2022-10-13T09:30:18.931] _slurm_rpc_submit_batch_job: JobId=50575 InitPrio=1037 usec=641
[2022-10-13T09:51:14.187] _job_complete: JobId=50565 WEXITSTATUS 0
[2022-10-13T09:51:14.189] _job_complete: JobId=50565 done
[2022-10-13T09:51:14.595] sched: Allocate JobId=50567 NodeList=gpu05 #CPUs=8 Partition=gpu-v100s
[2022-10-13T09:51:41.008] _job_complete: JobId=50566 WEXITSTATUS 0
[2022-10-13T09:51:41.009] _job_complete: JobId=50566 done
[2022-10-13T09:51:41.314] sched: Allocate JobId=50568 NodeList=gpu05 #CPUs=8 Partition=gpu-v100s
[2022-10-13T10:05:24.552] _job_complete: JobId=50534 WEXITSTATUS 0
[2022-10-13T10:05:24.557] _job_complete: JobId=50534 done
[2022-10-13T10:05:27.699] sched: Allocate JobId=50562 NodeList=gpu04 #CPUs=16 Partition=gpu-k40c
[2022-10-13T10:37:29.995] _job_complete: JobId=50567 WEXITSTATUS 0
[2022-10-13T10:37:29.996] _job_complete: JobId=50567 done
[2022-10-13T10:37:30.419] sched: Allocate JobId=50569 NodeList=gpu05 #CPUs=8 Partition=gpu-v100s
[2022-10-13T10:38:15.132] _job_complete: JobId=50568 WEXITSTATUS 0
[2022-10-13T10:38:15.133] _job_complete: JobId=50568 done
[2022-10-13T10:38:15.636] sched: Allocate JobId=50570 NodeList=gpu05 #CPUs=8 Partition=gpu-v100s
[2022-10-13T10:58:18.557] _slurm_rpc_submit_batch_job: JobId=50576 InitPrio=4356 usec=466
[2022-10-13T10:58:18.959] sched: Allocate JobId=50576 NodeList=cpu01 #CPUs=16 Partition=cpu-opteron
[2022-10-13T10:58:20.726] _job_complete: JobId=50576 WEXITSTATUS 0
[2022-10-13T10:58:20.726] _job_complete: JobId=50576 done
[2022-10-13T11:18:46.851] _slurm_rpc_kill_job: REQUEST_KILL_JOB JobId=50510 uid 548200021
[2022-10-13T11:18:51.075] sched: Allocate JobId=50527 NodeList=gpu02 #CPUs=2 Partition=gpu-titan
[2022-10-13T11:19:35.173] _job_complete: JobId=50527 WEXITSTATUS 0
[2022-10-13T11:19:35.174] _job_complete: JobId=50527 done
[2022-10-13T11:20:20.002] _slurm_rpc_submit_batch_job: JobId=50577 InitPrio=4356 usec=599
[2022-10-13T11:20:20.373] sched: Allocate JobId=50577 NodeList=cpu01 #CPUs=16 Partition=cpu-opteron
[2022-10-13T11:20:22.084] _job_complete: JobId=50577 WEXITSTATUS 21
[2022-10-13T11:20:22.084] _job_complete: JobId=50577 done
[2022-10-13T11:20:27.994] No nodes satisfy requirements for JobId=50578 in partition gpu-titan
[2022-10-13T11:20:27.994] _slurm_rpc_submit_batch_job: Requested node configuration is not available
[2022-10-13T11:20:44.165] _slurm_rpc_submit_batch_job: JobId=50579 InitPrio=414 usec=430
[2022-10-13T11:20:44.418] sched: Allocate JobId=50579 NodeList=gpu02 #CPUs=4 Partition=gpu-titan
[2022-10-13T11:21:26.265] _slurm_rpc_kill_job: REQUEST_KILL_JOB JobId=50577 uid 548300584
[2022-10-13T11:21:39.454] _slurm_rpc_submit_batch_job: JobId=50580 InitPrio=414 usec=507
[2022-10-13T11:21:39.631] sched: Allocate JobId=50580 NodeList=gpu02 #CPUs=4 Partition=gpu-titan
[2022-10-13T11:21:56.039] _slurm_rpc_kill_job: REQUEST_KILL_JOB JobId=505580 uid 548200021
[2022-10-13T11:21:56.039] job_str_signal(3): invalid JobId=505580
[2022-10-13T11:21:56.039] _slurm_rpc_kill_job: job_str_signal() uid=548200021 JobId=505580 sig=9 returned: Invalid job id specified
[2022-10-13T11:22:00.182] _slurm_rpc_kill_job: REQUEST_KILL_JOB JobId=50580 uid 548200021
[2022-10-13T11:22:05.887] _slurm_rpc_kill_job: REQUEST_KILL_JOB JobId=50579 uid 548200021
[2022-10-13T11:22:26.593] _slurm_rpc_submit_batch_job: JobId=50581 InitPrio=414 usec=418
[2022-10-13T11:22:26.694] sched: Allocate JobId=50581 NodeList=gpu02 #CPUs=16 Partition=gpu-titan
[2022-10-13T11:23:44.269] _job_complete: JobId=50569 WEXITSTATUS 0
[2022-10-13T11:23:44.270] _job_complete: JobId=50569 done
[2022-10-13T11:23:44.646] sched: Allocate JobId=50571 NodeList=gpu05 #CPUs=8 Partition=gpu-v100s
[2022-10-13T11:23:47.080] _slurm_rpc_submit_batch_job: JobId=50582 InitPrio=4356 usec=439
[2022-10-13T11:24:41.843] _slurm_rpc_submit_batch_job: JobId=50583 InitPrio=414 usec=534
[2022-10-13T11:24:49.109] _job_complete: JobId=50570 WEXITSTATUS 0
[2022-10-13T11:24:49.110] _job_complete: JobId=50570 done
[2022-10-13T11:24:49.455] sched: Allocate JobId=50572 NodeList=gpu05 #CPUs=8 Partition=gpu-v100s
[2022-10-13T11:28:18.543] _slurm_rpc_kill_job: REQUEST_KILL_JOB JobId=50582 uid 548300584
[2022-10-13T11:34:53.975] _slurm_rpc_submit_batch_job: JobId=50584 InitPrio=414 usec=452
[2022-10-13T11:34:54.054] sched: Allocate JobId=50584 NodeList=cpu01 #CPUs=4 Partition=cpu-opteron
[2022-10-13T11:35:05.149] _job_complete: JobId=50584 WEXITSTATUS 0
[2022-10-13T11:35:05.149] _job_complete: JobId=50584 done
[2022-10-13T12:04:49.870] _slurm_rpc_submit_batch_job: JobId=50585 InitPrio=1867 usec=478
[2022-10-13T12:04:50.037] sched: Allocate JobId=50585 NodeList=cpu01 #CPUs=16 Partition=cpu-opteron
[2022-10-13T12:05:02.898] _job_complete: JobId=50585 WEXITSTATUS 0
[2022-10-13T12:05:02.899] _job_complete: JobId=50585 done
[2022-10-13T12:05:42.374] _slurm_rpc_submit_batch_job: JobId=50586 InitPrio=1867 usec=536
[2022-10-13T12:05:43.088] sched: Allocate JobId=50586 NodeList=cpu01 #CPUs=16 Partition=cpu-opteron
[2022-10-13T12:05:48.282] _job_complete: JobId=50586 WEXITSTATUS 0
[2022-10-13T12:05:48.282] _job_complete: JobId=50586 done
[2022-10-13T12:09:59.780] _job_complete: JobId=50571 WEXITSTATUS 0
[2022-10-13T12:09:59.781] _job_complete: JobId=50571 done
[2022-10-13T12:10:00.173] sched: Allocate JobId=50573 NodeList=gpu05 #CPUs=8 Partition=gpu-v100s
[2022-10-13T12:11:19.711] _job_complete: JobId=50572 WEXITSTATUS 0
[2022-10-13T12:11:19.711] _job_complete: JobId=50572 done
[2022-10-13T12:11:20.049] sched: Allocate JobId=50574 NodeList=gpu05 #CPUs=8 Partition=gpu-v100s
[2022-10-13T12:20:31.164] _slurm_rpc_submit_batch_job: JobId=50587 InitPrio=414 usec=460
[2022-10-13T12:20:31.722] sched: Allocate JobId=50587 NodeList=cpu01 #CPUs=4 Partition=cpu-opteron
[2022-10-13T12:20:37.877] _job_complete: JobId=50587 WEXITSTATUS 0
[2022-10-13T12:20:37.877] _job_complete: JobId=50587 done
[2022-10-13T12:23:18.465] _slurm_rpc_submit_batch_job: JobId=50588 InitPrio=1867 usec=982
[2022-10-13T12:25:16.231] _slurm_rpc_submit_batch_job: JobId=50589 InitPrio=414 usec=461
[2022-10-13T12:25:17.229] sched: Allocate JobId=50589 NodeList=cpu01 #CPUs=4 Partition=cpu-opteron
[2022-10-13T12:25:23.495] _job_complete: JobId=50589 WEXITSTATUS 0
[2022-10-13T12:25:23.495] _job_complete: JobId=50589 done
[2022-10-13T12:34:49.549] _job_complete: JobId=50574 WEXITSTATUS 0
[2022-10-13T12:34:49.550] _job_complete: JobId=50574 done
[2022-10-13T12:34:49.984] sched: Allocate JobId=50410 NodeList=gpu05 #CPUs=8 Partition=gpu-v100s
[2022-10-13T12:37:45.857] _slurm_rpc_submit_batch_job: JobId=50590 InitPrio=414 usec=532
[2022-10-13T12:37:46.553] sched: Allocate JobId=50590 NodeList=cpu01 #CPUs=4 Partition=cpu-opteron
[2022-10-13T12:38:09.839] _job_complete: JobId=50590 WEXITSTATUS 0
[2022-10-13T12:38:09.839] _job_complete: JobId=50590 done
[2022-10-13T12:46:32.955] _slurm_rpc_submit_batch_job: JobId=50591 InitPrio=1867 usec=934
[2022-10-13T12:46:48.642] _slurm_rpc_kill_job: REQUEST_KILL_JOB JobId=50591 uid 548200029
[2022-10-13T12:46:57.402] _slurm_rpc_submit_batch_job: JobId=50592 InitPrio=1867 usec=1002
[2022-10-13T12:56:43.744] _job_complete: JobId=50573 WEXITSTATUS 0
[2022-10-13T12:56:43.745] _job_complete: JobId=50573 done
[2022-10-13T12:56:44.226] sched: Allocate JobId=50417 NodeList=gpu05 #CPUs=8 Partition=gpu-v100s
[2022-10-13T13:08:48.077] _slurm_rpc_submit_batch_job: JobId=50593 InitPrio=414 usec=630
[2022-10-13T13:22:33.697] _job_complete: JobId=49723 WEXITSTATUS 0
[2022-10-13T13:22:33.697] _job_complete: JobId=49723 done
[2022-10-13T13:22:34.181] sched: Allocate JobId=50533 NodeList=cpu14 #CPUs=48 Partition=cpu-epyc
[2022-10-13T13:33:35.330] _slurm_rpc_submit_batch_job: JobId=50594 InitPrio=622 usec=555
[2022-10-13T13:33:36.319] sched: Allocate JobId=50594 NodeList=cpu01 #CPUs=32 Partition=cpu-opteron
[2022-10-13T13:33:41.904] _job_complete: JobId=50594 WEXITSTATUS 0
[2022-10-13T13:33:41.904] _job_complete: JobId=50594 done
[2022-10-13T13:44:57.947] _slurm_rpc_submit_batch_job: JobId=50595 InitPrio=622 usec=572
[2022-10-13T13:46:12.766] _slurm_rpc_submit_batch_job: JobId=50596 InitPrio=622 usec=578
[2022-10-13T13:47:27.531] _slurm_rpc_kill_job: REQUEST_KILL_JOB JobId=50596 uid 548200023
[2022-10-13T13:47:30.375] _slurm_rpc_submit_batch_job: JobId=50597 InitPrio=622 usec=526
[2022-10-13T14:04:50.714] sched: _slurm_rpc_allocate_resources JobId=50598 NodeList=(null) usec=918
[2022-10-13T14:04:51.670] sched: Allocate JobId=50598 NodeList=cpu01 #CPUs=1 Partition=cpu-opteron
[2022-10-13T14:20:08.089] _slurm_rpc_submit_batch_job: JobId=50599 InitPrio=1867 usec=449
[2022-10-13T14:20:14.514] _slurm_rpc_submit_batch_job: JobId=50600 InitPrio=414 usec=494
[2022-10-13T15:00:22.669] _slurm_rpc_submit_batch_job: JobId=50601 InitPrio=829 usec=602
[2022-10-13T15:00:22.795] sched: Allocate JobId=50601 NodeList=cpu07 #CPUs=64 Partition=cpu-opteron
[2022-10-13T15:00:45.966] _job_complete: JobId=50601 WEXITSTATUS 0
[2022-10-13T15:00:45.966] _job_complete: JobId=50601 done
[2022-10-13T15:20:10.881] _slurm_rpc_kill_job: REQUEST_KILL_JOB JobId=50560 uid 548300621
[2022-10-13T15:20:20.032] _slurm_rpc_kill_job: REQUEST_KILL_JOB JobId=50559 uid 548300621
[2022-10-13T15:21:40.942] _slurm_rpc_kill_job: REQUEST_KILL_JOB JobId=50558 uid 548300621
[2022-10-13T15:26:07.219] _slurm_rpc_submit_batch_job: JobId=50602 InitPrio=622 usec=611
[2022-10-13T15:26:07.551] sched: Allocate JobId=50602 NodeList=cpu01 #CPUs=32 Partition=cpu-opteron
[2022-10-13T15:26:09.200] _job_complete: JobId=50602 WEXITSTATUS 1
[2022-10-13T15:26:09.200] _job_complete: JobId=50602 done
[2022-10-13T15:31:58.340] _slurm_rpc_submit_batch_job: JobId=50603 InitPrio=13112 usec=485
[2022-10-13T15:32:00.941] _slurm_rpc_submit_batch_job: JobId=50604 InitPrio=13112 usec=462
[2022-10-13T15:32:02.831] _slurm_rpc_submit_batch_job: JobId=50605 InitPrio=13112 usec=381
[2022-10-13T16:18:36.301] _slurm_rpc_submit_batch_job: JobId=50606 InitPrio=829 usec=539
[2022-10-13T16:18:37.186] sched: Allocate JobId=50606 NodeList=cpu03 #CPUs=64 Partition=cpu-opteron
[2022-10-13T16:18:38.607] _slurm_rpc_submit_batch_job: JobId=50607 InitPrio=829 usec=463
[2022-10-13T16:18:40.184] sched: Allocate JobId=50607 NodeList=cpu04 #CPUs=64 Partition=cpu-opteron
[2022-10-13T16:18:40.279] _slurm_rpc_submit_batch_job: JobId=50608 InitPrio=829 usec=410
[2022-10-13T16:18:43.188] sched: Allocate JobId=50608 NodeList=cpu05 #CPUs=64 Partition=cpu-opteron
[2022-10-13T16:18:43.702] _slurm_rpc_submit_batch_job: JobId=50609 InitPrio=829 usec=515
[2022-10-13T16:18:46.191] sched: Allocate JobId=50609 NodeList=cpu07 #CPUs=64 Partition=cpu-opteron
[2022-10-13T16:18:46.878] _slurm_rpc_submit_batch_job: JobId=50610 InitPrio=829 usec=416
[2022-10-13T16:18:49.195] sched: Allocate JobId=50610 NodeList=cpu08 #CPUs=64 Partition=cpu-opteron
[2022-10-13T16:18:52.727] _slurm_rpc_submit_batch_job: JobId=50611 InitPrio=829 usec=446
[2022-10-13T16:18:53.200] sched: Allocate JobId=50611 NodeList=cpu09 #CPUs=64 Partition=cpu-opteron
[2022-10-13T16:18:55.398] _slurm_rpc_submit_batch_job: JobId=50612 InitPrio=829 usec=539
[2022-10-13T16:18:56.204] sched: Allocate JobId=50612 NodeList=cpu10 #CPUs=64 Partition=cpu-opteron
[2022-10-13T16:18:58.311] _slurm_rpc_submit_batch_job: JobId=50613 InitPrio=829 usec=406
[2022-10-13T16:19:02.119] _slurm_rpc_submit_batch_job: JobId=50614 InitPrio=829 usec=472
[2022-10-13T16:37:38.418] _slurm_rpc_submit_batch_job: JobId=50615 InitPrio=4356 usec=523
[2022-10-13T16:37:39.202] sched: Allocate JobId=50615 NodeList=cpu01 #CPUs=16 Partition=cpu-opteron
[2022-10-13T16:37:40.361] _job_complete: JobId=50615 WEXITSTATUS 31
[2022-10-13T16:37:40.361] _job_complete: JobId=50615 done
[2022-10-13T16:40:46.504] _slurm_rpc_submit_batch_job: JobId=50616 InitPrio=2904 usec=567
[2022-10-13T16:40:47.465] sched: Allocate JobId=50616 NodeList=cpu01 #CPUs=8 Partition=cpu-opteron
[2022-10-13T16:40:49.727] _slurm_rpc_submit_batch_job: JobId=50617 InitPrio=2904 usec=504
[2022-10-13T16:40:50.453] sched: Allocate JobId=50617 NodeList=cpu01 #CPUs=8 Partition=cpu-opteron
[2022-10-13T16:40:52.816] _slurm_rpc_submit_batch_job: JobId=50618 InitPrio=2904 usec=437
[2022-10-13T16:40:53.457] sched: Allocate JobId=50618 NodeList=cpu01 #CPUs=8 Partition=cpu-opteron
[2022-10-13T16:40:55.375] _slurm_rpc_submit_batch_job: JobId=50619 InitPrio=2904 usec=422
[2022-10-13T16:40:56.461] sched: Allocate JobId=50619 NodeList=cpu01 #CPUs=8 Partition=cpu-opteron
[2022-10-13T16:40:58.135] _slurm_rpc_submit_batch_job: JobId=50620 InitPrio=2904 usec=442
[2022-10-13T16:40:59.465] sched: Allocate JobId=50620 NodeList=cpu01 #CPUs=8 Partition=cpu-opteron
[2022-10-13T16:41:00.830] _slurm_rpc_submit_batch_job: JobId=50621 InitPrio=2904 usec=475
[2022-10-13T16:41:02.459] _slurm_rpc_submit_batch_job: JobId=50622 InitPrio=4356 usec=465
[2022-10-13T16:41:02.535] sched: Allocate JobId=50622 NodeList=cpu01 #CPUs=16 Partition=cpu-opteron
[2022-10-13T16:41:02.536] sched: Allocate JobId=50621 NodeList=cpu11 #CPUs=8 Partition=cpu-opteron
[2022-10-13T16:41:03.654] _slurm_rpc_submit_batch_job: JobId=50623 InitPrio=2904 usec=497
[2022-10-13T16:41:03.692] _job_complete: JobId=50622 WEXITSTATUS 31
[2022-10-13T16:41:03.692] _job_complete: JobId=50622 done
[2022-10-13T16:41:04.947] sched: Allocate JobId=50623 NodeList=cpu01 #CPUs=8 Partition=cpu-opteron
[2022-10-13T16:41:06.246] _slurm_rpc_submit_batch_job: JobId=50624 InitPrio=2904 usec=398
[2022-10-13T16:41:08.553] sched: Allocate JobId=50624 NodeList=cpu01 #CPUs=8 Partition=cpu-opteron
[2022-10-13T16:41:10.942] _slurm_rpc_submit_batch_job: JobId=50625 InitPrio=2904 usec=520
[2022-10-13T16:41:11.599] sched: Allocate JobId=50625 NodeList=cpu11 #CPUs=8 Partition=cpu-opteron
[2022-10-13T16:41:14.331] _slurm_rpc_submit_batch_job: JobId=50626 InitPrio=2904 usec=549
[2022-10-13T16:41:14.603] sched: Allocate JobId=50626 NodeList=cpu11 #CPUs=8 Partition=cpu-opteron
[2022-10-13T16:41:17.142] _slurm_rpc_submit_batch_job: JobId=50627 InitPrio=2904 usec=424
[2022-10-13T16:41:17.607] sched: Allocate JobId=50627 NodeList=cpu11 #CPUs=8 Partition=cpu-opteron
[2022-10-13T16:41:20.079] _slurm_rpc_submit_batch_job: JobId=50628 InitPrio=2904 usec=516
[2022-10-13T16:41:20.612] sched: Allocate JobId=50628 NodeList=cpu11 #CPUs=8 Partition=cpu-opteron
[2022-10-13T16:41:22.742] _slurm_rpc_submit_batch_job: JobId=50629 InitPrio=2904 usec=473
[2022-10-13T16:41:23.335] sched/backfill: _start_job: Started JobId=50629 in cpu-opteron on cpu11
[2022-10-13T16:41:25.294] _slurm_rpc_submit_batch_job: JobId=50630 InitPrio=2904 usec=535
[2022-10-13T16:41:27.831] _slurm_rpc_submit_batch_job: JobId=50631 InitPrio=2904 usec=473
[2022-10-13T16:41:30.465] _slurm_rpc_submit_batch_job: JobId=50632 InitPrio=2904 usec=478
[2022-10-13T16:41:33.143] _slurm_rpc_submit_batch_job: JobId=50633 InitPrio=2904 usec=402
[2022-10-13T16:41:35.537] _slurm_rpc_submit_batch_job: JobId=50634 InitPrio=2904 usec=432
[2022-10-13T16:41:38.079] _slurm_rpc_submit_batch_job: JobId=50635 InitPrio=2904 usec=484
[2022-10-13T16:41:41.383] _slurm_rpc_submit_batch_job: JobId=50636 InitPrio=2904 usec=450
[2022-10-13T16:41:44.063] _slurm_rpc_submit_batch_job: JobId=50637 InitPrio=2904 usec=423
[2022-10-13T16:41:46.632] _slurm_rpc_submit_batch_job: JobId=50638 InitPrio=2904 usec=448
[2022-10-13T16:41:49.967] _slurm_rpc_submit_batch_job: JobId=50639 InitPrio=2904 usec=479
[2022-10-13T16:41:52.352] _slurm_rpc_submit_batch_job: JobId=50640 InitPrio=2904 usec=427
[2022-10-13T16:41:54.839] _slurm_rpc_submit_batch_job: JobId=50641 InitPrio=2904 usec=541
[2022-10-13T16:41:57.330] _slurm_rpc_submit_batch_job: JobId=50642 InitPrio=2904 usec=580
[2022-10-13T16:41:59.791] _slurm_rpc_submit_batch_job: JobId=50643 InitPrio=2904 usec=469
[2022-10-13T16:42:02.303] _slurm_rpc_submit_batch_job: JobId=50644 InitPrio=2904 usec=490
[2022-10-13T16:42:04.783] _slurm_rpc_submit_batch_job: JobId=50645 InitPrio=2904 usec=495
[2022-10-13T16:42:07.806] _slurm_rpc_submit_batch_job: JobId=50646 InitPrio=2904 usec=494
[2022-10-13T16:42:10.135] _slurm_rpc_submit_batch_job: JobId=50647 InitPrio=2904 usec=461
[2022-10-13T16:42:12.431] _slurm_rpc_submit_batch_job: JobId=50648 InitPrio=2904 usec=442
[2022-10-13T16:42:14.863] _slurm_rpc_submit_batch_job: JobId=50649 InitPrio=2904 usec=493
[2022-10-13T16:42:17.522] _slurm_rpc_submit_batch_job: JobId=50650 InitPrio=2904 usec=451
[2022-10-13T16:42:19.871] _slurm_rpc_submit_batch_job: JobId=50651 InitPrio=2904 usec=483
[2022-10-13T16:42:22.247] _slurm_rpc_submit_batch_job: JobId=50652 InitPrio=2904 usec=603
[2022-10-13T16:42:24.740] _slurm_rpc_submit_batch_job: JobId=50653 InitPrio=2904 usec=744
[2022-10-13T16:42:25.818] _slurm_rpc_submit_batch_job: JobId=50654 InitPrio=4356 usec=510
[2022-10-13T16:43:11.298] _slurm_rpc_submit_batch_job: JobId=50655 InitPrio=4356 usec=489
[2022-10-13T16:43:58.344] _slurm_rpc_kill_job: REQUEST_KILL_JOB JobId=50655 uid 548300584
[2022-10-13T16:44:05.671] _slurm_rpc_kill_job: REQUEST_KILL_JOB JobId=50654 uid 548300584
[2022-10-13T16:45:43.434] _slurm_rpc_submit_batch_job: JobId=50656 InitPrio=4356 usec=502
[2022-10-13T17:12:50.357] _slurm_rpc_submit_batch_job: JobId=50657 InitPrio=13112 usec=458
[2022-10-13T17:12:52.826] _slurm_rpc_submit_batch_job: JobId=50658 InitPrio=13112 usec=442
[2022-10-13T17:12:55.247] _slurm_rpc_submit_batch_job: JobId=50659 InitPrio=13112 usec=476
[2022-10-13T17:12:57.501] _slurm_rpc_submit_batch_job: JobId=50660 InitPrio=13112 usec=365
[2022-10-13T17:13:00.497] _slurm_rpc_submit_batch_job: JobId=50661 InitPrio=13112 usec=420
[2022-10-13T17:15:47.373] _slurm_rpc_submit_batch_job: JobId=50662 InitPrio=2904 usec=610
[2022-10-13T17:15:51.234] _slurm_rpc_submit_batch_job: JobId=50663 InitPrio=2904 usec=421
[2022-10-13T17:15:54.136] _slurm_rpc_submit_batch_job: JobId=50664 InitPrio=2904 usec=875
[2022-10-13T17:15:56.875] _slurm_rpc_submit_batch_job: JobId=50665 InitPrio=2904 usec=444
[2022-10-13T17:16:00.850] _slurm_rpc_submit_batch_job: JobId=50666 InitPrio=2904 usec=481
[2022-10-13T17:16:03.946] _slurm_rpc_submit_batch_job: JobId=50667 InitPrio=2904 usec=515
[2022-10-13T17:16:06.432] _slurm_rpc_submit_batch_job: JobId=50668 InitPrio=2904 usec=472
[2022-10-13T17:16:08.791] _slurm_rpc_submit_batch_job: JobId=50669 InitPrio=2904 usec=464
[2022-10-13T17:16:11.231] _slurm_rpc_submit_batch_job: JobId=50670 InitPrio=2904 usec=520
[2022-10-13T17:16:14.375] _slurm_rpc_submit_batch_job: JobId=50671 InitPrio=2904 usec=425
[2022-10-13T17:18:47.311] _slurm_rpc_kill_job: REQUEST_KILL_JOB JobId=50656 uid 548300584
[2022-10-13T17:19:31.775] _slurm_rpc_submit_batch_job: JobId=50672 InitPrio=4356 usec=471
[2022-10-13T17:21:05.094] _slurm_rpc_kill_job: REQUEST_KILL_JOB JobId=50672 uid 548300584
[2022-10-13T17:25:35.729] _slurm_rpc_submit_batch_job: JobId=50673 InitPrio=4356 usec=411
[2022-10-13T17:31:46.773] _slurm_rpc_submit_batch_job: JobId=50674 InitPrio=4356 usec=569
[2022-10-13T17:32:30.063] _slurm_rpc_kill_job: REQUEST_KILL_JOB JobId=50673 uid 548300584
[2022-10-13T17:37:04.869] _slurm_rpc_submit_batch_job: JobId=50675 InitPrio=4356 usec=497
[2022-10-13T17:37:10.587] _slurm_rpc_submit_batch_job: JobId=50676 InitPrio=2904 usec=442
[2022-10-13T17:37:14.098] _slurm_rpc_submit_batch_job: JobId=50677 InitPrio=2904 usec=500
[2022-10-13T17:37:16.939] _slurm_rpc_submit_batch_job: JobId=50678 InitPrio=2904 usec=523
[2022-10-13T17:37:19.553] _slurm_rpc_submit_batch_job: JobId=50679 InitPrio=2904 usec=463
[2022-10-13T17:37:22.010] _slurm_rpc_submit_batch_job: JobId=50680 InitPrio=2904 usec=513
[2022-10-13T17:37:24.620] _slurm_rpc_submit_batch_job: JobId=50681 InitPrio=2904 usec=487
[2022-10-13T17:37:27.218] _slurm_rpc_submit_batch_job: JobId=50682 InitPrio=2904 usec=396
[2022-10-13T17:37:29.780] _slurm_rpc_submit_batch_job: JobId=50683 InitPrio=2904 usec=451
[2022-10-13T17:37:32.369] _slurm_rpc_submit_batch_job: JobId=50684 InitPrio=2904 usec=487
[2022-10-13T17:37:35.731] _slurm_rpc_submit_batch_job: JobId=50685 InitPrio=2904 usec=452
[2022-10-13T17:38:05.431] _slurm_rpc_kill_job: REQUEST_KILL_JOB JobId=50674 uid 548300584
[2022-10-13T17:51:47.118] _slurm_rpc_submit_batch_job: JobId=50686 InitPrio=622 usec=479
[2022-10-13T18:06:29.145] _slurm_rpc_submit_batch_job: JobId=50687 InitPrio=4356 usec=619
[2022-10-13T18:13:02.642] _job_complete: JobId=50561 WEXITSTATUS 0
[2022-10-13T18:13:02.643] _job_complete: JobId=50561 done
[2022-10-13T18:17:18.174] _slurm_rpc_submit_batch_job: JobId=50688 InitPrio=49377 usec=894
[2022-10-13T18:17:18.723] sched: Allocate JobId=50688 NodeList=cpu15 #CPUs=48 Partition=cpu-epyc
[2022-10-13T18:22:18.613] _slurm_rpc_submit_batch_job: JobId=50689 InitPrio=4356 usec=455
[2022-10-13T19:07:57.851] _job_complete: JobId=50598 WEXITSTATUS 0
[2022-10-13T19:07:57.852] _job_complete: JobId=50598 done
[2022-10-13T19:12:59.327] cleanup_completing: JobId=50598 completion process took 302 seconds
[2022-10-13T20:01:32.934] _job_complete: JobId=50619 WEXITSTATUS 0
[2022-10-13T20:01:32.934] _job_complete: JobId=50619 done
[2022-10-13T20:01:33.945] sched: Allocate JobId=50630 NodeList=cpu01 #CPUs=8 Partition=cpu-opteron
[2022-10-13T20:05:35.895] _job_complete: JobId=50623 WEXITSTATUS 0
[2022-10-13T20:05:35.895] _job_complete: JobId=50623 done
[2022-10-13T20:05:37.210] sched: Allocate JobId=50631 NodeList=cpu01 #CPUs=8 Partition=cpu-opteron
[2022-10-13T20:06:05.164] _job_complete: JobId=50621 WEXITSTATUS 0
[2022-10-13T20:06:05.165] _job_complete: JobId=50621 done
[2022-10-13T20:06:06.056] sched: Allocate JobId=50632 NodeList=cpu11 #CPUs=8 Partition=cpu-opteron
[2022-10-13T20:08:12.379] _job_complete: JobId=50625 WEXITSTATUS 0
[2022-10-13T20:08:12.379] _job_complete: JobId=50625 done
[2022-10-13T20:08:13.067] sched: Allocate JobId=50633 NodeList=cpu11 #CPUs=8 Partition=cpu-opteron
[2022-10-13T20:11:53.749] _job_complete: JobId=50629 WEXITSTATUS 0
[2022-10-13T20:11:53.749] _job_complete: JobId=50629 done
[2022-10-13T20:11:54.428] sched: Allocate JobId=50634 NodeList=cpu11 #CPUs=8 Partition=cpu-opteron
[2022-10-13T20:12:52.280] _job_complete: JobId=50620 WEXITSTATUS 0
[2022-10-13T20:12:52.280] _job_complete: JobId=50620 done
[2022-10-13T20:12:53.663] sched: Allocate JobId=50635 NodeList=cpu01 #CPUs=8 Partition=cpu-opteron
[2022-10-13T20:14:49.306] _job_complete: JobId=50626 WEXITSTATUS 0
[2022-10-13T20:14:49.307] _job_complete: JobId=50626 done
[2022-10-13T20:14:50.375] sched: Allocate JobId=50636 NodeList=cpu11 #CPUs=8 Partition=cpu-opteron
[2022-10-13T20:15:17.838] _job_complete: JobId=50627 WEXITSTATUS 0
[2022-10-13T20:15:17.838] _job_complete: JobId=50627 done
[2022-10-13T20:15:18.811] sched: Allocate JobId=50637 NodeList=cpu11 #CPUs=8 Partition=cpu-opteron
[2022-10-13T20:20:04.168] _job_complete: JobId=50628 WEXITSTATUS 0
[2022-10-13T20:20:04.168] _job_complete: JobId=50628 done
[2022-10-13T20:20:04.861] sched: Allocate JobId=50638 NodeList=cpu11 #CPUs=8 Partition=cpu-opteron
[2022-10-13T20:29:57.228] _job_complete: JobId=50618 WEXITSTATUS 0
[2022-10-13T20:29:57.228] _job_complete: JobId=50618 done
[2022-10-13T20:29:58.154] sched: Allocate JobId=50639 NodeList=cpu01 #CPUs=8 Partition=cpu-opteron
[2022-10-13T20:32:54.910] _job_complete: JobId=50624 WEXITSTATUS 0
[2022-10-13T20:32:54.910] _job_complete: JobId=50624 done
[2022-10-13T20:32:56.482] sched: Allocate JobId=50640 NodeList=cpu01 #CPUs=8 Partition=cpu-opteron
[2022-10-13T20:33:11.730] _job_complete: JobId=50617 WEXITSTATUS 0
[2022-10-13T20:33:11.730] _job_complete: JobId=50617 done
[2022-10-13T20:33:12.543] sched: Allocate JobId=50641 NodeList=cpu01 #CPUs=8 Partition=cpu-opteron
[2022-10-13T20:33:22.336] _job_complete: JobId=50616 WEXITSTATUS 0
[2022-10-13T20:33:22.336] _job_complete: JobId=50616 done
[2022-10-13T20:33:23.342] sched: Allocate JobId=50642 NodeList=cpu01 #CPUs=8 Partition=cpu-opteron
[2022-10-13T22:00:43.692] _job_complete: JobId=50417 WEXITSTATUS 0
[2022-10-13T22:00:43.698] _job_complete: JobId=50417 done
[2022-10-13T22:00:44.242] sched: Allocate JobId=50603 NodeList=gpu05 #CPUs=8 Partition=gpu-v100s
[2022-10-13T22:15:37.996] _job_complete: JobId=50603 WEXITSTATUS 1
[2022-10-13T22:15:37.997] _job_complete: JobId=50603 done
[2022-10-13T22:15:38.390] sched: Allocate JobId=50604 NodeList=gpu05 #CPUs=8 Partition=gpu-v100s
[2022-10-13T22:23:15.864] _job_complete: JobId=50604 WEXITSTATUS 127
[2022-10-13T22:23:15.865] _job_complete: JobId=50604 done
[2022-10-13T22:23:16.286] sched: Allocate JobId=50605 NodeList=gpu05 #CPUs=8 Partition=gpu-v100s
[2022-10-13T22:30:53.473] _job_complete: JobId=50605 WEXITSTATUS 127
[2022-10-13T22:30:53.473] _job_complete: JobId=50605 done
[2022-10-13T22:30:53.907] sched: Allocate JobId=50657 NodeList=gpu05 #CPUs=8 Partition=gpu-v100s
[2022-10-13T22:38:28.368] _job_complete: JobId=50657 WEXITSTATUS 127
[2022-10-13T22:38:28.369] _job_complete: JobId=50657 done
[2022-10-13T22:38:28.801] sched: Allocate JobId=50658 NodeList=gpu05 #CPUs=8 Partition=gpu-v100s
[2022-10-13T22:42:24.016] _job_complete: JobId=50658 WEXITSTATUS 127
[2022-10-13T22:42:24.016] _job_complete: JobId=50658 done
[2022-10-13T22:42:24.360] sched: Allocate JobId=50659 NodeList=gpu05 #CPUs=8 Partition=gpu-v100s
[2022-10-13T22:50:00.719] _job_complete: JobId=50659 WEXITSTATUS 127
[2022-10-13T22:50:00.720] _job_complete: JobId=50659 done
[2022-10-13T22:50:01.097] sched: Allocate JobId=50660 NodeList=gpu05 #CPUs=8 Partition=gpu-v100s
[2022-10-13T22:57:37.309] _job_complete: JobId=50660 WEXITSTATUS 127
[2022-10-13T22:57:37.309] _job_complete: JobId=50660 done
[2022-10-13T22:57:37.660] sched: Allocate JobId=50661 NodeList=gpu05 #CPUs=8 Partition=gpu-v100s
[2022-10-13T23:05:10.657] _job_complete: JobId=50661 WEXITSTATUS 127
[2022-10-13T23:05:10.658] _job_complete: JobId=50661 done
[2022-10-13T23:27:26.889] _job_complete: JobId=50630 WEXITSTATUS 0
[2022-10-13T23:27:26.890] _job_complete: JobId=50630 done
[2022-10-13T23:27:28.623] sched: Allocate JobId=50643 NodeList=cpu01 #CPUs=8 Partition=cpu-opteron
[2022-10-13T23:29:54.954] _job_complete: JobId=50634 WEXITSTATUS 0
[2022-10-13T23:29:54.954] _job_complete: JobId=50634 done
[2022-10-13T23:29:55.787] sched: Allocate JobId=50644 NodeList=cpu11 #CPUs=8 Partition=cpu-opteron
[2022-10-13T23:34:28.559] _job_complete: JobId=50633 WEXITSTATUS 0
[2022-10-13T23:34:28.560] _job_complete: JobId=50633 done
[2022-10-13T23:34:29.312] sched: Allocate JobId=50645 NodeList=cpu11 #CPUs=8 Partition=cpu-opteron
[2022-10-13T23:44:25.736] _job_complete: JobId=50635 WEXITSTATUS 0
[2022-10-13T23:44:25.736] _job_complete: JobId=50635 done
[2022-10-13T23:44:27.147] sched: Allocate JobId=50646 NodeList=cpu01 #CPUs=8 Partition=cpu-opteron
[2022-10-13T23:46:40.885] _job_complete: JobId=50631 WEXITSTATUS 0
[2022-10-13T23:46:40.885] _job_complete: JobId=50631 done
[2022-10-13T23:46:41.626] sched: Allocate JobId=50647 NodeList=cpu01 #CPUs=8 Partition=cpu-opteron
[2022-10-13T23:47:40.109] _job_complete: JobId=50632 WEXITSTATUS 0
[2022-10-13T23:47:40.109] _job_complete: JobId=50632 done
[2022-10-13T23:47:40.890] sched: Allocate JobId=50648 NodeList=cpu11 #CPUs=8 Partition=cpu-opteron
[2022-10-13T23:50:18.965] _job_complete: JobId=50636 WEXITSTATUS 0
[2022-10-13T23:50:18.965] _job_complete: JobId=50636 done
[2022-10-13T23:50:19.664] sched: Allocate JobId=50649 NodeList=cpu11 #CPUs=8 Partition=cpu-opteron
[2022-10-13T23:50:45.714] _job_complete: JobId=50642 WEXITSTATUS 0
[2022-10-13T23:50:45.714] _job_complete: JobId=50642 done
[2022-10-13T23:50:46.529] sched: Allocate JobId=50650 NodeList=cpu01 #CPUs=8 Partition=cpu-opteron
[2022-10-13T23:50:49.417] _slurm_rpc_submit_batch_job: JobId=50690 InitPrio=13112 usec=540
[2022-10-13T23:50:49.612] sched: Allocate JobId=50690 NodeList=gpu05 #CPUs=8 Partition=gpu-v100s
[2022-10-13T23:53:12.607] _slurm_rpc_submit_batch_job: JobId=50691 InitPrio=13112 usec=436
[2022-10-13T23:54:16.321] _job_complete: JobId=50639 WEXITSTATUS 0
[2022-10-13T23:54:16.322] _job_complete: JobId=50639 done
[2022-10-13T23:54:17.900] sched: Allocate JobId=50651 NodeList=cpu01 #CPUs=8 Partition=cpu-opteron
[2022-10-13T23:54:32.117] _job_complete: JobId=50690 WEXITSTATUS 1
[2022-10-13T23:54:32.118] _job_complete: JobId=50690 done
[2022-10-13T23:54:32.489] sched: Allocate JobId=50691 NodeList=gpu05 #CPUs=8 Partition=gpu-v100s
[2022-10-13T23:58:14.042] _job_complete: JobId=50691 WEXITSTATUS 1
[2022-10-13T23:58:14.044] _job_complete: JobId=50691 done
[2022-10-14T00:01:24.271] _job_complete: JobId=50637 WEXITSTATUS 0
[2022-10-14T00:01:24.271] _job_complete: JobId=50637 done
[2022-10-14T00:01:24.550] sched: Allocate JobId=50652 NodeList=cpu11 #CPUs=8 Partition=cpu-opteron
[2022-10-14T00:01:25.109] _job_complete: JobId=50640 WEXITSTATUS 0
[2022-10-14T00:01:25.109] _job_complete: JobId=50640 done
[2022-10-14T00:01:25.676] sched: Allocate JobId=50653 NodeList=cpu01 #CPUs=8 Partition=cpu-opteron
[2022-10-14T00:19:05.156] _job_complete: JobId=50641 WEXITSTATUS 0
[2022-10-14T00:19:05.156] _job_complete: JobId=50641 done
[2022-10-14T00:19:06.676] sched: Allocate JobId=50676 NodeList=cpu01 #CPUs=8 Partition=cpu-opteron
[2022-10-14T00:30:12.257] _job_complete: JobId=50638 WEXITSTATUS 0
[2022-10-14T00:30:12.258] _job_complete: JobId=50638 done
[2022-10-14T00:30:13.542] sched: Allocate JobId=50677 NodeList=cpu11 #CPUs=8 Partition=cpu-opteron
[2022-10-14T02:46:07.129] _job_complete: JobId=50643 WEXITSTATUS 0
[2022-10-14T02:46:07.129] _job_complete: JobId=50643 done
[2022-10-14T02:46:08.164] sched: Allocate JobId=50678 NodeList=cpu01 #CPUs=8 Partition=cpu-opteron
[2022-10-14T02:46:52.462] _job_complete: JobId=50645 WEXITSTATUS 0
[2022-10-14T02:46:52.462] _job_complete: JobId=50645 done
[2022-10-14T02:46:53.374] sched: Allocate JobId=50679 NodeList=cpu11 #CPUs=8 Partition=cpu-opteron
[2022-10-14T02:50:40.020] _job_complete: JobId=50644 WEXITSTATUS 0
[2022-10-14T02:50:40.020] _job_complete: JobId=50644 done
[2022-10-14T02:50:40.746] sched: Allocate JobId=50680 NodeList=cpu11 #CPUs=8 Partition=cpu-opteron
[2022-10-14T03:05:43.060] _job_complete: JobId=50653 WEXITSTATUS 0
[2022-10-14T03:05:43.061] _job_complete: JobId=50653 done
[2022-10-14T03:05:44.421] sched: Allocate JobId=50681 NodeList=cpu01 #CPUs=8 Partition=cpu-opteron
[2022-10-14T03:07:56.761] _job_complete: JobId=50647 WEXITSTATUS 0
[2022-10-14T03:07:56.761] _job_complete: JobId=50647 done
[2022-10-14T03:07:58.124] sched: Allocate JobId=50682 NodeList=cpu01 #CPUs=8 Partition=cpu-opteron
[2022-10-14T03:08:05.368] _job_complete: JobId=50688 WEXITSTATUS 0
[2022-10-14T03:08:05.368] _job_complete: JobId=50688 done
[2022-10-14T03:11:11.775] _job_complete: JobId=50646 WEXITSTATUS 0
[2022-10-14T03:11:11.775] _job_complete: JobId=50646 done
[2022-10-14T03:11:13.307] sched: Allocate JobId=50683 NodeList=cpu01 #CPUs=8 Partition=cpu-opteron
[2022-10-14T03:15:02.017] _job_complete: JobId=50651 WEXITSTATUS 0
[2022-10-14T03:15:02.018] _job_complete: JobId=50651 done
[2022-10-14T03:15:03.624] sched: Allocate JobId=50684 NodeList=cpu01 #CPUs=8 Partition=cpu-opteron
[2022-10-14T03:15:29.406] _job_complete: JobId=50648 WEXITSTATUS 0
[2022-10-14T03:15:29.407] _job_complete: JobId=50648 done
[2022-10-14T03:15:30.373] sched: Allocate JobId=50685 NodeList=cpu11 #CPUs=8 Partition=cpu-opteron
[2022-10-14T03:16:37.054] _job_complete: JobId=50649 WEXITSTATUS 0
[2022-10-14T03:16:37.054] _job_complete: JobId=50649 done
[2022-10-14T03:27:28.852] _job_complete: JobId=50650 WEXITSTATUS 0
[2022-10-14T03:27:28.853] _job_complete: JobId=50650 done
[2022-10-14T03:27:41.652] _job_complete: JobId=50652 WEXITSTATUS 0
[2022-10-14T03:27:41.652] _job_complete: JobId=50652 done
[2022-10-14T04:04:53.474] _job_complete: JobId=50677 WEXITSTATUS 0
[2022-10-14T04:04:53.474] _job_complete: JobId=50677 done
[2022-10-14T04:04:54.273] sched: Allocate JobId=50686 NodeList=cpu11 #CPUs=32 Partition=cpu-opteron
[2022-10-14T04:04:56.077] _job_complete: JobId=50686 WEXITSTATUS 1
[2022-10-14T04:04:56.077] _job_complete: JobId=50686 done
[2022-10-14T04:15:35.902] _job_complete: JobId=50676 WEXITSTATUS 0
[2022-10-14T04:15:35.903] _job_complete: JobId=50676 done
[2022-10-14T05:10:55.624] _job_complete: JobId=50505 WEXITSTATUS 0
[2022-10-14T05:10:55.624] _job_complete: JobId=50505 done
[2022-10-14T05:10:56.020] sched: Allocate JobId=50675 NodeList=cpu13 #CPUs=12 Partition=cpu-epyc
[2022-10-14T05:10:56.035] sched: Allocate JobId=50662 NodeList=cpu13 #CPUs=8 Partition=cpu-epyc
[2022-10-14T05:10:56.036] sched: Allocate JobId=50663 NodeList=cpu13 #CPUs=8 Partition=cpu-epyc
[2022-10-14T05:10:56.037] sched: Allocate JobId=50664 NodeList=cpu13 #CPUs=8 Partition=cpu-epyc
[2022-10-14T05:10:56.038] sched: Allocate JobId=50665 NodeList=cpu13 #CPUs=8 Partition=cpu-epyc
[2022-10-14T05:10:58.047] _job_complete: JobId=50675 WEXITSTATUS 0
[2022-10-14T05:10:58.047] _job_complete: JobId=50675 done
[2022-10-14T05:10:58.391] sched: Allocate JobId=50666 NodeList=cpu13 #CPUs=8 Partition=cpu-epyc
[2022-10-14T05:10:58.391] sched: Allocate JobId=50667 NodeList=cpu13 #CPUs=8 Partition=cpu-epyc
[2022-10-14T05:16:23.036] _job_complete: JobId=50410 WEXITSTATUS 0
[2022-10-14T05:16:23.042] _job_complete: JobId=50410 done
[2022-10-14T05:16:24.060] sched: Allocate JobId=50411 NodeList=gpu05 #CPUs=32 Partition=gpu-v100s
[2022-10-14T05:18:28.244] _job_complete: JobId=50504 WEXITSTATUS 0
[2022-10-14T05:18:28.244] _job_complete: JobId=50504 done
[2022-10-14T05:18:28.557] sched: Allocate JobId=50668 NodeList=cpu12 #CPUs=8 Partition=cpu-epyc
[2022-10-14T05:18:28.558] sched: Allocate JobId=50669 NodeList=cpu12 #CPUs=8 Partition=cpu-epyc
[2022-10-14T05:18:28.559] sched: Allocate JobId=50670 NodeList=cpu12 #CPUs=8 Partition=cpu-epyc
[2022-10-14T05:18:28.559] sched: Allocate JobId=50671 NodeList=cpu12 #CPUs=8 Partition=cpu-epyc
[2022-10-14T05:24:40.839] sched: _slurm_rpc_allocate_resources JobId=50692 NodeList=(null) usec=1121
[2022-10-14T05:24:41.845] sched: Allocate JobId=50692 NodeList=cpu01 #CPUs=16 Partition=cpu-opteron
[2022-10-14T05:44:56.260] _job_complete: JobId=50667 WEXITSTATUS 0
[2022-10-14T05:44:56.260] _job_complete: JobId=50667 done
[2022-10-14T05:48:38.948] _job_complete: JobId=50666 WEXITSTATUS 0
[2022-10-14T05:48:38.948] _job_complete: JobId=50666 done
[2022-10-14T05:49:23.423] _job_complete: JobId=50665 WEXITSTATUS 0
[2022-10-14T05:49:23.423] _job_complete: JobId=50665 done
[2022-10-14T05:51:09.962] _job_complete: JobId=50663 WEXITSTATUS 0
[2022-10-14T05:51:09.962] _job_complete: JobId=50663 done
[2022-10-14T05:52:44.113] _job_complete: JobId=50662 WEXITSTATUS 0
[2022-10-14T05:52:44.113] _job_complete: JobId=50662 done
[2022-10-14T05:53:05.508] _job_complete: JobId=50664 WEXITSTATUS 0
[2022-10-14T05:53:05.509] _job_complete: JobId=50664 done
[2022-10-14T05:53:05.807] sched: Allocate JobId=50506 NodeList=cpu13 #CPUs=48 Partition=cpu-epyc
[2022-10-14T05:55:39.105] _job_complete: JobId=50668 WEXITSTATUS 0
[2022-10-14T05:55:39.105] _job_complete: JobId=50668 done
[2022-10-14T05:56:15.248] _job_complete: JobId=50669 WEXITSTATUS 0
[2022-10-14T05:56:15.248] _job_complete: JobId=50669 done
[2022-10-14T05:57:28.185] _job_complete: JobId=50671 WEXITSTATUS 0
[2022-10-14T05:57:28.185] _job_complete: JobId=50671 done
[2022-10-14T06:01:44.467] _job_complete: JobId=50670 WEXITSTATUS 0
[2022-10-14T06:01:44.467] _job_complete: JobId=50670 done
[2022-10-14T06:01:45.003] sched: Allocate JobId=50507 NodeList=cpu12 #CPUs=48 Partition=cpu-epyc
[2022-10-14T06:11:49.030] _job_complete: JobId=50682 WEXITSTATUS 0
[2022-10-14T06:11:49.030] _job_complete: JobId=50682 done
[2022-10-14T06:13:19.577] _job_complete: JobId=50680 WEXITSTATUS 0
[2022-10-14T06:13:19.578] _job_complete: JobId=50680 done
[2022-10-14T06:17:52.347] _job_complete: JobId=50679 WEXITSTATUS 0
[2022-10-14T06:17:52.347] _job_complete: JobId=50679 done
[2022-10-14T06:23:11.070] _job_complete: JobId=50678 WEXITSTATUS 0
[2022-10-14T06:23:11.070] _job_complete: JobId=50678 done
[2022-10-14T06:24:29.153] _job_complete: JobId=50684 WEXITSTATUS 0
[2022-10-14T06:24:29.153] _job_complete: JobId=50684 done
[2022-10-14T06:30:24.225] _job_complete: JobId=50681 WEXITSTATUS 0
[2022-10-14T06:30:24.225] _job_complete: JobId=50681 done
[2022-10-14T06:59:26.819] _job_complete: JobId=50685 WEXITSTATUS 0
[2022-10-14T06:59:26.819] _job_complete: JobId=50685 done
[2022-10-14T07:11:56.466] _job_complete: JobId=50683 WEXITSTATUS 0
[2022-10-14T07:11:56.467] _job_complete: JobId=50683 done
[2022-10-14T07:37:50.752] sched: _slurm_rpc_allocate_resources JobId=50693 NodeList=cpu01 usec=24471
[2022-10-14T07:46:29.960] _slurm_rpc_submit_batch_job: JobId=50694 InitPrio=9128 usec=468
[2022-10-14T07:46:30.619] sched: Allocate JobId=50694 NodeList=cpu01 #CPUs=1 Partition=cpu-opteron
[2022-10-14T08:28:26.865] _slurm_rpc_submit_batch_job: JobId=50695 InitPrio=4356 usec=565
[2022-10-14T08:28:27.224] sched: Allocate JobId=50695 NodeList=cpu01 #CPUs=16 Partition=cpu-opteron
[2022-10-14T08:28:28.442] _job_complete: JobId=50695 WEXITSTATUS 0
[2022-10-14T08:28:28.442] _job_complete: JobId=50695 done
[2022-10-14T08:32:26.851] _job_complete: JobId=50694 WEXITSTATUS 0
[2022-10-14T08:32:26.851] _job_complete: JobId=50694 done
[2022-10-14T08:53:27.887] _slurm_rpc_submit_batch_job: JobId=50696 InitPrio=4356 usec=487
[2022-10-14T08:53:28.868] sched: Allocate JobId=50696 NodeList=cpu01 #CPUs=16 Partition=cpu-opteron
[2022-10-14T08:53:30.033] _job_complete: JobId=50696 WEXITSTATUS 0
[2022-10-14T08:53:30.033] _job_complete: JobId=50696 done
[2022-10-14T08:55:49.324] _slurm_rpc_submit_batch_job: JobId=50697 InitPrio=4356 usec=486
[2022-10-14T08:55:50.055] sched: Allocate JobId=50697 NodeList=cpu01 #CPUs=16 Partition=cpu-opteron
[2022-10-14T08:55:56.633] _job_complete: JobId=50697 WEXITSTATUS 31
[2022-10-14T08:55:56.633] _job_complete: JobId=50697 done
[2022-10-14T08:58:08.422] _slurm_rpc_kill_job: REQUEST_KILL_JOB JobId=50697 uid 548300584
[2022-10-14T09:00:55.145] _slurm_rpc_submit_batch_job: JobId=50698 InitPrio=4356 usec=484
[2022-10-14T09:00:55.593] sched: Allocate JobId=50698 NodeList=cpu01 #CPUs=16 Partition=cpu-opteron
[2022-10-14T09:01:01.815] _job_complete: JobId=50698 WEXITSTATUS 31
[2022-10-14T09:01:01.815] _job_complete: JobId=50698 done
[2022-10-14T09:04:02.445] _slurm_rpc_submit_batch_job: JobId=50699 InitPrio=4356 usec=494
[2022-10-14T09:06:19.825] _slurm_rpc_submit_batch_job: JobId=50700 InitPrio=4356 usec=592
[2022-10-14T09:06:20.493] sched: Allocate JobId=50700 NodeList=cpu01 #CPUs=16 Partition=cpu-opteron
[2022-10-14T09:06:44.802] _slurm_rpc_kill_job: REQUEST_KILL_JOB JobId=50699 uid 548300584
[2022-10-14T09:06:46.142] _job_complete: JobId=50700 WEXITSTATUS 0
[2022-10-14T09:06:46.142] _job_complete: JobId=50700 done
[2022-10-14T09:18:07.449] _slurm_rpc_submit_batch_job: JobId=50701 InitPrio=4356 usec=547
[2022-10-14T09:49:33.764] _slurm_rpc_submit_batch_job: JobId=50702 InitPrio=2697 usec=498
[2022-10-14T09:49:34.707] sched: Allocate JobId=50702 NodeList=cpu01 #CPUs=8 Partition=cpu-opteron
[2022-10-14T09:49:37.331] _slurm_rpc_submit_batch_job: JobId=50703 InitPrio=2697 usec=507
[2022-10-14T09:49:37.690] sched: Allocate JobId=50703 NodeList=cpu01 #CPUs=8 Partition=cpu-opteron
[2022-10-14T09:49:40.804] _slurm_rpc_submit_batch_job: JobId=50704 InitPrio=2697 usec=412
[2022-10-14T09:49:41.695] sched: Allocate JobId=50704 NodeList=cpu01 #CPUs=8 Partition=cpu-opteron
[2022-10-14T09:49:43.571] _slurm_rpc_submit_batch_job: JobId=50705 InitPrio=2697 usec=468
[2022-10-14T09:49:44.699] sched: Allocate JobId=50705 NodeList=cpu01 #CPUs=8 Partition=cpu-opteron
[2022-10-14T09:49:46.260] _slurm_rpc_submit_batch_job: JobId=50706 InitPrio=2697 usec=592
[2022-10-14T09:49:47.703] sched: Allocate JobId=50706 NodeList=cpu01 #CPUs=8 Partition=cpu-opteron
[2022-10-14T09:49:48.837] _slurm_rpc_submit_batch_job: JobId=50707 InitPrio=2697 usec=424
[2022-10-14T09:49:50.707] sched: Allocate JobId=50707 NodeList=cpu11 #CPUs=8 Partition=cpu-opteron
[2022-10-14T09:49:51.757] _slurm_rpc_submit_batch_job: JobId=50708 InitPrio=2697 usec=476
[2022-10-14T09:49:53.711] sched: Allocate JobId=50708 NodeList=cpu11 #CPUs=8 Partition=cpu-opteron
[2022-10-14T09:49:54.411] _slurm_rpc_submit_batch_job: JobId=50709 InitPrio=2697 usec=500
[2022-10-14T09:49:56.715] sched: Allocate JobId=50709 NodeList=cpu11 #CPUs=8 Partition=cpu-opteron
[2022-10-14T09:49:57.172] _slurm_rpc_submit_batch_job: JobId=50710 InitPrio=2697 usec=482
[2022-10-14T09:49:59.720] sched: Allocate JobId=50710 NodeList=cpu11 #CPUs=8 Partition=cpu-opteron
[2022-10-14T09:50:00.774] _slurm_rpc_submit_batch_job: JobId=50711 InitPrio=2697 usec=495
[2022-10-14T09:50:02.724] sched: Allocate JobId=50711 NodeList=cpu11 #CPUs=8 Partition=cpu-opteron
[2022-10-14T09:50:44.699] _slurm_rpc_submit_batch_job: JobId=50712 InitPrio=2697 usec=506
[2022-10-14T09:50:44.783] sched: Allocate JobId=50712 NodeList=cpu11 #CPUs=8 Partition=cpu-opteron
[2022-10-14T09:50:47.709] _slurm_rpc_submit_batch_job: JobId=50713 InitPrio=2697 usec=454
[2022-10-14T09:50:50.605] _slurm_rpc_submit_batch_job: JobId=50714 InitPrio=2697 usec=444
[2022-10-14T09:50:53.149] _slurm_rpc_submit_batch_job: JobId=50715 InitPrio=2904 usec=434
[2022-10-14T09:50:56.220] _slurm_rpc_submit_batch_job: JobId=50716 InitPrio=2904 usec=421
[2022-10-14T09:50:58.709] _slurm_rpc_submit_batch_job: JobId=50717 InitPrio=2904 usec=532
[2022-10-14T09:51:01.357] _slurm_rpc_submit_batch_job: JobId=50718 InitPrio=2904 usec=491
[2022-10-14T09:51:04.199] _slurm_rpc_submit_batch_job: JobId=50719 InitPrio=2904 usec=507
[2022-10-14T09:51:06.949] _slurm_rpc_submit_batch_job: JobId=50720 InitPrio=2904 usec=508
[2022-10-14T09:51:10.725] _slurm_rpc_submit_batch_job: JobId=50721 InitPrio=2904 usec=455
[2022-10-14T09:51:13.357] _slurm_rpc_submit_batch_job: JobId=50722 InitPrio=2904 usec=528
[2022-10-14T09:51:15.893] _slurm_rpc_submit_batch_job: JobId=50723 InitPrio=2904 usec=457
[2022-10-14T09:51:18.639] _slurm_rpc_submit_batch_job: JobId=50724 InitPrio=2904 usec=75197
[2022-10-14T09:51:21.525] _slurm_rpc_submit_batch_job: JobId=50725 InitPrio=2904 usec=420
[2022-10-14T09:51:24.565] _slurm_rpc_submit_batch_job: JobId=50726 InitPrio=2904 usec=503
[2022-10-14T09:51:27.174] _slurm_rpc_submit_batch_job: JobId=50727 InitPrio=2904 usec=645
[2022-10-14T09:51:29.750] _slurm_rpc_submit_batch_job: JobId=50728 InitPrio=2904 usec=388
[2022-10-14T09:51:32.358] _slurm_rpc_submit_batch_job: JobId=50729 InitPrio=2904 usec=407
[2022-10-14T09:51:34.917] _slurm_rpc_submit_batch_job: JobId=50730 InitPrio=2904 usec=457
[2022-10-14T09:51:38.387] _slurm_rpc_submit_batch_job: JobId=50731 InitPrio=2904 usec=478
[2022-10-14T09:51:41.093] _slurm_rpc_submit_batch_job: JobId=50732 InitPrio=2904 usec=433
[2022-10-14T09:51:43.917] _slurm_rpc_submit_batch_job: JobId=50733 InitPrio=2904 usec=458
[2022-10-14T09:51:46.589] _slurm_rpc_submit_batch_job: JobId=50734 InitPrio=2904 usec=488
[2022-10-14T09:51:49.109] _slurm_rpc_submit_batch_job: JobId=50735 InitPrio=2904 usec=545
[2022-10-14T09:51:51.581] _slurm_rpc_submit_batch_job: JobId=50736 InitPrio=2904 usec=497
[2022-10-14T09:51:54.181] _slurm_rpc_submit_batch_job: JobId=50737 InitPrio=2904 usec=414
[2022-10-14T09:51:57.029] _slurm_rpc_submit_batch_job: JobId=50738 InitPrio=2904 usec=480
[2022-10-14T09:51:59.684] _slurm_rpc_submit_batch_job: JobId=50739 InitPrio=2904 usec=528
[2022-10-14T09:52:02.565] _slurm_rpc_submit_batch_job: JobId=50740 InitPrio=2904 usec=433
[2022-10-14T09:52:06.325] _slurm_rpc_submit_batch_job: JobId=50741 InitPrio=2904 usec=450
[2022-10-14T09:53:35.298] job_step_signal: JobId=50693 StepId=0 not found
[2022-10-14T09:53:35.300] _job_complete: JobId=50693 WTERMSIG 126
[2022-10-14T09:53:35.300] _job_complete: JobId=50693 cancelled by interactive user
[2022-10-14T09:53:35.300] _job_complete: JobId=50693 done
[2022-10-14T10:11:59.480] _slurm_rpc_submit_batch_job: JobId=50742 InitPrio=4356 usec=708
[2022-10-14T10:31:57.722] _slurm_rpc_submit_batch_job: JobId=50743 InitPrio=2697 usec=483
[2022-10-14T10:32:01.609] _slurm_rpc_submit_batch_job: JobId=50744 InitPrio=2697 usec=427
[2022-10-14T10:32:04.883] _slurm_rpc_submit_batch_job: JobId=50745 InitPrio=2697 usec=642
[2022-10-14T10:32:08.080] _slurm_rpc_submit_batch_job: JobId=50746 InitPrio=2697 usec=451
[2022-10-14T10:32:11.448] _slurm_rpc_submit_batch_job: JobId=50747 InitPrio=2697 usec=593
[2022-10-14T10:32:14.913] _slurm_rpc_submit_batch_job: JobId=50748 InitPrio=2697 usec=502
[2022-10-14T10:32:23.680] _slurm_rpc_submit_batch_job: JobId=50749 InitPrio=2697 usec=428
[2022-10-14T10:32:27.976] _slurm_rpc_submit_batch_job: JobId=50750 InitPrio=2697 usec=517
[2022-10-14T11:27:13.251] _job_complete: JobId=50692 WEXITSTATUS 0
[2022-10-14T11:27:13.251] _job_complete: JobId=50692 done
[2022-10-14T11:32:14.171] cleanup_completing: JobId=50692 completion process took 301 seconds
[2022-10-14T11:32:14.188] sched: Allocate JobId=50713 NodeList=cpu01 #CPUs=8 Partition=cpu-opteron
[2022-10-14T11:32:14.189] sched: Allocate JobId=50714 NodeList=cpu01 #CPUs=8 Partition=cpu-opteron
[2022-10-14T12:10:35.382] _slurm_rpc_submit_batch_job: JobId=50751 InitPrio=4356 usec=611
[2022-10-14T12:53:58.202] _job_complete: JobId=50709 WEXITSTATUS 0
[2022-10-14T12:53:58.203] _job_complete: JobId=50709 done
[2022-10-14T12:53:59.168] sched: Allocate JobId=50751 NodeList=cpu11 #CPUs=16 Partition=cpu-opteron
[2022-10-14T12:54:00.598] _job_complete: JobId=50751 WEXITSTATUS 0
[2022-10-14T12:54:00.598] _job_complete: JobId=50751 done
[2022-10-14T12:54:01.545] sched: Allocate JobId=50715 NodeList=cpu11 #CPUs=8 Partition=cpu-opteron
[2022-10-14T13:08:21.082] _job_complete: JobId=50705 WEXITSTATUS 0
[2022-10-14T13:08:21.082] _job_complete: JobId=50705 done
[2022-10-14T13:08:22.503] sched: Allocate JobId=50716 NodeList=cpu01 #CPUs=8 Partition=cpu-opteron
[2022-10-14T13:08:47.040] _job_complete: JobId=50702 WEXITSTATUS 0
[2022-10-14T13:08:47.040] _job_complete: JobId=50702 done
[2022-10-14T13:08:48.360] sched: Allocate JobId=50717 NodeList=cpu01 #CPUs=8 Partition=cpu-opteron
[2022-10-14T13:12:14.362] _job_complete: JobId=50712 WEXITSTATUS 0
[2022-10-14T13:12:14.363] _job_complete: JobId=50712 done
[2022-10-14T13:12:15.613] sched: Allocate JobId=50718 NodeList=cpu11 #CPUs=8 Partition=cpu-opteron
[2022-10-14T13:15:51.583] _job_complete: JobId=50704 WEXITSTATUS 0
[2022-10-14T13:15:51.583] _job_complete: JobId=50704 done
[2022-10-14T13:15:52.896] sched: Allocate JobId=50719 NodeList=cpu01 #CPUs=8 Partition=cpu-opteron
[2022-10-14T13:17:40.198] _job_complete: JobId=50710 WEXITSTATUS 0
[2022-10-14T13:17:40.198] _job_complete: JobId=50710 done
[2022-10-14T13:17:40.994] sched: Allocate JobId=50720 NodeList=cpu11 #CPUs=8 Partition=cpu-opteron
[2022-10-14T13:17:41.230] _job_complete: JobId=50711 WEXITSTATUS 0
[2022-10-14T13:17:41.230] _job_complete: JobId=50711 done
[2022-10-14T13:17:42.590] sched: Allocate JobId=50721 NodeList=cpu11 #CPUs=8 Partition=cpu-opteron
[2022-10-14T13:19:08.630] _job_complete: JobId=50708 WEXITSTATUS 0
[2022-10-14T13:19:08.630] _job_complete: JobId=50708 done
[2022-10-14T13:19:09.432] sched: Allocate JobId=50722 NodeList=cpu11 #CPUs=8 Partition=cpu-opteron
[2022-10-14T13:27:15.171] _job_complete: JobId=50703 WEXITSTATUS 0
[2022-10-14T13:27:15.171] _job_complete: JobId=50703 done
[2022-10-14T13:27:15.913] sched: Allocate JobId=50723 NodeList=cpu01 #CPUs=8 Partition=cpu-opteron
[2022-10-14T13:37:08.785] _job_complete: JobId=50707 WEXITSTATUS 0
[2022-10-14T13:37:08.786] _job_complete: JobId=50707 done
[2022-10-14T13:37:09.617] sched: Allocate JobId=50724 NodeList=cpu11 #CPUs=8 Partition=cpu-opteron
[2022-10-14T13:41:24.511] _job_complete: JobId=50706 WEXITSTATUS 0
[2022-10-14T13:41:24.511] _job_complete: JobId=50706 done
[2022-10-14T13:41:26.026] sched: Allocate JobId=50725 NodeList=cpu01 #CPUs=8 Partition=cpu-opteron
[2022-10-14T14:24:04.167] _slurm_rpc_submit_batch_job: JobId=50752 InitPrio=4356 usec=635
[2022-10-14T14:24:04.930] sched: Allocate JobId=50752 NodeList=cpu11 #CPUs=8 Partition=cpu-opteron
[2022-10-14T14:24:13.580] _job_complete: JobId=50752 WEXITSTATUS 0
[2022-10-14T14:24:13.581] _job_complete: JobId=50752 done
[2022-10-14T14:47:56.274] _job_complete: JobId=50714 WEXITSTATUS 0
[2022-10-14T14:47:56.274] _job_complete: JobId=50714 done
[2022-10-14T14:47:57.940] sched: Allocate JobId=50726 NodeList=cpu01 #CPUs=8 Partition=cpu-opteron
[2022-10-14T14:49:12.526] _slurm_rpc_submit_batch_job: JobId=50753 InitPrio=2697 usec=518
[2022-10-14T14:49:15.281] _slurm_rpc_submit_batch_job: JobId=50754 InitPrio=2697 usec=548
[2022-10-14T14:49:17.978] _slurm_rpc_submit_batch_job: JobId=50755 InitPrio=2697 usec=484
[2022-10-14T14:49:20.555] _slurm_rpc_submit_batch_job: JobId=50756 InitPrio=2697 usec=391
[2022-10-14T14:49:23.857] _slurm_rpc_submit_batch_job: JobId=50757 InitPrio=2697 usec=444
[2022-10-14T14:49:27.114] _slurm_rpc_submit_batch_job: JobId=50758 InitPrio=2697 usec=522
[2022-10-14T14:49:29.546] _slurm_rpc_submit_batch_job: JobId=50759 InitPrio=2697 usec=473
[2022-10-14T14:49:32.210] _slurm_rpc_submit_batch_job: JobId=50760 InitPrio=2697 usec=406
[2022-10-14T14:49:34.787] _slurm_rpc_submit_batch_job: JobId=50761 InitPrio=2697 usec=512
[2022-10-14T14:49:38.194] _slurm_rpc_submit_batch_job: JobId=50762 InitPrio=2697 usec=549
[2022-10-14T14:49:40.851] _slurm_rpc_submit_batch_job: JobId=50763 InitPrio=2697 usec=463
[2022-10-14T14:49:43.352] _slurm_rpc_submit_batch_job: JobId=50764 InitPrio=2697 usec=626
[2022-10-14T14:49:45.858] _slurm_rpc_submit_batch_job: JobId=50765 InitPrio=2697 usec=463
[2022-10-14T14:49:48.250] _slurm_rpc_submit_batch_job: JobId=50766 InitPrio=2697 usec=473
[2022-10-14T14:50:44.917] _slurm_rpc_submit_batch_job: JobId=50767 InitPrio=2697 usec=474
[2022-10-14T14:50:48.603] _slurm_rpc_submit_batch_job: JobId=50768 InitPrio=2697 usec=422
[2022-10-14T14:50:51.318] _slurm_rpc_submit_batch_job: JobId=50769 InitPrio=2697 usec=653
[2022-10-14T14:50:53.947] _slurm_rpc_submit_batch_job: JobId=50770 InitPrio=2697 usec=450
[2022-10-14T14:50:56.867] _slurm_rpc_submit_batch_job: JobId=50771 InitPrio=2697 usec=444
[2022-10-14T14:51:00.146] _slurm_rpc_submit_batch_job: JobId=50772 InitPrio=2697 usec=492
[2022-10-14T14:51:02.795] _slurm_rpc_submit_batch_job: JobId=50773 InitPrio=2697 usec=675
[2022-10-14T14:51:05.283] _slurm_rpc_submit_batch_job: JobId=50774 InitPrio=2697 usec=528
[2022-10-14T14:51:07.786] _slurm_rpc_submit_batch_job: JobId=50775 InitPrio=2697 usec=511
[2022-10-14T14:51:10.171] _slurm_rpc_submit_batch_job: JobId=50776 InitPrio=2697 usec=507
[2022-10-14T14:51:12.747] _slurm_rpc_submit_batch_job: JobId=50777 InitPrio=2697 usec=418
[2022-10-14T14:51:15.571] _slurm_rpc_submit_batch_job: JobId=50778 InitPrio=2697 usec=938
[2022-10-14T14:51:18.251] _slurm_rpc_submit_batch_job: JobId=50779 InitPrio=2697 usec=566
[2022-10-14T14:51:20.908] _slurm_rpc_submit_batch_job: JobId=50780 InitPrio=2697 usec=410
[2022-10-14T14:51:23.620] _slurm_rpc_submit_batch_job: JobId=50781 InitPrio=2697 usec=450
[2022-10-14T14:51:27.052] _slurm_rpc_submit_batch_job: JobId=50782 InitPrio=2697 usec=599
[2022-10-14T14:52:00.338] _job_complete: JobId=50713 WEXITSTATUS 0
[2022-10-14T14:52:00.338] _job_complete: JobId=50713 done
[2022-10-14T14:52:01.063] sched: Allocate JobId=50727 NodeList=cpu01 #CPUs=8 Partition=cpu-opteron
[2022-10-14T15:22:42.405] _slurm_rpc_submit_batch_job: JobId=50783 InitPrio=622 usec=554
[2022-10-14T15:23:19.574] _slurm_rpc_kill_job: REQUEST_KILL_JOB JobId=50783 uid 548200023
[2022-10-14T15:23:24.089] _slurm_rpc_submit_batch_job: JobId=50784 InitPrio=622 usec=580
[2022-10-14T15:23:25.950] sched/backfill: _start_job: Started JobId=50784 in cpu-opteron on cpu11
[2022-10-14T15:23:27.633] _job_complete: JobId=50784 WEXITSTATUS 1
[2022-10-14T15:23:27.634] _job_complete: JobId=50784 done
[2022-10-14T15:28:59.338] _slurm_rpc_submit_batch_job: JobId=50785 InitPrio=622 usec=691
[2022-10-14T16:11:05.394] _job_complete: JobId=50715 WEXITSTATUS 0
[2022-10-14T16:11:05.394] _job_complete: JobId=50715 done
[2022-10-14T16:11:06.256] sched: Allocate JobId=50728 NodeList=cpu11 #CPUs=8 Partition=cpu-opteron
[2022-10-14T16:29:10.918] _job_complete: JobId=50717 WEXITSTATUS 0
[2022-10-14T16:29:10.918] _job_complete: JobId=50717 done
[2022-10-14T16:29:12.265] sched: Allocate JobId=50729 NodeList=cpu01 #CPUs=8 Partition=cpu-opteron
[2022-10-14T16:32:21.363] _slurm_rpc_submit_batch_job: JobId=50786 InitPrio=2697 usec=557
[2022-10-14T16:32:24.194] _slurm_rpc_submit_batch_job: JobId=50787 InitPrio=2697 usec=455
[2022-10-14T16:32:26.755] _slurm_rpc_submit_batch_job: JobId=50788 InitPrio=2697 usec=620
[2022-10-14T16:32:29.234] _slurm_rpc_submit_batch_job: JobId=50789 InitPrio=2697 usec=451
[2022-10-14T16:32:31.802] _slurm_rpc_submit_batch_job: JobId=50790 InitPrio=2697 usec=477
[2022-10-14T16:32:34.203] _slurm_rpc_submit_batch_job: JobId=50791 InitPrio=2697 usec=497
[2022-10-14T16:32:36.490] _slurm_rpc_submit_batch_job: JobId=50792 InitPrio=2697 usec=495
[2022-10-14T16:32:38.934] _slurm_rpc_submit_batch_job: JobId=50793 InitPrio=2697 usec=468
[2022-10-14T16:32:41.370] _slurm_rpc_submit_batch_job: JobId=50794 InitPrio=2697 usec=570
[2022-10-14T16:32:44.123] _slurm_rpc_submit_batch_job: JobId=50795 InitPrio=2697 usec=709
[2022-10-14T16:32:46.658] _slurm_rpc_submit_batch_job: JobId=50796 InitPrio=2697 usec=623
[2022-10-14T16:32:49.202] _slurm_rpc_submit_batch_job: JobId=50797 InitPrio=2697 usec=483
[2022-10-14T16:32:52.122] _slurm_rpc_submit_batch_job: JobId=50798 InitPrio=2697 usec=407
[2022-10-14T16:32:54.682] _slurm_rpc_submit_batch_job: JobId=50799 InitPrio=2697 usec=533
[2022-10-14T16:32:57.290] _slurm_rpc_submit_batch_job: JobId=50800 InitPrio=2697 usec=441
[2022-10-14T16:32:59.810] _slurm_rpc_submit_batch_job: JobId=50801 InitPrio=2697 usec=424
[2022-10-14T16:33:02.042] _slurm_rpc_submit_batch_job: JobId=50802 InitPrio=2697 usec=421
[2022-10-14T16:33:04.778] _slurm_rpc_submit_batch_job: JobId=50803 InitPrio=2697 usec=507
[2022-10-14T16:33:08.049] _slurm_rpc_submit_batch_job: JobId=50804 InitPrio=2697 usec=436
[2022-10-14T16:33:11.914] _slurm_rpc_submit_batch_job: JobId=50805 InitPrio=2697 usec=420
[2022-10-14T16:42:23.797] _slurm_rpc_delete_reservation complete for cp2k_test usec=90
[2022-10-14T16:42:24.544] sched: Allocate JobId=50742 NodeList=cpu15 #CPUs=4 Partition=cpu-epyc
[2022-10-14T16:42:24.548] sched: Allocate JobId=50743 NodeList=cpu15 #CPUs=8 Partition=cpu-epyc
[2022-10-14T16:42:24.549] sched: Allocate JobId=50744 NodeList=cpu15 #CPUs=8 Partition=cpu-epyc
[2022-10-14T16:42:24.550] sched: Allocate JobId=50745 NodeList=cpu15 #CPUs=8 Partition=cpu-epyc
[2022-10-14T16:42:24.550] sched: Allocate JobId=50746 NodeList=cpu15 #CPUs=8 Partition=cpu-epyc
[2022-10-14T16:42:24.551] sched: Allocate JobId=50747 NodeList=cpu15 #CPUs=8 Partition=cpu-epyc
[2022-10-14T16:42:25.494] _job_complete: JobId=50742 WEXITSTATUS 0
[2022-10-14T16:42:25.494] _job_complete: JobId=50742 done
[2022-10-14T16:42:26.047] sched: Allocate JobId=50748 NodeList=cpu15 #CPUs=8 Partition=cpu-epyc
[2022-10-14T16:43:57.221] _job_complete: JobId=50723 WEXITSTATUS 0
[2022-10-14T16:43:57.221] _job_complete: JobId=50723 done
[2022-10-14T16:43:58.616] sched: Allocate JobId=50730 NodeList=cpu01 #CPUs=8 Partition=cpu-opteron
[2022-10-14T16:48:42.488] _job_complete: JobId=50722 WEXITSTATUS 0
[2022-10-14T16:48:42.488] _job_complete: JobId=50722 done
[2022-10-14T16:48:43.467] sched: Allocate JobId=50731 NodeList=cpu11 #CPUs=8 Partition=cpu-opteron
[2022-10-14T16:51:25.261] _job_complete: JobId=50716 WEXITSTATUS 0
[2022-10-14T16:51:25.262] _job_complete: JobId=50716 done
[2022-10-14T16:51:26.526] sched: Allocate JobId=50732 NodeList=cpu01 #CPUs=8 Partition=cpu-opteron
[2022-10-14T16:52:52.211] _job_complete: JobId=50720 WEXITSTATUS 0
[2022-10-14T16:52:52.211] _job_complete: JobId=50720 done
[2022-10-14T16:52:52.964] sched: Allocate JobId=50733 NodeList=cpu11 #CPUs=8 Partition=cpu-opteron
[2022-10-14T16:56:30.097] _job_complete: JobId=50748 WEXITSTATUS 0
[2022-10-14T16:56:30.097] _job_complete: JobId=50748 done
[2022-10-14T16:56:30.452] sched: Allocate JobId=50749 NodeList=cpu15 #CPUs=8 Partition=cpu-epyc
[2022-10-14T16:56:55.889] _job_complete: JobId=50743 WEXITSTATUS 0
[2022-10-14T16:56:55.889] _job_complete: JobId=50743 done
[2022-10-14T16:56:56.224] sched: Allocate JobId=50750 NodeList=cpu15 #CPUs=8 Partition=cpu-epyc
[2022-10-14T16:56:56.956] _job_complete: JobId=50744 WEXITSTATUS 0
[2022-10-14T16:56:56.956] _job_complete: JobId=50744 done
[2022-10-14T16:57:09.494] _job_complete: JobId=50746 WEXITSTATUS 0
[2022-10-14T16:57:09.494] _job_complete: JobId=50746 done
[2022-10-14T16:57:18.842] _job_complete: JobId=50745 WEXITSTATUS 0
[2022-10-14T16:57:18.842] _job_complete: JobId=50745 done
[2022-10-14T16:57:29.236] _job_complete: JobId=50747 WEXITSTATUS 0
[2022-10-14T16:57:29.236] _job_complete: JobId=50747 done
[2022-10-14T16:59:40.035] _slurm_rpc_submit_batch_job: JobId=50806 InitPrio=2697 usec=541
[2022-10-14T16:59:42.982] _slurm_rpc_submit_batch_job: JobId=50807 InitPrio=2697 usec=443
[2022-10-14T16:59:45.462] _slurm_rpc_submit_batch_job: JobId=50808 InitPrio=2697 usec=514
[2022-10-14T16:59:47.887] _slurm_rpc_submit_batch_job: JobId=50809 InitPrio=2697 usec=569
[2022-10-14T16:59:50.446] _slurm_rpc_submit_batch_job: JobId=50810 InitPrio=2697 usec=499
[2022-10-14T16:59:52.926] _slurm_rpc_submit_batch_job: JobId=50811 InitPrio=2697 usec=473
[2022-10-14T16:59:55.326] _slurm_rpc_submit_batch_job: JobId=50812 InitPrio=2697 usec=501
[2022-10-14T16:59:57.758] _slurm_rpc_submit_batch_job: JobId=50813 InitPrio=2697 usec=508
[2022-10-14T17:00:00.286] _slurm_rpc_submit_batch_job: JobId=50814 InitPrio=2697 usec=450
[2022-10-14T17:00:03.726] _slurm_rpc_submit_batch_job: JobId=50815 InitPrio=2697 usec=445
[2022-10-14T17:00:06.479] _slurm_rpc_submit_batch_job: JobId=50816 InitPrio=2697 usec=533
[2022-10-14T17:00:08.919] _slurm_rpc_submit_batch_job: JobId=50817 InitPrio=2697 usec=419
[2022-10-14T17:00:11.623] _slurm_rpc_submit_batch_job: JobId=50818 InitPrio=2697 usec=459
[2022-10-14T17:00:14.056] _slurm_rpc_submit_batch_job: JobId=50819 InitPrio=2697 usec=439
[2022-10-14T17:00:16.807] _slurm_rpc_submit_batch_job: JobId=50820 InitPrio=2697 usec=442
[2022-10-14T17:00:19.526] _slurm_rpc_submit_batch_job: JobId=50821 InitPrio=2697 usec=496
[2022-10-14T17:01:41.712] _job_complete: JobId=50719 WEXITSTATUS 0
[2022-10-14T17:01:41.712] _job_complete: JobId=50719 done
[2022-10-14T17:01:43.029] sched: Allocate JobId=50734 NodeList=cpu01 #CPUs=8 Partition=cpu-opteron
[2022-10-14T17:04:04.773] _job_complete: JobId=50724 WEXITSTATUS 0
[2022-10-14T17:04:04.773] _job_complete: JobId=50724 done
[2022-10-14T17:04:05.620] sched: Allocate JobId=50735 NodeList=cpu11 #CPUs=8 Partition=cpu-opteron
[2022-10-14T17:10:09.705] _job_complete: JobId=50749 WEXITSTATUS 0
[2022-10-14T17:10:09.706] _job_complete: JobId=50749 done
[2022-10-14T17:10:30.074] _job_complete: JobId=50750 WEXITSTATUS 0
[2022-10-14T17:10:30.074] _job_complete: JobId=50750 done
[2022-10-14T17:10:30.453] sched: Allocate JobId=50508 NodeList=cpu15 #CPUs=48 Partition=cpu-epyc
[2022-10-14T17:12:32.147] _job_complete: JobId=50718 WEXITSTATUS 0
[2022-10-14T17:12:32.147] _job_complete: JobId=50718 done
[2022-10-14T17:12:32.894] sched: Allocate JobId=50736 NodeList=cpu11 #CPUs=8 Partition=cpu-opteron
[2022-10-14T17:13:27.015] _job_complete: JobId=50725 WEXITSTATUS 0
[2022-10-14T17:13:27.015] _job_complete: JobId=50725 done
[2022-10-14T17:13:28.644] sched: Allocate JobId=50737 NodeList=cpu01 #CPUs=8 Partition=cpu-opteron
[2022-10-14T17:22:46.822] _job_complete: JobId=50721 WEXITSTATUS 0
[2022-10-14T17:22:46.822] _job_complete: JobId=50721 done
[2022-10-14T17:22:47.755] sched: Allocate JobId=50738 NodeList=cpu11 #CPUs=8 Partition=cpu-opteron
[2022-10-14T17:43:30.735] _slurm_rpc_submit_batch_job: JobId=50822 InitPrio=13112 usec=536
[2022-10-14T17:43:33.013] _slurm_rpc_submit_batch_job: JobId=50823 InitPrio=13112 usec=421
[2022-10-14T17:43:34.513] _slurm_rpc_submit_batch_job: JobId=50824 InitPrio=13112 usec=461
[2022-10-14T17:43:36.132] _slurm_rpc_submit_batch_job: JobId=50825 InitPrio=13112 usec=423
[2022-10-14T17:43:37.706] _slurm_rpc_submit_batch_job: JobId=50826 InitPrio=13112 usec=519
[2022-10-14T17:43:39.572] _slurm_rpc_submit_batch_job: JobId=50827 InitPrio=13112 usec=442
[2022-10-14T17:43:41.322] _slurm_rpc_submit_batch_job: JobId=50828 InitPrio=13112 usec=491
[2022-10-14T17:43:42.965] _slurm_rpc_submit_batch_job: JobId=50829 InitPrio=13112 usec=397
[2022-10-14T17:59:06.679] _job_complete: JobId=50726 WEXITSTATUS 0
[2022-10-14T17:59:06.680] _job_complete: JobId=50726 done
[2022-10-14T17:59:07.807] sched: Allocate JobId=50739 NodeList=cpu01 #CPUs=8 Partition=cpu-opteron
[2022-10-14T18:18:11.691] _job_complete: JobId=50727 WEXITSTATUS 0
[2022-10-14T18:18:11.691] _job_complete: JobId=50727 done
[2022-10-14T18:18:12.466] sched: Allocate JobId=50740 NodeList=cpu01 #CPUs=8 Partition=cpu-opteron
[2022-10-14T19:33:48.394] _job_complete: JobId=50728 WEXITSTATUS 0
[2022-10-14T19:33:48.395] _job_complete: JobId=50728 done
[2022-10-14T19:33:49.313] sched: Allocate JobId=50741 NodeList=cpu11 #CPUs=8 Partition=cpu-opteron
[2022-10-14T19:45:12.450] _job_complete: JobId=50729 WEXITSTATUS 0
[2022-10-14T19:45:12.450] _job_complete: JobId=50729 done
[2022-10-14T19:45:13.647] sched: Allocate JobId=50753 NodeList=cpu01 #CPUs=8 Partition=cpu-opteron
[2022-10-14T19:58:50.971] _job_complete: JobId=50733 WEXITSTATUS 0
[2022-10-14T19:58:50.971] _job_complete: JobId=50733 done
[2022-10-14T19:58:51.829] sched: Allocate JobId=50754 NodeList=cpu11 #CPUs=8 Partition=cpu-opteron
[2022-10-14T20:07:32.262] _job_complete: JobId=50731 WEXITSTATUS 0
[2022-10-14T20:07:32.262] _job_complete: JobId=50731 done
[2022-10-14T20:07:33.062] sched: Allocate JobId=50755 NodeList=cpu11 #CPUs=8 Partition=cpu-opteron
[2022-10-14T20:11:52.061] _job_complete: JobId=50730 WEXITSTATUS 0
[2022-10-14T20:11:52.061] _job_complete: JobId=50730 done
[2022-10-14T20:11:53.453] sched: Allocate JobId=50756 NodeList=cpu01 #CPUs=8 Partition=cpu-opteron
[2022-10-14T20:27:02.722] _job_complete: JobId=50734 WEXITSTATUS 0
[2022-10-14T20:27:02.722] _job_complete: JobId=50734 done
[2022-10-14T20:27:04.064] sched: Allocate JobId=50757 NodeList=cpu01 #CPUs=8 Partition=cpu-opteron
[2022-10-14T20:27:27.421] _job_complete: JobId=50732 WEXITSTATUS 0
[2022-10-14T20:27:27.421] _job_complete: JobId=50732 done
[2022-10-14T20:27:28.617] sched: Allocate JobId=50758 NodeList=cpu01 #CPUs=8 Partition=cpu-opteron
[2022-10-14T20:32:14.377] _job_complete: JobId=50737 WEXITSTATUS 0
[2022-10-14T20:32:14.378] _job_complete: JobId=50737 done
[2022-10-14T20:32:15.692] sched: Allocate JobId=50759 NodeList=cpu01 #CPUs=8 Partition=cpu-opteron
[2022-10-14T20:39:37.566] _job_complete: JobId=50736 WEXITSTATUS 0
[2022-10-14T20:39:37.566] _job_complete: JobId=50736 done
[2022-10-14T20:39:38.430] sched: Allocate JobId=50760 NodeList=cpu11 #CPUs=8 Partition=cpu-opteron
[2022-10-14T20:52:07.466] _job_complete: JobId=50735 WEXITSTATUS 0
[2022-10-14T20:52:07.466] _job_complete: JobId=50735 done
[2022-10-14T20:52:08.312] sched: Allocate JobId=50761 NodeList=cpu11 #CPUs=8 Partition=cpu-opteron
[2022-10-14T21:05:08.489] _job_complete: JobId=50738 WEXITSTATUS 0
[2022-10-14T21:05:08.489] _job_complete: JobId=50738 done
[2022-10-14T21:05:09.268] sched: Allocate JobId=50762 NodeList=cpu11 #CPUs=8 Partition=cpu-opteron
[2022-10-14T21:44:16.825] _job_complete: JobId=50739 WEXITSTATUS 0
[2022-10-14T21:44:16.825] _job_complete: JobId=50739 done
[2022-10-14T21:44:17.993] sched: Allocate JobId=50763 NodeList=cpu01 #CPUs=8 Partition=cpu-opteron
[2022-10-14T21:58:10.377] _job_complete: JobId=50581 WEXITSTATUS 0
[2022-10-14T21:58:10.377] _job_complete: JobId=50581 done
[2022-10-14T21:58:10.971] sched: Allocate JobId=50689 NodeList=gpu02 #CPUs=10 Partition=gpu-titan
[2022-10-14T21:58:12.404] _job_complete: JobId=50689 WEXITSTATUS 0
[2022-10-14T21:58:12.404] _job_complete: JobId=50689 done
[2022-10-14T21:58:13.017] sched: Allocate JobId=50588 NodeList=gpu02 #CPUs=8 Partition=gpu-titan
[2022-10-14T21:58:13.018] sched: Allocate JobId=50592 NodeList=gpu02 #CPUs=8 Partition=gpu-titan
[2022-10-14T22:00:03.020] _job_complete: JobId=50740 WEXITSTATUS 0
[2022-10-14T22:00:03.020] _job_complete: JobId=50740 done
[2022-10-14T22:00:03.798] sched: Allocate JobId=50764 NodeList=cpu01 #CPUs=8 Partition=cpu-opteron
[2022-10-14T22:04:00.893] _job_complete: JobId=50588 WEXITSTATUS 255
[2022-10-14T22:04:00.894] _job_complete: JobId=50588 done
[2022-10-14T22:04:01.852] _job_complete: JobId=50592 WEXITSTATUS 255
[2022-10-14T22:04:01.853] _job_complete: JobId=50592 done
[2022-10-14T22:04:02.440] sched: Allocate JobId=50583 NodeList=gpu02 #CPUs=16 Partition=gpu-titan
[2022-10-14T22:55:16.129] _job_complete: JobId=50741 WEXITSTATUS 0
[2022-10-14T22:55:16.129] _job_complete: JobId=50741 done
[2022-10-14T22:55:17.027] sched: Allocate JobId=50765 NodeList=cpu11 #CPUs=8 Partition=cpu-opteron
[2022-10-14T23:38:57.558] _job_complete: JobId=50753 WEXITSTATUS 0
[2022-10-14T23:38:57.558] _job_complete: JobId=50753 done
[2022-10-14T23:38:59.228] sched: Allocate JobId=50766 NodeList=cpu01 #CPUs=8 Partition=cpu-opteron
[2022-10-14T23:45:49.452] _job_complete: JobId=50754 WEXITSTATUS 0
[2022-10-14T23:45:49.452] _job_complete: JobId=50754 done
[2022-10-14T23:45:50.508] sched: Allocate JobId=50767 NodeList=cpu11 #CPUs=8 Partition=cpu-opteron
[2022-10-15T00:04:34.619] _job_complete: JobId=50756 WEXITSTATUS 0
[2022-10-15T00:04:34.619] _job_complete: JobId=50756 done
[2022-10-15T00:04:34.936] sched: Allocate JobId=50768 NodeList=cpu01 #CPUs=8 Partition=cpu-opteron
[2022-10-15T00:06:38.427] _job_complete: JobId=50755 WEXITSTATUS 0
[2022-10-15T00:06:38.427] _job_complete: JobId=50755 done
[2022-10-15T00:06:38.700] sched: Allocate JobId=50769 NodeList=cpu11 #CPUs=8 Partition=cpu-opteron
[2022-10-15T00:15:05.275] _job_complete: JobId=50758 WEXITSTATUS 0
[2022-10-15T00:15:05.275] _job_complete: JobId=50758 done
[2022-10-15T00:15:07.049] sched: Allocate JobId=50770 NodeList=cpu01 #CPUs=8 Partition=cpu-opteron
[2022-10-15T00:20:53.462] _job_complete: JobId=50760 WEXITSTATUS 0
[2022-10-15T00:20:53.462] _job_complete: JobId=50760 done
[2022-10-15T00:20:54.820] sched: Allocate JobId=50771 NodeList=cpu11 #CPUs=8 Partition=cpu-opteron
[2022-10-15T00:23:40.267] _job_complete: JobId=50759 WEXITSTATUS 0
[2022-10-15T00:23:40.267] _job_complete: JobId=50759 done
[2022-10-15T00:23:41.670] sched: Allocate JobId=50772 NodeList=cpu01 #CPUs=8 Partition=cpu-opteron
[2022-10-15T00:42:39.316] _job_complete: JobId=50761 WEXITSTATUS 0
[2022-10-15T00:42:39.316] _job_complete: JobId=50761 done
[2022-10-15T00:42:40.104] sched: Allocate JobId=50773 NodeList=cpu11 #CPUs=8 Partition=cpu-opteron
[2022-10-15T00:43:07.451] _job_complete: JobId=50757 WEXITSTATUS 0
[2022-10-15T00:43:07.452] _job_complete: JobId=50757 done
[2022-10-15T00:43:09.205] sched: Allocate JobId=50774 NodeList=cpu01 #CPUs=8 Partition=cpu-opteron
[2022-10-15T01:07:36.315] _job_complete: JobId=50762 WEXITSTATUS 0
[2022-10-15T01:07:36.315] _job_complete: JobId=50762 done
[2022-10-15T01:07:37.062] sched: Allocate JobId=50775 NodeList=cpu11 #CPUs=8 Partition=cpu-opteron
[2022-10-15T01:19:15.529] _job_complete: JobId=50763 WEXITSTATUS 0
[2022-10-15T01:19:15.530] _job_complete: JobId=50763 done
[2022-10-15T01:19:17.447] sched: Allocate JobId=50776 NodeList=cpu01 #CPUs=8 Partition=cpu-opteron
[2022-10-15T02:26:58.949] _job_complete: JobId=50764 WEXITSTATUS 0
[2022-10-15T02:26:58.949] _job_complete: JobId=50764 done
[2022-10-15T02:26:59.750] sched: Allocate JobId=50777 NodeList=cpu01 #CPUs=8 Partition=cpu-opteron
[2022-10-15T02:46:10.898] _job_complete: JobId=50765 WEXITSTATUS 0
[2022-10-15T02:46:10.899] _job_complete: JobId=50765 done
[2022-10-15T02:46:11.697] sched: Allocate JobId=50778 NodeList=cpu11 #CPUs=8 Partition=cpu-opteron
[2022-10-15T03:16:36.111] _job_complete: JobId=50766 WEXITSTATUS 0
[2022-10-15T03:16:36.111] _job_complete: JobId=50766 done
[2022-10-15T03:16:37.477] sched: Allocate JobId=50779 NodeList=cpu01 #CPUs=8 Partition=cpu-opteron
[2022-10-15T03:38:35.377] _job_complete: JobId=50767 WEXITSTATUS 0
[2022-10-15T03:38:35.377] _job_complete: JobId=50767 done
[2022-10-15T03:38:36.259] sched: Allocate JobId=50780 NodeList=cpu11 #CPUs=8 Partition=cpu-opteron
[2022-10-15T03:45:20.117] _job_complete: JobId=50769 WEXITSTATUS 0
[2022-10-15T03:45:20.117] _job_complete: JobId=50769 done
[2022-10-15T03:45:20.848] sched: Allocate JobId=50781 NodeList=cpu11 #CPUs=8 Partition=cpu-opteron
[2022-10-15T03:54:21.382] _job_complete: JobId=50768 WEXITSTATUS 0
[2022-10-15T03:54:21.382] _job_complete: JobId=50768 done
[2022-10-15T03:54:22.141] sched: Allocate JobId=50782 NodeList=cpu01 #CPUs=8 Partition=cpu-opteron
[2022-10-15T03:59:12.574] _job_complete: JobId=50771 WEXITSTATUS 0
[2022-10-15T03:59:12.574] _job_complete: JobId=50771 done
[2022-10-15T04:11:35.110] _job_complete: JobId=50772 WEXITSTATUS 0
[2022-10-15T04:11:35.111] _job_complete: JobId=50772 done
[2022-10-15T04:24:13.299] _job_complete: JobId=50774 WEXITSTATUS 0
[2022-10-15T04:24:13.299] _job_complete: JobId=50774 done
[2022-10-15T04:24:14.273] sched: Allocate JobId=50785 NodeList=cpu01 #CPUs=16 Partition=cpu-opteron
[2022-10-15T05:02:28.466] _job_complete: JobId=50775 WEXITSTATUS 0
[2022-10-15T05:02:28.466] _job_complete: JobId=50775 done
[2022-10-15T05:15:11.003] _job_complete: JobId=50776 WEXITSTATUS 0
[2022-10-15T05:15:11.003] _job_complete: JobId=50776 done
[2022-10-15T06:37:45.479] _job_complete: JobId=50778 WEXITSTATUS 0
[2022-10-15T06:37:45.479] _job_complete: JobId=50778 done
[2022-10-15T06:41:17.796] _job_complete: JobId=50773 WEXITSTATUS 0
[2022-10-15T06:41:17.796] _job_complete: JobId=50773 done
[2022-10-15T06:56:05.018] _job_complete: JobId=50779 WEXITSTATUS 0
[2022-10-15T06:56:05.018] _job_complete: JobId=50779 done
[2022-10-15T07:23:26.051] _job_complete: JobId=50780 WEXITSTATUS 0
[2022-10-15T07:23:26.051] _job_complete: JobId=50780 done
[2022-10-15T07:35:15.076] _job_complete: JobId=50781 WEXITSTATUS 0
[2022-10-15T07:35:15.077] _job_complete: JobId=50781 done
[2022-10-15T07:35:57.864] _job_complete: JobId=50782 WEXITSTATUS 0
[2022-10-15T07:35:57.864] _job_complete: JobId=50782 done
[2022-10-15T08:03:45.453] _job_complete: JobId=50777 WEXITSTATUS 0
[2022-10-15T08:03:45.454] _job_complete: JobId=50777 done
[2022-10-15T09:23:08.907] _job_complete: JobId=50770 WEXITSTATUS 0
[2022-10-15T09:23:08.908] _job_complete: JobId=50770 done
[2022-10-15T14:33:34.205] _slurm_rpc_submit_batch_job: JobId=50830 InitPrio=2282 usec=494
[2022-10-15T17:57:24.540] _job_complete: JobId=50611 WEXITSTATUS 0
[2022-10-15T17:57:24.540] _job_complete: JobId=50611 done
[2022-10-15T17:57:26.828] sched: Allocate JobId=50613 NodeList=cpu09 #CPUs=64 Partition=cpu-opteron
[2022-10-15T18:00:36.271] _job_complete: JobId=50610 WEXITSTATUS 0
[2022-10-15T18:00:36.271] _job_complete: JobId=50610 done
[2022-10-15T18:00:37.591] sched: Allocate JobId=50614 NodeList=cpu08 #CPUs=64 Partition=cpu-opteron
[2022-10-16T01:11:32.370] _job_complete: JobId=50506 WEXITSTATUS 0
[2022-10-16T01:11:32.370] _job_complete: JobId=50506 done
[2022-10-16T01:11:32.727] sched: Allocate JobId=50786 NodeList=cpu13 #CPUs=8 Partition=cpu-epyc
[2022-10-16T01:11:32.728] sched: Allocate JobId=50787 NodeList=cpu13 #CPUs=8 Partition=cpu-epyc
[2022-10-16T01:11:32.729] sched: Allocate JobId=50788 NodeList=cpu13 #CPUs=8 Partition=cpu-epyc
[2022-10-16T01:11:32.730] sched: Allocate JobId=50789 NodeList=cpu13 #CPUs=8 Partition=cpu-epyc
[2022-10-16T01:11:32.731] sched: Allocate JobId=50790 NodeList=cpu13 #CPUs=8 Partition=cpu-epyc
[2022-10-16T01:11:32.731] sched: Allocate JobId=50791 NodeList=cpu13 #CPUs=8 Partition=cpu-epyc
[2022-10-16T01:36:22.549] _job_complete: JobId=50507 WEXITSTATUS 0
[2022-10-16T01:36:22.549] _job_complete: JobId=50507 done
[2022-10-16T01:36:22.867] sched: Allocate JobId=50792 NodeList=cpu12 #CPUs=8 Partition=cpu-epyc
[2022-10-16T01:36:22.867] sched: Allocate JobId=50793 NodeList=cpu12 #CPUs=8 Partition=cpu-epyc
[2022-10-16T01:36:22.868] sched: Allocate JobId=50794 NodeList=cpu12 #CPUs=8 Partition=cpu-epyc
[2022-10-16T01:36:22.869] sched: Allocate JobId=50795 NodeList=cpu12 #CPUs=8 Partition=cpu-epyc
[2022-10-16T01:36:22.870] sched: Allocate JobId=50796 NodeList=cpu12 #CPUs=8 Partition=cpu-epyc
[2022-10-16T01:36:22.870] sched: Allocate JobId=50797 NodeList=cpu12 #CPUs=8 Partition=cpu-epyc
[2022-10-16T01:51:52.196] _job_complete: JobId=50787 WEXITSTATUS 0
[2022-10-16T01:51:52.197] _job_complete: JobId=50787 done
[2022-10-16T01:51:52.523] sched: Allocate JobId=50798 NodeList=cpu13 #CPUs=8 Partition=cpu-epyc
[2022-10-16T01:52:36.753] _job_complete: JobId=50791 WEXITSTATUS 0
[2022-10-16T01:52:36.753] _job_complete: JobId=50791 done
[2022-10-16T01:52:37.113] sched: Allocate JobId=50799 NodeList=cpu13 #CPUs=8 Partition=cpu-epyc
[2022-10-16T01:53:54.004] _job_complete: JobId=50790 WEXITSTATUS 0
[2022-10-16T01:53:54.004] _job_complete: JobId=50790 done
[2022-10-16T01:53:54.357] sched: Allocate JobId=50800 NodeList=cpu13 #CPUs=8 Partition=cpu-epyc
[2022-10-16T01:54:27.746] _job_complete: JobId=50788 WEXITSTATUS 0
[2022-10-16T01:54:27.746] _job_complete: JobId=50788 done
[2022-10-16T01:54:28.123] sched: Allocate JobId=50801 NodeList=cpu13 #CPUs=8 Partition=cpu-epyc
[2022-10-16T01:55:22.520] _job_complete: JobId=50786 WEXITSTATUS 0
[2022-10-16T01:55:22.520] _job_complete: JobId=50786 done
[2022-10-16T01:55:22.857] sched: Allocate JobId=50802 NodeList=cpu13 #CPUs=8 Partition=cpu-epyc
[2022-10-16T01:55:24.267] _job_complete: JobId=50789 WEXITSTATUS 0
[2022-10-16T01:55:24.267] _job_complete: JobId=50789 done
[2022-10-16T01:55:24.599] sched: Allocate JobId=50803 NodeList=cpu13 #CPUs=8 Partition=cpu-epyc
[2022-10-16T02:18:16.557] _job_complete: JobId=50794 WEXITSTATUS 0
[2022-10-16T02:18:16.557] _job_complete: JobId=50794 done
[2022-10-16T02:18:16.997] sched: Allocate JobId=50804 NodeList=cpu12 #CPUs=8 Partition=cpu-epyc
[2022-10-16T02:18:34.795] _job_complete: JobId=50792 WEXITSTATUS 0
[2022-10-16T02:18:34.796] _job_complete: JobId=50792 done
[2022-10-16T02:18:35.193] sched: Allocate JobId=50805 NodeList=cpu12 #CPUs=8 Partition=cpu-epyc
[2022-10-16T02:19:29.301] _job_complete: JobId=50793 WEXITSTATUS 0
[2022-10-16T02:19:29.301] _job_complete: JobId=50793 done
[2022-10-16T02:19:29.638] sched: Allocate JobId=50806 NodeList=cpu12 #CPUs=8 Partition=cpu-epyc
[2022-10-16T02:19:44.399] _job_complete: JobId=50796 WEXITSTATUS 0
[2022-10-16T02:19:44.399] _job_complete: JobId=50796 done
[2022-10-16T02:19:44.794] sched: Allocate JobId=50807 NodeList=cpu12 #CPUs=8 Partition=cpu-epyc
[2022-10-16T02:19:50.616] _job_complete: JobId=50797 WEXITSTATUS 0
[2022-10-16T02:19:50.616] _job_complete: JobId=50797 done
[2022-10-16T02:19:51.030] sched: Allocate JobId=50808 NodeList=cpu12 #CPUs=8 Partition=cpu-epyc
[2022-10-16T02:22:31.906] _job_complete: JobId=50795 WEXITSTATUS 0
[2022-10-16T02:22:31.907] _job_complete: JobId=50795 done
[2022-10-16T02:22:32.255] sched: Allocate JobId=50809 NodeList=cpu12 #CPUs=8 Partition=cpu-epyc
[2022-10-16T02:32:44.321] _job_complete: JobId=50798 WEXITSTATUS 0
[2022-10-16T02:32:44.321] _job_complete: JobId=50798 done
[2022-10-16T02:32:44.701] sched: Allocate JobId=50810 NodeList=cpu13 #CPUs=8 Partition=cpu-epyc
[2022-10-16T02:35:09.813] _job_complete: JobId=50799 WEXITSTATUS 0
[2022-10-16T02:35:09.813] _job_complete: JobId=50799 done
[2022-10-16T02:35:10.171] sched: Allocate JobId=50811 NodeList=cpu13 #CPUs=8 Partition=cpu-epyc
[2022-10-16T02:35:16.281] _job_complete: JobId=50800 WEXITSTATUS 0
[2022-10-16T02:35:16.281] _job_complete: JobId=50800 done
[2022-10-16T02:35:16.664] sched: Allocate JobId=50812 NodeList=cpu13 #CPUs=8 Partition=cpu-epyc
[2022-10-16T02:35:54.433] _job_complete: JobId=50801 WEXITSTATUS 0
[2022-10-16T02:35:54.434] _job_complete: JobId=50801 done
[2022-10-16T02:35:54.756] sched: Allocate JobId=50813 NodeList=cpu13 #CPUs=8 Partition=cpu-epyc
[2022-10-16T02:37:01.724] _job_complete: JobId=50802 WEXITSTATUS 0
[2022-10-16T02:37:01.724] _job_complete: JobId=50802 done
[2022-10-16T02:37:02.069] sched: Allocate JobId=50814 NodeList=cpu13 #CPUs=8 Partition=cpu-epyc
[2022-10-16T03:00:57.509] _job_complete: JobId=50807 WEXITSTATUS 0
[2022-10-16T03:00:57.509] _job_complete: JobId=50807 done
[2022-10-16T03:00:57.841] sched: Allocate JobId=50815 NodeList=cpu12 #CPUs=8 Partition=cpu-epyc
[2022-10-16T03:01:15.426] _job_complete: JobId=50808 WEXITSTATUS 0
[2022-10-16T03:01:15.427] _job_complete: JobId=50808 done
[2022-10-16T03:01:16.130] sched: Allocate JobId=50816 NodeList=cpu12 #CPUs=8 Partition=cpu-epyc
[2022-10-16T03:02:02.157] _job_complete: JobId=50805 WEXITSTATUS 0
[2022-10-16T03:02:02.158] _job_complete: JobId=50805 done
[2022-10-16T03:02:02.481] sched: Allocate JobId=50817 NodeList=cpu12 #CPUs=8 Partition=cpu-epyc
[2022-10-16T03:03:51.844] _job_complete: JobId=50809 WEXITSTATUS 0
[2022-10-16T03:03:51.844] _job_complete: JobId=50809 done
[2022-10-16T03:03:52.134] sched: Allocate JobId=50818 NodeList=cpu12 #CPUs=8 Partition=cpu-epyc
[2022-10-16T03:04:12.129] _job_complete: JobId=50804 WEXITSTATUS 0
[2022-10-16T03:04:12.129] _job_complete: JobId=50804 done
[2022-10-16T03:04:12.582] sched: Allocate JobId=50819 NodeList=cpu12 #CPUs=8 Partition=cpu-epyc
[2022-10-16T03:05:58.587] _job_complete: JobId=50803 WEXITSTATUS 0
[2022-10-16T03:05:58.587] _job_complete: JobId=50803 done
[2022-10-16T03:05:58.941] sched: Allocate JobId=50820 NodeList=cpu13 #CPUs=8 Partition=cpu-epyc
[2022-10-16T03:16:15.172] _job_complete: JobId=50812 WEXITSTATUS 0
[2022-10-16T03:16:15.172] _job_complete: JobId=50812 done
[2022-10-16T03:16:15.566] sched: Allocate JobId=50821 NodeList=cpu13 #CPUs=8 Partition=cpu-epyc
[2022-10-16T03:16:51.097] _job_complete: JobId=50813 WEXITSTATUS 0
[2022-10-16T03:16:51.097] _job_complete: JobId=50813 done
[2022-10-16T03:17:39.796] _job_complete: JobId=50811 WEXITSTATUS 0
[2022-10-16T03:17:39.796] _job_complete: JobId=50811 done
[2022-10-16T03:20:58.080] _job_complete: JobId=50810 WEXITSTATUS 0
[2022-10-16T03:20:58.080] _job_complete: JobId=50810 done
[2022-10-16T03:43:30.367] _job_complete: JobId=50806 WEXITSTATUS 0
[2022-10-16T03:43:30.368] _job_complete: JobId=50806 done
[2022-10-16T03:44:37.874] _job_complete: JobId=50819 WEXITSTATUS 0
[2022-10-16T03:44:37.874] _job_complete: JobId=50819 done
[2022-10-16T03:45:53.564] _job_complete: JobId=50815 WEXITSTATUS 0
[2022-10-16T03:45:53.564] _job_complete: JobId=50815 done
[2022-10-16T03:46:08.752] _job_complete: JobId=50814 WEXITSTATUS 0
[2022-10-16T03:46:08.752] _job_complete: JobId=50814 done
[2022-10-16T03:48:24.344] _job_complete: JobId=50816 WEXITSTATUS 0
[2022-10-16T03:48:24.344] _job_complete: JobId=50816 done
[2022-10-16T03:57:20.574] _job_complete: JobId=50821 WEXITSTATUS 0
[2022-10-16T03:57:20.574] _job_complete: JobId=50821 done
[2022-10-16T04:08:46.481] _job_complete: JobId=50817 WEXITSTATUS 0
[2022-10-16T04:08:46.482] _job_complete: JobId=50817 done
[2022-10-16T04:24:55.099] _job_complete: JobId=50818 WEXITSTATUS 0
[2022-10-16T04:24:55.099] _job_complete: JobId=50818 done
[2022-10-16T04:44:42.692] _job_complete: JobId=50607 WEXITSTATUS 0
[2022-10-16T04:44:42.692] _job_complete: JobId=50607 done
[2022-10-16T04:44:44.039] sched: Allocate JobId=50830 NodeList=cpu04 #CPUs=10 Partition=cpu-opteron
[2022-10-16T07:26:19.543] _job_complete: JobId=50612 WEXITSTATUS 0
[2022-10-16T07:26:19.543] _job_complete: JobId=50612 done
[2022-10-16T07:36:08.353] _job_complete: JobId=50830 WEXITSTATUS 0
[2022-10-16T07:36:08.359] _job_complete: JobId=50830 done
[2022-10-16T10:47:02.343] _job_complete: JobId=50820 WEXITSTATUS 1
[2022-10-16T10:47:02.344] _job_complete: JobId=50820 done
[2022-10-16T12:49:35.984] _job_complete: JobId=50583 WEXITSTATUS 0
[2022-10-16T12:49:35.984] _job_complete: JobId=50583 done
[2022-10-16T12:49:37.505] sched: Allocate JobId=50593 NodeList=gpu02 #CPUs=16 Partition=gpu-titan
[2022-10-16T13:30:05.127] _job_complete: JobId=50508 WEXITSTATUS 0
[2022-10-16T13:30:05.127] _job_complete: JobId=50508 done
[2022-10-16T15:27:08.247] Time limit exhausted for JobId=50381
[2022-10-16T20:06:58.278] _job_complete: JobId=50593 WEXITSTATUS 0
[2022-10-16T20:06:58.278] _job_complete: JobId=50593 done
[2022-10-16T20:06:58.804] sched: Allocate JobId=50600 NodeList=gpu02 #CPUs=8 Partition=gpu-titan
[2022-10-16T20:07:02.136] _job_complete: JobId=50600 WEXITSTATUS 1
[2022-10-16T20:07:02.136] _job_complete: JobId=50600 done
[2022-10-16T20:46:29.294] _slurm_rpc_kill_job: REQUEST_KILL_JOB JobId=50687 uid 548300584
[2022-10-16T20:46:47.357] _slurm_rpc_kill_job: REQUEST_KILL_JOB JobId=50701 uid 548300584
[2022-10-16T21:03:44.026] _slurm_rpc_submit_batch_job: JobId=50831 InitPrio=4356 usec=474
[2022-10-16T21:03:45.200] sched: Allocate JobId=50831 NodeList=cpu01 #CPUs=16 Partition=cpu-opteron
[2022-10-16T21:03:55.596] _job_complete: JobId=50831 WEXITSTATUS 0
[2022-10-16T21:03:55.596] _job_complete: JobId=50831 done
[2022-10-16T21:07:26.372] _job_complete: JobId=50608 WEXITSTATUS 0
[2022-10-16T21:07:26.372] _job_complete: JobId=50608 done
[2022-10-16T21:11:35.243] _slurm_rpc_submit_batch_job: JobId=50832 InitPrio=4356 usec=445
[2022-10-16T21:11:36.032] sched: Allocate JobId=50832 NodeList=cpu15 #CPUs=24 Partition=cpu-epyc
[2022-10-16T21:11:36.724] _job_complete: JobId=50832 WEXITSTATUS 0
[2022-10-16T21:11:36.724] _job_complete: JobId=50832 done
[2022-10-16T21:12:38.383] _slurm_rpc_submit_batch_job: JobId=50833 InitPrio=4356 usec=479
[2022-10-16T21:12:39.115] sched: Allocate JobId=50833 NodeList=cpu15 #CPUs=24 Partition=cpu-epyc
[2022-10-16T21:12:39.952] _job_complete: JobId=50833 WEXITSTATUS 0
[2022-10-16T21:12:39.952] _job_complete: JobId=50833 done
[2022-10-16T21:17:52.485] _slurm_rpc_submit_batch_job: JobId=50834 InitPrio=4356 usec=574
[2022-10-16T21:17:52.632] sched: Allocate JobId=50834 NodeList=cpu01 #CPUs=16 Partition=cpu-opteron
[2022-10-16T21:17:54.034] _job_complete: JobId=50834 WEXITSTATUS 0
[2022-10-16T21:17:54.034] _job_complete: JobId=50834 done
[2022-10-16T21:41:47.071] _slurm_rpc_submit_batch_job: JobId=50835 InitPrio=4356 usec=422
[2022-10-16T21:41:47.760] sched: Allocate JobId=50835 NodeList=cpu01 #CPUs=16 Partition=cpu-opteron
[2022-10-16T21:41:54.271] _job_complete: JobId=50835 WEXITSTATUS 31
[2022-10-16T21:41:54.271] _job_complete: JobId=50835 done
[2022-10-16T21:47:06.517] _slurm_rpc_submit_batch_job: JobId=50836 InitPrio=4356 usec=458
[2022-10-16T21:47:07.293] sched: Allocate JobId=50836 NodeList=cpu01 #CPUs=16 Partition=cpu-opteron
[2022-10-16T21:47:15.371] _job_complete: JobId=50836 WEXITSTATUS 0
[2022-10-16T21:47:15.372] _job_complete: JobId=50836 done
[2022-10-16T21:50:37.959] _slurm_rpc_submit_batch_job: JobId=50837 InitPrio=4356 usec=482
[2022-10-16T21:50:38.576] sched: Allocate JobId=50837 NodeList=cpu01 #CPUs=16 Partition=cpu-opteron
[2022-10-16T21:50:39.480] _job_complete: JobId=50837 WEXITSTATUS 0
[2022-10-16T21:50:39.480] _job_complete: JobId=50837 done
[2022-10-16T21:55:33.819] _pick_best_nodes: JobId=50838 never runnable in partition gpu-titan
[2022-10-16T21:55:33.819] _slurm_rpc_submit_batch_job: Requested node configuration is not available
[2022-10-16T21:57:06.672] _slurm_rpc_submit_batch_job: JobId=50839 InitPrio=4356 usec=488
[2022-10-16T22:02:10.498] _slurm_rpc_submit_batch_job: JobId=50840 InitPrio=4356 usec=421
[2022-10-16T22:02:10.789] sched: Allocate JobId=50840 NodeList=cpu01 #CPUs=16 Partition=cpu-opteron
[2022-10-16T22:02:11.885] _job_complete: JobId=50840 WEXITSTATUS 0
[2022-10-16T22:02:11.885] _job_complete: JobId=50840 done
[2022-10-16T22:03:33.377] _slurm_rpc_submit_batch_job: JobId=50841 InitPrio=4356 usec=415
[2022-10-16T22:06:51.318] _get_job_parts: invalid partition specified: gpu-titanxp
[2022-10-16T22:06:51.318] _slurm_rpc_submit_batch_job: Invalid partition name specified
[2022-10-16T22:07:07.778] _get_job_parts: invalid partition specified: gpu-titanxp
[2022-10-16T22:07:07.778] _slurm_rpc_submit_batch_job: Invalid partition name specified
[2022-10-16T22:07:41.519] _slurm_rpc_submit_batch_job: JobId=50842 InitPrio=4356 usec=513
[2022-10-16T22:08:34.637] _slurm_rpc_kill_job: REQUEST_KILL_JOB JobId=50842 uid 548300584
[2022-10-16T22:09:07.898] _pick_best_nodes: JobId=50843 never runnable in partition gpu-titan
[2022-10-16T22:09:07.898] _slurm_rpc_submit_batch_job: Requested node configuration is not available
[2022-10-16T22:51:42.739] _slurm_rpc_submit_batch_job: JobId=50844 InitPrio=4356 usec=493
[2022-10-16T22:51:42.885] sched: Allocate JobId=50844 NodeList=cpu01 #CPUs=16 Partition=cpu-opteron
[2022-10-16T22:51:50.174] _job_complete: JobId=50844 WEXITSTATUS 31
[2022-10-16T22:51:50.175] _job_complete: JobId=50844 done
[2022-10-16T22:55:17.974] _slurm_rpc_submit_batch_job: JobId=50845 InitPrio=4356 usec=532
[2022-10-16T22:55:18.149] sched: Allocate JobId=50845 NodeList=cpu01 #CPUs=16 Partition=cpu-opteron
[2022-10-16T22:55:27.937] _job_complete: JobId=50845 WEXITSTATUS 0
[2022-10-16T22:55:27.937] _job_complete: JobId=50845 done
[2022-10-16T22:56:54.054] _slurm_rpc_submit_batch_job: JobId=50846 InitPrio=4356 usec=475
[2022-10-16T22:58:31.134] _slurm_rpc_submit_batch_job: JobId=50847 InitPrio=4356 usec=442
[2022-10-16T22:59:16.041] _slurm_rpc_kill_job: REQUEST_KILL_JOB JobId=50846 uid 548300584
[2022-10-16T23:45:46.536] _slurm_rpc_submit_batch_job: JobId=50848 InitPrio=4356 usec=599
[2022-10-16T23:45:47.397] sched: Allocate JobId=50848 NodeList=cpu01 #CPUs=16 Partition=cpu-opteron
[2022-10-16T23:45:55.353] _job_complete: JobId=50848 WEXITSTATUS 0
[2022-10-16T23:45:55.353] _job_complete: JobId=50848 done
[2022-10-16T23:48:30.198] _slurm_rpc_submit_batch_job: JobId=50849 InitPrio=4356 usec=587
[2022-10-16T23:50:50.895] _slurm_rpc_submit_batch_job: JobId=50850 InitPrio=4356 usec=465
[2022-10-16T23:50:50.901] sched: Allocate JobId=50850 NodeList=cpu01 #CPUs=16 Partition=cpu-opteron
[2022-10-16T23:50:51.765] _job_complete: JobId=50850 WEXITSTATUS 0
[2022-10-16T23:50:51.765] _job_complete: JobId=50850 done
[2022-10-16T23:55:27.555] _slurm_rpc_submit_batch_job: JobId=50851 InitPrio=4356 usec=539
[2022-10-16T23:55:28.413] sched: Allocate JobId=50851 NodeList=cpu01 #CPUs=16 Partition=cpu-opteron
[2022-10-16T23:55:29.554] _job_complete: JobId=50851 WEXITSTATUS 0
[2022-10-16T23:55:29.554] _job_complete: JobId=50851 done
[2022-10-17T00:01:45.278] _slurm_rpc_submit_batch_job: JobId=50852 InitPrio=4356 usec=557
[2022-10-17T00:06:54.579] _slurm_rpc_submit_batch_job: JobId=50853 InitPrio=4356 usec=585
[2022-10-17T00:06:54.828] sched: Allocate JobId=50853 NodeList=cpu01 #CPUs=16 Partition=cpu-opteron
[2022-10-17T00:07:21.397] _job_complete: JobId=50853 WEXITSTATUS 0
[2022-10-17T00:07:21.398] _job_complete: JobId=50853 done
[2022-10-17T00:09:12.114] _slurm_rpc_submit_batch_job: JobId=50854 InitPrio=4356 usec=437
[2022-10-17T00:13:51.621] _slurm_rpc_submit_batch_job: JobId=50855 InitPrio=4356 usec=424
[2022-10-17T00:13:52.505] sched: Allocate JobId=50855 NodeList=cpu01 #CPUs=16 Partition=cpu-opteron
[2022-10-17T00:13:56.184] _job_complete: JobId=50855 WEXITSTATUS 0
[2022-10-17T00:13:56.185] _job_complete: JobId=50855 done
[2022-10-17T00:15:30.137] _slurm_rpc_submit_batch_job: JobId=50856 InitPrio=4356 usec=432
[2022-10-17T00:46:13.410] _job_complete: JobId=50411 WEXITSTATUS 0
[2022-10-17T00:46:13.416] _job_complete: JobId=50411 done
[2022-10-17T00:46:17.599] sched: Allocate JobId=50822 NodeList=gpu05 #CPUs=8 Partition=gpu-v100s
[2022-10-17T00:46:17.600] sched: Allocate JobId=50823 NodeList=gpu05 #CPUs=8 Partition=gpu-v100s
[2022-10-17T01:12:05.950] _job_complete: JobId=50822 WEXITSTATUS 1
[2022-10-17T01:12:05.951] _job_complete: JobId=50822 done
[2022-10-17T01:12:07.079] sched: Allocate JobId=50824 NodeList=gpu05 #CPUs=8 Partition=gpu-v100s
[2022-10-17T01:18:21.263] _job_complete: JobId=50823 WEXITSTATUS 1
[2022-10-17T01:18:21.264] _job_complete: JobId=50823 done
[2022-10-17T01:18:21.839] sched: Allocate JobId=50825 NodeList=gpu05 #CPUs=8 Partition=gpu-v100s
[2022-10-17T01:43:21.755] _job_complete: JobId=50824 WEXITSTATUS 1
[2022-10-17T01:43:21.756] _job_complete: JobId=50824 done
[2022-10-17T01:43:22.181] sched: Allocate JobId=50826 NodeList=gpu05 #CPUs=8 Partition=gpu-v100s
[2022-10-17T01:49:56.164] _job_complete: JobId=50825 WEXITSTATUS 1
[2022-10-17T01:49:56.165] _job_complete: JobId=50825 done
[2022-10-17T01:49:56.656] sched: Allocate JobId=50827 NodeList=gpu05 #CPUs=8 Partition=gpu-v100s
[2022-10-17T02:14:58.158] _job_complete: JobId=50826 WEXITSTATUS 1
[2022-10-17T02:14:58.159] _job_complete: JobId=50826 done
[2022-10-17T02:14:58.549] sched: Allocate JobId=50828 NodeList=gpu05 #CPUs=8 Partition=gpu-v100s
[2022-10-17T02:21:37.110] _job_complete: JobId=50827 WEXITSTATUS 1
[2022-10-17T02:21:37.111] _job_complete: JobId=50827 done
[2022-10-17T02:21:37.581] sched: Allocate JobId=50829 NodeList=gpu05 #CPUs=8 Partition=gpu-v100s
[2022-10-17T02:46:46.455] _job_complete: JobId=50828 WEXITSTATUS 1
[2022-10-17T02:46:46.456] _job_complete: JobId=50828 done
[2022-10-17T02:46:46.805] sched: Allocate JobId=50412 NodeList=gpu05 #CPUs=8 Partition=gpu-v100s
[2022-10-17T02:53:22.176] _job_complete: JobId=50829 WEXITSTATUS 1
[2022-10-17T02:53:22.177] _job_complete: JobId=50829 done
[2022-10-17T02:53:23.191] sched: Allocate JobId=50548 NodeList=gpu05 #CPUs=8 Partition=gpu-v100s
[2022-10-17T02:53:23.425] _job_complete: JobId=50548 WEXITSTATUS 1
[2022-10-17T02:53:23.426] _job_complete: JobId=50548 done
[2022-10-17T02:53:23.792] sched: Allocate JobId=50599 NodeList=gpu05 #CPUs=8 Partition=gpu-v100s
[2022-10-17T02:53:24.005] _job_complete: JobId=50599 WEXITSTATUS 1
[2022-10-17T02:53:24.006] _job_complete: JobId=50599 done
[2022-10-17T06:23:26.385] _job_complete: JobId=50412 WEXITSTATUS 0
[2022-10-17T06:23:26.391] _job_complete: JobId=50412 done
[2022-10-17T06:23:27.382] sched: Allocate JobId=50575 NodeList=gpu05 #CPUs=32 Partition=gpu-v100s
[2022-10-17T07:17:11.025] _slurm_rpc_submit_batch_job: JobId=50857 InitPrio=1037 usec=571
[2022-10-17T08:18:29.633] _pick_best_nodes: JobId=50858 never runnable in partition gpu-titan
[2022-10-17T08:18:29.634] _slurm_rpc_submit_batch_job: Requested node configuration is not available
[2022-10-17T08:25:44.089] _pick_best_nodes: JobId=50859 never runnable in partition gpu-titan
[2022-10-17T08:25:44.089] _slurm_rpc_submit_batch_job: Requested node configuration is not available
[2022-10-17T08:26:13.941] _slurm_rpc_submit_batch_job: JobId=50860 InitPrio=4356 usec=449
[2022-10-17T08:30:14.941] _slurm_rpc_kill_job: REQUEST_KILL_JOB JobId=50860 uid 548300584
[2022-10-17T08:43:58.775] _slurm_rpc_submit_batch_job: JobId=50861 InitPrio=1659 usec=522
[2022-10-17T08:44:17.710] _slurm_rpc_submit_batch_job: JobId=50862 InitPrio=1659 usec=450
[2022-10-17T09:43:49.974] _slurm_rpc_kill_job: REQUEST_KILL_JOB JobId=50595 uid 548200023
[2022-10-17T09:43:53.021] _slurm_rpc_submit_batch_job: JobId=50863 InitPrio=829 usec=588
[2022-10-17T09:43:53.832] sched: Allocate JobId=50863 NodeList=gpu02 #CPUs=5 Partition=gpu-titan
[2022-10-17T09:44:28.352] _job_complete: JobId=50863 WEXITSTATUS 0
[2022-10-17T09:44:28.352] _job_complete: JobId=50863 done
[2022-10-17T09:44:43.927] _slurm_rpc_kill_job: REQUEST_KILL_JOB JobId=50597 uid 548200023
[2022-10-17T10:01:48.427] _slurm_rpc_submit_batch_job: JobId=50864 InitPrio=829 usec=574
[2022-10-17T10:01:48.974] sched: Allocate JobId=50864 NodeList=gpu02 #CPUs=5 Partition=gpu-titan
[2022-10-17T10:03:42.933] _slurm_rpc_submit_batch_job: JobId=50865 InitPrio=829 usec=437
[2022-10-17T10:03:43.123] sched: Allocate JobId=50865 NodeList=cpu01 #CPUs=32 Partition=cpu-opteron
[2022-10-17T10:03:48.874] _job_complete: JobId=50865 WEXITSTATUS 0
[2022-10-17T10:03:48.874] _job_complete: JobId=50865 done
[2022-10-17T10:04:42.274] _slurm_rpc_submit_batch_job: JobId=50866 InitPrio=829 usec=589
[2022-10-17T10:04:43.204] sched: Allocate JobId=50866 NodeList=gpu02 #CPUs=5 Partition=gpu-titan
[2022-10-17T10:05:12.288] _slurm_rpc_submit_batch_job: JobId=50867 InitPrio=2697 usec=426
[2022-10-17T10:05:13.265] sched: Allocate JobId=50867 NodeList=cpu15 #CPUs=8 Partition=cpu-epyc
[2022-10-17T10:05:22.516] _slurm_rpc_kill_job: REQUEST_KILL_JOB JobId=50866 uid 548200023
[2022-10-17T10:05:25.160] _slurm_rpc_kill_job: REQUEST_KILL_JOB JobId=50864 uid 548200023
[2022-10-17T10:06:16.800] _slurm_rpc_submit_batch_job: JobId=50868 InitPrio=829 usec=536
[2022-10-17T10:06:17.453] sched: Allocate JobId=50868 NodeList=gpu02 #CPUs=5 Partition=gpu-titan
[2022-10-17T10:07:14.768] _slurm_rpc_submit_batch_job: JobId=50869 InitPrio=829 usec=526
[2022-10-17T10:07:15.532] sched: Allocate JobId=50869 NodeList=gpu02 #CPUs=5 Partition=gpu-titan
[2022-10-17T10:17:12.583] _slurm_rpc_submit_batch_job: JobId=50870 InitPrio=829 usec=517
[2022-10-17T10:17:13.545] sched: Allocate JobId=50870 NodeList=cpu12 #CPUs=48 Partition=cpu-epyc
[2022-10-17T10:17:14.634] _job_complete: JobId=50870 WEXITSTATUS 1
[2022-10-17T10:17:14.634] _job_complete: JobId=50870 done
[2022-10-17T10:18:52.514] _slurm_rpc_submit_batch_job: JobId=50871 InitPrio=829 usec=407
[2022-10-17T10:18:52.679] sched: Allocate JobId=50871 NodeList=cpu12 #CPUs=48 Partition=cpu-epyc
[2022-10-17T10:19:09.368] _job_complete: JobId=50871 WEXITSTATUS 0
[2022-10-17T10:19:09.368] _job_complete: JobId=50871 done
[2022-10-17T10:19:49.629] _slurm_rpc_submit_batch_job: JobId=50872 InitPrio=829 usec=410
[2022-10-17T10:19:49.758] sched: Allocate JobId=50872 NodeList=cpu12 #CPUs=48 Partition=cpu-epyc
[2022-10-17T10:20:05.847] _job_complete: JobId=50872 WEXITSTATUS 0
[2022-10-17T10:20:05.847] _job_complete: JobId=50872 done
[2022-10-17T10:22:38.984] _slurm_rpc_submit_batch_job: JobId=50873 InitPrio=829 usec=500
[2022-10-17T10:22:39.077] sched: Allocate JobId=50873 NodeList=cpu12 #CPUs=48 Partition=cpu-epyc
[2022-10-17T10:22:55.419] _job_complete: JobId=50873 WEXITSTATUS 0
[2022-10-17T10:22:55.419] _job_complete: JobId=50873 done
[2022-10-17T10:23:24.858] _slurm_rpc_submit_batch_job: JobId=50874 InitPrio=829 usec=513
[2022-10-17T10:23:25.136] sched: Allocate JobId=50874 NodeList=cpu12 #CPUs=48 Partition=cpu-epyc
[2022-10-17T10:23:42.178] _job_complete: JobId=50874 WEXITSTATUS 0
[2022-10-17T10:23:42.178] _job_complete: JobId=50874 done
[2022-10-17T10:24:14.767] _slurm_rpc_submit_batch_job: JobId=50875 InitPrio=829 usec=460
[2022-10-17T10:24:15.199] sched: Allocate JobId=50875 NodeList=cpu12 #CPUs=48 Partition=cpu-epyc
[2022-10-17T10:24:31.500] _job_complete: JobId=50875 WEXITSTATUS 0
[2022-10-17T10:24:31.501] _job_complete: JobId=50875 done
[2022-10-17T10:26:16.231] _slurm_rpc_submit_batch_job: JobId=50876 InitPrio=829 usec=464
[2022-10-17T10:26:16.502] sched: Allocate JobId=50876 NodeList=cpu12 #CPUs=48 Partition=cpu-epyc
[2022-10-17T10:28:02.103] _slurm_rpc_submit_batch_job: JobId=50877 InitPrio=829 usec=488
[2022-10-17T10:28:02.649] sched: Allocate JobId=50877 NodeList=cpu13 #CPUs=48 Partition=cpu-epyc
[2022-10-17T10:28:46.892] _job_complete: JobId=50876 WEXITSTATUS 0
[2022-10-17T10:28:46.892] _job_complete: JobId=50876 done
[2022-10-17T10:29:11.719] _slurm_rpc_submit_batch_job: JobId=50878 InitPrio=829 usec=483
[2022-10-17T10:29:11.740] sched: Allocate JobId=50878 NodeList=cpu12 #CPUs=48 Partition=cpu-epyc
[2022-10-17T10:30:18.036] _slurm_rpc_submit_batch_job: JobId=50879 InitPrio=829 usec=511
[2022-10-17T10:30:25.791] _job_complete: JobId=50877 WEXITSTATUS 0
[2022-10-17T10:30:25.791] _job_complete: JobId=50877 done
[2022-10-17T10:30:26.242] sched: Allocate JobId=50879 NodeList=cpu13 #CPUs=48 Partition=cpu-epyc
[2022-10-17T10:31:29.279] _job_complete: JobId=50878 WEXITSTATUS 0
[2022-10-17T10:31:29.279] _job_complete: JobId=50878 done
[2022-10-17T10:31:44.375] _slurm_rpc_submit_batch_job: JobId=50880 InitPrio=829 usec=533
[2022-10-17T10:31:46.076] sched: Allocate JobId=50880 NodeList=cpu12 #CPUs=48 Partition=cpu-epyc
[2022-10-17T10:32:50.184] _job_complete: JobId=50879 WEXITSTATUS 0
[2022-10-17T10:32:50.184] _job_complete: JobId=50879 done
[2022-10-17T10:34:03.366] _job_complete: JobId=50880 WEXITSTATUS 0
[2022-10-17T10:34:03.367] _job_complete: JobId=50880 done
[2022-10-17T11:08:18.718] _slurm_rpc_submit_batch_job: JobId=50881 InitPrio=2697 usec=489
[2022-10-17T11:08:18.833] sched: Allocate JobId=50881 NodeList=cpu15 #CPUs=8 Partition=cpu-epyc
[2022-10-17T11:08:22.078] _slurm_rpc_submit_batch_job: JobId=50882 InitPrio=2697 usec=425
[2022-10-17T11:08:22.835] sched: Allocate JobId=50882 NodeList=cpu15 #CPUs=8 Partition=cpu-epyc
[2022-10-17T11:08:25.302] _slurm_rpc_submit_batch_job: JobId=50883 InitPrio=2697 usec=471
[2022-10-17T11:08:25.839] sched: Allocate JobId=50883 NodeList=cpu15 #CPUs=8 Partition=cpu-epyc
[2022-10-17T11:08:28.502] _slurm_rpc_submit_batch_job: JobId=50884 InitPrio=2697 usec=464
[2022-10-17T11:08:28.842] sched: Allocate JobId=50884 NodeList=cpu15 #CPUs=8 Partition=cpu-epyc
[2022-10-17T11:08:40.933] _slurm_rpc_submit_batch_job: JobId=50885 InitPrio=2697 usec=412
[2022-10-17T11:08:41.859] sched: Allocate JobId=50885 NodeList=cpu15 #CPUs=8 Partition=cpu-epyc
[2022-10-17T11:08:44.133] _slurm_rpc_submit_batch_job: JobId=50886 InitPrio=2697 usec=479
[2022-10-17T11:08:46.866] sched: Allocate JobId=50886 NodeList=cpu12 #CPUs=8 Partition=cpu-epyc
[2022-10-17T11:08:47.629] _slurm_rpc_submit_batch_job: JobId=50887 InitPrio=2697 usec=415
[2022-10-17T11:08:49.869] sched: Allocate JobId=50887 NodeList=cpu12 #CPUs=8 Partition=cpu-epyc
[2022-10-17T11:08:50.957] _slurm_rpc_submit_batch_job: JobId=50888 InitPrio=2697 usec=410
[2022-10-17T11:08:52.874] sched: Allocate JobId=50888 NodeList=cpu12 #CPUs=8 Partition=cpu-epyc
[2022-10-17T11:09:03.868] _slurm_rpc_submit_batch_job: JobId=50889 InitPrio=2697 usec=442
[2022-10-17T11:09:03.888] sched: Allocate JobId=50889 NodeList=cpu12 #CPUs=8 Partition=cpu-epyc
[2022-10-17T11:09:07.653] _slurm_rpc_submit_batch_job: JobId=50890 InitPrio=2697 usec=448
[2022-10-17T11:09:07.895] sched: Allocate JobId=50890 NodeList=cpu12 #CPUs=8 Partition=cpu-epyc
[2022-10-17T11:09:10.893] _slurm_rpc_submit_batch_job: JobId=50891 InitPrio=2697 usec=446
[2022-10-17T11:09:10.899] sched: Allocate JobId=50891 NodeList=cpu12 #CPUs=8 Partition=cpu-epyc
[2022-10-17T11:09:14.854] _slurm_rpc_submit_batch_job: JobId=50892 InitPrio=2697 usec=448
[2022-10-17T11:09:14.903] sched: Allocate JobId=50892 NodeList=cpu13 #CPUs=8 Partition=cpu-epyc
[2022-10-17T11:22:43.809] _job_complete: JobId=50888 WEXITSTATUS 0
[2022-10-17T11:22:43.809] _job_complete: JobId=50888 done
[2022-10-17T11:22:47.291] _job_complete: JobId=50882 WEXITSTATUS 0
[2022-10-17T11:22:47.291] _job_complete: JobId=50882 done
[2022-10-17T11:22:48.717] _job_complete: JobId=50881 WEXITSTATUS 0
[2022-10-17T11:22:48.718] _job_complete: JobId=50881 done
[2022-10-17T11:22:51.122] _job_complete: JobId=50887 WEXITSTATUS 0
[2022-10-17T11:22:51.122] _job_complete: JobId=50887 done
[2022-10-17T11:22:54.242] _job_complete: JobId=50886 WEXITSTATUS 0
[2022-10-17T11:22:54.242] _job_complete: JobId=50886 done
[2022-10-17T11:23:06.979] _job_complete: JobId=50883 WEXITSTATUS 0
[2022-10-17T11:23:06.979] _job_complete: JobId=50883 done
[2022-10-17T11:23:09.844] _job_complete: JobId=50884 WEXITSTATUS 0
[2022-10-17T11:23:09.844] _job_complete: JobId=50884 done
[2022-10-17T11:23:19.406] _job_complete: JobId=50885 WEXITSTATUS 0
[2022-10-17T11:23:19.406] _job_complete: JobId=50885 done
[2022-10-17T11:23:22.925] _job_complete: JobId=50892 WEXITSTATUS 0
[2022-10-17T11:23:22.925] _job_complete: JobId=50892 done
[2022-10-17T11:23:26.095] _job_complete: JobId=50890 WEXITSTATUS 0
[2022-10-17T11:23:26.096] _job_complete: JobId=50890 done
[2022-10-17T11:23:32.768] _job_complete: JobId=50889 WEXITSTATUS 0
[2022-10-17T11:23:32.768] _job_complete: JobId=50889 done
[2022-10-17T11:23:49.559] _job_complete: JobId=50891 WEXITSTATUS 0
[2022-10-17T11:23:49.559] _job_complete: JobId=50891 done
[2022-10-17T11:23:57.221] _slurm_rpc_submit_batch_job: JobId=50893 InitPrio=829 usec=474
[2022-10-17T11:23:57.408] sched: Allocate JobId=50893 NodeList=cpu01 #CPUs=32 Partition=cpu-opteron
[2022-10-17T11:23:59.689] _job_complete: JobId=50893 WEXITSTATUS 0
[2022-10-17T11:23:59.689] _job_complete: JobId=50893 done
[2022-10-17T11:24:51.759] _slurm_rpc_submit_batch_job: JobId=50894 InitPrio=829 usec=631
[2022-10-17T11:24:52.462] sched: Allocate JobId=50894 NodeList=gpu02 #CPUs=6 Partition=gpu-titan
[2022-10-17T11:51:34.076] _slurm_rpc_submit_batch_job: JobId=50895 InitPrio=2697 usec=503
[2022-10-17T11:51:34.473] sched: Allocate JobId=50895 NodeList=cpu15 #CPUs=8 Partition=cpu-epyc
[2022-10-17T11:51:38.994] _slurm_rpc_submit_batch_job: JobId=50896 InitPrio=2697 usec=381
[2022-10-17T11:51:39.462] sched: Allocate JobId=50896 NodeList=cpu15 #CPUs=8 Partition=cpu-epyc
[2022-10-17T11:51:42.170] _slurm_rpc_submit_batch_job: JobId=50897 InitPrio=2697 usec=475
[2022-10-17T11:51:42.466] sched: Allocate JobId=50897 NodeList=cpu15 #CPUs=8 Partition=cpu-epyc
[2022-10-17T11:51:45.498] _slurm_rpc_submit_batch_job: JobId=50898 InitPrio=2697 usec=470
[2022-10-17T11:51:46.471] sched: Allocate JobId=50898 NodeList=cpu15 #CPUs=8 Partition=cpu-epyc
[2022-10-17T11:51:48.617] _slurm_rpc_submit_batch_job: JobId=50899 InitPrio=2697 usec=476
[2022-10-17T11:51:49.475] sched: Allocate JobId=50899 NodeList=cpu15 #CPUs=8 Partition=cpu-epyc
[2022-10-17T11:51:51.865] _slurm_rpc_submit_batch_job: JobId=50900 InitPrio=2697 usec=498
[2022-10-17T11:51:52.480] sched: Allocate JobId=50900 NodeList=cpu12 #CPUs=8 Partition=cpu-epyc
[2022-10-17T11:51:55.826] _slurm_rpc_submit_batch_job: JobId=50901 InitPrio=2697 usec=441
[2022-10-17T11:51:56.486] sched: Allocate JobId=50901 NodeList=cpu12 #CPUs=8 Partition=cpu-epyc
[2022-10-17T11:52:00.353] _slurm_rpc_submit_batch_job: JobId=50902 InitPrio=2697 usec=464
[2022-10-17T11:52:00.491] sched: Allocate JobId=50902 NodeList=cpu12 #CPUs=8 Partition=cpu-epyc
[2022-10-17T11:52:04.019] _slurm_rpc_submit_batch_job: JobId=50903 InitPrio=2697 usec=474
[2022-10-17T11:52:04.496] sched: Allocate JobId=50903 NodeList=cpu12 #CPUs=8 Partition=cpu-epyc
[2022-10-17T12:00:34.563] _slurm_rpc_submit_batch_job: JobId=50904 InitPrio=6016 usec=398
[2022-10-17T12:00:35.299] sched: Allocate JobId=50904 NodeList=cpu12 #CPUs=1 Partition=cpu-epyc
[2022-10-17T12:07:11.451] _job_complete: JobId=50896 WEXITSTATUS 0
[2022-10-17T12:07:11.451] _job_complete: JobId=50896 done
[2022-10-17T12:07:15.960] _job_complete: JobId=50902 WEXITSTATUS 0
[2022-10-17T12:07:15.960] _job_complete: JobId=50902 done
[2022-10-17T12:07:26.281] _job_complete: JobId=50898 WEXITSTATUS 0
[2022-10-17T12:07:26.281] _job_complete: JobId=50898 done
[2022-10-17T12:07:28.302] _job_complete: JobId=50903 WEXITSTATUS 0
[2022-10-17T12:07:28.302] _job_complete: JobId=50903 done
[2022-10-17T12:07:29.727] _job_complete: JobId=50901 WEXITSTATUS 0
[2022-10-17T12:07:29.727] _job_complete: JobId=50901 done
[2022-10-17T12:07:31.353] _job_complete: JobId=50900 WEXITSTATUS 0
[2022-10-17T12:07:31.353] _job_complete: JobId=50900 done
[2022-10-17T12:07:51.117] _job_complete: JobId=50895 WEXITSTATUS 0
[2022-10-17T12:07:51.117] _job_complete: JobId=50895 done
[2022-10-17T12:07:52.946] _job_complete: JobId=50897 WEXITSTATUS 0
[2022-10-17T12:07:52.946] _job_complete: JobId=50897 done
[2022-10-17T12:08:22.736] _job_complete: JobId=50899 WEXITSTATUS 0
[2022-10-17T12:08:22.736] _job_complete: JobId=50899 done
[2022-10-17T12:15:15.229] _job_complete: JobId=50562 WEXITSTATUS 0
[2022-10-17T12:15:15.235] _job_complete: JobId=50562 done
[2022-10-17T12:15:23.660] sched: Allocate JobId=50839 NodeList=gpu04 #CPUs=16 Partition=gpu-k40c
[2022-10-17T12:15:42.829] _job_complete: JobId=50839 WEXITSTATUS 0
[2022-10-17T12:15:42.829] _job_complete: JobId=50839 done
[2022-10-17T12:15:43.351] sched: Allocate JobId=50841 NodeList=gpu04 #CPUs=16 Partition=gpu-k40c
[2022-10-17T12:15:55.959] _job_complete: JobId=50841 WEXITSTATUS 0
[2022-10-17T12:15:55.959] _job_complete: JobId=50841 done
[2022-10-17T12:15:56.361] sched: Allocate JobId=50847 NodeList=gpu04 #CPUs=16 Partition=gpu-k40c
[2022-10-17T12:16:09.264] _job_complete: JobId=50847 WEXITSTATUS 0
[2022-10-17T12:16:09.264] _job_complete: JobId=50847 done
[2022-10-17T12:16:09.711] sched: Allocate JobId=50852 NodeList=gpu04 #CPUs=2 Partition=gpu-k40c
[2022-10-17T12:16:09.712] sched: Allocate JobId=50854 NodeList=gpu04 #CPUs=2 Partition=gpu-k40c
[2022-10-17T12:17:28.543] _job_complete: JobId=50854 WEXITSTATUS 0
[2022-10-17T12:17:28.543] _job_complete: JobId=50854 done
[2022-10-17T12:17:28.996] sched: Allocate JobId=50856 NodeList=gpu04 #CPUs=2 Partition=gpu-k40c
[2022-10-17T12:17:38.423] _job_complete: JobId=50856 WEXITSTATUS 0
[2022-10-17T12:17:38.423] _job_complete: JobId=50856 done
[2022-10-17T12:17:41.829] _job_complete: JobId=50852 WEXITSTATUS 0
[2022-10-17T12:17:41.829] _job_complete: JobId=50852 done
[2022-10-17T12:51:28.760] sched: _slurm_rpc_allocate_resources JobId=50905 NodeList=(null) usec=1298
[2022-10-17T12:51:28.929] sched: Allocate JobId=50905 NodeList=cpu01 #CPUs=1 Partition=cpu-opteron
[2022-10-17T13:03:16.571] _slurm_rpc_submit_batch_job: JobId=50906 InitPrio=414 usec=480
[2022-10-17T13:03:17.100] sched: Allocate JobId=50906 NodeList=cpu15 #CPUs=24 Partition=cpu-epyc
[2022-10-17T13:03:33.702] _job_complete: JobId=50906 WEXITSTATUS 0
[2022-10-17T13:03:33.702] _job_complete: JobId=50906 done
[2022-10-17T13:36:53.432] _slurm_rpc_submit_batch_job: JobId=50907 InitPrio=414 usec=503
[2022-10-17T13:36:53.788] sched: Allocate JobId=50907 NodeList=cpu13 #CPUs=48 Partition=cpu-epyc
[2022-10-17T13:37:11.083] _job_complete: JobId=50907 WEXITSTATUS 0
[2022-10-17T13:37:11.083] _job_complete: JobId=50907 done
[2022-10-17T13:40:50.985] _slurm_rpc_submit_batch_job: JobId=50908 InitPrio=414 usec=502
[2022-10-17T13:40:51.109] sched: Allocate JobId=50908 NodeList=cpu13 #CPUs=48 Partition=cpu-epyc
[2022-10-17T14:06:27.261] _slurm_rpc_submit_batch_job: JobId=50909 InitPrio=15186 usec=440
[2022-10-17T14:06:27.532] _slurm_rpc_submit_batch_job: JobId=50910 InitPrio=829 usec=422
[2022-10-17T14:06:27.989] sched: Allocate JobId=50909 NodeList=cpu01 #CPUs=8 Partition=cpu-opteron
[2022-10-17T14:06:28.008] sched: Allocate JobId=50910 NodeList=cpu01 #CPUs=4 Partition=cpu-opteron
[2022-10-17T14:06:31.824] _job_complete: JobId=50910 WEXITSTATUS 0
[2022-10-17T14:06:31.824] _job_complete: JobId=50910 done
[2022-10-17T14:06:43.129] _slurm_rpc_kill_job: REQUEST_KILL_JOB JobId=50909 uid 548300543
[2022-10-17T14:07:27.714] _slurm_rpc_submit_batch_job: JobId=50911 InitPrio=15186 usec=385
[2022-10-17T14:07:28.049] sched: Allocate JobId=50911 NodeList=cpu01 #CPUs=8 Partition=cpu-opteron
[2022-10-17T14:07:38.194] _slurm_rpc_kill_job: REQUEST_KILL_JOB JobId=50911 uid 548300543
[2022-10-17T14:07:53.022] _slurm_rpc_submit_batch_job: JobId=50912 InitPrio=829 usec=436
[2022-10-17T14:07:53.081] sched: Allocate JobId=50912 NodeList=cpu01 #CPUs=4 Partition=cpu-opteron
[2022-10-17T14:08:35.780] _slurm_rpc_submit_batch_job: JobId=50913 InitPrio=15186 usec=374
[2022-10-17T14:08:36.140] sched: Allocate JobId=50913 NodeList=cpu01 #CPUs=8 Partition=cpu-opteron
[2022-10-17T14:08:38.056] _job_complete: JobId=50912 WEXITSTATUS 0
[2022-10-17T14:08:38.056] _job_complete: JobId=50912 done
[2022-10-17T14:09:39.841] _slurm_rpc_submit_batch_job: JobId=50914 InitPrio=829 usec=564
[2022-10-17T14:09:53.404] _slurm_rpc_kill_job: REQUEST_KILL_JOB JobId=50913 uid 548300543
[2022-10-17T14:13:08.372] _slurm_rpc_submit_batch_job: JobId=50915 InitPrio=15186 usec=388
[2022-10-17T14:13:20.884] _slurm_rpc_kill_job: REQUEST_KILL_JOB JobId=50915 uid 548300543
[2022-10-17T14:14:11.829] _slurm_rpc_submit_batch_job: JobId=50916 InitPrio=15186 usec=366
[2022-10-17T14:14:14.616] _slurm_rpc_kill_job: REQUEST_KILL_JOB JobId=50916 uid 548300543
[2022-10-17T14:25:02.338] _slurm_rpc_kill_job: REQUEST_KILL_JOB JobId=50869 uid 548200023
[2022-10-17T14:25:19.286] _slurm_rpc_submit_batch_job: JobId=50917 InitPrio=829 usec=475
[2022-10-17T14:25:19.789] sched: Allocate JobId=50917 NodeList=gpu02 #CPUs=4 Partition=gpu-titan
[2022-10-17T14:25:55.557] _slurm_rpc_kill_job: REQUEST_KILL_JOB JobId=50917 uid 548200023
[2022-10-17T14:26:21.329] _slurm_rpc_submit_batch_job: JobId=50918 InitPrio=829 usec=475
[2022-10-17T14:26:21.973] sched: Allocate JobId=50918 NodeList=gpu02 #CPUs=5 Partition=gpu-titan
[2022-10-17T14:27:57.973] _slurm_rpc_kill_job: REQUEST_KILL_JOB JobId=50868 uid 548200023
[2022-10-17T14:28:09.633] _slurm_rpc_submit_batch_job: JobId=50919 InitPrio=829 usec=489
[2022-10-17T14:29:13.664] _slurm_rpc_kill_job: REQUEST_KILL_JOB JobId=50919 uid 548200023
[2022-10-17T14:29:17.143] _slurm_rpc_kill_job: REQUEST_KILL_JOB JobId=50918 uid 548200023
[2022-10-17T14:29:25.996] _slurm_rpc_submit_batch_job: JobId=50920 InitPrio=829 usec=516
[2022-10-17T14:29:26.225] sched: Allocate JobId=50920 NodeList=gpu02 #CPUs=6 Partition=gpu-titan
[2022-10-17T14:31:35.569] _slurm_rpc_kill_job: REQUEST_KILL_JOB JobId=50920 uid 548200023
[2022-10-17T14:31:54.835] _slurm_rpc_submit_batch_job: JobId=50921 InitPrio=829 usec=550
[2022-10-17T14:31:55.562] sched: Allocate JobId=50921 NodeList=gpu02 #CPUs=3 Partition=gpu-titan
[2022-10-17T14:32:36.120] _slurm_rpc_submit_batch_job: JobId=50922 InitPrio=829 usec=543
[2022-10-17T14:32:36.618] sched: Allocate JobId=50922 NodeList=gpu02 #CPUs=6 Partition=gpu-titan
[2022-10-17T14:41:04.723] _slurm_rpc_submit_batch_job: JobId=50923 InitPrio=15186 usec=397
[2022-10-17T14:41:14.791] _slurm_rpc_kill_job: REQUEST_KILL_JOB JobId=50923 uid 548300543
[2022-10-17T14:41:28.965] _slurm_rpc_submit_batch_job: JobId=50924 InitPrio=15186 usec=485
[2022-10-17T14:41:29.541] sched: Allocate JobId=50924 NodeList=cpu01 #CPUs=8 Partition=cpu-opteron
[2022-10-17T14:42:33.561] _slurm_rpc_kill_job: REQUEST_KILL_JOB JobId=50924 uid 548300543
[2022-10-17T14:42:41.643] _slurm_rpc_submit_batch_job: JobId=50925 InitPrio=15186 usec=485
[2022-10-17T14:43:11.375] _slurm_rpc_kill_job: REQUEST_KILL_JOB JobId=50925 uid 548300543
[2022-10-17T15:58:16.940] _slurm_rpc_submit_batch_job: JobId=50926 InitPrio=5186 usec=557
[2022-10-17T15:58:17.604] sched: Allocate JobId=50926 NodeList=cpu01 #CPUs=1 Partition=cpu-opteron
[2022-10-17T15:59:35.082] _slurm_rpc_kill_job: REQUEST_KILL_JOB JobId=50926 uid 548300543
[2022-10-17T16:07:23.806] _slurm_rpc_submit_batch_job: JobId=50927 InitPrio=5186 usec=432
[2022-10-17T16:07:24.585] sched: Allocate JobId=50927 NodeList=cpu01 #CPUs=1 Partition=cpu-opteron
[2022-10-17T16:15:32.849] _slurm_rpc_submit_batch_job: JobId=50928 InitPrio=5186 usec=415
[2022-10-17T16:15:33.114] sched/backfill: _start_job: Started JobId=50928 in cpu-opteron on cpu01
[2022-10-17T16:15:37.603] _slurm_rpc_kill_job: REQUEST_KILL_JOB JobId=50927 uid 548300543
[2022-10-17T16:16:06.437] _slurm_rpc_kill_job: REQUEST_KILL_JOB JobId=50928 uid 548300543
[2022-10-17T16:17:17.119] _slurm_rpc_submit_batch_job: JobId=50929 InitPrio=5186 usec=387
[2022-10-17T16:17:17.622] sched: Allocate JobId=50929 NodeList=cpu01 #CPUs=1 Partition=cpu-opteron
[2022-10-17T16:17:36.079] _slurm_rpc_kill_job: REQUEST_KILL_JOB JobId=50929 uid 548300543
[2022-10-17T16:17:39.852] _slurm_rpc_submit_batch_job: JobId=50930 InitPrio=5186 usec=410
[2022-10-17T16:17:40.654] sched: Allocate JobId=50930 NodeList=cpu01 #CPUs=1 Partition=cpu-opteron
[2022-10-17T16:19:03.710] _slurm_rpc_kill_job: REQUEST_KILL_JOB JobId=50930 uid 548300543
[2022-10-17T16:25:42.667] _slurm_rpc_submit_batch_job: JobId=50931 InitPrio=15186 usec=371
[2022-10-17T16:25:52.197] _slurm_rpc_kill_job: REQUEST_KILL_JOB JobId=50931 uid 548300543
[2022-10-17T16:26:08.729] _job_complete: JobId=50921 WEXITSTATUS 0
[2022-10-17T16:26:08.729] _job_complete: JobId=50921 done
[2022-10-17T16:26:11.499] _slurm_rpc_submit_batch_job: JobId=50932 InitPrio=15186 usec=548
[2022-10-17T16:26:11.507] sched: Allocate JobId=50932 NodeList=gpu02 #CPUs=2 Partition=gpu-titan
[2022-10-17T16:26:19.723] _slurm_rpc_kill_job: REQUEST_KILL_JOB JobId=50932 uid 548300543
[2022-10-17T16:27:02.788] _slurm_rpc_submit_batch_job: JobId=50933 InitPrio=15186 usec=415
[2022-10-17T16:27:03.613] sched: Allocate JobId=50933 NodeList=gpu02 #CPUs=2 Partition=gpu-titan
[2022-10-17T16:27:23.618] _slurm_rpc_kill_job: REQUEST_KILL_JOB JobId=50933 uid 548300543
[2022-10-17T16:27:32.755] _slurm_rpc_submit_batch_job: JobId=50934 InitPrio=15186 usec=403
[2022-10-17T16:27:33.121] sched/backfill: _start_job: Started JobId=50934 in gpu-titan on gpu02
[2022-10-17T16:28:34.545] _slurm_rpc_kill_job: REQUEST_KILL_JOB JobId=50934 uid 548300543
[2022-10-17T17:55:01.610] _job_complete: JobId=50867 WEXITSTATUS 1
[2022-10-17T17:55:01.611] _job_complete: JobId=50867 done
[2022-10-17T20:45:42.521] _job_complete: JobId=50908 WEXITSTATUS 0
[2022-10-17T20:45:42.521] _job_complete: JobId=50908 done
[2022-10-17T21:08:36.283] _slurm_rpc_submit_batch_job: JobId=50935 InitPrio=414 usec=487
[2022-10-17T21:08:37.282] sched: Allocate JobId=50935 NodeList=cpu15 #CPUs=1 Partition=cpu-epyc
[2022-10-17T21:08:37.937] _job_complete: JobId=50935 WEXITSTATUS 1
[2022-10-17T21:08:37.937] _job_complete: JobId=50935 done
[2022-10-17T21:09:19.912] _slurm_rpc_submit_batch_job: JobId=50936 InitPrio=414 usec=443
[2022-10-17T21:09:20.319] sched: Allocate JobId=50936 NodeList=cpu15 #CPUs=1 Partition=cpu-epyc
[2022-10-17T21:14:36.381] _slurm_rpc_kill_job: REQUEST_KILL_JOB JobId=50936 uid 548200021
[2022-10-17T21:14:39.151] _slurm_rpc_submit_batch_job: JobId=50937 InitPrio=414 usec=440
[2022-10-17T21:14:39.844] sched: Allocate JobId=50937 NodeList=cpu15 #CPUs=1 Partition=cpu-epyc
[2022-10-17T21:14:40.848] _job_complete: JobId=50937 WEXITSTATUS 1
[2022-10-17T21:14:40.848] _job_complete: JobId=50937 done
[2022-10-17T21:15:30.190] _slurm_rpc_submit_batch_job: JobId=50938 InitPrio=414 usec=558
[2022-10-17T21:15:30.911] sched: Allocate JobId=50938 NodeList=cpu15 #CPUs=1 Partition=cpu-epyc
[2022-10-17T21:22:47.904] _job_complete: JobId=50938 WEXITSTATUS 0
[2022-10-17T21:22:47.905] _job_complete: JobId=50938 done
[2022-10-17T21:59:48.553] _slurm_rpc_submit_batch_job: JobId=50939 InitPrio=414 usec=499
[2022-10-17T21:59:48.620] sched: Allocate JobId=50939 NodeList=cpu13 #CPUs=1 Partition=cpu-epyc
[2022-10-17T21:59:50.108] _job_complete: JobId=50939 WEXITSTATUS 0
[2022-10-17T21:59:50.108] _job_complete: JobId=50939 done
[2022-10-17T22:04:10.673] _slurm_rpc_submit_batch_job: JobId=50940 InitPrio=414 usec=457
[2022-10-17T22:04:11.133] sched: Allocate JobId=50940 NodeList=cpu13 #CPUs=1 Partition=cpu-epyc
[2022-10-17T22:04:12.547] _job_complete: JobId=50940 WEXITSTATUS 0
[2022-10-17T22:04:12.547] _job_complete: JobId=50940 done
[2022-10-17T22:04:37.439] _slurm_rpc_submit_batch_job: JobId=50941 InitPrio=414 usec=456
[2022-10-17T22:04:38.171] sched: Allocate JobId=50941 NodeList=cpu13 #CPUs=48 Partition=cpu-epyc
[2022-10-17T22:10:50.768] _job_complete: JobId=50941 WEXITSTATUS 0
[2022-10-17T22:10:50.768] _job_complete: JobId=50941 done
[2022-10-17T22:13:59.094] _slurm_rpc_submit_batch_job: JobId=50942 InitPrio=414 usec=404
[2022-10-17T22:13:59.653] sched: Allocate JobId=50942 NodeList=cpu15 #CPUs=1 Partition=cpu-epyc
[2022-10-17T22:14:01.123] _job_complete: JobId=50942 WEXITSTATUS 0
[2022-10-17T22:14:01.123] _job_complete: JobId=50942 done
[2022-10-17T22:14:29.716] _slurm_rpc_submit_batch_job: JobId=50943 InitPrio=414 usec=537
[2022-10-17T22:14:30.691] sched: Allocate JobId=50943 NodeList=cpu13 #CPUs=48 Partition=cpu-epyc
[2022-10-17T22:58:01.197] _job_complete: JobId=50943 WEXITSTATUS 0
[2022-10-17T22:58:01.197] _job_complete: JobId=50943 done
[2022-10-18T00:03:26.624] _slurm_rpc_submit_batch_job: JobId=50944 InitPrio=414 usec=511
[2022-10-18T00:03:27.593] sched: Allocate JobId=50944 NodeList=cpu15 #CPUs=1 Partition=cpu-epyc
[2022-10-18T00:13:00.561] _job_complete: JobId=50944 WEXITSTATUS 0
[2022-10-18T00:13:00.561] _job_complete: JobId=50944 done
[2022-10-18T00:29:25.586] _slurm_rpc_submit_batch_job: JobId=50945 InitPrio=414 usec=600
[2022-10-18T00:29:26.351] sched: Allocate JobId=50945 NodeList=cpu13 #CPUs=1 Partition=cpu-epyc
[2022-10-18T00:29:28.037] _job_complete: JobId=50945 WEXITSTATUS 0
[2022-10-18T00:29:28.037] _job_complete: JobId=50945 done
[2022-10-18T00:29:47.284] _slurm_rpc_submit_batch_job: JobId=50946 InitPrio=414 usec=463
[2022-10-18T00:29:47.374] sched: Allocate JobId=50946 NodeList=cpu13 #CPUs=48 Partition=cpu-epyc
[2022-10-18T00:39:57.358] _job_complete: JobId=50946 WEXITSTATUS 0
[2022-10-18T00:39:57.359] _job_complete: JobId=50946 done
[2022-10-18T00:43:42.297] _slurm_rpc_submit_batch_job: JobId=50947 InitPrio=414 usec=587
[2022-10-18T00:43:42.829] sched: Allocate JobId=50947 NodeList=cpu15 #CPUs=1 Partition=cpu-epyc
[2022-10-18T00:43:44.285] _job_complete: JobId=50947 WEXITSTATUS 0
[2022-10-18T00:43:44.286] _job_complete: JobId=50947 done
[2022-10-18T00:44:46.163] _slurm_rpc_submit_batch_job: JobId=50948 InitPrio=414 usec=448
[2022-10-18T00:44:46.909] sched: Allocate JobId=50948 NodeList=cpu13 #CPUs=48 Partition=cpu-epyc
[2022-10-18T01:02:53.958] _job_complete: JobId=50905 WEXITSTATUS 0
[2022-10-18T01:02:53.959] _job_complete: JobId=50905 done
[2022-10-18T01:04:32.089] _job_complete: JobId=50948 WEXITSTATUS 0
[2022-10-18T01:04:32.089] _job_complete: JobId=50948 done
[2022-10-18T01:06:08.701] _slurm_rpc_submit_batch_job: JobId=50949 InitPrio=414 usec=499
[2022-10-18T01:06:09.262] sched: Allocate JobId=50949 NodeList=cpu15 #CPUs=1 Partition=cpu-epyc
[2022-10-18T01:06:10.699] _job_complete: JobId=50949 WEXITSTATUS 0
[2022-10-18T01:06:10.699] _job_complete: JobId=50949 done
[2022-10-18T01:06:40.459] _slurm_rpc_submit_batch_job: JobId=50950 InitPrio=414 usec=476
[2022-10-18T01:06:41.340] sched: Allocate JobId=50950 NodeList=cpu13 #CPUs=48 Partition=cpu-epyc
[2022-10-18T01:07:54.372] cleanup_completing: JobId=50905 completion process took 301 seconds
[2022-10-18T02:03:37.260] _job_complete: JobId=50950 WEXITSTATUS 0
[2022-10-18T02:03:37.260] _job_complete: JobId=50950 done
[2022-10-18T07:16:07.462] _job_complete: JobId=50544 WEXITSTATUS 0
[2022-10-18T07:16:07.468] _job_complete: JobId=50544 done
[2022-10-18T07:16:11.480] sched: Allocate JobId=50849 NodeList=gpu01 #CPUs=16 Partition=gpu-k10
[2022-10-18T07:16:50.881] _job_complete: JobId=50849 WEXITSTATUS 0
[2022-10-18T07:16:50.881] _job_complete: JobId=50849 done
[2022-10-18T09:01:44.375] _slurm_rpc_submit_batch_job: JobId=50951 InitPrio=1037 usec=640
[2022-10-18T09:04:24.811] _slurm_rpc_submit_batch_job: JobId=50952 InitPrio=1452 usec=453
[2022-10-18T09:04:25.755] sched: Allocate JobId=50952 NodeList=gpu04 #CPUs=16 Partition=gpu-k40c
[2022-10-18T09:31:21.771] _job_complete: JobId=50894 WEXITSTATUS 0
[2022-10-18T09:31:21.771] _job_complete: JobId=50894 done
[2022-10-18T09:31:22.946] sched: Allocate JobId=50951 NodeList=gpu02 #CPUs=6 Partition=gpu-titan
[2022-10-18T09:57:09.785] _slurm_rpc_kill_job: REQUEST_KILL_JOB JobId=50323 uid 548200003
[2022-10-18T09:57:09.791] _slurm_rpc_kill_job: REQUEST_KILL_JOB JobId=50324 uid 548200003
[2022-10-18T09:57:33.460] _slurm_rpc_kill_job: REQUEST_KILL_JOB JobId=50951 uid 548200023
[2022-10-18T09:57:58.626] _slurm_rpc_submit_batch_job: JobId=50953 InitPrio=1037 usec=521
[2022-10-18T09:57:59.574] sched: Allocate JobId=50953 NodeList=gpu02 #CPUs=2 Partition=gpu-titan
[2022-10-18T09:58:23.125] _slurm_rpc_submit_batch_job: JobId=50954 InitPrio=1037 usec=533
[2022-10-18T09:58:23.601] sched: Allocate JobId=50954 NodeList=gpu02 #CPUs=6 Partition=gpu-titan
[2022-10-18T09:58:44.077] _job_complete: JobId=50953 WEXITSTATUS 0
[2022-10-18T09:58:44.077] _job_complete: JobId=50953 done
[2022-10-18T10:12:21.159] _slurm_rpc_submit_batch_job: JobId=50955 InitPrio=1033 usec=583
[2022-10-18T10:12:22.024] sched: Allocate JobId=50955 NodeList=cpu01 #CPUs=32 Partition=cpu-opteron
[2022-10-18T10:17:52.975] _slurm_rpc_submit_batch_job: JobId=50956 InitPrio=2663 usec=431
[2022-10-18T10:17:53.577] sched: Allocate JobId=50956 NodeList=cpu15 #CPUs=8 Partition=cpu-epyc
[2022-10-18T10:17:56.331] _slurm_rpc_submit_batch_job: JobId=50957 InitPrio=2663 usec=458
[2022-10-18T10:17:56.565] sched: Allocate JobId=50957 NodeList=cpu15 #CPUs=8 Partition=cpu-epyc
[2022-10-18T10:18:00.203] _slurm_rpc_submit_batch_job: JobId=50958 InitPrio=2663 usec=563
[2022-10-18T10:18:00.570] sched: Allocate JobId=50958 NodeList=cpu15 #CPUs=8 Partition=cpu-epyc
[2022-10-18T10:18:03.226] _slurm_rpc_submit_batch_job: JobId=50959 InitPrio=2663 usec=433
[2022-10-18T10:18:03.575] sched: Allocate JobId=50959 NodeList=cpu15 #CPUs=8 Partition=cpu-epyc
[2022-10-18T10:18:08.683] _slurm_rpc_submit_batch_job: JobId=50960 InitPrio=2663 usec=482
[2022-10-18T10:18:09.583] sched: Allocate JobId=50960 NodeList=cpu15 #CPUs=8 Partition=cpu-epyc
[2022-10-18T10:18:15.092] _slurm_rpc_submit_batch_job: JobId=50961 InitPrio=2663 usec=510
[2022-10-18T10:18:15.590] sched: Allocate JobId=50961 NodeList=cpu15 #CPUs=8 Partition=cpu-epyc
[2022-10-18T10:18:18.747] _slurm_rpc_submit_batch_job: JobId=50962 InitPrio=2663 usec=423
[2022-10-18T10:18:19.595] sched: Allocate JobId=50962 NodeList=cpu12 #CPUs=8 Partition=cpu-epyc
[2022-10-18T10:18:25.691] _slurm_rpc_submit_batch_job: JobId=50963 InitPrio=2663 usec=441
[2022-10-18T10:18:26.605] sched: Allocate JobId=50963 NodeList=cpu12 #CPUs=8 Partition=cpu-epyc
[2022-10-18T10:18:41.819] _job_complete: JobId=50955 WEXITSTATUS 0
[2022-10-18T10:18:41.819] _job_complete: JobId=50955 done
[2022-10-18T10:22:17.301] _slurm_rpc_kill_job: REQUEST_KILL_JOB JobId=50963 uid 548200020
[2022-10-18T10:23:17.158] _slurm_rpc_submit_batch_job: JobId=50964 InitPrio=2663 usec=541
[2022-10-18T10:23:18.087] sched: Allocate JobId=50964 NodeList=cpu12 #CPUs=8 Partition=cpu-epyc
[2022-10-18T10:23:56.807] _slurm_rpc_submit_batch_job: JobId=50965 InitPrio=1024 usec=525
[2022-10-18T10:23:57.148] sched: Allocate JobId=50965 NodeList=cpu01 #CPUs=2 Partition=cpu-opteron
[2022-10-18T10:23:59.812] _job_complete: JobId=50965 WEXITSTATUS 0
[2022-10-18T10:23:59.812] _job_complete: JobId=50965 done
[2022-10-18T10:26:59.701] _slurm_rpc_submit_batch_job: JobId=50966 InitPrio=2663 usec=467
[2022-10-18T10:27:00.484] sched: Allocate JobId=50966 NodeList=cpu01 #CPUs=8 Partition=cpu-opteron
[2022-10-18T10:33:04.750] _job_complete: JobId=50962 WEXITSTATUS 0
[2022-10-18T10:33:04.750] _job_complete: JobId=50962 done
[2022-10-18T10:33:47.561] _job_complete: JobId=50957 WEXITSTATUS 0
[2022-10-18T10:33:47.562] _job_complete: JobId=50957 done
[2022-10-18T10:33:48.321] _job_complete: JobId=50959 WEXITSTATUS 0
[2022-10-18T10:33:48.322] _job_complete: JobId=50959 done
[2022-10-18T10:33:52.631] _job_complete: JobId=50958 WEXITSTATUS 0
[2022-10-18T10:33:52.631] _job_complete: JobId=50958 done
[2022-10-18T10:33:56.565] _job_complete: JobId=50956 WEXITSTATUS 0
[2022-10-18T10:33:56.566] _job_complete: JobId=50956 done
[2022-10-18T10:34:09.358] _job_complete: JobId=50960 WEXITSTATUS 0
[2022-10-18T10:34:09.358] _job_complete: JobId=50960 done
[2022-10-18T10:34:12.740] _job_complete: JobId=50961 WEXITSTATUS 0
[2022-10-18T10:34:12.740] _job_complete: JobId=50961 done
[2022-10-18T10:39:44.453] _job_complete: JobId=50964 WEXITSTATUS 0
[2022-10-18T10:39:44.453] _job_complete: JobId=50964 done
[2022-10-18T10:39:47.755] Time limit exhausted for JobId=50423
[2022-10-18T10:59:26.369] _slurm_rpc_submit_batch_job: JobId=50967 InitPrio=4303 usec=559
[2022-10-18T10:59:27.027] sched: Allocate JobId=50967 NodeList=cpu01 #CPUs=4 Partition=cpu-opteron
[2022-10-18T10:59:34.110] _job_complete: JobId=50967 WEXITSTATUS 0
[2022-10-18T10:59:34.111] _job_complete: JobId=50967 done
[2022-10-18T11:04:05.447] _slurm_rpc_submit_batch_job: JobId=50968 InitPrio=4303 usec=498
[2022-10-18T11:04:05.486] sched: Allocate JobId=50968 NodeList=cpu15 #CPUs=4 Partition=cpu-epyc
[2022-10-18T11:04:07.985] _job_complete: JobId=50968 WEXITSTATUS 0
[2022-10-18T11:04:07.985] _job_complete: JobId=50968 done
[2022-10-18T11:05:38.707] _slurm_rpc_submit_batch_job: JobId=50969 InitPrio=4303 usec=479
[2022-10-18T11:05:39.618] sched: Allocate JobId=50969 NodeList=cpu01 #CPUs=4 Partition=cpu-opteron
[2022-10-18T11:05:42.110] _job_complete: JobId=50969 WEXITSTATUS 0
[2022-10-18T11:05:42.110] _job_complete: JobId=50969 done
[2022-10-18T11:06:33.799] _slurm_rpc_submit_batch_job: JobId=50970 InitPrio=4303 usec=526
[2022-10-18T11:06:34.787] sched: Allocate JobId=50970 NodeList=cpu01 #CPUs=4 Partition=cpu-opteron
[2022-10-18T11:06:36.292] _job_complete: JobId=50970 WEXITSTATUS 0
[2022-10-18T11:06:36.292] _job_complete: JobId=50970 done
[2022-10-18T11:07:25.702] _slurm_rpc_submit_batch_job: JobId=50971 InitPrio=4303 usec=465
[2022-10-18T11:07:25.858] sched: Allocate JobId=50971 NodeList=cpu01 #CPUs=4 Partition=cpu-opteron
[2022-10-18T11:07:27.335] _job_complete: JobId=50971 WEXITSTATUS 0
[2022-10-18T11:07:27.335] _job_complete: JobId=50971 done
[2022-10-18T11:08:23.788] _slurm_rpc_submit_batch_job: JobId=50972 InitPrio=4303 usec=659
[2022-10-18T11:08:23.936] sched: Allocate JobId=50972 NodeList=cpu01 #CPUs=4 Partition=cpu-opteron
[2022-10-18T11:08:25.886] _job_complete: JobId=50972 WEXITSTATUS 0
[2022-10-18T11:08:25.886] _job_complete: JobId=50972 done
[2022-10-18T11:09:08.830] _slurm_rpc_submit_batch_job: JobId=50973 InitPrio=4303 usec=466
[2022-10-18T11:09:08.996] sched: Allocate JobId=50973 NodeList=cpu01 #CPUs=4 Partition=cpu-opteron
[2022-10-18T11:09:10.387] _job_complete: JobId=50973 WEXITSTATUS 0
[2022-10-18T11:09:10.387] _job_complete: JobId=50973 done
[2022-10-18T11:10:15.742] _slurm_rpc_submit_batch_job: JobId=50974 InitPrio=409 usec=473
[2022-10-18T11:10:16.103] sched: Allocate JobId=50974 NodeList=cpu15 #CPUs=1 Partition=cpu-epyc
[2022-10-18T11:11:07.181] _slurm_rpc_submit_batch_job: JobId=50975 InitPrio=2663 usec=405
[2022-10-18T11:11:07.199] sched: Allocate JobId=50975 NodeList=cpu15 #CPUs=8 Partition=cpu-epyc
[2022-10-18T11:11:10.724] _slurm_rpc_submit_batch_job: JobId=50976 InitPrio=2663 usec=457
[2022-10-18T11:11:11.200] sched: Allocate JobId=50976 NodeList=cpu15 #CPUs=8 Partition=cpu-epyc
[2022-10-18T11:11:14.859] _slurm_rpc_submit_batch_job: JobId=50977 InitPrio=2663 usec=452
[2022-10-18T11:11:15.247] sched: Allocate JobId=50977 NodeList=cpu15 #CPUs=8 Partition=cpu-epyc
[2022-10-18T11:11:18.524] _slurm_rpc_submit_batch_job: JobId=50978 InitPrio=2663 usec=423
[2022-10-18T11:11:19.252] sched: Allocate JobId=50978 NodeList=cpu15 #CPUs=8 Partition=cpu-epyc
[2022-10-18T11:11:25.187] _slurm_rpc_submit_batch_job: JobId=50979 InitPrio=2663 usec=438
[2022-10-18T11:11:25.259] sched: Allocate JobId=50979 NodeList=cpu15 #CPUs=8 Partition=cpu-epyc
[2022-10-18T11:11:34.151] _slurm_rpc_submit_batch_job: JobId=50980 InitPrio=2663 usec=504
[2022-10-18T11:11:34.271] sched: Allocate JobId=50980 NodeList=cpu12 #CPUs=8 Partition=cpu-epyc
[2022-10-18T11:11:37.371] _slurm_rpc_submit_batch_job: JobId=50981 InitPrio=2663 usec=395
[2022-10-18T11:11:38.277] sched: Allocate JobId=50981 NodeList=cpu12 #CPUs=8 Partition=cpu-epyc
[2022-10-18T11:11:40.598] _slurm_rpc_submit_batch_job: JobId=50982 InitPrio=2663 usec=645
[2022-10-18T11:11:41.281] sched: Allocate JobId=50982 NodeList=cpu12 #CPUs=8 Partition=cpu-epyc
[2022-10-18T11:13:44.075] _slurm_rpc_submit_batch_job: JobId=50983 InitPrio=409 usec=562
[2022-10-18T11:13:44.442] sched: Allocate JobId=50983 NodeList=gpu03 #CPUs=16 Partition=gpu-k10
[2022-10-18T11:13:46.619] _slurm_rpc_submit_batch_job: JobId=50984 InitPrio=5737 usec=397
[2022-10-18T11:13:47.470] sched: Allocate JobId=50984 NodeList=cpu01 #CPUs=1 Partition=cpu-opteron
[2022-10-18T11:14:04.546] _job_complete: JobId=50983 WEXITSTATUS 1
[2022-10-18T11:14:04.546] _job_complete: JobId=50983 done
[2022-10-18T11:14:28.591] _slurm_rpc_submit_batch_job: JobId=50985 InitPrio=409 usec=444
[2022-10-18T11:14:29.502] sched: Allocate JobId=50985 NodeList=gpu03 #CPUs=16 Partition=gpu-k10
[2022-10-18T11:18:22.554] _slurm_rpc_submit_batch_job: JobId=50986 InitPrio=409 usec=465
[2022-10-18T11:19:59.007] _slurm_rpc_submit_batch_job: JobId=50987 InitPrio=5737 usec=483
[2022-10-18T11:19:59.032] sched: Allocate JobId=50987 NodeList=cpu01 #CPUs=1 Partition=cpu-opteron
[2022-10-18T11:20:18.365] _job_complete: JobId=50987 WEXITSTATUS 1
[2022-10-18T11:20:18.366] _job_complete: JobId=50987 done
[2022-10-18T11:22:12.959] _job_complete: JobId=50974 WEXITSTATUS 0
[2022-10-18T11:22:12.959] _job_complete: JobId=50974 done
[2022-10-18T11:23:25.250] _job_complete: JobId=50980 WEXITSTATUS 0
[2022-10-18T11:23:25.250] _job_complete: JobId=50980 done
[2022-10-18T11:23:48.556] _job_complete: JobId=50977 WEXITSTATUS 0
[2022-10-18T11:23:48.556] _job_complete: JobId=50977 done
[2022-10-18T11:23:54.166] _job_complete: JobId=50976 WEXITSTATUS 0
[2022-10-18T11:23:54.166] _job_complete: JobId=50976 done
[2022-10-18T11:24:13.899] _job_complete: JobId=50978 WEXITSTATUS 0
[2022-10-18T11:24:13.899] _job_complete: JobId=50978 done
[2022-10-18T11:24:15.045] _job_complete: JobId=50979 WEXITSTATUS 0
[2022-10-18T11:24:15.045] _job_complete: JobId=50979 done
[2022-10-18T11:24:18.543] _job_complete: JobId=50975 WEXITSTATUS 0
[2022-10-18T11:24:18.543] _job_complete: JobId=50975 done
[2022-10-18T11:24:23.080] _job_complete: JobId=50982 WEXITSTATUS 0
[2022-10-18T11:24:23.081] _job_complete: JobId=50982 done
[2022-10-18T11:25:00.934] _job_complete: JobId=50981 WEXITSTATUS 0
[2022-10-18T11:25:00.934] _job_complete: JobId=50981 done
[2022-10-18T11:26:32.987] _slurm_rpc_submit_batch_job: JobId=50988 InitPrio=409 usec=462
[2022-10-18T11:26:33.651] sched/backfill: _start_job: Started JobId=50988 in cpu-epyc on cpu13
[2022-10-18T11:26:35.184] _job_complete: JobId=50988 WEXITSTATUS 0
[2022-10-18T11:26:35.184] _job_complete: JobId=50988 done
[2022-10-18T11:27:30.996] _job_complete: JobId=50614 WEXITSTATUS 0
[2022-10-18T11:27:30.996] _job_complete: JobId=50614 done
[2022-10-18T11:27:44.899] _slurm_rpc_submit_batch_job: JobId=50989 InitPrio=409 usec=386
[2022-10-18T11:27:44.931] sched: Allocate JobId=50989 NodeList=cpu13 #CPUs=48 Partition=cpu-epyc
[2022-10-18T11:31:47.347] _job_complete: JobId=50984 WEXITSTATUS 0
[2022-10-18T11:31:47.347] _job_complete: JobId=50984 done
[2022-10-18T11:42:13.528] _job_complete: JobId=50989 WEXITSTATUS 0
[2022-10-18T11:42:13.528] _job_complete: JobId=50989 done
[2022-10-18T11:44:13.063] _slurm_rpc_submit_batch_job: JobId=50990 InitPrio=2663 usec=459
[2022-10-18T11:44:13.597] sched: Allocate JobId=50990 NodeList=cpu15 #CPUs=8 Partition=cpu-epyc
[2022-10-18T11:44:17.348] _slurm_rpc_submit_batch_job: JobId=50991 InitPrio=2663 usec=501
[2022-10-18T11:44:17.599] sched: Allocate JobId=50991 NodeList=cpu15 #CPUs=8 Partition=cpu-epyc
[2022-10-18T11:44:26.636] _slurm_rpc_submit_batch_job: JobId=50992 InitPrio=2663 usec=415
[2022-10-18T11:44:27.613] sched: Allocate JobId=50992 NodeList=cpu15 #CPUs=8 Partition=cpu-epyc
[2022-10-18T11:44:29.812] _slurm_rpc_submit_batch_job: JobId=50993 InitPrio=2663 usec=664
[2022-10-18T11:44:30.616] sched: Allocate JobId=50993 NodeList=cpu15 #CPUs=8 Partition=cpu-epyc
[2022-10-18T11:44:33.308] _slurm_rpc_submit_batch_job: JobId=50994 InitPrio=2663 usec=544
[2022-10-18T11:44:33.620] sched: Allocate JobId=50994 NodeList=cpu15 #CPUs=8 Partition=cpu-epyc
[2022-10-18T11:44:34.008] _job_complete: JobId=50994 WEXITSTATUS 1
[2022-10-18T11:44:34.009] _job_complete: JobId=50994 done
[2022-10-18T11:44:40.606] _slurm_rpc_submit_batch_job: JobId=50995 InitPrio=2663 usec=426
[2022-10-18T11:44:40.632] sched: Allocate JobId=50995 NodeList=cpu15 #CPUs=8 Partition=cpu-epyc
[2022-10-18T11:44:50.668] _slurm_rpc_submit_batch_job: JobId=50996 InitPrio=2663 usec=433
[2022-10-18T11:44:51.647] sched: Allocate JobId=50996 NodeList=cpu15 #CPUs=8 Partition=cpu-epyc
[2022-10-18T11:44:54.172] _slurm_rpc_submit_batch_job: JobId=50997 InitPrio=2663 usec=523
[2022-10-18T11:44:54.651] sched: Allocate JobId=50997 NodeList=cpu12 #CPUs=8 Partition=cpu-epyc
[2022-10-18T11:44:57.516] _slurm_rpc_submit_batch_job: JobId=50998 InitPrio=2663 usec=421
[2022-10-18T11:44:57.655] sched: Allocate JobId=50998 NodeList=cpu12 #CPUs=8 Partition=cpu-epyc
[2022-10-18T11:45:01.207] _slurm_rpc_submit_batch_job: JobId=50999 InitPrio=2663 usec=435
[2022-10-18T11:45:01.661] sched: Allocate JobId=50999 NodeList=cpu12 #CPUs=8 Partition=cpu-epyc
[2022-10-18T11:51:08.267] _slurm_rpc_submit_batch_job: JobId=51000 InitPrio=409 usec=439
[2022-10-18T11:51:08.495] sched: Allocate JobId=51000 NodeList=cpu12 #CPUs=1 Partition=cpu-epyc
[2022-10-18T11:51:11.509] _job_complete: JobId=51000 WEXITSTATUS 0
[2022-10-18T11:51:11.509] _job_complete: JobId=51000 done
[2022-10-18T11:51:32.640] _job_complete: JobId=50985 WEXITSTATUS 0
[2022-10-18T11:51:32.640] _job_complete: JobId=50985 done
[2022-10-18T11:51:33.210] sched: Allocate JobId=50986 NodeList=gpu03 #CPUs=16 Partition=gpu-k10
[2022-10-18T11:51:35.809] _slurm_rpc_submit_batch_job: JobId=51001 InitPrio=5737 usec=400
[2022-10-18T11:51:36.572] sched: Allocate JobId=51001 NodeList=cpu01 #CPUs=1 Partition=cpu-opteron
[2022-10-18T11:54:38.666] _slurm_rpc_submit_batch_job: JobId=51002 InitPrio=409 usec=506
[2022-10-18T11:54:38.817] sched: Allocate JobId=51002 NodeList=cpu13 #CPUs=48 Partition=cpu-epyc
[2022-10-18T11:56:41.350] _job_complete: JobId=50991 WEXITSTATUS 0
[2022-10-18T11:56:41.350] _job_complete: JobId=50991 done
[2022-10-18T11:56:44.063] _job_complete: JobId=50990 WEXITSTATUS 0
[2022-10-18T11:56:44.063] _job_complete: JobId=50990 done
[2022-10-18T11:56:44.999] _job_complete: JobId=51001 WEXITSTATUS 0
[2022-10-18T11:56:45.000] _job_complete: JobId=51001 done
[2022-10-18T11:56:45.229] _job_complete: JobId=50997 WEXITSTATUS 0
[2022-10-18T11:56:45.229] _job_complete: JobId=50997 done
[2022-10-18T11:56:47.658] _job_complete: JobId=50993 WEXITSTATUS 0
[2022-10-18T11:56:47.659] _job_complete: JobId=50993 done
[2022-10-18T11:56:48.538] _job_complete: JobId=50992 WEXITSTATUS 0
[2022-10-18T11:56:48.538] _job_complete: JobId=50992 done
[2022-10-18T11:57:01.484] _job_complete: JobId=50995 WEXITSTATUS 0
[2022-10-18T11:57:01.485] _job_complete: JobId=50995 done
[2022-10-18T11:57:20.692] _job_complete: JobId=50996 WEXITSTATUS 0
[2022-10-18T11:57:20.692] _job_complete: JobId=50996 done
[2022-10-18T11:57:21.720] _job_complete: JobId=50999 WEXITSTATUS 0
[2022-10-18T11:57:21.720] _job_complete: JobId=50999 done
[2022-10-18T11:57:38.086] _job_complete: JobId=50986 WEXITSTATUS 0
[2022-10-18T11:57:38.087] _job_complete: JobId=50986 done
[2022-10-18T11:57:44.981] _slurm_rpc_submit_batch_job: JobId=51003 InitPrio=409 usec=490
[2022-10-18T11:57:47.182] sched: Allocate JobId=51003 NodeList=cpu12 #CPUs=1 Partition=cpu-epyc
[2022-10-18T11:57:55.273] _job_complete: JobId=51003 WEXITSTATUS 0
[2022-10-18T11:57:55.274] _job_complete: JobId=51003 done
[2022-10-18T11:58:22.417] _job_complete: JobId=50998 WEXITSTATUS 0
[2022-10-18T11:58:22.417] _job_complete: JobId=50998 done
[2022-10-18T12:01:38.029] _pick_best_nodes: JobId=51004 never runnable in partition gpu-v100s
[2022-10-18T12:01:38.034] _slurm_rpc_submit_batch_job: Requested node configuration is not available
[2022-10-18T12:01:55.688] _slurm_rpc_submit_batch_job: JobId=51005 InitPrio=6557 usec=373
[2022-10-18T12:02:04.264] _slurm_rpc_kill_job: REQUEST_KILL_JOB JobId=51005 uid 548300576
[2022-10-18T12:02:42.140] _slurm_rpc_submit_batch_job: JobId=51006 InitPrio=6557 usec=460
[2022-10-18T12:03:30.993] _slurm_rpc_submit_batch_job: JobId=51007 InitPrio=6557 usec=409
[2022-10-18T12:12:44.298] _slurm_rpc_submit_batch_job: JobId=51008 InitPrio=2663 usec=483
[2022-10-18T12:12:44.757] sched: Allocate JobId=51008 NodeList=cpu12 #CPUs=8 Partition=cpu-epyc
[2022-10-18T12:24:11.035] _job_complete: JobId=51008 WEXITSTATUS 0
[2022-10-18T12:24:11.035] _job_complete: JobId=51008 done
[2022-10-18T12:46:56.731] _slurm_rpc_submit_batch_job: JobId=51009 InitPrio=409 usec=462
[2022-10-18T12:46:57.336] sched: Allocate JobId=51009 NodeList=cpu12 #CPUs=1 Partition=cpu-epyc
[2022-10-18T12:47:06.134] _job_complete: JobId=51009 WEXITSTATUS 1
[2022-10-18T12:47:06.134] _job_complete: JobId=51009 done
[2022-10-18T12:48:55.897] _slurm_rpc_submit_batch_job: JobId=51010 InitPrio=409 usec=584
[2022-10-18T12:48:56.486] sched: Allocate JobId=51010 NodeList=cpu12 #CPUs=1 Partition=cpu-epyc
[2022-10-18T12:49:07.957] _job_complete: JobId=51010 WEXITSTATUS 1
[2022-10-18T12:49:07.958] _job_complete: JobId=51010 done
[2022-10-18T12:51:26.155] _slurm_rpc_submit_batch_job: JobId=51011 InitPrio=409 usec=413
[2022-10-18T12:51:26.811] sched: Allocate JobId=51011 NodeList=cpu12 #CPUs=1 Partition=cpu-epyc
[2022-10-18T12:52:19.113] _job_complete: JobId=51011 WEXITSTATUS 0
[2022-10-18T12:52:19.113] _job_complete: JobId=51011 done
[2022-10-18T12:58:01.676] _slurm_rpc_submit_batch_job: JobId=51012 InitPrio=409 usec=503
[2022-10-18T12:58:02.444] sched: Allocate JobId=51012 NodeList=cpu12 #CPUs=1 Partition=cpu-epyc
[2022-10-18T12:58:54.769] _job_complete: JobId=51012 WEXITSTATUS 0
[2022-10-18T12:58:54.769] _job_complete: JobId=51012 done
[2022-10-18T13:00:44.963] _slurm_rpc_submit_batch_job: JobId=51013 InitPrio=409 usec=782
[2022-10-18T13:00:47.665] sched: Allocate JobId=51013 NodeList=cpu12 #CPUs=1 Partition=cpu-epyc
[2022-10-18T13:01:39.979] _job_complete: JobId=51013 WEXITSTATUS 0
[2022-10-18T13:01:39.979] _job_complete: JobId=51013 done
[2022-10-18T13:03:46.268] _job_complete: JobId=51002 WEXITSTATUS 0
[2022-10-18T13:03:46.268] _job_complete: JobId=51002 done
[2022-10-18T13:03:52.376] _slurm_rpc_submit_batch_job: JobId=51014 InitPrio=409 usec=519
[2022-10-18T13:03:53.359] sched: Allocate JobId=51014 NodeList=cpu15 #CPUs=1 Partition=cpu-epyc
[2022-10-18T13:04:06.756] _job_complete: JobId=51014 WEXITSTATUS 0
[2022-10-18T13:04:06.756] _job_complete: JobId=51014 done
[2022-10-18T13:05:27.183] _slurm_rpc_submit_batch_job: JobId=51015 InitPrio=409 usec=455
[2022-10-18T13:05:27.489] sched: Allocate JobId=51015 NodeList=cpu15 #CPUs=1 Partition=cpu-epyc
[2022-10-18T13:05:40.815] _job_complete: JobId=51015 WEXITSTATUS 0
[2022-10-18T13:05:40.815] _job_complete: JobId=51015 done
[2022-10-18T13:08:39.779] _slurm_rpc_submit_batch_job: JobId=51016 InitPrio=409 usec=449
[2022-10-18T13:08:39.836] sched: Allocate JobId=51016 NodeList=cpu15 #CPUs=1 Partition=cpu-epyc
[2022-10-18T13:08:53.257] _job_complete: JobId=51016 WEXITSTATUS 0
[2022-10-18T13:08:53.257] _job_complete: JobId=51016 done
[2022-10-18T13:09:04.456] _slurm_rpc_submit_batch_job: JobId=51017 InitPrio=409 usec=383
[2022-10-18T13:09:04.870] sched: Allocate JobId=51017 NodeList=cpu15 #CPUs=1 Partition=cpu-epyc
[2022-10-18T13:09:17.713] _job_complete: JobId=51017 WEXITSTATUS 0
[2022-10-18T13:09:17.713] _job_complete: JobId=51017 done
[2022-10-18T13:10:55.603] _slurm_rpc_submit_batch_job: JobId=51018 InitPrio=409 usec=433
[2022-10-18T13:10:56.020] sched: Allocate JobId=51018 NodeList=cpu15 #CPUs=1 Partition=cpu-epyc
[2022-10-18T13:12:03.498] _job_complete: JobId=51018 WEXITSTATUS 0
[2022-10-18T13:12:03.498] _job_complete: JobId=51018 done
[2022-10-18T13:26:50.514] _slurm_rpc_submit_batch_job: JobId=51019 InitPrio=409 usec=538
[2022-10-18T13:26:50.750] sched: Allocate JobId=51019 NodeList=cpu15 #CPUs=1 Partition=cpu-epyc
[2022-10-18T13:31:48.557] _job_complete: JobId=50966 WEXITSTATUS 0
[2022-10-18T13:31:48.557] _job_complete: JobId=50966 done
[2022-10-18T13:40:29.212] _job_complete: JobId=51019 WEXITSTATUS 0
[2022-10-18T13:40:29.212] _job_complete: JobId=51019 done
[2022-10-18T13:45:17.986] _slurm_rpc_submit_batch_job: JobId=51020 InitPrio=409 usec=508
[2022-10-18T13:45:18.544] sched: Allocate JobId=51020 NodeList=cpu13 #CPUs=1 Partition=cpu-epyc
[2022-10-18T13:45:19.968] _job_complete: JobId=51020 WEXITSTATUS 0
[2022-10-18T13:45:19.968] _job_complete: JobId=51020 done
[2022-10-18T13:45:32.977] _slurm_rpc_submit_batch_job: JobId=51021 InitPrio=409 usec=403
[2022-10-18T13:45:33.559] sched: Allocate JobId=51021 NodeList=cpu13 #CPUs=48 Partition=cpu-epyc
[2022-10-18T13:45:57.232] _slurm_rpc_submit_batch_job: JobId=51022 InitPrio=409 usec=447
[2022-10-18T13:45:57.592] sched: Allocate JobId=51022 NodeList=cpu12 #CPUs=1 Partition=cpu-epyc
[2022-10-18T13:46:15.718] _job_complete: JobId=51022 WEXITSTATUS 1
[2022-10-18T13:46:15.718] _job_complete: JobId=51022 done
[2022-10-18T13:47:13.161] _slurm_rpc_submit_batch_job: JobId=51023 InitPrio=409 usec=464
[2022-10-18T13:47:13.769] sched: Allocate JobId=51023 NodeList=cpu12 #CPUs=1 Partition=cpu-epyc
[2022-10-18T13:47:36.996] _job_complete: JobId=51023 WEXITSTATUS 1
[2022-10-18T13:47:36.996] _job_complete: JobId=51023 done
[2022-10-18T13:48:54.666] _slurm_rpc_submit_batch_job: JobId=51024 InitPrio=409 usec=464
[2022-10-18T13:48:54.906] sched: Allocate JobId=51024 NodeList=cpu12 #CPUs=1 Partition=cpu-epyc
[2022-10-18T13:49:18.219] _job_complete: JobId=51024 WEXITSTATUS 0
[2022-10-18T13:49:18.219] _job_complete: JobId=51024 done
[2022-10-18T13:55:34.484] _slurm_rpc_submit_batch_job: JobId=51025 InitPrio=409 usec=408
[2022-10-18T13:55:34.553] sched: Allocate JobId=51025 NodeList=cpu15 #CPUs=48 Partition=cpu-epyc
[2022-10-18T14:00:20.241] _job_complete: JobId=51021 WEXITSTATUS 0
[2022-10-18T14:00:20.241] _job_complete: JobId=51021 done
[2022-10-18T14:02:05.713] _slurm_rpc_submit_batch_job: JobId=51026 InitPrio=409 usec=388
[2022-10-18T14:02:06.215] sched: Allocate JobId=51026 NodeList=cpu12 #CPUs=1 Partition=cpu-epyc
[2022-10-18T14:02:08.120] _job_complete: JobId=51026 WEXITSTATUS 0
[2022-10-18T14:02:08.120] _job_complete: JobId=51026 done
[2022-10-18T14:02:21.398] _slurm_rpc_submit_batch_job: JobId=51027 InitPrio=409 usec=443
[2022-10-18T14:02:22.236] sched: Allocate JobId=51027 NodeList=cpu13 #CPUs=48 Partition=cpu-epyc
[2022-10-18T14:11:18.528] _job_complete: JobId=51025 WEXITSTATUS 0
[2022-10-18T14:11:18.529] _job_complete: JobId=51025 done
[2022-10-18T14:15:12.844] _slurm_rpc_submit_batch_job: JobId=51028 InitPrio=409 usec=457
[2022-10-18T14:15:13.551] sched: Allocate JobId=51028 NodeList=cpu15 #CPUs=48 Partition=cpu-epyc
[2022-10-18T14:20:16.164] _slurm_rpc_submit_batch_job: JobId=51029 InitPrio=2663 usec=471
[2022-10-18T14:20:17.054] sched: Allocate JobId=51029 NodeList=cpu12 #CPUs=8 Partition=cpu-epyc
[2022-10-18T14:25:08.493] _slurm_rpc_submit_batch_job: JobId=51030 InitPrio=409 usec=549
[2022-10-18T14:25:08.510] sched: Allocate JobId=51030 NodeList=gpu03 #CPUs=16 Partition=gpu-k10
[2022-10-18T14:31:42.214] _slurm_rpc_kill_job: REQUEST_KILL_JOB JobId=50606 uid 548300621
[2022-10-18T14:31:52.032] _slurm_rpc_kill_job: REQUEST_KILL_JOB JobId=50609 uid 548300621
[2022-10-18T14:32:00.809] _slurm_rpc_kill_job: REQUEST_KILL_JOB JobId=50613 uid 548300621
[2022-10-18T14:32:13.581] _job_complete: JobId=51030 WEXITSTATUS 0
[2022-10-18T14:32:13.581] _job_complete: JobId=51030 done
[2022-10-18T14:32:21.416] _slurm_rpc_kill_job: REQUEST_KILL_JOB JobId=50613 uid 548300621
[2022-10-18T14:35:08.036] _slurm_rpc_submit_batch_job: JobId=51031 InitPrio=409 usec=465
[2022-10-18T14:35:08.540] sched: Allocate JobId=51031 NodeList=gpu03 #CPUs=16 Partition=gpu-k10
[2022-10-18T14:36:18.996] _slurm_rpc_submit_batch_job: JobId=51032 InitPrio=409 usec=469
[2022-10-18T14:36:24.016] _slurm_rpc_submit_batch_job: JobId=51033 InitPrio=204 usec=483
[2022-10-18T14:36:24.756] sched: Allocate JobId=51033 NodeList=cpu03 #CPUs=64 Partition=cpu-opteron
[2022-10-18T14:36:41.846] _slurm_rpc_submit_batch_job: JobId=51034 InitPrio=204 usec=495
[2022-10-18T14:36:42.760] sched: Allocate JobId=51034 NodeList=cpu04 #CPUs=64 Partition=cpu-opteron
[2022-10-18T14:37:00.911] _slurm_rpc_submit_batch_job: JobId=51035 InitPrio=204 usec=495
[2022-10-18T14:37:01.786] sched: Allocate JobId=51035 NodeList=cpu05 #CPUs=64 Partition=cpu-opteron
[2022-10-18T14:37:11.517] _slurm_rpc_submit_batch_job: JobId=51036 InitPrio=204 usec=469
[2022-10-18T14:37:11.798] sched: Allocate JobId=51036 NodeList=cpu07 #CPUs=64 Partition=cpu-opteron
[2022-10-18T14:38:57.210] _job_complete: JobId=51028 WEXITSTATUS 0
[2022-10-18T14:38:57.210] _job_complete: JobId=51028 done
[2022-10-18T14:53:41.115] _slurm_rpc_submit_batch_job: JobId=51037 InitPrio=204 usec=520
[2022-10-18T14:53:41.715] sched: Allocate JobId=51037 NodeList=cpu08 #CPUs=64 Partition=cpu-opteron
[2022-10-18T14:53:47.948] _slurm_rpc_submit_batch_job: JobId=51038 InitPrio=204 usec=422
[2022-10-18T14:53:48.720] sched: Allocate JobId=51038 NodeList=cpu09 #CPUs=64 Partition=cpu-opteron
[2022-10-18T14:53:55.845] _slurm_rpc_submit_batch_job: JobId=51039 InitPrio=204 usec=505
[2022-10-18T14:53:56.731] sched: Allocate JobId=51039 NodeList=cpu10 #CPUs=64 Partition=cpu-opteron
[2022-10-18T14:54:37.577] _job_complete: JobId=51031 WEXITSTATUS 0
[2022-10-18T14:54:37.577] _job_complete: JobId=51031 done
[2022-10-18T14:54:38.122] sched: Allocate JobId=51032 NodeList=gpu03 #CPUs=16 Partition=gpu-k10
[2022-10-18T15:01:19.059] _slurm_rpc_submit_batch_job: JobId=51040 InitPrio=4303 usec=494
[2022-10-18T15:01:31.612] _slurm_rpc_kill_job: REQUEST_KILL_JOB JobId=51040 uid 548300584
[2022-10-18T15:10:55.251] _job_complete: JobId=51029 WEXITSTATUS 0
[2022-10-18T15:10:55.252] _job_complete: JobId=51029 done
[2022-10-18T15:23:07.637] _job_complete: JobId=51027 WEXITSTATUS 0
[2022-10-18T15:23:07.637] _job_complete: JobId=51027 done
[2022-10-18T15:29:46.399] _job_create: exceeded association/QOS limit for user 548200021: QOSMaxWallDurationPerJobLimit
[2022-10-18T15:29:46.399] _slurm_rpc_submit_batch_job: Job violates accounting/QOS policy (job submit limit, user's size and/or time limits)
[2022-10-18T15:30:00.842] _job_create: exceeded association/QOS limit for user 548200021: QOSMaxWallDurationPerJobLimit
[2022-10-18T15:30:00.842] _slurm_rpc_submit_batch_job: Job violates accounting/QOS policy (job submit limit, user's size and/or time limits)
[2022-10-18T15:30:19.370] _job_create: exceeded association/QOS limit for user 548200021: QOSMaxWallDurationPerJobLimit
[2022-10-18T15:30:19.370] _slurm_rpc_submit_batch_job: Job violates accounting/QOS policy (job submit limit, user's size and/or time limits)
[2022-10-18T15:30:29.441] _job_complete: JobId=51032 WEXITSTATUS 0
[2022-10-18T15:30:29.441] _job_complete: JobId=51032 done
[2022-10-18T15:30:51.100] _job_create: exceeded association/QOS limit for user 548200021: QOSMaxWallDurationPerJobLimit
[2022-10-18T15:30:51.100] _slurm_rpc_submit_batch_job: Job violates accounting/QOS policy (job submit limit, user's size and/or time limits)
[2022-10-18T15:31:23.211] _slurm_rpc_submit_batch_job: JobId=51041 InitPrio=409 usec=474
[2022-10-18T15:31:23.675] sched: Allocate JobId=51041 NodeList=cpu13 #CPUs=48 Partition=cpu-epyc
[2022-10-18T15:39:15.085] _slurm_rpc_submit_batch_job: JobId=51042 InitPrio=409 usec=522
[2022-10-18T15:39:15.412] sched: Allocate JobId=51042 NodeList=gpu03 #CPUs=16 Partition=gpu-k10
[2022-10-18T16:39:02.233] _slurm_rpc_submit_batch_job: JobId=51043 InitPrio=4303 usec=543
[2022-10-18T16:39:02.661] sched: Allocate JobId=51043 NodeList=cpu01 #CPUs=32 Partition=cpu-opteron
[2022-10-18T16:44:36.275] _slurm_rpc_submit_batch_job: JobId=51044 InitPrio=4303 usec=547
[2022-10-18T16:44:37.195] sched: Allocate JobId=51044 NodeList=cpu01 #CPUs=16 Partition=cpu-opteron
[2022-10-18T16:45:06.782] _job_complete: JobId=51044 WEXITSTATUS 0
[2022-10-18T16:45:06.783] _job_complete: JobId=51044 done
[2022-10-18T16:45:52.755] _job_complete: JobId=51043 WEXITSTATUS 0
[2022-10-18T16:45:52.755] _job_complete: JobId=51043 done
[2022-10-18T16:54:38.230] _slurm_rpc_submit_batch_job: JobId=51045 InitPrio=4303 usec=516
[2022-10-18T16:54:39.186] sched: Allocate JobId=51045 NodeList=gpu02 #CPUs=4 Partition=gpu-titan
[2022-10-18T18:14:15.889] _job_complete: JobId=50785 WEXITSTATUS 0
[2022-10-18T18:14:15.889] _job_complete: JobId=50785 done
[2022-10-18T20:04:50.400] _slurm_rpc_submit_batch_job: JobId=51046 InitPrio=1024 usec=523
[2022-10-18T20:04:50.450] sched: Allocate JobId=51046 NodeList=cpu01 #CPUs=32 Partition=cpu-opteron
[2022-10-18T20:05:37.734] _job_complete: JobId=51046 WEXITSTATUS 0
[2022-10-18T20:05:37.735] _job_complete: JobId=51046 done
[2022-10-18T20:07:28.543] _slurm_rpc_submit_batch_job: JobId=51047 InitPrio=1024 usec=507
[2022-10-18T20:07:28.728] sched: Allocate JobId=51047 NodeList=cpu01 #CPUs=2 Partition=cpu-opteron
[2022-10-18T20:07:29.509] _job_complete: JobId=51047 WEXITSTATUS 1
[2022-10-18T20:07:29.509] _job_complete: JobId=51047 done
[2022-10-18T20:07:58.998] _slurm_rpc_submit_batch_job: JobId=51048 InitPrio=1024 usec=428
[2022-10-18T20:07:59.768] sched: Allocate JobId=51048 NodeList=cpu01 #CPUs=2 Partition=cpu-opteron
[2022-10-18T20:08:01.038] _job_complete: JobId=51048 WEXITSTATUS 0
[2022-10-18T20:08:01.038] _job_complete: JobId=51048 done
[2022-10-18T21:53:33.982] sched: _slurm_rpc_allocate_resources JobId=51049 NodeList=(null) usec=1255
[2022-10-18T21:53:34.772] sched: Allocate JobId=51049 NodeList=cpu01 #CPUs=1 Partition=cpu-opteron
[2022-10-18T22:10:10.913] _slurm_rpc_submit_batch_job: JobId=51050 InitPrio=409 usec=478
[2022-10-18T22:10:11.364] sched: Allocate JobId=51050 NodeList=cpu15 #CPUs=48 Partition=cpu-epyc
[2022-10-18T22:30:17.323] _job_complete: JobId=51050 WEXITSTATUS 0
[2022-10-18T22:30:17.323] _job_complete: JobId=51050 done
[2022-10-18T22:43:16.666] _slurm_rpc_submit_batch_job: JobId=51051 InitPrio=409 usec=490
[2022-10-18T22:43:17.519] sched: Allocate JobId=51051 NodeList=cpu15 #CPUs=48 Partition=cpu-epyc
[2022-10-18T23:20:44.475] _job_complete: JobId=51049 WEXITSTATUS 0
[2022-10-18T23:20:44.476] _job_complete: JobId=51049 done
[2022-10-18T23:25:14.832] _slurm_rpc_kill_job: REQUEST_KILL_JOB JobId=51051 uid 548200021
[2022-10-18T23:31:27.198] _slurm_rpc_submit_batch_job: JobId=51052 InitPrio=409 usec=484
[2022-10-18T23:31:27.651] sched: Allocate JobId=51052 NodeList=cpu15 #CPUs=48 Partition=cpu-epyc
[2022-10-19T01:20:37.960] _job_complete: JobId=51042 WEXITSTATUS 1
[2022-10-19T01:20:37.961] _job_complete: JobId=51042 done
[2022-10-19T01:25:10.267] _slurm_rpc_submit_batch_job: JobId=51053 InitPrio=5532 usec=509
[2022-10-19T02:46:34.957] _slurm_rpc_submit_batch_job: JobId=51054 InitPrio=2868 usec=634
[2022-10-19T02:46:35.916] sched: Allocate JobId=51054 NodeList=cpu01 #CPUs=4 Partition=cpu-opteron
[2022-10-19T02:58:29.835] _job_complete: JobId=51054 WEXITSTATUS 1
[2022-10-19T02:58:29.835] _job_complete: JobId=51054 done
[2022-10-19T04:02:58.710] _job_complete: JobId=51036 WEXITSTATUS 0
[2022-10-19T04:02:58.710] _job_complete: JobId=51036 done
[2022-10-19T07:14:42.481] _slurm_rpc_submit_batch_job: JobId=51055 InitPrio=2868 usec=533
[2022-10-19T07:14:42.672] sched: Allocate JobId=51055 NodeList=cpu01 #CPUs=4 Partition=cpu-opteron
[2022-10-19T07:27:46.268] _slurm_rpc_submit_batch_job: JobId=51056 InitPrio=2459 usec=418
[2022-10-19T07:27:47.213] sched: Allocate JobId=51056 NodeList=cpu01 #CPUs=10 Partition=cpu-opteron
[2022-10-19T07:27:51.272] _job_complete: JobId=51056 WEXITSTATUS 1
[2022-10-19T07:27:51.273] _job_complete: JobId=51056 done
[2022-10-19T07:28:18.185] _slurm_rpc_kill_job: REQUEST_KILL_JOB JobId=51056 uid 548300593
[2022-10-19T07:29:26.944] _slurm_rpc_submit_batch_job: JobId=51057 InitPrio=2459 usec=432
[2022-10-19T07:29:27.321] sched: Allocate JobId=51057 NodeList=cpu01 #CPUs=50 Partition=cpu-opteron
[2022-10-19T07:29:33.476] _job_complete: JobId=51057 WEXITSTATUS 1
[2022-10-19T07:29:33.476] _job_complete: JobId=51057 done
[2022-10-19T07:30:41.606] _slurm_rpc_kill_job: REQUEST_KILL_JOB JobId=51057 uid 548300593
[2022-10-19T07:36:20.776] _slurm_rpc_submit_batch_job: JobId=51058 InitPrio=2459 usec=408
[2022-10-19T07:36:21.509] sched: Allocate JobId=51058 NodeList=cpu01 #CPUs=50 Partition=cpu-opteron
[2022-10-19T07:36:29.055] _job_complete: JobId=51058 WEXITSTATUS 1
[2022-10-19T07:36:29.056] _job_complete: JobId=51058 done
[2022-10-19T08:26:28.324] _job_complete: JobId=51055 WEXITSTATUS 1
[2022-10-19T08:26:28.324] _job_complete: JobId=51055 done
[2022-10-19T08:28:42.384] _slurm_rpc_submit_batch_job: JobId=51059 InitPrio=2459 usec=431
[2022-10-19T08:28:42.532] sched: Allocate JobId=51059 NodeList=cpu01 #CPUs=50 Partition=cpu-opteron
[2022-10-19T09:53:40.287] _job_complete: JobId=51034 WEXITSTATUS 0
[2022-10-19T09:53:40.287] _job_complete: JobId=51034 done
[2022-10-19T10:45:30.540] _slurm_rpc_submit_batch_job: JobId=51060 InitPrio=3893 usec=547
[2022-10-19T10:45:31.493] sched: Allocate JobId=51060 NodeList=cpu04 #CPUs=16 Partition=cpu-opteron
[2022-10-19T10:45:33.156] _job_complete: JobId=51060 WEXITSTATUS 31
[2022-10-19T10:45:33.157] _job_complete: JobId=51060 done
[2022-10-19T10:47:13.932] _slurm_rpc_submit_batch_job: JobId=51061 InitPrio=3893 usec=567
[2022-10-19T10:47:14.695] sched: Allocate JobId=51061 NodeList=cpu04 #CPUs=16 Partition=cpu-opteron
[2022-10-19T10:47:36.259] _job_complete: JobId=51061 WEXITSTATUS 0
[2022-10-19T10:47:36.259] _job_complete: JobId=51061 done
[2022-10-19T10:50:58.906] _slurm_rpc_submit_batch_job: JobId=51062 InitPrio=3893 usec=496
[2022-10-19T10:54:24.287] _slurm_rpc_submit_batch_job: JobId=51063 InitPrio=3893 usec=493
[2022-10-19T10:54:24.487] sched: Allocate JobId=51063 NodeList=cpu04 #CPUs=16 Partition=cpu-opteron
[2022-10-19T10:54:28.176] _job_complete: JobId=51063 WEXITSTATUS 0
[2022-10-19T10:54:28.176] _job_complete: JobId=51063 done
[2022-10-19T10:56:59.628] _slurm_rpc_submit_batch_job: JobId=51064 InitPrio=3893 usec=532
[2022-10-19T10:59:53.886] _slurm_rpc_submit_batch_job: JobId=51065 InitPrio=3893 usec=428
[2022-10-19T10:59:54.061] sched: Allocate JobId=51065 NodeList=cpu04 #CPUs=16 Partition=cpu-opteron
[2022-10-19T11:00:03.457] _job_complete: JobId=51065 WEXITSTATUS 0
[2022-10-19T11:00:03.457] _job_complete: JobId=51065 done
[2022-10-19T11:02:30.263] _slurm_rpc_submit_batch_job: JobId=51066 InitPrio=3893 usec=568
[2022-10-19T11:04:46.067] _slurm_rpc_submit_batch_job: JobId=51067 InitPrio=3893 usec=556
[2022-10-19T11:04:48.661] sched: Allocate JobId=51067 NodeList=cpu04 #CPUs=16 Partition=cpu-opteron
[2022-10-19T11:04:56.558] _job_complete: JobId=51067 WEXITSTATUS 0
[2022-10-19T11:04:56.558] _job_complete: JobId=51067 done
[2022-10-19T11:07:31.277] _slurm_rpc_submit_batch_job: JobId=51068 InitPrio=3893 usec=634
[2022-10-19T11:10:36.451] _slurm_rpc_submit_batch_job: JobId=51069 InitPrio=3893 usec=450
[2022-10-19T11:10:37.242] sched: Allocate JobId=51069 NodeList=cpu04 #CPUs=16 Partition=cpu-opteron
[2022-10-19T11:10:44.999] _job_complete: JobId=51069 WEXITSTATUS 0
[2022-10-19T11:10:44.999] _job_complete: JobId=51069 done
[2022-10-19T11:14:59.458] _slurm_rpc_submit_batch_job: JobId=51070 InitPrio=3893 usec=486
[2022-10-19T11:17:00.458] _slurm_rpc_submit_batch_job: JobId=51071 InitPrio=3893 usec=595
[2022-10-19T11:17:00.944] sched: Allocate JobId=51071 NodeList=cpu04 #CPUs=16 Partition=cpu-opteron
[2022-10-19T11:17:10.524] _job_complete: JobId=51071 WEXITSTATUS 0
[2022-10-19T11:17:10.524] _job_complete: JobId=51071 done
[2022-10-19T11:20:42.046] _slurm_rpc_submit_batch_job: JobId=51072 InitPrio=3893 usec=471
[2022-10-19T11:46:38.890] _slurm_rpc_submit_batch_job: JobId=51073 InitPrio=409 usec=459
[2022-10-19T11:46:39.030] sched: Allocate JobId=51073 NodeList=cpu01 #CPUs=4 Partition=cpu-opteron
[2022-10-19T11:46:43.405] _job_complete: JobId=51073 WEXITSTATUS 0
[2022-10-19T11:46:43.406] _job_complete: JobId=51073 done
[2022-10-19T11:53:10.832] _slurm_rpc_submit_batch_job: JobId=51074 InitPrio=409 usec=513
[2022-10-19T11:53:11.659] sched: Allocate JobId=51074 NodeList=cpu01 #CPUs=4 Partition=cpu-opteron
[2022-10-19T11:53:15.373] _job_complete: JobId=51074 WEXITSTATUS 0
[2022-10-19T11:53:15.373] _job_complete: JobId=51074 done
[2022-10-19T12:12:02.979] _slurm_rpc_submit_batch_job: JobId=51075 InitPrio=409 usec=543
[2022-10-19T12:12:03.678] sched: Allocate JobId=51075 NodeList=cpu01 #CPUs=4 Partition=cpu-opteron
[2022-10-19T12:12:07.399] _job_complete: JobId=51075 WEXITSTATUS 0
[2022-10-19T12:12:07.399] _job_complete: JobId=51075 done
[2022-10-19T12:12:43.039] _slurm_rpc_submit_batch_job: JobId=51076 InitPrio=409 usec=496
[2022-10-19T12:12:43.727] sched: Allocate JobId=51076 NodeList=cpu01 #CPUs=4 Partition=cpu-opteron
[2022-10-19T12:12:45.891] _job_complete: JobId=51076 WEXITSTATUS 0
[2022-10-19T12:12:45.891] _job_complete: JobId=51076 done
[2022-10-19T13:20:14.853] _slurm_rpc_submit_batch_job: JobId=51077 InitPrio=2459 usec=479
[2022-10-19T13:20:15.698] sched: Allocate JobId=51077 NodeList=cpu04 #CPUs=50 Partition=cpu-opteron
[2022-10-19T13:20:17.151] _job_complete: JobId=51077 WEXITSTATUS 0
[2022-10-19T13:20:17.151] _job_complete: JobId=51077 done
[2022-10-19T13:23:51.039] _slurm_rpc_submit_batch_job: JobId=51078 InitPrio=2459 usec=501
[2022-10-19T13:23:51.120] sched: Allocate JobId=51078 NodeList=cpu04 #CPUs=50 Partition=cpu-opteron
[2022-10-19T13:23:52.277] _job_complete: JobId=51078 WEXITSTATUS 0
[2022-10-19T13:23:52.278] _job_complete: JobId=51078 done
[2022-10-19T13:24:46.474] _slurm_rpc_submit_batch_job: JobId=51079 InitPrio=2459 usec=486
[2022-10-19T13:24:48.193] sched: Allocate JobId=51079 NodeList=cpu04 #CPUs=50 Partition=cpu-opteron
[2022-10-19T13:24:49.184] _job_complete: JobId=51079 WEXITSTATUS 0
[2022-10-19T13:24:49.184] _job_complete: JobId=51079 done
[2022-10-19T13:26:27.091] _slurm_rpc_submit_batch_job: JobId=51080 InitPrio=2459 usec=527
[2022-10-19T13:26:27.565] sched: Allocate JobId=51080 NodeList=cpu04 #CPUs=50 Partition=cpu-opteron
[2022-10-19T13:43:50.367] _job_complete: JobId=51059 WEXITSTATUS 0
[2022-10-19T13:43:50.368] _job_complete: JobId=51059 done
[2022-10-19T13:58:34.411] _slurm_rpc_submit_batch_job: JobId=51081 InitPrio=15122 usec=495
[2022-10-19T13:58:34.628] sched/backfill: _start_job: Started JobId=51081 in cpu-opteron on cpu04
[2022-10-19T13:59:03.450] _slurm_rpc_kill_job: REQUEST_KILL_JOB JobId=51081 uid 548300543
[2022-10-19T13:59:17.121] _slurm_rpc_submit_batch_job: JobId=51082 InitPrio=1024 usec=486
[2022-10-19T13:59:17.900] sched: Allocate JobId=51082 NodeList=cpu04 #CPUs=8 Partition=cpu-opteron
[2022-10-19T13:59:20.025] _job_complete: JobId=51082 WEXITSTATUS 127
[2022-10-19T13:59:20.026] _job_complete: JobId=51082 done
[2022-10-19T13:59:47.158] _slurm_rpc_submit_batch_job: JobId=51083 InitPrio=1024 usec=613
[2022-10-19T13:59:48.922] sched: Allocate JobId=51083 NodeList=cpu01 #CPUs=32 Partition=cpu-opteron
[2022-10-19T13:59:50.524] _job_complete: JobId=51083 WEXITSTATUS 1
[2022-10-19T13:59:50.524] _job_complete: JobId=51083 done
[2022-10-19T14:03:18.877] _slurm_rpc_submit_batch_job: JobId=51084 InitPrio=15122 usec=452
[2022-10-19T14:03:19.523] sched: Allocate JobId=51084 NodeList=cpu04 #CPUs=4 Partition=cpu-opteron
[2022-10-19T14:04:04.851] _slurm_rpc_kill_job: REQUEST_KILL_JOB JobId=51084 uid 548300543
[2022-10-19T14:08:45.845] _slurm_rpc_submit_batch_job: JobId=51085 InitPrio=15122 usec=865
[2022-10-19T14:08:48.096] sched: Allocate JobId=51085 NodeList=cpu04 #CPUs=4 Partition=cpu-opteron
[2022-10-19T14:48:33.437] _slurm_rpc_submit_batch_job: JobId=51086 InitPrio=2459 usec=488
[2022-10-19T14:48:34.203] sched: Allocate JobId=51086 NodeList=cpu01 #CPUs=50 Partition=cpu-opteron
[2022-10-19T15:05:57.525] _slurm_rpc_submit_batch_job: JobId=51087 InitPrio=22295 usec=5879
[2022-10-19T15:05:58.062] sched: Allocate JobId=51087 NodeList=cpu04 #CPUs=1 Partition=cpu-opteron
[2022-10-19T15:06:46.015] _job_complete: JobId=51087 WEXITSTATUS 1
[2022-10-19T15:06:46.015] _job_complete: JobId=51087 done
[2022-10-19T15:08:51.599] _slurm_rpc_kill_job: REQUEST_KILL_JOB JobId=51085 uid 548300543
[2022-10-19T15:10:57.086] _slurm_rpc_submit_batch_job: JobId=51088 InitPrio=21065 usec=459
[2022-10-19T15:10:57.554] sched: Allocate JobId=51088 NodeList=cpu01 #CPUs=1 Partition=cpu-opteron
[2022-10-19T15:11:17.732] _job_complete: JobId=51088 WEXITSTATUS 1
[2022-10-19T15:11:17.732] _job_complete: JobId=51088 done
[2022-10-19T15:13:17.938] _slurm_rpc_submit_batch_job: JobId=51089 InitPrio=21065 usec=559
[2022-10-19T15:13:18.870] sched: Allocate JobId=51089 NodeList=cpu01 #CPUs=1 Partition=cpu-opteron
[2022-10-19T15:13:37.327] _job_complete: JobId=51089 WEXITSTATUS 1
[2022-10-19T15:13:37.327] _job_complete: JobId=51089 done
[2022-10-19T15:17:29.335] _slurm_rpc_submit_batch_job: JobId=51090 InitPrio=21065 usec=447
[2022-10-19T15:17:30.317] sched: Allocate JobId=51090 NodeList=cpu01 #CPUs=1 Partition=cpu-opteron
[2022-10-19T15:17:49.435] _job_complete: JobId=51090 WEXITSTATUS 0
[2022-10-19T15:17:49.435] _job_complete: JobId=51090 done
[2022-10-19T15:22:24.253] _slurm_rpc_submit_batch_job: JobId=51091 InitPrio=21065 usec=535
[2022-10-19T15:22:25.157] sched: Allocate JobId=51091 NodeList=cpu01 #CPUs=1 Partition=cpu-opteron
[2022-10-19T15:22:49.358] _job_complete: JobId=51091 WEXITSTATUS 0
[2022-10-19T15:22:49.358] _job_complete: JobId=51091 done
[2022-10-19T15:27:36.110] _slurm_rpc_submit_batch_job: JobId=51092 InitPrio=5122 usec=389
[2022-10-19T15:27:36.660] sched: Allocate JobId=51092 NodeList=cpu01 #CPUs=1 Partition=cpu-opteron
[2022-10-19T15:27:38.718] _job_complete: JobId=51092 WEXITSTATUS 0
[2022-10-19T15:27:38.718] _job_complete: JobId=51092 done
[2022-10-19T15:31:12.580] _job_create: invalid account or partition for user 548300543, account 'yeehengteh', and partition 'cpu-opteron'
[2022-10-19T15:31:12.580] _slurm_rpc_submit_batch_job: Invalid account or account/partition combination specified
[2022-10-19T15:31:35.774] _slurm_rpc_submit_batch_job: JobId=51093 InitPrio=5122 usec=363
[2022-10-19T15:31:36.059] sched: Allocate JobId=51093 NodeList=cpu01 #CPUs=1 Partition=cpu-opteron
[2022-10-19T15:31:37.993] _job_complete: JobId=51093 WEXITSTATUS 0
[2022-10-19T15:31:37.993] _job_complete: JobId=51093 done
[2022-10-19T16:03:16.847] _slurm_rpc_submit_batch_job: JobId=51094 InitPrio=21065 usec=598
[2022-10-19T16:03:17.378] sched: Allocate JobId=51094 NodeList=cpu01 #CPUs=1 Partition=cpu-opteron
[2022-10-19T16:03:34.972] _job_complete: JobId=51094 WEXITSTATUS 1
[2022-10-19T16:03:34.972] _job_complete: JobId=51094 done
[2022-10-19T16:04:30.438] _slurm_rpc_submit_batch_job: JobId=51095 InitPrio=21065 usec=489
[2022-10-19T16:04:30.476] sched: Allocate JobId=51095 NodeList=cpu01 #CPUs=1 Partition=cpu-opteron
[2022-10-19T16:04:49.512] _job_complete: JobId=51095 WEXITSTATUS 0
[2022-10-19T16:04:49.512] _job_complete: JobId=51095 done
[2022-10-19T16:06:39.127] _slurm_rpc_submit_batch_job: JobId=51096 InitPrio=20860 usec=606
[2022-10-19T16:06:39.816] sched: Allocate JobId=51096 NodeList=cpu01 #CPUs=1 Partition=cpu-opteron
[2022-10-19T16:07:08.019] _job_complete: JobId=51096 WEXITSTATUS 0
[2022-10-19T16:07:08.019] _job_complete: JobId=51096 done
[2022-10-19T16:21:48.558] _slurm_rpc_submit_batch_job: JobId=51097 InitPrio=2254 usec=406
[2022-10-19T16:21:49.431] sched: Allocate JobId=51097 NodeList=cpu12 #CPUs=1 Partition=cpu-epyc
[2022-10-19T16:22:07.878] _slurm_rpc_kill_job: REQUEST_KILL_JOB JobId=51097 uid 548300595
[2022-10-19T16:23:19.183] _slurm_rpc_submit_batch_job: JobId=51098 InitPrio=2254 usec=412
[2022-10-19T16:23:19.531] sched: Allocate JobId=51098 NodeList=cpu01 #CPUs=1 Partition=cpu-opteron
[2022-10-19T16:46:00.877] _job_complete: JobId=51098 WEXITSTATUS 0
[2022-10-19T16:46:00.878] _job_complete: JobId=51098 done
[2022-10-19T16:55:13.056] _slurm_rpc_submit_batch_job: JobId=51099 InitPrio=2254 usec=651
[2022-10-19T16:55:13.802] sched: Allocate JobId=51099 NodeList=cpu01 #CPUs=1 Partition=cpu-opteron
[2022-10-19T17:41:23.826] _job_complete: JobId=51099 WEXITSTATUS 0
[2022-10-19T17:41:23.827] _job_complete: JobId=51099 done
[2022-10-19T17:45:54.649] _slurm_rpc_submit_batch_job: JobId=51100 InitPrio=2254 usec=471
[2022-10-19T17:45:54.840] sched: Allocate JobId=51100 NodeList=cpu01 #CPUs=1 Partition=cpu-opteron
[2022-10-19T17:47:54.607] _slurm_rpc_submit_batch_job: JobId=51101 InitPrio=3893 usec=535
[2022-10-19T17:47:55.117] sched: Allocate JobId=51101 NodeList=cpu07 #CPUs=32 Partition=cpu-opteron
[2022-10-19T17:58:35.889] _slurm_rpc_submit_batch_job: JobId=51102 InitPrio=3893 usec=492
[2022-10-19T17:58:36.225] sched: Allocate JobId=51102 NodeList=cpu07 #CPUs=32 Partition=cpu-opteron
[2022-10-19T17:58:54.938] _job_complete: JobId=51101 WEXITSTATUS 0
[2022-10-19T17:58:54.939] _job_complete: JobId=51101 done
[2022-10-19T18:26:13.422] _job_complete: JobId=51086 WEXITSTATUS 0
[2022-10-19T18:26:13.453] _job_complete: JobId=51086 done
[2022-10-19T18:40:06.103] _job_complete: JobId=51102 WEXITSTATUS 0
[2022-10-19T18:40:06.103] _job_complete: JobId=51102 done
[2022-10-19T18:43:20.480] _job_complete: JobId=51100 WEXITSTATUS 0
[2022-10-19T18:43:20.481] _job_complete: JobId=51100 done
[2022-10-20T01:40:02.531] _slurm_rpc_submit_batch_job: JobId=51103 InitPrio=1229 usec=561
[2022-10-20T01:40:02.998] sched: Allocate JobId=51103 NodeList=cpu01 #CPUs=64 Partition=cpu-opteron
[2022-10-20T01:40:06.053] _job_complete: JobId=51103 WEXITSTATUS 1
[2022-10-20T01:40:06.054] _job_complete: JobId=51103 done
[2022-10-20T01:47:23.122] _slurm_rpc_submit_batch_job: JobId=51104 InitPrio=1229 usec=544
[2022-10-20T01:47:23.853] sched: Allocate JobId=51104 NodeList=cpu01 #CPUs=64 Partition=cpu-opteron
[2022-10-20T02:07:41.326] _job_complete: JobId=51104 WEXITSTATUS 0
[2022-10-20T02:07:41.326] _job_complete: JobId=51104 done
[2022-10-20T02:08:22.946] _slurm_rpc_submit_batch_job: JobId=51105 InitPrio=1229 usec=502
[2022-10-20T02:08:23.141] sched: Allocate JobId=51105 NodeList=cpu01 #CPUs=64 Partition=cpu-opteron
[2022-10-20T02:08:25.718] _job_complete: JobId=51105 WEXITSTATUS 1
[2022-10-20T02:08:25.718] _job_complete: JobId=51105 done
[2022-10-20T02:09:07.982] _slurm_rpc_submit_batch_job: JobId=51106 InitPrio=1229 usec=549
[2022-10-20T02:09:08.192] sched: Allocate JobId=51106 NodeList=cpu01 #CPUs=64 Partition=cpu-opteron
[2022-10-20T02:40:59.196] _slurm_rpc_submit_batch_job: JobId=51107 InitPrio=1844 usec=940
[2022-10-20T02:41:46.829] _slurm_rpc_submit_batch_job: JobId=51108 InitPrio=1844 usec=941
[2022-10-20T02:44:25.537] _slurm_rpc_submit_batch_job: JobId=51109 InitPrio=1844 usec=443
[2022-10-20T02:44:26.394] sched: Allocate JobId=51109 NodeList=cpu07 #CPUs=16 Partition=cpu-opteron
[2022-10-20T02:51:24.283] _job_complete: JobId=51109 WEXITSTATUS 0
[2022-10-20T02:51:24.283] _job_complete: JobId=51109 done
[2022-10-20T02:53:12.024] _job_complete: JobId=50575 WEXITSTATUS 0
[2022-10-20T02:53:12.029] _job_complete: JobId=50575 done
[2022-10-20T02:53:16.253] sched: Allocate JobId=51006 NodeList=gpu05 #CPUs=32 Partition=gpu-v100s
[2022-10-20T05:10:03.739] _job_complete: JobId=51106 WEXITSTATUS 2
[2022-10-20T05:10:03.739] _job_complete: JobId=51106 done
[2022-10-20T06:40:51.809] _job_complete: JobId=51035 WEXITSTATUS 0
[2022-10-20T06:40:51.809] _job_complete: JobId=51035 done
[2022-10-20T07:41:47.703] _job_complete: JobId=51006 WEXITSTATUS 1
[2022-10-20T07:41:47.708] _job_complete: JobId=51006 done
[2022-10-20T07:41:56.149] sched: Allocate JobId=51053 NodeList=gpu05 #CPUs=16 Partition=gpu-v100s
[2022-10-20T10:23:42.234] _job_complete: JobId=51053 WEXITSTATUS 0
[2022-10-20T10:23:42.239] _job_complete: JobId=51053 done
[2022-10-20T10:23:49.259] sched: Allocate JobId=51007 NodeList=gpu05 #CPUs=32 Partition=gpu-v100s
[2022-10-20T13:22:57.148] Time limit exhausted for JobId=50533
[2022-10-20T13:26:27.516] Time limit exhausted for JobId=51080
[2022-10-20T13:46:02.394] _job_complete: JobId=51007 WEXITSTATUS 1
[2022-10-20T13:46:02.400] _job_complete: JobId=51007 done
[2022-10-20T13:46:08.513] sched: Allocate JobId=50861 NodeList=gpu05 #CPUs=8 Partition=gpu-v100s
[2022-10-20T13:46:08.514] sched: Allocate JobId=50862 NodeList=gpu05 #CPUs=8 Partition=gpu-v100s
[2022-10-20T13:46:08.850] _job_complete: JobId=50861 WEXITSTATUS 1
[2022-10-20T13:46:08.851] _job_complete: JobId=50861 done
[2022-10-20T13:46:09.573] sched: Allocate JobId=50914 NodeList=gpu05 #CPUs=12 Partition=gpu-v100s
[2022-10-20T14:54:10.439] _slurm_rpc_submit_batch_job: JobId=51110 InitPrio=3278 usec=488
[2022-10-20T14:54:18.398] _slurm_rpc_submit_batch_job: JobId=51111 InitPrio=3278 usec=428
[2022-10-20T15:00:59.004] _slurm_rpc_submit_batch_job: JobId=51112 InitPrio=2049 usec=393
[2022-10-20T15:00:59.451] sched: Allocate JobId=51112 NodeList=cpu14 #CPUs=48 Partition=cpu-epyc
[2022-10-20T20:05:30.345] _job_complete: JobId=50922 WEXITSTATUS 0
[2022-10-20T20:05:30.345] _job_complete: JobId=50922 done
[2022-10-20T20:05:31.402] sched: Allocate JobId=51062 NodeList=gpu02 #CPUs=4 Partition=gpu-titan
[2022-10-20T20:07:22.480] _job_complete: JobId=51062 WEXITSTATUS 0
[2022-10-20T20:07:22.480] _job_complete: JobId=51062 done
[2022-10-20T20:07:23.005] sched: Allocate JobId=51064 NodeList=gpu02 #CPUs=4 Partition=gpu-titan
[2022-10-20T21:40:01.244] _slurm_rpc_submit_batch_job: JobId=51113 InitPrio=409 usec=617
[2022-10-20T21:40:01.771] sched: Allocate JobId=51113 NodeList=gpu01 #CPUs=16 Partition=gpu-k10
[2022-10-20T21:40:26.891] _slurm_rpc_submit_batch_job: JobId=51114 InitPrio=5942 usec=433
[2022-10-20T21:40:27.810] sched: Allocate JobId=51114 NodeList=cpu01 #CPUs=1 Partition=cpu-opteron
[2022-10-20T21:40:29.653] _slurm_rpc_submit_batch_job: JobId=51115 InitPrio=5942 usec=467
[2022-10-20T21:40:30.796] sched: Allocate JobId=51115 NodeList=cpu01 #CPUs=1 Partition=cpu-opteron
[2022-10-20T21:48:28.243] _job_complete: JobId=51115 WEXITSTATUS 0
[2022-10-20T21:48:28.244] _job_complete: JobId=51115 done
[2022-10-20T21:59:09.215] _job_complete: JobId=51114 WEXITSTATUS 0
[2022-10-20T21:59:09.216] _job_complete: JobId=51114 done
[2022-10-20T21:59:11.492] _slurm_rpc_submit_batch_job: JobId=51116 InitPrio=5942 usec=650
[2022-10-20T21:59:11.986] sched: Allocate JobId=51116 NodeList=cpu01 #CPUs=1 Partition=cpu-opteron
[2022-10-20T22:17:28.182] _job_complete: JobId=51116 WEXITSTATUS 0
[2022-10-20T22:17:28.184] _job_complete: JobId=51116 done
[2022-10-20T22:21:46.851] _slurm_rpc_submit_batch_job: JobId=51117 InitPrio=5942 usec=418
[2022-10-20T22:21:49.194] _slurm_rpc_submit_batch_job: JobId=51118 InitPrio=5942 usec=410
[2022-10-20T22:21:49.485] sched: Allocate JobId=51117 NodeList=cpu01 #CPUs=1 Partition=cpu-opteron
[2022-10-20T22:21:49.486] sched: Allocate JobId=51118 NodeList=cpu01 #CPUs=1 Partition=cpu-opteron
[2022-10-20T22:28:36.947] _slurm_rpc_submit_batch_job: JobId=51119 InitPrio=1229 usec=579
[2022-10-20T22:28:37.170] sched: Allocate JobId=51119 NodeList=cpu11 #CPUs=64 Partition=cpu-opteron
[2022-10-20T22:29:33.129] _job_complete: JobId=51118 WEXITSTATUS 0
[2022-10-20T22:29:33.130] _job_complete: JobId=51118 done
[2022-10-20T22:35:16.397] _job_complete: JobId=51052 WEXITSTATUS 0
[2022-10-20T22:35:16.397] _job_complete: JobId=51052 done
[2022-10-20T22:41:09.377] _job_complete: JobId=51117 WEXITSTATUS 0
[2022-10-20T22:41:09.378] _job_complete: JobId=51117 done
[2022-10-20T23:23:41.409] _job_complete: JobId=51119 WEXITSTATUS 2
[2022-10-20T23:23:41.409] _job_complete: JobId=51119 done
[2022-10-21T02:13:55.327] _slurm_rpc_submit_batch_job: JobId=51120 InitPrio=409 usec=599
[2022-10-21T02:13:56.230] sched: Allocate JobId=51120 NodeList=cpu15 #CPUs=48 Partition=cpu-epyc
[2022-10-21T02:35:02.905] _slurm_rpc_submit_batch_job: JobId=51121 InitPrio=1229 usec=604
[2022-10-21T02:35:03.590] sched: Allocate JobId=51121 NodeList=cpu01 #CPUs=64 Partition=cpu-opteron
[2022-10-21T03:19:58.417] _job_complete: JobId=51121 WEXITSTATUS 2
[2022-10-21T03:19:58.417] _job_complete: JobId=51121 done
[2022-10-21T05:46:09.469] _job_complete: JobId=51113 WEXITSTATUS 0
[2022-10-21T05:46:09.469] _job_complete: JobId=51113 done
[2022-10-21T08:25:57.994] _slurm_rpc_submit_batch_job: JobId=51122 InitPrio=2663 usec=644
[2022-10-21T08:25:58.191] sched: Allocate JobId=51122 NodeList=cpu12 #CPUs=8 Partition=cpu-epyc
[2022-10-21T08:26:02.664] _slurm_rpc_submit_batch_job: JobId=51123 InitPrio=2663 usec=456
[2022-10-21T08:26:03.182] sched: Allocate JobId=51123 NodeList=cpu12 #CPUs=8 Partition=cpu-epyc
[2022-10-21T08:26:05.983] _slurm_rpc_submit_batch_job: JobId=51124 InitPrio=2663 usec=469
[2022-10-21T08:26:06.231] sched: Allocate JobId=51124 NodeList=cpu12 #CPUs=8 Partition=cpu-epyc
[2022-10-21T08:26:09.312] _slurm_rpc_submit_batch_job: JobId=51125 InitPrio=2663 usec=454
[2022-10-21T08:26:10.237] sched: Allocate JobId=51125 NodeList=cpu12 #CPUs=8 Partition=cpu-epyc
[2022-10-21T08:34:54.961] _slurm_rpc_submit_batch_job: JobId=51126 InitPrio=2663 usec=437
[2022-10-21T08:34:55.204] sched: Allocate JobId=51126 NodeList=cpu12 #CPUs=8 Partition=cpu-epyc
[2022-10-21T08:34:58.333] _slurm_rpc_submit_batch_job: JobId=51127 InitPrio=2663 usec=452
[2022-10-21T08:35:01.701] _slurm_rpc_submit_batch_job: JobId=51128 InitPrio=2663 usec=466
[2022-10-21T08:38:27.093] _job_complete: JobId=51122 WEXITSTATUS 0
[2022-10-21T08:38:27.093] _job_complete: JobId=51122 done
[2022-10-21T08:38:27.477] sched: Allocate JobId=51127 NodeList=cpu12 #CPUs=8 Partition=cpu-epyc
[2022-10-21T08:38:34.127] _job_complete: JobId=51125 WEXITSTATUS 0
[2022-10-21T08:38:34.127] _job_complete: JobId=51125 done
[2022-10-21T08:38:34.490] sched: Allocate JobId=51128 NodeList=cpu12 #CPUs=8 Partition=cpu-epyc
[2022-10-21T08:38:47.929] _job_complete: JobId=51124 WEXITSTATUS 0
[2022-10-21T08:38:47.929] _job_complete: JobId=51124 done
[2022-10-21T08:40:00.904] _job_complete: JobId=51123 WEXITSTATUS 0
[2022-10-21T08:40:00.905] _job_complete: JobId=51123 done
[2022-10-21T08:47:42.378] _job_complete: JobId=51126 WEXITSTATUS 0
[2022-10-21T08:47:42.378] _job_complete: JobId=51126 done
[2022-10-21T08:50:40.883] _job_complete: JobId=51127 WEXITSTATUS 0
[2022-10-21T08:50:40.883] _job_complete: JobId=51127 done
[2022-10-21T08:51:17.704] _job_complete: JobId=51128 WEXITSTATUS 0
[2022-10-21T08:51:17.704] _job_complete: JobId=51128 done
[2022-10-21T09:06:58.999] _job_complete: JobId=51064 WEXITSTATUS 0
[2022-10-21T09:06:58.999] _job_complete: JobId=51064 done
[2022-10-21T09:07:00.155] sched: Allocate JobId=51066 NodeList=gpu02 #CPUs=4 Partition=gpu-titan
[2022-10-21T09:30:35.133] _job_complete: JobId=51041 WEXITSTATUS 0
[2022-10-21T09:30:35.134] _job_complete: JobId=51041 done
[2022-10-21T09:33:02.140] _slurm_rpc_submit_batch_job: JobId=51129 InitPrio=2663 usec=579
[2022-10-21T09:33:02.815] sched: Allocate JobId=51129 NodeList=cpu01 #CPUs=8 Partition=cpu-opteron
[2022-10-21T09:33:06.856] _slurm_rpc_submit_batch_job: JobId=51130 InitPrio=2663 usec=455
[2022-10-21T09:33:07.822] sched: Allocate JobId=51130 NodeList=cpu01 #CPUs=8 Partition=cpu-opteron
[2022-10-21T09:33:09.290] _slurm_rpc_submit_batch_job: JobId=51131 InitPrio=2663 usec=474
[2022-10-21T09:33:10.826] sched: Allocate JobId=51131 NodeList=cpu01 #CPUs=8 Partition=cpu-opteron
[2022-10-21T09:33:11.697] _slurm_rpc_submit_batch_job: JobId=51132 InitPrio=2663 usec=448
[2022-10-21T09:33:13.830] sched: Allocate JobId=51132 NodeList=cpu01 #CPUs=8 Partition=cpu-opteron
[2022-10-21T09:33:14.129] _slurm_rpc_submit_batch_job: JobId=51133 InitPrio=2663 usec=475
[2022-10-21T09:33:16.673] _slurm_rpc_submit_batch_job: JobId=51134 InitPrio=2663 usec=505
[2022-10-21T09:33:16.834] sched: Allocate JobId=51133 NodeList=cpu01 #CPUs=8 Partition=cpu-opteron
[2022-10-21T09:33:16.835] sched: Allocate JobId=51134 NodeList=cpu01 #CPUs=8 Partition=cpu-opteron
[2022-10-21T09:33:19.286] _slurm_rpc_submit_batch_job: JobId=51135 InitPrio=2663 usec=466
[2022-10-21T09:33:19.839] sched: Allocate JobId=51135 NodeList=cpu01 #CPUs=8 Partition=cpu-opteron
[2022-10-21T11:23:50.532] _slurm_rpc_submit_batch_job: JobId=51136 InitPrio=409 usec=502
[2022-10-21T11:23:50.991] sched: Allocate JobId=51136 NodeList=gpu01 #CPUs=16 Partition=gpu-k10
[2022-10-21T11:23:54.912] _job_complete: JobId=51136 WEXITSTATUS 1
[2022-10-21T11:23:54.912] _job_complete: JobId=51136 done
[2022-10-21T11:24:25.028] _slurm_rpc_submit_batch_job: JobId=51137 InitPrio=409 usec=436
[2022-10-21T11:24:26.026] sched: Allocate JobId=51137 NodeList=gpu01 #CPUs=16 Partition=gpu-k10
[2022-10-21T11:28:26.295] _slurm_rpc_submit_batch_job: JobId=51138 InitPrio=409 usec=545
[2022-10-21T11:30:34.328] _slurm_rpc_submit_batch_job: JobId=51139 InitPrio=409 usec=451
[2022-10-21T11:36:31.471] _job_complete: JobId=51137 WEXITSTATUS 0
[2022-10-21T11:36:31.471] _job_complete: JobId=51137 done
[2022-10-21T11:36:32.883] sched: Allocate JobId=51138 NodeList=gpu01 #CPUs=16 Partition=gpu-k10
[2022-10-21T11:47:53.152] _job_complete: JobId=51138 WEXITSTATUS 0
[2022-10-21T11:47:53.152] _job_complete: JobId=51138 done
[2022-10-21T11:47:54.568] sched: Allocate JobId=51139 NodeList=gpu01 #CPUs=16 Partition=gpu-k10
[2022-10-21T11:56:20.142] _job_complete: JobId=51139 WEXITSTATUS 0
[2022-10-21T11:56:20.142] _job_complete: JobId=51139 done
[2022-10-21T12:30:28.641] _job_complete: JobId=51135 WEXITSTATUS 0
[2022-10-21T12:30:28.641] _job_complete: JobId=51135 done
[2022-10-21T12:31:09.900] _job_complete: JobId=51132 WEXITSTATUS 0
[2022-10-21T12:31:09.901] _job_complete: JobId=51132 done
[2022-10-21T12:31:39.550] _job_complete: JobId=51130 WEXITSTATUS 0
[2022-10-21T12:31:39.550] _job_complete: JobId=51130 done
[2022-10-21T12:48:26.111] _job_complete: JobId=51133 WEXITSTATUS 0
[2022-10-21T12:48:26.111] _job_complete: JobId=51133 done
[2022-10-21T12:48:27.226] _job_complete: JobId=51131 WEXITSTATUS 0
[2022-10-21T12:48:27.226] _job_complete: JobId=51131 done
[2022-10-21T12:50:43.313] _job_complete: JobId=51129 WEXITSTATUS 0
[2022-10-21T12:50:43.313] _job_complete: JobId=51129 done
[2022-10-21T13:52:52.697] _slurm_rpc_submit_batch_job: JobId=51140 InitPrio=2459 usec=485
[2022-10-21T13:52:52.887] sched: Allocate JobId=51140 NodeList=cpu04 #CPUs=50 Partition=cpu-opteron
[2022-10-21T13:52:59.814] _job_complete: JobId=51140 WEXITSTATUS 0
[2022-10-21T13:52:59.814] _job_complete: JobId=51140 done
[2022-10-21T13:53:59.442] _slurm_rpc_kill_job: REQUEST_KILL_JOB JobId=51140 uid 548300593
[2022-10-21T13:54:25.221] _slurm_rpc_submit_batch_job: JobId=51141 InitPrio=2459 usec=444
[2022-10-21T13:54:25.983] sched: Allocate JobId=51141 NodeList=cpu04 #CPUs=50 Partition=cpu-opteron
[2022-10-21T13:58:30.126] _slurm_rpc_submit_batch_job: JobId=51142 InitPrio=3483 usec=567
[2022-10-21T13:58:30.575] sched: Allocate JobId=51142 NodeList=cpu01 #CPUs=32 Partition=cpu-opteron
[2022-10-21T13:59:30.264] _slurm_rpc_submit_batch_job: JobId=51143 InitPrio=2459 usec=394
[2022-10-21T13:59:30.645] sched: Allocate JobId=51143 NodeList=cpu05 #CPUs=50 Partition=cpu-opteron
[2022-10-21T14:02:57.197] _job_complete: JobId=51142 WEXITSTATUS 0
[2022-10-21T14:02:57.197] _job_complete: JobId=51142 done
[2022-10-21T14:06:41.937] _slurm_rpc_submit_batch_job: JobId=51144 InitPrio=3483 usec=642
[2022-10-21T14:06:42.497] sched: Allocate JobId=51144 NodeList=cpu01 #CPUs=2 Partition=cpu-opteron
[2022-10-21T14:06:44.428] _job_complete: JobId=51144 WEXITSTATUS 0
[2022-10-21T14:06:44.428] _job_complete: JobId=51144 done
[2022-10-21T14:16:49.307] _slurm_rpc_kill_job: REQUEST_KILL_JOB JobId=51141 uid 548300593
[2022-10-21T14:18:29.015] _slurm_rpc_submit_batch_job: JobId=51145 InitPrio=2459 usec=400
[2022-10-21T14:18:29.880] sched: Allocate JobId=51145 NodeList=cpu04 #CPUs=50 Partition=cpu-opteron
[2022-10-21T14:19:49.176] _slurm_rpc_submit_batch_job: JobId=51146 InitPrio=3483 usec=454
[2022-10-21T14:19:50.993] sched: Allocate JobId=51146 NodeList=cpu01 #CPUs=32 Partition=cpu-opteron
[2022-10-21T14:20:57.021] _job_complete: JobId=51146 WEXITSTATUS 0
[2022-10-21T14:20:57.021] _job_complete: JobId=51146 done
[2022-10-21T14:35:54.593] _slurm_rpc_submit_batch_job: JobId=51147 InitPrio=3483 usec=593
[2022-10-21T14:35:54.625] sched: Allocate JobId=51147 NodeList=cpu01 #CPUs=32 Partition=cpu-opteron
[2022-10-21T14:36:01.936] _job_complete: JobId=51147 WEXITSTATUS 1
[2022-10-21T14:36:01.936] _job_complete: JobId=51147 done
[2022-10-21T14:36:34.009] _slurm_rpc_kill_job: REQUEST_KILL_JOB JobId=51147 uid 548300584
[2022-10-21T14:36:56.812] _slurm_rpc_submit_batch_job: JobId=51148 InitPrio=3483 usec=482
[2022-10-21T14:36:57.783] sched: Allocate JobId=51148 NodeList=cpu01 #CPUs=32 Partition=cpu-opteron
[2022-10-21T14:37:01.686] _job_complete: JobId=51148 WEXITSTATUS 1
[2022-10-21T14:37:01.686] _job_complete: JobId=51148 done
[2022-10-21T14:44:16.775] _slurm_rpc_submit_batch_job: JobId=51149 InitPrio=3483 usec=450
[2022-10-21T14:44:17.466] sched: Allocate JobId=51149 NodeList=cpu07 #CPUs=64 Partition=cpu-opteron
[2022-10-21T14:44:29.921] _job_complete: JobId=51149 WEXITSTATUS 1
[2022-10-21T14:44:29.921] _job_complete: JobId=51149 done
[2022-10-21T14:46:56.722] _slurm_rpc_submit_batch_job: JobId=51150 InitPrio=3483 usec=448
[2022-10-21T14:46:56.837] sched: Allocate JobId=51150 NodeList=cpu01 #CPUs=32 Partition=cpu-opteron
[2022-10-21T14:47:11.862] _job_complete: JobId=51150 WEXITSTATUS 0
[2022-10-21T14:47:11.862] _job_complete: JobId=51150 done
[2022-10-21T14:47:48.921] _slurm_rpc_submit_batch_job: JobId=51151 InitPrio=3483 usec=437
[2022-10-21T14:47:50.909] sched: Allocate JobId=51151 NodeList=cpu07 #CPUs=64 Partition=cpu-opteron
[2022-10-21T14:48:17.689] _job_complete: JobId=51134 WEXITSTATUS 0
[2022-10-21T14:48:17.689] _job_complete: JobId=51134 done
[2022-10-21T14:51:56.860] _job_complete: JobId=51151 WEXITSTATUS 0
[2022-10-21T14:51:56.860] _job_complete: JobId=51151 done
[2022-10-21T15:35:59.530] _slurm_rpc_submit_batch_job: JobId=51152 InitPrio=5737 usec=509
[2022-10-21T15:36:00.065] sched: Allocate JobId=51152 NodeList=cpu01 #CPUs=1 Partition=cpu-opteron
[2022-10-21T15:36:22.204] _slurm_rpc_kill_job: REQUEST_KILL_JOB JobId=51152 uid 548300543
[2022-10-21T15:36:28.224] _slurm_rpc_submit_batch_job: JobId=51153 InitPrio=5737 usec=343
[2022-10-21T15:36:29.224] sched: Allocate JobId=51153 NodeList=cpu01 #CPUs=1 Partition=cpu-opteron
[2022-10-21T15:38:40.767] _slurm_rpc_kill_job: REQUEST_KILL_JOB JobId=51153 uid 548300543
[2022-10-21T15:39:03.896] _slurm_rpc_submit_batch_job: JobId=51154 InitPrio=5737 usec=389
[2022-10-21T15:39:04.437] sched: Allocate JobId=51154 NodeList=cpu01 #CPUs=1 Partition=cpu-opteron
[2022-10-21T15:39:27.701] _slurm_rpc_kill_job: REQUEST_KILL_JOB JobId=51154 uid 548300543
[2022-10-21T15:42:24.951] _slurm_rpc_submit_batch_job: JobId=51155 InitPrio=15737 usec=415
[2022-10-21T15:42:33.613] _slurm_rpc_kill_job: REQUEST_KILL_JOB JobId=51155 uid 548300543
[2022-10-21T15:42:41.051] _slurm_rpc_submit_batch_job: JobId=51156 InitPrio=15737 usec=390
[2022-10-21T15:42:41.821] sched: Allocate JobId=51156 NodeList=gpu01 #CPUs=2 Partition=gpu-k10
[2022-10-21T15:43:05.922] _slurm_rpc_kill_job: REQUEST_KILL_JOB JobId=51156 uid 548300543
[2022-10-21T15:47:19.761] _slurm_rpc_submit_batch_job: JobId=51157 InitPrio=15737 usec=370
[2022-10-21T15:47:20.312] sched: Allocate JobId=51157 NodeList=cpu12 #CPUs=8 Partition=cpu-epyc
[2022-10-21T15:47:46.066] _slurm_rpc_kill_job: REQUEST_KILL_JOB JobId=51157 uid 548300543
[2022-10-21T16:05:06.891] _slurm_rpc_submit_batch_job: JobId=51158 InitPrio=15737 usec=450
[2022-10-21T16:05:07.510] sched: Allocate JobId=51158 NodeList=gpu01 #CPUs=2 Partition=gpu-k10
[2022-10-21T16:09:38.255] _job_complete: JobId=50954 WEXITSTATUS 0
[2022-10-21T16:09:38.255] _job_complete: JobId=50954 done
[2022-10-21T16:09:40.399] sched: Allocate JobId=51068 NodeList=gpu02 #CPUs=4 Partition=gpu-titan
[2022-10-21T16:18:42.566] _slurm_rpc_submit_batch_job: JobId=51159 InitPrio=2663 usec=492
[2022-10-21T16:18:42.619] sched: Allocate JobId=51159 NodeList=cpu12 #CPUs=8 Partition=cpu-epyc
[2022-10-21T16:30:49.809] _job_complete: JobId=51159 WEXITSTATUS 0
[2022-10-21T16:30:49.809] _job_complete: JobId=51159 done
[2022-10-21T17:05:31.674] Time limit exhausted for JobId=51158
[2022-10-21T17:11:21.388] _slurm_rpc_submit_batch_job: JobId=51160 InitPrio=1229 usec=616
[2022-10-21T17:11:21.423] sched: Allocate JobId=51160 NodeList=cpu01 #CPUs=64 Partition=cpu-opteron
[2022-10-21T18:01:55.171] _job_complete: JobId=51160 WEXITSTATUS 2
[2022-10-21T18:01:55.171] _job_complete: JobId=51160 done
[2022-10-21T18:08:16.728] _job_complete: JobId=51038 WEXITSTATUS 0
[2022-10-21T18:08:16.728] _job_complete: JobId=51038 done
[2022-10-21T18:49:04.447] _job_complete: JobId=50862 WEXITSTATUS 0
[2022-10-21T18:49:04.453] _job_complete: JobId=50862 done
[2022-10-21T21:19:26.259] sched: _slurm_rpc_allocate_resources JobId=51161 NodeList=cpu01 usec=45235
[2022-10-21T21:40:04.741] sched: _slurm_rpc_allocate_resources JobId=51162 NodeList=(null) usec=1105
[2022-10-21T21:40:05.747] sched: Allocate JobId=51162 NodeList=cpu01 #CPUs=1 Partition=cpu-opteron
[2022-10-21T21:47:43.983] _slurm_rpc_submit_batch_job: JobId=51163 InitPrio=409 usec=508
[2022-10-21T21:47:44.595] sched: Allocate JobId=51163 NodeList=cpu13 #CPUs=48 Partition=cpu-epyc
[2022-10-21T21:53:35.252] _job_complete: JobId=51163 WEXITSTATUS 1
[2022-10-21T21:53:35.252] _job_complete: JobId=51163 done
[2022-10-21T21:56:42.402] _slurm_rpc_submit_batch_job: JobId=51164 InitPrio=409 usec=486
[2022-10-21T21:56:42.542] sched: Allocate JobId=51164 NodeList=cpu13 #CPUs=48 Partition=cpu-epyc
[2022-10-21T22:17:40.960] job_step_signal: JobId=51161 StepId=0 not found
[2022-10-21T22:17:40.962] _job_complete: JobId=51161 WTERMSIG 126
[2022-10-21T22:17:40.962] _job_complete: JobId=51161 cancelled by interactive user
[2022-10-21T22:17:40.962] _job_complete: JobId=51161 done
[2022-10-21T22:19:09.920] _slurm_rpc_submit_batch_job: JobId=51165 InitPrio=9221 usec=554
[2022-10-21T22:19:10.912] sched: Allocate JobId=51165 NodeList=cpu12 #CPUs=4 Partition=cpu-epyc
[2022-10-21T22:19:12.803] _job_complete: JobId=51165 WEXITSTATUS 127
[2022-10-21T22:19:12.803] _job_complete: JobId=51165 done
[2022-10-21T22:19:53.634] _job_complete: JobId=51162 WEXITSTATUS 0
[2022-10-21T22:19:53.635] _job_complete: JobId=51162 done
[2022-10-21T22:21:27.478] _slurm_rpc_submit_batch_job: JobId=51166 InitPrio=9221 usec=444
[2022-10-21T22:21:28.207] sched: Allocate JobId=51166 NodeList=cpu12 #CPUs=4 Partition=cpu-epyc
[2022-10-21T22:26:50.663] _job_complete: JobId=51143 WEXITSTATUS 0
[2022-10-21T22:26:50.668] _job_complete: JobId=51143 done
[2022-10-21T22:40:34.641] _slurm_rpc_kill_job: REQUEST_KILL_JOB JobId=51166 uid 548200011
[2022-10-21T22:41:02.650] _slurm_rpc_submit_batch_job: JobId=51167 InitPrio=9221 usec=559
[2022-10-21T22:41:03.109] sched: Allocate JobId=51167 NodeList=cpu12 #CPUs=4 Partition=cpu-epyc
[2022-10-21T22:41:45.193] _slurm_rpc_kill_job: REQUEST_KILL_JOB JobId=51166 uid 548200011
[2022-10-21T22:41:48.056] _slurm_rpc_kill_job: REQUEST_KILL_JOB JobId=51167 uid 548200011
[2022-10-21T22:42:06.570] _slurm_rpc_submit_batch_job: JobId=51168 InitPrio=9221 usec=505
[2022-10-21T22:42:07.531] sched: Allocate JobId=51168 NodeList=cpu12 #CPUs=4 Partition=cpu-epyc
[2022-10-21T22:43:16.431] _slurm_rpc_kill_job: REQUEST_KILL_JOB JobId=51168 uid 548200011
[2022-10-21T22:43:41.122] _slurm_rpc_submit_batch_job: JobId=51169 InitPrio=9221 usec=455
[2022-10-21T22:43:41.659] sched: Allocate JobId=51169 NodeList=cpu12 #CPUs=4 Partition=cpu-epyc
[2022-10-21T22:44:53.282] _slurm_rpc_kill_job: REQUEST_KILL_JOB JobId=51169 uid 548200011
[2022-10-21T22:45:14.798] _slurm_rpc_submit_batch_job: JobId=51170 InitPrio=9221 usec=449
[2022-10-21T22:45:15.785] sched: Allocate JobId=51170 NodeList=cpu12 #CPUs=4 Partition=cpu-epyc
[2022-10-21T23:53:32.162] _job_complete: JobId=51170 WEXITSTATUS 0
[2022-10-21T23:53:32.162] _job_complete: JobId=51170 done
[2022-10-22T01:14:21.047] _slurm_rpc_kill_job: REQUEST_KILL_JOB JobId=51033 uid 548300621
[2022-10-22T01:14:23.342] _slurm_rpc_kill_job: REQUEST_KILL_JOB JobId=51033 uid 548300621
[2022-10-22T01:14:29.811] _slurm_rpc_submit_batch_job: JobId=51171 InitPrio=204 usec=601
[2022-10-22T01:14:30.003] sched: Allocate JobId=51171 NodeList=cpu09 #CPUs=64 Partition=cpu-opteron
[2022-10-22T01:20:38.470] _slurm_rpc_kill_job: REQUEST_KILL_JOB JobId=51039 uid 548300621
[2022-10-22T01:20:39.285] _slurm_rpc_kill_job: REQUEST_KILL_JOB JobId=51039 uid 548300621
[2022-10-22T01:20:51.290] _slurm_rpc_kill_job: REQUEST_KILL_JOB JobId=51037 uid 548300621
[2022-10-22T01:20:52.455] _slurm_rpc_kill_job: REQUEST_KILL_JOB JobId=51037 uid 548300621
[2022-10-22T01:21:21.042] _slurm_rpc_submit_batch_job: JobId=51172 InitPrio=204 usec=582
[2022-10-22T01:21:21.765] sched: Allocate JobId=51172 NodeList=cpu10 #CPUs=64 Partition=cpu-opteron
[2022-10-22T01:22:09.571] _slurm_rpc_submit_batch_job: JobId=51173 InitPrio=204 usec=497
[2022-10-22T01:22:09.830] sched: Allocate JobId=51173 NodeList=cpu01 #CPUs=64 Partition=cpu-opteron
[2022-10-22T01:23:57.936] _slurm_rpc_kill_job: REQUEST_KILL_JOB JobId=51171 uid 548300621
[2022-10-22T01:23:58.686] _slurm_rpc_kill_job: REQUEST_KILL_JOB JobId=51171 uid 548300621
[2022-10-22T01:24:27.651] _slurm_rpc_submit_batch_job: JobId=51174 InitPrio=204 usec=430
[2022-10-22T01:24:28.014] sched: Allocate JobId=51174 NodeList=cpu03 #CPUs=64 Partition=cpu-opteron
[2022-10-22T01:24:49.881] _slurm_rpc_submit_batch_job: JobId=51175 InitPrio=204 usec=432
[2022-10-22T01:24:50.043] sched: Allocate JobId=51175 NodeList=cpu05 #CPUs=64 Partition=cpu-opteron
[2022-10-22T01:26:35.251] _slurm_rpc_kill_job: REQUEST_KILL_JOB JobId=51172 uid 548300621
[2022-10-22T01:26:37.625] _slurm_rpc_kill_job: REQUEST_KILL_JOB JobId=51173 uid 548300621
[2022-10-22T01:26:39.898] _slurm_rpc_kill_job: REQUEST_KILL_JOB JobId=51174 uid 548300621
[2022-10-22T01:26:45.201] _slurm_rpc_kill_job: REQUEST_KILL_JOB JobId=51175 uid 548300621
[2022-10-22T01:26:54.405] _slurm_rpc_submit_batch_job: JobId=51176 InitPrio=204 usec=484
[2022-10-22T01:26:55.290] sched: Allocate JobId=51176 NodeList=cpu01 #CPUs=64 Partition=cpu-opteron
[2022-10-22T01:26:58.121] _slurm_rpc_submit_batch_job: JobId=51177 InitPrio=204 usec=501
[2022-10-22T01:26:58.294] sched: Allocate JobId=51177 NodeList=cpu03 #CPUs=64 Partition=cpu-opteron
[2022-10-22T01:27:02.051] _slurm_rpc_submit_batch_job: JobId=51178 InitPrio=204 usec=397
[2022-10-22T01:27:02.299] sched: Allocate JobId=51178 NodeList=cpu05 #CPUs=64 Partition=cpu-opteron
[2022-10-22T01:27:05.589] _slurm_rpc_submit_batch_job: JobId=51179 InitPrio=204 usec=398
[2022-10-22T01:27:06.305] sched: Allocate JobId=51179 NodeList=cpu07 #CPUs=64 Partition=cpu-opteron
[2022-10-22T03:37:08.523] _job_complete: JobId=51066 WEXITSTATUS 0
[2022-10-22T03:37:08.523] _job_complete: JobId=51066 done
[2022-10-22T03:37:09.672] sched: Allocate JobId=51070 NodeList=gpu02 #CPUs=4 Partition=gpu-titan
[2022-10-22T08:24:36.673] _job_complete: JobId=50952 WEXITSTATUS 0
[2022-10-22T08:24:36.679] _job_complete: JobId=50952 done
[2022-10-22T10:11:52.478] _slurm_rpc_submit_batch_job: JobId=51180 InitPrio=18196 usec=592
[2022-10-22T10:11:53.221] sched: Allocate JobId=51180 NodeList=cpu12 #CPUs=4 Partition=cpu-epyc
[2022-10-22T10:12:08.328] _job_complete: JobId=51180 WEXITSTATUS 0
[2022-10-22T10:12:08.328] _job_complete: JobId=51180 done
[2022-10-22T10:13:03.873] _slurm_rpc_submit_batch_job: JobId=51181 InitPrio=18196 usec=479
[2022-10-22T10:13:04.306] sched: Allocate JobId=51181 NodeList=cpu12 #CPUs=4 Partition=cpu-epyc
[2022-10-22T10:13:17.588] _job_complete: JobId=51181 WEXITSTATUS 0
[2022-10-22T10:13:17.588] _job_complete: JobId=51181 done
[2022-10-22T10:13:59.483] _slurm_rpc_submit_batch_job: JobId=51182 InitPrio=18196 usec=440
[2022-10-22T10:14:00.382] sched: Allocate JobId=51182 NodeList=cpu12 #CPUs=4 Partition=cpu-epyc
[2022-10-22T10:14:12.573] _job_complete: JobId=51182 WEXITSTATUS 0
[2022-10-22T10:14:12.574] _job_complete: JobId=51182 done
[2022-10-22T10:16:41.375] _slurm_rpc_submit_batch_job: JobId=51183 InitPrio=18196 usec=519
[2022-10-22T10:16:41.710] sched: Allocate JobId=51183 NodeList=cpu12 #CPUs=4 Partition=cpu-epyc
[2022-10-22T10:16:51.957] _job_complete: JobId=51183 WEXITSTATUS 0
[2022-10-22T10:16:51.957] _job_complete: JobId=51183 done
[2022-10-22T12:30:40.549] sched: _slurm_rpc_allocate_resources JobId=51184 NodeList=cpu04 usec=15247
[2022-10-22T13:03:52.386] _job_complete: JobId=51184 WTERMSIG 126
[2022-10-22T13:03:52.386] _job_complete: JobId=51184 cancelled by interactive user
[2022-10-22T13:03:52.387] _job_complete: JobId=51184 done
[2022-10-22T13:14:08.381] _job_complete: JobId=51068 WEXITSTATUS 0
[2022-10-22T13:14:08.381] _job_complete: JobId=51068 done
[2022-10-22T13:14:09.519] sched: Allocate JobId=51072 NodeList=gpu02 #CPUs=4 Partition=gpu-titan
[2022-10-22T13:21:48.289] _get_job_parts: invalid partition specified: cpu-standard
[2022-10-22T13:21:48.289] _slurm_rpc_submit_batch_job: Invalid partition name specified
[2022-10-22T13:22:14.317] _slurm_rpc_submit_batch_job: JobId=51185 InitPrio=17991 usec=537
[2022-10-22T13:22:14.903] sched: Allocate JobId=51185 NodeList=cpu12 #CPUs=4 Partition=cpu-epyc
[2022-10-22T13:23:01.281] _job_complete: JobId=51185 WEXITSTATUS 0
[2022-10-22T13:23:01.281] _job_complete: JobId=51185 done
[2022-10-22T14:16:26.914] _slurm_rpc_submit_batch_job: JobId=51186 InitPrio=7991 usec=622
[2022-10-22T14:16:27.714] sched: Allocate JobId=51186 NodeList=cpu12 #CPUs=4 Partition=cpu-epyc
[2022-10-22T15:24:30.030] _job_complete: JobId=51186 WEXITSTATUS 0
[2022-10-22T15:24:30.031] _job_complete: JobId=51186 done
[2022-10-22T15:43:46.870] _slurm_rpc_submit_batch_job: JobId=51187 InitPrio=17786 usec=629
[2022-10-22T15:43:47.675] sched: Allocate JobId=51187 NodeList=cpu12 #CPUs=4 Partition=cpu-epyc
[2022-10-22T15:44:00.927] _job_complete: JobId=51187 WEXITSTATUS 0
[2022-10-22T15:44:00.927] _job_complete: JobId=51187 done
[2022-10-22T15:44:55.983] _slurm_rpc_submit_batch_job: JobId=51188 InitPrio=17786 usec=504
[2022-10-22T15:44:56.766] sched: Allocate JobId=51188 NodeList=cpu12 #CPUs=4 Partition=cpu-epyc
[2022-10-22T15:45:00.666] _job_complete: JobId=51188 WEXITSTATUS 2
[2022-10-22T15:45:00.666] _job_complete: JobId=51188 done
[2022-10-22T15:46:01.578] _slurm_rpc_submit_batch_job: JobId=51189 InitPrio=17786 usec=449
[2022-10-22T15:46:01.853] sched: Allocate JobId=51189 NodeList=cpu12 #CPUs=4 Partition=cpu-epyc
[2022-10-22T15:46:05.345] _job_complete: JobId=51189 WEXITSTATUS 0
[2022-10-22T15:46:05.345] _job_complete: JobId=51189 done
[2022-10-22T21:49:15.121] _slurm_rpc_submit_batch_job: JobId=51190 InitPrio=1639 usec=525
[2022-10-23T01:05:14.288] _build_node_list: No nodes satisfy JobId=51191 requirements in partition cpu-opteron
[2022-10-23T01:05:14.288] _slurm_rpc_submit_batch_job: Requested node configuration is not available
[2022-10-23T01:05:29.578] _slurm_rpc_submit_batch_job: JobId=51192 InitPrio=2459 usec=516
[2022-10-23T01:05:29.865] sched: Allocate JobId=51192 NodeList=cpu08 #CPUs=1 Partition=cpu-opteron
[2022-10-23T01:05:52.463] _slurm_rpc_submit_batch_job: JobId=51193 InitPrio=2459 usec=452
[2022-10-23T01:05:52.881] sched: Allocate JobId=51193 NodeList=cpu09 #CPUs=1 Partition=cpu-opteron
[2022-10-23T01:13:22.413] _slurm_rpc_kill_job: REQUEST_KILL_JOB JobId=51192 uid 548300593
[2022-10-23T10:00:37.195] _job_complete: JobId=51072 WEXITSTATUS 0
[2022-10-23T10:00:37.195] _job_complete: JobId=51072 done
[2022-10-23T10:00:38.375] sched: Allocate JobId=51107 NodeList=gpu02 #CPUs=8 Partition=gpu-titan
[2022-10-23T10:05:42.354] _job_complete: JobId=51107 WEXITSTATUS 255
[2022-10-23T10:05:42.355] _job_complete: JobId=51107 done
[2022-10-23T10:05:42.879] sched: Allocate JobId=51108 NodeList=gpu02 #CPUs=8 Partition=gpu-titan
[2022-10-23T10:11:13.993] _job_complete: JobId=51108 WEXITSTATUS 255
[2022-10-23T10:11:13.994] _job_complete: JobId=51108 done
[2022-10-23T11:23:07.718] _slurm_rpc_submit_batch_job: JobId=51194 InitPrio=17786 usec=642
[2022-10-23T11:23:07.959] sched: Allocate JobId=51194 NodeList=cpu12 #CPUs=4 Partition=cpu-epyc
[2022-10-23T11:23:23.869] _job_complete: JobId=51194 WEXITSTATUS 0
[2022-10-23T11:23:23.869] _job_complete: JobId=51194 done
[2022-10-23T11:24:31.823] _slurm_rpc_submit_batch_job: JobId=51195 InitPrio=17786 usec=515
[2022-10-23T11:24:32.067] sched: Allocate JobId=51195 NodeList=cpu12 #CPUs=4 Partition=cpu-epyc
[2022-10-23T11:24:45.183] _job_complete: JobId=51195 WEXITSTATUS 0
[2022-10-23T11:24:45.183] _job_complete: JobId=51195 done
[2022-10-23T11:25:04.090] _slurm_rpc_submit_batch_job: JobId=51196 InitPrio=17786 usec=455
[2022-10-23T11:25:04.111] sched: Allocate JobId=51196 NodeList=cpu12 #CPUs=4 Partition=cpu-epyc
[2022-10-23T11:25:16.125] _job_complete: JobId=51196 WEXITSTATUS 0
[2022-10-23T11:25:16.125] _job_complete: JobId=51196 done
[2022-10-23T11:25:53.286] _slurm_rpc_submit_batch_job: JobId=51197 InitPrio=17786 usec=505
[2022-10-23T11:25:54.176] sched: Allocate JobId=51197 NodeList=cpu12 #CPUs=4 Partition=cpu-epyc
[2022-10-23T11:26:05.592] _job_complete: JobId=51197 WEXITSTATUS 0
[2022-10-23T11:26:05.592] _job_complete: JobId=51197 done
[2022-10-23T11:27:37.398] _slurm_rpc_submit_batch_job: JobId=51198 InitPrio=17786 usec=592
[2022-10-23T11:27:37.427] sched: Allocate JobId=51198 NodeList=cpu12 #CPUs=4 Partition=cpu-epyc
[2022-10-23T11:27:45.456] _job_complete: JobId=51198 WEXITSTATUS 0
[2022-10-23T11:27:45.457] _job_complete: JobId=51198 done
[2022-10-23T11:28:33.939] _slurm_rpc_submit_batch_job: JobId=51199 InitPrio=17786 usec=500
[2022-10-23T11:28:34.501] sched: Allocate JobId=51199 NodeList=cpu12 #CPUs=4 Partition=cpu-epyc
[2022-10-23T11:28:38.836] _job_complete: JobId=51199 WEXITSTATUS 0
[2022-10-23T11:28:38.837] _job_complete: JobId=51199 done
[2022-10-23T11:32:47.913] sched: _slurm_rpc_allocate_resources JobId=51200 NodeList=cpu04 usec=1272
[2022-10-23T11:35:12.135] _job_complete: JobId=51200 WTERMSIG 126
[2022-10-23T11:35:12.135] _job_complete: JobId=51200 cancelled by interactive user
[2022-10-23T11:35:12.135] _job_complete: JobId=51200 done
[2022-10-23T11:35:36.070] sched: _slurm_rpc_allocate_resources JobId=51201 NodeList=cpu04 usec=2135
[2022-10-23T11:39:31.146] job_step_signal: JobId=51201 StepId=0 not found
[2022-10-23T11:39:31.148] _job_complete: JobId=51201 WTERMSIG 126
[2022-10-23T11:39:31.148] _job_complete: JobId=51201 cancelled by interactive user
[2022-10-23T11:39:31.148] _job_complete: JobId=51201 done
[2022-10-23T11:40:12.991] sched: _slurm_rpc_allocate_resources JobId=51202 NodeList=cpu04 usec=1307
[2022-10-23T11:46:02.791] job_step_signal: JobId=51202 StepId=0 not found
[2022-10-23T11:46:02.793] _job_complete: JobId=51202 WTERMSIG 126
[2022-10-23T11:46:02.793] _job_complete: JobId=51202 cancelled by interactive user
[2022-10-23T11:46:02.793] _job_complete: JobId=51202 done
[2022-10-23T12:12:59.324] _job_complete: JobId=51145 OOM failure
[2022-10-23T12:12:59.330] _job_complete: JobId=51145 done
[2022-10-23T17:16:06.268] _job_complete: JobId=51070 WEXITSTATUS 0
[2022-10-23T17:16:06.268] _job_complete: JobId=51070 done
[2022-10-23T17:21:59.535] _job_complete: JobId=51120 WEXITSTATUS 0
[2022-10-23T17:21:59.535] _job_complete: JobId=51120 done
[2022-10-24T00:43:02.759] _job_complete: JobId=51178 WEXITSTATUS 0
[2022-10-24T00:43:02.759] _job_complete: JobId=51178 done
[2022-10-24T01:06:11.301] Time limit exhausted for JobId=51193
[2022-10-24T03:24:02.366] _slurm_rpc_submit_batch_job: JobId=51203 InitPrio=2868 usec=643
[2022-10-24T03:24:02.843] sched: Allocate JobId=51203 NodeList=cpu04 #CPUs=4 Partition=cpu-opteron
[2022-10-24T04:54:41.848] _job_complete: JobId=51203 WEXITSTATUS 1
[2022-10-24T04:54:41.848] _job_complete: JobId=51203 done
[2022-10-24T06:07:03.762] _slurm_rpc_submit_batch_job: JobId=51204 InitPrio=2868 usec=592
[2022-10-24T06:07:03.862] sched: Allocate JobId=51204 NodeList=cpu04 #CPUs=4 Partition=cpu-opteron
[2022-10-24T06:07:08.169] _job_complete: JobId=51204 WEXITSTATUS 1
[2022-10-24T06:07:08.169] _job_complete: JobId=51204 done
[2022-10-24T06:09:18.875] _slurm_rpc_submit_batch_job: JobId=51205 InitPrio=2868 usec=496
[2022-10-24T06:09:19.035] sched: Allocate JobId=51205 NodeList=cpu04 #CPUs=4 Partition=cpu-opteron
[2022-10-24T07:19:04.869] _job_complete: JobId=51205 WEXITSTATUS 1
[2022-10-24T07:19:04.869] _job_complete: JobId=51205 done
[2022-10-24T07:34:44.347] _slurm_rpc_submit_batch_job: JobId=51206 InitPrio=2868 usec=604
[2022-10-24T07:34:44.599] sched: Allocate JobId=51206 NodeList=cpu04 #CPUs=4 Partition=cpu-opteron
[2022-10-24T07:42:51.696] _job_complete: JobId=51206 WEXITSTATUS 1
[2022-10-24T07:42:51.696] _job_complete: JobId=51206 done
[2022-10-24T07:51:07.259] _slurm_rpc_submit_batch_job: JobId=51207 InitPrio=2868 usec=590
[2022-10-24T07:51:07.328] sched: Allocate JobId=51207 NodeList=cpu04 #CPUs=4 Partition=cpu-opteron
[2022-10-24T09:01:02.217] _job_complete: JobId=51207 WEXITSTATUS 1
[2022-10-24T09:01:02.217] _job_complete: JobId=51207 done
[2022-10-24T11:05:55.097] _slurm_rpc_submit_batch_job: JobId=51208 InitPrio=409 usec=617
[2022-10-24T11:05:56.364] sched: Allocate JobId=51208 NodeList=cpu15 #CPUs=48 Partition=cpu-epyc
[2022-10-24T11:11:36.980] sched: _slurm_rpc_allocate_resources JobId=51209 NodeList=(null) usec=1168
[2022-10-24T11:11:37.024] sched: Allocate JobId=51209 NodeList=cpu04 #CPUs=1 Partition=cpu-opteron
[2022-10-24T11:55:43.458] Time limit exhausted for JobId=50904
[2022-10-24T14:47:23.439] _job_complete: JobId=51209 WEXITSTATUS 0
[2022-10-24T14:47:23.440] _job_complete: JobId=51209 done
[2022-10-24T14:52:23.894] cleanup_completing: JobId=51209 completion process took 300 seconds
[2022-10-24T16:18:06.114] _slurm_rpc_submit_batch_job: JobId=51210 InitPrio=5122 usec=611
[2022-10-24T16:18:07.121] sched: Allocate JobId=51210 NodeList=cpu04 #CPUs=8 Partition=cpu-opteron
[2022-10-24T16:18:11.233] _job_complete: JobId=51210 WEXITSTATUS 0
[2022-10-24T16:18:11.233] _job_complete: JobId=51210 done
[2022-10-24T16:24:17.673] _slurm_rpc_submit_batch_job: JobId=51211 InitPrio=5122 usec=485
[2022-10-24T16:24:17.695] sched: Allocate JobId=51211 NodeList=cpu04 #CPUs=8 Partition=cpu-opteron
[2022-10-24T16:25:26.540] _job_complete: JobId=51211 WEXITSTATUS 0
[2022-10-24T16:25:26.540] _job_complete: JobId=51211 done
[2022-10-24T16:29:12.990] _slurm_rpc_submit_batch_job: JobId=51212 InitPrio=5122 usec=467
[2022-10-24T16:29:13.303] sched: Allocate JobId=51212 NodeList=cpu04 #CPUs=8 Partition=cpu-opteron
[2022-10-24T16:33:46.859] _job_complete: JobId=51212 WEXITSTATUS 0
[2022-10-24T16:33:46.859] _job_complete: JobId=51212 done
[2022-10-24T16:37:31.677] _slurm_rpc_submit_batch_job: JobId=51213 InitPrio=5122 usec=465
[2022-10-24T16:37:32.139] sched: Allocate JobId=51213 NodeList=cpu04 #CPUs=8 Partition=cpu-opteron
[2022-10-24T16:42:00.798] _job_complete: JobId=51213 WEXITSTATUS 0
[2022-10-24T16:42:00.798] _job_complete: JobId=51213 done
[2022-10-24T16:52:32.294] _slurm_rpc_submit_batch_job: JobId=51214 InitPrio=5122 usec=567
[2022-10-24T16:52:32.757] sched: Allocate JobId=51214 NodeList=cpu04 #CPUs=32 Partition=cpu-opteron
[2022-10-24T16:53:26.444] _slurm_rpc_submit_batch_job: JobId=51215 InitPrio=5122 usec=487
[2022-10-24T16:53:26.829] sched: Allocate JobId=51215 NodeList=cpu04 #CPUs=8 Partition=cpu-opteron
[2022-10-24T16:57:10.909] _job_complete: JobId=51215 WEXITSTATUS 0
[2022-10-24T16:57:10.909] _job_complete: JobId=51215 done
[2022-10-24T17:00:28.154] _slurm_rpc_submit_batch_job: JobId=51216 InitPrio=5122 usec=486
[2022-10-24T17:00:28.513] sched: Allocate JobId=51216 NodeList=cpu04 #CPUs=8 Partition=cpu-opteron
[2022-10-24T17:00:38.373] _job_complete: JobId=51216 WEXITSTATUS 1
[2022-10-24T17:00:38.373] _job_complete: JobId=51216 done
[2022-10-24T17:09:36.312] _slurm_rpc_submit_batch_job: JobId=51217 InitPrio=5122 usec=505
[2022-10-24T17:09:36.517] sched: Allocate JobId=51217 NodeList=cpu04 #CPUs=8 Partition=cpu-opteron
[2022-10-24T17:12:35.090] _job_complete: JobId=51217 WEXITSTATUS 0
[2022-10-24T17:12:35.091] _job_complete: JobId=51217 done
[2022-10-24T17:16:53.184] _slurm_rpc_submit_batch_job: JobId=51218 InitPrio=5122 usec=449
[2022-10-24T17:16:53.390] sched: Allocate JobId=51218 NodeList=cpu04 #CPUs=8 Partition=cpu-opteron
[2022-10-24T17:24:19.839] _job_complete: JobId=51218 WEXITSTATUS 0
[2022-10-24T17:24:19.839] _job_complete: JobId=51218 done
[2022-10-24T17:26:48.051] _slurm_rpc_submit_batch_job: JobId=51219 InitPrio=5122 usec=594
[2022-10-24T17:26:48.411] sched: Allocate JobId=51219 NodeList=cpu04 #CPUs=8 Partition=cpu-opteron
[2022-10-24T17:34:15.243] _job_complete: JobId=51219 WEXITSTATUS 0
[2022-10-24T17:34:15.243] _job_complete: JobId=51219 done
[2022-10-24T18:24:22.460] _slurm_rpc_submit_batch_job: JobId=51220 InitPrio=5122 usec=575
[2022-10-24T18:24:23.317] sched: Allocate JobId=51220 NodeList=cpu04 #CPUs=32 Partition=cpu-opteron
[2022-10-24T18:25:18.512] _slurm_rpc_submit_batch_job: JobId=51221 InitPrio=5122 usec=432
[2022-10-24T18:25:19.391] sched: Allocate JobId=51221 NodeList=cpu05 #CPUs=8 Partition=cpu-opteron
[2022-10-24T18:33:24.439] _job_complete: JobId=51221 WEXITSTATUS 0
[2022-10-24T18:33:24.439] _job_complete: JobId=51221 done
[2022-10-24T18:37:07.247] _slurm_rpc_submit_batch_job: JobId=51222 InitPrio=5122 usec=483
[2022-10-24T18:37:07.743] sched: Allocate JobId=51222 NodeList=cpu05 #CPUs=8 Partition=cpu-opteron
[2022-10-24T18:44:12.528] _slurm_rpc_submit_batch_job: JobId=51223 InitPrio=5122 usec=478
[2022-10-24T18:44:13.425] sched: Allocate JobId=51223 NodeList=cpu05 #CPUs=8 Partition=cpu-opteron
[2022-10-24T18:44:14.944] _job_complete: JobId=51223 WEXITSTATUS 1
[2022-10-24T18:44:14.945] _job_complete: JobId=51223 done
[2022-10-24T18:45:05.130] _slurm_rpc_submit_batch_job: JobId=51224 InitPrio=5122 usec=486
[2022-10-24T18:45:05.498] sched: Allocate JobId=51224 NodeList=cpu05 #CPUs=8 Partition=cpu-opteron
[2022-10-24T18:45:06.887] _job_complete: JobId=51224 WEXITSTATUS 1
[2022-10-24T18:45:06.887] _job_complete: JobId=51224 done
[2022-10-24T18:46:26.993] _slurm_rpc_submit_batch_job: JobId=51225 InitPrio=5122 usec=592
[2022-10-24T18:46:27.684] sched: Allocate JobId=51225 NodeList=cpu12 #CPUs=8 Partition=cpu-epyc
[2022-10-24T18:46:30.700] _job_complete: JobId=51225 WEXITSTATUS 1
[2022-10-24T18:46:30.700] _job_complete: JobId=51225 done
[2022-10-24T18:48:04.531] _job_complete: JobId=51222 WEXITSTATUS 0
[2022-10-24T18:48:04.531] _job_complete: JobId=51222 done
[2022-10-24T18:48:38.447] _slurm_rpc_submit_batch_job: JobId=51226 InitPrio=5122 usec=479
[2022-10-24T18:48:38.870] sched: Allocate JobId=51226 NodeList=cpu12 #CPUs=8 Partition=cpu-epyc
[2022-10-24T18:50:45.250] _job_complete: JobId=51226 WEXITSTATUS 0
[2022-10-24T18:50:45.251] _job_complete: JobId=51226 done
[2022-10-24T19:02:01.005] _slurm_rpc_submit_batch_job: JobId=51227 InitPrio=5122 usec=475
[2022-10-24T19:02:01.396] sched: Allocate JobId=51227 NodeList=cpu05 #CPUs=8 Partition=cpu-opteron
[2022-10-24T19:05:11.971] _slurm_rpc_submit_batch_job: JobId=51228 InitPrio=5122 usec=537
[2022-10-24T19:05:12.663] sched: Allocate JobId=51228 NodeList=cpu05 #CPUs=8 Partition=cpu-opteron
[2022-10-24T19:13:06.621] _job_complete: JobId=51227 WEXITSTATUS 0
[2022-10-24T19:13:06.621] _job_complete: JobId=51227 done
[2022-10-24T19:17:54.978] _job_complete: JobId=51228 WEXITSTATUS 0
[2022-10-24T19:17:54.978] _job_complete: JobId=51228 done
[2022-10-24T19:46:42.092] _slurm_rpc_submit_batch_job: JobId=51229 InitPrio=5122 usec=485
[2022-10-24T19:46:42.296] sched: Allocate JobId=51229 NodeList=cpu05 #CPUs=64 Partition=cpu-opteron
[2022-10-24T19:49:46.779] _slurm_rpc_submit_batch_job: JobId=51230 InitPrio=5122 usec=535
[2022-10-24T19:49:47.546] sched: Allocate JobId=51230 NodeList=cpu08 #CPUs=8 Partition=cpu-opteron
[2022-10-24T20:02:34.229] _job_complete: JobId=51230 WEXITSTATUS 0
[2022-10-24T20:02:34.230] _job_complete: JobId=51230 done
[2022-10-24T20:17:04.372] _slurm_rpc_submit_batch_job: JobId=51231 InitPrio=4713 usec=571
[2022-10-24T20:17:04.524] sched: Allocate JobId=51231 NodeList=cpu08 #CPUs=64 Partition=cpu-opteron
[2022-10-24T20:18:25.568] _job_complete: JobId=51214 WEXITSTATUS 0
[2022-10-24T20:18:25.568] _job_complete: JobId=51214 done
[2022-10-24T20:28:06.108] _slurm_rpc_submit_batch_job: JobId=51232 InitPrio=4713 usec=553
[2022-10-24T20:28:06.222] sched: Allocate JobId=51232 NodeList=cpu12 #CPUs=8 Partition=cpu-epyc
[2022-10-24T20:28:08.803] _job_complete: JobId=51232 WEXITSTATUS 1
