[2022-09-01T00:11:57.866] _job_complete: JobId=48462 WEXITSTATUS 0
[2022-09-01T00:11:57.867] _job_complete: JobId=48462 done
[2022-09-01T01:16:49.537] _job_complete: JobId=48453 WEXITSTATUS 0
[2022-09-01T01:16:49.537] _job_complete: JobId=48453 done
[2022-09-01T01:40:34.498] _slurm_rpc_kill_job: REQUEST_KILL_JOB JobId=48567 uid 548200021
[2022-09-01T01:42:26.184] _job_complete: JobId=48533 WEXITSTATUS 0
[2022-09-01T01:42:26.184] _job_complete: JobId=48533 done
[2022-09-01T02:00:07.376] _job_complete: JobId=48534 WEXITSTATUS 0
[2022-09-01T02:00:07.376] _job_complete: JobId=48534 done
[2022-09-01T02:01:04.211] sched/backfill: _start_job: Started JobId=48490 in cpu-epyc on cpu13
[2022-09-01T02:01:39.567] _job_complete: JobId=48566 WEXITSTATUS 0
[2022-09-01T02:01:39.567] _job_complete: JobId=48566 done
[2022-09-01T02:23:14.362] _job_complete: JobId=48535 WEXITSTATUS 0
[2022-09-01T02:23:14.362] _job_complete: JobId=48535 done
[2022-09-01T02:23:43.826] _slurm_rpc_submit_batch_job: JobId=48568 InitPrio=5963 usec=407
[2022-09-01T02:25:22.230] _job_complete: JobId=48452 WEXITSTATUS 0
[2022-09-01T02:25:22.230] _job_complete: JobId=48452 done
[2022-09-01T02:30:26.768] _job_complete: JobId=48536 WEXITSTATUS 0
[2022-09-01T02:30:26.768] _job_complete: JobId=48536 done
[2022-09-01T02:32:14.760] _slurm_rpc_kill_job: REQUEST_KILL_JOB JobId=48565 uid 548300565
[2022-09-01T02:32:16.858] sched: Allocate JobId=48568 NodeList=gpu04 #CPUs=8 Partition=gpu-k40c
[2022-09-01T02:32:18.951] _slurm_rpc_submit_batch_job: JobId=48569 InitPrio=458 usec=437
[2022-09-01T02:32:19.102] sched: Allocate JobId=48569 NodeList=gpu03 #CPUs=16 Partition=gpu-k10
[2022-09-01T02:32:22.569] _job_complete: JobId=48568 WEXITSTATUS 1
[2022-09-01T02:32:22.570] _job_complete: JobId=48568 done
[2022-09-01T02:35:05.081] _job_complete: JobId=48569 WEXITSTATUS 0
[2022-09-01T02:35:05.081] _job_complete: JobId=48569 done
[2022-09-01T02:42:05.925] _slurm_rpc_submit_batch_job: JobId=48570 InitPrio=5963 usec=406
[2022-09-01T02:42:06.068] sched: Allocate JobId=48570 NodeList=gpu04 #CPUs=8 Partition=gpu-k40c
[2022-09-01T02:42:07.618] _job_complete: JobId=48570 WEXITSTATUS 1
[2022-09-01T02:42:07.618] _job_complete: JobId=48570 done
[2022-09-01T02:45:10.571] _job_complete: JobId=48537 WEXITSTATUS 0
[2022-09-01T02:45:10.571] _job_complete: JobId=48537 done
[2022-09-01T02:46:04.265] sched/backfill: _start_job: Started JobId=48491 in cpu-epyc on cpu13
[2022-09-01T02:53:56.674] _slurm_rpc_submit_batch_job: JobId=48571 InitPrio=15963 usec=535
[2022-09-01T02:53:57.424] sched: Allocate JobId=48571 NodeList=cpu08 #CPUs=4 Partition=cpu-opteron
[2022-09-01T02:54:02.237] _job_complete: JobId=48571 WEXITSTATUS 0
[2022-09-01T02:54:02.237] _job_complete: JobId=48571 done
[2022-09-01T02:56:05.607] _slurm_rpc_submit_batch_job: JobId=48572 InitPrio=5963 usec=487
[2022-09-01T02:56:06.596] sched: Allocate JobId=48572 NodeList=gpu04 #CPUs=8 Partition=gpu-k40c
[2022-09-01T02:56:08.144] _job_complete: JobId=48572 WEXITSTATUS 1
[2022-09-01T02:56:08.145] _job_complete: JobId=48572 done
[2022-09-01T02:57:56.496] _slurm_rpc_submit_batch_job: JobId=48573 InitPrio=458 usec=398
[2022-09-01T02:57:56.784] sched: Allocate JobId=48573 NodeList=gpu03 #CPUs=16 Partition=gpu-k10
[2022-09-01T03:12:34.862] _slurm_rpc_submit_batch_job: JobId=48574 InitPrio=15963 usec=530
[2022-09-01T03:12:35.250] sched: Allocate JobId=48574 NodeList=cpu08 #CPUs=4 Partition=cpu-opteron
[2022-09-01T03:12:36.328] _job_complete: JobId=48574 WEXITSTATUS 1
[2022-09-01T03:12:36.328] _job_complete: JobId=48574 done
[2022-09-01T03:22:07.831] _slurm_rpc_submit_batch_job: JobId=48575 InitPrio=15963 usec=654
[2022-09-01T03:22:08.181] sched: Allocate JobId=48575 NodeList=cpu08 #CPUs=4 Partition=cpu-opteron
[2022-09-01T03:22:09.209] _job_complete: JobId=48575 WEXITSTATUS 0
[2022-09-01T03:22:09.209] _job_complete: JobId=48575 done
[2022-09-01T03:24:45.934] _slurm_rpc_submit_batch_job: JobId=48576 InitPrio=15963 usec=816
[2022-09-01T03:24:46.488] sched: Allocate JobId=48576 NodeList=cpu08 #CPUs=4 Partition=cpu-opteron
[2022-09-01T03:24:47.508] _job_complete: JobId=48576 WEXITSTATUS 1
[2022-09-01T03:24:47.508] _job_complete: JobId=48576 done
[2022-09-01T03:26:04.832] _slurm_rpc_submit_batch_job: JobId=48577 InitPrio=15963 usec=523
[2022-09-01T03:26:05.590] sched: Allocate JobId=48577 NodeList=gpu04 #CPUs=4 Partition=gpu-k40c
[2022-09-01T03:26:06.707] _job_complete: JobId=48577 WEXITSTATUS 1
[2022-09-01T03:26:06.707] _job_complete: JobId=48577 done
[2022-09-01T03:42:30.618] _slurm_rpc_submit_batch_job: JobId=48578 InitPrio=5963 usec=439
[2022-09-01T03:42:31.574] sched: Allocate JobId=48578 NodeList=gpu04 #CPUs=8 Partition=gpu-k40c
[2022-09-01T03:42:33.090] _job_complete: JobId=48578 WEXITSTATUS 0
[2022-09-01T03:42:33.091] _job_complete: JobId=48578 done
[2022-09-01T03:43:23.423] _slurm_rpc_submit_batch_job: JobId=48579 InitPrio=5963 usec=512
[2022-09-01T03:43:23.736] sched: Allocate JobId=48579 NodeList=gpu04 #CPUs=8 Partition=gpu-k40c
[2022-09-01T03:43:24.907] _job_complete: JobId=48579 WEXITSTATUS 0
[2022-09-01T03:43:24.908] _job_complete: JobId=48579 done
[2022-09-01T04:23:29.914] _slurm_rpc_submit_batch_job: JobId=48580 InitPrio=5963 usec=522
[2022-09-01T04:23:30.838] sched: Allocate JobId=48580 NodeList=gpu04 #CPUs=8 Partition=gpu-k40c
[2022-09-01T04:23:34.542] _job_complete: JobId=48580 WEXITSTATUS 0
[2022-09-01T04:23:34.543] _job_complete: JobId=48580 done
[2022-09-01T04:28:50.244] _slurm_rpc_submit_batch_job: JobId=48581 InitPrio=5963 usec=449
[2022-09-01T04:28:52.334] sched: Allocate JobId=48581 NodeList=gpu04 #CPUs=8 Partition=gpu-k40c
[2022-09-01T04:28:53.734] _job_complete: JobId=48581 WEXITSTATUS 1
[2022-09-01T04:28:53.734] _job_complete: JobId=48581 done
[2022-09-01T04:31:00.073] _slurm_rpc_submit_batch_job: JobId=48582 InitPrio=5963 usec=541
[2022-09-01T04:31:00.500] sched: Allocate JobId=48582 NodeList=gpu04 #CPUs=8 Partition=gpu-k40c
[2022-09-01T04:31:01.816] _job_complete: JobId=48582 WEXITSTATUS 1
[2022-09-01T04:31:01.816] _job_complete: JobId=48582 done
[2022-09-01T04:31:53.490] _slurm_rpc_submit_batch_job: JobId=48583 InitPrio=5963 usec=526
[2022-09-01T04:31:53.572] sched: Allocate JobId=48583 NodeList=gpu04 #CPUs=8 Partition=gpu-k40c
[2022-09-01T04:31:54.682] _job_complete: JobId=48583 WEXITSTATUS 1
[2022-09-01T04:31:54.682] _job_complete: JobId=48583 done
[2022-09-01T04:35:53.772] _slurm_rpc_submit_batch_job: JobId=48584 InitPrio=5963 usec=544
[2022-09-01T04:35:54.001] sched: Allocate JobId=48584 NodeList=gpu04 #CPUs=8 Partition=gpu-k40c
[2022-09-01T04:35:55.263] _job_complete: JobId=48584 WEXITSTATUS 1
[2022-09-01T04:35:55.264] _job_complete: JobId=48584 done
[2022-09-01T04:38:15.922] _slurm_rpc_submit_batch_job: JobId=48585 InitPrio=5963 usec=539
[2022-09-01T04:38:16.299] sched: Allocate JobId=48585 NodeList=gpu04 #CPUs=8 Partition=gpu-k40c
[2022-09-01T04:38:17.635] _job_complete: JobId=48585 WEXITSTATUS 0
[2022-09-01T04:38:17.636] _job_complete: JobId=48585 done
[2022-09-01T04:39:19.665] _slurm_rpc_submit_batch_job: JobId=48586 InitPrio=5963 usec=506
[2022-09-01T04:39:20.385] sched: Allocate JobId=48586 NodeList=gpu04 #CPUs=8 Partition=gpu-k40c
[2022-09-01T04:39:21.490] _job_complete: JobId=48586 WEXITSTATUS 1
[2022-09-01T04:39:21.490] _job_complete: JobId=48586 done
[2022-09-01T04:50:07.768] _slurm_rpc_submit_batch_job: JobId=48587 InitPrio=5963 usec=669
[2022-09-01T04:50:08.447] sched: Allocate JobId=48587 NodeList=gpu04 #CPUs=8 Partition=gpu-k40c
[2022-09-01T04:50:09.866] _job_complete: JobId=48587 WEXITSTATUS 0
[2022-09-01T04:50:09.867] _job_complete: JobId=48587 done
[2022-09-01T04:50:49.037] _slurm_rpc_submit_batch_job: JobId=48588 InitPrio=5963 usec=462
[2022-09-01T04:50:49.501] sched: Allocate JobId=48588 NodeList=gpu04 #CPUs=8 Partition=gpu-k40c
[2022-09-01T04:50:50.585] _job_complete: JobId=48588 WEXITSTATUS 1
[2022-09-01T04:50:50.585] _job_complete: JobId=48588 done
[2022-09-01T04:54:43.719] _slurm_rpc_submit_batch_job: JobId=48589 InitPrio=5963 usec=522
[2022-09-01T04:54:43.919] sched: Allocate JobId=48589 NodeList=gpu04 #CPUs=8 Partition=gpu-k40c
[2022-09-01T04:54:45.218] _job_complete: JobId=48589 WEXITSTATUS 1
[2022-09-01T04:54:45.218] _job_complete: JobId=48589 done
[2022-09-01T04:56:54.318] _slurm_rpc_submit_batch_job: JobId=48590 InitPrio=5963 usec=534
[2022-09-01T04:56:55.100] sched: Allocate JobId=48590 NodeList=gpu04 #CPUs=8 Partition=gpu-k40c
[2022-09-01T04:56:56.514] _job_complete: JobId=48590 WEXITSTATUS 0
[2022-09-01T04:56:56.514] _job_complete: JobId=48590 done
[2022-09-01T04:59:10.525] _slurm_rpc_submit_batch_job: JobId=48591 InitPrio=5963 usec=499
[2022-09-01T04:59:11.370] sched: Allocate JobId=48591 NodeList=gpu04 #CPUs=8 Partition=gpu-k40c
[2022-09-01T04:59:12.802] _job_complete: JobId=48591 WEXITSTATUS 1
[2022-09-01T04:59:12.802] _job_complete: JobId=48591 done
[2022-09-01T05:02:02.659] _slurm_rpc_submit_batch_job: JobId=48592 InitPrio=5963 usec=468
[2022-09-01T05:02:03.592] sched: Allocate JobId=48592 NodeList=gpu04 #CPUs=8 Partition=gpu-k40c
[2022-09-01T05:02:05.168] _job_complete: JobId=48592 WEXITSTATUS 1
[2022-09-01T05:02:05.169] _job_complete: JobId=48592 done
[2022-09-01T05:07:24.591] _slurm_rpc_submit_batch_job: JobId=48593 InitPrio=5963 usec=513
[2022-09-01T05:07:25.171] sched: Allocate JobId=48593 NodeList=gpu04 #CPUs=8 Partition=gpu-k40c
[2022-09-01T05:07:26.468] _job_complete: JobId=48593 WEXITSTATUS 1
[2022-09-01T05:07:26.468] _job_complete: JobId=48593 done
[2022-09-01T05:08:32.868] _slurm_rpc_submit_batch_job: JobId=48594 InitPrio=5963 usec=463
[2022-09-01T05:08:33.470] sched: Allocate JobId=48594 NodeList=gpu04 #CPUs=8 Partition=gpu-k40c
[2022-09-01T05:08:34.604] _job_complete: JobId=48594 WEXITSTATUS 2
[2022-09-01T05:08:34.605] _job_complete: JobId=48594 done
[2022-09-01T05:08:54.234] _slurm_rpc_submit_batch_job: JobId=48595 InitPrio=5963 usec=571
[2022-09-01T05:08:54.496] sched: Allocate JobId=48595 NodeList=gpu04 #CPUs=8 Partition=gpu-k40c
[2022-09-01T05:08:55.618] _job_complete: JobId=48595 WEXITSTATUS 2
[2022-09-01T05:08:55.618] _job_complete: JobId=48595 done
[2022-09-01T05:14:54.519] _slurm_rpc_submit_batch_job: JobId=48596 InitPrio=5963 usec=519
[2022-09-01T05:14:54.545] sched: Allocate JobId=48596 NodeList=gpu04 #CPUs=8 Partition=gpu-k40c
[2022-09-01T05:14:55.906] _job_complete: JobId=48596 WEXITSTATUS 1
[2022-09-01T05:14:55.907] _job_complete: JobId=48596 done
[2022-09-01T05:20:57.328] _get_job_parts: invalid partition specified: gpu-k40
[2022-09-01T05:20:57.328] _slurm_rpc_submit_batch_job: Invalid partition name specified
[2022-09-01T05:21:18.520] _slurm_rpc_submit_batch_job: JobId=48597 InitPrio=5963 usec=482
[2022-09-01T05:21:19.213] sched: Allocate JobId=48597 NodeList=gpu04 #CPUs=8 Partition=gpu-k40c
[2022-09-01T05:21:20.755] _job_complete: JobId=48597 WEXITSTATUS 0
[2022-09-01T05:21:20.755] _job_complete: JobId=48597 done
[2022-09-01T05:22:16.171] _job_complete: JobId=48458 WEXITSTATUS 0
[2022-09-01T05:22:16.176] _job_complete: JobId=48458 done
[2022-09-01T05:22:38.758] _slurm_rpc_submit_batch_job: JobId=48598 InitPrio=5963 usec=426
[2022-09-01T05:22:39.322] sched: Allocate JobId=48598 NodeList=gpu04 #CPUs=8 Partition=gpu-k40c
[2022-09-01T05:22:40.496] _job_complete: JobId=48598 WEXITSTATUS 1
[2022-09-01T05:22:40.496] _job_complete: JobId=48598 done
[2022-09-01T05:30:03.894] _slurm_rpc_submit_batch_job: JobId=48599 InitPrio=5963 usec=459
[2022-09-01T05:30:04.154] sched: Allocate JobId=48599 NodeList=gpu04 #CPUs=8 Partition=gpu-k40c
[2022-09-01T05:30:05.597] _job_complete: JobId=48599 WEXITSTATUS 1
[2022-09-01T05:30:05.597] _job_complete: JobId=48599 done
[2022-09-01T05:32:11.505] _slurm_rpc_submit_batch_job: JobId=48600 InitPrio=5963 usec=435
[2022-09-01T05:32:12.324] sched: Allocate JobId=48600 NodeList=gpu04 #CPUs=8 Partition=gpu-k40c
[2022-09-01T05:32:14.051] _job_complete: JobId=48600 WEXITSTATUS 0
[2022-09-01T05:32:14.051] _job_complete: JobId=48600 done
[2022-09-01T05:32:28.284] _slurm_rpc_submit_batch_job: JobId=48601 InitPrio=5963 usec=432
[2022-09-01T05:32:28.343] sched: Allocate JobId=48601 NodeList=gpu04 #CPUs=8 Partition=gpu-k40c
[2022-09-01T05:32:29.608] _job_complete: JobId=48601 WEXITSTATUS 0
[2022-09-01T05:32:29.608] _job_complete: JobId=48601 done
[2022-09-01T05:34:27.608] _slurm_rpc_submit_batch_job: JobId=48602 InitPrio=5963 usec=486
[2022-09-01T05:34:27.648] sched: Allocate JobId=48602 NodeList=gpu04 #CPUs=8 Partition=gpu-k40c
[2022-09-01T05:34:31.601] _job_complete: JobId=48602 WEXITSTATUS 0
[2022-09-01T05:34:31.601] _job_complete: JobId=48602 done
[2022-09-01T05:39:18.590] _slurm_rpc_submit_batch_job: JobId=48603 InitPrio=5963 usec=497
[2022-09-01T05:39:19.300] sched: Allocate JobId=48603 NodeList=gpu04 #CPUs=8 Partition=gpu-k40c
[2022-09-01T05:39:23.172] _job_complete: JobId=48603 WEXITSTATUS 0
[2022-09-01T05:39:23.172] _job_complete: JobId=48603 done
[2022-09-01T05:44:52.256] _slurm_rpc_submit_batch_job: JobId=48604 InitPrio=5963 usec=396
[2022-09-01T05:44:53.844] sched: Allocate JobId=48604 NodeList=gpu04 #CPUs=8 Partition=gpu-k40c
[2022-09-01T05:45:03.688] _job_complete: JobId=48604 WEXITSTATUS 0
[2022-09-01T05:45:03.688] _job_complete: JobId=48604 done
[2022-09-01T05:46:29.265] _slurm_rpc_submit_batch_job: JobId=48605 InitPrio=5963 usec=492
[2022-09-01T05:46:29.971] sched: Allocate JobId=48605 NodeList=gpu04 #CPUs=8 Partition=gpu-k40c
[2022-09-01T05:53:41.745] _job_complete: JobId=48454 WEXITSTATUS 0
[2022-09-01T05:53:41.746] _job_complete: JobId=48454 done
[2022-09-01T06:02:42.683] _slurm_rpc_kill_job: REQUEST_KILL_JOB JobId=48605 uid 548300565
[2022-09-01T06:07:21.695] _slurm_rpc_submit_batch_job: JobId=48606 InitPrio=5963 usec=434
[2022-09-01T06:07:22.112] sched: Allocate JobId=48606 NodeList=gpu04 #CPUs=8 Partition=gpu-k40c
[2022-09-01T07:00:19.797] _slurm_rpc_submit_batch_job: JobId=48607 InitPrio=229 usec=487
[2022-09-01T07:00:19.964] sched: Allocate JobId=48607 NodeList=cpu11 #CPUs=64 Partition=cpu-opteron
[2022-09-01T07:09:16.437] _slurm_rpc_submit_batch_job: JobId=48608 InitPrio=229 usec=407
[2022-09-01T07:09:16.935] sched: Allocate JobId=48608 NodeList=cpu03 #CPUs=64 Partition=cpu-opteron
[2022-09-01T07:15:48.764] _slurm_rpc_submit_batch_job: JobId=48609 InitPrio=229 usec=385
[2022-09-01T10:11:53.398] _slurm_rpc_submit_batch_job: JobId=48610 InitPrio=917 usec=481
[2022-09-01T10:11:53.728] sched: Allocate JobId=48610 NodeList=gpu01 #CPUs=4 Partition=gpu-k10
[2022-09-01T10:12:21.806] _job_complete: JobId=48610 WEXITSTATUS 0
[2022-09-01T10:12:21.806] _job_complete: JobId=48610 done
[2022-09-01T10:14:17.820] _slurm_rpc_submit_batch_job: JobId=48611 InitPrio=917 usec=382
[2022-09-01T10:14:18.041] sched: Allocate JobId=48611 NodeList=cpu01 #CPUs=32 Partition=cpu-opteron
[2022-09-01T10:14:43.459] _job_complete: JobId=48611 WEXITSTATUS 1
[2022-09-01T10:14:43.460] _job_complete: JobId=48611 done
[2022-09-01T10:15:23.150] _slurm_rpc_submit_batch_job: JobId=48612 InitPrio=917 usec=393
[2022-09-01T10:15:24.130] sched: Allocate JobId=48612 NodeList=cpu01 #CPUs=32 Partition=cpu-opteron
[2022-09-01T11:24:30.883] _slurm_rpc_submit_batch_job: JobId=48613 InitPrio=4128 usec=440
[2022-09-01T11:24:31.253] sched: Allocate JobId=48613 NodeList=cpu01 #CPUs=8 Partition=cpu-opteron
[2022-09-01T11:25:03.281] Time limit exhausted for JobId=46803
[2022-09-01T11:25:05.471] sched: Allocate JobId=48496 NodeList=gpu05 #CPUs=32 Partition=gpu-v100s
[2022-09-01T11:25:57.074] _job_complete: JobId=48613 WEXITSTATUS 0
[2022-09-01T11:25:57.074] _job_complete: JobId=48613 done
[2022-09-01T11:39:56.108] _slurm_rpc_submit_batch_job: JobId=48614 InitPrio=4128 usec=445
[2022-09-01T11:39:56.828] sched: Allocate JobId=48614 NodeList=cpu04 #CPUs=12 Partition=cpu-opteron
[2022-09-01T11:47:16.909] _slurm_rpc_submit_batch_job: JobId=48615 InitPrio=2752 usec=398
[2022-09-01T11:48:00.528] _slurm_rpc_kill_job: REQUEST_KILL_JOB JobId=48615 uid 548200029
[2022-09-01T11:48:17.902] _slurm_rpc_submit_batch_job: JobId=48616 InitPrio=2752 usec=441
[2022-09-01T12:25:33.020] Time limit exhausted for JobId=48496
[2022-09-01T12:25:42.201] sched: Allocate JobId=48172 NodeList=gpu05 #CPUs=32 Partition=gpu-v100s
[2022-09-01T12:31:24.582] _job_complete: JobId=48612 WEXITSTATUS 0
[2022-09-01T12:31:24.583] _job_complete: JobId=48612 done
[2022-09-01T12:34:03.000] _job_complete: JobId=48172 WEXITSTATUS 1
[2022-09-01T12:34:03.000] _job_complete: JobId=48172 done
[2022-09-01T12:34:04.186] sched: Allocate JobId=48268 NodeList=gpu05 #CPUs=8 Partition=gpu-v100s
[2022-09-01T12:34:04.187] sched: Allocate JobId=48269 NodeList=gpu05 #CPUs=8 Partition=gpu-v100s
[2022-09-01T12:34:12.060] _job_complete: JobId=48269 WEXITSTATUS 1
[2022-09-01T12:34:12.060] _job_complete: JobId=48269 done
[2022-09-01T12:34:12.531] sched: Allocate JobId=48322 NodeList=gpu05 #CPUs=12 Partition=gpu-v100s
[2022-09-01T12:36:46.490] _slurm_rpc_submit_batch_job: JobId=48617 InitPrio=2752 usec=395
[2022-09-01T12:36:46.543] sched: Allocate JobId=48617 NodeList=cpu01 #CPUs=32 Partition=cpu-opteron
[2022-09-01T12:36:49.108] _job_complete: JobId=48617 WEXITSTATUS 1
[2022-09-01T12:36:49.108] _job_complete: JobId=48617 done
[2022-09-01T13:20:12.800] _job_complete: JobId=48614 WEXITSTATUS 0
[2022-09-01T13:20:12.800] _job_complete: JobId=48614 done
[2022-09-01T13:30:21.464] _slurm_rpc_submit_batch_job: JobId=48618 InitPrio=2752 usec=444
[2022-09-01T13:30:22.296] sched: Allocate JobId=48618 NodeList=cpu01 #CPUs=32 Partition=cpu-opteron
[2022-09-01T13:32:04.531] _job_complete: JobId=48618 WEXITSTATUS 0
[2022-09-01T13:32:04.532] _job_complete: JobId=48618 done
[2022-09-01T13:55:29.581] _job_complete: JobId=48573 WEXITSTATUS 1
[2022-09-01T13:55:29.581] _job_complete: JobId=48573 done
[2022-09-01T14:22:05.291] _slurm_rpc_submit_batch_job: JobId=48619 InitPrio=4128 usec=579
[2022-09-01T14:22:05.627] sched: Allocate JobId=48619 NodeList=cpu01 #CPUs=16 Partition=cpu-opteron
[2022-09-01T14:23:06.796] _job_complete: JobId=48619 WEXITSTATUS 139
[2022-09-01T14:23:06.796] _job_complete: JobId=48619 done
[2022-09-01T14:44:59.227] _job_complete: JobId=48606 WEXITSTATUS 0
[2022-09-01T14:44:59.232] _job_complete: JobId=48606 done
[2022-09-01T14:48:47.518] _slurm_rpc_submit_batch_job: JobId=48620 InitPrio=688 usec=463
[2022-09-01T14:48:48.430] sched: Allocate JobId=48620 NodeList=cpu01 #CPUs=32 Partition=cpu-opteron
[2022-09-01T14:49:51.908] _slurm_rpc_submit_batch_job: JobId=48621 InitPrio=688 usec=423
[2022-09-01T14:49:52.505] sched: Allocate JobId=48621 NodeList=cpu04 #CPUs=32 Partition=cpu-opteron
[2022-09-01T14:58:35.377] _slurm_rpc_submit_batch_job: JobId=48622 InitPrio=4128 usec=520
[2022-09-01T14:58:35.479] sched: Allocate JobId=48622 NodeList=cpu01 #CPUs=8 Partition=cpu-opteron
[2022-09-01T14:59:48.275] _slurm_rpc_submit_batch_job: JobId=48623 InitPrio=2752 usec=471
[2022-09-01T14:59:48.589] sched: Allocate JobId=48623 NodeList=cpu04 #CPUs=32 Partition=cpu-opteron
[2022-09-01T14:59:51.101] _job_complete: JobId=48623 WEXITSTATUS 1
[2022-09-01T14:59:51.102] _job_complete: JobId=48623 done
[2022-09-01T15:00:10.007] _job_complete: JobId=48622 WEXITSTATUS 0
[2022-09-01T15:00:10.007] _job_complete: JobId=48622 done
[2022-09-01T15:04:03.003] Time limit exhausted for JobId=48320
[2022-09-01T15:04:06.206] sched: Allocate JobId=48099 NodeList=gpu02 #CPUs=16 Partition=gpu-titan
[2022-09-01T15:04:10.358] _job_complete: JobId=48099 WEXITSTATUS 1
[2022-09-01T15:04:10.358] _job_complete: JobId=48099 done
[2022-09-01T15:04:56.364] _slurm_rpc_submit_batch_job: JobId=48624 InitPrio=2752 usec=360
[2022-09-01T15:04:57.083] sched: Allocate JobId=48624 NodeList=cpu04 #CPUs=32 Partition=cpu-opteron
[2022-09-01T15:06:33.717] _job_complete: JobId=48624 WEXITSTATUS 0
[2022-09-01T15:06:33.718] _job_complete: JobId=48624 done
[2022-09-01T15:07:17.343] _slurm_rpc_submit_batch_job: JobId=48625 InitPrio=2752 usec=352
[2022-09-01T15:07:18.266] sched: Allocate JobId=48625 NodeList=cpu04 #CPUs=32 Partition=cpu-opteron
[2022-09-01T15:07:20.733] _job_complete: JobId=48625 WEXITSTATUS 1
[2022-09-01T15:07:20.734] _job_complete: JobId=48625 done
[2022-09-01T15:08:11.146] _slurm_rpc_submit_batch_job: JobId=48626 InitPrio=2752 usec=452
[2022-09-01T15:08:11.439] sched: Allocate JobId=48626 NodeList=cpu04 #CPUs=32 Partition=cpu-opteron
[2022-09-01T15:08:13.645] _job_complete: JobId=48626 WEXITSTATUS 1
[2022-09-01T15:08:13.646] _job_complete: JobId=48626 done
[2022-09-01T15:09:36.199] _slurm_rpc_submit_batch_job: JobId=48627 InitPrio=2752 usec=493
[2022-09-01T15:09:36.547] sched: Allocate JobId=48627 NodeList=cpu04 #CPUs=32 Partition=cpu-opteron
[2022-09-01T15:09:38.858] _job_complete: JobId=48627 WEXITSTATUS 1
[2022-09-01T15:09:38.859] _job_complete: JobId=48627 done
[2022-09-01T15:10:06.648] _slurm_rpc_submit_batch_job: JobId=48628 InitPrio=2752 usec=454
[2022-09-01T15:10:07.589] sched: Allocate JobId=48628 NodeList=cpu04 #CPUs=32 Partition=cpu-opteron
[2022-09-01T15:10:09.717] _job_complete: JobId=48628 WEXITSTATUS 1
[2022-09-01T15:10:09.717] _job_complete: JobId=48628 done
[2022-09-01T15:10:51.947] _slurm_rpc_submit_batch_job: JobId=48629 InitPrio=2752 usec=439
[2022-09-01T15:10:52.645] sched: Allocate JobId=48629 NodeList=cpu04 #CPUs=32 Partition=cpu-opteron
[2022-09-01T15:10:54.843] _job_complete: JobId=48629 WEXITSTATUS 1
[2022-09-01T15:10:54.844] _job_complete: JobId=48629 done
[2022-09-01T15:11:15.706] _slurm_rpc_submit_batch_job: JobId=48630 InitPrio=2752 usec=384
[2022-09-01T15:11:16.678] sched: Allocate JobId=48630 NodeList=cpu04 #CPUs=32 Partition=cpu-opteron
[2022-09-01T15:11:18.798] _job_complete: JobId=48630 WEXITSTATUS 1
[2022-09-01T15:11:18.799] _job_complete: JobId=48630 done
[2022-09-01T15:11:43.630] _slurm_rpc_submit_batch_job: JobId=48631 InitPrio=2752 usec=399
[2022-09-01T15:11:43.715] sched: Allocate JobId=48631 NodeList=cpu04 #CPUs=32 Partition=cpu-opteron
[2022-09-01T15:11:45.847] _job_complete: JobId=48631 WEXITSTATUS 1
[2022-09-01T15:11:45.847] _job_complete: JobId=48631 done
[2022-09-01T15:12:10.239] _slurm_rpc_submit_batch_job: JobId=48632 InitPrio=2752 usec=397
[2022-09-01T15:12:10.752] sched: Allocate JobId=48632 NodeList=cpu04 #CPUs=32 Partition=cpu-opteron
[2022-09-01T15:12:12.912] _job_complete: JobId=48632 WEXITSTATUS 1
[2022-09-01T15:12:12.912] _job_complete: JobId=48632 done
[2022-09-01T15:13:47.039] _slurm_rpc_submit_batch_job: JobId=48633 InitPrio=2752 usec=388
[2022-09-01T15:13:48.018] sched: Allocate JobId=48633 NodeList=cpu04 #CPUs=32 Partition=cpu-opteron
[2022-09-01T15:13:51.275] _slurm_rpc_submit_batch_job: JobId=48634 InitPrio=4128 usec=502
[2022-09-01T15:13:52.026] sched: Allocate JobId=48634 NodeList=cpu01 #CPUs=8 Partition=cpu-opteron
[2022-09-01T15:14:01.535] _job_complete: JobId=48634 WEXITSTATUS 139
[2022-09-01T15:14:01.535] _job_complete: JobId=48634 done
[2022-09-01T15:14:18.623] _slurm_rpc_submit_batch_job: JobId=48635 InitPrio=2752 usec=380
[2022-09-01T15:14:19.059] sched: Allocate JobId=48635 NodeList=cpu08 #CPUs=32 Partition=cpu-opteron
[2022-09-01T15:14:22.190] _job_complete: JobId=48635 WEXITSTATUS 1
[2022-09-01T15:14:22.190] _job_complete: JobId=48635 done
[2022-09-01T15:15:08.941] _slurm_rpc_submit_batch_job: JobId=48636 InitPrio=2752 usec=345
[2022-09-01T15:15:09.127] sched: Allocate JobId=48636 NodeList=cpu08 #CPUs=32 Partition=cpu-opteron
[2022-09-01T15:15:20.652] _job_complete: JobId=48633 WEXITSTATUS 0
[2022-09-01T15:15:20.652] _job_complete: JobId=48633 done
[2022-09-01T15:15:38.186] _slurm_rpc_submit_batch_job: JobId=48637 InitPrio=2752 usec=378
[2022-09-01T15:15:39.168] sched: Allocate JobId=48637 NodeList=cpu04 #CPUs=32 Partition=cpu-opteron
[2022-09-01T15:15:41.600] _job_complete: JobId=48637 WEXITSTATUS 1
[2022-09-01T15:15:41.600] _job_complete: JobId=48637 done
[2022-09-01T15:16:11.625] _slurm_rpc_submit_batch_job: JobId=48638 InitPrio=2752 usec=418
[2022-09-01T15:16:12.213] sched: Allocate JobId=48638 NodeList=cpu04 #CPUs=32 Partition=cpu-opteron
[2022-09-01T15:16:27.102] _slurm_rpc_submit_batch_job: JobId=48639 InitPrio=2752 usec=503
[2022-09-01T15:16:27.233] sched: Allocate JobId=48639 NodeList=cpu08 #CPUs=32 Partition=cpu-opteron
[2022-09-01T15:16:29.505] _job_complete: JobId=48639 WEXITSTATUS 1
[2022-09-01T15:16:29.506] _job_complete: JobId=48639 done
[2022-09-01T15:16:42.598] _job_complete: JobId=48636 WEXITSTATUS 0
[2022-09-01T15:16:42.599] _job_complete: JobId=48636 done
[2022-09-01T15:16:51.216] _slurm_rpc_submit_batch_job: JobId=48640 InitPrio=2752 usec=423
[2022-09-01T15:16:51.266] sched: Allocate JobId=48640 NodeList=cpu08 #CPUs=32 Partition=cpu-opteron
[2022-09-01T15:17:08.072] _slurm_rpc_submit_batch_job: JobId=48641 InitPrio=2752 usec=404
[2022-09-01T15:17:08.289] sched: Allocate JobId=48641 NodeList=cpu08 #CPUs=32 Partition=cpu-opteron
[2022-09-01T15:17:10.455] _job_complete: JobId=48641 WEXITSTATUS 1
[2022-09-01T15:17:10.455] _job_complete: JobId=48641 done
[2022-09-01T15:17:33.873] _slurm_rpc_submit_batch_job: JobId=48642 InitPrio=2752 usec=443
[2022-09-01T15:17:34.324] sched: Allocate JobId=48642 NodeList=cpu08 #CPUs=32 Partition=cpu-opteron
[2022-09-01T15:17:48.503] _slurm_rpc_submit_batch_job: JobId=48643 InitPrio=2752 usec=445
[2022-09-01T15:17:49.431] sched: Allocate JobId=48643 NodeList=cpu09 #CPUs=32 Partition=cpu-opteron
[2022-09-01T15:17:49.677] _job_complete: JobId=48638 WEXITSTATUS 0
[2022-09-01T15:17:49.677] _job_complete: JobId=48638 done
[2022-09-01T15:17:52.353] _job_complete: JobId=48643 WEXITSTATUS 1
[2022-09-01T15:17:52.353] _job_complete: JobId=48643 done
[2022-09-01T15:18:18.659] _job_complete: JobId=48640 WEXITSTATUS 0
[2022-09-01T15:18:18.659] _job_complete: JobId=48640 done
[2022-09-01T15:19:07.820] _job_complete: JobId=48642 WEXITSTATUS 0
[2022-09-01T15:19:07.820] _job_complete: JobId=48642 done
[2022-09-01T15:24:05.076] _slurm_rpc_submit_batch_job: JobId=48644 InitPrio=688 usec=479
[2022-09-01T15:24:05.122] sched: Allocate JobId=48644 NodeList=cpu04 #CPUs=32 Partition=cpu-opteron
[2022-09-01T15:25:21.371] _slurm_rpc_submit_batch_job: JobId=48645 InitPrio=4128 usec=439
[2022-09-01T15:25:22.227] sched: Allocate JobId=48645 NodeList=cpu01 #CPUs=8 Partition=cpu-opteron
[2022-09-01T15:25:49.229] _job_complete: JobId=48645 WEXITSTATUS 0
[2022-09-01T15:25:49.230] _job_complete: JobId=48645 done
[2022-09-01T15:35:53.164] _slurm_rpc_submit_batch_job: JobId=48646 InitPrio=4128 usec=413
[2022-09-01T15:35:55.314] sched: Allocate JobId=48646 NodeList=cpu01 #CPUs=8 Partition=cpu-opteron
[2022-09-01T15:36:06.379] _job_complete: JobId=48646 WEXITSTATUS 139
[2022-09-01T15:36:06.379] _job_complete: JobId=48646 done
[2022-09-01T15:36:42.119] _slurm_rpc_submit_batch_job: JobId=48647 InitPrio=2752 usec=344
[2022-09-01T15:36:42.378] sched: Allocate JobId=48647 NodeList=cpu08 #CPUs=32 Partition=cpu-opteron
[2022-09-01T15:38:14.248] _slurm_rpc_submit_batch_job: JobId=48648 InitPrio=2752 usec=350
[2022-09-01T15:38:14.587] sched: Allocate JobId=48648 NodeList=cpu08 #CPUs=32 Partition=cpu-opteron
[2022-09-01T15:38:21.269] _job_complete: JobId=48647 WEXITSTATUS 0
[2022-09-01T15:38:21.269] _job_complete: JobId=48647 done
[2022-09-01T15:39:19.010] _slurm_rpc_submit_batch_job: JobId=48649 InitPrio=2752 usec=376
[2022-09-01T15:39:19.675] sched: Allocate JobId=48649 NodeList=cpu08 #CPUs=32 Partition=cpu-opteron
[2022-09-01T15:39:21.988] _job_complete: JobId=48649 WEXITSTATUS 1
[2022-09-01T15:39:21.988] _job_complete: JobId=48649 done
[2022-09-01T15:39:56.676] _job_complete: JobId=48648 WEXITSTATUS 0
[2022-09-01T15:39:56.677] _job_complete: JobId=48648 done
[2022-09-01T15:43:01.264] _slurm_rpc_submit_batch_job: JobId=48650 InitPrio=2752 usec=376
[2022-09-01T15:43:02.084] sched: Allocate JobId=48650 NodeList=cpu08 #CPUs=32 Partition=cpu-opteron
[2022-09-01T15:43:04.477] _job_complete: JobId=48650 WEXITSTATUS 1
[2022-09-01T15:43:04.477] _job_complete: JobId=48650 done
[2022-09-01T15:43:38.004] _slurm_rpc_submit_batch_job: JobId=48651 InitPrio=4816 usec=447
[2022-09-01T15:43:38.148] sched: Allocate JobId=48651 NodeList=gpu04 #CPUs=8 Partition=gpu-k40c
[2022-09-01T15:43:43.034] _job_complete: JobId=48651 WEXITSTATUS 1
[2022-09-01T15:43:43.034] _job_complete: JobId=48651 done
[2022-09-01T15:44:11.949] _slurm_rpc_submit_batch_job: JobId=48652 InitPrio=2752 usec=382
[2022-09-01T15:44:12.180] sched: Allocate JobId=48652 NodeList=cpu08 #CPUs=32 Partition=cpu-opteron
[2022-09-01T15:44:49.303] _slurm_rpc_submit_batch_job: JobId=48653 InitPrio=2752 usec=453
[2022-09-01T15:44:50.234] sched: Allocate JobId=48653 NodeList=cpu08 #CPUs=32 Partition=cpu-opteron
[2022-09-01T15:45:17.308] _slurm_rpc_submit_batch_job: JobId=48654 InitPrio=4128 usec=444
[2022-09-01T15:45:18.271] sched: Allocate JobId=48654 NodeList=cpu01 #CPUs=8 Partition=cpu-opteron
[2022-09-01T15:45:28.522] _job_complete: JobId=48654 WEXITSTATUS 139
[2022-09-01T15:45:28.522] _job_complete: JobId=48654 done
[2022-09-01T15:45:31.536] _slurm_rpc_submit_batch_job: JobId=48655 InitPrio=2752 usec=424
[2022-09-01T15:45:32.291] sched: Allocate JobId=48655 NodeList=cpu09 #CPUs=32 Partition=cpu-opteron
[2022-09-01T15:45:34.622] _job_complete: JobId=48655 WEXITSTATUS 1
[2022-09-01T15:45:34.623] _job_complete: JobId=48655 done
[2022-09-01T15:45:51.670] _job_complete: JobId=48652 WEXITSTATUS 0
[2022-09-01T15:45:51.670] _job_complete: JobId=48652 done
[2022-09-01T15:46:11.068] _slurm_rpc_submit_batch_job: JobId=48656 InitPrio=2752 usec=408
[2022-09-01T15:46:11.346] sched: Allocate JobId=48656 NodeList=cpu08 #CPUs=32 Partition=cpu-opteron
[2022-09-01T15:46:13.499] _job_complete: JobId=48656 WEXITSTATUS 1
[2022-09-01T15:46:13.499] _job_complete: JobId=48656 done
[2022-09-01T15:46:32.786] _job_complete: JobId=48653 WEXITSTATUS 0
[2022-09-01T15:46:32.786] _job_complete: JobId=48653 done
[2022-09-01T15:46:58.997] _slurm_rpc_submit_batch_job: JobId=48657 InitPrio=2752 usec=521
[2022-09-01T15:46:59.414] sched: Allocate JobId=48657 NodeList=cpu08 #CPUs=32 Partition=cpu-opteron
[2022-09-01T15:47:01.531] _job_complete: JobId=48657 WEXITSTATUS 1
[2022-09-01T15:47:01.532] _job_complete: JobId=48657 done
[2022-09-01T15:48:18.458] _slurm_rpc_submit_batch_job: JobId=48658 InitPrio=2752 usec=400
[2022-09-01T15:48:18.618] sched: Allocate JobId=48658 NodeList=cpu08 #CPUs=32 Partition=cpu-opteron
[2022-09-01T15:48:20.918] _job_complete: JobId=48658 WEXITSTATUS 1
[2022-09-01T15:48:20.918] _job_complete: JobId=48658 done
[2022-09-01T15:55:26.352] _slurm_rpc_submit_batch_job: JobId=48659 InitPrio=4128 usec=497
[2022-09-01T15:55:26.369] sched: Allocate JobId=48659 NodeList=cpu01 #CPUs=8 Partition=cpu-opteron
[2022-09-01T16:00:08.757] _job_complete: JobId=48659 WEXITSTATUS 0
[2022-09-01T16:00:08.757] _job_complete: JobId=48659 done
[2022-09-01T16:00:29.289] _slurm_rpc_submit_batch_job: JobId=48660 InitPrio=4816 usec=437
[2022-09-01T16:00:29.865] sched: Allocate JobId=48660 NodeList=gpu04 #CPUs=8 Partition=gpu-k40c
[2022-09-01T16:16:26.401] _slurm_rpc_submit_batch_job: JobId=48661 InitPrio=4128 usec=438
[2022-09-01T16:16:26.529] sched: Allocate JobId=48661 NodeList=cpu01 #CPUs=8 Partition=cpu-opteron
[2022-09-01T16:18:53.209] _job_complete: JobId=48661 WEXITSTATUS 139
[2022-09-01T16:18:53.209] _job_complete: JobId=48661 done
[2022-09-01T16:38:25.423] _slurm_rpc_submit_batch_job: JobId=48662 InitPrio=4128 usec=473
[2022-09-01T16:38:26.131] sched: Allocate JobId=48662 NodeList=cpu08 #CPUs=12 Partition=cpu-opteron
[2022-09-01T16:49:27.811] _slurm_rpc_submit_batch_job: JobId=48663 InitPrio=4128 usec=452
[2022-09-01T16:49:28.181] sched: Allocate JobId=48663 NodeList=cpu01 #CPUs=8 Partition=cpu-opteron
[2022-09-01T16:54:05.048] _job_complete: JobId=48663 WEXITSTATUS 0
[2022-09-01T16:54:05.048] _job_complete: JobId=48663 done
[2022-09-01T17:12:27.994] _slurm_rpc_submit_batch_job: JobId=48664 InitPrio=4128 usec=435
[2022-09-01T17:12:28.365] sched: Allocate JobId=48664 NodeList=cpu08 #CPUs=16 Partition=cpu-opteron
[2022-09-01T17:32:58.956] _slurm_rpc_submit_batch_job: JobId=48665 InitPrio=917 usec=474
[2022-09-01T17:32:59.687] sched: Allocate JobId=48665 NodeList=gpu01 #CPUs=1 Partition=gpu-k10
[2022-09-01T17:33:01.147] _job_complete: JobId=48665 WEXITSTATUS 21
[2022-09-01T17:33:01.147] _job_complete: JobId=48665 done
[2022-09-01T17:34:23.759] _slurm_rpc_submit_batch_job: JobId=48666 InitPrio=917 usec=431
[2022-09-01T17:34:23.781] sched: Allocate JobId=48666 NodeList=gpu01 #CPUs=1 Partition=gpu-k10
[2022-09-01T17:34:25.356] _job_complete: JobId=48666 WEXITSTATUS 0
[2022-09-01T17:34:25.356] _job_complete: JobId=48666 done
[2022-09-01T17:35:04.395] _slurm_rpc_submit_batch_job: JobId=48667 InitPrio=917 usec=467
[2022-09-01T17:35:04.835] sched: Allocate JobId=48667 NodeList=gpu01 #CPUs=1 Partition=gpu-k10
[2022-09-01T17:35:29.265] _job_complete: JobId=48667 WEXITSTATUS 0
[2022-09-01T17:35:29.265] _job_complete: JobId=48667 done
[2022-09-01T18:27:13.165] _job_complete: JobId=48457 WEXITSTATUS 0
[2022-09-01T18:27:13.169] _job_complete: JobId=48457 done
[2022-09-01T18:27:18.414] sched: Allocate JobId=48609 NodeList=cpu09 #CPUs=64 Partition=cpu-opteron
[2022-09-01T19:27:13.035] _slurm_rpc_submit_batch_job: JobId=48668 InitPrio=229 usec=437
[2022-09-01T19:47:05.470] _slurm_rpc_submit_batch_job: JobId=48669 InitPrio=458 usec=520
[2022-09-01T19:47:06.333] sched: Allocate JobId=48669 NodeList=gpu03 #CPUs=16 Partition=gpu-k10
[2022-09-01T19:47:08.232] _job_complete: JobId=48669 WEXITSTATUS 2
[2022-09-01T19:47:08.232] _job_complete: JobId=48669 done
[2022-09-01T19:47:50.711] _slurm_rpc_submit_batch_job: JobId=48670 InitPrio=458 usec=434
[2022-09-01T19:47:51.441] sched: Allocate JobId=48670 NodeList=gpu03 #CPUs=16 Partition=gpu-k10
[2022-09-01T22:18:58.539] _job_complete: JobId=48662 WEXITSTATUS 0
[2022-09-01T22:18:58.539] _job_complete: JobId=48662 done
[2022-09-01T22:20:47.115] _job_complete: JobId=48664 WEXITSTATUS 0
[2022-09-01T22:20:47.115] _job_complete: JobId=48664 done
[2022-09-01T22:47:52.560] _slurm_rpc_submit_batch_job: JobId=48671 InitPrio=917 usec=554
[2022-09-01T22:47:53.389] sched: Allocate JobId=48671 NodeList=gpu02 #CPUs=5 Partition=gpu-titan
[2022-09-01T22:49:17.516] _slurm_rpc_submit_batch_job: JobId=48672 InitPrio=917 usec=435
[2022-09-01T22:49:17.528] sched: Allocate JobId=48672 NodeList=gpu02 #CPUs=5 Partition=gpu-titan
[2022-09-01T22:49:53.032] _job_complete: JobId=48672 WEXITSTATUS 0
[2022-09-01T22:49:53.032] _job_complete: JobId=48672 done
[2022-09-01T23:29:22.182] _slurm_rpc_submit_batch_job: JobId=48673 InitPrio=917 usec=380
[2022-09-01T23:29:22.892] sched: Allocate JobId=48673 NodeList=gpu01 #CPUs=2 Partition=gpu-k10
[2022-09-01T23:29:25.283] _job_complete: JobId=48673 WEXITSTATUS 0
[2022-09-01T23:29:25.283] _job_complete: JobId=48673 done
[2022-09-01T23:31:01.954] _slurm_rpc_submit_batch_job: JobId=48674 InitPrio=917 usec=524
[2022-09-01T23:31:02.027] sched: Allocate JobId=48674 NodeList=gpu01 #CPUs=1 Partition=gpu-k10
[2022-09-01T23:31:27.154] _job_complete: JobId=48674 WEXITSTATUS 0
[2022-09-01T23:31:27.154] _job_complete: JobId=48674 done
[2022-09-01T23:32:29.587] _slurm_rpc_submit_batch_job: JobId=48675 InitPrio=917 usec=641
[2022-09-01T23:32:30.146] sched: Allocate JobId=48675 NodeList=gpu02 #CPUs=5 Partition=gpu-titan
[2022-09-01T23:52:28.683] _job_complete: JobId=48490 WEXITSTATUS 0
[2022-09-01T23:52:28.684] _job_complete: JobId=48490 done
[2022-09-01T23:53:05.468] sched/backfill: _start_job: Started JobId=48492 in cpu-epyc on cpu13
[2022-09-02T00:56:05.539] _job_complete: JobId=48491 WEXITSTATUS 0
[2022-09-02T00:56:05.539] _job_complete: JobId=48491 done
[2022-09-02T00:57:05.542] sched/backfill: _start_job: Started JobId=48616 in cpu-epyc on cpu13
[2022-09-02T04:43:04.468] _job_complete: JobId=48616 WEXITSTATUS 0
[2022-09-02T04:43:04.473] _job_complete: JobId=48616 done
[2022-09-02T10:19:07.341] _slurm_rpc_submit_batch_job: JobId=48676 InitPrio=15045 usec=424
[2022-09-02T10:19:08.077] sched: Allocate JobId=48676 NodeList=cpu13 #CPUs=16 Partition=cpu-epyc
[2022-09-02T10:19:34.443] _slurm_rpc_submit_batch_job: JobId=48677 InitPrio=15045 usec=507
[2022-09-02T10:19:35.093] sched: Allocate JobId=48677 NodeList=cpu08 #CPUs=16 Partition=cpu-opteron
[2022-09-02T10:37:03.615] _job_complete: JobId=48676 WEXITSTATUS 0
[2022-09-02T10:37:03.616] _job_complete: JobId=48676 done
[2022-09-02T11:19:37.522] Time limit exhausted for JobId=48677
[2022-09-02T12:50:10.883] _job_complete: JobId=48670 WEXITSTATUS 0
[2022-09-02T12:50:10.883] _job_complete: JobId=48670 done
[2022-09-02T14:46:47.840] _slurm_rpc_submit_batch_job: JobId=48678 InitPrio=458 usec=535
[2022-09-02T14:46:48.772] sched: Allocate JobId=48678 NodeList=gpu03 #CPUs=16 Partition=gpu-k10
[2022-09-02T14:47:28.047] _job_complete: JobId=48678 WEXITSTATUS 1
[2022-09-02T14:47:28.047] _job_complete: JobId=48678 done
[2022-09-02T14:53:11.605] _slurm_rpc_submit_batch_job: JobId=48679 InitPrio=458 usec=434
[2022-09-02T14:53:12.530] sched: Allocate JobId=48679 NodeList=gpu03 #CPUs=16 Partition=gpu-k10
[2022-09-02T14:57:42.123] _job_complete: JobId=48679 WEXITSTATUS 1
[2022-09-02T14:57:42.124] _job_complete: JobId=48679 done
[2022-09-02T15:05:03.486] _slurm_rpc_submit_batch_job: JobId=48680 InitPrio=458 usec=464
[2022-09-02T15:05:03.666] sched: Allocate JobId=48680 NodeList=gpu03 #CPUs=16 Partition=gpu-k10
[2022-09-02T15:11:03.970] _job_complete: JobId=48680 WEXITSTATUS 0
[2022-09-02T15:11:03.970] _job_complete: JobId=48680 done
[2022-09-02T15:24:58.407] _slurm_rpc_submit_batch_job: JobId=48681 InitPrio=2752 usec=412
[2022-09-02T15:25:06.227] sched/backfill: _start_job: Started JobId=48681 in cpu-epyc on cpu13
[2022-09-02T15:34:01.809] _slurm_rpc_submit_batch_job: JobId=48682 InitPrio=2752 usec=869
[2022-09-02T15:34:01.879] sched: Allocate JobId=48682 NodeList=gpu01 #CPUs=16 Partition=gpu-k10
[2022-09-02T15:37:52.411] _slurm_rpc_submit_batch_job: JobId=48683 InitPrio=2752 usec=1077
[2022-09-02T15:37:53.278] sched: Allocate JobId=48683 NodeList=gpu03 #CPUs=16 Partition=gpu-k10
[2022-09-02T15:58:05.606] _slurm_rpc_submit_batch_job: JobId=48684 InitPrio=458 usec=467
[2022-09-02T16:00:38.596] Time limit exhausted for JobId=48660
[2022-09-02T16:16:18.049] _slurm_rpc_submit_batch_job: JobId=48685 InitPrio=3211 usec=441
[2022-09-02T16:16:18.230] sched: Allocate JobId=48685 NodeList=gpu04 #CPUs=8 Partition=gpu-k40c
[2022-09-02T16:37:41.685] _slurm_rpc_submit_batch_job: JobId=48686 InitPrio=456 usec=449
[2022-09-02T16:49:16.395] _slurm_rpc_submit_batch_job: JobId=48687 InitPrio=454 usec=506
[2022-09-02T16:58:50.436] _slurm_rpc_submit_batch_job: JobId=48688 InitPrio=454 usec=461
[2022-09-02T17:05:43.928] _slurm_rpc_submit_batch_job: JobId=48689 InitPrio=454 usec=454
[2022-09-02T19:31:30.224] sched: _slurm_rpc_allocate_resources JobId=48690 NodeList=(null) usec=900
[2022-09-02T19:31:30.690] sched: Allocate JobId=48690 NodeList=cpu01 #CPUs=1 Partition=cpu-opteron
[2022-09-02T19:46:51.482] _job_complete: JobId=48681 WEXITSTATUS 0
[2022-09-02T19:46:51.487] _job_complete: JobId=48681 done
[2022-09-02T21:41:54.007] _job_complete: JobId=48492 WEXITSTATUS 0
[2022-09-02T21:41:54.007] _job_complete: JobId=48492 done
[2022-09-02T21:41:54.479] sched: Allocate JobId=48554 NodeList=cpu13 #CPUs=24 Partition=cpu-epyc
[2022-09-02T21:42:00.669] _job_complete: JobId=48554 WEXITSTATUS 1
[2022-09-02T21:42:00.669] _job_complete: JobId=48554 done
[2022-09-02T21:42:01.083] sched: Allocate JobId=48549 NodeList=cpu13 #CPUs=48 Partition=cpu-epyc
[2022-09-02T22:06:01.839] _slurm_rpc_submit_batch_job: JobId=48691 InitPrio=909 usec=549
[2022-09-02T22:07:10.392] _slurm_rpc_submit_batch_job: JobId=48692 InitPrio=909 usec=428
[2022-09-02T22:09:15.781] _slurm_rpc_submit_batch_job: JobId=48693 InitPrio=909 usec=397
[2022-09-02T22:10:19.252] _slurm_rpc_submit_batch_job: JobId=48694 InitPrio=909 usec=492
[2022-09-02T22:11:22.784] _slurm_rpc_submit_batch_job: JobId=48695 InitPrio=909 usec=419
[2022-09-02T23:36:30.685] _slurm_rpc_submit_batch_job: JobId=48696 InitPrio=12272 usec=482
[2022-09-03T00:35:39.097] _job_complete: JobId=48690 WEXITSTATUS 0
[2022-09-03T00:35:39.098] _job_complete: JobId=48690 done
[2022-09-03T00:40:40.651] cleanup_completing: JobId=48690 completion process took 301 seconds
[2022-09-03T02:25:58.313] _slurm_rpc_submit_batch_job: JobId=48697 InitPrio=2727 usec=917
[2022-09-03T02:26:16.056] _slurm_rpc_kill_job: REQUEST_KILL_JOB JobId=48683 uid 548200029
[2022-09-03T02:26:22.224] sched: Allocate JobId=48697 NodeList=gpu03 #CPUs=16 Partition=gpu-k10
[2022-09-03T06:36:47.693] _job_complete: JobId=48620 WEXITSTATUS 0
[2022-09-03T06:36:47.694] _job_complete: JobId=48620 done
[2022-09-03T07:32:45.778] _job_complete: JobId=48682 WEXITSTATUS 1
[2022-09-03T07:32:45.783] _job_complete: JobId=48682 done
[2022-09-03T08:46:43.497] _slurm_rpc_kill_job: REQUEST_KILL_JOB JobId=48696 uid 548300595
[2022-09-03T08:47:47.260] _slurm_rpc_submit_batch_job: JobId=48698 InitPrio=12272 usec=430
[2022-09-03T11:37:55.260] _slurm_rpc_submit_batch_job: JobId=48699 InitPrio=909 usec=515
[2022-09-03T11:37:55.942] sched: Allocate JobId=48699 NodeList=gpu02 #CPUs=2 Partition=gpu-titan
[2022-09-03T11:37:56.895] _job_complete: JobId=48699 WEXITSTATUS 31
[2022-09-03T11:37:56.895] _job_complete: JobId=48699 done
[2022-09-03T11:38:56.445] _slurm_rpc_submit_batch_job: JobId=48700 InitPrio=909 usec=603
[2022-09-03T11:38:57.049] sched: Allocate JobId=48700 NodeList=gpu02 #CPUs=2 Partition=gpu-titan
[2022-09-03T11:38:58.046] _job_complete: JobId=48700 WEXITSTATUS 0
[2022-09-03T11:38:58.046] _job_complete: JobId=48700 done
[2022-09-03T11:40:54.505] _slurm_rpc_submit_batch_job: JobId=48701 InitPrio=909 usec=371
[2022-09-03T11:40:55.209] sched: Allocate JobId=48701 NodeList=gpu02 #CPUs=2 Partition=gpu-titan
[2022-09-03T11:41:20.178] _job_complete: JobId=48701 WEXITSTATUS 0
[2022-09-03T11:41:20.178] _job_complete: JobId=48701 done
[2022-09-03T11:41:34.022] _slurm_rpc_submit_batch_job: JobId=48702 InitPrio=909 usec=458
[2022-09-03T11:41:34.262] sched: Allocate JobId=48702 NodeList=gpu02 #CPUs=5 Partition=gpu-titan
[2022-09-03T11:42:10.542] _job_complete: JobId=48702 WEXITSTATUS 0
[2022-09-03T11:42:10.542] _job_complete: JobId=48702 done
[2022-09-03T11:42:36.119] _slurm_rpc_submit_batch_job: JobId=48703 InitPrio=909 usec=421
[2022-09-03T11:42:36.346] sched: Allocate JobId=48703 NodeList=gpu02 #CPUs=2 Partition=gpu-titan
[2022-09-03T11:42:37.817] _job_complete: JobId=48703 WEXITSTATUS 0
[2022-09-03T11:42:37.817] _job_complete: JobId=48703 done
[2022-09-03T11:43:43.255] _slurm_rpc_submit_batch_job: JobId=48704 InitPrio=909 usec=381
[2022-09-03T11:43:43.518] sched: Allocate JobId=48704 NodeList=gpu02 #CPUs=1 Partition=gpu-titan
[2022-09-03T11:44:08.576] _job_complete: JobId=48704 WEXITSTATUS 0
[2022-09-03T11:44:08.576] _job_complete: JobId=48704 done
[2022-09-03T11:48:38.554] _slurm_rpc_submit_batch_job: JobId=48705 InitPrio=909 usec=542
[2022-09-03T11:48:39.011] sched: Allocate JobId=48705 NodeList=gpu02 #CPUs=6 Partition=gpu-titan
[2022-09-03T11:48:50.899] _slurm_rpc_kill_job: REQUEST_KILL_JOB JobId=48675 uid 548200023
[2022-09-03T11:49:10.543] _slurm_rpc_kill_job: REQUEST_KILL_JOB JobId=48795 uid 548200023
[2022-09-03T11:49:10.543] job_str_signal(3): invalid JobId=48795
[2022-09-03T11:49:10.543] _slurm_rpc_kill_job: job_str_signal() uid=548200023 JobId=48795 sig=9 returned: Invalid job id specified
[2022-09-03T11:49:22.958] _slurm_rpc_kill_job: REQUEST_KILL_JOB JobId=48705 uid 548200023
[2022-09-03T12:27:55.873] _slurm_rpc_submit_batch_job: JobId=48706 InitPrio=2727 usec=848
[2022-09-03T12:27:56.344] sched: Allocate JobId=48706 NodeList=gpu01 #CPUs=16 Partition=gpu-k10
[2022-09-03T12:53:46.247] _slurm_rpc_submit_batch_job: JobId=48707 InitPrio=2272 usec=424
[2022-09-03T12:53:47.073] sched: Allocate JobId=48707 NodeList=cpu01 #CPUs=1 Partition=cpu-opteron
[2022-09-03T13:05:32.217] _slurm_rpc_submit_batch_job: JobId=48708 InitPrio=2727 usec=439
[2022-09-03T13:05:33.196] sched: Allocate JobId=48708 NodeList=cpu01 #CPUs=8 Partition=cpu-opteron
[2022-09-03T13:05:44.043] _job_complete: JobId=48708 WEXITSTATUS 1
[2022-09-03T13:05:44.044] _job_complete: JobId=48708 done
[2022-09-03T13:06:19.618] _slurm_rpc_submit_batch_job: JobId=48709 InitPrio=2727 usec=410
[2022-09-03T13:07:26.551] _slurm_rpc_submit_batch_job: JobId=48710 InitPrio=2727 usec=380
[2022-09-03T13:07:27.347] sched: Allocate JobId=48710 NodeList=cpu01 #CPUs=8 Partition=cpu-opteron
[2022-09-03T13:08:39.966] _slurm_rpc_submit_batch_job: JobId=48711 InitPrio=2727 usec=411
[2022-09-03T13:08:40.541] sched: Allocate JobId=48711 NodeList=cpu01 #CPUs=8 Partition=cpu-opteron
[2022-09-03T13:09:20.253] _slurm_rpc_submit_batch_job: JobId=48712 InitPrio=2727 usec=393
[2022-09-03T13:09:20.597] sched: Allocate JobId=48712 NodeList=cpu01 #CPUs=8 Partition=cpu-opteron
[2022-09-03T13:09:54.441] _slurm_rpc_submit_batch_job: JobId=48713 InitPrio=2727 usec=448
[2022-09-03T13:10:52.082] _slurm_rpc_submit_batch_job: JobId=48714 InitPrio=909 usec=414
[2022-09-03T13:10:52.747] sched: Allocate JobId=48714 NodeList=gpu02 #CPUs=2 Partition=gpu-titan
[2022-09-03T13:10:53.366] _job_complete: JobId=48714 WEXITSTATUS 31
[2022-09-03T13:10:53.366] _job_complete: JobId=48714 done
[2022-09-03T13:11:09.905] _slurm_rpc_submit_batch_job: JobId=48715 InitPrio=909 usec=531
[2022-09-03T13:11:10.754] sched: Allocate JobId=48715 NodeList=gpu02 #CPUs=2 Partition=gpu-titan
[2022-09-03T13:11:11.735] _job_complete: JobId=48715 WEXITSTATUS 0
[2022-09-03T13:11:11.735] _job_complete: JobId=48715 done
[2022-09-03T13:11:37.628] _slurm_rpc_submit_batch_job: JobId=48716 InitPrio=909 usec=469
[2022-09-03T13:11:37.790] sched: Allocate JobId=48716 NodeList=gpu02 #CPUs=2 Partition=gpu-titan
[2022-09-03T13:11:58.962] _job_complete: JobId=48711 WEXITSTATUS 1
[2022-09-03T13:11:58.963] _job_complete: JobId=48711 done
[2022-09-03T13:12:02.498] _job_complete: JobId=48716 WEXITSTATUS 0
[2022-09-03T13:12:02.498] _job_complete: JobId=48716 done
[2022-09-03T13:12:50.075] _slurm_rpc_submit_batch_job: JobId=48717 InitPrio=909 usec=603
[2022-09-03T13:12:50.984] sched: Allocate JobId=48717 NodeList=gpu02 #CPUs=5 Partition=gpu-titan
[2022-09-03T13:13:25.947] _job_complete: JobId=48717 WEXITSTATUS 0
[2022-09-03T13:13:25.947] _job_complete: JobId=48717 done
[2022-09-03T13:13:30.241] _slurm_rpc_submit_batch_job: JobId=48718 InitPrio=909 usec=519
[2022-09-03T13:13:31.080] sched: Allocate JobId=48718 NodeList=gpu02 #CPUs=2 Partition=gpu-titan
[2022-09-03T13:13:32.316] _job_complete: JobId=48718 WEXITSTATUS 0
[2022-09-03T13:13:32.316] _job_complete: JobId=48718 done
[2022-09-03T13:14:14.185] _slurm_rpc_submit_batch_job: JobId=48719 InitPrio=909 usec=425
[2022-09-03T13:14:15.144] sched: Allocate JobId=48719 NodeList=gpu02 #CPUs=1 Partition=gpu-titan
[2022-09-03T13:14:39.618] _job_complete: JobId=48719 WEXITSTATUS 0
[2022-09-03T13:14:39.618] _job_complete: JobId=48719 done
[2022-09-03T13:15:08.069] _slurm_rpc_submit_batch_job: JobId=48720 InitPrio=909 usec=604
[2022-09-03T13:15:08.218] sched: Allocate JobId=48720 NodeList=gpu02 #CPUs=6 Partition=gpu-titan
[2022-09-03T13:16:34.141] _job_complete: JobId=48707 WEXITSTATUS 0
[2022-09-03T13:16:34.143] _job_complete: JobId=48707 done
[2022-09-03T13:16:48.286] _slurm_rpc_submit_batch_job: JobId=48721 InitPrio=909 usec=523
[2022-09-03T13:30:01.780] _slurm_rpc_submit_batch_job: JobId=48722 InitPrio=2272 usec=437
[2022-09-03T13:30:02.747] sched: Allocate JobId=48722 NodeList=cpu01 #CPUs=1 Partition=cpu-opteron
[2022-09-03T13:49:48.729] _job_complete: JobId=48722 WEXITSTATUS 0
[2022-09-03T13:49:48.730] _job_complete: JobId=48722 done
[2022-09-03T14:10:12.547] sched: _slurm_rpc_allocate_resources JobId=48723 NodeList=(null) usec=741
[2022-09-03T14:10:13.009] sched: Allocate JobId=48723 NodeList=cpu01 #CPUs=1 Partition=cpu-opteron
[2022-09-03T14:28:12.107] _job_complete: JobId=48710 WEXITSTATUS 0
[2022-09-03T14:28:12.108] _job_complete: JobId=48710 done
[2022-09-03T14:32:21.858] _slurm_rpc_submit_batch_job: JobId=48724 InitPrio=2272 usec=426
[2022-09-03T14:32:22.168] sched: Allocate JobId=48724 NodeList=cpu01 #CPUs=1 Partition=cpu-opteron
[2022-09-03T14:37:26.690] _job_complete: JobId=48712 WEXITSTATUS 0
[2022-09-03T14:37:26.690] _job_complete: JobId=48712 done
[2022-09-03T14:45:12.599] _job_complete: JobId=48724 WEXITSTATUS 0
[2022-09-03T14:45:12.600] _job_complete: JobId=48724 done
[2022-09-03T14:48:14.989] _slurm_rpc_submit_batch_job: JobId=48725 InitPrio=2272 usec=407
[2022-09-03T14:48:15.797] sched: Allocate JobId=48725 NodeList=cpu01 #CPUs=1 Partition=cpu-opteron
[2022-09-03T15:42:19.438] _job_complete: JobId=48725 WEXITSTATUS 0
[2022-09-03T15:42:19.439] _job_complete: JobId=48725 done
[2022-09-03T18:56:09.028] _slurm_rpc_submit_batch_job: JobId=48726 InitPrio=12272 usec=470
[2022-09-03T18:56:09.277] sched: Allocate JobId=48726 NodeList=cpu01 #CPUs=1 Partition=cpu-opteron
[2022-09-03T19:03:21.648] _job_complete: JobId=48726 WEXITSTATUS 0
[2022-09-03T19:03:21.649] _job_complete: JobId=48726 done
[2022-09-03T19:07:06.618] _slurm_rpc_submit_batch_job: JobId=48727 InitPrio=2272 usec=412
[2022-09-03T19:07:07.379] sched: Allocate JobId=48727 NodeList=cpu08 #CPUs=64 Partition=cpu-opteron
[2022-09-03T21:38:50.072] _slurm_rpc_submit_batch_job: JobId=48728 InitPrio=227 usec=421
[2022-09-03T22:09:34.670] _job_complete: JobId=48723 WEXITSTATUS 0
[2022-09-03T22:09:34.671] _job_complete: JobId=48723 done
[2022-09-03T22:14:35.012] cleanup_completing: JobId=48723 completion process took 301 seconds
[2022-09-04T00:39:04.120] _slurm_rpc_submit_batch_job: JobId=48729 InitPrio=2727 usec=461
[2022-09-04T00:39:04.876] sched: Allocate JobId=48729 NodeList=cpu01 #CPUs=8 Partition=cpu-opteron
[2022-09-04T00:39:13.227] _job_complete: JobId=48729 WEXITSTATUS 1
[2022-09-04T00:39:13.228] _job_complete: JobId=48729 done
[2022-09-04T00:39:40.633] _slurm_rpc_kill_job: REQUEST_KILL_JOB JobId=48709 uid 548200029
[2022-09-04T00:39:51.476] _slurm_rpc_kill_job: REQUEST_KILL_JOB JobId=48713 uid 548200029
[2022-09-04T00:40:09.509] _slurm_rpc_submit_batch_job: JobId=48730 InitPrio=2727 usec=386
[2022-09-04T00:40:09.947] sched: Allocate JobId=48730 NodeList=cpu01 #CPUs=8 Partition=cpu-opteron
[2022-09-04T00:43:07.794] _slurm_rpc_submit_batch_job: JobId=48731 InitPrio=2727 usec=397
[2022-09-04T00:43:08.310] sched: Allocate JobId=48731 NodeList=cpu01 #CPUs=8 Partition=cpu-opteron
[2022-09-04T00:43:31.325] _slurm_rpc_submit_batch_job: JobId=48732 InitPrio=2727 usec=402
[2022-09-04T00:43:31.342] sched: Allocate JobId=48732 NodeList=cpu01 #CPUs=8 Partition=cpu-opteron
[2022-09-04T00:44:07.080] _slurm_rpc_submit_batch_job: JobId=48733 InitPrio=2727 usec=403
[2022-09-04T00:44:07.393] sched: Allocate JobId=48733 NodeList=cpu01 #CPUs=8 Partition=cpu-opteron
[2022-09-04T00:45:59.332] _slurm_rpc_kill_job: REQUEST_KILL_JOB JobId=48732 uid 548200029
[2022-09-04T00:46:04.162] _slurm_rpc_kill_job: REQUEST_KILL_JOB JobId=48731 uid 548200029
[2022-09-04T00:46:05.979] _slurm_rpc_kill_job: REQUEST_KILL_JOB JobId=48730 uid 548200029
[2022-09-04T00:47:20.146] _slurm_rpc_kill_job: REQUEST_KILL_JOB JobId=48733 uid 548200029
[2022-09-04T00:47:26.835] _slurm_rpc_submit_batch_job: JobId=48734 InitPrio=2727 usec=503
[2022-09-04T00:47:27.662] sched: Allocate JobId=48734 NodeList=cpu01 #CPUs=8 Partition=cpu-opteron
[2022-09-04T00:47:47.019] _slurm_rpc_submit_batch_job: JobId=48735 InitPrio=2727 usec=409
[2022-09-04T00:47:47.758] sched: Allocate JobId=48735 NodeList=cpu01 #CPUs=8 Partition=cpu-opteron
[2022-09-04T00:50:45.211] _slurm_rpc_submit_batch_job: JobId=48736 InitPrio=2727 usec=485
[2022-09-04T00:50:46.051] sched: Allocate JobId=48736 NodeList=cpu01 #CPUs=8 Partition=cpu-opteron
[2022-09-04T00:51:21.570] _slurm_rpc_submit_batch_job: JobId=48737 InitPrio=2727 usec=498
[2022-09-04T00:51:22.093] sched: Allocate JobId=48737 NodeList=cpu01 #CPUs=8 Partition=cpu-opteron
[2022-09-04T00:52:52.339] _slurm_rpc_submit_batch_job: JobId=48738 InitPrio=2727 usec=444
[2022-09-04T00:52:53.270] sched: Allocate JobId=48738 NodeList=cpu01 #CPUs=8 Partition=cpu-opteron
[2022-09-04T01:09:02.781] _slurm_rpc_submit_batch_job: JobId=48739 InitPrio=2727 usec=572
[2022-09-04T01:09:04.660] sched: Allocate JobId=48739 NodeList=cpu10 #CPUs=32 Partition=cpu-opteron
[2022-09-04T01:10:23.088] _slurm_rpc_submit_batch_job: JobId=48740 InitPrio=2727 usec=402
[2022-09-04T01:10:23.757] sched: Allocate JobId=48740 NodeList=cpu10 #CPUs=32 Partition=cpu-opteron
[2022-09-04T01:10:26.477] _job_complete: JobId=48740 WEXITSTATUS 1
[2022-09-04T01:10:26.478] _job_complete: JobId=48740 done
[2022-09-04T01:10:48.834] _job_complete: JobId=48739 WEXITSTATUS 0
[2022-09-04T01:10:48.835] _job_complete: JobId=48739 done
[2022-09-04T01:14:09.913] _slurm_rpc_submit_batch_job: JobId=48741 InitPrio=2727 usec=446
[2022-09-04T01:14:10.272] sched: Allocate JobId=48741 NodeList=cpu10 #CPUs=32 Partition=cpu-opteron
[2022-09-04T01:14:13.271] _job_complete: JobId=48741 WEXITSTATUS 1
[2022-09-04T01:14:13.271] _job_complete: JobId=48741 done
[2022-09-04T01:14:43.430] _slurm_rpc_submit_batch_job: JobId=48742 InitPrio=2727 usec=424
[2022-09-04T01:14:44.318] sched: Allocate JobId=48742 NodeList=cpu10 #CPUs=32 Partition=cpu-opteron
[2022-09-04T01:14:46.539] _job_complete: JobId=48742 WEXITSTATUS 1
[2022-09-04T01:14:46.540] _job_complete: JobId=48742 done
[2022-09-04T01:16:35.713] _slurm_rpc_submit_batch_job: JobId=48743 InitPrio=2727 usec=348
[2022-09-04T01:16:36.471] sched: Allocate JobId=48743 NodeList=cpu10 #CPUs=32 Partition=cpu-opteron
[2022-09-04T01:16:39.719] _job_complete: JobId=48743 WEXITSTATUS 1
[2022-09-04T01:16:39.720] _job_complete: JobId=48743 done
[2022-09-04T01:17:01.406] _slurm_rpc_submit_batch_job: JobId=48744 InitPrio=2727 usec=400
[2022-09-04T01:17:01.503] sched: Allocate JobId=48744 NodeList=cpu10 #CPUs=32 Partition=cpu-opteron
[2022-09-04T01:17:03.709] _job_complete: JobId=48744 WEXITSTATUS 1
[2022-09-04T01:17:03.709] _job_complete: JobId=48744 done
[2022-09-04T01:17:49.436] _slurm_rpc_submit_batch_job: JobId=48745 InitPrio=2727 usec=414
[2022-09-04T01:17:49.609] sched: Allocate JobId=48745 NodeList=cpu10 #CPUs=32 Partition=cpu-opteron
[2022-09-04T01:17:51.949] _job_complete: JobId=48745 WEXITSTATUS 1
[2022-09-04T01:17:51.949] _job_complete: JobId=48745 done
[2022-09-04T01:18:25.192] _slurm_rpc_kill_job: REQUEST_KILL_JOB JobId=48745 uid 548200029
[2022-09-04T01:18:35.387] _slurm_rpc_submit_batch_job: JobId=48746 InitPrio=2727 usec=421
[2022-09-04T01:18:35.715] sched: Allocate JobId=48746 NodeList=cpu10 #CPUs=32 Partition=cpu-opteron
[2022-09-04T01:18:37.905] _job_complete: JobId=48746 WEXITSTATUS 1
[2022-09-04T01:18:37.906] _job_complete: JobId=48746 done
[2022-09-04T01:19:34.646] _slurm_rpc_submit_batch_job: JobId=48747 InitPrio=2727 usec=410
[2022-09-04T01:19:34.801] sched: Allocate JobId=48747 NodeList=cpu10 #CPUs=32 Partition=cpu-opteron
[2022-09-04T01:19:37.058] _job_complete: JobId=48747 WEXITSTATUS 1
[2022-09-04T01:19:37.059] _job_complete: JobId=48747 done
[2022-09-04T01:28:20.886] _slurm_rpc_submit_batch_job: JobId=48748 InitPrio=2727 usec=480
[2022-09-04T01:28:21.683] sched: Allocate JobId=48748 NodeList=cpu10 #CPUs=32 Partition=cpu-opteron
[2022-09-04T01:29:15.262] _job_complete: JobId=48748 WEXITSTATUS 0
[2022-09-04T01:29:15.263] _job_complete: JobId=48748 done
[2022-09-04T01:31:51.682] _slurm_rpc_submit_batch_job: JobId=48749 InitPrio=2727 usec=439
[2022-09-04T01:31:51.971] sched: Allocate JobId=48749 NodeList=cpu10 #CPUs=32 Partition=cpu-opteron
[2022-09-04T01:31:54.397] _job_complete: JobId=48749 WEXITSTATUS 1
[2022-09-04T01:31:54.398] _job_complete: JobId=48749 done
[2022-09-04T01:41:33.759] _slurm_rpc_submit_batch_job: JobId=48750 InitPrio=2727 usec=533
[2022-09-04T01:41:33.986] sched: Allocate JobId=48750 NodeList=cpu10 #CPUs=32 Partition=cpu-opteron
[2022-09-04T01:41:36.700] _job_complete: JobId=48750 WEXITSTATUS 1
[2022-09-04T01:41:36.700] _job_complete: JobId=48750 done
[2022-09-04T01:43:52.894] _slurm_rpc_submit_batch_job: JobId=48751 InitPrio=2727 usec=415
[2022-09-04T01:43:53.277] sched: Allocate JobId=48751 NodeList=cpu10 #CPUs=32 Partition=cpu-opteron
[2022-09-04T01:43:55.999] _job_complete: JobId=48751 WEXITSTATUS 1
[2022-09-04T01:43:56.000] _job_complete: JobId=48751 done
[2022-09-04T01:47:58.172] _slurm_rpc_submit_batch_job: JobId=48752 InitPrio=2727 usec=442
[2022-09-04T01:47:58.667] sched: Allocate JobId=48752 NodeList=cpu10 #CPUs=32 Partition=cpu-opteron
[2022-09-04T01:49:29.684] _job_complete: JobId=48752 WEXITSTATUS 0
[2022-09-04T01:49:29.684] _job_complete: JobId=48752 done
[2022-09-04T01:50:07.987] _slurm_rpc_submit_batch_job: JobId=48753 InitPrio=2727 usec=433
[2022-09-04T01:50:08.807] sched/backfill: _start_job: Started JobId=48753 in cpu-opteron on cpu10
[2022-09-04T01:51:38.283] _job_complete: JobId=48753 WEXITSTATUS 0
[2022-09-04T01:51:38.284] _job_complete: JobId=48753 done
[2022-09-04T01:55:50.892] _slurm_rpc_submit_batch_job: JobId=48754 InitPrio=2727 usec=379
[2022-09-04T01:55:51.481] sched: Allocate JobId=48754 NodeList=cpu10 #CPUs=32 Partition=cpu-opteron
[2022-09-04T01:57:16.844] _job_complete: JobId=48754 WEXITSTATUS 0
[2022-09-04T01:57:16.844] _job_complete: JobId=48754 done
[2022-09-04T01:58:23.200] _slurm_rpc_submit_batch_job: JobId=48755 InitPrio=2727 usec=413
[2022-09-04T01:58:23.770] sched: Allocate JobId=48755 NodeList=cpu10 #CPUs=32 Partition=cpu-opteron
[2022-09-04T01:59:47.427] _job_complete: JobId=48755 WEXITSTATUS 0
[2022-09-04T01:59:47.428] _job_complete: JobId=48755 done
[2022-09-04T02:02:10.165] _slurm_rpc_submit_batch_job: JobId=48756 InitPrio=2727 usec=433
[2022-09-04T02:02:11.055] sched: Allocate JobId=48756 NodeList=cpu10 #CPUs=32 Partition=cpu-opteron
[2022-09-04T02:02:39.787] _slurm_rpc_submit_batch_job: JobId=48757 InitPrio=2727 usec=501
[2022-09-04T02:02:40.087] sched: Allocate JobId=48757 NodeList=cpu10 #CPUs=32 Partition=cpu-opteron
[2022-09-04T02:03:20.383] _slurm_rpc_submit_batch_job: JobId=48758 InitPrio=2727 usec=452
[2022-09-04T02:03:35.556] _job_complete: JobId=48756 WEXITSTATUS 0
[2022-09-04T02:03:35.556] _job_complete: JobId=48756 done
[2022-09-04T02:03:36.821] sched: Allocate JobId=48758 NodeList=cpu10 #CPUs=32 Partition=cpu-opteron
[2022-09-04T02:03:50.912] _slurm_rpc_submit_batch_job: JobId=48759 InitPrio=2727 usec=536
[2022-09-04T02:04:05.178] _job_complete: JobId=48757 WEXITSTATUS 0
[2022-09-04T02:04:05.179] _job_complete: JobId=48757 done
[2022-09-04T02:04:05.932] sched: Allocate JobId=48759 NodeList=cpu10 #CPUs=32 Partition=cpu-opteron
[2022-09-04T02:04:54.697] _job_complete: JobId=48758 WEXITSTATUS 0
[2022-09-04T02:04:54.698] _job_complete: JobId=48758 done
[2022-09-04T02:05:24.353] _job_complete: JobId=48759 WEXITSTATUS 0
[2022-09-04T02:05:24.353] _job_complete: JobId=48759 done
[2022-09-04T02:24:17.464] _job_complete: JobId=48735 WEXITSTATUS 0
[2022-09-04T02:24:17.465] _job_complete: JobId=48735 done
[2022-09-04T02:25:36.057] _job_complete: JobId=48737 WEXITSTATUS 0
[2022-09-04T02:25:36.058] _job_complete: JobId=48737 done
[2022-09-04T02:31:32.399] _job_complete: JobId=48738 WEXITSTATUS 0
[2022-09-04T02:31:32.400] _job_complete: JobId=48738 done
[2022-09-04T02:51:54.706] _job_complete: JobId=48685 WEXITSTATUS 0
[2022-09-04T02:51:54.712] _job_complete: JobId=48685 done
[2022-09-04T03:07:43.654] Time limit exhausted for JobId=48459
[2022-09-04T03:07:46.860] sched: Allocate JobId=48698 NodeList=cpu12 #CPUs=24 Partition=cpu-epyc
[2022-09-04T04:08:13.122] Time limit exhausted for JobId=48698
[2022-09-04T04:08:23.208] sched: Allocate JobId=48691 NodeList=cpu12 #CPUs=24 Partition=cpu-epyc
[2022-09-04T04:08:23.209] sched: Allocate JobId=48692 NodeList=cpu12 #CPUs=24 Partition=cpu-epyc
[2022-09-04T07:18:43.662] Time limit exhausted for JobId=48460
[2022-09-04T07:18:46.854] sched: Allocate JobId=48668 NodeList=cpu10 #CPUs=64 Partition=cpu-opteron
[2022-09-04T07:18:46.871] sched: Allocate JobId=48693 NodeList=cpu14 #CPUs=24 Partition=cpu-epyc
[2022-09-04T07:18:46.872] sched: Allocate JobId=48694 NodeList=cpu14 #CPUs=24 Partition=cpu-epyc
[2022-09-04T07:18:55.954] _job_complete: JobId=48693 WEXITSTATUS 1
[2022-09-04T07:18:55.954] _job_complete: JobId=48693 done
[2022-09-04T07:18:56.531] sched: Allocate JobId=48695 NodeList=cpu14 #CPUs=24 Partition=cpu-epyc
[2022-09-04T09:33:56.870] _slurm_rpc_submit_batch_job: JobId=48760 InitPrio=2272 usec=427
[2022-09-04T09:43:43.814] _slurm_rpc_submit_batch_job: JobId=48761 InitPrio=227 usec=500
[2022-09-04T09:50:08.225] _slurm_rpc_submit_batch_job: JobId=48762 InitPrio=227 usec=341
[2022-09-04T10:53:44.078] _slurm_rpc_submit_batch_job: JobId=48763 InitPrio=13181 usec=339
[2022-09-04T10:53:45.005] sched: Allocate JobId=48763 NodeList=gpu04 #CPUs=1 Partition=gpu-k40c
[2022-09-04T11:12:55.058] _job_complete: JobId=48671 WEXITSTATUS 0
[2022-09-04T11:12:55.058] _job_complete: JobId=48671 done
[2022-09-04T11:32:26.867] _slurm_rpc_kill_job: REQUEST_KILL_JOB JobId=48763 uid 548300565
[2022-09-04T11:49:47.222] _slurm_rpc_submit_batch_job: JobId=48764 InitPrio=2500 usec=431
[2022-09-04T11:49:47.673] sched: Allocate JobId=48764 NodeList=cpu01 #CPUs=8 Partition=cpu-opteron
[2022-09-04T11:51:02.163] _slurm_rpc_submit_batch_job: JobId=48765 InitPrio=2500 usec=423
[2022-09-04T11:51:04.757] sched: Allocate JobId=48765 NodeList=cpu01 #CPUs=8 Partition=cpu-opteron
[2022-09-04T11:51:54.599] _job_complete: JobId=48668 WEXITSTATUS 0
[2022-09-04T11:51:54.604] _job_complete: JobId=48668 done
[2022-09-04T11:52:00.927] sched: Allocate JobId=48728 NodeList=cpu10 #CPUs=64 Partition=cpu-opteron
[2022-09-04T11:59:13.667] _slurm_rpc_submit_batch_job: JobId=48766 InitPrio=2500 usec=423
[2022-09-04T12:00:20.754] _slurm_rpc_submit_batch_job: JobId=48767 InitPrio=2500 usec=370
[2022-09-04T12:01:34.886] _slurm_rpc_submit_batch_job: JobId=48768 InitPrio=2500 usec=430
[2022-09-04T12:02:53.665] _slurm_rpc_submit_batch_job: JobId=48769 InitPrio=2500 usec=476
[2022-09-04T12:04:04.459] _slurm_rpc_submit_batch_job: JobId=48770 InitPrio=2500 usec=376
[2022-09-04T12:04:58.470] _slurm_rpc_submit_batch_job: JobId=48771 InitPrio=2500 usec=386
[2022-09-04T12:05:54.088] _slurm_rpc_submit_batch_job: JobId=48772 InitPrio=2500 usec=367
[2022-09-04T12:58:24.709] _job_complete: JobId=48736 WEXITSTATUS 0
[2022-09-04T12:58:24.710] _job_complete: JobId=48736 done
[2022-09-04T14:24:24.248] _slurm_rpc_submit_batch_job: JobId=48773 InitPrio=13181 usec=421
[2022-09-04T14:24:24.713] sched: Allocate JobId=48773 NodeList=gpu04 #CPUs=1 Partition=gpu-k40c
[2022-09-04T14:48:51.834] _job_complete: JobId=48734 WEXITSTATUS 0
[2022-09-04T14:48:51.839] _job_complete: JobId=48734 done
[2022-09-04T15:23:25.795] _slurm_rpc_kill_job: REQUEST_KILL_JOB JobId=48773 uid 548300565
[2022-09-04T15:23:47.771] _slurm_rpc_submit_batch_job: JobId=48774 InitPrio=13181 usec=424
[2022-09-04T15:23:48.110] sched: Allocate JobId=48774 NodeList=gpu04 #CPUs=1 Partition=gpu-k40c
[2022-09-04T15:33:43.994] _slurm_rpc_submit_batch_job: JobId=48775 InitPrio=909 usec=469
[2022-09-04T15:36:07.470] _slurm_rpc_submit_batch_job: JobId=48776 InitPrio=909 usec=633
[2022-09-04T15:36:08.410] sched: Allocate JobId=48776 NodeList=gpu02 #CPUs=6 Partition=gpu-titan
[2022-09-04T15:36:23.897] _slurm_rpc_kill_job: REQUEST_KILL_JOB JobId=48774 uid 548300565
[2022-09-04T15:37:21.887] _slurm_rpc_submit_batch_job: JobId=48777 InitPrio=13181 usec=488
[2022-09-04T15:37:22.497] sched: Allocate JobId=48777 NodeList=gpu04 #CPUs=1 Partition=gpu-k40c
[2022-09-04T15:41:02.058] _job_complete: JobId=48776 WEXITSTATUS 0
[2022-09-04T15:41:02.058] _job_complete: JobId=48776 done
[2022-09-04T15:43:00.114] _slurm_rpc_kill_job: REQUEST_KILL_JOB JobId=48777 uid 548300565
[2022-09-04T15:45:08.585] _slurm_rpc_submit_batch_job: JobId=48778 InitPrio=909 usec=434
[2022-09-04T15:45:09.451] sched: Allocate JobId=48778 NodeList=gpu02 #CPUs=4 Partition=gpu-titan
[2022-09-04T15:45:13.076] _slurm_rpc_submit_batch_job: JobId=48779 InitPrio=13181 usec=332
[2022-09-04T15:45:13.456] sched: Allocate JobId=48779 NodeList=gpu04 #CPUs=1 Partition=gpu-k40c
[2022-09-04T15:45:33.867] _job_complete: JobId=48778 WEXITSTATUS 0
[2022-09-04T15:45:33.867] _job_complete: JobId=48778 done
[2022-09-04T15:52:00.007] _slurm_rpc_submit_batch_job: JobId=48780 InitPrio=909 usec=477
[2022-09-04T16:45:14.605] Time limit exhausted for JobId=48779
[2022-09-04T16:56:53.788] _slurm_rpc_submit_batch_job: JobId=48781 InitPrio=3181 usec=408
[2022-09-04T16:56:54.787] sched: Allocate JobId=48781 NodeList=gpu04 #CPUs=1 Partition=gpu-k40c
[2022-09-04T17:04:55.776] _slurm_rpc_submit_batch_job: JobId=48782 InitPrio=2500 usec=495
[2022-09-04T17:06:58.875] _slurm_rpc_submit_batch_job: JobId=48783 InitPrio=2500 usec=476
[2022-09-04T17:07:08.272] _slurm_rpc_kill_job: REQUEST_KILL_JOB JobId=48782 uid 548200029
[2022-09-04T17:09:10.321] _slurm_rpc_submit_batch_job: JobId=48784 InitPrio=2500 usec=440
[2022-09-04T17:17:08.204] _slurm_rpc_submit_batch_job: JobId=48785 InitPrio=4318 usec=433
[2022-09-04T17:17:08.918] sched: Allocate JobId=48785 NodeList=cpu01 #CPUs=8 Partition=cpu-opteron
[2022-09-04T17:17:29.904] _job_complete: JobId=48785 WEXITSTATUS 0
[2022-09-04T17:17:29.904] _job_complete: JobId=48785 done
[2022-09-04T17:23:40.165] _slurm_rpc_kill_job: REQUEST_KILL_JOB JobId=48781 uid 548300565
[2022-09-04T17:30:26.924] _slurm_rpc_submit_batch_job: JobId=48786 InitPrio=4318 usec=548
[2022-09-04T17:30:27.575] sched: Allocate JobId=48786 NodeList=cpu01 #CPUs=8 Partition=cpu-opteron
[2022-09-04T17:30:50.830] _job_complete: JobId=48786 WEXITSTATUS 0
[2022-09-04T17:30:50.830] _job_complete: JobId=48786 done
[2022-09-04T17:41:06.576] _slurm_rpc_submit_batch_job: JobId=48787 InitPrio=4318 usec=398
[2022-09-04T17:41:06.689] sched: Allocate JobId=48787 NodeList=cpu01 #CPUs=8 Partition=cpu-opteron
[2022-09-04T17:44:06.540] _job_complete: JobId=48787 WEXITSTATUS 0
[2022-09-04T17:44:06.540] _job_complete: JobId=48787 done
[2022-09-04T17:52:39.929] _slurm_rpc_submit_batch_job: JobId=48788 InitPrio=3181 usec=416
[2022-09-04T17:52:40.825] sched: Allocate JobId=48788 NodeList=gpu04 #CPUs=1 Partition=gpu-k40c
[2022-09-04T17:59:20.766] _slurm_rpc_submit_batch_job: JobId=48789 InitPrio=4318 usec=587
[2022-09-04T17:59:21.557] sched: Allocate JobId=48789 NodeList=cpu01 #CPUs=12 Partition=cpu-opteron
[2022-09-04T18:11:07.073] _slurm_rpc_submit_batch_job: JobId=48790 InitPrio=4318 usec=423
[2022-09-04T18:11:07.678] sched: Allocate JobId=48790 NodeList=cpu01 #CPUs=8 Partition=cpu-opteron
[2022-09-04T18:14:17.375] _job_complete: JobId=48790 WEXITSTATUS 0
[2022-09-04T18:14:17.376] _job_complete: JobId=48790 done
[2022-09-04T18:19:44.616] _job_complete: JobId=48788 OOM failure
[2022-09-04T18:19:44.616] _job_complete: JobId=48788 done
[2022-09-04T18:21:13.426] _slurm_rpc_kill_job: REQUEST_KILL_JOB JobId=48788 uid 548300565
[2022-09-04T18:23:42.583] _slurm_rpc_submit_batch_job: JobId=48791 InitPrio=13181 usec=384
[2022-09-04T18:23:43.074] sched: Allocate JobId=48791 NodeList=gpu02 #CPUs=1 Partition=gpu-titan
[2022-09-04T18:26:46.137] _slurm_rpc_submit_batch_job: JobId=48792 InitPrio=4318 usec=461
[2022-09-04T18:26:46.331] sched: Allocate JobId=48792 NodeList=cpu01 #CPUs=12 Partition=cpu-opteron
[2022-09-04T18:28:45.120] _slurm_rpc_kill_job: REQUEST_KILL_JOB JobId=48791 uid 548300565
[2022-09-04T18:29:53.332] _slurm_rpc_submit_batch_job: JobId=48793 InitPrio=13181 usec=393
[2022-09-04T18:29:53.663] sched: Allocate JobId=48793 NodeList=gpu02 #CPUs=1 Partition=gpu-titan
[2022-09-04T18:30:25.727] _slurm_rpc_kill_job: REQUEST_KILL_JOB JobId=48793 uid 548300565
[2022-09-04T18:30:40.657] _slurm_rpc_submit_batch_job: JobId=48794 InitPrio=13181 usec=483
[2022-09-04T18:30:40.727] sched: Allocate JobId=48794 NodeList=gpu02 #CPUs=1 Partition=gpu-titan
[2022-09-04T18:35:52.249] _slurm_rpc_submit_batch_job: JobId=48795 InitPrio=4318 usec=402
[2022-09-04T18:36:19.299] _slurm_rpc_kill_job: REQUEST_KILL_JOB JobId=48795 uid 548200084
[2022-09-04T18:36:31.909] _slurm_rpc_submit_batch_job: JobId=48796 InitPrio=4318 usec=704
[2022-09-04T18:37:08.960] _slurm_rpc_kill_job: REQUEST_KILL_JOB JobId=48796 uid 548200084
[2022-09-04T18:37:25.195] _slurm_rpc_submit_batch_job: JobId=48797 InitPrio=4318 usec=499
[2022-09-04T18:49:45.004] _slurm_rpc_kill_job: REQUEST_KILL_JOB JobId=48797 uid 548200084
[2022-09-04T18:50:04.427] _slurm_rpc_submit_batch_job: JobId=48798 InitPrio=4318 usec=451
[2022-09-04T19:30:44.521] Time limit exhausted for JobId=48794
[2022-09-04T19:49:32.833] _slurm_rpc_submit_batch_job: JobId=48799 InitPrio=3181 usec=463
[2022-09-04T19:49:33.520] sched: Allocate JobId=48799 NodeList=gpu02 #CPUs=8 Partition=gpu-titan
[2022-09-04T19:49:34.601] _job_complete: JobId=48799 WEXITSTATUS 1
[2022-09-04T19:49:34.602] _job_complete: JobId=48799 done
[2022-09-04T19:52:04.791] _slurm_rpc_submit_batch_job: JobId=48800 InitPrio=3181 usec=396
[2022-09-04T19:52:05.720] sched: Allocate JobId=48800 NodeList=gpu02 #CPUs=8 Partition=gpu-titan
[2022-09-04T19:52:06.582] _job_complete: JobId=48800 WEXITSTATUS 1
[2022-09-04T19:52:06.583] _job_complete: JobId=48800 done
[2022-09-04T19:53:57.849] _slurm_rpc_submit_batch_job: JobId=48801 InitPrio=3181 usec=424
[2022-09-04T19:53:57.997] sched: Allocate JobId=48801 NodeList=gpu02 #CPUs=8 Partition=gpu-titan
[2022-09-04T20:05:01.659] _job_complete: JobId=48801 WEXITSTATUS 0
[2022-09-04T20:05:01.659] _job_complete: JobId=48801 done
[2022-09-04T20:13:33.237] _slurm_rpc_submit_batch_job: JobId=48802 InitPrio=13181 usec=344
[2022-09-04T20:13:34.010] sched: Allocate JobId=48802 NodeList=gpu02 #CPUs=1 Partition=gpu-titan
[2022-09-04T20:23:00.180] _slurm_rpc_kill_job: REQUEST_KILL_JOB JobId=48802 uid 548300565
[2022-09-05T00:08:04.832] _job_complete: JobId=48764 WEXITSTATUS 0
[2022-09-05T00:08:04.837] _job_complete: JobId=48764 done
[2022-09-05T00:08:05.459] sched: Allocate JobId=48798 NodeList=cpu01 #CPUs=4 Partition=cpu-opteron
[2022-09-05T00:08:37.355] _job_complete: JobId=48798 WEXITSTATUS 0
[2022-09-05T00:08:37.355] _job_complete: JobId=48798 done
[2022-09-05T00:15:49.916] _job_complete: JobId=48765 WEXITSTATUS 0
[2022-09-05T00:15:49.917] _job_complete: JobId=48765 done
[2022-09-05T00:33:07.749] _slurm_rpc_submit_batch_job: JobId=48803 InitPrio=3863 usec=733
[2022-09-05T00:33:08.436] sched: Allocate JobId=48803 NodeList=cpu01 #CPUs=8 Partition=cpu-opteron
[2022-09-05T00:36:09.922] _job_complete: JobId=48803 WEXITSTATUS 0
[2022-09-05T00:36:09.922] _job_complete: JobId=48803 done
[2022-09-05T00:48:06.469] _slurm_rpc_submit_batch_job: JobId=48804 InitPrio=3863 usec=501
[2022-09-05T00:48:06.906] sched: Allocate JobId=48804 NodeList=cpu01 #CPUs=8 Partition=cpu-opteron
[2022-09-05T00:49:56.650] _job_complete: JobId=48789 WEXITSTATUS 0
[2022-09-05T00:49:56.650] _job_complete: JobId=48789 done
[2022-09-05T00:50:22.186] _slurm_rpc_submit_batch_job: JobId=48805 InitPrio=2500 usec=439
[2022-09-05T00:53:15.058] _slurm_rpc_submit_batch_job: JobId=48806 InitPrio=2500 usec=400
[2022-09-05T01:00:21.292] _slurm_rpc_submit_batch_job: JobId=48807 InitPrio=3863 usec=456
[2022-09-05T01:00:22.111] sched: Allocate JobId=48807 NodeList=cpu01 #CPUs=8 Partition=cpu-opteron
[2022-09-05T01:03:22.795] _job_complete: JobId=48807 WEXITSTATUS 0
[2022-09-05T01:03:22.795] _job_complete: JobId=48807 done
[2022-09-05T01:16:08.393] _slurm_rpc_submit_batch_job: JobId=48808 InitPrio=3863 usec=534
[2022-09-05T01:16:09.112] sched: Allocate JobId=48808 NodeList=cpu01 #CPUs=12 Partition=cpu-opteron
[2022-09-05T01:18:22.505] _job_complete: JobId=48792 WEXITSTATUS 0
[2022-09-05T01:18:22.506] _job_complete: JobId=48792 done
[2022-09-05T01:24:40.080] _slurm_rpc_submit_batch_job: JobId=48809 InitPrio=3863 usec=421
[2022-09-05T01:24:41.000] sched: Allocate JobId=48809 NodeList=cpu01 #CPUs=8 Partition=cpu-opteron
[2022-09-05T01:24:56.743] _job_complete: JobId=48809 WEXITSTATUS 0
[2022-09-05T01:24:56.743] _job_complete: JobId=48809 done
[2022-09-05T01:27:05.541] _job_complete: JobId=48692 WEXITSTATUS 0
[2022-09-05T01:27:05.541] _job_complete: JobId=48692 done
[2022-09-05T01:27:13.522] sched/backfill: _start_job: Started JobId=48775 in cpu-epyc on cpu12
[2022-09-05T01:27:20.119] _job_complete: JobId=48775 WEXITSTATUS 1
[2022-09-05T01:27:20.119] _job_complete: JobId=48775 done
[2022-09-05T01:28:13.526] sched/backfill: _start_job: Started JobId=48780 in cpu-epyc on cpu12
[2022-09-05T01:43:33.051] _slurm_rpc_submit_batch_job: JobId=48810 InitPrio=3863 usec=483
[2022-09-05T01:43:33.899] sched: Allocate JobId=48810 NodeList=cpu01 #CPUs=8 Partition=cpu-opteron
[2022-09-05T01:44:55.387] _job_complete: JobId=48691 WEXITSTATUS 0
[2022-09-05T01:44:55.387] _job_complete: JobId=48691 done
[2022-09-05T01:46:32.311] _job_complete: JobId=48810 WEXITSTATUS 0
[2022-09-05T01:46:32.311] _job_complete: JobId=48810 done
[2022-09-05T01:58:07.307] _slurm_rpc_submit_batch_job: JobId=48811 InitPrio=3636 usec=407
[2022-09-05T01:58:07.512] sched: Allocate JobId=48811 NodeList=cpu01 #CPUs=8 Partition=cpu-opteron
[2022-09-05T02:09:31.175] _slurm_rpc_submit_batch_job: JobId=48812 InitPrio=3636 usec=574
[2022-09-05T02:09:31.560] sched: Allocate JobId=48812 NodeList=cpu01 #CPUs=8 Partition=cpu-opteron
[2022-09-05T02:09:33.923] _job_complete: JobId=48812 WEXITSTATUS 1
[2022-09-05T02:09:33.923] _job_complete: JobId=48812 done
[2022-09-05T02:10:26.044] _job_complete: JobId=48780 WEXITSTATUS 0
[2022-09-05T02:10:26.044] _job_complete: JobId=48780 done
[2022-09-05T02:10:26.423] _slurm_rpc_submit_batch_job: JobId=48813 InitPrio=3636 usec=479
[2022-09-05T02:10:26.626] sched: Allocate JobId=48813 NodeList=cpu01 #CPUs=8 Partition=cpu-opteron
[2022-09-05T02:10:26.965] sched: Allocate JobId=48760 NodeList=cpu12 #CPUs=48 Partition=cpu-epyc
[2022-09-05T02:13:26.516] _job_complete: JobId=48813 WEXITSTATUS 0
[2022-09-05T02:13:26.516] _job_complete: JobId=48813 done
[2022-09-05T02:28:35.516] _slurm_rpc_submit_batch_job: JobId=48814 InitPrio=3636 usec=510
[2022-09-05T02:28:36.177] sched: Allocate JobId=48814 NodeList=cpu01 #CPUs=8 Partition=cpu-opteron
[2022-09-05T05:36:49.671] _job_complete: JobId=48695 WEXITSTATUS 0
[2022-09-05T05:36:49.671] _job_complete: JobId=48695 done
[2022-09-05T08:11:43.778] _job_complete: JobId=48808 WEXITSTATUS 0
[2022-09-05T08:11:43.778] _job_complete: JobId=48808 done
[2022-09-05T10:04:56.090] _job_complete: JobId=48694 WEXITSTATUS 0
[2022-09-05T10:04:56.090] _job_complete: JobId=48694 done
[2022-09-05T10:23:10.616] _job_complete: JobId=48804 WEXITSTATUS 0
[2022-09-05T10:23:10.616] _job_complete: JobId=48804 done
[2022-09-05T10:39:21.044] _slurm_rpc_kill_job: REQUEST_KILL_JOB JobId=48548 uid 548200017
[2022-09-05T10:39:21.044] _slurm_rpc_kill_job: REQUEST_KILL_JOB JobId=48607 uid 548200017
[2022-09-05T10:39:24.277] sched: Allocate JobId=48766 NodeList=cpu05 #CPUs=32 Partition=cpu-opteron
[2022-09-05T10:39:24.278] sched: Allocate JobId=48767 NodeList=cpu05 #CPUs=32 Partition=cpu-opteron
[2022-09-05T10:39:24.294] sched: Allocate JobId=48761 NodeList=cpu14 #CPUs=48 Partition=cpu-epyc
[2022-09-05T10:39:24.717] sched: Allocate JobId=48768 NodeList=cpu11 #CPUs=32 Partition=cpu-opteron
[2022-09-05T10:39:24.718] sched: Allocate JobId=48769 NodeList=cpu11 #CPUs=32 Partition=cpu-opteron
[2022-09-05T10:40:47.543] _job_complete: JobId=48769 WEXITSTATUS 0
[2022-09-05T10:40:47.543] _job_complete: JobId=48769 done
[2022-09-05T10:40:47.995] _job_complete: JobId=48768 WEXITSTATUS 0
[2022-09-05T10:40:47.996] _job_complete: JobId=48768 done
[2022-09-05T10:40:50.690] sched: Allocate JobId=48770 NodeList=cpu11 #CPUs=32 Partition=cpu-opteron
[2022-09-05T10:40:50.691] sched: Allocate JobId=48771 NodeList=cpu11 #CPUs=32 Partition=cpu-opteron
[2022-09-05T10:40:52.348] _job_complete: JobId=48766 WEXITSTATUS 0
[2022-09-05T10:40:52.348] _job_complete: JobId=48766 done
[2022-09-05T10:40:52.526] _job_complete: JobId=48767 WEXITSTATUS 0
[2022-09-05T10:40:52.527] _job_complete: JobId=48767 done
[2022-09-05T10:40:53.993] sched: Allocate JobId=48772 NodeList=cpu05 #CPUs=32 Partition=cpu-opteron
[2022-09-05T10:40:53.994] sched: Allocate JobId=48783 NodeList=cpu01 #CPUs=8 Partition=cpu-opteron
[2022-09-05T10:40:53.995] sched: Allocate JobId=48784 NodeList=cpu01 #CPUs=8 Partition=cpu-opteron
[2022-09-05T10:40:53.996] sched: Allocate JobId=48805 NodeList=cpu01 #CPUs=8 Partition=cpu-opteron
[2022-09-05T10:40:53.997] sched: Allocate JobId=48806 NodeList=cpu05 #CPUs=8 Partition=cpu-opteron
[2022-09-05T10:42:13.477] _job_complete: JobId=48770 WEXITSTATUS 0
[2022-09-05T10:42:13.478] _job_complete: JobId=48770 done
[2022-09-05T10:42:14.918] _job_complete: JobId=48771 WEXITSTATUS 0
[2022-09-05T10:42:14.918] _job_complete: JobId=48771 done
[2022-09-05T10:42:33.009] _job_complete: JobId=48772 WEXITSTATUS 0
[2022-09-05T10:42:33.009] _job_complete: JobId=48772 done
[2022-09-05T10:42:48.667] _slurm_rpc_submit_batch_job: JobId=48815 InitPrio=226 usec=442
[2022-09-05T10:42:49.507] sched: Allocate JobId=48815 NodeList=cpu11 #CPUs=64 Partition=cpu-opteron
[2022-09-05T10:43:01.672] _slurm_rpc_submit_batch_job: JobId=48816 InitPrio=226 usec=514
[2022-09-05T11:17:01.867] _job_complete: JobId=48811 WEXITSTATUS 0
[2022-09-05T11:17:01.867] _job_complete: JobId=48811 done
[2022-09-05T12:14:27.950] _job_complete: JobId=48814 WEXITSTATUS 0
[2022-09-05T12:14:27.950] _job_complete: JobId=48814 done
[2022-09-05T12:18:15.836] error: This association 234(account='free', user='hva170037', partition='(null)') does not have access to qos normal
[2022-09-05T12:18:15.836] _slurm_rpc_submit_batch_job: Invalid qos specification
[2022-09-05T12:18:55.798] error: This association 234(account='free', user='hva170037', partition='(null)') does not have access to qos normal
[2022-09-05T12:18:55.798] _slurm_rpc_submit_batch_job: Invalid qos specification
[2022-09-05T12:23:04.951] error: Invalid qos (general-compute)
[2022-09-05T12:23:04.951] _slurm_rpc_submit_batch_job: Invalid qos specification
[2022-09-05T12:25:03.955] error: Invalid qos (cpu-epyc)
[2022-09-05T12:25:03.955] _slurm_rpc_submit_batch_job: Invalid qos specification
[2022-09-05T12:27:06.647] error: Invalid qos (normal*)
[2022-09-05T12:27:06.647] _slurm_rpc_submit_batch_job: Invalid qos specification
[2022-09-05T12:27:42.581] _job_create: exceeded association/QOS limit for user 548300616: AssocGrpCpuLimit
[2022-09-05T12:27:42.581] _slurm_rpc_submit_batch_job: Job violates accounting/QOS policy (job submit limit, user's size and/or time limits)
[2022-09-05T12:28:15.502] error: This association 234(account='free', user='hva170037', partition='(null)') does not have access to qos long
[2022-09-05T12:28:15.502] _slurm_rpc_submit_batch_job: Invalid qos specification
[2022-09-05T12:29:22.469] _job_complete: JobId=48697 WEXITSTATUS 1
[2022-09-05T12:29:22.474] _job_complete: JobId=48697 done
[2022-09-05T12:29:23.764] sched: Allocate JobId=48684 NodeList=gpu03 #CPUs=16 Partition=gpu-k10
[2022-09-05T12:30:06.273] _job_complete: JobId=48684 WEXITSTATUS 1
[2022-09-05T12:30:06.273] _job_complete: JobId=48684 done
[2022-09-05T12:33:15.973] error: This association 234(account='free', user='hva170037', partition='(null)') does not have access to qos long
[2022-09-05T12:33:15.973] _slurm_rpc_submit_batch_job: Invalid qos specification
[2022-09-05T12:47:07.447] error: This association 234(account='free', user='hva170037', partition='(null)') does not have access to qos normal
[2022-09-05T12:47:07.447] _slurm_rpc_submit_batch_job: Invalid qos specification
[2022-09-05T15:31:27.166] _slurm_rpc_submit_batch_job: JobId=48817 InitPrio=14977 usec=687
[2022-09-05T15:31:27.921] sched: Allocate JobId=48817 NodeList=cpu01 #CPUs=4 Partition=cpu-opteron
[2022-09-05T15:31:39.318] _slurm_rpc_submit_batch_job: JobId=48818 InitPrio=14977 usec=422
[2022-09-05T15:31:39.939] sched: Allocate JobId=48818 NodeList=cpu01 #CPUs=4 Partition=cpu-opteron
[2022-09-05T15:31:53.791] _slurm_rpc_submit_batch_job: JobId=48819 InitPrio=14977 usec=490
[2022-09-05T15:31:53.957] sched: Allocate JobId=48819 NodeList=cpu01 #CPUs=4 Partition=cpu-opteron
[2022-09-05T15:32:04.928] _slurm_rpc_submit_batch_job: JobId=48820 InitPrio=14977 usec=475
[2022-09-05T15:32:04.972] sched: Allocate JobId=48820 NodeList=cpu01 #CPUs=4 Partition=cpu-opteron
[2022-09-05T15:32:11.399] _slurm_rpc_submit_batch_job: JobId=48821 InitPrio=14977 usec=495
[2022-09-05T15:32:11.981] sched: Allocate JobId=48821 NodeList=cpu05 #CPUs=4 Partition=cpu-opteron
[2022-09-05T15:32:25.464] _slurm_rpc_submit_batch_job: JobId=48822 InitPrio=14977 usec=425
[2022-09-05T15:32:26.000] sched: Allocate JobId=48822 NodeList=cpu05 #CPUs=4 Partition=cpu-opteron
[2022-09-05T15:32:36.720] _slurm_rpc_submit_batch_job: JobId=48823 InitPrio=14977 usec=427
[2022-09-05T15:32:37.015] sched: Allocate JobId=48823 NodeList=cpu05 #CPUs=4 Partition=cpu-opteron
[2022-09-05T15:32:45.336] _slurm_rpc_submit_batch_job: JobId=48824 InitPrio=14977 usec=739
[2022-09-05T15:32:46.097] sched: Allocate JobId=48824 NodeList=cpu05 #CPUs=4 Partition=cpu-opteron
[2022-09-05T15:32:52.679] _slurm_rpc_submit_batch_job: JobId=48825 InitPrio=14977 usec=472
[2022-09-05T15:32:53.107] sched: Allocate JobId=48825 NodeList=cpu05 #CPUs=4 Partition=cpu-opteron
[2022-09-05T15:33:02.313] _slurm_rpc_submit_batch_job: JobId=48826 InitPrio=14977 usec=419
[2022-09-05T15:33:03.160] sched: Allocate JobId=48826 NodeList=cpu05 #CPUs=4 Partition=cpu-opteron
[2022-09-05T15:34:30.418] _slurm_rpc_submit_batch_job: JobId=48827 InitPrio=14977 usec=465
[2022-09-05T15:34:31.280] sched: Allocate JobId=48827 NodeList=cpu05 #CPUs=4 Partition=cpu-opteron
[2022-09-05T15:34:35.595] _job_complete: JobId=48827 WEXITSTATUS 0
[2022-09-05T15:34:35.595] _job_complete: JobId=48827 done
[2022-09-05T15:44:08.570] _slurm_rpc_kill_job: REQUEST_KILL_JOB JobId=48817 uid 548300543
[2022-09-05T15:44:10.818] _slurm_rpc_kill_job: REQUEST_KILL_JOB JobId=48818 uid 548300543
[2022-09-05T15:44:12.922] _slurm_rpc_kill_job: REQUEST_KILL_JOB JobId=48819 uid 548300543
[2022-09-05T15:44:14.706] _slurm_rpc_kill_job: REQUEST_KILL_JOB JobId=48820 uid 548300543
[2022-09-05T15:44:16.403] _slurm_rpc_kill_job: REQUEST_KILL_JOB JobId=48821 uid 548300543
[2022-09-05T15:44:18.238] _slurm_rpc_kill_job: REQUEST_KILL_JOB JobId=48822 uid 548300543
[2022-09-05T15:44:19.902] _slurm_rpc_kill_job: REQUEST_KILL_JOB JobId=48823 uid 548300543
[2022-09-05T15:44:21.237] _slurm_rpc_kill_job: REQUEST_KILL_JOB JobId=48824 uid 548300543
[2022-09-05T15:44:22.715] _slurm_rpc_kill_job: REQUEST_KILL_JOB JobId=48825 uid 548300543
[2022-09-05T15:44:24.098] _slurm_rpc_kill_job: REQUEST_KILL_JOB JobId=48826 uid 548300543
[2022-09-05T15:46:33.439] _job_complete: JobId=48815 WEXITSTATUS 0
[2022-09-05T15:46:33.445] _job_complete: JobId=48815 done
[2022-09-05T15:46:35.722] sched: Allocate JobId=48816 NodeList=cpu11 #CPUs=64 Partition=cpu-opteron
[2022-09-05T16:09:12.537] _slurm_rpc_submit_batch_job: JobId=48828 InitPrio=14977 usec=647
[2022-09-05T16:09:13.010] sched: Allocate JobId=48828 NodeList=cpu01 #CPUs=4 Partition=cpu-opteron
[2022-09-05T16:09:21.274] _slurm_rpc_submit_batch_job: JobId=48829 InitPrio=14977 usec=470
[2022-09-05T16:09:22.018] sched: Allocate JobId=48829 NodeList=cpu01 #CPUs=4 Partition=cpu-opteron
[2022-09-05T16:09:26.142] _slurm_rpc_submit_batch_job: JobId=48830 InitPrio=14977 usec=508
[2022-09-05T16:09:27.025] sched: Allocate JobId=48830 NodeList=cpu01 #CPUs=4 Partition=cpu-opteron
[2022-09-05T16:09:32.617] _slurm_rpc_submit_batch_job: JobId=48831 InitPrio=14977 usec=512
[2022-09-05T16:09:33.033] sched: Allocate JobId=48831 NodeList=cpu01 #CPUs=4 Partition=cpu-opteron
[2022-09-05T16:09:40.002] _slurm_rpc_submit_batch_job: JobId=48832 InitPrio=14977 usec=512
[2022-09-05T16:09:40.043] sched: Allocate JobId=48832 NodeList=cpu05 #CPUs=4 Partition=cpu-opteron
[2022-09-05T16:09:48.418] _slurm_rpc_submit_batch_job: JobId=48833 InitPrio=14977 usec=489
[2022-09-05T16:09:49.055] sched: Allocate JobId=48833 NodeList=cpu05 #CPUs=4 Partition=cpu-opteron
[2022-09-05T16:09:55.564] _slurm_rpc_submit_batch_job: JobId=48834 InitPrio=14977 usec=449
[2022-09-05T16:09:56.064] sched: Allocate JobId=48834 NodeList=cpu05 #CPUs=4 Partition=cpu-opteron
[2022-09-05T16:10:00.865] _slurm_rpc_submit_batch_job: JobId=48835 InitPrio=14977 usec=467
[2022-09-05T16:10:01.071] sched: Allocate JobId=48835 NodeList=cpu05 #CPUs=4 Partition=cpu-opteron
[2022-09-05T16:10:06.524] _slurm_rpc_submit_batch_job: JobId=48836 InitPrio=14977 usec=420
[2022-09-05T16:10:08.080] sched: Allocate JobId=48836 NodeList=cpu05 #CPUs=4 Partition=cpu-opteron
[2022-09-05T16:10:13.283] _slurm_rpc_submit_batch_job: JobId=48837 InitPrio=14977 usec=485
[2022-09-05T16:10:14.087] sched: Allocate JobId=48837 NodeList=cpu05 #CPUs=4 Partition=cpu-opteron
[2022-09-05T16:24:01.216] _slurm_rpc_submit_batch_job: JobId=48838 InitPrio=14977 usec=579
[2022-09-05T16:24:01.610] sched: Allocate JobId=48838 NodeList=cpu05 #CPUs=4 Partition=cpu-opteron
[2022-09-05T16:24:02.194] _job_complete: JobId=48838 WEXITSTATUS 127
[2022-09-05T16:24:02.194] _job_complete: JobId=48838 done
[2022-09-05T16:24:33.396] _slurm_rpc_submit_batch_job: JobId=48839 InitPrio=14977 usec=468
[2022-09-05T16:24:33.650] sched: Allocate JobId=48839 NodeList=cpu05 #CPUs=4 Partition=cpu-opteron
[2022-09-05T16:27:29.186] _job_complete: JobId=48839 OOM failure
[2022-09-05T16:27:29.186] _job_complete: JobId=48839 done
[2022-09-05T16:31:11.012] _slurm_rpc_kill_job: REQUEST_KILL_JOB JobId=48828 uid 548300543
[2022-09-05T16:31:12.763] _slurm_rpc_kill_job: REQUEST_KILL_JOB JobId=48829 uid 548300543
[2022-09-05T16:31:14.751] _slurm_rpc_kill_job: REQUEST_KILL_JOB JobId=48830 uid 548300543
[2022-09-05T16:31:17.669] _slurm_rpc_kill_job: REQUEST_KILL_JOB JobId=48831 uid 548300543
[2022-09-05T16:31:19.674] _slurm_rpc_kill_job: REQUEST_KILL_JOB JobId=48832 uid 548300543
[2022-09-05T16:31:21.491] _slurm_rpc_kill_job: REQUEST_KILL_JOB JobId=48833 uid 548300543
[2022-09-05T16:31:23.954] _slurm_rpc_kill_job: REQUEST_KILL_JOB JobId=48834 uid 548300543
[2022-09-05T16:31:25.173] _slurm_rpc_kill_job: REQUEST_KILL_JOB JobId=48835 uid 548300543
[2022-09-05T16:31:26.543] _slurm_rpc_kill_job: REQUEST_KILL_JOB JobId=48836 uid 548300543
[2022-09-05T16:31:27.963] _slurm_rpc_kill_job: REQUEST_KILL_JOB JobId=48837 uid 548300543
[2022-09-05T18:38:03.562] _slurm_rpc_kill_job: REQUEST_KILL_JOB JobId=48816 uid 548200017
[2022-09-05T18:39:09.698] _slurm_rpc_submit_batch_job: JobId=48840 InitPrio=226 usec=513
[2022-09-05T18:39:10.143] sched: Allocate JobId=48840 NodeList=cpu11 #CPUs=64 Partition=cpu-opteron
[2022-09-05T18:42:15.899] _slurm_rpc_submit_batch_job: JobId=48841 InitPrio=226 usec=446
[2022-09-05T20:02:50.401] _job_complete: JobId=48727 WEXITSTATUS 0
[2022-09-05T20:02:50.407] _job_complete: JobId=48727 done
[2022-09-05T20:20:31.634] _slurm_rpc_submit_batch_job: JobId=48842 InitPrio=1131 usec=594
[2022-09-05T22:01:18.515] _slurm_rpc_submit_batch_job: JobId=48843 InitPrio=1809 usec=520
[2022-09-05T22:01:19.387] sched: Allocate JobId=48843 NodeList=cpu01 #CPUs=1 Partition=cpu-opteron
[2022-09-05T22:12:53.934] _job_complete: JobId=48843 WEXITSTATUS 0
[2022-09-05T22:12:53.935] _job_complete: JobId=48843 done
[2022-09-05T22:14:45.954] _slurm_rpc_submit_batch_job: JobId=48844 InitPrio=1809 usec=502
[2022-09-05T22:14:46.790] sched: Allocate JobId=48844 NodeList=cpu01 #CPUs=1 Partition=cpu-opteron
[2022-09-05T23:00:58.615] _job_complete: JobId=48844 WEXITSTATUS 0
[2022-09-05T23:00:58.616] _job_complete: JobId=48844 done
[2022-09-05T23:11:35.602] _slurm_rpc_submit_batch_job: JobId=48845 InitPrio=11809 usec=466
[2022-09-05T23:11:35.726] sched: Allocate JobId=48845 NodeList=cpu01 #CPUs=1 Partition=cpu-opteron
[2022-09-05T23:19:05.252] _job_complete: JobId=48845 WEXITSTATUS 0
[2022-09-05T23:19:05.253] _job_complete: JobId=48845 done
[2022-09-05T23:28:47.237] _slurm_rpc_submit_batch_job: JobId=48846 InitPrio=1809 usec=442
[2022-09-05T23:28:47.608] sched: Allocate JobId=48846 NodeList=cpu08 #CPUs=64 Partition=cpu-opteron
[2022-09-05T23:28:50.406] _job_complete: JobId=48840 WEXITSTATUS 0
[2022-09-05T23:28:50.410] _job_complete: JobId=48840 done
[2022-09-05T23:28:52.663] sched: Allocate JobId=48841 NodeList=cpu11 #CPUs=64 Partition=cpu-opteron
[2022-09-06T01:52:07.764] _slurm_rpc_submit_batch_job: JobId=48847 InitPrio=14027 usec=550
[2022-09-06T02:40:35.878] _slurm_rpc_submit_batch_job: JobId=48848 InitPrio=452 usec=596
[2022-09-06T02:40:35.896] sched: Allocate JobId=48848 NodeList=gpu03 #CPUs=16 Partition=gpu-k10
[2022-09-06T02:48:35.592] _slurm_rpc_submit_batch_job: JobId=48849 InitPrio=14027 usec=466
[2022-09-06T02:49:41.546] _slurm_rpc_kill_job: REQUEST_KILL_JOB JobId=48849 uid 548300621
[2022-09-06T02:49:42.753] _slurm_rpc_kill_job: REQUEST_KILL_JOB JobId=48849 uid 548300621
[2022-09-06T03:15:29.669] _job_complete: JobId=48805 WEXITSTATUS 0
[2022-09-06T03:15:29.674] _job_complete: JobId=48805 done
[2022-09-06T03:19:00.532] _job_complete: JobId=48784 WEXITSTATUS 0
[2022-09-06T03:19:00.532] _job_complete: JobId=48784 done
[2022-09-06T03:19:43.044] _job_complete: JobId=48806 WEXITSTATUS 0
[2022-09-06T03:19:43.044] _job_complete: JobId=48806 done
[2022-09-06T03:30:16.828] _job_complete: JobId=48783 WEXITSTATUS 0
[2022-09-06T03:30:16.829] _job_complete: JobId=48783 done
[2022-09-06T03:39:39.452] _slurm_rpc_kill_job: REQUEST_KILL_JOB JobId=48847 uid 548300621
[2022-09-06T03:39:40.105] _slurm_rpc_kill_job: REQUEST_KILL_JOB JobId=48847 uid 548300621
[2022-09-06T03:39:54.754] _slurm_rpc_submit_batch_job: JobId=48850 InitPrio=14027 usec=533
[2022-09-06T04:16:03.925] _job_complete: JobId=48841 WEXITSTATUS 0
[2022-09-06T04:16:03.930] _job_complete: JobId=48841 done
[2022-09-06T05:57:54.371] _job_complete: JobId=48760 WEXITSTATUS 0
[2022-09-06T05:57:54.376] _job_complete: JobId=48760 done
[2022-09-06T05:57:58.305] sched: Allocate JobId=48850 NodeList=cpu12 #CPUs=48 Partition=cpu-epyc
[2022-09-06T05:57:58.563] _job_complete: JobId=48850 WEXITSTATUS 2
[2022-09-06T05:57:58.563] _job_complete: JobId=48850 done
[2022-09-06T05:57:58.877] sched: Allocate JobId=48762 NodeList=cpu12 #CPUs=48 Partition=cpu-epyc
[2022-09-06T06:42:22.516] _slurm_rpc_submit_batch_job: JobId=48851 InitPrio=226 usec=577
[2022-09-06T06:42:22.674] sched: Allocate JobId=48851 NodeList=cpu05 #CPUs=48 Partition=cpu-opteron
[2022-09-06T06:43:35.478] _slurm_rpc_submit_batch_job: JobId=48852 InitPrio=226 usec=419
[2022-09-06T06:44:14.051] _slurm_rpc_submit_batch_job: JobId=48853 InitPrio=226 usec=455
[2022-09-06T06:44:40.876] _slurm_rpc_kill_job: REQUEST_KILL_JOB JobId=48851 uid 548200017
[2022-09-06T06:44:43.156] sched: Allocate JobId=48853 NodeList=cpu05 #CPUs=64 Partition=cpu-opteron
[2022-09-06T06:45:16.870] _slurm_rpc_submit_batch_job: JobId=48854 InitPrio=226 usec=374
[2022-09-06T06:45:42.221] _slurm_rpc_submit_batch_job: JobId=48855 InitPrio=226 usec=400
[2022-09-06T06:46:09.713] _slurm_rpc_kill_job: REQUEST_KILL_JOB JobId=48853 uid 548200017
[2022-09-06T06:46:12.154] sched: Allocate JobId=48854 NodeList=cpu05 #CPUs=64 Partition=cpu-opteron
[2022-09-06T06:46:31.790] _slurm_rpc_kill_job: REQUEST_KILL_JOB JobId=48855 uid 548200017
[2022-09-06T06:46:52.218] _slurm_rpc_submit_batch_job: JobId=48856 InitPrio=226 usec=498
[2022-09-06T10:44:25.351] Time limit exhausted for JobId=48465
[2022-09-06T10:44:28.440] sched: Allocate JobId=48852 NodeList=cpu15 #CPUs=48 Partition=cpu-epyc
[2022-09-06T12:26:19.279] _slurm_rpc_submit_batch_job: JobId=48857 InitPrio=1809 usec=471
[2022-09-06T12:33:07.603] _job_complete: JobId=48706 WEXITSTATUS 0
[2022-09-06T12:33:07.609] _job_complete: JobId=48706 done
[2022-09-06T14:43:06.962] _slurm_rpc_submit_batch_job: JobId=48858 InitPrio=14027 usec=539
[2022-09-06T14:43:07.897] sched: Allocate JobId=48858 NodeList=cpu01 #CPUs=16 Partition=cpu-opteron
[2022-09-06T14:43:12.171] _job_complete: JobId=48858 WEXITSTATUS 0
[2022-09-06T14:43:12.171] _job_complete: JobId=48858 done
[2022-09-06T15:31:00.526] _slurm_rpc_submit_batch_job: JobId=48859 InitPrio=11085 usec=520
[2022-09-06T15:31:00.855] sched: Allocate JobId=48859 NodeList=cpu01 #CPUs=16 Partition=cpu-opteron
[2022-09-06T15:31:01.616] _job_complete: JobId=48859 WEXITSTATUS 1
[2022-09-06T15:31:01.617] _job_complete: JobId=48859 done
[2022-09-06T15:34:31.268] _slurm_rpc_submit_batch_job: JobId=48860 InitPrio=11085 usec=506
[2022-09-06T15:34:56.967] _slurm_rpc_submit_batch_job: JobId=48861 InitPrio=11085 usec=612
[2022-09-06T15:59:45.913] _job_complete: JobId=48852 WEXITSTATUS 0
[2022-09-06T15:59:45.917] _job_complete: JobId=48852 done
[2022-09-06T15:59:47.955] sched: Allocate JobId=48857 NodeList=cpu15 #CPUs=48 Partition=cpu-epyc
[2022-09-06T16:11:27.513] _slurm_rpc_submit_batch_job: JobId=48862 InitPrio=678 usec=555
[2022-09-06T16:12:04.854] _slurm_rpc_kill_job: REQUEST_KILL_JOB JobId=48862 uid 548200019
[2022-09-06T16:12:15.998] _slurm_rpc_submit_batch_job: JobId=48863 InitPrio=678 usec=514
[2022-09-06T16:12:29.627] _slurm_rpc_kill_job: REQUEST_KILL_JOB JobId=48863 uid 548200019
[2022-09-06T16:12:32.619] _slurm_rpc_kill_job: REQUEST_KILL_JOB JobId=48862 uid 548200019
[2022-09-06T16:12:51.908] _slurm_rpc_submit_batch_job: JobId=48864 InitPrio=678 usec=471
[2022-09-06T16:13:17.440] _slurm_rpc_submit_batch_job: JobId=48865 InitPrio=678 usec=542
[2022-09-06T16:14:16.026] sched/backfill: _start_job: Started JobId=48865 in cpu-opteron on cpu11
[2022-09-06T16:23:44.213] _slurm_rpc_kill_job: REQUEST_KILL_JOB JobId=48864 uid 548200019
[2022-09-06T16:24:41.704] _slurm_rpc_submit_batch_job: JobId=48866 InitPrio=678 usec=485
[2022-09-06T16:25:16.040] sched/backfill: _start_job: Started JobId=48866 in cpu-opteron on cpu11
[2022-09-06T17:20:50.340] _slurm_rpc_submit_batch_job: JobId=48867 InitPrio=2488 usec=1082
[2022-09-06T17:20:51.249] sched: Allocate JobId=48867 NodeList=gpu01 #CPUs=16 Partition=gpu-k10
[2022-09-06T17:22:15.536] _slurm_rpc_submit_batch_job: JobId=48868 InitPrio=2488 usec=1099
[2022-09-06T17:24:14.728] _slurm_rpc_submit_batch_job: JobId=48869 InitPrio=2488 usec=1051
[2022-09-06T17:24:32.948] _job_complete: JobId=48644 WEXITSTATUS 0
[2022-09-06T17:24:32.948] _job_complete: JobId=48644 done
[2022-09-06T18:00:40.963] _job_complete: JobId=48854 WEXITSTATUS 1
[2022-09-06T18:00:40.968] _job_complete: JobId=48854 done
[2022-09-06T18:00:47.159] sched: Allocate JobId=48860 NodeList=cpu05 #CPUs=64 Partition=cpu-opteron
[2022-09-06T18:19:16.247] _job_complete: JobId=48322 WEXITSTATUS 0
[2022-09-06T18:19:16.247] _job_complete: JobId=48322 done
[2022-09-06T18:19:18.527] sched: Allocate JobId=48686 NodeList=gpu05 #CPUs=8 Partition=gpu-v100s
[2022-09-06T18:19:22.255] _job_complete: JobId=48686 WEXITSTATUS 1
[2022-09-06T18:19:22.255] _job_complete: JobId=48686 done
[2022-09-06T18:19:23.001] sched: Allocate JobId=48687 NodeList=gpu05 #CPUs=8 Partition=gpu-v100s
[2022-09-06T19:07:22.808] _slurm_rpc_submit_batch_job: JobId=48870 InitPrio=226 usec=465
[2022-09-06T19:15:11.957] _slurm_rpc_submit_batch_job: JobId=48871 InitPrio=226 usec=420
[2022-09-06T21:15:04.648] _slurm_rpc_submit_batch_job: JobId=48872 InitPrio=452 usec=528
[2022-09-06T23:33:58.508] Time limit exhausted for JobId=48502
[2022-09-06T23:34:07.855] sched: Allocate JobId=48861 NodeList=cpu07 #CPUs=64 Partition=cpu-opteron
[2022-09-06T23:44:59.578] Time limit exhausted for JobId=48506
[2022-09-06T23:45:00.299] sched: Allocate JobId=48856 NodeList=cpu01 #CPUs=64 Partition=cpu-opteron
[2022-09-07T01:30:16.124] _slurm_rpc_submit_batch_job: JobId=48873 InitPrio=678 usec=635
[2022-09-07T01:31:54.158] _slurm_rpc_submit_batch_job: JobId=48874 InitPrio=678 usec=556
[2022-09-07T01:32:16.617] sched/backfill: _start_job: Started JobId=48874 in cpu-opteron on cpu11
[2022-09-07T01:33:06.736] _slurm_rpc_submit_batch_job: JobId=48875 InitPrio=678 usec=533
[2022-09-07T01:33:16.619] sched/backfill: _start_job: Started JobId=48875 in cpu-opteron on cpu04
[2022-09-07T09:04:43.197] _slurm_rpc_submit_batch_job: JobId=48876 InitPrio=904 usec=616
[2022-09-07T09:04:43.759] sched: Allocate JobId=48876 NodeList=gpu02 #CPUs=6 Partition=gpu-titan
[2022-09-07T09:05:26.754] _slurm_rpc_submit_batch_job: JobId=48877 InitPrio=904 usec=498
[2022-09-07T09:05:26.794] sched: Allocate JobId=48877 NodeList=gpu02 #CPUs=4 Partition=gpu-titan
[2022-09-07T09:05:46.531] _job_complete: JobId=48877 WEXITSTATUS 0
[2022-09-07T09:05:46.531] _job_complete: JobId=48877 done
[2022-09-07T09:07:38.875] _slurm_rpc_submit_batch_job: JobId=48878 InitPrio=904 usec=437
[2022-09-07T09:08:55.516] _slurm_rpc_submit_batch_job: JobId=48879 InitPrio=904 usec=450
[2022-09-07T09:09:19.353] _job_complete: JobId=48876 WEXITSTATUS 0
[2022-09-07T09:09:19.353] _job_complete: JobId=48876 done
[2022-09-07T09:12:55.097] _slurm_rpc_submit_batch_job: JobId=48880 InitPrio=904 usec=498
[2022-09-07T09:13:20.924] _slurm_rpc_submit_batch_job: JobId=48881 InitPrio=904 usec=524
[2022-09-07T09:28:33.665] _job_complete: JobId=48874 WEXITSTATUS 0
[2022-09-07T09:28:33.665] _job_complete: JobId=48874 done
[2022-09-07T09:48:47.352] _slurm_rpc_submit_batch_job: JobId=48882 InitPrio=1583 usec=530
[2022-09-07T09:48:47.546] sched: Allocate JobId=48882 NodeList=cpu04 #CPUs=1 Partition=cpu-opteron
[2022-09-07T09:48:57.532] _job_complete: JobId=48882 WEXITSTATUS 1
[2022-09-07T09:48:57.533] _job_complete: JobId=48882 done
[2022-09-07T10:53:41.091] _job_complete: JobId=48608 WEXITSTATUS 0
[2022-09-07T10:53:41.096] _job_complete: JobId=48608 done
[2022-09-07T10:53:46.233] sched: Allocate JobId=48873 NodeList=cpu03 #CPUs=64 Partition=cpu-opteron
[2022-09-07T11:43:33.733] error: This association 43(account='free', user='han', partition='(null)') does not have access to qos normal
[2022-09-07T11:43:33.733] _slurm_rpc_submit_batch_job: Invalid qos specification
[2022-09-07T11:43:58.475] error: This association 43(account='free', user='han', partition='(null)') does not have access to qos normal
[2022-09-07T11:43:58.475] _slurm_rpc_submit_batch_job: Invalid qos specification
[2022-09-07T14:12:34.538] _slurm_rpc_kill_job: REQUEST_KILL_JOB JobId=48860 uid 548300621
[2022-09-07T14:12:35.466] _slurm_rpc_kill_job: REQUEST_KILL_JOB JobId=48860 uid 548300621
[2022-09-07T14:12:48.006] _slurm_rpc_submit_batch_job: JobId=48883 InitPrio=3378 usec=511
[2022-09-07T14:13:05.854] sched: Allocate JobId=48883 NodeList=cpu05 #CPUs=64 Partition=cpu-opteron
[2022-09-07T15:06:49.388] _slurm_rpc_submit_batch_job: JobId=48884 InitPrio=4504 usec=425
[2022-09-07T15:16:07.450] sched: _slurm_rpc_allocate_resources JobId=48885 NodeList=(null) usec=879
[2022-09-07T15:16:17.994] sched/backfill: _start_job: Started JobId=48885 in cpu-opteron on cpu11
[2022-09-07T15:39:48.668] _job_complete: JobId=48885 WEXITSTATUS 0
[2022-09-07T15:39:48.668] _job_complete: JobId=48885 done
[2022-09-07T15:39:57.768] sched: _slurm_rpc_allocate_resources JobId=48886 NodeList=(null) usec=824
[2022-09-07T15:42:45.453] sched: _slurm_rpc_allocate_resources JobId=48887 NodeList=(null) usec=827
[2022-09-07T15:43:18.096] sched/backfill: _start_job: Started JobId=48887 in cpu-opteron on cpu11
[2022-09-07T15:50:29.860] _slurm_rpc_kill_job: REQUEST_KILL_JOB JobId=48467 uid 548300593
[2022-09-07T16:10:37.192] error: This association 43(account='free', user='han', partition='(null)') does not have access to qos normal
[2022-09-07T16:10:37.192] _slurm_rpc_submit_batch_job: Invalid qos specification
[2022-09-07T16:10:53.934] _job_create: exceeded association/QOS limit for user 548200045: AssocGrpCpuLimit
[2022-09-07T16:10:53.934] _slurm_rpc_submit_batch_job: Job violates accounting/QOS policy (job submit limit, user's size and/or time limits)
[2022-09-07T16:18:00.882] _job_complete: JobId=48886 WTERMSIG 126
[2022-09-07T16:18:00.882] _job_complete: JobId=48886 cancelled by interactive user
[2022-09-07T16:18:00.882] _job_complete: JobId=48886 done
[2022-09-07T16:18:00.884] _slurm_rpc_complete_job_allocation: JobId=48886 error Job/step already completing or completed
[2022-09-07T16:18:55.388] _slurm_rpc_submit_batch_job: JobId=48888 InitPrio=450 usec=577
[2022-09-07T16:23:16.743] _slurm_rpc_kill_job: REQUEST_KILL_JOB JobId=48848 uid 548200021
[2022-09-07T16:23:21.060] sched: Allocate JobId=48868 NodeList=gpu03 #CPUs=16 Partition=gpu-k10
[2022-09-07T16:25:06.437] _slurm_rpc_submit_batch_job: JobId=48889 InitPrio=450 usec=514
[2022-09-07T16:25:06.878] sched: Allocate JobId=48889 NodeList=gpu02 #CPUs=8 Partition=gpu-titan
[2022-09-07T16:37:57.026] _slurm_rpc_submit_batch_job: JobId=48890 InitPrio=225 usec=387
[2022-09-07T17:39:04.100] _slurm_rpc_submit_batch_job: JobId=48891 InitPrio=2252 usec=1040
[2022-09-07T17:48:42.065] _job_complete: JobId=48846 WEXITSTATUS 0
[2022-09-07T17:48:42.071] _job_complete: JobId=48846 done
[2022-09-07T17:48:44.335] sched: Allocate JobId=48884 NodeList=cpu08 #CPUs=64 Partition=cpu-opteron
[2022-09-07T17:55:10.839] _slurm_rpc_submit_batch_job: JobId=48892 InitPrio=450 usec=745
[2022-09-07T17:55:26.111] _slurm_rpc_kill_job: REQUEST_KILL_JOB JobId=48889 uid 548200021
[2022-09-07T17:55:29.428] sched: Allocate JobId=48892 NodeList=gpu02 #CPUs=8 Partition=gpu-titan
[2022-09-07T18:03:37.065] _slurm_rpc_submit_batch_job: JobId=48893 InitPrio=1576 usec=566
[2022-09-07T18:03:37.387] sched: Allocate JobId=48893 NodeList=cpu11 #CPUs=1 Partition=cpu-opteron
[2022-09-07T18:05:15.639] _job_complete: JobId=48893 WEXITSTATUS 0
[2022-09-07T18:05:15.639] _job_complete: JobId=48893 done
[2022-09-07T18:25:36.884] _job_complete: JobId=48875 WEXITSTATUS 0
[2022-09-07T18:25:36.884] _job_complete: JobId=48875 done
[2022-09-07T18:25:39.154] sched: Allocate JobId=48878 NodeList=cpu04 #CPUs=32 Partition=cpu-opteron
[2022-09-07T18:25:41.044] _job_complete: JobId=48878 WEXITSTATUS 1
[2022-09-07T18:25:41.044] _job_complete: JobId=48878 done
[2022-09-07T18:25:41.785] sched: Allocate JobId=48879 NodeList=cpu04 #CPUs=32 Partition=cpu-opteron
[2022-09-07T18:25:43.072] _job_complete: JobId=48879 WEXITSTATUS 1
[2022-09-07T18:25:43.072] _job_complete: JobId=48879 done
[2022-09-07T18:25:43.746] sched: Allocate JobId=48881 NodeList=cpu04 #CPUs=32 Partition=cpu-opteron
[2022-09-07T18:25:44.957] _job_complete: JobId=48881 WEXITSTATUS 1
[2022-09-07T18:25:44.957] _job_complete: JobId=48881 done
[2022-09-07T18:43:46.624] _slurm_rpc_submit_batch_job: JobId=48894 InitPrio=450 usec=534
[2022-09-07T19:48:20.645] _job_create: exceeded association/QOS limit for user 548200021: QOSMaxWallDurationPerJobLimit
[2022-09-07T19:48:20.645] _slurm_rpc_submit_batch_job: Job violates accounting/QOS policy (job submit limit, user's size and/or time limits)
[2022-09-07T19:49:47.608] _job_create: exceeded association/QOS limit for user 548200021: QOSMaxWallDurationPerJobLimit
[2022-09-07T19:49:47.609] _slurm_rpc_submit_batch_job: Job violates accounting/QOS policy (job submit limit, user's size and/or time limits)
[2022-09-07T19:50:23.208] _job_create: exceeded association/QOS limit for user 548200021: QOSMaxWallDurationPerJobLimit
[2022-09-07T19:50:23.208] _slurm_rpc_submit_batch_job: Job violates accounting/QOS policy (job submit limit, user's size and/or time limits)
[2022-09-07T19:50:56.823] _job_create: exceeded association/QOS limit for user 548200021: QOSMaxWallDurationPerJobLimit
[2022-09-07T19:50:56.823] _slurm_rpc_submit_batch_job: Job violates accounting/QOS policy (job submit limit, user's size and/or time limits)
[2022-09-07T19:52:05.468] _job_create: exceeded association/QOS limit for user 548200021: QOSMaxWallDurationPerJobLimit
[2022-09-07T19:52:05.469] _slurm_rpc_submit_batch_job: Job violates accounting/QOS policy (job submit limit, user's size and/or time limits)
[2022-09-07T19:52:38.372] _slurm_rpc_submit_batch_job: JobId=48895 InitPrio=450 usec=438
[2022-09-07T20:12:55.653] _slurm_rpc_kill_job: REQUEST_KILL_JOB JobId=48892 uid 548200021
[2022-09-07T20:12:57.950] sched: Allocate JobId=48894 NodeList=gpu02 #CPUs=8 Partition=gpu-titan
[2022-09-07T20:36:15.718] _slurm_rpc_submit_batch_job: JobId=48896 InitPrio=450 usec=559
[2022-09-07T20:36:53.317] _slurm_rpc_kill_job: REQUEST_KILL_JOB JobId=48894 uid 548200021
[2022-09-07T20:36:55.604] sched: Allocate JobId=48896 NodeList=gpu02 #CPUs=8 Partition=gpu-titan
[2022-09-07T20:43:41.939] _slurm_rpc_submit_batch_job: JobId=48897 InitPrio=450 usec=453
[2022-09-07T20:46:07.583] _slurm_rpc_kill_job: REQUEST_KILL_JOB JobId=48896 uid 548200021
[2022-09-07T20:46:09.947] sched: Allocate JobId=48897 NodeList=gpu02 #CPUs=8 Partition=gpu-titan
[2022-09-07T20:46:13.447] _job_complete: JobId=48897 WEXITSTATUS 1
[2022-09-07T20:46:13.447] _job_complete: JobId=48897 done
[2022-09-07T20:46:54.121] _slurm_rpc_submit_batch_job: JobId=48898 InitPrio=450 usec=498
[2022-09-07T20:46:54.251] sched: Allocate JobId=48898 NodeList=gpu02 #CPUs=8 Partition=gpu-titan
[2022-09-07T20:46:57.830] _job_complete: JobId=48898 WEXITSTATUS 1
[2022-09-07T20:46:57.830] _job_complete: JobId=48898 done
[2022-09-07T20:47:24.710] _slurm_rpc_submit_batch_job: JobId=48899 InitPrio=450 usec=424
[2022-09-07T20:47:25.296] sched: Allocate JobId=48899 NodeList=gpu02 #CPUs=8 Partition=gpu-titan
[2022-09-07T20:59:07.280] _job_complete: JobId=48856 WEXITSTATUS 0
[2022-09-07T20:59:07.286] _job_complete: JobId=48856 done
[2022-09-07T20:59:14.457] sched: Allocate JobId=48870 NodeList=cpu01 #CPUs=64 Partition=cpu-opteron
[2022-09-07T20:59:14.461] sched: Allocate JobId=48888 NodeList=cpu04 #CPUs=32 Partition=cpu-opteron
[2022-09-07T21:22:58.719] _slurm_rpc_submit_batch_job: JobId=48900 InitPrio=900 usec=613
[2022-09-07T21:23:43.529] _slurm_rpc_submit_batch_job: JobId=48901 InitPrio=900 usec=446
[2022-09-07T21:25:29.925] _slurm_rpc_submit_batch_job: JobId=48902 InitPrio=900 usec=532
[2022-09-07T22:35:12.191] _job_complete: JobId=48887 WEXITSTATUS 0
[2022-09-07T22:35:12.192] _job_complete: JobId=48887 done
[2022-09-07T22:35:19.136] sched/backfill: _start_job: Started JobId=48901 in cpu-opteron on cpu11
[2022-09-07T23:59:15.088] _job_complete: JobId=48899 WEXITSTATUS 0
[2022-09-07T23:59:15.088] _job_complete: JobId=48899 done
[2022-09-08T01:10:38.641] _job_complete: JobId=48901 WEXITSTATUS 0
[2022-09-08T01:10:38.641] _job_complete: JobId=48901 done
[2022-09-08T01:11:19.401] sched/backfill: _start_job: Started JobId=48902 in cpu-opteron on cpu11
[2022-09-08T01:45:38.165] _slurm_rpc_submit_batch_job: JobId=48903 InitPrio=450 usec=539
[2022-09-08T01:45:38.632] sched: Allocate JobId=48903 NodeList=gpu02 #CPUs=8 Partition=gpu-titan
[2022-09-08T01:51:08.929] _slurm_rpc_submit_batch_job: JobId=48904 InitPrio=450 usec=506
[2022-09-08T01:51:25.583] _slurm_rpc_kill_job: REQUEST_KILL_JOB JobId=48903 uid 548200021
[2022-09-08T01:51:27.886] sched: Allocate JobId=48904 NodeList=gpu02 #CPUs=8 Partition=gpu-titan
[2022-09-08T01:52:16.200] _slurm_rpc_kill_job: REQUEST_KILL_JOB JobId=48872 uid 548200021
[2022-09-08T03:45:56.745] _job_complete: JobId=48902 WEXITSTATUS 0
[2022-09-08T03:45:56.745] _job_complete: JobId=48902 done
[2022-09-08T04:14:19.897] _slurm_rpc_kill_job: REQUEST_KILL_JOB JobId=48884 uid 548300593
[2022-09-08T04:14:20.646] sched: Allocate JobId=48900 NodeList=cpu08 #CPUs=32 Partition=cpu-opteron
[2022-09-08T05:00:46.101] _job_complete: JobId=48870 WEXITSTATUS 0
[2022-09-08T05:00:46.107] _job_complete: JobId=48870 done
[2022-09-08T05:00:53.278] sched: Allocate JobId=48890 NodeList=cpu01 #CPUs=64 Partition=cpu-opteron
[2022-09-08T05:20:27.658] _slurm_rpc_submit_batch_job: JobId=48905 InitPrio=450 usec=505
[2022-09-08T05:20:59.476] _slurm_rpc_kill_job: REQUEST_KILL_JOB JobId=48904 uid 548200021
[2022-09-08T05:21:01.855] sched: Allocate JobId=48905 NodeList=gpu02 #CPUs=8 Partition=gpu-titan
[2022-09-08T06:45:22.611] _job_complete: JobId=48900 WEXITSTATUS 0
[2022-09-08T06:45:22.611] _job_complete: JobId=48900 done
[2022-09-08T09:39:45.179] _slurm_rpc_submit_batch_job: JobId=48906 InitPrio=900 usec=511
[2022-09-08T09:39:45.570] sched: Allocate JobId=48906 NodeList=cpu11 #CPUs=16 Partition=cpu-opteron
[2022-09-08T09:39:57.665] _slurm_rpc_kill_job: REQUEST_KILL_JOB JobId=48880 uid 548200023
[2022-09-08T09:41:19.273] _slurm_rpc_kill_job: REQUEST_KILL_JOB JobId=48906 uid 548200023
[2022-09-08T09:41:47.199] _slurm_rpc_submit_batch_job: JobId=48907 InitPrio=900 usec=504
[2022-09-08T09:41:47.717] sched: Allocate JobId=48907 NodeList=cpu08 #CPUs=32 Partition=cpu-opteron
[2022-09-08T09:45:20.157] _slurm_rpc_submit_batch_job: JobId=48908 InitPrio=225 usec=449
[2022-09-08T09:47:40.680] _pick_best_nodes: JobId=48909 never runnable in partition cpu-opteron
[2022-09-08T09:47:40.680] _slurm_rpc_submit_batch_job: Requested node configuration is not available
[2022-09-08T09:47:56.285] _slurm_rpc_submit_batch_job: JobId=48910 InitPrio=900 usec=425
[2022-09-08T09:47:56.479] sched: Allocate JobId=48910 NodeList=cpu11 #CPUs=16 Partition=cpu-opteron
[2022-09-08T09:50:45.715] _job_complete: JobId=48910 WEXITSTATUS 0
[2022-09-08T09:50:45.715] _job_complete: JobId=48910 done
[2022-09-08T09:51:36.985] _slurm_rpc_submit_batch_job: JobId=48911 InitPrio=900 usec=476
[2022-09-08T09:51:37.822] sched: Allocate JobId=48911 NodeList=cpu11 #CPUs=16 Partition=cpu-opteron
[2022-09-08T09:52:42.438] _slurm_rpc_submit_batch_job: JobId=48912 InitPrio=900 usec=622
[2022-09-08T09:52:42.908] sched: Allocate JobId=48912 NodeList=cpu08 #CPUs=16 Partition=cpu-opteron
[2022-09-08T09:52:44.273] _job_complete: JobId=48912 WEXITSTATUS 1
[2022-09-08T09:52:44.273] _job_complete: JobId=48912 done
[2022-09-08T09:53:40.210] _slurm_rpc_submit_batch_job: JobId=48913 InitPrio=900 usec=542
[2022-09-08T09:53:41.201] sched: Allocate JobId=48913 NodeList=cpu08 #CPUs=16 Partition=cpu-opteron
[2022-09-08T09:54:27.689] _job_complete: JobId=48911 WEXITSTATUS 0
[2022-09-08T09:54:27.689] _job_complete: JobId=48911 done
[2022-09-08T09:54:29.088] _slurm_rpc_submit_batch_job: JobId=48914 InitPrio=900 usec=413
[2022-09-08T09:54:29.267] sched: Allocate JobId=48914 NodeList=cpu08 #CPUs=16 Partition=cpu-opteron
[2022-09-08T09:56:28.494] _job_complete: JobId=48913 WEXITSTATUS 0
[2022-09-08T09:56:28.494] _job_complete: JobId=48913 done
[2022-09-08T09:57:19.775] _job_complete: JobId=48914 WEXITSTATUS 0
[2022-09-08T09:57:19.775] _job_complete: JobId=48914 done
[2022-09-08T10:03:29.963] _slurm_rpc_submit_batch_job: JobId=48915 InitPrio=225 usec=416
[2022-09-08T10:10:05.364] _slurm_rpc_submit_batch_job: JobId=48916 InitPrio=3603 usec=538
[2022-09-08T10:10:37.175] _slurm_rpc_kill_job: REQUEST_KILL_JOB JobId=48916 uid 548300593
[2022-09-08T10:35:42.825] _slurm_rpc_submit_batch_job: JobId=48917 InitPrio=900 usec=583
[2022-09-08T10:35:43.629] sched: Allocate JobId=48917 NodeList=cpu08 #CPUs=32 Partition=cpu-opteron
[2022-09-08T10:35:55.931] _job_complete: JobId=48917 WEXITSTATUS 1
[2022-09-08T10:35:55.931] _job_complete: JobId=48917 done
[2022-09-08T10:37:52.408] _slurm_rpc_submit_batch_job: JobId=48918 InitPrio=900 usec=416
[2022-09-08T10:37:52.835] sched: Allocate JobId=48918 NodeList=cpu08 #CPUs=32 Partition=cpu-opteron
[2022-09-08T10:39:32.135] _slurm_rpc_submit_batch_job: JobId=48919 InitPrio=900 usec=417
[2022-09-08T10:43:44.801] _slurm_rpc_submit_batch_job: JobId=48920 InitPrio=900 usec=482
[2022-09-08T11:12:40.349] _slurm_rpc_submit_batch_job: JobId=48921 InitPrio=3603 usec=490
[2022-09-08T11:29:21.548] _job_complete: JobId=48918 WEXITSTATUS 0
[2022-09-08T11:29:21.548] _job_complete: JobId=48918 done
[2022-09-08T11:30:20.213] sched/backfill: _start_job: Started JobId=48919 in cpu-opteron on cpu08
[2022-09-08T11:30:32.514] _job_complete: JobId=48919 WEXITSTATUS 1
[2022-09-08T11:30:32.514] _job_complete: JobId=48919 done
[2022-09-08T11:31:20.216] sched/backfill: _start_job: Started JobId=48920 in cpu-opteron on cpu08
[2022-09-08T11:31:32.430] _job_complete: JobId=48920 WEXITSTATUS 1
[2022-09-08T11:31:32.430] _job_complete: JobId=48920 done
[2022-09-08T11:56:19.779] _job_complete: JobId=48907 WEXITSTATUS 0
[2022-09-08T11:56:19.779] _job_complete: JobId=48907 done
[2022-09-08T11:56:21.066] sched: Allocate JobId=48921 NodeList=cpu08 #CPUs=64 Partition=cpu-opteron
[2022-09-08T12:34:33.671] Time limit exhausted for JobId=48268
[2022-09-08T12:34:44.073] sched: Allocate JobId=48688 NodeList=gpu05 #CPUs=8 Partition=gpu-v100s
[2022-09-08T12:34:45.574] _job_complete: JobId=48688 WEXITSTATUS 1
[2022-09-08T12:34:45.575] _job_complete: JobId=48688 done
[2022-09-08T12:34:46.799] sched: Allocate JobId=48689 NodeList=gpu05 #CPUs=8 Partition=gpu-v100s
[2022-09-08T12:34:47.950] _job_complete: JobId=48689 WEXITSTATUS 1
[2022-09-08T12:34:47.951] _job_complete: JobId=48689 done
[2022-09-08T12:34:48.566] sched: Allocate JobId=48721 NodeList=gpu05 #CPUs=12 Partition=gpu-v100s
[2022-09-08T13:36:09.556] _slurm_rpc_submit_batch_job: JobId=48922 InitPrio=900 usec=524
[2022-09-08T13:38:28.674] _slurm_rpc_submit_batch_job: JobId=48923 InitPrio=900 usec=500
[2022-09-08T13:40:16.002] _slurm_rpc_submit_batch_job: JobId=48924 InitPrio=900 usec=576
[2022-09-08T13:42:15.953] _slurm_rpc_submit_batch_job: JobId=48925 InitPrio=900 usec=523
[2022-09-08T14:27:12.639] _slurm_rpc_submit_batch_job: JobId=48926 InitPrio=2927 usec=535
[2022-09-08T14:27:13.539] sched: Allocate JobId=48926 NodeList=cpu11 #CPUs=16 Partition=cpu-opteron
[2022-09-08T14:27:16.564] _job_complete: JobId=48926 WEXITSTATUS 1
[2022-09-08T14:27:16.565] _job_complete: JobId=48926 done
[2022-09-08T14:28:31.302] _slurm_rpc_submit_batch_job: JobId=48927 InitPrio=2927 usec=472
[2022-09-08T14:28:31.755] sched: Allocate JobId=48927 NodeList=cpu11 #CPUs=16 Partition=cpu-opteron
[2022-09-08T14:28:34.846] _job_complete: JobId=48927 WEXITSTATUS 1
[2022-09-08T14:28:34.846] _job_complete: JobId=48927 done
[2022-09-08T14:42:52.838] _slurm_rpc_submit_batch_job: JobId=48928 InitPrio=2927 usec=587
[2022-09-08T14:42:53.290] sched: Allocate JobId=48928 NodeList=cpu11 #CPUs=16 Partition=cpu-opteron
[2022-09-08T14:42:59.989] _job_complete: JobId=48928 WEXITSTATUS 0
[2022-09-08T14:42:59.989] _job_complete: JobId=48928 done
[2022-09-08T14:50:04.061] Time limit exhausted for JobId=48621
[2022-09-08T14:52:39.475] _slurm_rpc_submit_batch_job: JobId=48929 InitPrio=450 usec=527
[2022-09-08T14:52:52.919] _slurm_rpc_kill_job: REQUEST_KILL_JOB JobId=48888 uid 548200021
[2022-09-08T14:52:53.684] sched: Allocate JobId=48922 NodeList=cpu04 #CPUs=32 Partition=cpu-opteron
[2022-09-08T14:52:53.685] sched: Allocate JobId=48923 NodeList=cpu04 #CPUs=32 Partition=cpu-opteron
[2022-09-08T14:53:07.400] _job_complete: JobId=48923 WEXITSTATUS 1
[2022-09-08T14:53:07.400] _job_complete: JobId=48923 done
[2022-09-08T14:53:08.060] sched: Allocate JobId=48924 NodeList=cpu04 #CPUs=32 Partition=cpu-opteron
[2022-09-08T14:55:56.107] _slurm_rpc_kill_job: REQUEST_KILL_JOB JobId=48861 uid 548300621
[2022-09-08T14:55:57.139] _slurm_rpc_kill_job: REQUEST_KILL_JOB JobId=48861 uid 548300621
[2022-09-08T14:56:00.373] sched: Allocate JobId=48925 NodeList=cpu07 #CPUs=24 Partition=cpu-opteron
[2022-09-08T14:56:56.261] _slurm_rpc_submit_batch_job: JobId=48930 InitPrio=2927 usec=445
[2022-09-08T15:00:09.226] _job_complete: JobId=48921 WEXITSTATUS 1
[2022-09-08T15:00:09.231] _job_complete: JobId=48921 done
[2022-09-08T15:00:16.472] sched: Allocate JobId=48930 NodeList=cpu08 #CPUs=64 Partition=cpu-opteron
[2022-09-08T15:08:37.149] sched: _slurm_rpc_allocate_resources JobId=48931 NodeList=(null) usec=946
[2022-09-08T15:09:20.628] sched/backfill: _start_job: Started JobId=48931 in cpu-opteron on cpu11
[2022-09-08T15:44:31.992] _job_complete: JobId=48924 WEXITSTATUS 0
[2022-09-08T15:44:31.992] _job_complete: JobId=48924 done
[2022-09-08T15:44:33.919] _job_complete: JobId=48922 WEXITSTATUS 0
[2022-09-08T15:44:33.919] _job_complete: JobId=48922 done
[2022-09-08T15:44:36.126] sched: Allocate JobId=48929 NodeList=cpu04 #CPUs=32 Partition=cpu-opteron
[2022-09-08T16:01:55.671] _job_complete: JobId=48925 WEXITSTATUS 0
[2022-09-08T16:01:55.671] _job_complete: JobId=48925 done
[2022-09-08T16:01:57.931] sched: Allocate JobId=48908 NodeList=cpu07 #CPUs=64 Partition=cpu-opteron
[2022-09-08T16:02:03.162] _job_complete: JobId=48908 WEXITSTATUS 1
[2022-09-08T16:02:03.162] _job_complete: JobId=48908 done
[2022-09-08T16:02:03.877] sched: Allocate JobId=48915 NodeList=cpu07 #CPUs=64 Partition=cpu-opteron
[2022-09-08T16:02:08.476] _job_complete: JobId=48915 WEXITSTATUS 1
[2022-09-08T16:02:08.476] _job_complete: JobId=48915 done
[2022-09-08T16:04:57.019] _slurm_rpc_submit_batch_job: JobId=48932 InitPrio=1126 usec=466
[2022-09-08T16:07:28.454] _slurm_rpc_kill_job: REQUEST_KILL_JOB JobId=48932 uid 548300547
[2022-09-08T16:08:20.674] _slurm_rpc_kill_job: REQUEST_KILL_JOB JobId=48842 uid 548300547
[2022-09-08T16:08:37.832] _slurm_rpc_submit_batch_job: JobId=48933 InitPrio=1126 usec=538
[2022-09-08T16:10:20.910] _slurm_rpc_submit_batch_job: JobId=48934 InitPrio=1126 usec=480
[2022-09-08T16:10:39.056] _slurm_rpc_kill_job: REQUEST_KILL_JOB JobId=48933 uid 548300547
[2022-09-08T16:10:39.056] _slurm_rpc_kill_job: REQUEST_KILL_JOB JobId=48934 uid 548300547
[2022-09-08T16:12:19.037] _slurm_rpc_submit_batch_job: JobId=48935 InitPrio=1126 usec=416
[2022-09-08T16:13:36.995] _slurm_rpc_submit_batch_job: JobId=48936 InitPrio=1126 usec=524
[2022-09-08T16:15:18.794] _slurm_rpc_submit_batch_job: JobId=48937 InitPrio=225 usec=410
[2022-09-08T16:15:19.115] sched: Allocate JobId=48937 NodeList=cpu07 #CPUs=64 Partition=cpu-opteron
[2022-09-08T16:16:03.747] _slurm_rpc_submit_batch_job: JobId=48938 InitPrio=225 usec=441
[2022-09-08T16:28:46.876] _slurm_rpc_submit_batch_job: JobId=48939 InitPrio=900 usec=415
[2022-09-08T16:38:25.183] _slurm_rpc_submit_batch_job: JobId=48940 InitPrio=900 usec=621
[2022-09-08T16:38:25.519] sched: Allocate JobId=48940 NodeList=cpu04 #CPUs=32 Partition=cpu-opteron
[2022-09-08T16:40:05.630] _slurm_rpc_submit_batch_job: JobId=48941 InitPrio=900 usec=476
[2022-09-08T16:41:03.237] _slurm_rpc_submit_batch_job: JobId=48942 InitPrio=900 usec=419
[2022-09-08T16:46:25.677] _slurm_rpc_submit_batch_job: JobId=48943 InitPrio=900 usec=530
[2022-09-08T16:59:44.471] _slurm_rpc_submit_batch_job: JobId=48944 InitPrio=450 usec=591
[2022-09-08T17:00:53.150] _slurm_rpc_kill_job: REQUEST_KILL_JOB JobId=48929 uid 548200021
[2022-09-08T17:00:53.956] sched: Allocate JobId=48941 NodeList=cpu04 #CPUs=32 Partition=cpu-opteron
[2022-09-08T17:01:00.334] _job_complete: JobId=48941 WEXITSTATUS 1
[2022-09-08T17:01:00.334] _job_complete: JobId=48941 done
[2022-09-08T17:01:01.019] sched: Allocate JobId=48942 NodeList=cpu04 #CPUs=32 Partition=cpu-opteron
[2022-09-08T17:02:28.697] _slurm_rpc_submit_batch_job: JobId=48945 InitPrio=900 usec=645
[2022-09-08T17:02:42.844] _slurm_rpc_kill_job: REQUEST_KILL_JOB JobId=48945 uid 548200023
[2022-09-08T17:03:31.601] _slurm_rpc_submit_batch_job: JobId=48946 InitPrio=900 usec=438
[2022-09-08T17:03:32.094] sched: Allocate JobId=48946 NodeList=gpu04 #CPUs=5 Partition=gpu-k40c
[2022-09-08T17:04:31.843] _job_complete: JobId=48946 WEXITSTATUS 0
[2022-09-08T17:04:31.843] _job_complete: JobId=48946 done
[2022-09-08T17:14:07.131] _slurm_rpc_submit_batch_job: JobId=48947 InitPrio=450 usec=459
[2022-09-08T17:14:36.875] _slurm_rpc_kill_job: REQUEST_KILL_JOB JobId=48905 uid 548200021
[2022-09-08T17:14:38.966] sched: Allocate JobId=48947 NodeList=gpu02 #CPUs=8 Partition=gpu-titan
[2022-09-08T17:14:41.009] _job_complete: JobId=48947 WEXITSTATUS 1
[2022-09-08T17:14:41.010] _job_complete: JobId=48947 done
[2022-09-08T17:20:07.731] _slurm_rpc_submit_batch_job: JobId=48948 InitPrio=450 usec=440
[2022-09-08T17:20:07.753] sched: Allocate JobId=48948 NodeList=gpu02 #CPUs=8 Partition=gpu-titan
[2022-09-08T17:24:55.792] _slurm_rpc_submit_batch_job: JobId=48949 InitPrio=450 usec=538
[2022-09-08T17:30:03.334] _slurm_rpc_submit_batch_job: JobId=48950 InitPrio=450 usec=482
[2022-09-08T17:33:43.506] _job_complete: JobId=48940 WEXITSTATUS 0
[2022-09-08T17:33:43.506] _job_complete: JobId=48940 done
[2022-09-08T17:33:44.884] sched: Allocate JobId=48943 NodeList=cpu04 #CPUs=32 Partition=cpu-opteron
[2022-09-08T17:34:19.889] _job_complete: JobId=48931 WEXITSTATUS 0
[2022-09-08T17:34:19.890] _job_complete: JobId=48931 done
[2022-09-08T17:56:49.391] _job_complete: JobId=48942 WEXITSTATUS 0
[2022-09-08T17:56:49.391] _job_complete: JobId=48942 done
[2022-09-08T18:27:36.807] Time limit exhausted for JobId=48609
[2022-09-08T18:27:39.155] sched: Allocate JobId=48944 NodeList=cpu09 #CPUs=32 Partition=cpu-opteron
[2022-09-08T18:29:27.634] _job_complete: JobId=48943 WEXITSTATUS 0
[2022-09-08T18:29:27.634] _job_complete: JobId=48943 done
[2022-09-08T18:29:29.921] sched: Allocate JobId=48938 NodeList=cpu04 #CPUs=64 Partition=cpu-opteron
[2022-09-08T18:38:04.624] _slurm_rpc_submit_batch_job: JobId=48951 InitPrio=225 usec=400
[2022-09-08T19:07:41.592] _job_complete: JobId=48937 WEXITSTATUS 0
[2022-09-08T19:07:41.593] _job_complete: JobId=48937 done
[2022-09-08T19:07:45.077] sched: Allocate JobId=48951 NodeList=cpu07 #CPUs=64 Partition=cpu-opteron
[2022-09-08T20:35:05.342] _slurm_rpc_submit_batch_job: JobId=48952 InitPrio=225 usec=558
[2022-09-08T21:20:17.217] _job_complete: JobId=48938 WEXITSTATUS 0
[2022-09-08T21:20:17.221] _job_complete: JobId=48938 done
[2022-09-08T21:20:19.680] sched: Allocate JobId=48952 NodeList=cpu04 #CPUs=64 Partition=cpu-opteron
[2022-09-08T21:26:36.710] _job_complete: JobId=48873 WEXITSTATUS 0
[2022-09-08T21:26:36.711] _job_complete: JobId=48873 done
[2022-09-08T21:40:45.318] sched: _slurm_rpc_allocate_resources JobId=48953 NodeList=(null) usec=1087
[2022-09-08T21:40:45.532] sched: Allocate JobId=48953 NodeList=cpu11 #CPUs=1 Partition=cpu-opteron
[2022-09-09T00:01:24.684] _job_complete: JobId=48944 WEXITSTATUS 0
[2022-09-09T00:01:24.684] _job_complete: JobId=48944 done
[2022-09-09T00:06:23.957] _job_complete: JobId=48953 WEXITSTATUS 0
[2022-09-09T00:06:23.958] _job_complete: JobId=48953 done
[2022-09-09T00:11:24.623] cleanup_completing: JobId=48953 completion process took 301 seconds
[2022-09-09T00:40:41.900] _slurm_rpc_submit_batch_job: JobId=48954 InitPrio=450 usec=602
[2022-09-09T00:40:42.493] sched: Allocate JobId=48954 NodeList=cpu03 #CPUs=32 Partition=cpu-opteron
[2022-09-09T01:07:49.615] _slurm_rpc_submit_batch_job: JobId=48955 InitPrio=3603 usec=532
[2022-09-09T01:07:50.617] sched: Allocate JobId=48955 NodeList=cpu09 #CPUs=64 Partition=cpu-opteron
[2022-09-09T01:58:55.023] _slurm_rpc_submit_batch_job: JobId=48956 InitPrio=675 usec=667
[2022-09-09T02:03:00.708] _slurm_rpc_submit_batch_job: JobId=48957 InitPrio=675 usec=553
[2022-09-09T02:03:21.345] sched/backfill: _start_job: Started JobId=48957 in cpu-opteron on cpu11
[2022-09-09T02:43:15.365] _slurm_rpc_submit_batch_job: JobId=48958 InitPrio=2702 usec=654
[2022-09-09T04:06:25.280] _job_complete: JobId=48955 WEXITSTATUS 1
[2022-09-09T04:06:25.286] _job_complete: JobId=48955 done
[2022-09-09T04:06:32.574] sched: Allocate JobId=48958 NodeList=cpu09 #CPUs=64 Partition=cpu-opteron
[2022-09-09T10:49:17.320] _slurm_rpc_submit_batch_job: JobId=48959 InitPrio=3603 usec=530
[2022-09-09T14:17:45.579] _slurm_rpc_kill_job: REQUEST_KILL_JOB JobId=48958 uid 548300621
[2022-09-09T14:17:46.632] _slurm_rpc_kill_job: REQUEST_KILL_JOB JobId=48958 uid 548300621
[2022-09-09T14:17:49.603] _slurm_rpc_submit_batch_job: JobId=48960 InitPrio=2252 usec=565
[2022-09-09T14:17:49.807] sched: Allocate JobId=48959 NodeList=cpu09 #CPUs=64 Partition=cpu-opteron
[2022-09-09T14:17:51.549] _job_complete: JobId=48959 WEXITSTATUS 1
[2022-09-09T14:17:51.549] _job_complete: JobId=48959 done
[2022-09-09T14:17:52.138] sched: Allocate JobId=48960 NodeList=cpu09 #CPUs=64 Partition=cpu-opteron
[2022-09-09T14:53:23.541] sched: _slurm_rpc_allocate_resources JobId=48961 NodeList=(null) usec=635
[2022-09-09T14:53:23.581] sched: Allocate JobId=48961 NodeList=cpu03 #CPUs=1 Partition=cpu-opteron
[2022-09-09T14:56:46.869] _job_complete: JobId=48961 WEXITSTATUS 2
[2022-09-09T14:56:46.869] _job_complete: JobId=48961 done
[2022-09-09T15:41:48.064] _slurm_rpc_submit_batch_job: JobId=48962 InitPrio=3603 usec=548
[2022-09-09T17:26:57.907] _slurm_rpc_kill_job: REQUEST_KILL_JOB JobId=48960 uid 548300621
[2022-09-09T17:27:02.177] sched: Allocate JobId=48962 NodeList=cpu09 #CPUs=64 Partition=cpu-opteron
[2022-09-09T17:27:03.773] _job_complete: JobId=48962 WEXITSTATUS 1
[2022-09-09T17:27:03.774] _job_complete: JobId=48962 done
[2022-09-09T17:27:04.464] sched: Allocate JobId=48956 NodeList=cpu09 #CPUs=64 Partition=cpu-opteron
[2022-09-09T17:27:05.515] _slurm_rpc_kill_job: REQUEST_KILL_JOB JobId=48960 uid 548300621
[2022-09-09T17:27:18.711] _slurm_rpc_submit_batch_job: JobId=48963 InitPrio=2252 usec=619
[2022-09-09T18:46:51.560] sched: _slurm_rpc_allocate_resources JobId=48964 NodeList=(null) usec=1063
[2022-09-09T18:47:23.586] sched/backfill: _start_job: Started JobId=48964 in cpu-opteron on cpu03
[2022-09-09T19:17:37.385] sched: _slurm_rpc_allocate_resources JobId=48965 NodeList=(null) usec=1201
[2022-09-09T19:18:23.622] sched/backfill: _start_job: Started JobId=48965 in cpu-opteron on cpu03
[2022-09-09T19:30:23.081] _job_complete: JobId=48867 WEXITSTATUS 1
[2022-09-09T19:30:23.087] _job_complete: JobId=48867 done
[2022-09-09T19:30:25.876] sched: Allocate JobId=48869 NodeList=gpu01 #CPUs=16 Partition=gpu-k10
[2022-09-09T19:42:58.627] _slurm_rpc_kill_job: REQUEST_KILL_JOB JobId=48954 uid 548200021
[2022-09-09T19:52:56.517] _slurm_rpc_submit_batch_job: JobId=48966 InitPrio=450 usec=478
[2022-09-09T20:03:16.918] _slurm_rpc_kill_job: REQUEST_KILL_JOB JobId=48964 uid 548200021
[2022-09-09T20:03:22.311] _slurm_rpc_kill_job: REQUEST_KILL_JOB JobId=48965 uid 548200021
[2022-09-09T20:08:17.199] cleanup_completing: JobId=48964 completion process took 301 seconds
[2022-09-09T20:08:23.174] cleanup_completing: JobId=48965 completion process took 301 seconds
[2022-09-09T20:08:23.192] sched: Allocate JobId=48963 NodeList=cpu03 #CPUs=64 Partition=cpu-opteron
[2022-09-09T20:22:47.422] _slurm_rpc_submit_batch_job: JobId=48967 InitPrio=3603 usec=433
[2022-09-09T20:56:15.673] _job_create: exceeded association/QOS limit for user 548200045: AssocGrpCpuLimit
[2022-09-09T20:56:15.673] _slurm_rpc_submit_batch_job: Job violates accounting/QOS policy (job submit limit, user's size and/or time limits)
[2022-09-09T21:05:38.197] _slurm_rpc_kill_job: REQUEST_KILL_JOB JobId=48967 uid 548300593
[2022-09-09T21:11:36.595] _slurm_rpc_submit_batch_job: JobId=48968 InitPrio=3603 usec=543
[2022-09-09T21:38:49.146] _slurm_rpc_submit_batch_job: JobId=48969 InitPrio=2252 usec=591
[2022-09-09T21:42:12.230] Time limit exhausted for JobId=48549
[2022-09-09T21:42:15.238] sched: Allocate JobId=48871 NodeList=cpu13 #CPUs=48 Partition=cpu-epyc
[2022-09-09T21:46:45.388] _slurm_rpc_submit_batch_job: JobId=48970 InitPrio=3603 usec=544
[2022-09-09T22:33:45.134] _job_complete: JobId=48883 WEXITSTATUS 1
[2022-09-09T22:33:45.135] _job_complete: JobId=48883 done
[2022-09-09T22:33:46.389] sched: Allocate JobId=48968 NodeList=cpu05 #CPUs=64 Partition=cpu-opteron
[2022-09-10T00:26:49.699] _job_complete: JobId=48968 WEXITSTATUS 1
[2022-09-10T00:26:49.704] _job_complete: JobId=48968 done
[2022-09-10T00:26:52.005] sched: Allocate JobId=48970 NodeList=cpu05 #CPUs=64 Partition=cpu-opteron
[2022-09-10T00:26:52.906] _job_complete: JobId=48970 WEXITSTATUS 2
[2022-09-10T00:26:52.907] _job_complete: JobId=48970 done
[2022-09-10T00:26:53.586] sched: Allocate JobId=48969 NodeList=cpu05 #CPUs=64 Partition=cpu-opteron
[2022-09-10T00:27:22.202] _job_complete: JobId=48969 WEXITSTATUS 1
[2022-09-10T00:27:22.202] _job_complete: JobId=48969 done
[2022-09-10T00:27:23.080] sched: Allocate JobId=48966 NodeList=cpu05 #CPUs=32 Partition=cpu-opteron
[2022-09-10T01:04:37.891] _slurm_rpc_submit_batch_job: JobId=48971 InitPrio=2252 usec=681
[2022-09-10T01:23:44.858] _slurm_rpc_submit_batch_job: JobId=48972 InitPrio=2252 usec=471
[2022-09-10T01:23:45.318] sched: Allocate JobId=48972 NodeList=cpu05 #CPUs=8 Partition=cpu-opteron
[2022-09-10T01:24:29.415] _slurm_rpc_submit_batch_job: JobId=48973 InitPrio=2252 usec=486
[2022-09-10T01:24:30.359] sched: Allocate JobId=48973 NodeList=cpu05 #CPUs=8 Partition=cpu-opteron
[2022-09-10T01:27:51.221] _job_complete: JobId=48973 WEXITSTATUS 1
[2022-09-10T01:27:51.222] _job_complete: JobId=48973 done
[2022-09-10T02:16:23.823] _slurm_rpc_submit_batch_job: JobId=48974 InitPrio=3603 usec=521
[2022-09-10T02:18:06.974] _slurm_rpc_submit_batch_job: JobId=48975 InitPrio=3603 usec=446
[2022-09-10T02:18:29.768] _slurm_rpc_kill_job: REQUEST_KILL_JOB JobId=48974 uid 548300593
[2022-09-10T02:19:23.542] _slurm_rpc_submit_batch_job: JobId=48976 InitPrio=3603 usec=459
[2022-09-10T02:51:16.348] _job_complete: JobId=48972 WEXITSTATUS 0
[2022-09-10T02:51:16.349] _job_complete: JobId=48972 done
[2022-09-10T03:22:32.155] _slurm_rpc_submit_batch_job: JobId=48977 InitPrio=2252 usec=600
[2022-09-10T03:23:24.219] sched/backfill: _start_job: Started JobId=48977 in cpu-opteron on cpu05
[2022-09-10T03:26:43.885] _job_complete: JobId=48977 WEXITSTATUS 1
[2022-09-10T03:26:43.886] _job_complete: JobId=48977 done
[2022-09-10T08:20:52.508] _slurm_rpc_submit_batch_job: JobId=48978 InitPrio=225 usec=497
[2022-09-10T13:15:20.297] Time limit exhausted for JobId=48720
[2022-09-10T14:14:24.249] _slurm_rpc_submit_batch_job: JobId=48979 InitPrio=2252 usec=443
[2022-09-10T14:14:25.170] sched/backfill: _start_job: Started JobId=48979 in cpu-opteron on cpu05
[2022-09-10T16:47:21.605] _slurm_rpc_submit_batch_job: JobId=48980 InitPrio=1801 usec=560
[2022-09-10T16:56:51.959] _slurm_rpc_submit_batch_job: JobId=48981 InitPrio=1801 usec=525
[2022-09-10T17:08:36.305] _slurm_rpc_submit_batch_job: JobId=48982 InitPrio=1801 usec=522
[2022-09-10T17:10:02.891] _slurm_rpc_kill_job: REQUEST_KILL_JOB JobId=48963 uid 548300621
[2022-09-10T17:10:04.183] _slurm_rpc_kill_job: REQUEST_KILL_JOB JobId=48963 uid 548300621
[2022-09-10T17:10:06.031] sched: Allocate JobId=48975 NodeList=cpu03 #CPUs=64 Partition=cpu-opteron
[2022-09-10T17:10:42.496] _job_complete: JobId=48975 WEXITSTATUS 104
[2022-09-10T17:10:42.496] _job_complete: JobId=48975 done
[2022-09-10T17:10:43.007] sched: Allocate JobId=48976 NodeList=cpu03 #CPUs=64 Partition=cpu-opteron
[2022-09-10T17:59:28.556] _job_complete: JobId=48890 WEXITSTATUS 0
[2022-09-10T17:59:28.561] _job_complete: JobId=48890 done
[2022-09-10T17:59:32.081] sched: Allocate JobId=48980 NodeList=cpu01 #CPUs=64 Partition=cpu-opteron
[2022-09-10T17:59:35.503] _job_complete: JobId=48980 WEXITSTATUS 1
[2022-09-10T17:59:35.503] _job_complete: JobId=48980 done
[2022-09-10T17:59:36.142] sched: Allocate JobId=48981 NodeList=cpu01 #CPUs=64 Partition=cpu-opteron
[2022-09-10T20:54:27.076] _job_complete: JobId=48952 WEXITSTATUS 0
[2022-09-10T20:54:27.081] _job_complete: JobId=48952 done
[2022-09-10T20:54:30.429] sched: Allocate JobId=48982 NodeList=cpu04 #CPUs=64 Partition=cpu-opteron
[2022-09-10T21:25:01.132] _job_complete: JobId=48868 WEXITSTATUS 1
[2022-09-10T21:25:01.137] _job_complete: JobId=48868 done
[2022-09-10T21:25:03.397] sched: Allocate JobId=48891 NodeList=gpu03 #CPUs=16 Partition=gpu-k10
[2022-09-10T22:16:09.209] _job_complete: JobId=48976 WEXITSTATUS 1
[2022-09-10T22:16:09.215] _job_complete: JobId=48976 done
[2022-09-10T22:36:11.793] _slurm_rpc_submit_batch_job: JobId=48983 InitPrio=3378 usec=498
[2022-09-10T22:36:12.721] sched: Allocate JobId=48983 NodeList=cpu03 #CPUs=64 Partition=cpu-opteron
[2022-09-10T22:40:18.150] _slurm_rpc_submit_batch_job: JobId=48984 InitPrio=3378 usec=503
[2022-09-10T22:59:33.030] _slurm_rpc_kill_job: REQUEST_KILL_JOB JobId=48983 uid 548300593
[2022-09-10T22:59:37.184] sched: Allocate JobId=48984 NodeList=cpu03 #CPUs=64 Partition=cpu-opteron
[2022-09-10T22:59:38.997] _slurm_rpc_submit_batch_job: JobId=48985 InitPrio=3378 usec=477
[2022-09-10T23:00:16.694] _job_complete: JobId=48984 WEXITSTATUS 104
[2022-09-10T23:00:16.695] _job_complete: JobId=48984 done
[2022-09-10T23:00:17.219] sched: Allocate JobId=48985 NodeList=cpu03 #CPUs=64 Partition=cpu-opteron
[2022-09-10T23:00:31.193] _slurm_rpc_kill_job: REQUEST_KILL_JOB JobId=48984 uid 548300593
[2022-09-10T23:01:40.159] _slurm_rpc_submit_batch_job: JobId=48986 InitPrio=3378 usec=507
[2022-09-11T02:25:45.787] _job_complete: JobId=48979 WEXITSTATUS 0
[2022-09-11T02:25:45.793] _job_complete: JobId=48979 done
[2022-09-11T04:05:17.928] _job_complete: JobId=48985 WEXITSTATUS 1
[2022-09-11T04:05:17.934] _job_complete: JobId=48985 done
[2022-09-11T04:05:24.070] sched: Allocate JobId=48986 NodeList=cpu03 #CPUs=64 Partition=cpu-opteron
[2022-09-11T04:05:25.288] _job_complete: JobId=48986 WEXITSTATUS 102
[2022-09-11T04:05:25.289] _job_complete: JobId=48986 done
[2022-09-11T04:08:27.214] _slurm_rpc_submit_batch_job: JobId=48987 InitPrio=3378 usec=549
[2022-09-11T04:08:27.426] sched: Allocate JobId=48987 NodeList=cpu03 #CPUs=64 Partition=cpu-opteron
[2022-09-11T04:09:18.874] _job_complete: JobId=48987 WEXITSTATUS 104
[2022-09-11T04:09:18.874] _job_complete: JobId=48987 done
[2022-09-11T04:18:19.951] _slurm_rpc_submit_batch_job: JobId=48988 InitPrio=3378 usec=514
[2022-09-11T04:18:20.461] sched: Allocate JobId=48988 NodeList=cpu03 #CPUs=64 Partition=cpu-opteron
[2022-09-11T04:41:09.853] _slurm_rpc_submit_batch_job: JobId=48989 InitPrio=3378 usec=494
[2022-09-11T11:52:24.357] Time limit exhausted for JobId=48728
[2022-09-11T11:52:26.695] sched: Allocate JobId=48989 NodeList=cpu10 #CPUs=64 Partition=cpu-opteron
[2022-09-11T12:46:49.744] _slurm_rpc_submit_batch_job: JobId=48990 InitPrio=225 usec=478
[2022-09-11T12:58:48.061] _slurm_rpc_submit_batch_job: JobId=48991 InitPrio=225 usec=509
[2022-09-11T13:00:01.930] _job_complete: JobId=48989 WEXITSTATUS 1
[2022-09-11T13:00:01.931] _job_complete: JobId=48989 done
[2022-09-11T13:00:07.208] sched: Allocate JobId=48990 NodeList=cpu10 #CPUs=64 Partition=cpu-opteron
[2022-09-11T13:01:07.563] _slurm_rpc_submit_batch_job: JobId=48992 InitPrio=3153 usec=465
[2022-09-11T13:21:37.542] _slurm_rpc_kill_job: REQUEST_KILL_JOB JobId=48992 uid 548300593
[2022-09-11T13:58:27.416] _slurm_rpc_submit_batch_job: JobId=48993 InitPrio=3153 usec=513
[2022-09-11T14:34:33.400] _job_create: exceeded association/QOS limit for user 548200045: AssocGrpCpuLimit
[2022-09-11T14:34:33.400] _slurm_rpc_submit_batch_job: Job violates accounting/QOS policy (job submit limit, user's size and/or time limits)
[2022-09-11T14:43:23.706] _slurm_rpc_submit_batch_job: JobId=48994 InitPrio=225 usec=460
[2022-09-11T15:12:51.890] _job_complete: JobId=48988 WEXITSTATUS 0
[2022-09-11T15:12:51.895] _job_complete: JobId=48988 done
[2022-09-11T15:12:56.031] sched: Allocate JobId=48993 NodeList=cpu03 #CPUs=64 Partition=cpu-opteron
[2022-09-11T15:16:02.338] _slurm_rpc_submit_batch_job: JobId=48995 InitPrio=3153 usec=513
[2022-09-11T15:30:18.453] _job_complete: JobId=48990 WEXITSTATUS 0
[2022-09-11T15:30:18.459] _job_complete: JobId=48990 done
[2022-09-11T15:30:20.703] sched: Allocate JobId=48995 NodeList=cpu10 #CPUs=64 Partition=cpu-opteron
[2022-09-11T15:32:23.986] _slurm_rpc_kill_job: REQUEST_KILL_JOB JobId=48994 uid 548200017
[2022-09-11T15:46:35.486] _slurm_rpc_kill_job: REQUEST_KILL_JOB JobId=48981 uid 548300621
[2022-09-11T15:46:36.253] _slurm_rpc_kill_job: REQUEST_KILL_JOB JobId=48981 uid 548300621
[2022-09-11T15:46:38.662] sched: Allocate JobId=48991 NodeList=cpu01 #CPUs=64 Partition=cpu-opteron
[2022-09-11T15:48:16.646] _slurm_rpc_submit_batch_job: JobId=48996 InitPrio=1801 usec=565
[2022-09-11T16:30:03.158] _slurm_rpc_submit_batch_job: JobId=48997 InitPrio=1801 usec=530
[2022-09-11T18:01:20.578] _slurm_rpc_submit_batch_job: JobId=48998 InitPrio=3153 usec=596
[2022-09-11T18:41:24.943] _job_complete: JobId=48993 WEXITSTATUS 0
[2022-09-11T18:41:24.948] _job_complete: JobId=48993 done
[2022-09-11T18:41:27.091] sched: Allocate JobId=48998 NodeList=cpu03 #CPUs=64 Partition=cpu-opteron
[2022-09-11T19:20:36.326] _job_complete: JobId=48995 WEXITSTATUS 0
[2022-09-11T19:20:36.327] _job_complete: JobId=48995 done
[2022-09-11T19:20:38.634] sched: Allocate JobId=48996 NodeList=cpu10 #CPUs=64 Partition=cpu-opteron
[2022-09-11T20:36:10.823] _slurm_rpc_submit_batch_job: JobId=48999 InitPrio=3153 usec=506
[2022-09-11T20:38:24.118] _slurm_rpc_kill_job: REQUEST_KILL_JOB JobId=48999 uid 548300593
[2022-09-11T20:47:02.015] _slurm_rpc_submit_batch_job: JobId=49000 InitPrio=3153 usec=416
[2022-09-12T00:07:58.547] _slurm_rpc_kill_job: REQUEST_KILL_JOB JobId=48996 uid 548300621
[2022-09-12T00:08:00.754] _slurm_rpc_kill_job: REQUEST_KILL_JOB JobId=48996 uid 548300621
[2022-09-12T00:08:02.435] sched: Allocate JobId=49000 NodeList=cpu10 #CPUs=64 Partition=cpu-opteron
[2022-09-12T00:08:03.741] _slurm_rpc_submit_batch_job: JobId=49001 InitPrio=1801 usec=531
[2022-09-12T00:11:03.321] _slurm_rpc_kill_job: REQUEST_KILL_JOB JobId=48971 uid 548200029
[2022-09-12T00:11:38.804] _slurm_rpc_submit_batch_job: JobId=49002 InitPrio=2027 usec=499
[2022-09-12T00:12:42.504] _slurm_rpc_submit_batch_job: JobId=49003 InitPrio=2027 usec=409
[2022-09-12T00:14:34.126] _slurm_rpc_submit_batch_job: JobId=49004 InitPrio=2027 usec=648
[2022-09-12T00:15:27.318] sched/backfill: _start_job: Started JobId=49004 in cpu-opteron on cpu05
[2022-09-12T08:24:38.706] _job_complete: JobId=48891 WEXITSTATUS 1
[2022-09-12T08:24:38.711] _job_complete: JobId=48891 done
[2022-09-12T08:24:39.385] sched: Allocate JobId=49002 NodeList=gpu03 #CPUs=16 Partition=gpu-k10
[2022-09-12T09:31:18.862] _job_complete: JobId=48998 WEXITSTATUS 0
[2022-09-12T09:31:18.868] _job_complete: JobId=48998 done
[2022-09-12T09:31:22.002] sched: Allocate JobId=48997 NodeList=cpu03 #CPUs=64 Partition=cpu-opteron
[2022-09-12T09:31:31.263] _job_complete: JobId=48997 WEXITSTATUS 1
[2022-09-12T09:31:31.264] _job_complete: JobId=48997 done
[2022-09-12T09:31:31.777] sched: Allocate JobId=49001 NodeList=cpu03 #CPUs=64 Partition=cpu-opteron
[2022-09-12T10:22:48.640] _job_create: exceeded association/QOS limit for user 548200045: AssocGrpCpuLimit
[2022-09-12T10:22:48.640] _slurm_rpc_submit_batch_job: Job violates accounting/QOS policy (job submit limit, user's size and/or time limits)
[2022-09-12T10:26:19.256] _job_create: exceeded association/QOS limit for user 548200045: AssocGrpCpuLimit
[2022-09-12T10:26:19.256] _slurm_rpc_submit_batch_job: Job violates accounting/QOS policy (job submit limit, user's size and/or time limits)
[2022-09-12T10:27:33.063] _job_create: exceeded association/QOS limit for user 548200045: AssocGrpCpuLimit
[2022-09-12T10:27:33.063] _slurm_rpc_submit_batch_job: Job violates accounting/QOS policy (job submit limit, user's size and/or time limits)
[2022-09-12T10:27:33.073] _job_create: exceeded association/QOS limit for user 548200045: AssocGrpCpuLimit
[2022-09-12T10:27:33.073] _slurm_rpc_submit_batch_job: Job violates accounting/QOS policy (job submit limit, user's size and/or time limits)
[2022-09-12T10:27:33.082] _job_create: exceeded association/QOS limit for user 548200045: AssocGrpCpuLimit
[2022-09-12T10:27:33.082] _slurm_rpc_submit_batch_job: Job violates accounting/QOS policy (job submit limit, user's size and/or time limits)
[2022-09-12T10:27:33.092] _job_create: exceeded association/QOS limit for user 548200045: AssocGrpCpuLimit
[2022-09-12T10:27:33.092] _slurm_rpc_submit_batch_job: Job violates accounting/QOS policy (job submit limit, user's size and/or time limits)
[2022-09-12T10:27:33.101] _job_create: exceeded association/QOS limit for user 548200045: AssocGrpCpuLimit
[2022-09-12T10:27:33.101] _slurm_rpc_submit_batch_job: Job violates accounting/QOS policy (job submit limit, user's size and/or time limits)
[2022-09-12T10:27:33.109] _job_create: exceeded association/QOS limit for user 548200045: AssocGrpCpuLimit
[2022-09-12T10:27:33.109] _slurm_rpc_submit_batch_job: Job violates accounting/QOS policy (job submit limit, user's size and/or time limits)
[2022-09-12T10:27:33.118] _job_create: exceeded association/QOS limit for user 548200045: AssocGrpCpuLimit
[2022-09-12T10:27:33.118] _slurm_rpc_submit_batch_job: Job violates accounting/QOS policy (job submit limit, user's size and/or time limits)
[2022-09-12T10:27:33.126] _job_create: exceeded association/QOS limit for user 548200045: AssocGrpCpuLimit
[2022-09-12T10:27:33.126] _slurm_rpc_submit_batch_job: Job violates accounting/QOS policy (job submit limit, user's size and/or time limits)
[2022-09-12T10:27:33.135] _job_create: exceeded association/QOS limit for user 548200045: AssocGrpCpuLimit
[2022-09-12T10:27:33.135] _slurm_rpc_submit_batch_job: Job violates accounting/QOS policy (job submit limit, user's size and/or time limits)
[2022-09-12T10:27:33.144] _job_create: exceeded association/QOS limit for user 548200045: AssocGrpCpuLimit
[2022-09-12T10:27:33.144] _slurm_rpc_submit_batch_job: Job violates accounting/QOS policy (job submit limit, user's size and/or time limits)
[2022-09-12T10:39:28.262] Time limit exhausted for JobId=48761
[2022-09-12T10:39:31.555] sched: Allocate JobId=48895 NodeList=cpu14 #CPUs=48 Partition=cpu-epyc
[2022-09-12T12:54:23.180] _slurm_rpc_submit_batch_job: JobId=49005 InitPrio=2017 usec=791
[2022-09-12T13:20:03.438] _job_complete: JobId=48991 WEXITSTATUS 0
[2022-09-12T13:20:03.443] _job_complete: JobId=48991 done
[2022-09-12T14:34:23.916] _job_complete: JobId=48869 WEXITSTATUS 1
[2022-09-12T14:34:23.921] _job_complete: JobId=48869 done
[2022-09-12T14:34:26.852] sched: Allocate JobId=49003 NodeList=gpu01 #CPUs=16 Partition=gpu-k10
[2022-09-12T14:35:39.360] _job_complete: JobId=48857 WEXITSTATUS 139
[2022-09-12T14:35:39.364] _job_complete: JobId=48857 done
[2022-09-12T14:35:39.806] sched: Allocate JobId=48939 NodeList=cpu15 #CPUs=24 Partition=cpu-epyc
[2022-09-12T15:16:48.222] _job_complete: JobId=49002 WEXITSTATUS 0
[2022-09-12T15:16:48.224] _job_complete: JobId=49002 done
[2022-09-12T15:16:50.722] sched: Allocate JobId=49005 NodeList=gpu03 #CPUs=16 Partition=gpu-k10
[2022-09-12T16:19:47.396] _slurm_rpc_kill_job: REQUEST_KILL_JOB JobId=47778 uid 548200003
[2022-09-12T16:26:42.296] _slurm_rpc_submit_batch_job: JobId=49006 InitPrio=1345 usec=443
[2022-09-12T16:30:52.380] _job_complete: JobId=49003 WEXITSTATUS 0
[2022-09-12T16:30:52.386] _job_complete: JobId=49003 done
[2022-09-12T16:44:14.423] _job_complete: JobId=49004 WEXITSTATUS 0
[2022-09-12T16:44:14.423] _job_complete: JobId=49004 done
[2022-09-12T16:47:42.863] _job_complete: JobId=49005 WEXITSTATUS 1
[2022-09-12T16:47:42.864] _job_complete: JobId=49005 done
[2022-09-12T16:53:55.334] _slurm_rpc_submit_batch_job: JobId=49007 InitPrio=224 usec=415
[2022-09-12T16:53:55.609] sched: Allocate JobId=49007 NodeList=cpu01 #CPUs=64 Partition=cpu-opteron
[2022-09-12T17:01:18.843] _slurm_rpc_submit_batch_job: JobId=49008 InitPrio=224 usec=429
[2022-09-12T17:07:53.744] sched: _slurm_rpc_allocate_resources JobId=49009 NodeList=(null) usec=1205
[2022-09-12T17:07:54.031] sched: Allocate JobId=49009 NodeList=cpu05 #CPUs=1 Partition=cpu-opteron
[2022-09-12T19:01:19.206] _job_complete: JobId=48895 WEXITSTATUS 1
[2022-09-12T19:01:19.206] _job_complete: JobId=48895 done
[2022-09-12T19:01:19.849] sched: Allocate JobId=48978 NodeList=cpu14 #CPUs=48 Partition=cpu-epyc
[2022-09-12T19:16:21.522] _slurm_rpc_submit_batch_job: JobId=49010 InitPrio=2017 usec=464
[2022-09-12T19:16:21.911] sched: Allocate JobId=49010 NodeList=cpu05 #CPUs=8 Partition=cpu-opteron
[2022-09-12T19:17:08.115] _slurm_rpc_submit_batch_job: JobId=49011 InitPrio=2017 usec=476
[2022-09-12T19:17:08.959] sched: Allocate JobId=49011 NodeList=cpu05 #CPUs=8 Partition=cpu-opteron
[2022-09-12T19:19:29.062] _slurm_rpc_submit_batch_job: JobId=49012 InitPrio=2017 usec=962
[2022-09-12T19:19:29.325] sched: Allocate JobId=49012 NodeList=gpu01 #CPUs=16 Partition=gpu-k10
[2022-09-12T19:21:41.681] _slurm_rpc_submit_batch_job: JobId=49013 InitPrio=2017 usec=547
[2022-09-12T19:21:42.511] sched: Allocate JobId=49013 NodeList=gpu03 #CPUs=16 Partition=gpu-k10
[2022-09-12T19:24:32.014] _slurm_rpc_submit_batch_job: JobId=49014 InitPrio=2017 usec=719
[2022-09-12T19:33:14.735] _job_complete: JobId=49009 WEXITSTATUS 0
[2022-09-12T19:33:14.735] _job_complete: JobId=49009 done
[2022-09-12T19:57:26.286] _slurm_rpc_submit_batch_job: JobId=49015 InitPrio=1569 usec=516
[2022-09-12T20:20:30.393] _slurm_rpc_kill_job: REQUEST_KILL_JOB JobId=49001 uid 548300621
[2022-09-12T20:20:33.273] _slurm_rpc_kill_job: REQUEST_KILL_JOB JobId=49001 uid 548300621
[2022-09-12T20:20:33.595] sched: Allocate JobId=49015 NodeList=cpu03 #CPUs=64 Partition=cpu-opteron
[2022-09-12T20:20:45.614] _job_complete: JobId=49015 WEXITSTATUS 1
[2022-09-12T20:20:45.614] _job_complete: JobId=49015 done
[2022-09-12T20:20:46.115] sched: Allocate JobId=49008 NodeList=cpu03 #CPUs=64 Partition=cpu-opteron
[2022-09-12T20:21:28.996] _slurm_rpc_submit_batch_job: JobId=49016 InitPrio=1569 usec=569
[2022-09-12T20:22:31.831] _slurm_rpc_submit_batch_job: JobId=49017 InitPrio=1569 usec=476
[2022-09-12T20:42:27.154] _job_complete: JobId=49010 WEXITSTATUS 0
[2022-09-12T20:42:27.156] _job_complete: JobId=49010 done
[2022-09-12T20:48:21.240] _job_complete: JobId=49011 WEXITSTATUS 0
[2022-09-12T20:48:21.241] _job_complete: JobId=49011 done
[2022-09-12T21:10:01.694] _job_complete: JobId=48951 WEXITSTATUS 0
[2022-09-12T21:10:01.695] _job_complete: JobId=48951 done
[2022-09-12T21:10:06.986] sched: Allocate JobId=49016 NodeList=cpu07 #CPUs=64 Partition=cpu-opteron
[2022-09-13T00:08:30.199] Time limit exhausted for JobId=49000
[2022-09-13T00:09:01.115] sched: Allocate JobId=49017 NodeList=cpu10 #CPUs=64 Partition=cpu-opteron
[2022-09-13T00:56:43.763] _slurm_rpc_submit_batch_job: JobId=49018 InitPrio=2914 usec=564
[2022-09-13T01:58:11.372] _slurm_rpc_kill_job: REQUEST_KILL_JOB JobId=49017 uid 548300621
[2022-09-13T01:58:12.528] _slurm_rpc_kill_job: REQUEST_KILL_JOB JobId=49017 uid 548300621
[2022-09-13T01:58:16.681] sched: Allocate JobId=49018 NodeList=cpu10 #CPUs=34 Partition=cpu-opteron
[2022-09-13T01:58:40.064] _slurm_rpc_submit_batch_job: JobId=49019 InitPrio=1345 usec=521
[2022-09-13T02:58:03.906] _slurm_rpc_submit_batch_job: JobId=49020 InitPrio=2017 usec=548
[2022-09-13T02:58:04.535] sched: Allocate JobId=49020 NodeList=cpu10 #CPUs=8 Partition=cpu-opteron
[2022-09-13T02:59:17.106] _slurm_rpc_submit_batch_job: JobId=49021 InitPrio=2017 usec=425
[2022-09-13T02:59:17.616] sched: Allocate JobId=49021 NodeList=cpu05 #CPUs=8 Partition=cpu-opteron
[2022-09-13T03:04:49.967] _slurm_rpc_submit_batch_job: JobId=49022 InitPrio=2017 usec=420
[2022-09-13T03:04:50.206] sched: Allocate JobId=49022 NodeList=cpu05 #CPUs=16 Partition=cpu-opteron
[2022-09-13T03:04:56.958] _job_complete: JobId=49022 WEXITSTATUS 1
[2022-09-13T03:04:56.959] _job_complete: JobId=49022 done
[2022-09-13T05:58:00.738] Time limit exhausted for JobId=48762
[2022-09-13T05:58:03.819] sched: Allocate JobId=49006 NodeList=cpu12 #CPUs=48 Partition=cpu-epyc
[2022-09-13T07:06:19.719] _job_complete: JobId=49006 WEXITSTATUS 139
[2022-09-13T07:06:19.720] _job_complete: JobId=49006 done
[2022-09-13T07:27:04.021] _job_complete: JobId=49007 WEXITSTATUS 0
[2022-09-13T07:27:04.022] _job_complete: JobId=49007 done
[2022-09-13T07:27:06.231] sched: Allocate JobId=49019 NodeList=cpu01 #CPUs=64 Partition=cpu-opteron
[2022-09-13T08:04:15.152] _job_complete: JobId=48721 WEXITSTATUS 0
[2022-09-13T08:04:15.152] _job_complete: JobId=48721 done
[2022-09-13T08:04:18.701] sched: Allocate JobId=48935 NodeList=gpu05 #CPUs=8 Partition=gpu-v100s
[2022-09-13T09:03:17.469] _job_complete: JobId=49013 WEXITSTATUS 0
[2022-09-13T09:03:17.490] _job_complete: JobId=49013 done
[2022-09-13T09:03:19.984] sched: Allocate JobId=49014 NodeList=gpu03 #CPUs=16 Partition=gpu-k10
[2022-09-13T09:28:29.112] _slurm_rpc_submit_batch_job: JobId=49023 InitPrio=1793 usec=579
[2022-09-13T09:28:29.320] sched: Allocate JobId=49023 NodeList=gpu04 #CPUs=16 Partition=gpu-k40c
[2022-09-13T10:30:16.298] _slurm_rpc_submit_batch_job: JobId=49024 InitPrio=15156 usec=548
[2022-09-13T10:30:17.059] sched: Allocate JobId=49024 NodeList=cpu15 #CPUs=24 Partition=cpu-epyc
[2022-09-13T10:39:59.600] _slurm_rpc_kill_job: REQUEST_KILL_JOB JobId=49024 uid 548300543
[2022-09-13T10:59:05.682] _slurm_rpc_submit_batch_job: JobId=49025 InitPrio=6053 usec=448
[2022-09-13T10:59:06.007] sched: Allocate JobId=49025 NodeList=cpu10 #CPUs=16 Partition=cpu-opteron
[2022-09-13T10:59:08.871] _job_complete: JobId=49025 WEXITSTATUS 1
[2022-09-13T10:59:08.872] _job_complete: JobId=49025 done
[2022-09-13T11:03:43.626] _slurm_rpc_submit_batch_job: JobId=49026 InitPrio=2017 usec=451
[2022-09-13T11:03:44.475] sched: Allocate JobId=49026 NodeList=cpu05 #CPUs=16 Partition=cpu-opteron
[2022-09-13T11:06:58.420] _slurm_rpc_submit_batch_job: JobId=49027 InitPrio=6053 usec=397
[2022-09-13T11:06:58.716] sched: Allocate JobId=49027 NodeList=cpu10 #CPUs=16 Partition=cpu-opteron
[2022-09-13T11:07:01.202] _job_complete: JobId=49027 WEXITSTATUS 1
[2022-09-13T11:07:01.202] _job_complete: JobId=49027 done
[2022-09-13T11:08:19.759] _job_complete: JobId=49026 WEXITSTATUS 0
[2022-09-13T11:08:19.760] _job_complete: JobId=49026 done
[2022-09-13T12:11:23.523] _slurm_rpc_submit_batch_job: JobId=49028 InitPrio=2017 usec=565
[2022-09-13T12:11:24.478] sched: Allocate JobId=49028 NodeList=cpu05 #CPUs=16 Partition=cpu-opteron
[2022-09-13T12:11:30.444] _slurm_rpc_kill_job: REQUEST_KILL_JOB JobId=49028 uid 548200029
[2022-09-13T12:12:05.541] _slurm_rpc_submit_batch_job: JobId=49029 InitPrio=2017 usec=427
[2022-09-13T12:12:06.522] sched: Allocate JobId=49029 NodeList=cpu05 #CPUs=16 Partition=cpu-opteron
[2022-09-13T12:16:39.199] _job_complete: JobId=49029 WEXITSTATUS 0
[2022-09-13T12:16:39.200] _job_complete: JobId=49029 done
[2022-09-13T12:21:06.472] _slurm_rpc_submit_batch_job: JobId=49030 InitPrio=2017 usec=510
[2022-09-13T12:21:06.483] sched: Allocate JobId=49030 NodeList=cpu05 #CPUs=16 Partition=cpu-opteron
[2022-09-13T12:21:08.781] _job_complete: JobId=49030 WEXITSTATUS 1
[2022-09-13T12:21:08.782] _job_complete: JobId=49030 done
[2022-09-13T12:21:37.090] _slurm_rpc_submit_batch_job: JobId=49031 InitPrio=2017 usec=370
[2022-09-13T12:21:37.530] sched: Allocate JobId=49031 NodeList=cpu05 #CPUs=16 Partition=cpu-opteron
[2022-09-13T12:23:10.078] _slurm_rpc_submit_batch_job: JobId=49032 InitPrio=2017 usec=371
[2022-09-13T12:23:31.576] _job_complete: JobId=48939 WEXITSTATUS 0
[2022-09-13T12:23:31.576] _job_complete: JobId=48939 done
[2022-09-13T12:24:10.685] _slurm_rpc_submit_batch_job: JobId=49033 InitPrio=2017 usec=459
[2022-09-13T12:24:55.943] _slurm_rpc_submit_batch_job: JobId=49034 InitPrio=2017 usec=459
[2022-09-13T12:25:27.781] _slurm_rpc_submit_batch_job: JobId=49035 InitPrio=2017 usec=463
[2022-09-13T12:26:09.441] _slurm_rpc_submit_batch_job: JobId=49036 InitPrio=2017 usec=368
[2022-09-13T12:26:22.944] _job_complete: JobId=49031 WEXITSTATUS 0
[2022-09-13T12:26:22.945] _job_complete: JobId=49031 done
[2022-09-13T12:26:27.181] sched: Allocate JobId=49032 NodeList=cpu05 #CPUs=16 Partition=cpu-opteron
[2022-09-13T12:31:13.992] _job_complete: JobId=49032 WEXITSTATUS 0
[2022-09-13T12:31:13.992] _job_complete: JobId=49032 done
[2022-09-13T12:31:18.455] sched: Allocate JobId=49033 NodeList=cpu05 #CPUs=16 Partition=cpu-opteron
[2022-09-13T12:35:47.453] _job_complete: JobId=49033 WEXITSTATUS 0
[2022-09-13T12:35:47.454] _job_complete: JobId=49033 done
[2022-09-13T12:35:49.750] sched: Allocate JobId=49034 NodeList=cpu05 #CPUs=16 Partition=cpu-opteron
[2022-09-13T12:39:02.041] _slurm_rpc_submit_batch_job: JobId=49037 InitPrio=1569 usec=412
[2022-09-13T12:39:02.422] sched: Allocate JobId=49037 NodeList=cpu12 #CPUs=48 Partition=cpu-epyc
[2022-09-13T12:40:30.231] _job_complete: JobId=49034 WEXITSTATUS 0
[2022-09-13T12:40:30.231] _job_complete: JobId=49034 done
[2022-09-13T12:40:34.561] sched: Allocate JobId=49035 NodeList=cpu05 #CPUs=16 Partition=cpu-opteron
[2022-09-13T12:45:45.207] _job_complete: JobId=49035 WEXITSTATUS 0
[2022-09-13T12:45:45.208] _job_complete: JobId=49035 done
[2022-09-13T12:45:49.629] sched: Allocate JobId=49036 NodeList=cpu05 #CPUs=16 Partition=cpu-opteron
[2022-09-13T12:50:34.529] _job_complete: JobId=49036 WEXITSTATUS 0
[2022-09-13T12:50:34.530] _job_complete: JobId=49036 done
[2022-09-13T14:02:48.389] _job_complete: JobId=49037 WEXITSTATUS 139
[2022-09-13T14:02:48.390] _job_complete: JobId=49037 done
[2022-09-13T14:37:40.768] _job_complete: JobId=49021 WEXITSTATUS 0
[2022-09-13T14:37:40.773] _job_complete: JobId=49021 done
[2022-09-13T14:41:09.597] _pick_best_nodes: JobId=49038 never runnable in partition cpu-opteron
[2022-09-13T14:41:09.597] _slurm_rpc_submit_batch_job: Requested node configuration is not available
[2022-09-13T14:41:23.577] _slurm_rpc_submit_batch_job: JobId=49039 InitPrio=896 usec=483
[2022-09-13T14:41:48.709] _slurm_rpc_kill_job: REQUEST_KILL_JOB JobId=49039 uid 548200023
[2022-09-13T14:42:06.930] _slurm_rpc_submit_batch_job: JobId=49040 InitPrio=896 usec=535
[2022-09-13T14:42:07.506] sched: Allocate JobId=49040 NodeList=cpu12 #CPUs=24 Partition=cpu-epyc
[2022-09-13T14:44:47.855] _job_complete: JobId=49040 WEXITSTATUS 0
[2022-09-13T14:44:47.855] _job_complete: JobId=49040 done
[2022-09-13T14:45:24.877] _slurm_rpc_submit_batch_job: JobId=49041 InitPrio=896 usec=468
[2022-09-13T14:45:24.902] sched: Allocate JobId=49041 NodeList=cpu12 #CPUs=24 Partition=cpu-epyc
[2022-09-13T14:45:45.815] _job_complete: JobId=49041 WEXITSTATUS 0
[2022-09-13T14:45:45.815] _job_complete: JobId=49041 done
[2022-09-13T14:46:35.342] _slurm_rpc_submit_batch_job: JobId=49042 InitPrio=896 usec=448
[2022-09-13T14:46:35.996] sched: Allocate JobId=49042 NodeList=cpu12 #CPUs=24 Partition=cpu-epyc
[2022-09-13T14:47:38.904] _slurm_rpc_submit_batch_job: JobId=49043 InitPrio=896 usec=579
[2022-09-13T14:47:39.083] sched: Allocate JobId=49043 NodeList=cpu12 #CPUs=24 Partition=cpu-epyc
[2022-09-13T14:48:55.007] _slurm_rpc_submit_batch_job: JobId=49044 InitPrio=896 usec=463
[2022-09-13T14:48:55.293] sched: Allocate JobId=49044 NodeList=cpu15 #CPUs=48 Partition=cpu-epyc
[2022-09-13T14:49:05.517] _job_complete: JobId=49044 WEXITSTATUS 1
[2022-09-13T14:49:05.517] _job_complete: JobId=49044 done
[2022-09-13T14:57:11.590] _slurm_rpc_submit_batch_job: JobId=49045 InitPrio=896 usec=446
[2022-09-13T14:57:12.094] sched: Allocate JobId=49045 NodeList=cpu15 #CPUs=48 Partition=cpu-epyc
[2022-09-13T15:04:55.071] _slurm_rpc_submit_batch_job: JobId=49046 InitPrio=896 usec=600
[2022-09-13T15:04:55.954] sched: Allocate JobId=49046 NodeList=gpu02 #CPUs=4 Partition=gpu-titan
[2022-09-13T15:04:58.529] _job_complete: JobId=49046 WEXITSTATUS 0
[2022-09-13T15:04:58.529] _job_complete: JobId=49046 done
[2022-09-13T15:07:57.338] _job_complete: JobId=49020 WEXITSTATUS 0
[2022-09-13T15:07:57.339] _job_complete: JobId=49020 done
[2022-09-13T15:28:45.023] _job_complete: JobId=49042 WEXITSTATUS 0
[2022-09-13T15:28:45.023] _job_complete: JobId=49042 done
[2022-09-13T15:36:09.898] _job_complete: JobId=49043 WEXITSTATUS 0
[2022-09-13T15:36:09.898] _job_complete: JobId=49043 done
[2022-09-13T15:38:56.174] _slurm_rpc_submit_batch_job: JobId=49047 InitPrio=1569 usec=448
[2022-09-13T15:38:56.687] sched: Allocate JobId=49047 NodeList=cpu12 #CPUs=48 Partition=cpu-epyc
[2022-09-13T16:14:31.342] Time limit exhausted for JobId=48865
[2022-09-13T16:25:31.406] Time limit exhausted for JobId=48866
[2022-09-13T17:41:29.888] _slurm_rpc_submit_batch_job: JobId=49048 InitPrio=896 usec=641
[2022-09-13T17:42:19.066] _slurm_rpc_kill_job: REQUEST_KILL_JOB JobId=49048 uid 548200023
[2022-09-13T17:42:46.087] _slurm_rpc_submit_batch_job: JobId=49049 InitPrio=896 usec=537
[2022-09-13T17:42:46.486] sched: Allocate JobId=49049 NodeList=cpu05 #CPUs=16 Partition=cpu-opteron
[2022-09-13T17:42:49.089] _job_complete: JobId=49049 WEXITSTATUS 21
[2022-09-13T17:42:49.089] _job_complete: JobId=49049 done
[2022-09-13T17:43:15.545] _slurm_rpc_submit_batch_job: JobId=49050 InitPrio=896 usec=468
[2022-09-13T17:43:15.554] sched: Allocate JobId=49050 NodeList=cpu05 #CPUs=16 Partition=cpu-opteron
[2022-09-13T17:43:17.194] _job_complete: JobId=49050 WEXITSTATUS 21
[2022-09-13T17:43:17.195] _job_complete: JobId=49050 done
[2022-09-13T17:43:58.523] _slurm_rpc_submit_batch_job: JobId=49051 InitPrio=896 usec=485
[2022-09-13T17:43:58.610] sched: Allocate JobId=49051 NodeList=cpu05 #CPUs=32 Partition=cpu-opteron
[2022-09-13T17:44:00.430] _job_complete: JobId=49051 WEXITSTATUS 21
[2022-09-13T17:44:00.431] _job_complete: JobId=49051 done
[2022-09-13T17:45:04.352] _slurm_rpc_submit_batch_job: JobId=49052 InitPrio=896 usec=411
[2022-09-13T17:45:04.699] sched: Allocate JobId=49052 NodeList=cpu05 #CPUs=32 Partition=cpu-opteron
[2022-09-13T17:45:40.583] _job_complete: JobId=49052 WEXITSTATUS 31
[2022-09-13T17:45:40.584] _job_complete: JobId=49052 done
[2022-09-13T17:47:45.481] _slurm_rpc_submit_batch_job: JobId=49053 InitPrio=896 usec=506
[2022-09-13T17:47:45.998] sched: Allocate JobId=49053 NodeList=cpu05 #CPUs=32 Partition=cpu-opteron
[2022-09-13T17:48:23.072] _job_complete: JobId=49053 WEXITSTATUS 1
[2022-09-13T17:48:23.072] _job_complete: JobId=49053 done
[2022-09-13T17:53:34.753] _slurm_rpc_submit_batch_job: JobId=49054 InitPrio=896 usec=491
[2022-09-13T17:53:35.630] sched: Allocate JobId=49054 NodeList=cpu05 #CPUs=32 Partition=cpu-opteron
[2022-09-13T17:54:12.971] _job_complete: JobId=49054 WEXITSTATUS 1
[2022-09-13T17:54:12.972] _job_complete: JobId=49054 done
[2022-09-13T17:55:23.242] _slurm_rpc_submit_batch_job: JobId=49055 InitPrio=896 usec=461
[2022-09-13T17:55:24.773] sched: Allocate JobId=49055 NodeList=gpu02 #CPUs=4 Partition=gpu-titan
[2022-09-13T17:55:25.844] _job_complete: JobId=49055 WEXITSTATUS 0
[2022-09-13T17:55:25.844] _job_complete: JobId=49055 done
[2022-09-13T17:56:25.058] _slurm_rpc_submit_batch_job: JobId=49056 InitPrio=896 usec=511
[2022-09-13T17:56:25.859] sched: Allocate JobId=49056 NodeList=gpu02 #CPUs=4 Partition=gpu-titan
[2022-09-13T17:56:43.348] _job_complete: JobId=49056 WEXITSTATUS 1
[2022-09-13T17:56:43.348] _job_complete: JobId=49056 done
[2022-09-13T17:57:31.442] _slurm_rpc_submit_batch_job: JobId=49057 InitPrio=896 usec=418
[2022-09-13T17:57:31.951] sched: Allocate JobId=49057 NodeList=gpu02 #CPUs=4 Partition=gpu-titan
[2022-09-13T17:57:48.741] _job_complete: JobId=49057 WEXITSTATUS 31
[2022-09-13T17:57:48.741] _job_complete: JobId=49057 done
[2022-09-13T17:58:47.561] _slurm_rpc_submit_batch_job: JobId=49058 InitPrio=896 usec=474
[2022-09-13T17:58:48.169] sched: Allocate JobId=49058 NodeList=gpu02 #CPUs=4 Partition=gpu-titan
[2022-09-13T17:59:05.788] _job_complete: JobId=49058 WEXITSTATUS 0
[2022-09-13T17:59:05.788] _job_complete: JobId=49058 done
[2022-09-13T18:04:43.055] _slurm_rpc_submit_batch_job: JobId=49059 InitPrio=896 usec=560
[2022-09-13T18:04:43.746] sched: Allocate JobId=49059 NodeList=gpu02 #CPUs=4 Partition=gpu-titan
[2022-09-13T18:05:04.250] _job_complete: JobId=49059 WEXITSTATUS 0
[2022-09-13T18:05:04.251] _job_complete: JobId=49059 done
[2022-09-13T18:06:08.723] _slurm_rpc_submit_batch_job: JobId=49060 InitPrio=896 usec=460
[2022-09-13T18:06:08.855] sched: Allocate JobId=49060 NodeList=gpu02 #CPUs=5 Partition=gpu-titan
[2022-09-13T18:06:47.737] _job_complete: JobId=49060 WEXITSTATUS 0
[2022-09-13T18:06:47.737] _job_complete: JobId=49060 done
[2022-09-13T18:07:42.219] _slurm_rpc_submit_batch_job: JobId=49061 InitPrio=896 usec=538
[2022-09-13T18:07:42.983] sched: Allocate JobId=49061 NodeList=gpu02 #CPUs=4 Partition=gpu-titan
[2022-09-13T18:07:43.960] _job_complete: JobId=49061 WEXITSTATUS 0
[2022-09-13T18:07:43.960] _job_complete: JobId=49061 done
[2022-09-13T18:09:07.906] _slurm_rpc_submit_batch_job: JobId=49062 InitPrio=896 usec=535
[2022-09-13T18:09:08.181] sched: Allocate JobId=49062 NodeList=gpu02 #CPUs=4 Partition=gpu-titan
[2022-09-13T18:09:28.915] _job_complete: JobId=49062 WEXITSTATUS 0
[2022-09-13T18:09:28.916] _job_complete: JobId=49062 done
[2022-09-13T18:10:44.779] _slurm_rpc_submit_batch_job: JobId=49063 InitPrio=896 usec=466
[2022-09-13T18:10:45.313] sched: Allocate JobId=49063 NodeList=gpu02 #CPUs=4 Partition=gpu-titan
[2022-09-13T18:11:23.543] _job_complete: JobId=49063 WEXITSTATUS 0
[2022-09-13T18:11:23.543] _job_complete: JobId=49063 done
[2022-09-13T18:12:08.132] _slurm_rpc_submit_batch_job: JobId=49064 InitPrio=896 usec=427
[2022-09-13T18:12:08.423] sched: Allocate JobId=49064 NodeList=cpu05 #CPUs=4 Partition=cpu-opteron
[2022-09-13T18:12:11.845] _job_complete: JobId=49064 WEXITSTATUS 0
[2022-09-13T18:12:11.845] _job_complete: JobId=49064 done
[2022-09-13T18:12:58.353] _slurm_rpc_submit_batch_job: JobId=49065 InitPrio=896 usec=427
[2022-09-13T18:12:58.730] sched: Allocate JobId=49065 NodeList=gpu02 #CPUs=4 Partition=gpu-titan
[2022-09-13T18:13:19.862] _job_complete: JobId=49065 WEXITSTATUS 0
[2022-09-13T18:13:19.862] _job_complete: JobId=49065 done
[2022-09-13T18:14:59.518] _slurm_rpc_submit_batch_job: JobId=49066 InitPrio=896 usec=559
[2022-09-13T18:14:59.943] sched: Allocate JobId=49066 NodeList=gpu02 #CPUs=5 Partition=gpu-titan
[2022-09-13T18:15:18.597] _slurm_rpc_kill_job: REQUEST_KILL_JOB JobId=49066 uid 548200023
[2022-09-13T18:15:57.888] _slurm_rpc_submit_batch_job: JobId=49067 InitPrio=896 usec=636
[2022-09-13T18:15:58.017] sched: Allocate JobId=49067 NodeList=gpu02 #CPUs=5 Partition=gpu-titan
[2022-09-13T18:16:47.733] _slurm_rpc_submit_batch_job: JobId=49068 InitPrio=896 usec=463
[2022-09-13T18:16:48.083] sched: Allocate JobId=49068 NodeList=cpu05 #CPUs=4 Partition=cpu-opteron
[2022-09-13T18:16:51.259] _job_complete: JobId=49068 WEXITSTATUS 0
[2022-09-13T18:16:51.259] _job_complete: JobId=49068 done
[2022-09-13T18:17:51.368] _slurm_rpc_submit_batch_job: JobId=49069 InitPrio=896 usec=501
[2022-09-13T18:18:26.446] _slurm_rpc_kill_job: REQUEST_KILL_JOB JobId=49069 uid 548200023
[2022-09-13T18:18:52.876] _slurm_rpc_submit_batch_job: JobId=49070 InitPrio=896 usec=431
[2022-09-13T18:18:53.389] sched: Allocate JobId=49070 NodeList=gpu02 #CPUs=2 Partition=gpu-titan
[2022-09-13T18:19:14.076] _job_complete: JobId=49070 WEXITSTATUS 0
[2022-09-13T18:19:14.076] _job_complete: JobId=49070 done
[2022-09-13T18:19:33.444] Time limit exhausted for JobId=48687
[2022-09-13T18:19:36.494] sched: Allocate JobId=48936 NodeList=gpu05 #CPUs=8 Partition=gpu-v100s
[2022-09-13T18:19:42.803] _job_complete: JobId=48936 WEXITSTATUS 0
[2022-09-13T18:19:42.804] _job_complete: JobId=48936 done
[2022-09-13T18:19:43.286] sched: Allocate JobId=48949 NodeList=gpu05 #CPUs=8 Partition=gpu-v100s
[2022-09-13T18:20:15.147] _slurm_rpc_submit_batch_job: JobId=49071 InitPrio=896 usec=654
[2022-09-13T20:00:33.383] _slurm_rpc_submit_batch_job: JobId=49072 InitPrio=2690 usec=597
[2022-09-13T20:00:34.218] sched: Allocate JobId=49072 NodeList=cpu11 #CPUs=39 Partition=cpu-opteron
[2022-09-13T20:09:30.681] _job_complete: JobId=48957 WEXITSTATUS 0
[2022-09-13T20:09:30.681] _job_complete: JobId=48957 done
[2022-09-13T21:47:59.806] _slurm_rpc_submit_batch_job: JobId=49073 InitPrio=6053 usec=498
[2022-09-13T21:48:00.431] sched: Allocate JobId=49073 NodeList=cpu05 #CPUs=16 Partition=cpu-opteron
[2022-09-13T21:48:21.552] _job_complete: JobId=49073 WEXITSTATUS 1
[2022-09-13T21:48:21.552] _job_complete: JobId=49073 done
[2022-09-13T21:58:00.263] _slurm_rpc_submit_batch_job: JobId=49074 InitPrio=6053 usec=496
[2022-09-13T21:58:00.459] sched: Allocate JobId=49074 NodeList=cpu05 #CPUs=16 Partition=cpu-opteron
[2022-09-13T22:11:09.399] _slurm_rpc_submit_batch_job: JobId=49075 InitPrio=5829 usec=570
[2022-09-13T22:11:09.764] sched: Allocate JobId=49075 NodeList=cpu05 #CPUs=16 Partition=cpu-opteron
[2022-09-13T22:11:39.384] _job_complete: JobId=49075 WEXITSTATUS 1
[2022-09-13T22:11:39.385] _job_complete: JobId=49075 done
[2022-09-13T22:12:45.042] _job_complete: JobId=49074 WEXITSTATUS 0
[2022-09-13T22:12:45.042] _job_complete: JobId=49074 done
[2022-09-13T22:13:36.915] _slurm_rpc_submit_batch_job: JobId=49076 InitPrio=448 usec=476
[2022-09-13T22:13:37.059] sched: Allocate JobId=49076 NodeList=cpu05 #CPUs=1 Partition=cpu-opteron
[2022-09-13T22:15:06.283] _job_complete: JobId=49076 WEXITSTATUS 0
[2022-09-13T22:15:06.283] _job_complete: JobId=49076 done
[2022-09-13T22:15:20.243] _slurm_rpc_submit_batch_job: JobId=49077 InitPrio=5829 usec=488
[2022-09-13T22:15:21.187] sched: Allocate JobId=49077 NodeList=cpu05 #CPUs=16 Partition=cpu-opteron
[2022-09-13T22:16:06.892] _job_complete: JobId=49077 WEXITSTATUS 1
[2022-09-13T22:16:06.892] _job_complete: JobId=49077 done
[2022-09-13T22:24:59.663] _job_complete: JobId=49014 WEXITSTATUS 1
[2022-09-13T22:24:59.668] _job_complete: JobId=49014 done
[2022-09-13T22:26:02.158] _slurm_rpc_submit_batch_job: JobId=49078 InitPrio=5829 usec=589
[2022-09-13T22:26:02.277] sched: Allocate JobId=49078 NodeList=cpu05 #CPUs=16 Partition=cpu-opteron
[2022-09-13T22:26:48.036] _job_complete: JobId=49078 WEXITSTATUS 1
[2022-09-13T22:26:48.037] _job_complete: JobId=49078 done
[2022-09-14T01:29:01.354] _slurm_rpc_submit_batch_job: JobId=49079 InitPrio=2017 usec=497
[2022-09-14T01:29:01.662] sched: Allocate JobId=49079 NodeList=cpu10 #CPUs=8 Partition=cpu-opteron
[2022-09-14T01:30:19.285] _slurm_rpc_submit_batch_job: JobId=49080 InitPrio=2017 usec=447
[2022-09-14T01:30:19.744] sched: Allocate JobId=49080 NodeList=cpu05 #CPUs=8 Partition=cpu-opteron
[2022-09-14T06:06:02.885] _slurm_rpc_submit_batch_job: JobId=49081 InitPrio=5829 usec=554
[2022-09-14T06:06:03.276] sched: Allocate JobId=49081 NodeList=cpu05 #CPUs=16 Partition=cpu-opteron
[2022-09-14T06:08:55.820] _job_complete: JobId=49081 OOM failure
[2022-09-14T06:08:55.820] _job_complete: JobId=49081 done
[2022-09-14T07:06:18.314] _slurm_rpc_submit_batch_job: JobId=49082 InitPrio=5829 usec=452
[2022-09-14T07:06:18.667] sched: Allocate JobId=49082 NodeList=cpu05 #CPUs=16 Partition=cpu-opteron
[2022-09-14T07:14:50.247] _job_complete: JobId=48966 WEXITSTATUS 0
[2022-09-14T07:14:50.248] _job_complete: JobId=48966 done
[2022-09-14T08:16:04.394] _slurm_rpc_submit_batch_job: JobId=49083 InitPrio=5829 usec=780
[2022-09-14T08:16:05.241] sched: Allocate JobId=49083 NodeList=cpu05 #CPUs=16 Partition=cpu-opteron
[2022-09-14T09:30:06.489] _slurm_rpc_submit_batch_job: JobId=49084 InitPrio=224 usec=484
[2022-09-14T13:18:46.052] _job_create: exceeded association/QOS limit for user 548200045: AssocGrpCpuLimit
[2022-09-14T13:18:46.052] _slurm_rpc_submit_batch_job: Job violates accounting/QOS policy (job submit limit, user's size and/or time limits)
[2022-09-14T14:06:08.597] _slurm_rpc_kill_job: REQUEST_KILL_JOB JobId=49016 uid 548300621
[2022-09-14T14:06:10.186] _slurm_rpc_kill_job: REQUEST_KILL_JOB JobId=49016 uid 548300621
[2022-09-14T14:06:54.689] _slurm_rpc_submit_batch_job: JobId=49085 InitPrio=1345 usec=556
[2022-09-14T14:06:54.815] sched: Allocate JobId=49085 NodeList=cpu07 #CPUs=64 Partition=cpu-opteron
[2022-09-14T15:12:18.565] sched: _slurm_rpc_allocate_resources JobId=49086 NodeList=(null) usec=1028
[2022-09-14T15:12:18.844] sched: Allocate JobId=49086 NodeList=cpu05 #CPUs=1 Partition=cpu-opteron
[2022-09-14T16:22:44.513] _slurm_rpc_submit_batch_job: JobId=49087 InitPrio=896 usec=676
[2022-09-14T16:22:48.440] _slurm_rpc_submit_batch_job: JobId=49088 InitPrio=448 usec=508
[2022-09-14T16:48:36.229] _job_complete: JobId=49086 WEXITSTATUS 0
[2022-09-14T16:48:36.230] _job_complete: JobId=49086 done
[2022-09-14T16:53:36.631] cleanup_completing: JobId=49086 completion process took 300 seconds
[2022-09-14T17:18:14.674] _slurm_rpc_submit_batch_job: JobId=49089 InitPrio=896 usec=447
[2022-09-14T17:18:14.775] sched: Allocate JobId=49089 NodeList=gpu02 #CPUs=2 Partition=gpu-titan
[2022-09-14T17:19:19.329] _job_complete: JobId=49089 WEXITSTATUS 0
[2022-09-14T17:19:19.329] _job_complete: JobId=49089 done
[2022-09-14T17:29:13.513] _slurm_rpc_submit_batch_job: JobId=49090 InitPrio=896 usec=555
[2022-09-14T17:29:13.868] sched: Allocate JobId=49090 NodeList=gpu02 #CPUs=2 Partition=gpu-titan
[2022-09-14T17:30:13.195] _job_complete: JobId=49090 WEXITSTATUS 0
[2022-09-14T17:30:13.195] _job_complete: JobId=49090 done
[2022-09-14T17:58:32.061] _job_complete: JobId=49080 WEXITSTATUS 0
[2022-09-14T17:58:32.066] _job_complete: JobId=49080 done
[2022-09-14T17:58:32.849] sched: Allocate JobId=49087 NodeList=cpu05 #CPUs=32 Partition=cpu-opteron
[2022-09-14T17:59:12.236] _job_complete: JobId=49079 WEXITSTATUS 0
[2022-09-14T17:59:12.237] _job_complete: JobId=49079 done
[2022-09-14T18:09:08.923] sched: _slurm_rpc_allocate_resources JobId=49091 NodeList=(null) usec=1018
[2022-09-14T18:09:30.847] sched/backfill: _start_job: Started JobId=49091 in cpu-opteron on cpu11
[2022-09-14T18:17:26.241] _job_complete: JobId=49091 WEXITSTATUS 0
[2022-09-14T18:17:26.241] _job_complete: JobId=49091 done
[2022-09-14T18:17:44.282] _slurm_rpc_submit_batch_job: JobId=49092 InitPrio=2017 usec=804
[2022-09-14T18:17:44.849] sched: Allocate JobId=49092 NodeList=gpu03 #CPUs=16 Partition=gpu-k10
[2022-09-14T18:19:03.175] _slurm_rpc_submit_batch_job: JobId=49093 InitPrio=2017 usec=984
[2022-09-14T18:21:07.326] _slurm_rpc_submit_batch_job: JobId=49094 InitPrio=2017 usec=481
[2022-09-14T18:21:08.207] sched: Allocate JobId=49094 NodeList=cpu10 #CPUs=16 Partition=cpu-opteron
[2022-09-14T18:21:11.075] _job_complete: JobId=49094 WEXITSTATUS 1
[2022-09-14T18:21:11.076] _job_complete: JobId=49094 done
[2022-09-14T18:22:15.754] _slurm_rpc_submit_batch_job: JobId=49095 InitPrio=2017 usec=408
[2022-09-14T18:22:16.302] sched: Allocate JobId=49095 NodeList=cpu10 #CPUs=16 Partition=cpu-opteron
[2022-09-14T18:22:18.764] _job_complete: JobId=49095 WEXITSTATUS 1
[2022-09-14T18:22:18.765] _job_complete: JobId=49095 done
[2022-09-14T19:34:32.909] _job_complete: JobId=49092 WEXITSTATUS 1
[2022-09-14T19:34:32.914] _job_complete: JobId=49092 done
[2022-09-14T19:34:33.704] sched: Allocate JobId=49093 NodeList=gpu03 #CPUs=16 Partition=gpu-k10
[2022-09-14T20:22:59.304] _job_complete: JobId=49012 WEXITSTATUS 1
[2022-09-14T20:22:59.305] _job_complete: JobId=49012 done
[2022-09-14T20:37:39.436] _slurm_rpc_submit_batch_job: JobId=49096 InitPrio=1121 usec=565
[2022-09-14T20:39:33.192] _slurm_rpc_submit_batch_job: JobId=49097 InitPrio=448 usec=460
[2022-09-14T20:40:30.976] sched/backfill: _start_job: Started JobId=49097 in cpu-opteron on cpu11
[2022-09-14T20:40:34.439] _job_complete: JobId=49097 WEXITSTATUS 127
[2022-09-14T20:40:34.439] _job_complete: JobId=49097 done
[2022-09-14T20:41:24.810] _slurm_rpc_submit_batch_job: JobId=49098 InitPrio=448 usec=500
[2022-09-14T20:41:30.978] sched/backfill: _start_job: Started JobId=49098 in cpu-opteron on cpu11
[2022-09-14T20:45:37.117] _job_complete: JobId=49098 WEXITSTATUS 0
[2022-09-14T20:45:37.117] _job_complete: JobId=49098 done
[2022-09-14T20:56:05.652] _slurm_rpc_submit_batch_job: JobId=49099 InitPrio=448 usec=532
[2022-09-14T20:56:30.994] sched/backfill: _start_job: Started JobId=49099 in cpu-opteron on cpu11
[2022-09-14T20:57:05.890] _job_complete: JobId=49099 WEXITSTATUS 0
[2022-09-14T20:57:05.890] _job_complete: JobId=49099 done
[2022-09-14T20:57:37.314] _slurm_rpc_submit_batch_job: JobId=49100 InitPrio=448 usec=482
[2022-09-14T20:57:39.311] _job_complete: JobId=49047 WEXITSTATUS 139
[2022-09-14T20:57:39.315] _job_complete: JobId=49047 done
[2022-09-14T20:57:39.672] sched: Allocate JobId=49084 NodeList=cpu12 #CPUs=32 Partition=cpu-epyc
[2022-09-14T20:58:20.420] _slurm_rpc_submit_batch_job: JobId=49101 InitPrio=448 usec=401
[2022-09-14T20:58:30.996] sched/backfill: _start_job: Started JobId=49100 in cpu-opteron on cpu11
[2022-09-14T20:58:30.996] sched/backfill: _start_job: Started JobId=49101 in cpu-opteron on cpu11
[2022-09-14T20:58:32.393] _job_complete: JobId=49101 WEXITSTATUS 0
[2022-09-14T20:58:32.393] _job_complete: JobId=49101 done
[2022-09-14T20:58:35.626] _job_complete: JobId=49100 WEXITSTATUS 0
[2022-09-14T20:58:35.626] _job_complete: JobId=49100 done
[2022-09-14T21:16:12.690] _slurm_rpc_submit_batch_job: JobId=49102 InitPrio=448 usec=591
[2022-09-14T21:23:41.033] _job_create: exceeded association/QOS limit for user 548200021: QOSMaxWallDurationPerJobLimit
[2022-09-14T21:23:41.033] _slurm_rpc_submit_batch_job: Job violates accounting/QOS policy (job submit limit, user's size and/or time limits)
[2022-09-14T21:24:47.444] _slurm_rpc_submit_batch_job: JobId=49103 InitPrio=448 usec=462
[2022-09-14T21:26:43.632] _slurm_rpc_submit_batch_job: JobId=49104 InitPrio=448 usec=475
[2022-09-15T00:57:37.053] _slurm_rpc_submit_batch_job: JobId=49105 InitPrio=896 usec=604
[2022-09-15T03:27:12.048] _job_complete: JobId=49093 WEXITSTATUS 1
[2022-09-15T03:27:12.054] _job_complete: JobId=49093 done
[2022-09-15T04:24:05.262] _job_complete: JobId=49008 WEXITSTATUS 0
[2022-09-15T04:24:05.268] _job_complete: JobId=49008 done
[2022-09-15T04:24:07.456] sched: Allocate JobId=49105 NodeList=cpu03 #CPUs=32 Partition=cpu-opteron
[2022-09-15T04:24:07.472] sched: Allocate JobId=49088 NodeList=cpu03 #CPUs=32 Partition=cpu-opteron
[2022-09-15T04:34:06.778] _job_complete: JobId=49084 WEXITSTATUS 0
[2022-09-15T04:34:06.779] _job_complete: JobId=49084 done
[2022-09-15T07:06:42.728] Time limit exhausted for JobId=49082
[2022-09-15T07:40:21.008] _slurm_rpc_submit_batch_job: JobId=49106 InitPrio=3811 usec=654
[2022-09-15T07:40:21.989] sched: Allocate JobId=49106 NodeList=cpu05 #CPUs=16 Partition=cpu-opteron
[2022-09-15T07:40:25.614] _job_complete: JobId=49106 WEXITSTATUS 1
[2022-09-15T07:40:25.615] _job_complete: JobId=49106 done
[2022-09-15T07:47:26.090] _slurm_rpc_submit_batch_job: JobId=49107 InitPrio=3811 usec=466
[2022-09-15T07:47:27.664] sched: Allocate JobId=49107 NodeList=cpu05 #CPUs=16 Partition=cpu-opteron
[2022-09-15T07:47:31.559] _job_complete: JobId=49107 WEXITSTATUS 1
[2022-09-15T07:47:31.559] _job_complete: JobId=49107 done
[2022-09-15T07:58:56.905] _slurm_rpc_submit_batch_job: JobId=49108 InitPrio=3811 usec=556
[2022-09-15T07:58:57.084] sched: Allocate JobId=49108 NodeList=cpu05 #CPUs=16 Partition=cpu-opteron
[2022-09-15T07:59:00.485] _job_complete: JobId=49108 WEXITSTATUS 1
[2022-09-15T07:59:00.485] _job_complete: JobId=49108 done
[2022-09-15T08:00:54.026] _slurm_rpc_submit_batch_job: JobId=49109 InitPrio=3811 usec=456
[2022-09-15T08:00:54.235] sched: Allocate JobId=49109 NodeList=cpu05 #CPUs=16 Partition=cpu-opteron
[2022-09-15T08:16:13.704] Time limit exhausted for JobId=49083
[2022-09-15T08:18:32.503] _slurm_rpc_submit_batch_job: JobId=49110 InitPrio=3811 usec=500
[2022-09-15T08:18:33.158] sched: Allocate JobId=49110 NodeList=cpu05 #CPUs=16 Partition=cpu-opteron
[2022-09-15T09:20:34.974] _slurm_rpc_submit_batch_job: JobId=49111 InitPrio=672 usec=623
[2022-09-15T09:20:35.246] sched: Allocate JobId=49111 NodeList=cpu12 #CPUs=24 Partition=cpu-epyc
[2022-09-15T09:22:03.829] _get_job_parts: invalid partition specified: gpu-epyc
[2022-09-15T09:22:03.830] _slurm_rpc_submit_batch_job: Invalid partition name specified
[2022-09-15T09:22:20.412] _slurm_rpc_submit_batch_job: JobId=49112 InitPrio=672 usec=409
[2022-09-15T09:22:21.374] sched: Allocate JobId=49112 NodeList=cpu12 #CPUs=24 Partition=cpu-epyc
[2022-09-15T09:23:00.245] _job_complete: JobId=49112 WEXITSTATUS 0
[2022-09-15T09:23:00.245] _job_complete: JobId=49112 done
[2022-09-15T09:26:00.878] _slurm_rpc_submit_batch_job: JobId=49113 InitPrio=672 usec=472
[2022-09-15T09:26:01.789] sched: Allocate JobId=49113 NodeList=cpu12 #CPUs=24 Partition=cpu-epyc
[2022-09-15T09:26:36.169] _job_complete: JobId=49113 WEXITSTATUS 0
[2022-09-15T09:26:36.169] _job_complete: JobId=49113 done
[2022-09-15T09:28:17.421] _slurm_rpc_submit_batch_job: JobId=49114 InitPrio=672 usec=463
[2022-09-15T09:28:18.077] sched: Allocate JobId=49114 NodeList=cpu12 #CPUs=24 Partition=cpu-epyc
[2022-09-15T09:29:41.244] _slurm_rpc_submit_batch_job: JobId=49115 InitPrio=672 usec=465
[2022-09-15T09:29:42.189] sched: Allocate JobId=49115 NodeList=gpu02 #CPUs=2 Partition=gpu-titan
[2022-09-15T09:30:48.477] _job_complete: JobId=49115 WEXITSTATUS 0
[2022-09-15T09:30:48.477] _job_complete: JobId=49115 done
[2022-09-15T09:32:30.408] sched: _slurm_rpc_allocate_resources JobId=49116 NodeList=cpu11 usec=15566
[2022-09-15T10:04:34.959] _job_complete: JobId=49111 WEXITSTATUS 0
[2022-09-15T10:04:34.959] _job_complete: JobId=49111 done
[2022-09-15T10:12:10.428] _job_complete: JobId=49114 WEXITSTATUS 0
[2022-09-15T10:12:10.428] _job_complete: JobId=49114 done
[2022-09-15T10:17:04.530] _slurm_rpc_submit_batch_job: JobId=49117 InitPrio=672 usec=547
[2022-09-15T10:17:05.451] sched: Allocate JobId=49117 NodeList=gpu02 #CPUs=2 Partition=gpu-titan
[2022-09-15T10:18:10.255] _job_complete: JobId=49117 WEXITSTATUS 0
[2022-09-15T10:18:10.256] _job_complete: JobId=49117 done
[2022-09-15T10:19:42.896] _slurm_rpc_submit_batch_job: JobId=49118 InitPrio=672 usec=480
[2022-09-15T10:19:43.803] sched: Allocate JobId=49118 NodeList=cpu12 #CPUs=48 Partition=cpu-epyc
[2022-09-15T10:21:14.966] sched: _slurm_rpc_allocate_resources JobId=49119 NodeList=cpu11 usec=5847
[2022-09-15T10:23:06.475] _slurm_rpc_submit_batch_job: JobId=49120 InitPrio=672 usec=443
[2022-09-15T10:32:46.290] _job_complete: JobId=49045 WEXITSTATUS 0
[2022-09-15T10:32:46.290] _job_complete: JobId=49045 done
[2022-09-15T10:32:46.809] sched: Allocate JobId=49120 NodeList=cpu15 #CPUs=48 Partition=cpu-epyc
[2022-09-15T10:37:28.355] _slurm_rpc_submit_batch_job: JobId=49121 InitPrio=672 usec=414
[2022-09-15T10:42:40.403] _job_complete: JobId=49118 WEXITSTATUS 0
[2022-09-15T10:42:40.403] _job_complete: JobId=49118 done
[2022-09-15T10:42:41.312] sched: Allocate JobId=49121 NodeList=cpu12 #CPUs=24 Partition=cpu-epyc
[2022-09-15T10:43:30.122] _job_complete: JobId=49119 WEXITSTATUS 0
[2022-09-15T10:43:30.122] _job_complete: JobId=49119 done
[2022-09-15T10:43:56.826] _job_complete: JobId=49121 WEXITSTATUS 0
[2022-09-15T10:43:56.826] _job_complete: JobId=49121 done
[2022-09-15T10:44:38.503] _slurm_rpc_submit_batch_job: JobId=49122 InitPrio=8744 usec=626
[2022-09-15T10:44:39.384] sched: Allocate JobId=49122 NodeList=cpu11 #CPUs=1 Partition=cpu-opteron
[2022-09-15T10:44:44.360] _job_complete: JobId=49122 WEXITSTATUS 0
[2022-09-15T10:44:44.360] _job_complete: JobId=49122 done
[2022-09-15T11:12:41.364] _slurm_rpc_submit_batch_job: JobId=49123 InitPrio=672 usec=455
[2022-09-15T11:12:42.235] sched: Allocate JobId=49123 NodeList=cpu12 #CPUs=24 Partition=cpu-epyc
[2022-09-15T11:13:44.561] _slurm_rpc_submit_batch_job: JobId=49124 InitPrio=672 usec=399
[2022-09-15T11:13:45.393] sched: Allocate JobId=49124 NodeList=cpu12 #CPUs=24 Partition=cpu-epyc
[2022-09-15T11:29:18.464] _job_complete: JobId=49123 WEXITSTATUS 0
[2022-09-15T11:29:18.464] _job_complete: JobId=49123 done
[2022-09-15T11:31:07.179] _job_complete: JobId=49124 WEXITSTATUS 0
[2022-09-15T11:31:07.179] _job_complete: JobId=49124 done
[2022-09-15T11:52:58.815] job_step_signal: JobId=49116 StepId=0 not found
[2022-09-15T11:52:58.817] _job_complete: JobId=49116 WTERMSIG 126
[2022-09-15T11:52:58.817] _job_complete: JobId=49116 cancelled by interactive user
[2022-09-15T11:52:58.817] _job_complete: JobId=49116 done
[2022-09-15T11:55:44.261] _slurm_rpc_submit_batch_job: JobId=49125 InitPrio=2017 usec=1003
[2022-09-15T11:55:44.829] sched: Allocate JobId=49125 NodeList=gpu01 #CPUs=16 Partition=gpu-k10
[2022-09-15T12:00:48.205] _slurm_rpc_submit_batch_job: JobId=49126 InitPrio=2017 usec=943
[2022-09-15T12:00:48.329] sched: Allocate JobId=49126 NodeList=gpu03 #CPUs=16 Partition=gpu-k10
[2022-09-15T12:10:12.475] _job_complete: JobId=49088 WEXITSTATUS 0
[2022-09-15T12:10:12.475] _job_complete: JobId=49088 done
[2022-09-15T12:10:21.034] _slurm_rpc_submit_batch_job: JobId=49127 InitPrio=8295 usec=527
[2022-09-15T12:10:21.317] sched: Allocate JobId=49127 NodeList=cpu03 #CPUs=1 Partition=cpu-opteron
[2022-09-15T12:10:27.098] _job_complete: JobId=49127 WEXITSTATUS 0
[2022-09-15T12:10:27.098] _job_complete: JobId=49127 done
[2022-09-15T13:43:35.161] _job_complete: JobId=49023 WEXITSTATUS 0
[2022-09-15T13:43:35.165] _job_complete: JobId=49023 done
[2022-09-15T14:09:40.779] _slurm_rpc_submit_batch_job: JobId=49128 InitPrio=672 usec=521
[2022-09-15T14:09:40.926] sched: Allocate JobId=49128 NodeList=cpu12 #CPUs=48 Partition=cpu-epyc
[2022-09-15T14:09:51.333] _job_complete: JobId=49128 WEXITSTATUS 1
[2022-09-15T14:09:51.334] _job_complete: JobId=49128 done
[2022-09-15T14:13:40.529] _slurm_rpc_submit_batch_job: JobId=49129 InitPrio=672 usec=458
[2022-09-15T14:13:41.318] sched: Allocate JobId=49129 NodeList=cpu12 #CPUs=48 Partition=cpu-epyc
[2022-09-15T14:15:04.728] _slurm_rpc_submit_batch_job: JobId=49130 InitPrio=672 usec=448
[2022-09-15T14:16:07.629] _slurm_rpc_submit_batch_job: JobId=49131 InitPrio=672 usec=520
[2022-09-15T14:16:46.729] _slurm_rpc_submit_batch_job: JobId=49132 InitPrio=672 usec=525
[2022-09-15T14:26:37.674] _slurm_rpc_kill_job: REQUEST_KILL_JOB JobId=49085 uid 548300621
[2022-09-15T14:26:38.398] _slurm_rpc_kill_job: REQUEST_KILL_JOB JobId=49085 uid 548300621
[2022-09-15T14:26:58.300] _slurm_rpc_submit_batch_job: JobId=49133 InitPrio=1121 usec=481
[2022-09-15T14:26:58.711] sched: Allocate JobId=49133 NodeList=cpu07 #CPUs=64 Partition=cpu-opteron
[2022-09-15T14:34:25.639] _slurm_rpc_submit_batch_job: JobId=49134 InitPrio=3363 usec=433
[2022-09-15T14:39:01.538] _job_complete: JobId=49126 WEXITSTATUS 1
[2022-09-15T14:39:01.544] _job_complete: JobId=49126 done
[2022-09-15T15:00:45.131] Time limit exhausted for JobId=48930
[2022-09-15T15:56:48.257] _slurm_rpc_kill_job: REQUEST_KILL_JOB JobId=49133 uid 548300621
[2022-09-15T15:56:49.672] _slurm_rpc_kill_job: REQUEST_KILL_JOB JobId=49133 uid 548300621
[2022-09-15T15:56:55.979] _slurm_rpc_submit_batch_job: JobId=49135 InitPrio=1121 usec=483
[2022-09-15T15:56:56.845] sched: Allocate JobId=49135 NodeList=cpu07 #CPUs=64 Partition=cpu-opteron
[2022-09-15T16:55:17.223] _slurm_rpc_submit_batch_job: JobId=49136 InitPrio=1121 usec=675
[2022-09-15T16:55:18.155] sched: Allocate JobId=49136 NodeList=cpu08 #CPUs=64 Partition=cpu-opteron
[2022-09-15T17:07:59.822] _job_complete: JobId=48935 WEXITSTATUS 0
[2022-09-15T17:07:59.827] _job_complete: JobId=48935 done
[2022-09-15T17:08:02.834] sched: Allocate JobId=48950 NodeList=gpu05 #CPUs=8 Partition=gpu-v100s
[2022-09-15T17:20:15.678] Time limit exhausted for JobId=48948
[2022-09-15T17:45:39.276] _job_complete: JobId=49135 WEXITSTATUS 1
[2022-09-15T17:45:39.276] _job_complete: JobId=49135 done
[2022-09-15T17:58:45.641] Time limit exhausted for JobId=49087
[2022-09-15T18:53:10.868] _slurm_rpc_submit_batch_job: JobId=49137 InitPrio=448 usec=555
[2022-09-15T18:53:11.561] sched: Allocate JobId=49137 NodeList=gpu02 #CPUs=8 Partition=gpu-titan
[2022-09-15T19:03:01.813] _slurm_rpc_submit_batch_job: JobId=49138 InitPrio=448 usec=449
[2022-09-15T19:03:02.588] sched: Allocate JobId=49138 NodeList=cpu03 #CPUs=32 Partition=cpu-opteron
[2022-09-15T21:48:13.554] sched: _slurm_rpc_allocate_resources JobId=49139 NodeList=cpu11 usec=17336
[2022-09-15T22:10:21.389] job_step_signal: JobId=49139 StepId=0 not found
[2022-09-15T22:10:21.391] _job_complete: JobId=49139 WTERMSIG 126
[2022-09-15T22:10:21.391] _job_complete: JobId=49139 cancelled by interactive user
[2022-09-15T22:10:21.391] _job_complete: JobId=49139 done
[2022-09-15T23:37:57.044] _slurm_rpc_submit_batch_job: JobId=49140 InitPrio=672 usec=556
[2022-09-15T23:37:57.179] sched: Allocate JobId=49140 NodeList=cpu05 #CPUs=32 Partition=cpu-opteron
[2022-09-15T23:59:23.792] _job_complete: JobId=49120 WEXITSTATUS 1
[2022-09-15T23:59:23.792] _job_complete: JobId=49120 done
[2022-09-15T23:59:24.945] sched: Allocate JobId=49134 NodeList=cpu15 #CPUs=16 Partition=cpu-epyc
[2022-09-15T23:59:58.785] _job_complete: JobId=49140 WEXITSTATUS 1
[2022-09-15T23:59:58.785] _job_complete: JobId=49140 done
[2022-09-16T04:44:51.487] _job_complete: JobId=49134 WEXITSTATUS 0
[2022-09-16T04:44:51.487] _job_complete: JobId=49134 done
[2022-09-16T04:44:52.110] sched: Allocate JobId=49130 NodeList=cpu15 #CPUs=48 Partition=cpu-epyc
[2022-09-16T08:01:15.398] Time limit exhausted for JobId=49109
[2022-09-16T08:06:51.234] _slurm_rpc_submit_batch_job: JobId=49141 InitPrio=3587 usec=599
[2022-09-16T08:06:52.052] sched: Allocate JobId=49141 NodeList=cpu10 #CPUs=16 Partition=cpu-opteron
[2022-09-16T08:18:45.472] Time limit exhausted for JobId=49110
[2022-09-16T08:32:43.328] _slurm_rpc_submit_batch_job: JobId=49142 InitPrio=3587 usec=488
[2022-09-16T08:32:44.074] sched: Allocate JobId=49142 NodeList=cpu05 #CPUs=16 Partition=cpu-opteron
[2022-09-16T09:32:13.996] _slurm_rpc_submit_batch_job: JobId=49143 InitPrio=672 usec=607
[2022-09-16T09:47:21.101] _job_complete: JobId=49138 WEXITSTATUS 0
[2022-09-16T09:47:21.101] _job_complete: JobId=49138 done
[2022-09-16T10:50:20.932] _slurm_rpc_submit_batch_job: JobId=49144 InitPrio=224 usec=453
[2022-09-16T10:50:20.983] sched: Allocate JobId=49144 NodeList=cpu07 #CPUs=64 Partition=cpu-opteron
[2022-09-16T10:59:06.952] _slurm_rpc_submit_batch_job: JobId=49145 InitPrio=1793 usec=452
[2022-09-16T10:59:07.917] sched: Allocate JobId=49145 NodeList=gpu04 #CPUs=16 Partition=gpu-k40c
[2022-09-16T11:19:13.310] _slurm_rpc_submit_batch_job: JobId=49146 InitPrio=224 usec=452
[2022-09-16T11:19:24.124] _slurm_rpc_submit_batch_job: JobId=49147 InitPrio=224 usec=489
[2022-09-16T11:19:36.367] _slurm_rpc_submit_batch_job: JobId=49148 InitPrio=224 usec=448
[2022-09-16T11:19:50.075] _slurm_rpc_submit_batch_job: JobId=49149 InitPrio=224 usec=387
[2022-09-16T11:20:00.529] _slurm_rpc_submit_batch_job: JobId=49150 InitPrio=224 usec=409
[2022-09-16T11:20:10.868] _slurm_rpc_submit_batch_job: JobId=49151 InitPrio=224 usec=378
[2022-09-16T11:20:22.390] _slurm_rpc_submit_batch_job: JobId=49152 InitPrio=224 usec=385
[2022-09-16T11:20:35.433] _slurm_rpc_submit_batch_job: JobId=49153 InitPrio=224 usec=403
[2022-09-16T11:20:43.747] _slurm_rpc_submit_batch_job: JobId=49154 InitPrio=224 usec=439
[2022-09-16T11:21:41.486] _slurm_rpc_kill_job: REQUEST_KILL_JOB JobId=49147 uid 548200017
[2022-09-16T11:21:41.486] _slurm_rpc_kill_job: REQUEST_KILL_JOB JobId=49146 uid 548200017
[2022-09-16T11:21:41.487] _slurm_rpc_kill_job: REQUEST_KILL_JOB JobId=49148 uid 548200017
[2022-09-16T11:22:28.328] _slurm_rpc_submit_batch_job: JobId=49155 InitPrio=224 usec=551
[2022-09-16T11:22:56.607] _slurm_rpc_submit_batch_job: JobId=49156 InitPrio=224 usec=408
[2022-09-16T11:23:07.383] _slurm_rpc_submit_batch_job: JobId=49157 InitPrio=224 usec=372
[2022-09-16T11:48:26.920] _job_complete: JobId=49129 WEXITSTATUS 0
[2022-09-16T11:48:26.920] _job_complete: JobId=49129 done
[2022-09-16T11:48:27.261] sched: Allocate JobId=49131 NodeList=cpu12 #CPUs=48 Partition=cpu-epyc
[2022-09-16T12:30:42.095] _slurm_rpc_submit_batch_job: JobId=49158 InitPrio=2017 usec=491
[2022-09-16T12:30:42.384] sched: Allocate JobId=49158 NodeList=cpu03 #CPUs=8 Partition=cpu-opteron
[2022-09-16T12:30:47.621] _job_complete: JobId=49158 WEXITSTATUS 1
[2022-09-16T12:30:47.622] _job_complete: JobId=49158 done
[2022-09-16T12:33:03.905] _slurm_rpc_submit_batch_job: JobId=49159 InitPrio=2017 usec=430
[2022-09-16T12:33:04.659] sched: Allocate JobId=49159 NodeList=cpu03 #CPUs=8 Partition=cpu-opteron
[2022-09-16T12:37:18.238] _slurm_rpc_submit_batch_job: JobId=49160 InitPrio=2017 usec=418
[2022-09-16T12:37:19.009] sched: Allocate JobId=49160 NodeList=cpu03 #CPUs=8 Partition=cpu-opteron
[2022-09-16T12:37:24.044] _job_complete: JobId=49160 WEXITSTATUS 1
[2022-09-16T12:37:24.044] _job_complete: JobId=49160 done
[2022-09-16T12:45:30.088] _slurm_rpc_submit_batch_job: JobId=49161 InitPrio=2017 usec=473
[2022-09-16T12:45:30.913] sched: Allocate JobId=49161 NodeList=cpu03 #CPUs=8 Partition=cpu-opteron
[2022-09-16T12:45:36.182] _job_complete: JobId=49161 WEXITSTATUS 1
[2022-09-16T12:45:36.183] _job_complete: JobId=49161 done
[2022-09-16T12:47:59.415] _slurm_rpc_submit_batch_job: JobId=49162 InitPrio=2017 usec=433
[2022-09-16T12:48:00.178] sched: Allocate JobId=49162 NodeList=cpu03 #CPUs=8 Partition=cpu-opteron
[2022-09-16T12:48:05.178] _job_complete: JobId=49162 WEXITSTATUS 1
[2022-09-16T12:48:05.179] _job_complete: JobId=49162 done
[2022-09-16T12:48:59.516] _slurm_rpc_submit_batch_job: JobId=49163 InitPrio=2017 usec=459
[2022-09-16T12:49:00.301] sched: Allocate JobId=49163 NodeList=cpu03 #CPUs=8 Partition=cpu-opteron
[2022-09-16T12:49:05.349] _job_complete: JobId=49163 WEXITSTATUS 1
[2022-09-16T12:49:05.350] _job_complete: JobId=49163 done
[2022-09-16T12:50:11.754] _slurm_rpc_submit_batch_job: JobId=49164 InitPrio=2017 usec=448
[2022-09-16T12:50:12.403] sched: Allocate JobId=49164 NodeList=cpu03 #CPUs=8 Partition=cpu-opteron
[2022-09-16T12:50:17.405] _job_complete: JobId=49164 WEXITSTATUS 1
[2022-09-16T12:50:17.406] _job_complete: JobId=49164 done
[2022-09-16T12:52:02.259] _slurm_rpc_submit_batch_job: JobId=49165 InitPrio=2017 usec=527
[2022-09-16T12:52:02.561] sched: Allocate JobId=49165 NodeList=cpu03 #CPUs=8 Partition=cpu-opteron
[2022-09-16T12:52:07.382] _job_complete: JobId=49165 WEXITSTATUS 1
[2022-09-16T12:52:07.383] _job_complete: JobId=49165 done
[2022-09-16T12:52:36.764] _slurm_rpc_submit_batch_job: JobId=49166 InitPrio=2017 usec=401
[2022-09-16T12:52:37.611] sched: Allocate JobId=49166 NodeList=cpu03 #CPUs=8 Partition=cpu-opteron
[2022-09-16T12:52:42.891] _job_complete: JobId=49166 WEXITSTATUS 1
[2022-09-16T12:52:42.891] _job_complete: JobId=49166 done
[2022-09-16T12:53:53.269] _slurm_rpc_submit_batch_job: JobId=49167 InitPrio=2017 usec=417
[2022-09-16T12:53:53.802] sched: Allocate JobId=49167 NodeList=cpu03 #CPUs=8 Partition=cpu-opteron
[2022-09-16T12:56:07.115] _slurm_rpc_kill_job: REQUEST_KILL_JOB JobId=49167 uid 548200029
[2022-09-16T12:57:20.313] _slurm_rpc_submit_batch_job: JobId=49168 InitPrio=2017 usec=383
[2022-09-16T12:57:21.096] sched: Allocate JobId=49168 NodeList=cpu03 #CPUs=8 Partition=cpu-opteron
[2022-09-16T14:04:19.116] _job_complete: JobId=49159 WEXITSTATUS 0
[2022-09-16T14:04:19.122] _job_complete: JobId=49159 done
[2022-09-16T14:06:42.879] _job_complete: JobId=49168 WEXITSTATUS 0
[2022-09-16T14:06:42.880] _job_complete: JobId=49168 done
[2022-09-16T15:09:16.654] _slurm_rpc_kill_job: REQUEST_KILL_JOB JobId=48982 uid 548300621
[2022-09-16T15:09:18.128] _slurm_rpc_kill_job: REQUEST_KILL_JOB JobId=48982 uid 548300621
[2022-09-16T15:09:27.017] sched: Allocate JobId=49149 NodeList=cpu04 #CPUs=64 Partition=cpu-opteron
[2022-09-16T15:10:14.811] _slurm_rpc_kill_job: REQUEST_KILL_JOB JobId=49136 uid 548300621
[2022-09-16T15:10:16.045] _slurm_rpc_kill_job: REQUEST_KILL_JOB JobId=49136 uid 548300621
[2022-09-16T15:10:26.102] sched: Allocate JobId=49150 NodeList=cpu08 #CPUs=64 Partition=cpu-opteron
[2022-09-16T15:10:32.967] _slurm_rpc_kill_job: REQUEST_KILL_JOB JobId=49136 uid 548300621
[2022-09-16T15:10:33.920] _slurm_rpc_kill_job: REQUEST_KILL_JOB JobId=49136 uid 548300621
[2022-09-16T15:12:13.711] _slurm_rpc_submit_batch_job: JobId=49169 InitPrio=1121 usec=505
[2022-09-16T15:12:17.261] _slurm_rpc_submit_batch_job: JobId=49170 InitPrio=1121 usec=419
[2022-09-16T15:12:20.037] _slurm_rpc_submit_batch_job: JobId=49171 InitPrio=1121 usec=557
[2022-09-16T15:13:32.642] _slurm_rpc_kill_job: REQUEST_KILL_JOB JobId=49171 uid 548300621
[2022-09-16T15:13:38.113] _slurm_rpc_kill_job: REQUEST_KILL_JOB JobId=49170 uid 548300621
[2022-09-16T15:13:43.204] _slurm_rpc_kill_job: REQUEST_KILL_JOB JobId=49169 uid 548300621
[2022-09-16T15:14:04.933] _slurm_rpc_submit_batch_job: JobId=49172 InitPrio=1121 usec=405
[2022-09-16T15:14:13.817] _slurm_rpc_submit_batch_job: JobId=49173 InitPrio=1121 usec=429
[2022-09-16T15:14:28.874] _slurm_rpc_submit_batch_job: JobId=49174 InitPrio=1121 usec=558
[2022-09-16T17:21:45.589] _slurm_rpc_submit_batch_job: JobId=49175 InitPrio=672 usec=557
[2022-09-16T17:22:33.113] sched/backfill: _start_job: Started JobId=49175 in cpu-opteron on cpu03
[2022-09-16T17:22:34.716] _job_complete: JobId=49175 WEXITSTATUS 1
[2022-09-16T17:22:34.716] _job_complete: JobId=49175 done
[2022-09-16T17:27:19.425] Time limit exhausted for JobId=48956
[2022-09-16T17:27:27.693] sched: Allocate JobId=49172 NodeList=cpu09 #CPUs=64 Partition=cpu-opteron
[2022-09-16T17:27:54.182] _job_complete: JobId=49172 WEXITSTATUS 1
[2022-09-16T17:27:54.182] _job_complete: JobId=49172 done
[2022-09-16T17:27:54.964] sched: Allocate JobId=49173 NodeList=cpu09 #CPUs=64 Partition=cpu-opteron
[2022-09-16T17:29:31.136] _job_complete: JobId=49173 WEXITSTATUS 0
[2022-09-16T17:29:31.136] _job_complete: JobId=49173 done
[2022-09-16T17:29:32.382] sched: Allocate JobId=49174 NodeList=cpu09 #CPUs=64 Partition=cpu-opteron
[2022-09-16T17:29:58.603] _job_complete: JobId=49174 WEXITSTATUS 1
[2022-09-16T17:29:58.603] _job_complete: JobId=49174 done
[2022-09-16T17:29:59.298] sched: Allocate JobId=49151 NodeList=cpu09 #CPUs=64 Partition=cpu-opteron
[2022-09-16T20:12:51.246] _job_complete: JobId=49150 WEXITSTATUS 0
[2022-09-16T20:12:51.252] _job_complete: JobId=49150 done
[2022-09-16T20:13:12.547] sched: Allocate JobId=49152 NodeList=cpu08 #CPUs=64 Partition=cpu-opteron
[2022-09-16T20:35:00.759] _job_complete: JobId=49149 WEXITSTATUS 0
[2022-09-16T20:35:00.760] _job_complete: JobId=49149 done
[2022-09-16T20:35:21.972] sched: Allocate JobId=49153 NodeList=cpu04 #CPUs=64 Partition=cpu-opteron
[2022-09-16T21:42:19.801] Time limit exhausted for JobId=48871
[2022-09-16T21:42:22.801] sched: Allocate JobId=49132 NodeList=cpu13 #CPUs=48 Partition=cpu-epyc
[2022-09-16T22:03:48.053] _job_complete: JobId=49151 WEXITSTATUS 0
[2022-09-16T22:03:48.054] _job_complete: JobId=49151 done
[2022-09-16T22:04:09.283] sched: Allocate JobId=49154 NodeList=cpu09 #CPUs=64 Partition=cpu-opteron
[2022-09-16T22:07:06.777] _slurm_rpc_submit_batch_job: JobId=49176 InitPrio=1121 usec=533
[2022-09-16T22:07:09.406] _slurm_rpc_submit_batch_job: JobId=49177 InitPrio=1121 usec=470
[2022-09-16T22:07:11.816] _slurm_rpc_submit_batch_job: JobId=49178 InitPrio=1121 usec=441
[2022-09-16T22:07:20.638] _slurm_rpc_submit_batch_job: JobId=49179 InitPrio=224 usec=710
[2022-09-16T22:07:33.584] sched/backfill: _start_job: Started JobId=49179 in cpu-opteron on cpu03
[2022-09-16T22:07:36.629] _slurm_rpc_submit_batch_job: JobId=49180 InitPrio=224 usec=457
[2022-09-16T22:07:52.283] _slurm_rpc_submit_batch_job: JobId=49181 InitPrio=224 usec=381
[2022-09-16T22:08:06.828] _slurm_rpc_submit_batch_job: JobId=49182 InitPrio=224 usec=364
[2022-09-16T22:08:18.548] _slurm_rpc_submit_batch_job: JobId=49183 InitPrio=224 usec=460
[2022-09-16T22:08:33.827] _slurm_rpc_submit_batch_job: JobId=49184 InitPrio=224 usec=406
[2022-09-16T22:12:02.006] _slurm_rpc_submit_batch_job: JobId=49185 InitPrio=224 usec=400
[2022-09-16T22:12:14.649] _slurm_rpc_submit_batch_job: JobId=49186 InitPrio=224 usec=416
[2022-09-16T22:12:27.652] _slurm_rpc_submit_batch_job: JobId=49187 InitPrio=224 usec=453
[2022-09-16T22:22:42.010] _slurm_rpc_submit_batch_job: JobId=49188 InitPrio=224 usec=442
[2022-09-16T22:24:44.896] _slurm_rpc_kill_job: REQUEST_KILL_JOB JobId=49155 uid 548200017
[2022-09-16T22:26:40.465] _slurm_rpc_submit_batch_job: JobId=49189 InitPrio=224 usec=427
[2022-09-17T02:08:38.373] _slurm_rpc_submit_batch_job: JobId=49190 InitPrio=2017 usec=516
[2022-09-17T02:09:55.824] _slurm_rpc_submit_batch_job: JobId=49191 InitPrio=2017 usec=528
[2022-09-17T02:09:56.133] sched: Allocate JobId=49191 NodeList=cpu05 #CPUs=8 Partition=cpu-opteron
[2022-09-17T02:10:01.309] _job_complete: JobId=49191 WEXITSTATUS 1
[2022-09-17T02:10:01.310] _job_complete: JobId=49191 done
[2022-09-17T02:11:32.791] _job_complete: JobId=49153 WEXITSTATUS 0
[2022-09-17T02:11:32.796] _job_complete: JobId=49153 done
[2022-09-17T02:11:54.078] sched: Allocate JobId=49176 NodeList=cpu04 #CPUs=64 Partition=cpu-opteron
[2022-09-17T02:24:47.026] _job_complete: JobId=49152 WEXITSTATUS 0
[2022-09-17T02:24:47.026] _job_complete: JobId=49152 done
[2022-09-17T02:25:08.305] sched: Allocate JobId=49177 NodeList=cpu08 #CPUs=64 Partition=cpu-opteron
[2022-09-17T02:31:33.441] _slurm_rpc_submit_batch_job: JobId=49192 InitPrio=2017 usec=447
[2022-09-17T02:31:33.636] sched: Allocate JobId=49192 NodeList=cpu05 #CPUs=8 Partition=cpu-opteron
[2022-09-17T02:33:41.509] _slurm_rpc_submit_batch_job: JobId=49193 InitPrio=2017 usec=933
[2022-09-17T02:33:41.915] sched: Allocate JobId=49193 NodeList=gpu03 #CPUs=16 Partition=gpu-k10
[2022-09-17T02:34:23.510] _slurm_rpc_submit_batch_job: JobId=49194 InitPrio=2017 usec=667
[2022-09-17T02:36:27.549] _slurm_rpc_submit_batch_job: JobId=49195 InitPrio=2017 usec=662
[2022-09-17T02:50:50.237] _job_complete: JobId=49154 WEXITSTATUS 0
[2022-09-17T02:50:50.238] _job_complete: JobId=49154 done
[2022-09-17T02:51:11.492] sched: Allocate JobId=49178 NodeList=cpu09 #CPUs=64 Partition=cpu-opteron
[2022-09-17T04:06:03.766] _job_complete: JobId=49192 WEXITSTATUS 0
[2022-09-17T04:06:03.815] _job_complete: JobId=49192 done
[2022-09-17T05:48:15.375] _job_complete: JobId=49179 WEXITSTATUS 0
[2022-09-17T05:48:15.380] _job_complete: JobId=49179 done
[2022-09-17T05:48:34.481] sched/backfill: _start_job: Started JobId=49180 in cpu-opteron on cpu03
[2022-09-17T07:23:26.503] _job_complete: JobId=49130 WEXITSTATUS 0
[2022-09-17T07:23:26.503] _job_complete: JobId=49130 done
[2022-09-17T07:23:27.208] sched: Allocate JobId=49190 NodeList=cpu15 #CPUs=8 Partition=cpu-epyc
[2022-09-17T07:23:28.236] _job_complete: JobId=49190 WEXITSTATUS 127
[2022-09-17T07:23:28.236] _job_complete: JobId=49190 done
[2022-09-17T07:23:28.767] sched: Allocate JobId=49143 NodeList=cpu15 #CPUs=48 Partition=cpu-epyc
[2022-09-17T08:07:20.806] Time limit exhausted for JobId=49141
[2022-09-17T08:13:42.496] _slurm_rpc_submit_batch_job: JobId=49196 InitPrio=3363 usec=517
[2022-09-17T08:13:42.554] sched: Allocate JobId=49196 NodeList=cpu10 #CPUs=16 Partition=cpu-opteron
[2022-09-17T08:32:50.948] Time limit exhausted for JobId=49142
[2022-09-17T08:32:54.180] sched: Allocate JobId=49156 NodeList=cpu05 #CPUs=64 Partition=cpu-opteron
[2022-09-17T08:34:51.145] _slurm_rpc_submit_batch_job: JobId=49197 InitPrio=3363 usec=555
[2022-09-17T09:01:22.485] _job_complete: JobId=49131 WEXITSTATUS 0
[2022-09-17T09:01:22.485] _job_complete: JobId=49131 done
[2022-09-17T09:01:22.921] sched: Allocate JobId=49188 NodeList=cpu12 #CPUs=24 Partition=cpu-epyc
[2022-09-17T13:14:22.756] _job_complete: JobId=49180 WEXITSTATUS 0
[2022-09-17T13:14:22.761] _job_complete: JobId=49180 done
[2022-09-17T13:14:29.288] sched: Allocate JobId=49197 NodeList=cpu03 #CPUs=16 Partition=cpu-opteron
[2022-09-17T13:21:37.589] _job_complete: JobId=49156 WEXITSTATUS 0
[2022-09-17T13:21:37.590] _job_complete: JobId=49156 done
[2022-09-17T13:21:58.795] sched: Allocate JobId=49157 NodeList=cpu05 #CPUs=64 Partition=cpu-opteron
[2022-09-17T17:23:37.838] _job_complete: JobId=49157 WEXITSTATUS 0
[2022-09-17T17:23:37.844] _job_complete: JobId=49157 done
[2022-09-17T17:23:59.060] sched: Allocate JobId=49181 NodeList=cpu05 #CPUs=32 Partition=cpu-opteron
[2022-09-17T17:23:59.061] sched: Allocate JobId=49182 NodeList=cpu05 #CPUs=32 Partition=cpu-opteron
[2022-09-17T17:37:16.370] _job_complete: JobId=49193 WEXITSTATUS 1
[2022-09-17T17:37:16.375] _job_complete: JobId=49193 done
[2022-09-17T17:37:17.319] sched: Allocate JobId=49194 NodeList=gpu03 #CPUs=16 Partition=gpu-k10
[2022-09-17T19:18:52.196] _job_complete: JobId=49132 WEXITSTATUS 0
[2022-09-17T19:18:52.196] _job_complete: JobId=49132 done
[2022-09-17T20:34:14.822] _slurm_rpc_submit_batch_job: JobId=49198 InitPrio=10224 usec=510
[2022-09-17T20:34:15.376] sched: Allocate JobId=49198 NodeList=cpu03 #CPUs=1 Partition=cpu-opteron
[2022-09-17T20:34:39.600] _slurm_rpc_submit_batch_job: JobId=49199 InitPrio=10224 usec=406
[2022-09-17T20:34:40.388] sched: Allocate JobId=49199 NodeList=cpu03 #CPUs=1 Partition=cpu-opteron
[2022-09-17T20:40:31.767] _slurm_rpc_submit_batch_job: JobId=49200 InitPrio=224 usec=390
[2022-09-17T20:40:33.976] sched: Allocate JobId=49200 NodeList=cpu12 #CPUs=24 Partition=cpu-epyc
[2022-09-17T20:40:40.085] _slurm_rpc_submit_batch_job: JobId=49201 InitPrio=224 usec=392
[2022-09-17T20:40:40.985] sched: Allocate JobId=49201 NodeList=cpu13 #CPUs=24 Partition=cpu-epyc
[2022-09-17T20:40:46.765] _slurm_rpc_submit_batch_job: JobId=49202 InitPrio=224 usec=417
[2022-09-17T20:40:46.994] sched: Allocate JobId=49202 NodeList=cpu13 #CPUs=24 Partition=cpu-epyc
[2022-09-17T20:40:55.701] _slurm_rpc_submit_batch_job: JobId=49203 InitPrio=224 usec=502
[2022-09-17T20:41:02.926] _slurm_rpc_submit_batch_job: JobId=49204 InitPrio=224 usec=373
[2022-09-17T20:41:06.177] _job_complete: JobId=49198 WEXITSTATUS 0
[2022-09-17T20:41:06.177] _job_complete: JobId=49198 done
[2022-09-17T20:41:09.814] _slurm_rpc_submit_batch_job: JobId=49205 InitPrio=224 usec=426
[2022-09-17T20:41:18.843] _slurm_rpc_submit_batch_job: JobId=49206 InitPrio=224 usec=405
[2022-09-17T20:41:26.082] _slurm_rpc_submit_batch_job: JobId=49207 InitPrio=224 usec=405
[2022-09-17T20:41:33.771] _slurm_rpc_submit_batch_job: JobId=49208 InitPrio=224 usec=370
[2022-09-17T20:46:35.729] _job_complete: JobId=49199 WEXITSTATUS 0
[2022-09-17T20:46:35.730] _job_complete: JobId=49199 done
[2022-09-17T22:24:50.289] _job_complete: JobId=49201 WEXITSTATUS 0
[2022-09-17T22:24:50.294] _job_complete: JobId=49201 done
[2022-09-17T22:24:52.263] sched: Allocate JobId=49203 NodeList=cpu13 #CPUs=24 Partition=cpu-epyc
[2022-09-17T22:24:58.166] _job_complete: JobId=49200 WEXITSTATUS 0
[2022-09-17T22:24:58.166] _job_complete: JobId=49200 done
[2022-09-17T22:25:00.163] sched: Allocate JobId=49204 NodeList=cpu12 #CPUs=24 Partition=cpu-epyc
[2022-09-17T23:50:19.311] _job_complete: JobId=49204 WEXITSTATUS 0
[2022-09-17T23:50:19.312] _job_complete: JobId=49204 done
[2022-09-17T23:50:21.372] sched: Allocate JobId=49205 NodeList=cpu12 #CPUs=24 Partition=cpu-epyc
[2022-09-17T23:59:27.841] _job_complete: JobId=49203 WEXITSTATUS 0
[2022-09-17T23:59:27.842] _job_complete: JobId=49203 done
[2022-09-17T23:59:29.823] sched: Allocate JobId=49206 NodeList=cpu13 #CPUs=24 Partition=cpu-epyc
[2022-09-18T00:11:21.742] _job_complete: JobId=49202 WEXITSTATUS 0
[2022-09-18T00:11:21.743] _job_complete: JobId=49202 done
[2022-09-18T00:11:22.811] sched: Allocate JobId=49207 NodeList=cpu13 #CPUs=24 Partition=cpu-epyc
[2022-09-18T00:54:16.389] _job_complete: JobId=49181 WEXITSTATUS 0
[2022-09-18T00:54:16.390] _job_complete: JobId=49181 done
[2022-09-18T00:54:20.672] sched: Allocate JobId=49183 NodeList=cpu05 #CPUs=32 Partition=cpu-opteron
[2022-09-18T00:56:25.155] _job_complete: JobId=49196 WEXITSTATUS 0
[2022-09-18T00:56:25.155] _job_complete: JobId=49196 done
[2022-09-18T01:21:53.391] _job_complete: JobId=49182 WEXITSTATUS 0
[2022-09-18T01:21:53.392] _job_complete: JobId=49182 done
[2022-09-18T01:21:56.661] sched: Allocate JobId=49184 NodeList=cpu05 #CPUs=32 Partition=cpu-opteron
[2022-09-18T01:38:48.636] _job_complete: JobId=49205 WEXITSTATUS 0
[2022-09-18T01:38:48.637] _job_complete: JobId=49205 done
[2022-09-18T01:38:50.845] sched: Allocate JobId=49208 NodeList=cpu12 #CPUs=24 Partition=cpu-epyc
[2022-09-18T01:47:17.975] _job_complete: JobId=49206 WEXITSTATUS 0
[2022-09-18T01:47:17.976] _job_complete: JobId=49206 done
[2022-09-18T01:58:33.990] _job_complete: JobId=49207 WEXITSTATUS 0
[2022-09-18T01:58:33.991] _job_complete: JobId=49207 done
[2022-09-18T03:17:46.967] _slurm_rpc_submit_batch_job: JobId=49209 InitPrio=2017 usec=483
[2022-09-18T03:17:47.513] sched: Allocate JobId=49209 NodeList=cpu13 #CPUs=8 Partition=cpu-epyc
[2022-09-18T03:18:32.064] _slurm_rpc_submit_batch_job: JobId=49210 InitPrio=2017 usec=352
[2022-09-18T03:18:33.605] sched: Allocate JobId=49210 NodeList=cpu03 #CPUs=8 Partition=cpu-opteron
[2022-09-18T03:19:42.981] _slurm_rpc_submit_batch_job: JobId=49211 InitPrio=2017 usec=383
[2022-09-18T03:19:43.707] sched: Allocate JobId=49211 NodeList=cpu03 #CPUs=8 Partition=cpu-opteron
[2022-09-18T03:22:26.722] _job_complete: JobId=49208 WEXITSTATUS 0
[2022-09-18T03:22:26.727] _job_complete: JobId=49208 done
[2022-09-18T03:40:55.002] _job_complete: JobId=49209 WEXITSTATUS 1
[2022-09-18T03:40:55.003] _job_complete: JobId=49209 done
[2022-09-18T04:27:16.609] _job_complete: JobId=49210 WEXITSTATUS 0
[2022-09-18T04:27:16.610] _job_complete: JobId=49210 done
[2022-09-18T04:33:34.385] _job_complete: JobId=49211 WEXITSTATUS 0
[2022-09-18T04:33:34.386] _job_complete: JobId=49211 done
[2022-09-18T06:30:00.641] _job_complete: JobId=49018 WEXITSTATUS 0
[2022-09-18T06:30:00.647] _job_complete: JobId=49018 done
[2022-09-18T06:30:06.913] sched: Allocate JobId=49185 NodeList=cpu10 #CPUs=32 Partition=cpu-opteron
[2022-09-18T06:30:06.914] sched: Allocate JobId=49186 NodeList=cpu10 #CPUs=32 Partition=cpu-opteron
[2022-09-18T08:54:42.382] _job_complete: JobId=49183 WEXITSTATUS 0
[2022-09-18T08:54:42.388] _job_complete: JobId=49183 done
[2022-09-18T08:54:45.676] sched: Allocate JobId=49187 NodeList=cpu05 #CPUs=32 Partition=cpu-opteron
[2022-09-18T09:27:55.825] _job_complete: JobId=49184 WEXITSTATUS 0
[2022-09-18T09:27:55.826] _job_complete: JobId=49184 done
[2022-09-18T10:41:54.683] _slurm_rpc_kill_job: REQUEST_KILL_JOB JobId=49189 uid 548200017
[2022-09-18T10:42:35.701] _slurm_rpc_submit_batch_job: JobId=49212 InitPrio=224 usec=433
[2022-09-18T10:42:36.705] sched: Allocate JobId=49212 NodeList=cpu13 #CPUs=48 Partition=cpu-epyc
[2022-09-18T10:43:16.675] _slurm_rpc_submit_batch_job: JobId=49213 InitPrio=10224 usec=458
[2022-09-18T10:43:16.885] sched: Allocate JobId=49213 NodeList=cpu03 #CPUs=1 Partition=cpu-opteron
[2022-09-18T10:43:32.961] _slurm_rpc_submit_batch_job: JobId=49214 InitPrio=10224 usec=438
[2022-09-18T10:43:34.910] sched: Allocate JobId=49214 NodeList=cpu03 #CPUs=1 Partition=cpu-opteron
[2022-09-18T10:43:48.339] _slurm_rpc_submit_batch_job: JobId=49215 InitPrio=10224 usec=539
[2022-09-18T10:43:48.930] sched: Allocate JobId=49215 NodeList=cpu03 #CPUs=1 Partition=cpu-opteron
[2022-09-18T10:43:51.311] _job_complete: JobId=49215 WEXITSTATUS 1
[2022-09-18T10:43:51.312] _job_complete: JobId=49215 done
[2022-09-18T10:44:01.908] _slurm_rpc_submit_batch_job: JobId=49216 InitPrio=10224 usec=455
[2022-09-18T10:44:01.948] sched: Allocate JobId=49216 NodeList=cpu03 #CPUs=1 Partition=cpu-opteron
[2022-09-18T10:44:20.071] _slurm_rpc_submit_batch_job: JobId=49217 InitPrio=10224 usec=416
[2022-09-18T10:44:20.974] sched: Allocate JobId=49217 NodeList=cpu03 #CPUs=1 Partition=cpu-opteron
[2022-09-18T10:44:39.618] _slurm_rpc_submit_batch_job: JobId=49218 InitPrio=10224 usec=422
[2022-09-18T10:44:40.000] sched: Allocate JobId=49218 NodeList=cpu03 #CPUs=1 Partition=cpu-opteron
[2022-09-18T10:44:54.658] _slurm_rpc_submit_batch_job: JobId=49219 InitPrio=10224 usec=543
[2022-09-18T10:44:55.022] sched: Allocate JobId=49219 NodeList=cpu03 #CPUs=1 Partition=cpu-opteron
[2022-09-18T10:45:09.228] _slurm_rpc_submit_batch_job: JobId=49220 InitPrio=10224 usec=411
[2022-09-18T10:45:10.042] sched: Allocate JobId=49220 NodeList=cpu03 #CPUs=1 Partition=cpu-opteron
[2022-09-18T10:45:30.170] _slurm_rpc_submit_batch_job: JobId=49221 InitPrio=10224 usec=471
[2022-09-18T10:45:31.071] sched: Allocate JobId=49221 NodeList=cpu03 #CPUs=1 Partition=cpu-opteron
[2022-09-18T10:46:31.842] _slurm_rpc_submit_batch_job: JobId=49222 InitPrio=10224 usec=483
[2022-09-18T10:46:34.159] sched: Allocate JobId=49222 NodeList=cpu03 #CPUs=1 Partition=cpu-opteron
[2022-09-18T10:47:00.409] _slurm_rpc_submit_batch_job: JobId=49223 InitPrio=10224 usec=518
[2022-09-18T10:47:01.196] sched: Allocate JobId=49223 NodeList=cpu05 #CPUs=1 Partition=cpu-opteron
[2022-09-18T10:47:19.921] _slurm_rpc_submit_batch_job: JobId=49224 InitPrio=10224 usec=427
[2022-09-18T10:47:20.223] sched: Allocate JobId=49224 NodeList=cpu05 #CPUs=1 Partition=cpu-opteron
[2022-09-18T10:47:37.304] _slurm_rpc_submit_batch_job: JobId=49225 InitPrio=10224 usec=401
[2022-09-18T10:47:38.247] sched: Allocate JobId=49225 NodeList=cpu05 #CPUs=1 Partition=cpu-opteron
[2022-09-18T10:50:28.263] _slurm_rpc_submit_batch_job: JobId=49226 InitPrio=672 usec=417
[2022-09-18T10:52:59.165] _job_complete: JobId=49222 WEXITSTATUS 0
[2022-09-18T10:52:59.167] _job_complete: JobId=49222 done
[2022-09-18T10:53:18.727] _slurm_rpc_submit_batch_job: JobId=49227 InitPrio=224 usec=439
[2022-09-18T10:53:25.305] _slurm_rpc_submit_batch_job: JobId=49228 InitPrio=224 usec=431
[2022-09-18T10:53:37.114] sched/backfill: _start_job: Started JobId=49227 in cpu-epyc on cpu12
[2022-09-18T10:53:37.642] _slurm_rpc_submit_batch_job: JobId=49229 InitPrio=224 usec=413
[2022-09-18T10:53:44.449] _slurm_rpc_submit_batch_job: JobId=49230 InitPrio=224 usec=388
[2022-09-18T10:53:50.953] _slurm_rpc_submit_batch_job: JobId=49231 InitPrio=224 usec=438
[2022-09-18T10:53:53.638] _job_complete: JobId=49225 WEXITSTATUS 0
[2022-09-18T10:53:53.639] _job_complete: JobId=49225 done
[2022-09-18T10:54:05.620] _job_complete: JobId=49223 WEXITSTATUS 0
[2022-09-18T10:54:05.620] _job_complete: JobId=49223 done
[2022-09-18T10:54:24.070] _job_complete: JobId=49224 WEXITSTATUS 0
[2022-09-18T10:54:24.071] _job_complete: JobId=49224 done
[2022-09-18T10:57:23.805] _job_complete: JobId=49213 WEXITSTATUS 0
[2022-09-18T10:57:23.806] _job_complete: JobId=49213 done
[2022-09-18T10:57:34.420] _job_complete: JobId=49214 WEXITSTATUS 0
[2022-09-18T10:57:34.421] _job_complete: JobId=49214 done
[2022-09-18T10:57:34.602] _job_complete: JobId=49216 WEXITSTATUS 0
[2022-09-18T10:57:34.603] _job_complete: JobId=49216 done
[2022-09-18T10:57:42.808] _job_complete: JobId=49217 WEXITSTATUS 0
[2022-09-18T10:57:42.809] _job_complete: JobId=49217 done
[2022-09-18T10:59:24.223] _job_complete: JobId=49219 WEXITSTATUS 0
[2022-09-18T10:59:24.225] _job_complete: JobId=49219 done
[2022-09-18T10:59:24.756] _job_complete: JobId=49218 WEXITSTATUS 0
[2022-09-18T10:59:24.757] _job_complete: JobId=49218 done
[2022-09-18T10:59:34.691] _job_complete: JobId=49220 WEXITSTATUS 0
[2022-09-18T10:59:34.692] _job_complete: JobId=49220 done
[2022-09-18T10:59:58.880] _job_complete: JobId=49221 WEXITSTATUS 0
[2022-09-18T10:59:58.881] _job_complete: JobId=49221 done
[2022-09-18T11:03:19.383] _slurm_rpc_submit_batch_job: JobId=49232 InitPrio=672 usec=469
[2022-09-18T11:10:51.659] _slurm_rpc_submit_batch_job: JobId=49233 InitPrio=10224 usec=480
[2022-09-18T11:10:51.722] sched: Allocate JobId=49233 NodeList=cpu03 #CPUs=1 Partition=cpu-opteron
[2022-09-18T11:22:04.399] _job_complete: JobId=49233 WEXITSTATUS 0
[2022-09-18T11:22:04.400] _job_complete: JobId=49233 done
[2022-09-18T11:35:50.226] _slurm_rpc_submit_batch_job: JobId=49234 InitPrio=224 usec=473
[2022-09-18T11:35:57.937] _slurm_rpc_submit_batch_job: JobId=49235 InitPrio=224 usec=428
[2022-09-18T11:36:04.031] _slurm_rpc_submit_batch_job: JobId=49236 InitPrio=224 usec=440
[2022-09-18T11:36:10.531] _slurm_rpc_submit_batch_job: JobId=49237 InitPrio=224 usec=410
[2022-09-18T11:36:17.465] _slurm_rpc_submit_batch_job: JobId=49238 InitPrio=224 usec=400
[2022-09-18T11:36:25.170] _slurm_rpc_submit_batch_job: JobId=49239 InitPrio=224 usec=497
[2022-09-18T11:36:31.539] _slurm_rpc_submit_batch_job: JobId=49240 InitPrio=224 usec=381
[2022-09-18T11:36:37.171] sched/backfill: _start_job: Started JobId=49234 in cpu-opteron on cpu05
[2022-09-18T11:36:37.875] _slurm_rpc_submit_batch_job: JobId=49241 InitPrio=224 usec=403
[2022-09-18T11:36:48.144] _slurm_rpc_submit_batch_job: JobId=49242 InitPrio=224 usec=385
[2022-09-18T11:50:05.778] _slurm_rpc_submit_batch_job: JobId=49243 InitPrio=224 usec=468
[2022-09-18T11:50:11.908] _slurm_rpc_submit_batch_job: JobId=49244 InitPrio=224 usec=380
[2022-09-18T11:50:17.845] _slurm_rpc_submit_batch_job: JobId=49245 InitPrio=224 usec=473
[2022-09-18T11:50:25.146] _slurm_rpc_submit_batch_job: JobId=49246 InitPrio=224 usec=409
[2022-09-18T11:50:36.458] _slurm_rpc_submit_batch_job: JobId=49247 InitPrio=224 usec=399
[2022-09-18T11:50:44.000] _slurm_rpc_submit_batch_job: JobId=49248 InitPrio=224 usec=437
[2022-09-18T11:50:50.931] _slurm_rpc_submit_batch_job: JobId=49249 InitPrio=224 usec=416
[2022-09-18T11:50:57.756] _slurm_rpc_submit_batch_job: JobId=49250 InitPrio=224 usec=475
[2022-09-18T11:51:06.608] _slurm_rpc_submit_batch_job: JobId=49251 InitPrio=224 usec=553
[2022-09-18T11:55:18.498] _job_complete: JobId=49212 WEXITSTATUS 0
[2022-09-18T11:55:18.499] _job_complete: JobId=49212 done
[2022-09-18T11:55:23.476] sched: Allocate JobId=49226 NodeList=cpu13 #CPUs=48 Partition=cpu-epyc
[2022-09-18T11:55:24.677] _job_complete: JobId=49226 WEXITSTATUS 1
[2022-09-18T11:55:24.677] _job_complete: JobId=49226 done
[2022-09-18T11:55:24.975] sched: Allocate JobId=49228 NodeList=cpu13 #CPUs=24 Partition=cpu-epyc
[2022-09-18T11:55:24.976] sched: Allocate JobId=49229 NodeList=cpu13 #CPUs=24 Partition=cpu-epyc
[2022-09-18T12:31:48.113] _job_complete: JobId=49227 WEXITSTATUS 0
[2022-09-18T12:31:48.115] _job_complete: JobId=49227 done
[2022-09-18T12:31:50.148] sched: Allocate JobId=49230 NodeList=cpu12 #CPUs=24 Partition=cpu-epyc
[2022-09-18T12:35:21.420] _job_complete: JobId=49234 WEXITSTATUS 0
[2022-09-18T12:35:21.421] _job_complete: JobId=49234 done
[2022-09-18T12:35:37.292] sched/backfill: _start_job: Started JobId=49235 in cpu-opteron on cpu05
[2022-09-18T12:59:13.271] _job_complete: JobId=49186 WEXITSTATUS 0
[2022-09-18T12:59:13.272] _job_complete: JobId=49186 done
[2022-09-18T12:59:37.346] sched/backfill: _start_job: Started JobId=49236 in cpu-opteron on cpu10
[2022-09-18T13:14:54.492] Time limit exhausted for JobId=49197
[2022-09-18T13:15:37.384] sched/backfill: _start_job: Started JobId=49237 in cpu-opteron on cpu03
[2022-09-18T13:18:41.556] _job_complete: JobId=49229 WEXITSTATUS 0
[2022-09-18T13:18:41.557] _job_complete: JobId=49229 done
[2022-09-18T13:18:43.583] sched: Allocate JobId=49231 NodeList=cpu13 #CPUs=24 Partition=cpu-epyc
[2022-09-18T13:21:38.755] _job_complete: JobId=49228 WEXITSTATUS 0
[2022-09-18T13:21:38.756] _job_complete: JobId=49228 done
[2022-09-18T13:21:40.666] sched: Allocate JobId=49243 NodeList=cpu13 #CPUs=16 Partition=cpu-epyc
[2022-09-18T13:28:32.838] _job_complete: JobId=49235 WEXITSTATUS 0
[2022-09-18T13:28:32.838] _job_complete: JobId=49235 done
[2022-09-18T13:40:02.807] _job_complete: JobId=49243 WEXITSTATUS 0
[2022-09-18T13:40:02.808] _job_complete: JobId=49243 done
[2022-09-18T13:40:03.779] sched: Allocate JobId=49244 NodeList=cpu13 #CPUs=16 Partition=cpu-epyc
[2022-09-18T13:48:01.418] _job_complete: JobId=49230 WEXITSTATUS 0
[2022-09-18T13:48:01.419] _job_complete: JobId=49230 done
[2022-09-18T13:48:03.621] sched: Allocate JobId=49245 NodeList=cpu12 #CPUs=16 Partition=cpu-epyc
[2022-09-18T13:52:06.183] _job_complete: JobId=49236 WEXITSTATUS 0
[2022-09-18T13:52:06.184] _job_complete: JobId=49236 done
[2022-09-18T13:52:37.460] sched/backfill: _start_job: Started JobId=49238 in cpu-opteron on cpu05
[2022-09-18T13:57:18.743] _job_complete: JobId=49244 WEXITSTATUS 0
[2022-09-18T13:57:18.744] _job_complete: JobId=49244 done
[2022-09-18T13:57:19.670] sched: Allocate JobId=49246 NodeList=cpu13 #CPUs=16 Partition=cpu-epyc
[2022-09-18T14:04:55.956] _job_complete: JobId=49245 WEXITSTATUS 0
[2022-09-18T14:04:55.957] _job_complete: JobId=49245 done
[2022-09-18T14:04:57.172] sched: Allocate JobId=49247 NodeList=cpu12 #CPUs=16 Partition=cpu-epyc
[2022-09-18T14:09:26.618] _job_complete: JobId=49237 WEXITSTATUS 0
[2022-09-18T14:09:26.618] _job_complete: JobId=49237 done
[2022-09-18T14:09:37.491] sched/backfill: _start_job: Started JobId=49239 in cpu-opteron on cpu03
[2022-09-18T14:14:28.935] _job_complete: JobId=49246 WEXITSTATUS 0
[2022-09-18T14:14:28.936] _job_complete: JobId=49246 done
[2022-09-18T14:14:29.864] sched: Allocate JobId=49248 NodeList=cpu13 #CPUs=16 Partition=cpu-epyc
[2022-09-18T14:15:18.799] _slurm_rpc_submit_batch_job: JobId=49252 InitPrio=10224 usec=628
[2022-09-18T14:15:18.963] sched: Allocate JobId=49252 NodeList=cpu10 #CPUs=1 Partition=cpu-opteron
[2022-09-18T14:15:36.511] _slurm_rpc_submit_batch_job: JobId=49253 InitPrio=10224 usec=567
[2022-09-18T14:15:36.983] sched: Allocate JobId=49253 NodeList=cpu10 #CPUs=1 Partition=cpu-opteron
[2022-09-18T14:15:58.041] _slurm_rpc_submit_batch_job: JobId=49254 InitPrio=10224 usec=463
[2022-09-18T14:15:59.013] sched: Allocate JobId=49254 NodeList=cpu10 #CPUs=1 Partition=cpu-opteron
[2022-09-18T14:16:15.979] _slurm_rpc_submit_batch_job: JobId=49255 InitPrio=10224 usec=575
[2022-09-18T14:16:16.035] sched: Allocate JobId=49255 NodeList=cpu10 #CPUs=1 Partition=cpu-opteron
[2022-09-18T14:17:31.530] _slurm_rpc_submit_batch_job: JobId=49256 InitPrio=10224 usec=465
[2022-09-18T14:17:34.144] sched: Allocate JobId=49256 NodeList=cpu10 #CPUs=1 Partition=cpu-opteron
[2022-09-18T14:17:46.071] _slurm_rpc_submit_batch_job: JobId=49257 InitPrio=10224 usec=432
[2022-09-18T14:17:46.160] sched: Allocate JobId=49257 NodeList=cpu10 #CPUs=1 Partition=cpu-opteron
[2022-09-18T14:18:12.367] _slurm_rpc_submit_batch_job: JobId=49258 InitPrio=10224 usec=489
[2022-09-18T14:18:13.292] sched: Allocate JobId=49258 NodeList=cpu10 #CPUs=1 Partition=cpu-opteron
[2022-09-18T14:18:15.586] _job_complete: JobId=49258 WEXITSTATUS 1
[2022-09-18T14:18:15.587] _job_complete: JobId=49258 done
[2022-09-18T14:18:24.231] _job_complete: JobId=49252 WEXITSTATUS 0
[2022-09-18T14:18:24.232] _job_complete: JobId=49252 done
[2022-09-18T14:18:27.680] _slurm_rpc_submit_batch_job: JobId=49259 InitPrio=10224 usec=517
[2022-09-18T14:18:28.313] sched: Allocate JobId=49259 NodeList=cpu10 #CPUs=1 Partition=cpu-opteron
[2022-09-18T14:18:38.364] _job_complete: JobId=49253 WEXITSTATUS 0
[2022-09-18T14:18:38.364] _job_complete: JobId=49253 done
[2022-09-18T14:18:58.383] _job_complete: JobId=49254 WEXITSTATUS 0
[2022-09-18T14:18:58.384] _job_complete: JobId=49254 done
[2022-09-18T14:19:13.695] _job_complete: JobId=49255 WEXITSTATUS 0
[2022-09-18T14:19:13.696] _job_complete: JobId=49255 done
[2022-09-18T14:19:47.150] _slurm_rpc_submit_batch_job: JobId=49260 InitPrio=10224 usec=404
[2022-09-18T14:19:47.428] sched: Allocate JobId=49260 NodeList=cpu10 #CPUs=1 Partition=cpu-opteron
[2022-09-18T14:20:03.985] _slurm_rpc_submit_batch_job: JobId=49261 InitPrio=10224 usec=465
[2022-09-18T14:20:04.451] sched: Allocate JobId=49261 NodeList=cpu10 #CPUs=1 Partition=cpu-opteron
[2022-09-18T14:20:22.265] _slurm_rpc_submit_batch_job: JobId=49262 InitPrio=10224 usec=465
[2022-09-18T14:20:22.475] sched: Allocate JobId=49262 NodeList=cpu10 #CPUs=1 Partition=cpu-opteron
[2022-09-18T14:20:37.877] _slurm_rpc_submit_batch_job: JobId=49263 InitPrio=10224 usec=484
[2022-09-18T14:20:38.496] sched: Allocate JobId=49263 NodeList=cpu10 #CPUs=1 Partition=cpu-opteron
[2022-09-18T14:20:38.609] _job_complete: JobId=49247 WEXITSTATUS 0
[2022-09-18T14:20:38.610] _job_complete: JobId=49247 done
[2022-09-18T14:20:39.782] sched: Allocate JobId=49249 NodeList=cpu12 #CPUs=16 Partition=cpu-epyc
[2022-09-18T14:20:56.920] _job_complete: JobId=49256 WEXITSTATUS 0
[2022-09-18T14:20:56.921] _job_complete: JobId=49256 done
[2022-09-18T14:20:58.892] _job_complete: JobId=49257 WEXITSTATUS 0
[2022-09-18T14:20:58.892] _job_complete: JobId=49257 done
[2022-09-18T14:21:16.049] _job_complete: JobId=49259 WEXITSTATUS 0
[2022-09-18T14:21:16.050] _job_complete: JobId=49259 done
[2022-09-18T14:24:08.331] _job_complete: JobId=49185 WEXITSTATUS 0
[2022-09-18T14:24:08.332] _job_complete: JobId=49185 done
[2022-09-18T14:29:46.352] _job_complete: JobId=49260 WEXITSTATUS 0
[2022-09-18T14:29:46.353] _job_complete: JobId=49260 done
[2022-09-18T14:30:08.094] _job_complete: JobId=49263 WEXITSTATUS 0
[2022-09-18T14:30:08.095] _job_complete: JobId=49263 done
[2022-09-18T14:31:09.227] _job_complete: JobId=49261 WEXITSTATUS 0
[2022-09-18T14:31:09.227] _job_complete: JobId=49261 done
[2022-09-18T14:31:21.661] _job_complete: JobId=49262 WEXITSTATUS 0
[2022-09-18T14:31:21.661] _job_complete: JobId=49262 done
[2022-09-18T14:31:24.923] sched: Allocate JobId=49232 NodeList=cpu10 #CPUs=64 Partition=cpu-opteron
[2022-09-18T14:33:00.302] _job_complete: JobId=49248 WEXITSTATUS 0
[2022-09-18T14:33:00.302] _job_complete: JobId=49248 done
[2022-09-18T14:33:01.303] sched: Allocate JobId=49250 NodeList=cpu13 #CPUs=16 Partition=cpu-epyc
[2022-09-18T14:38:36.711] _job_complete: JobId=49249 WEXITSTATUS 0
[2022-09-18T14:38:36.712] _job_complete: JobId=49249 done
[2022-09-18T14:38:37.756] sched: Allocate JobId=49251 NodeList=cpu12 #CPUs=16 Partition=cpu-epyc
[2022-09-18T14:43:49.195] _job_complete: JobId=49238 WEXITSTATUS 0
[2022-09-18T14:43:49.196] _job_complete: JobId=49238 done
[2022-09-18T14:43:50.531] sched: Allocate JobId=49240 NodeList=cpu05 #CPUs=32 Partition=cpu-opteron
[2022-09-18T14:51:21.448] _job_complete: JobId=49232 WEXITSTATUS 1
[2022-09-18T14:51:21.448] _job_complete: JobId=49232 done
[2022-09-18T14:51:24.703] sched: Allocate JobId=49241 NodeList=cpu10 #CPUs=32 Partition=cpu-opteron
[2022-09-18T14:51:24.704] sched: Allocate JobId=49242 NodeList=cpu10 #CPUs=32 Partition=cpu-opteron
[2022-09-18T14:52:08.319] _job_complete: JobId=49250 WEXITSTATUS 0
[2022-09-18T14:52:08.320] _job_complete: JobId=49250 done
[2022-09-18T14:53:15.207] _job_complete: JobId=49231 WEXITSTATUS 0
[2022-09-18T14:53:15.207] _job_complete: JobId=49231 done
[2022-09-18T14:57:23.997] _job_complete: JobId=49251 WEXITSTATUS 0
[2022-09-18T14:57:23.998] _job_complete: JobId=49251 done
[2022-09-18T15:04:08.771] _slurm_rpc_submit_batch_job: JobId=49264 InitPrio=2017 usec=1064
[2022-09-18T15:05:24.329] _slurm_rpc_submit_batch_job: JobId=49265 InitPrio=2017 usec=341
[2022-09-18T15:05:25.196] sched: Allocate JobId=49265 NodeList=cpu12 #CPUs=8 Partition=cpu-epyc
[2022-09-18T15:06:38.709] _slurm_rpc_submit_batch_job: JobId=49266 InitPrio=2017 usec=412
[2022-09-18T15:06:39.272] sched: Allocate JobId=49266 NodeList=cpu12 #CPUs=8 Partition=cpu-epyc
[2022-09-18T15:07:03.083] _slurm_rpc_kill_job: REQUEST_KILL_JOB JobId=49194 uid 548200029
[2022-09-18T15:07:10.084] _slurm_rpc_kill_job: REQUEST_KILL_JOB JobId=49125 uid 548200029
[2022-09-18T15:07:10.345] sched: Allocate JobId=49195 NodeList=gpu03 #CPUs=16 Partition=gpu-k10
[2022-09-18T15:07:15.208] sched: Allocate JobId=49264 NodeList=gpu01 #CPUs=16 Partition=gpu-k10
[2022-09-18T15:07:34.233] _job_complete: JobId=49239 WEXITSTATUS 0
[2022-09-18T15:07:34.234] _job_complete: JobId=49239 done
[2022-09-18T15:28:15.566] _job_complete: JobId=49265 WEXITSTATUS 1
[2022-09-18T15:28:15.567] _job_complete: JobId=49265 done
[2022-09-18T15:30:33.737] _job_complete: JobId=49266 WEXITSTATUS 1
[2022-09-18T15:30:33.737] _job_complete: JobId=49266 done
[2022-09-18T15:42:17.438] _job_complete: JobId=49240 WEXITSTATUS 0
[2022-09-18T15:42:17.439] _job_complete: JobId=49240 done
[2022-09-18T15:49:53.021] _job_complete: JobId=49242 WEXITSTATUS 0
[2022-09-18T15:49:53.021] _job_complete: JobId=49242 done
[2022-09-18T15:51:54.599] _job_complete: JobId=49241 WEXITSTATUS 0
[2022-09-18T15:51:54.599] _job_complete: JobId=49241 done
[2022-09-18T15:52:00.342] _job_complete: JobId=49187 WEXITSTATUS 0
[2022-09-18T15:52:00.343] _job_complete: JobId=49187 done
[2022-09-18T15:53:04.895] _slurm_rpc_kill_job: REQUEST_KILL_JOB JobId=49176 uid 548300621
[2022-09-18T15:53:05.951] _slurm_rpc_kill_job: REQUEST_KILL_JOB JobId=49176 uid 548300621
[2022-09-18T15:53:11.714] _slurm_rpc_submit_batch_job: JobId=49267 InitPrio=1121 usec=553
[2022-09-18T15:53:12.280] sched: Allocate JobId=49267 NodeList=cpu10 #CPUs=64 Partition=cpu-opteron
[2022-09-18T16:02:55.694] _job_complete: JobId=49264 WEXITSTATUS 2
[2022-09-18T16:02:55.696] _job_complete: JobId=49264 done
[2022-09-18T16:29:23.381] _slurm_rpc_submit_batch_job: JobId=49268 InitPrio=1569 usec=496
[2022-09-18T17:50:19.342] _slurm_rpc_submit_batch_job: JobId=49269 InitPrio=10224 usec=518
[2022-09-18T17:50:19.471] sched: Allocate JobId=49269 NodeList=cpu03 #CPUs=1 Partition=cpu-opteron
[2022-09-18T17:53:21.897] _slurm_rpc_submit_batch_job: JobId=49270 InitPrio=10224 usec=433
[2022-09-18T17:53:22.820] sched: Allocate JobId=49270 NodeList=cpu03 #CPUs=1 Partition=cpu-opteron
[2022-09-18T17:53:51.748] _slurm_rpc_submit_batch_job: JobId=49271 InitPrio=10224 usec=452
[2022-09-18T17:53:51.860] sched: Allocate JobId=49271 NodeList=cpu03 #CPUs=1 Partition=cpu-opteron
[2022-09-18T17:54:11.357] _slurm_rpc_submit_batch_job: JobId=49272 InitPrio=10224 usec=497
[2022-09-18T17:54:11.887] sched: Allocate JobId=49272 NodeList=cpu03 #CPUs=1 Partition=cpu-opteron
[2022-09-18T17:54:47.736] _slurm_rpc_submit_batch_job: JobId=49273 InitPrio=10224 usec=380
[2022-09-18T17:54:47.936] sched: Allocate JobId=49273 NodeList=cpu03 #CPUs=1 Partition=cpu-opteron
[2022-09-18T17:55:08.641] _slurm_rpc_submit_batch_job: JobId=49274 InitPrio=10224 usec=485
[2022-09-18T17:55:08.965] sched: Allocate JobId=49274 NodeList=cpu03 #CPUs=1 Partition=cpu-opteron
[2022-09-18T17:55:48.899] _slurm_rpc_submit_batch_job: JobId=49275 InitPrio=10224 usec=511
[2022-09-18T17:55:49.024] sched: Allocate JobId=49275 NodeList=cpu03 #CPUs=1 Partition=cpu-opteron
[2022-09-18T17:56:25.884] _job_complete: JobId=49270 WEXITSTATUS 0
[2022-09-18T17:56:25.885] _job_complete: JobId=49270 done
[2022-09-18T17:56:50.736] _job_complete: JobId=49271 WEXITSTATUS 0
[2022-09-18T17:56:50.737] _job_complete: JobId=49271 done
[2022-09-18T17:56:56.332] _slurm_rpc_submit_batch_job: JobId=49276 InitPrio=10224 usec=408
[2022-09-18T17:56:57.114] sched: Allocate JobId=49276 NodeList=cpu03 #CPUs=1 Partition=cpu-opteron
[2022-09-18T17:57:16.379] _slurm_rpc_submit_batch_job: JobId=49277 InitPrio=10224 usec=400
[2022-09-18T17:57:17.141] sched: Allocate JobId=49277 NodeList=cpu03 #CPUs=1 Partition=cpu-opteron
[2022-09-18T17:57:20.341] _job_complete: JobId=49272 WEXITSTATUS 0
[2022-09-18T17:57:20.342] _job_complete: JobId=49272 done
[2022-09-18T17:57:32.329] _slurm_rpc_submit_batch_job: JobId=49278 InitPrio=10224 usec=401
[2022-09-18T17:57:35.166] sched: Allocate JobId=49278 NodeList=cpu03 #CPUs=1 Partition=cpu-opteron
[2022-09-18T17:57:51.203] _slurm_rpc_submit_batch_job: JobId=49279 InitPrio=10224 usec=507
[2022-09-18T17:57:51.224] sched: Allocate JobId=49279 NodeList=cpu03 #CPUs=1 Partition=cpu-opteron
[2022-09-18T17:58:01.341] _job_complete: JobId=49273 WEXITSTATUS 0
[2022-09-18T17:58:01.342] _job_complete: JobId=49273 done
[2022-09-18T17:58:05.403] _slurm_rpc_submit_batch_job: JobId=49280 InitPrio=10224 usec=451
[2022-09-18T17:58:06.285] sched: Allocate JobId=49280 NodeList=cpu03 #CPUs=1 Partition=cpu-opteron
[2022-09-18T17:58:07.757] _job_complete: JobId=49280 WEXITSTATUS 1
[2022-09-18T17:58:07.758] _job_complete: JobId=49280 done
[2022-09-18T17:58:25.141] _job_complete: JobId=49274 WEXITSTATUS 0
[2022-09-18T17:58:25.141] _job_complete: JobId=49274 done
[2022-09-18T17:58:49.146] _job_complete: JobId=49275 WEXITSTATUS 0
[2022-09-18T17:58:49.147] _job_complete: JobId=49275 done
[2022-09-18T17:59:56.309] _job_complete: JobId=49276 WEXITSTATUS 0
[2022-09-18T17:59:56.309] _job_complete: JobId=49276 done
[2022-09-18T18:00:29.856] _job_complete: JobId=49277 WEXITSTATUS 0
[2022-09-18T18:00:29.857] _job_complete: JobId=49277 done
[2022-09-18T18:00:46.598] _job_complete: JobId=49279 WEXITSTATUS 0
[2022-09-18T18:00:46.598] _job_complete: JobId=49279 done
[2022-09-18T18:00:46.757] _job_complete: JobId=49278 WEXITSTATUS 0
[2022-09-18T18:00:46.758] _job_complete: JobId=49278 done
[2022-09-18T18:01:24.900] _job_complete: JobId=49269 WEXITSTATUS 0
[2022-09-18T18:01:24.901] _job_complete: JobId=49269 done
[2022-09-18T18:07:58.377] _slurm_rpc_submit_batch_job: JobId=49281 InitPrio=10224 usec=365
[2022-09-18T18:07:59.321] sched: Allocate JobId=49281 NodeList=cpu03 #CPUs=1 Partition=cpu-opteron
[2022-09-18T18:10:50.325] _job_complete: JobId=49281 WEXITSTATUS 0
[2022-09-18T18:10:50.326] _job_complete: JobId=49281 done
[2022-09-18T18:13:16.882] _slurm_rpc_submit_batch_job: JobId=49282 InitPrio=10224 usec=469
[2022-09-18T18:13:16.903] sched: Allocate JobId=49282 NodeList=cpu03 #CPUs=1 Partition=cpu-opteron
[2022-09-18T18:19:41.257] _job_complete: JobId=49282 WEXITSTATUS 0
[2022-09-18T18:19:41.258] _job_complete: JobId=49282 done
[2022-09-18T18:29:42.597] _job_complete: JobId=49145 WEXITSTATUS 0
[2022-09-18T18:29:42.603] _job_complete: JobId=49145 done
[2022-09-18T18:29:50.624] sched: Allocate JobId=49268 NodeList=gpu04 #CPUs=16 Partition=gpu-k40c
[2022-09-18T18:45:25.076] _slurm_rpc_submit_batch_job: JobId=49283 InitPrio=2017 usec=992
[2022-09-18T18:45:25.181] sched: Allocate JobId=49283 NodeList=gpu01 #CPUs=16 Partition=gpu-k10
[2022-09-18T18:46:48.392] _slurm_rpc_submit_batch_job: JobId=49284 InitPrio=2017 usec=942
[2022-09-18T18:47:40.065] _slurm_rpc_submit_batch_job: JobId=49285 InitPrio=2017 usec=931
[2022-09-18T18:48:18.976] _slurm_rpc_kill_job: REQUEST_KILL_JOB JobId=49195 uid 548200029
[2022-09-18T18:48:21.219] sched: Allocate JobId=49284 NodeList=gpu03 #CPUs=16 Partition=gpu-k10
[2022-09-18T18:49:08.021] _slurm_rpc_submit_batch_job: JobId=49286 InitPrio=2017 usec=688
[2022-09-18T18:51:20.540] _slurm_rpc_submit_batch_job: JobId=49287 InitPrio=2017 usec=540
[2022-09-18T21:13:31.788] sched: _slurm_rpc_allocate_resources JobId=49288 NodeList=cpu03 usec=18066
[2022-09-18T21:29:26.052] _job_complete: JobId=49288 WEXITSTATUS 0
[2022-09-18T21:29:26.052] _job_complete: JobId=49288 done
[2022-09-18T21:44:45.627] _pick_best_nodes: JobId=49289 never runnable in partition cpu-epyc
[2022-09-18T21:44:45.633] _slurm_rpc_submit_batch_job: Requested node configuration is not available
[2022-09-18T21:45:07.996] _slurm_rpc_submit_batch_job: JobId=49290 InitPrio=8295 usec=409
[2022-09-18T21:45:36.409] _slurm_rpc_submit_batch_job: JobId=49291 InitPrio=10224 usec=548
[2022-09-18T21:45:36.602] sched: Allocate JobId=49291 NodeList=cpu03 #CPUs=1 Partition=cpu-opteron
[2022-09-18T21:46:08.466] _slurm_rpc_submit_batch_job: JobId=49292 InitPrio=10224 usec=451
[2022-09-18T21:46:08.619] sched: Allocate JobId=49292 NodeList=cpu03 #CPUs=1 Partition=cpu-opteron
[2022-09-18T21:53:11.738] _job_complete: JobId=49292 WEXITSTATUS 0
[2022-09-18T21:53:11.739] _job_complete: JobId=49292 done
[2022-09-18T21:56:35.157] sched: _slurm_rpc_allocate_resources JobId=49293 NodeList=(null) usec=1029
[2022-09-18T21:56:37.771] sched/backfill: _start_job: Started JobId=49293 in cpu-epyc on cpu12
[2022-09-18T21:57:06.247] _job_complete: JobId=49291 WEXITSTATUS 0
[2022-09-18T21:57:06.247] _job_complete: JobId=49291 done
[2022-09-18T21:59:08.052] _job_complete: JobId=49293 WEXITSTATUS 130
[2022-09-18T21:59:08.052] _job_complete: JobId=49293 done
[2022-09-18T22:01:45.120] _slurm_rpc_submit_batch_job: JobId=49294 InitPrio=8295 usec=377
[2022-09-18T22:06:17.781] _slurm_rpc_kill_job: REQUEST_KILL_JOB JobId=49290 uid 548300544
[2022-09-18T22:06:32.741] sched: Allocate JobId=49294 NodeList=cpu13 #CPUs=48 Partition=cpu-epyc
[2022-09-18T22:06:37.420] _slurm_rpc_kill_job: REQUEST_KILL_JOB JobId=49294 uid 548300544
[2022-09-18T22:07:44.368] _slurm_rpc_submit_batch_job: JobId=49295 InitPrio=8295 usec=383
[2022-09-18T22:07:44.844] sched: Allocate JobId=49295 NodeList=cpu13 #CPUs=48 Partition=cpu-epyc
[2022-09-18T23:07:16.815] _job_complete: JobId=49295 WEXITSTATUS 0
[2022-09-18T23:07:16.816] _job_complete: JobId=49295 done
[2022-09-18T23:22:21.121] _job_complete: JobId=49284 WEXITSTATUS 1
[2022-09-18T23:22:21.126] _job_complete: JobId=49284 done
[2022-09-18T23:22:21.733] sched: Allocate JobId=49285 NodeList=gpu03 #CPUs=16 Partition=gpu-k10
[2022-09-18T23:32:43.382] _slurm_rpc_submit_batch_job: JobId=49296 InitPrio=3363 usec=527
[2022-09-18T23:32:43.857] sched: Allocate JobId=49296 NodeList=cpu03 #CPUs=16 Partition=cpu-opteron
[2022-09-19T05:17:13.367] _job_complete: JobId=49283 WEXITSTATUS 1
[2022-09-19T05:17:13.373] _job_complete: JobId=49283 done
[2022-09-19T05:17:14.601] sched: Allocate JobId=49286 NodeList=gpu01 #CPUs=16 Partition=gpu-k10
[2022-09-19T09:21:27.233] _job_create: exceeded association/QOS limit for user 548200045: AssocGrpCpuLimit
[2022-09-19T09:21:27.233] _slurm_rpc_submit_batch_job: Job violates accounting/QOS policy (job submit limit, user's size and/or time limits)
[2022-09-19T09:28:10.125] _slurm_rpc_submit_batch_job: JobId=49297 InitPrio=672 usec=509
[2022-09-19T09:28:10.656] sched: Allocate JobId=49297 NodeList=cpu13 #CPUs=48 Partition=cpu-epyc
[2022-09-19T09:59:57.931] _slurm_rpc_submit_batch_job: JobId=49298 InitPrio=672 usec=577
[2022-09-19T11:00:15.997] _slurm_rpc_submit_batch_job: JobId=49299 InitPrio=3587 usec=489
[2022-09-19T11:00:16.804] sched: Allocate JobId=49299 NodeList=cpu12 #CPUs=16 Partition=cpu-epyc
[2022-09-19T11:00:17.979] _slurm_rpc_submit_batch_job: JobId=49300 InitPrio=3587 usec=471
[2022-09-19T11:00:20.348] _slurm_rpc_submit_batch_job: JobId=49301 InitPrio=3587 usec=460
[2022-09-19T11:00:21.826] _slurm_rpc_submit_batch_job: JobId=49302 InitPrio=3587 usec=424
[2022-09-19T11:00:23.223] _slurm_rpc_submit_batch_job: JobId=49303 InitPrio=3587 usec=556
[2022-09-19T11:00:24.715] _slurm_rpc_submit_batch_job: JobId=49304 InitPrio=3587 usec=490
[2022-09-19T11:00:26.099] _slurm_rpc_submit_batch_job: JobId=49305 InitPrio=3587 usec=551
[2022-09-19T11:00:27.475] _slurm_rpc_submit_batch_job: JobId=49306 InitPrio=3587 usec=403
[2022-09-19T11:00:29.859] _slurm_rpc_submit_batch_job: JobId=49307 InitPrio=3587 usec=548
[2022-09-19T11:18:26.621] _slurm_rpc_submit_batch_job: JobId=49308 InitPrio=3587 usec=549
[2022-09-19T11:18:28.191] _slurm_rpc_submit_batch_job: JobId=49309 InitPrio=3587 usec=454
[2022-09-19T11:18:29.668] _slurm_rpc_submit_batch_job: JobId=49310 InitPrio=3587 usec=1196
[2022-09-19T11:18:31.011] _slurm_rpc_submit_batch_job: JobId=49311 InitPrio=3587 usec=453
[2022-09-19T11:18:32.357] _slurm_rpc_submit_batch_job: JobId=49312 InitPrio=3587 usec=424
[2022-09-19T11:18:33.792] _slurm_rpc_submit_batch_job: JobId=49313 InitPrio=3587 usec=415
[2022-09-19T11:18:35.157] _slurm_rpc_submit_batch_job: JobId=49314 InitPrio=3587 usec=476
[2022-09-19T11:18:36.550] _slurm_rpc_submit_batch_job: JobId=49315 InitPrio=3587 usec=449
[2022-09-19T11:18:38.381] _slurm_rpc_submit_batch_job: JobId=49316 InitPrio=3587 usec=512
[2022-09-19T11:18:40.845] _slurm_rpc_submit_batch_job: JobId=49317 InitPrio=3587 usec=434
[2022-09-19T11:41:41.504] _slurm_rpc_submit_batch_job: JobId=49318 InitPrio=3587 usec=487
[2022-09-19T11:41:43.782] _slurm_rpc_submit_batch_job: JobId=49319 InitPrio=3587 usec=496
[2022-09-19T11:41:45.278] _slurm_rpc_submit_batch_job: JobId=49320 InitPrio=3587 usec=431
[2022-09-19T11:41:46.686] _slurm_rpc_submit_batch_job: JobId=49321 InitPrio=3587 usec=664
[2022-09-19T11:41:48.038] _slurm_rpc_submit_batch_job: JobId=49322 InitPrio=3587 usec=493
[2022-09-19T11:41:49.422] _slurm_rpc_submit_batch_job: JobId=49323 InitPrio=3587 usec=418
[2022-09-19T11:41:50.782] _slurm_rpc_submit_batch_job: JobId=49324 InitPrio=3587 usec=553
[2022-09-19T11:41:52.478] _slurm_rpc_submit_batch_job: JobId=49325 InitPrio=3587 usec=460
[2022-09-19T11:41:54.118] _slurm_rpc_submit_batch_job: JobId=49326 InitPrio=3587 usec=480
[2022-09-19T11:41:56.798] _slurm_rpc_submit_batch_job: JobId=49327 InitPrio=3587 usec=387
[2022-09-19T12:00:49.828] _slurm_rpc_submit_batch_job: JobId=49328 InitPrio=3587 usec=486
[2022-09-19T12:00:51.704] _slurm_rpc_submit_batch_job: JobId=49329 InitPrio=3587 usec=528
[2022-09-19T12:00:53.079] _slurm_rpc_submit_batch_job: JobId=49330 InitPrio=3587 usec=503
[2022-09-19T12:00:54.455] _slurm_rpc_submit_batch_job: JobId=49331 InitPrio=3587 usec=568
[2022-09-19T12:00:55.911] _slurm_rpc_submit_batch_job: JobId=49332 InitPrio=3587 usec=449
[2022-09-19T12:00:57.303] _slurm_rpc_submit_batch_job: JobId=49333 InitPrio=3587 usec=413
[2022-09-19T12:00:59.144] _slurm_rpc_submit_batch_job: JobId=49334 InitPrio=3587 usec=673
[2022-09-19T12:01:00.703] _slurm_rpc_submit_batch_job: JobId=49335 InitPrio=3587 usec=420
[2022-09-19T12:01:02.162] _slurm_rpc_submit_batch_job: JobId=49336 InitPrio=3587 usec=443
[2022-09-19T12:01:04.559] _slurm_rpc_submit_batch_job: JobId=49337 InitPrio=3587 usec=424
[2022-09-19T12:16:34.227] _slurm_rpc_submit_batch_job: JobId=49338 InitPrio=672 usec=535
[2022-09-19T12:16:36.029] sched: Allocate JobId=49338 NodeList=cpu03 #CPUs=16 Partition=cpu-opteron
[2022-09-19T12:16:37.786] _job_complete: JobId=49338 WEXITSTATUS 1
[2022-09-19T12:16:37.786] _job_complete: JobId=49338 done
[2022-09-19T12:17:20.157] _slurm_rpc_submit_batch_job: JobId=49339 InitPrio=672 usec=480
[2022-09-19T12:17:21.070] sched: Allocate JobId=49339 NodeList=cpu04 #CPUs=32 Partition=cpu-opteron
[2022-09-19T12:17:23.297] _job_complete: JobId=49339 WEXITSTATUS 1
[2022-09-19T12:17:23.297] _job_complete: JobId=49339 done
[2022-09-19T12:18:19.167] _slurm_rpc_submit_batch_job: JobId=49340 InitPrio=672 usec=527
[2022-09-19T12:18:19.260] sched: Allocate JobId=49340 NodeList=cpu04 #CPUs=32 Partition=cpu-opteron
[2022-09-19T12:21:17.012] _job_complete: JobId=49340 WEXITSTATUS 0
[2022-09-19T12:21:17.013] _job_complete: JobId=49340 done
[2022-09-19T12:21:43.046] _slurm_rpc_submit_batch_job: JobId=49341 InitPrio=672 usec=490
[2022-09-19T12:21:43.537] sched: Allocate JobId=49341 NodeList=cpu04 #CPUs=64 Partition=cpu-opteron
[2022-09-19T12:23:40.999] _slurm_rpc_submit_batch_job: JobId=49342 InitPrio=672 usec=467
[2022-09-19T12:23:41.822] sched: Allocate JobId=49342 NodeList=cpu05 #CPUs=32 Partition=cpu-opteron
[2022-09-19T12:24:23.529] _slurm_rpc_submit_batch_job: JobId=49343 InitPrio=672 usec=417
[2022-09-19T12:24:23.872] sched: Allocate JobId=49343 NodeList=cpu05 #CPUs=32 Partition=cpu-opteron
[2022-09-19T12:24:38.892] _slurm_rpc_kill_job: REQUEST_KILL_JOB JobId=49343 uid 548200023
[2022-09-19T12:26:43.409] _job_complete: JobId=49342 WEXITSTATUS 0
[2022-09-19T12:26:43.410] _job_complete: JobId=49342 done
[2022-09-19T12:26:52.458] _slurm_rpc_submit_batch_job: JobId=49344 InitPrio=672 usec=564
[2022-09-19T12:26:53.082] sched: Allocate JobId=49344 NodeList=cpu05 #CPUs=32 Partition=cpu-opteron
[2022-09-19T12:28:50.600] _slurm_rpc_submit_batch_job: JobId=49345 InitPrio=672 usec=499
[2022-09-19T12:28:51.359] sched: Allocate JobId=49345 NodeList=cpu05 #CPUs=32 Partition=cpu-opteron
[2022-09-19T12:31:57.816] _job_complete: JobId=49345 WEXITSTATUS 0
[2022-09-19T12:31:57.816] _job_complete: JobId=49345 done
[2022-09-19T12:33:29.884] _slurm_rpc_submit_batch_job: JobId=49346 InitPrio=672 usec=428
[2022-09-19T12:33:30.843] sched: Allocate JobId=49346 NodeList=cpu05 #CPUs=32 Partition=cpu-opteron
[2022-09-19T12:35:22.093] _slurm_rpc_submit_batch_job: JobId=49347 InitPrio=672 usec=409
[2022-09-19T12:35:51.055] _slurm_rpc_kill_job: REQUEST_KILL_JOB JobId=49347 uid 548200023
[2022-09-19T12:36:23.328] _slurm_rpc_submit_batch_job: JobId=49348 InitPrio=672 usec=379
[2022-09-19T12:36:24.083] sched: Allocate JobId=49348 NodeList=gpu02 #CPUs=2 Partition=gpu-titan
[2022-09-19T12:38:50.921] _job_complete: JobId=49348 WEXITSTATUS 0
[2022-09-19T12:38:50.921] _job_complete: JobId=49348 done
[2022-09-19T12:40:49.591] _slurm_rpc_submit_batch_job: JobId=49349 InitPrio=672 usec=419
[2022-09-19T12:49:33.943] _job_complete: JobId=49341 WEXITSTATUS 0
[2022-09-19T12:49:33.943] _job_complete: JobId=49341 done
[2022-09-19T12:49:36.180] sched: Allocate JobId=49349 NodeList=cpu04 #CPUs=32 Partition=cpu-opteron
[2022-09-19T13:17:51.857] _job_complete: JobId=49344 WEXITSTATUS 0
[2022-09-19T13:17:51.857] _job_complete: JobId=49344 done
[2022-09-19T13:25:34.066] _job_complete: JobId=49346 WEXITSTATUS 0
[2022-09-19T13:25:34.066] _job_complete: JobId=49346 done
[2022-09-19T13:40:30.084] _job_complete: JobId=49349 WEXITSTATUS 0
[2022-09-19T13:40:30.085] _job_complete: JobId=49349 done
[2022-09-19T13:55:07.916] _slurm_rpc_submit_batch_job: JobId=49350 InitPrio=3587 usec=516
[2022-09-19T13:55:09.931] _slurm_rpc_submit_batch_job: JobId=49351 InitPrio=3587 usec=501
[2022-09-19T13:55:11.747] _slurm_rpc_submit_batch_job: JobId=49352 InitPrio=3587 usec=435
[2022-09-19T13:55:13.298] _slurm_rpc_submit_batch_job: JobId=49353 InitPrio=3587 usec=434
[2022-09-19T13:55:14.731] _slurm_rpc_submit_batch_job: JobId=49354 InitPrio=3587 usec=565
[2022-09-19T13:55:16.142] _slurm_rpc_submit_batch_job: JobId=49355 InitPrio=3587 usec=542
[2022-09-19T13:55:17.675] _slurm_rpc_submit_batch_job: JobId=49356 InitPrio=3587 usec=465
[2022-09-19T13:55:19.051] _slurm_rpc_submit_batch_job: JobId=49357 InitPrio=3587 usec=495
[2022-09-19T13:55:20.579] _slurm_rpc_submit_batch_job: JobId=49358 InitPrio=3587 usec=504
[2022-09-19T13:55:22.820] _slurm_rpc_submit_batch_job: JobId=49359 InitPrio=3587 usec=595
[2022-09-19T13:55:24.817] _slurm_rpc_submit_batch_job: JobId=49360 InitPrio=3587 usec=413
[2022-09-19T13:55:26.419] _slurm_rpc_submit_batch_job: JobId=49361 InitPrio=3587 usec=544
[2022-09-19T13:55:28.219] _slurm_rpc_submit_batch_job: JobId=49362 InitPrio=3587 usec=420
[2022-09-19T14:45:23.392] _slurm_rpc_submit_batch_job: JobId=49363 InitPrio=17847 usec=444
[2022-09-19T14:45:49.213] _slurm_rpc_submit_batch_job: JobId=49364 InitPrio=17847 usec=439
[2022-09-19T15:45:18.958] _job_complete: JobId=49299 WEXITSTATUS 0
[2022-09-19T15:45:18.958] _job_complete: JobId=49299 done
[2022-09-19T15:45:19.372] sched: Allocate JobId=49300 NodeList=cpu12 #CPUs=16 Partition=cpu-epyc
[2022-09-19T16:10:56.350] _slurm_rpc_submit_batch_job: JobId=49365 InitPrio=1569 usec=526
[2022-09-19T16:17:04.414] _slurm_rpc_submit_batch_job: JobId=49366 InitPrio=3139 usec=454
[2022-09-19T16:17:07.843] _slurm_rpc_submit_batch_job: JobId=49367 InitPrio=3139 usec=553
[2022-09-19T16:17:09.978] _slurm_rpc_submit_batch_job: JobId=49368 InitPrio=3139 usec=494
[2022-09-19T16:17:12.013] _slurm_rpc_submit_batch_job: JobId=49369 InitPrio=3139 usec=455
[2022-09-19T16:17:14.491] _slurm_rpc_submit_batch_job: JobId=49370 InitPrio=3139 usec=574
[2022-09-19T16:17:16.474] _slurm_rpc_submit_batch_job: JobId=49371 InitPrio=3139 usec=648
[2022-09-19T16:17:18.378] _slurm_rpc_submit_batch_job: JobId=49372 InitPrio=3139 usec=555
[2022-09-19T16:17:20.386] _slurm_rpc_submit_batch_job: JobId=49373 InitPrio=3139 usec=545
[2022-09-19T16:17:22.842] _slurm_rpc_submit_batch_job: JobId=49374 InitPrio=3139 usec=442
[2022-09-19T16:17:29.780] _slurm_rpc_submit_batch_job: JobId=49375 InitPrio=3139 usec=453
[2022-09-19T16:17:35.555] _slurm_rpc_submit_batch_job: JobId=49376 InitPrio=3139 usec=483
[2022-09-19T16:17:37.217] _slurm_rpc_submit_batch_job: JobId=49377 InitPrio=3139 usec=410
[2022-09-19T16:17:39.074] _slurm_rpc_submit_batch_job: JobId=49378 InitPrio=3139 usec=419
[2022-09-19T16:17:41.065] _slurm_rpc_submit_batch_job: JobId=49379 InitPrio=3139 usec=420
[2022-09-19T16:17:44.202] _slurm_rpc_submit_batch_job: JobId=49380 InitPrio=3139 usec=419
[2022-09-19T17:50:39.327] sched: _slurm_rpc_allocate_resources JobId=49381 NodeList=(null) usec=976
[2022-09-19T17:50:39.851] sched: Allocate JobId=49381 NodeList=cpu11 #CPUs=1 Partition=cpu-opteron
[2022-09-19T18:04:40.925] _slurm_rpc_submit_batch_job: JobId=49382 InitPrio=896 usec=518
[2022-09-19T18:04:41.374] sched: Allocate JobId=49382 NodeList=cpu04 #CPUs=64 Partition=cpu-opteron
[2022-09-19T19:01:32.355] Time limit exhausted for JobId=48978
[2022-09-19T19:01:35.569] sched: Allocate JobId=49301 NodeList=cpu14 #CPUs=16 Partition=cpu-epyc
[2022-09-19T19:01:35.570] sched: Allocate JobId=49302 NodeList=cpu14 #CPUs=16 Partition=cpu-epyc
[2022-09-19T19:01:35.570] sched: Allocate JobId=49303 NodeList=cpu14 #CPUs=16 Partition=cpu-epyc
[2022-09-19T19:15:02.992] _job_complete: JobId=49381 WEXITSTATUS 0
[2022-09-19T19:15:02.992] _job_complete: JobId=49381 done
[2022-09-19T19:20:03.658] cleanup_completing: JobId=49381 completion process took 301 seconds
[2022-09-19T21:15:45.270] _job_complete: JobId=49300 WEXITSTATUS 1
[2022-09-19T21:15:45.270] _job_complete: JobId=49300 done
[2022-09-19T21:15:46.299] sched: Allocate JobId=49304 NodeList=cpu12 #CPUs=16 Partition=cpu-epyc
[2022-09-19T21:50:13.250] _job_complete: JobId=49188 WEXITSTATUS 0
[2022-09-19T21:50:13.255] _job_complete: JobId=49188 done
[2022-09-19T21:50:15.251] sched: Allocate JobId=49305 NodeList=cpu12 #CPUs=16 Partition=cpu-epyc
[2022-09-19T21:50:15.252] sched: Allocate JobId=49306 NodeList=cpu12 #CPUs=16 Partition=cpu-epyc
[2022-09-19T23:33:04.763] Time limit exhausted for JobId=49296
[2022-09-20T00:22:13.951] _job_complete: JobId=49301 WEXITSTATUS 0
[2022-09-20T00:22:13.951] _job_complete: JobId=49301 done
[2022-09-20T00:22:14.504] sched: Allocate JobId=49307 NodeList=cpu14 #CPUs=16 Partition=cpu-epyc
[2022-09-20T00:33:22.457] _job_complete: JobId=49302 WEXITSTATUS 0
[2022-09-20T00:33:22.457] _job_complete: JobId=49302 done
[2022-09-20T00:33:23.064] sched: Allocate JobId=49308 NodeList=cpu14 #CPUs=16 Partition=cpu-epyc
[2022-09-20T01:09:44.227] _job_complete: JobId=49303 WEXITSTATUS 0
[2022-09-20T01:09:44.228] _job_complete: JobId=49303 done
[2022-09-20T01:09:44.832] sched: Allocate JobId=49309 NodeList=cpu14 #CPUs=16 Partition=cpu-epyc
[2022-09-20T03:34:53.010] _slurm_rpc_submit_batch_job: JobId=49383 InitPrio=3587 usec=683
[2022-09-20T03:34:53.264] sched: Allocate JobId=49383 NodeList=cpu03 #CPUs=20 Partition=cpu-opteron
[2022-09-20T04:05:13.779] _job_complete: JobId=49304 WEXITSTATUS 0
[2022-09-20T04:05:13.779] _job_complete: JobId=49304 done
[2022-09-20T04:05:14.202] sched: Allocate JobId=49366 NodeList=cpu12 #CPUs=8 Partition=cpu-epyc
[2022-09-20T04:05:14.203] sched: Allocate JobId=49367 NodeList=cpu12 #CPUs=8 Partition=cpu-epyc
[2022-09-20T05:08:45.519] _job_complete: JobId=49306 WEXITSTATUS 0
[2022-09-20T05:08:45.520] _job_complete: JobId=49306 done
[2022-09-20T05:08:46.007] sched: Allocate JobId=49368 NodeList=cpu12 #CPUs=8 Partition=cpu-epyc
[2022-09-20T05:08:46.008] sched: Allocate JobId=49369 NodeList=cpu12 #CPUs=8 Partition=cpu-epyc
[2022-09-20T05:20:44.851] _job_complete: JobId=49305 WEXITSTATUS 0
[2022-09-20T05:20:44.851] _job_complete: JobId=49305 done
[2022-09-20T05:20:45.211] sched: Allocate JobId=49370 NodeList=cpu12 #CPUs=8 Partition=cpu-epyc
[2022-09-20T05:20:45.212] sched: Allocate JobId=49371 NodeList=cpu12 #CPUs=8 Partition=cpu-epyc
[2022-09-20T06:17:18.002] _job_complete: JobId=49308 WEXITSTATUS 0
[2022-09-20T06:17:18.002] _job_complete: JobId=49308 done
[2022-09-20T06:17:18.546] sched: Allocate JobId=49372 NodeList=cpu14 #CPUs=8 Partition=cpu-epyc
[2022-09-20T06:17:18.546] sched: Allocate JobId=49373 NodeList=cpu14 #CPUs=8 Partition=cpu-epyc
[2022-09-20T06:57:42.249] _job_complete: JobId=49382 WEXITSTATUS 0
[2022-09-20T06:57:42.249] _job_complete: JobId=49382 done
[2022-09-20T07:24:34.026] _job_complete: JobId=49307 WEXITSTATUS 0
[2022-09-20T07:24:34.026] _job_complete: JobId=49307 done
[2022-09-20T07:24:34.613] sched: Allocate JobId=49374 NodeList=cpu14 #CPUs=8 Partition=cpu-epyc
[2022-09-20T07:24:34.614] sched: Allocate JobId=49375 NodeList=cpu14 #CPUs=8 Partition=cpu-epyc
[2022-09-20T07:27:34.502] Time limit exhausted for JobId=49019
[2022-09-20T09:01:41.775] _job_complete: JobId=49309 WEXITSTATUS 0
[2022-09-20T09:01:41.775] _job_complete: JobId=49309 done
[2022-09-20T09:01:42.433] sched: Allocate JobId=49310 NodeList=cpu14 #CPUs=16 Partition=cpu-epyc
[2022-09-20T09:39:53.758] _job_complete: JobId=49286 WEXITSTATUS 0
[2022-09-20T09:39:53.764] _job_complete: JobId=49286 done
[2022-09-20T09:39:56.703] sched: Allocate JobId=49287 NodeList=gpu01 #CPUs=16 Partition=gpu-k10
[2022-09-20T09:43:34.589] sched: _slurm_rpc_allocate_resources JobId=49384 NodeList=(null) usec=1157
[2022-09-20T09:43:37.337] sched: Allocate JobId=49384 NodeList=cpu11 #CPUs=1 Partition=cpu-opteron
[2022-09-20T09:44:34.575] _job_complete: JobId=49366 WEXITSTATUS 0
[2022-09-20T09:44:34.576] _job_complete: JobId=49366 done
[2022-09-20T09:44:41.382] sched/backfill: _start_job: Started JobId=49376 in cpu-epyc on cpu12
[2022-09-20T10:10:35.671] _job_complete: JobId=49367 WEXITSTATUS 0
[2022-09-20T10:10:35.671] _job_complete: JobId=49367 done
[2022-09-20T10:10:41.429] sched/backfill: _start_job: Started JobId=49377 in cpu-epyc on cpu12
[2022-09-20T10:19:46.666] _slurm_rpc_submit_batch_job: JobId=49385 InitPrio=672 usec=522
[2022-09-20T10:19:47.562] sched: Allocate JobId=49385 NodeList=cpu01 #CPUs=32 Partition=cpu-opteron
[2022-09-20T10:19:49.832] _job_complete: JobId=49385 WEXITSTATUS 127
[2022-09-20T10:19:49.832] _job_complete: JobId=49385 done
[2022-09-20T10:20:14.822] _slurm_rpc_submit_batch_job: JobId=49386 InitPrio=672 usec=427
[2022-09-20T10:20:15.582] sched: Allocate JobId=49386 NodeList=cpu01 #CPUs=32 Partition=cpu-opteron
[2022-09-20T10:20:16.955] _job_complete: JobId=49386 WEXITSTATUS 1
[2022-09-20T10:20:16.955] _job_complete: JobId=49386 done
[2022-09-20T10:25:58.659] _slurm_rpc_submit_batch_job: JobId=49387 InitPrio=672 usec=489
[2022-09-20T10:25:59.179] sched: Allocate JobId=49387 NodeList=cpu01 #CPUs=32 Partition=cpu-opteron
[2022-09-20T10:26:00.486] _job_complete: JobId=49387 WEXITSTATUS 1
[2022-09-20T10:26:00.486] _job_complete: JobId=49387 done
[2022-09-20T10:27:53.280] _job_complete: JobId=49370 WEXITSTATUS 0
[2022-09-20T10:27:53.280] _job_complete: JobId=49370 done
[2022-09-20T10:28:41.463] sched/backfill: _start_job: Started JobId=49378 in cpu-epyc on cpu12
[2022-09-20T10:28:58.573] _job_complete: JobId=49369 WEXITSTATUS 0
[2022-09-20T10:28:58.574] _job_complete: JobId=49369 done
[2022-09-20T10:29:41.466] sched/backfill: _start_job: Started JobId=49379 in cpu-epyc on cpu12
[2022-09-20T10:36:48.207] _slurm_rpc_submit_batch_job: JobId=49388 InitPrio=672 usec=404
[2022-09-20T10:36:48.341] sched: Allocate JobId=49388 NodeList=cpu01 #CPUs=32 Partition=cpu-opteron
[2022-09-20T10:36:49.491] _job_complete: JobId=49388 WEXITSTATUS 139
[2022-09-20T10:36:49.492] _job_complete: JobId=49388 done
[2022-09-20T10:41:40.769] _slurm_rpc_submit_batch_job: JobId=49389 InitPrio=672 usec=490
[2022-09-20T10:41:40.808] sched: Allocate JobId=49389 NodeList=cpu01 #CPUs=32 Partition=cpu-opteron
[2022-09-20T10:41:42.337] _job_complete: JobId=49389 WEXITSTATUS 139
[2022-09-20T10:41:42.337] _job_complete: JobId=49389 done
[2022-09-20T10:41:54.215] _slurm_rpc_submit_batch_job: JobId=49390 InitPrio=3363 usec=407
[2022-09-20T10:42:15.954] _slurm_rpc_submit_batch_job: JobId=49391 InitPrio=672 usec=425
[2022-09-20T10:42:16.858] sched: Allocate JobId=49391 NodeList=cpu01 #CPUs=32 Partition=cpu-opteron
[2022-09-20T10:42:17.939] _job_complete: JobId=49391 WEXITSTATUS 139
[2022-09-20T10:42:17.939] _job_complete: JobId=49391 done
[2022-09-20T10:45:39.231] _slurm_rpc_submit_batch_job: JobId=49392 InitPrio=672 usec=429
[2022-09-20T10:45:39.282] sched: Allocate JobId=49392 NodeList=cpu01 #CPUs=32 Partition=cpu-opteron
[2022-09-20T10:45:40.432] _job_complete: JobId=49392 WEXITSTATUS 139
[2022-09-20T10:45:40.432] _job_complete: JobId=49392 done
[2022-09-20T10:52:45.016] _job_complete: JobId=49368 WEXITSTATUS 0
[2022-09-20T10:52:45.016] _job_complete: JobId=49368 done
[2022-09-20T10:53:41.509] sched/backfill: _start_job: Started JobId=49380 in cpu-epyc on cpu12
[2022-09-20T11:11:48.055] _job_complete: JobId=49371 WEXITSTATUS 0
[2022-09-20T11:11:48.055] _job_complete: JobId=49371 done
[2022-09-20T11:19:44.757] _slurm_rpc_kill_job: REQUEST_KILL_JOB JobId=49383 uid 548200110
[2022-09-20T11:49:50.929] _job_complete: JobId=49384 WEXITSTATUS 130
[2022-09-20T11:49:50.929] _job_complete: JobId=49384 done
[2022-09-20T11:50:09.215] _slurm_rpc_submit_batch_job: JobId=49393 InitPrio=8520 usec=458
[2022-09-20T11:50:10.204] sched: Allocate JobId=49393 NodeList=cpu11 #CPUs=1 Partition=cpu-opteron
[2022-09-20T11:50:15.108] _job_complete: JobId=49393 WEXITSTATUS 0
[2022-09-20T11:50:15.108] _job_complete: JobId=49393 done
[2022-09-20T12:01:13.689] _slurm_rpc_submit_batch_job: JobId=49394 InitPrio=672 usec=597
[2022-09-20T12:01:14.406] sched: Allocate JobId=49394 NodeList=cpu03 #CPUs=32 Partition=cpu-opteron
[2022-09-20T12:01:16.052] _job_complete: JobId=49394 WEXITSTATUS 139
[2022-09-20T12:01:16.052] _job_complete: JobId=49394 done
[2022-09-20T12:17:16.160] _job_complete: JobId=49373 WEXITSTATUS 0
[2022-09-20T12:17:16.160] _job_complete: JobId=49373 done
[2022-09-20T12:19:18.830] _slurm_rpc_submit_batch_job: JobId=49395 InitPrio=672 usec=513
[2022-09-20T12:19:19.288] sched: Allocate JobId=49395 NodeList=cpu03 #CPUs=32 Partition=cpu-opteron
[2022-09-20T12:19:20.313] _job_complete: JobId=49395 WEXITSTATUS 127
[2022-09-20T12:19:20.313] _job_complete: JobId=49395 done
[2022-09-20T12:19:52.962] _slurm_rpc_submit_batch_job: JobId=49396 InitPrio=672 usec=454
[2022-09-20T12:19:53.330] sched: Allocate JobId=49396 NodeList=cpu03 #CPUs=32 Partition=cpu-opteron
[2022-09-20T12:19:54.486] _job_complete: JobId=49396 WEXITSTATUS 1
[2022-09-20T12:19:54.486] _job_complete: JobId=49396 done
[2022-09-20T12:49:45.378] _slurm_rpc_submit_batch_job: JobId=49397 InitPrio=2017 usec=970
[2022-09-20T12:50:40.812] _slurm_rpc_submit_batch_job: JobId=49398 InitPrio=2017 usec=980
[2022-09-20T13:06:52.728] _job_complete: JobId=49372 WEXITSTATUS 0
[2022-09-20T13:06:52.728] _job_complete: JobId=49372 done
[2022-09-20T13:06:53.371] sched: Allocate JobId=49311 NodeList=cpu14 #CPUs=16 Partition=cpu-epyc
[2022-09-20T13:08:29.320] _job_complete: JobId=49375 WEXITSTATUS 0
[2022-09-20T13:08:29.321] _job_complete: JobId=49375 done
[2022-09-20T13:09:23.954] _slurm_rpc_submit_batch_job: JobId=49399 InitPrio=2017 usec=455
[2022-09-20T13:09:24.636] sched: Allocate JobId=49399 NodeList=cpu03 #CPUs=16 Partition=cpu-opteron
[2022-09-20T13:10:00.901] _slurm_rpc_submit_batch_job: JobId=49400 InitPrio=2017 usec=588
[2022-09-20T13:10:01.668] sched: Allocate JobId=49400 NodeList=cpu03 #CPUs=16 Partition=cpu-opteron
[2022-09-20T13:11:40.800] _job_complete: JobId=49374 WEXITSTATUS 0
[2022-09-20T13:11:40.800] _job_complete: JobId=49374 done
[2022-09-20T13:11:41.307] sched: Allocate JobId=49312 NodeList=cpu14 #CPUs=16 Partition=cpu-epyc
[2022-09-20T13:13:22.941] _job_complete: JobId=49400 WEXITSTATUS 0
[2022-09-20T13:13:22.941] _job_complete: JobId=49400 done
[2022-09-20T13:13:48.542] _job_complete: JobId=49399 WEXITSTATUS 0
[2022-09-20T13:13:48.542] _job_complete: JobId=49399 done
[2022-09-20T13:51:14.051] _slurm_rpc_submit_batch_job: JobId=49401 InitPrio=2017 usec=501
[2022-09-20T13:51:14.983] sched: Allocate JobId=49401 NodeList=cpu03 #CPUs=8 Partition=cpu-opteron
[2022-09-20T14:22:49.259] _job_complete: JobId=49287 WEXITSTATUS 0
[2022-09-20T14:22:49.260] _job_complete: JobId=49287 done
[2022-09-20T14:22:52.062] sched: Allocate JobId=49397 NodeList=gpu01 #CPUs=16 Partition=gpu-k10
[2022-09-20T15:07:02.163] _job_complete: JobId=49310 WEXITSTATUS 0
[2022-09-20T15:07:02.163] _job_complete: JobId=49310 done
[2022-09-20T15:07:02.744] sched: Allocate JobId=49313 NodeList=cpu14 #CPUs=16 Partition=cpu-epyc
[2022-09-20T15:22:17.685] _job_complete: JobId=49378 WEXITSTATUS 0
[2022-09-20T15:22:17.685] _job_complete: JobId=49378 done
[2022-09-20T15:22:18.093] sched: Allocate JobId=49314 NodeList=cpu12 #CPUs=16 Partition=cpu-epyc
[2022-09-20T15:44:49.243] _job_complete: JobId=49379 WEXITSTATUS 0
[2022-09-20T15:44:49.243] _job_complete: JobId=49379 done
[2022-09-20T15:46:00.947] _job_complete: JobId=49376 WEXITSTATUS 0
[2022-09-20T15:46:00.948] _job_complete: JobId=49376 done
[2022-09-20T15:46:01.276] sched: Allocate JobId=49315 NodeList=cpu12 #CPUs=16 Partition=cpu-epyc
[2022-09-20T15:58:42.303] _job_complete: JobId=49377 WEXITSTATUS 0
[2022-09-20T15:58:42.303] _job_complete: JobId=49377 done
[2022-09-20T16:19:25.916] _slurm_rpc_submit_batch_job: JobId=49402 InitPrio=1116 usec=558
[2022-09-20T16:19:26.686] sched: Allocate JobId=49402 NodeList=cpu01 #CPUs=64 Partition=cpu-opteron
[2022-09-20T16:31:00.997] _job_complete: JobId=49380 WEXITSTATUS 0
[2022-09-20T16:31:00.997] _job_complete: JobId=49380 done
[2022-09-20T16:31:01.408] sched: Allocate JobId=49316 NodeList=cpu12 #CPUs=16 Partition=cpu-epyc
[2022-09-20T17:20:58.059] _job_complete: JobId=49397 WEXITSTATUS 1
[2022-09-20T17:20:58.102] _job_complete: JobId=49397 done
[2022-09-20T17:20:59.459] sched: Allocate JobId=49398 NodeList=gpu01 #CPUs=16 Partition=gpu-k10
[2022-09-20T17:38:37.504] _job_complete: JobId=49401 WEXITSTATUS 0
[2022-09-20T17:38:37.505] _job_complete: JobId=49401 done
[2022-09-20T18:16:05.670] Time limit exhausted for JobId=49067
[2022-09-20T18:16:20.654] _slurm_rpc_submit_batch_job: JobId=49403 InitPrio=669 usec=643
[2022-09-20T18:16:20.713] sched: Allocate JobId=49403 NodeList=gpu02 #CPUs=5 Partition=gpu-titan
[2022-09-20T18:17:17.423] _slurm_rpc_submit_batch_job: JobId=49404 InitPrio=669 usec=524
[2022-09-20T18:17:35.761] _slurm_rpc_kill_job: REQUEST_KILL_JOB JobId=49404 uid 548200023
[2022-09-20T18:17:38.936] _job_complete: JobId=49311 WEXITSTATUS 0
[2022-09-20T18:17:38.936] _job_complete: JobId=49311 done
[2022-09-20T18:17:39.628] sched: Allocate JobId=49317 NodeList=cpu14 #CPUs=16 Partition=cpu-epyc
[2022-09-20T18:17:48.720] _slurm_rpc_submit_batch_job: JobId=49405 InitPrio=669 usec=493
[2022-09-20T18:18:20.018] _slurm_rpc_kill_job: REQUEST_KILL_JOB JobId=49405 uid 548200023
[2022-09-20T18:18:24.775] _slurm_rpc_submit_batch_job: JobId=49406 InitPrio=669 usec=546
[2022-09-20T18:19:54.076] _slurm_rpc_submit_batch_job: JobId=49407 InitPrio=669 usec=405
[2022-09-20T18:19:54.077] sched: Allocate JobId=49407 NodeList=cpu03 #CPUs=32 Partition=cpu-opteron
[2022-09-20T18:20:05.091] Time limit exhausted for JobId=48949
[2022-09-20T18:25:23.596] _job_complete: JobId=49407 WEXITSTATUS 0
[2022-09-20T18:25:23.596] _job_complete: JobId=49407 done
[2022-09-20T18:25:40.485] _slurm_rpc_submit_batch_job: JobId=49408 InitPrio=669 usec=429
[2022-09-20T18:25:40.665] sched: Allocate JobId=49408 NodeList=cpu03 #CPUs=2 Partition=cpu-opteron
[2022-09-20T18:25:42.833] _job_complete: JobId=49408 WEXITSTATUS 0
[2022-09-20T18:25:42.833] _job_complete: JobId=49408 done
[2022-09-20T18:27:41.631] _slurm_rpc_submit_batch_job: JobId=49409 InitPrio=669 usec=429
[2022-09-20T18:27:41.832] sched: Allocate JobId=49409 NodeList=cpu03 #CPUs=32 Partition=cpu-opteron
[2022-09-20T18:32:33.763] _slurm_rpc_submit_batch_job: JobId=49410 InitPrio=669 usec=474
[2022-09-20T18:32:34.322] sched: Allocate JobId=49410 NodeList=cpu04 #CPUs=16 Partition=cpu-opteron
[2022-09-20T18:33:04.290] _job_complete: JobId=49409 WEXITSTATUS 0
[2022-09-20T18:33:04.290] _job_complete: JobId=49409 done
[2022-09-20T18:33:30.242] _slurm_rpc_submit_batch_job: JobId=49411 InitPrio=669 usec=472
[2022-09-20T18:33:30.486] sched: Allocate JobId=49411 NodeList=cpu03 #CPUs=2 Partition=cpu-opteron
[2022-09-20T18:33:34.127] _job_complete: JobId=49411 WEXITSTATUS 0
[2022-09-20T18:33:34.127] _job_complete: JobId=49411 done
[2022-09-20T18:37:46.643] _job_complete: JobId=49410 WEXITSTATUS 0
[2022-09-20T18:37:46.644] _job_complete: JobId=49410 done
[2022-09-20T18:38:26.055] _slurm_rpc_submit_batch_job: JobId=49412 InitPrio=669 usec=545
[2022-09-20T18:38:26.983] sched: Allocate JobId=49412 NodeList=cpu03 #CPUs=32 Partition=cpu-opteron
[2022-09-20T18:38:29.815] _job_complete: JobId=49412 WEXITSTATUS 0
[2022-09-20T18:38:29.815] _job_complete: JobId=49412 done
[2022-09-20T18:43:15.487] _job_complete: JobId=49312 WEXITSTATUS 0
[2022-09-20T18:43:15.487] _job_complete: JobId=49312 done
[2022-09-20T18:43:16.306] sched: Allocate JobId=49318 NodeList=cpu14 #CPUs=16 Partition=cpu-epyc
[2022-09-20T19:06:31.445] _job_complete: JobId=49402 WEXITSTATUS 0
[2022-09-20T19:06:31.445] _job_complete: JobId=49402 done
[2022-09-20T20:00:35.437] Time limit exhausted for JobId=49072
[2022-09-20T21:05:03.101] _job_complete: JobId=49314 WEXITSTATUS 0
[2022-09-20T21:05:03.101] _job_complete: JobId=49314 done
[2022-09-20T21:05:03.398] sched: Allocate JobId=49319 NodeList=cpu12 #CPUs=16 Partition=cpu-epyc
[2022-09-20T21:08:03.560] _job_complete: JobId=49315 WEXITSTATUS 0
[2022-09-20T21:08:03.560] _job_complete: JobId=49315 done
[2022-09-20T21:08:03.918] sched: Allocate JobId=49320 NodeList=cpu12 #CPUs=16 Partition=cpu-epyc
[2022-09-20T21:17:04.119] _job_complete: JobId=49313 WEXITSTATUS 0
[2022-09-20T21:17:04.119] _job_complete: JobId=49313 done
[2022-09-20T21:17:04.978] sched: Allocate JobId=49321 NodeList=cpu14 #CPUs=16 Partition=cpu-epyc
[2022-09-20T23:20:30.863] _job_complete: JobId=49268 WEXITSTATUS 0
[2022-09-20T23:20:30.869] _job_complete: JobId=49268 done
[2022-09-20T23:20:37.960] sched: Allocate JobId=49365 NodeList=gpu04 #CPUs=16 Partition=gpu-k40c
[2022-09-20T23:50:09.581] _job_complete: JobId=49317 WEXITSTATUS 0
[2022-09-20T23:50:09.581] _job_complete: JobId=49317 done
[2022-09-20T23:50:10.441] sched: Allocate JobId=49322 NodeList=cpu14 #CPUs=16 Partition=cpu-epyc
[2022-09-21T00:28:50.072] _job_complete: JobId=49318 WEXITSTATUS 0
[2022-09-21T00:28:50.072] _job_complete: JobId=49318 done
[2022-09-21T00:28:50.385] sched: Allocate JobId=49323 NodeList=cpu14 #CPUs=16 Partition=cpu-epyc
[2022-09-21T01:16:16.945] _job_complete: JobId=49316 WEXITSTATUS 0
[2022-09-21T01:16:16.945] _job_complete: JobId=49316 done
[2022-09-21T01:16:17.293] sched: Allocate JobId=49324 NodeList=cpu12 #CPUs=16 Partition=cpu-epyc
[2022-09-21T02:13:07.746] _slurm_rpc_submit_batch_job: JobId=49413 InitPrio=892 usec=547
[2022-09-21T02:13:08.382] sched: Allocate JobId=49413 NodeList=cpu01 #CPUs=48 Partition=cpu-opteron
[2022-09-21T02:13:19.849] _slurm_rpc_kill_job: REQUEST_KILL_JOB JobId=4941 uid 548200019
[2022-09-21T02:13:19.849] job_str_signal(3): invalid JobId=4941
[2022-09-21T02:13:19.849] _slurm_rpc_kill_job: job_str_signal() uid=548200019 JobId=4941 sig=9 returned: Invalid job id specified
[2022-09-21T02:13:22.104] _slurm_rpc_kill_job: REQUEST_KILL_JOB JobId=49413 uid 548200019
[2022-09-21T02:13:35.840] _slurm_rpc_submit_batch_job: JobId=49414 InitPrio=892 usec=578
[2022-09-21T02:13:38.403] sched: Allocate JobId=49414 NodeList=cpu01 #CPUs=64 Partition=cpu-opteron
[2022-09-21T02:50:58.875] _slurm_rpc_submit_batch_job: JobId=49415 InitPrio=2008 usec=494
[2022-09-21T02:50:58.908] sched: Allocate JobId=49415 NodeList=cpu11 #CPUs=8 Partition=cpu-opteron
[2022-09-21T02:59:10.164] _slurm_rpc_submit_batch_job: JobId=49416 InitPrio=2008 usec=1377
[2022-09-21T03:00:34.774] _job_complete: JobId=49285 WEXITSTATUS 1
[2022-09-21T03:00:34.774] _job_complete: JobId=49285 done
[2022-09-21T03:00:35.474] sched: Allocate JobId=49416 NodeList=gpu03 #CPUs=16 Partition=gpu-k10
[2022-09-21T03:03:17.415] _slurm_rpc_submit_batch_job: JobId=49417 InitPrio=2008 usec=767
[2022-09-21T03:15:14.986] _job_complete: JobId=49319 WEXITSTATUS 0
[2022-09-21T03:15:14.986] _job_complete: JobId=49319 done
[2022-09-21T03:15:15.282] sched: Allocate JobId=49325 NodeList=cpu12 #CPUs=16 Partition=cpu-epyc
[2022-09-21T03:16:18.795] _job_complete: JobId=49320 WEXITSTATUS 0
[2022-09-21T03:16:18.795] _job_complete: JobId=49320 done
[2022-09-21T03:16:19.084] sched: Allocate JobId=49326 NodeList=cpu12 #CPUs=16 Partition=cpu-epyc
[2022-09-21T03:41:32.661] _job_complete: JobId=49143 WEXITSTATUS 0
[2022-09-21T03:41:32.661] _job_complete: JobId=49143 done
[2022-09-21T03:41:33.840] sched: Allocate JobId=49327 NodeList=cpu15 #CPUs=16 Partition=cpu-epyc
[2022-09-21T03:41:33.841] sched: Allocate JobId=49328 NodeList=cpu15 #CPUs=16 Partition=cpu-epyc
[2022-09-21T03:41:33.842] sched: Allocate JobId=49329 NodeList=cpu15 #CPUs=16 Partition=cpu-epyc
[2022-09-21T04:48:12.880] _job_complete: JobId=49415 WEXITSTATUS 0
[2022-09-21T04:48:12.886] _job_complete: JobId=49415 done
[2022-09-21T05:19:48.028] _job_complete: JobId=49322 WEXITSTATUS 0
[2022-09-21T05:19:48.028] _job_complete: JobId=49322 done
[2022-09-21T05:19:48.416] sched: Allocate JobId=49330 NodeList=cpu14 #CPUs=16 Partition=cpu-epyc
[2022-09-21T05:39:29.866] _job_complete: JobId=49321 WEXITSTATUS 0
[2022-09-21T05:39:29.866] _job_complete: JobId=49321 done
[2022-09-21T05:39:30.147] sched: Allocate JobId=49331 NodeList=cpu14 #CPUs=16 Partition=cpu-epyc
[2022-09-21T06:20:21.912] _job_complete: JobId=49323 WEXITSTATUS 0
[2022-09-21T06:20:21.912] _job_complete: JobId=49323 done
[2022-09-21T06:20:22.186] sched: Allocate JobId=49332 NodeList=cpu14 #CPUs=16 Partition=cpu-epyc
[2022-09-21T06:25:45.118] _job_complete: JobId=49416 WEXITSTATUS 1
[2022-09-21T06:25:45.125] _job_complete: JobId=49416 done
[2022-09-21T06:25:45.815] sched: Allocate JobId=49417 NodeList=gpu03 #CPUs=16 Partition=gpu-k10
[2022-09-21T07:51:33.644] _slurm_rpc_submit_batch_job: JobId=49418 InitPrio=3571 usec=538
[2022-09-21T07:51:34.351] sched: Allocate JobId=49418 NodeList=cpu11 #CPUs=4 Partition=cpu-opteron
[2022-09-21T07:59:27.339] _job_complete: JobId=49178 WEXITSTATUS 1
[2022-09-21T07:59:27.340] _job_complete: JobId=49178 done
[2022-09-21T08:06:33.586] _slurm_rpc_submit_batch_job: JobId=49419 InitPrio=3571 usec=478
[2022-09-21T08:06:34.056] sched: Allocate JobId=49419 NodeList=cpu11 #CPUs=4 Partition=cpu-opteron
[2022-09-21T08:38:57.296] _job_complete: JobId=49418 WEXITSTATUS 0
[2022-09-21T08:38:57.296] _job_complete: JobId=49418 done
[2022-09-21T08:47:24.752] _slurm_rpc_submit_batch_job: JobId=49420 InitPrio=3571 usec=526
[2022-09-21T08:47:25.558] sched: Allocate JobId=49420 NodeList=cpu11 #CPUs=4 Partition=cpu-opteron
[2022-09-21T08:50:27.383] _job_complete: JobId=49420 WEXITSTATUS 1
[2022-09-21T08:50:27.384] _job_complete: JobId=49420 done
[2022-09-21T08:54:27.980] _job_complete: JobId=49419 WEXITSTATUS 0
[2022-09-21T08:54:27.980] _job_complete: JobId=49419 done
[2022-09-21T08:54:54.177] _job_complete: JobId=49327 WEXITSTATUS 0
[2022-09-21T08:54:54.177] _job_complete: JobId=49327 done
[2022-09-21T08:54:54.720] sched: Allocate JobId=49333 NodeList=cpu15 #CPUs=16 Partition=cpu-epyc
[2022-09-21T09:02:37.337] _job_complete: JobId=49105 WEXITSTATUS 0
[2022-09-21T09:02:37.337] _job_complete: JobId=49105 done
[2022-09-21T09:24:50.116] _slurm_rpc_submit_batch_job: JobId=49421 InitPrio=669 usec=486
[2022-09-21T09:24:50.980] sched: Allocate JobId=49421 NodeList=cpu09 #CPUs=32 Partition=cpu-opteron
[2022-09-21T09:35:55.978] _job_complete: JobId=49325 WEXITSTATUS 0
[2022-09-21T09:35:55.978] _job_complete: JobId=49325 done
[2022-09-21T09:35:56.320] sched: Allocate JobId=49334 NodeList=cpu12 #CPUs=16 Partition=cpu-epyc
[2022-09-21T09:50:09.440] _job_complete: JobId=49326 WEXITSTATUS 0
[2022-09-21T09:50:09.440] _job_complete: JobId=49326 done
[2022-09-21T09:50:09.838] sched: Allocate JobId=49335 NodeList=cpu12 #CPUs=16 Partition=cpu-epyc
[2022-09-21T10:16:37.617] _job_complete: JobId=49324 WEXITSTATUS 0
[2022-09-21T10:16:37.617] _job_complete: JobId=49324 done
[2022-09-21T10:16:37.957] sched: Allocate JobId=49336 NodeList=cpu12 #CPUs=16 Partition=cpu-epyc
[2022-09-21T10:58:20.650] _job_complete: JobId=49330 WEXITSTATUS 0
[2022-09-21T10:58:20.650] _job_complete: JobId=49330 done
[2022-09-21T10:58:20.981] sched: Allocate JobId=49337 NodeList=cpu14 #CPUs=16 Partition=cpu-epyc
[2022-09-21T11:15:26.336] _job_complete: JobId=49328 WEXITSTATUS 1
[2022-09-21T11:15:26.336] _job_complete: JobId=49328 done
[2022-09-21T11:15:27.537] sched: Allocate JobId=49350 NodeList=cpu15 #CPUs=16 Partition=cpu-epyc
[2022-09-21T11:41:08.279] _slurm_rpc_submit_batch_job: JobId=49422 InitPrio=2222 usec=425
[2022-09-21T11:41:08.746] sched: Allocate JobId=49422 NodeList=cpu11 #CPUs=39 Partition=cpu-opteron
[2022-09-21T11:52:29.030] _job_complete: JobId=49332 WEXITSTATUS 0
[2022-09-21T11:52:29.030] _job_complete: JobId=49332 done
[2022-09-21T11:52:29.337] sched: Allocate JobId=49351 NodeList=cpu14 #CPUs=16 Partition=cpu-epyc
[2022-09-21T11:54:03.794] _job_complete: JobId=49331 WEXITSTATUS 0
[2022-09-21T11:54:03.794] _job_complete: JobId=49331 done
[2022-09-21T11:54:04.086] sched: Allocate JobId=49352 NodeList=cpu14 #CPUs=16 Partition=cpu-epyc
[2022-09-21T12:03:09.609] _slurm_rpc_submit_batch_job: JobId=49423 InitPrio=2000 usec=414
[2022-09-21T12:04:23.112] _slurm_rpc_submit_batch_job: JobId=49424 InitPrio=2000 usec=961
[2022-09-21T12:04:40.851] _slurm_rpc_kill_job: REQUEST_KILL_JOB JobId=49417 uid 548200029
[2022-09-21T12:04:43.110] sched: Allocate JobId=49424 NodeList=gpu03 #CPUs=16 Partition=gpu-k10
[2022-09-21T12:07:28.084] _slurm_rpc_submit_batch_job: JobId=49425 InitPrio=2000 usec=805
[2022-09-21T12:48:17.743] _job_complete: JobId=49329 WEXITSTATUS 0
[2022-09-21T12:48:17.744] _job_complete: JobId=49329 done
[2022-09-21T12:48:18.379] sched: Allocate JobId=49353 NodeList=cpu15 #CPUs=16 Partition=cpu-epyc
[2022-09-21T14:14:08.726] _slurm_rpc_submit_batch_job: JobId=49426 InitPrio=2444 usec=631
[2022-09-21T14:30:38.940] _job_complete: JobId=49333 WEXITSTATUS 0
[2022-09-21T14:30:38.940] _job_complete: JobId=49333 done
[2022-09-21T14:30:39.534] sched: Allocate JobId=49354 NodeList=cpu15 #CPUs=16 Partition=cpu-epyc
[2022-09-21T14:42:45.144] _slurm_rpc_kill_job: REQUEST_KILL_JOB JobId=49423 uid 548200029
[2022-09-21T14:43:14.217] _slurm_rpc_submit_batch_job: JobId=49427 InitPrio=2000 usec=503
[2022-09-21T14:43:14.972] sched: Allocate JobId=49427 NodeList=cpu09 #CPUs=8 Partition=cpu-opteron
[2022-09-21T14:53:22.699] error: This association 212(account='free', user='yatyuen.lim', partition='(null)') does not have access to qos long
[2022-09-21T14:53:22.699] _slurm_rpc_submit_batch_job: Invalid qos specification
[2022-09-21T15:01:45.621] _job_complete: JobId=49334 WEXITSTATUS 0
[2022-09-21T15:01:45.621] _job_complete: JobId=49334 done
[2022-09-21T15:01:45.963] sched: Allocate JobId=49355 NodeList=cpu12 #CPUs=16 Partition=cpu-epyc
[2022-09-21T15:31:19.741] _job_complete: JobId=49335 WEXITSTATUS 0
[2022-09-21T15:31:19.742] _job_complete: JobId=49335 done
[2022-09-21T15:31:20.114] sched: Allocate JobId=49356 NodeList=cpu12 #CPUs=16 Partition=cpu-epyc
[2022-09-21T15:59:08.669] _slurm_rpc_submit_batch_job: JobId=49428 InitPrio=3333 usec=575
[2022-09-21T15:59:11.375] _slurm_rpc_submit_batch_job: JobId=49429 InitPrio=3333 usec=494
[2022-09-21T15:59:13.455] _slurm_rpc_submit_batch_job: JobId=49430 InitPrio=3333 usec=465
[2022-09-21T15:59:15.799] _slurm_rpc_submit_batch_job: JobId=49431 InitPrio=3333 usec=475
[2022-09-21T15:59:18.648] _slurm_rpc_submit_batch_job: JobId=49432 InitPrio=3333 usec=430
[2022-09-21T15:59:21.200] _slurm_rpc_submit_batch_job: JobId=49433 InitPrio=3333 usec=493
[2022-09-21T15:59:27.743] _slurm_rpc_submit_batch_job: JobId=49434 InitPrio=3333 usec=443
[2022-09-21T15:59:30.392] _slurm_rpc_submit_batch_job: JobId=49435 InitPrio=3333 usec=604
[2022-09-21T15:59:34.315] _slurm_rpc_submit_batch_job: JobId=49436 InitPrio=3333 usec=410
[2022-09-21T15:59:42.738] _slurm_rpc_submit_batch_job: JobId=49437 InitPrio=3333 usec=482
[2022-09-21T15:59:45.264] _slurm_rpc_submit_batch_job: JobId=49438 InitPrio=3333 usec=439
[2022-09-21T15:59:47.880] _slurm_rpc_submit_batch_job: JobId=49439 InitPrio=3333 usec=503
[2022-09-21T15:59:50.229] _slurm_rpc_submit_batch_job: JobId=49440 InitPrio=3333 usec=403
[2022-09-21T15:59:52.464] _slurm_rpc_submit_batch_job: JobId=49441 InitPrio=3333 usec=412
[2022-09-21T15:59:58.760] _slurm_rpc_submit_batch_job: JobId=49442 InitPrio=3333 usec=430
[2022-09-21T16:15:54.202] _slurm_rpc_submit_batch_job: JobId=49443 InitPrio=3333 usec=561
[2022-09-21T16:29:12.329] _slurm_rpc_submit_batch_job: JobId=49444 InitPrio=2000 usec=413
[2022-09-21T16:29:13.078] sched: Allocate JobId=49444 NodeList=cpu09 #CPUs=8 Partition=cpu-opteron
[2022-09-21T16:46:32.155] _job_complete: JobId=49421 OOM failure
[2022-09-21T16:46:32.155] _job_complete: JobId=49421 done
[2022-09-21T16:58:01.788] _slurm_rpc_submit_batch_job: JobId=49445 InitPrio=888 usec=549
[2022-09-21T16:58:02.000] sched: Allocate JobId=49445 NodeList=cpu09 #CPUs=32 Partition=cpu-opteron
[2022-09-21T16:58:56.609] _slurm_rpc_submit_batch_job: JobId=49446 InitPrio=888 usec=523
[2022-09-21T16:58:57.102] sched: Allocate JobId=49446 NodeList=cpu03 #CPUs=32 Partition=cpu-opteron
[2022-09-21T17:08:24.424] _job_complete: JobId=49350 WEXITSTATUS 0
[2022-09-21T17:08:24.424] _job_complete: JobId=49350 done
[2022-09-21T17:08:25.129] sched: Allocate JobId=49357 NodeList=cpu15 #CPUs=16 Partition=cpu-epyc
[2022-09-21T17:11:40.974] _job_complete: JobId=49337 WEXITSTATUS 0
[2022-09-21T17:11:40.974] _job_complete: JobId=49337 done
[2022-09-21T17:11:41.294] sched: Allocate JobId=49358 NodeList=cpu14 #CPUs=16 Partition=cpu-epyc
[2022-09-21T17:15:38.431] _job_complete: JobId=49427 WEXITSTATUS 1
[2022-09-21T17:15:38.432] _job_complete: JobId=49427 done
[2022-09-21T17:17:04.264] _job_complete: JobId=49351 WEXITSTATUS 0
[2022-09-21T17:17:04.264] _job_complete: JobId=49351 done
[2022-09-21T17:17:04.548] sched: Allocate JobId=49359 NodeList=cpu14 #CPUs=16 Partition=cpu-epyc
[2022-09-21T17:29:17.248] _slurm_rpc_submit_batch_job: JobId=49447 InitPrio=2222 usec=545
[2022-09-21T17:29:17.320] sched: Allocate JobId=49447 NodeList=cpu04 #CPUs=45 Partition=cpu-opteron
[2022-09-21T17:57:17.811] _slurm_rpc_submit_batch_job: JobId=49448 InitPrio=2000 usec=1077
[2022-09-21T18:02:16.080] _job_complete: JobId=49444 WEXITSTATUS 0
[2022-09-21T18:02:16.081] _job_complete: JobId=49444 done
[2022-09-21T18:25:27.808] _job_complete: JobId=49353 WEXITSTATUS 0
[2022-09-21T18:25:27.808] _job_complete: JobId=49353 done
[2022-09-21T18:25:28.382] sched: Allocate JobId=49360 NodeList=cpu15 #CPUs=16 Partition=cpu-epyc
[2022-09-21T19:20:25.326] _job_complete: JobId=49336 WEXITSTATUS 0
[2022-09-21T19:20:25.326] _job_complete: JobId=49336 done
[2022-09-21T19:20:25.702] sched: Allocate JobId=49361 NodeList=cpu12 #CPUs=16 Partition=cpu-epyc
[2022-09-21T20:04:40.260] _job_complete: JobId=49352 WEXITSTATUS 0
[2022-09-21T20:04:40.261] _job_complete: JobId=49352 done
[2022-09-21T20:04:40.536] sched: Allocate JobId=49362 NodeList=cpu14 #CPUs=16 Partition=cpu-epyc
[2022-09-21T20:09:09.649] _job_complete: JobId=49354 WEXITSTATUS 0
[2022-09-21T20:09:09.649] _job_complete: JobId=49354 done
[2022-09-21T20:09:10.213] sched: Allocate JobId=49390 NodeList=cpu15 #CPUs=16 Partition=cpu-epyc
[2022-09-21T21:25:08.972] _job_complete: JobId=49356 WEXITSTATUS 0
[2022-09-21T21:25:08.972] _job_complete: JobId=49356 done
[2022-09-21T21:25:09.325] sched: Allocate JobId=49428 NodeList=cpu12 #CPUs=8 Partition=cpu-epyc
[2022-09-21T21:25:09.326] sched: Allocate JobId=49429 NodeList=cpu12 #CPUs=8 Partition=cpu-epyc
[2022-09-21T22:11:01.272] _slurm_rpc_submit_batch_job: JobId=49449 InitPrio=666 usec=655
[2022-09-21T22:11:02.201] sched: Allocate JobId=49449 NodeList=cpu03 #CPUs=32 Partition=cpu-opteron
[2022-09-21T22:11:55.311] _slurm_rpc_submit_batch_job: JobId=49450 InitPrio=666 usec=401
[2022-09-21T22:11:56.259] sched: Allocate JobId=49450 NodeList=cpu09 #CPUs=32 Partition=cpu-opteron
[2022-09-21T22:13:48.465] _slurm_rpc_submit_batch_job: JobId=49451 InitPrio=666 usec=537
[2022-09-21T22:13:48.537] sched: Allocate JobId=49451 NodeList=cpu05 #CPUs=32 Partition=cpu-opteron
[2022-09-21T22:20:01.177] _job_complete: JobId=49451 WEXITSTATUS 0
[2022-09-21T22:20:01.177] _job_complete: JobId=49451 done
[2022-09-21T22:27:46.194] _job_complete: JobId=49357 WEXITSTATUS 0
[2022-09-21T22:27:46.194] _job_complete: JobId=49357 done
[2022-09-21T22:27:46.500] sched: Allocate JobId=49430 NodeList=cpu15 #CPUs=8 Partition=cpu-epyc
[2022-09-21T22:27:46.501] sched: Allocate JobId=49431 NodeList=cpu15 #CPUs=8 Partition=cpu-epyc
[2022-09-21T22:28:11.961] _job_complete: JobId=49358 WEXITSTATUS 0
[2022-09-21T22:28:11.962] _job_complete: JobId=49358 done
[2022-09-21T22:28:12.212] sched: Allocate JobId=49432 NodeList=cpu14 #CPUs=8 Partition=cpu-epyc
[2022-09-21T22:28:12.213] sched: Allocate JobId=49433 NodeList=cpu14 #CPUs=8 Partition=cpu-epyc
[2022-09-21T22:32:04.309] _job_complete: JobId=49355 WEXITSTATUS 0
[2022-09-21T22:32:04.309] _job_complete: JobId=49355 done
[2022-09-21T22:32:04.670] sched: Allocate JobId=49434 NodeList=cpu12 #CPUs=8 Partition=cpu-epyc
[2022-09-21T22:32:04.671] sched: Allocate JobId=49435 NodeList=cpu12 #CPUs=8 Partition=cpu-epyc
[2022-09-21T22:32:07.221] _job_complete: JobId=49450 WEXITSTATUS 0
[2022-09-21T22:32:07.221] _job_complete: JobId=49450 done
[2022-09-21T22:32:21.487] _job_complete: JobId=49449 WEXITSTATUS 0
[2022-09-21T22:32:21.487] _job_complete: JobId=49449 done
[2022-09-21T23:50:44.219] _job_complete: JobId=49359 WEXITSTATUS 0
[2022-09-21T23:50:44.219] _job_complete: JobId=49359 done
[2022-09-21T23:50:44.574] sched: Allocate JobId=49436 NodeList=cpu14 #CPUs=8 Partition=cpu-epyc
[2022-09-21T23:50:44.575] sched: Allocate JobId=49437 NodeList=cpu14 #CPUs=8 Partition=cpu-epyc
[2022-09-22T00:21:01.882] _job_complete: JobId=49360 WEXITSTATUS 0
[2022-09-22T00:21:01.882] _job_complete: JobId=49360 done
[2022-09-22T00:21:02.384] sched: Allocate JobId=49438 NodeList=cpu15 #CPUs=8 Partition=cpu-epyc
[2022-09-22T00:21:02.385] sched: Allocate JobId=49439 NodeList=cpu15 #CPUs=8 Partition=cpu-epyc
[2022-09-22T00:26:07.494] _job_complete: JobId=49144 WEXITSTATUS 0
[2022-09-22T00:26:07.499] _job_complete: JobId=49144 done
[2022-09-22T02:35:27.630] _job_complete: JobId=49428 WEXITSTATUS 0
[2022-09-22T02:35:27.630] _job_complete: JobId=49428 done
[2022-09-22T02:35:45.059] sched/backfill: _start_job: Started JobId=49440 in cpu-epyc on cpu12
[2022-09-22T02:39:33.401] _job_complete: JobId=49297 WEXITSTATUS 0
[2022-09-22T02:39:33.401] _job_complete: JobId=49297 done
[2022-09-22T02:39:33.748] sched: Allocate JobId=49298 NodeList=cpu13 #CPUs=48 Partition=cpu-epyc
[2022-09-22T02:41:04.390] _job_complete: JobId=49429 WEXITSTATUS 0
[2022-09-22T02:41:04.390] _job_complete: JobId=49429 done
[2022-09-22T02:41:04.726] sched: Allocate JobId=49441 NodeList=cpu12 #CPUs=8 Partition=cpu-epyc
[2022-09-22T02:54:21.077] _slurm_rpc_submit_batch_job: JobId=49452 InitPrio=1777 usec=559
[2022-09-22T02:54:21.503] sched: Allocate JobId=49452 NodeList=cpu03 #CPUs=8 Partition=cpu-opteron
[2022-09-22T03:05:36.389] _job_complete: JobId=49390 WEXITSTATUS 0
[2022-09-22T03:05:36.390] _job_complete: JobId=49390 done
[2022-09-22T03:05:36.736] sched: Allocate JobId=49442 NodeList=cpu15 #CPUs=8 Partition=cpu-epyc
[2022-09-22T03:41:37.265] _job_complete: JobId=49430 WEXITSTATUS 0
[2022-09-22T03:41:37.265] _job_complete: JobId=49430 done
[2022-09-22T03:41:45.148] sched/backfill: _start_job: Started JobId=49426 in cpu-epyc on cpu15
[2022-09-22T03:53:13.254] _job_complete: JobId=49431 WEXITSTATUS 0
[2022-09-22T03:53:13.255] _job_complete: JobId=49431 done
[2022-09-22T04:00:26.631] _job_complete: JobId=49452 WEXITSTATUS 0
[2022-09-22T04:00:26.633] _job_complete: JobId=49452 done
[2022-09-22T04:39:23.785] _job_complete: JobId=49361 WEXITSTATUS 0
[2022-09-22T04:39:23.785] _job_complete: JobId=49361 done
[2022-09-22T04:55:26.182] _job_complete: JobId=49362 WEXITSTATUS 0
[2022-09-22T04:55:26.182] _job_complete: JobId=49362 done
[2022-09-22T05:01:51.008] _job_complete: JobId=49432 WEXITSTATUS 0
[2022-09-22T05:01:51.008] _job_complete: JobId=49432 done
[2022-09-22T05:01:51.332] sched: Allocate JobId=49443 NodeList=cpu14 #CPUs=16 Partition=cpu-epyc
[2022-09-22T05:04:00.967] _job_complete: JobId=49437 WEXITSTATUS 0
[2022-09-22T05:04:00.967] _job_complete: JobId=49437 done
[2022-09-22T05:13:19.460] _job_complete: JobId=49433 WEXITSTATUS 0
[2022-09-22T05:13:19.460] _job_complete: JobId=49433 done
[2022-09-22T05:23:53.026] _job_complete: JobId=49434 WEXITSTATUS 0
[2022-09-22T05:23:53.026] _job_complete: JobId=49434 done
[2022-09-22T05:33:16.697] _job_complete: JobId=49435 WEXITSTATUS 0
[2022-09-22T05:33:16.698] _job_complete: JobId=49435 done
[2022-09-22T05:47:14.789] _job_complete: JobId=49438 WEXITSTATUS 0
[2022-09-22T05:47:14.789] _job_complete: JobId=49438 done
[2022-09-22T06:09:47.411] _job_complete: JobId=49436 WEXITSTATUS 0
[2022-09-22T06:09:47.411] _job_complete: JobId=49436 done
[2022-09-22T06:15:21.810] _job_complete: JobId=49439 WEXITSTATUS 0
[2022-09-22T06:15:21.810] _job_complete: JobId=49439 done
[2022-09-22T07:53:40.291] _job_complete: JobId=49440 WEXITSTATUS 0
[2022-09-22T07:53:40.291] _job_complete: JobId=49440 done
[2022-09-22T08:31:33.593] _job_complete: JobId=49441 WEXITSTATUS 0
[2022-09-22T08:31:33.593] _job_complete: JobId=49441 done
[2022-09-22T08:32:13.788] _job_complete: JobId=49442 WEXITSTATUS 0
[2022-09-22T08:32:13.788] _job_complete: JobId=49442 done
[2022-09-22T09:00:09.500] _slurm_rpc_submit_batch_job: JobId=49453 InitPrio=1777 usec=478
[2022-09-22T09:00:10.387] sched: Allocate JobId=49453 NodeList=cpu12 #CPUs=8 Partition=cpu-epyc
[2022-09-22T09:00:18.745] _slurm_rpc_kill_job: REQUEST_KILL_JOB JobId=49453 uid 548200029
[2022-09-22T09:00:31.216] _slurm_rpc_submit_batch_job: JobId=49454 InitPrio=1777 usec=409
[2022-09-22T09:00:31.394] sched: Allocate JobId=49454 NodeList=cpu03 #CPUs=8 Partition=cpu-opteron
[2022-09-22T10:16:55.601] _job_complete: JobId=49403 WEXITSTATUS 0
[2022-09-22T10:16:55.601] _job_complete: JobId=49403 done
[2022-09-22T10:16:56.766] _slurm_rpc_submit_batch_job: JobId=49455 InitPrio=2222 usec=496
[2022-09-22T10:16:57.053] sched: Allocate JobId=49455 NodeList=cpu05 #CPUs=35 Partition=cpu-opteron
[2022-09-22T10:16:57.737] sched: Allocate JobId=49406 NodeList=gpu02 #CPUs=2 Partition=gpu-titan
[2022-09-22T10:26:58.482] _job_complete: JobId=49454 WEXITSTATUS 1
[2022-09-22T10:26:58.483] _job_complete: JobId=49454 done
[2022-09-22T11:41:11.016] Time limit exhausted for JobId=49422
[2022-09-22T12:32:19.786] _slurm_rpc_submit_batch_job: JobId=49456 InitPrio=666 usec=521
[2022-09-22T12:32:20.340] sched: Allocate JobId=49456 NodeList=cpu03 #CPUs=32 Partition=cpu-opteron
[2022-09-22T12:36:38.572] _job_complete: JobId=49456 WEXITSTATUS 0
[2022-09-22T12:36:38.572] _job_complete: JobId=49456 done
[2022-09-22T12:36:52.627] _slurm_rpc_submit_batch_job: JobId=49457 InitPrio=666 usec=580
[2022-09-22T12:36:52.855] sched: Allocate JobId=49457 NodeList=cpu07 #CPUs=64 Partition=cpu-opteron
[2022-09-22T12:47:37.075] _slurm_rpc_submit_batch_job: JobId=49458 InitPrio=666 usec=446
[2022-09-22T12:47:37.982] sched: Allocate JobId=49458 NodeList=cpu12 #CPUs=48 Partition=cpu-epyc
[2022-09-22T12:47:57.063] _job_complete: JobId=49458 WEXITSTATUS 1
[2022-09-22T12:47:57.064] _job_complete: JobId=49458 done
[2022-09-22T12:49:30.679] _slurm_rpc_submit_batch_job: JobId=49459 InitPrio=666 usec=466
[2022-09-22T12:49:31.246] sched: Allocate JobId=49459 NodeList=cpu12 #CPUs=48 Partition=cpu-epyc
[2022-09-22T12:50:37.587] sched: Created reservation=opteron_hyperthread users=jitkang nodes=cpu11 cores=64 licenses=(null) tres=cpu=64 watts=4294967294 start=2022-09-22T12:50:37 end=2023-09-22T12:50:37 MaxStartDelay=
[2022-09-22T12:54:13.724] _job_complete: JobId=49459 WEXITSTATUS 1
[2022-09-22T12:54:13.725] _job_complete: JobId=49459 done
[2022-09-22T12:55:51.128] Processing Reconfiguration Request
[2022-09-22T12:55:51.135] restoring original state of nodes
[2022-09-22T12:55:51.135] select/cons_tres: part_data_create_array: select/cons_tres: preparing for 6 partitions
[2022-09-22T12:55:51.136] read_slurm_conf: backup_controller not specified
[2022-09-22T12:55:51.136] select/cons_tres: select_p_reconfigure: select/cons_tres: reconfigure
[2022-09-22T12:55:51.136] select/cons_tres: part_data_create_array: select/cons_tres: preparing for 6 partitions
[2022-09-22T12:55:51.137] No parameter for mcs plugin, default values set
[2022-09-22T12:55:51.137] mcs: MCSParameters = (null). ondemand set.
[2022-09-22T12:55:51.138] _slurm_rpc_reconfigure_controller: completed usec=10175
[2022-09-22T12:55:51.854] SchedulerParameters=default_queue_depth=100,max_rpc_cnt=0,max_sched_time=2,partition_job_depth=0,sched_max_job_start=0,sched_min_interval=2
[2022-09-22T12:57:11.012] sched: Updated reservation=opteron_hyperthread users=jitkang,yeehengteh nodes=cpu11 cores=32 licenses=(null) tres=cpu=64 watts=4294967294 start=2022-09-22T12:50:37 end=2023-09-22T12:50:37 MaxStartDelay=
[2022-09-22T12:58:06.186] _slurm_rpc_submit_batch_job: JobId=49460 InitPrio=666 usec=455
[2022-09-22T12:58:07.122] sched: Allocate JobId=49460 NodeList=cpu12 #CPUs=48 Partition=cpu-epyc
[2022-09-22T12:58:14.143] _job_complete: JobId=49460 WEXITSTATUS 1
[2022-09-22T12:58:14.143] _job_complete: JobId=49460 done
[2022-09-22T12:58:46.624] _slurm_rpc_submit_batch_job: JobId=49461 InitPrio=666 usec=411
[2022-09-22T12:58:47.174] sched: Allocate JobId=49461 NodeList=cpu12 #CPUs=48 Partition=cpu-epyc
[2022-09-22T12:59:14.456] _job_complete: JobId=49461 WEXITSTATUS 0
[2022-09-22T12:59:14.457] _job_complete: JobId=49461 done
[2022-09-22T13:02:40.950] _slurm_rpc_submit_batch_job: JobId=49462 InitPrio=15333 usec=463
[2022-09-22T13:02:42.510] sched: Allocate JobId=49462 NodeList=cpu03 #CPUs=32 Partition=cpu-opteron
[2022-09-22T13:02:58.739] _slurm_rpc_submit_batch_job: JobId=49463 InitPrio=15333 usec=449
[2022-09-22T13:02:59.563] sched: Allocate JobId=49463 NodeList=cpu09 #CPUs=32 Partition=cpu-opteron
[2022-09-22T13:03:25.881] _slurm_rpc_kill_job: REQUEST_KILL_JOB JobId=49463 uid 548300543
[2022-09-22T13:03:32.929] _slurm_rpc_kill_job: REQUEST_KILL_JOB JobId=49462 uid 548300543
[2022-09-22T13:04:19.814] _slurm_rpc_submit_batch_job: JobId=49464 InitPrio=15333 usec=578
[2022-09-22T13:04:52.319] _slurm_rpc_submit_batch_job: JobId=49465 InitPrio=15333 usec=454
[2022-09-22T13:05:01.768] error: Nodes cpu12 not responding, setting DOWN
[2022-09-22T13:05:26.235] _slurm_rpc_kill_job: REQUEST_KILL_JOB JobId=49465 uid 548300543
[2022-09-22T13:05:28.627] _slurm_rpc_kill_job: REQUEST_KILL_JOB JobId=49464 uid 548300543
[2022-09-22T13:06:44.536] _slurm_rpc_submit_batch_job: JobId=49466 InitPrio=15333 usec=453
[2022-09-22T13:06:44.911] sched: Allocate JobId=49466 NodeList=cpu11 #CPUs=32 Partition=cpu-opteron
[2022-09-22T13:07:08.992] _job_complete: JobId=49455 WEXITSTATUS 102
[2022-09-22T13:07:08.993] _job_complete: JobId=49455 done
[2022-09-22T13:07:12.449] _slurm_rpc_submit_batch_job: JobId=49467 InitPrio=15333 usec=547
[2022-09-22T13:08:03.534] Node cpu12 now responding
[2022-09-22T13:08:03.534] node cpu12 returned to service
[2022-09-22T13:09:53.081] _slurm_rpc_kill_job: REQUEST_KILL_JOB JobId=49466 uid 548300543
[2022-09-22T13:09:55.367] sched: Allocate JobId=49467 NodeList=cpu11 #CPUs=32 Partition=cpu-opteron
[2022-09-22T13:10:38.613] _slurm_rpc_submit_batch_job: JobId=49468 InitPrio=15333 usec=558
[2022-09-22T13:10:39.370] sched: Allocate JobId=49468 NodeList=cpu03 #CPUs=32 Partition=cpu-opteron
[2022-09-22T13:13:17.046] _job_complete: JobId=49467 WEXITSTATUS 0
[2022-09-22T13:13:17.046] _job_complete: JobId=49467 done
[2022-09-22T13:15:38.177] _job_complete: JobId=49468 WEXITSTATUS 0
[2022-09-22T13:15:38.177] _job_complete: JobId=49468 done
[2022-09-22T13:18:18.805] _job_complete: JobId=49457 WEXITSTATUS 0
[2022-09-22T13:18:18.805] _job_complete: JobId=49457 done
[2022-09-22T13:22:08.620] _slurm_rpc_submit_batch_job: JobId=49469 InitPrio=15777 usec=465
[2022-09-22T13:22:09.289] sched: Allocate JobId=49469 NodeList=cpu11 #CPUs=32 Partition=cpu-opteron
[2022-09-22T13:22:39.943] _slurm_rpc_kill_job: REQUEST_KILL_JOB JobId=49469 uid 548200003
[2022-09-22T13:22:53.798] _slurm_rpc_submit_batch_job: JobId=49470 InitPrio=15777 usec=465
[2022-09-22T13:22:54.438] sched: Allocate JobId=49470 NodeList=cpu11 #CPUs=32 Partition=cpu-opteron
[2022-09-22T13:23:28.555] _slurm_rpc_kill_job: REQUEST_KILL_JOB JobId=49470 uid 548200003
[2022-09-22T13:23:47.954] _slurm_rpc_submit_batch_job: JobId=49471 InitPrio=15777 usec=504
[2022-09-22T13:23:48.557] sched: Allocate JobId=49471 NodeList=cpu11 #CPUs=8 Partition=cpu-opteron
[2022-09-22T13:25:21.815] _slurm_rpc_kill_job: REQUEST_KILL_JOB JobId=49471 uid 548200003
[2022-09-22T13:25:24.398] _job_complete: JobId=49426 WEXITSTATUS 0
[2022-09-22T13:25:24.398] _job_complete: JobId=49426 done
[2022-09-22T13:25:51.580] _slurm_rpc_submit_batch_job: JobId=49472 InitPrio=15777 usec=463
[2022-09-22T13:25:51.720] sched: Allocate JobId=49472 NodeList=cpu11 #CPUs=4 Partition=cpu-opteron
[2022-09-22T13:29:53.496] _slurm_rpc_kill_job: REQUEST_KILL_JOB JobId=49472 uid 548200003
[2022-09-22T13:30:10.335] _slurm_rpc_submit_batch_job: JobId=49473 InitPrio=15777 usec=492
[2022-09-22T13:30:11.175] sched: Allocate JobId=49473 NodeList=cpu11 #CPUs=16 Partition=cpu-opteron
[2022-09-22T13:32:15.632] _slurm_rpc_kill_job: REQUEST_KILL_JOB JobId=49473 uid 548200003
[2022-09-22T13:32:36.866] Processing Reconfiguration Request
[2022-09-22T13:32:36.873] restoring original state of nodes
[2022-09-22T13:32:36.873] select/cons_tres: part_data_create_array: select/cons_tres: preparing for 6 partitions
[2022-09-22T13:32:36.874] read_slurm_conf: backup_controller not specified
[2022-09-22T13:32:36.874] select/cons_tres: select_p_reconfigure: select/cons_tres: reconfigure
[2022-09-22T13:32:36.874] select/cons_tres: part_data_create_array: select/cons_tres: preparing for 6 partitions
[2022-09-22T13:32:36.875] No parameter for mcs plugin, default values set
[2022-09-22T13:32:36.875] mcs: MCSParameters = (null). ondemand set.
[2022-09-22T13:32:36.875] _slurm_rpc_reconfigure_controller: completed usec=9960
[2022-09-22T13:32:37.374] SchedulerParameters=default_queue_depth=100,max_rpc_cnt=0,max_sched_time=2,partition_job_depth=0,sched_max_job_start=0,sched_min_interval=2
[2022-09-22T13:32:52.401] _slurm_rpc_submit_batch_job: JobId=49474 InitPrio=15777 usec=428
[2022-09-22T13:32:52.454] sched: Allocate JobId=49474 NodeList=cpu11 #CPUs=16 Partition=cpu-opteron
[2022-09-22T13:34:08.655] _slurm_rpc_kill_job: REQUEST_KILL_JOB JobId=49474 uid 548200003
[2022-09-22T13:34:28.750] _slurm_rpc_delete_reservation complete for opteron_hyperthread usec=56
[2022-09-22T13:54:11.097] _slurm_rpc_submit_batch_job: JobId=49475 InitPrio=2222 usec=496
[2022-09-22T13:54:11.806] sched: Allocate JobId=49475 NodeList=cpu11 #CPUs=35 Partition=cpu-opteron
[2022-09-22T13:55:28.241] _slurm_rpc_submit_batch_job: JobId=49476 InitPrio=2222 usec=410
[2022-09-22T13:55:28.892] sched: Allocate JobId=49476 NodeList=cpu05 #CPUs=39 Partition=cpu-opteron
[2022-09-22T13:57:22.470] Reservation request overlaps jobs
[2022-09-22T13:57:22.470] _slurm_rpc_resv_create reservation=opteron_hyperthread: Requested nodes are busy
[2022-09-22T13:57:48.919] sched: Created reservation=opteron_hyperthread users=jitkang,yeehengteh nodes=cpu07 cores=64 licenses=(null) tres=cpu=64 watts=4294967294 start=2022-09-22T13:57:48 end=2023-09-22T13:57:48 MaxStartDelay=
[2022-09-22T14:00:09.358] Processing Reconfiguration Request
[2022-09-22T14:00:09.365] restoring original state of nodes
[2022-09-22T14:00:09.365] error: Configured cpu count change on cpu07 (64 to 32)
[2022-09-22T14:00:09.366] select/cons_tres: part_data_create_array: select/cons_tres: preparing for 6 partitions
[2022-09-22T14:00:09.367] read_slurm_conf: backup_controller not specified
[2022-09-22T14:00:09.367] select/cons_tres: select_p_reconfigure: select/cons_tres: reconfigure
[2022-09-22T14:00:09.367] select/cons_tres: part_data_create_array: select/cons_tres: preparing for 6 partitions
[2022-09-22T14:00:09.367] No parameter for mcs plugin, default values set
[2022-09-22T14:00:09.367] mcs: MCSParameters = (null). ondemand set.
[2022-09-22T14:00:09.368] error: _slurm_rpc_reconfigure_controller: The node configuration changes that were made require restart of the slurmctld daemon to take effect
[2022-09-22T14:00:16.680] Terminate signal (SIGINT or SIGTERM) received
[2022-09-22T14:00:16.778] Saving all slurm state
[2022-09-22T14:00:17.214] slurmctld version 21.08.8-2 started on cluster um-hpc
[2022-09-22T14:00:17.240] accounting_storage/slurmdbd: clusteracct_storage_p_register_ctld: Registering slurmctld at port 6817 with slurmdbd
[2022-09-22T14:00:21.325] Recovered state of 19 nodes
[2022-09-22T14:00:21.325] Down nodes: umhpc
[2022-09-22T14:00:21.325] Recovered JobId=48950 StepId=extern
[2022-09-22T14:00:21.329] Recovered JobId=48950 StepId=batch
[2022-09-22T14:00:21.329] Recovered JobId=48950 Assoc=20
[2022-09-22T14:00:21.329] Recovered JobId=49071 Assoc=23
[2022-09-22T14:00:21.329] Recovered JobId=49096 Assoc=183
[2022-09-22T14:00:21.331] Recovered JobId=49102 Assoc=20
[2022-09-22T14:00:21.331] Recovered JobId=49103 Assoc=20
[2022-09-22T14:00:21.331] Recovered JobId=49104 Assoc=20
[2022-09-22T14:00:21.331] Recovered JobId=49137 StepId=extern
[2022-09-22T14:00:21.331] Recovered JobId=49137 StepId=batch
[2022-09-22T14:00:21.331] Recovered JobId=49137 Assoc=20
[2022-09-22T14:00:21.331] Recovered JobId=49177 StepId=extern
[2022-09-22T14:00:21.331] Recovered JobId=49177 StepId=batch
[2022-09-22T14:00:21.331] Recovered JobId=49177 Assoc=238
[2022-09-22T14:00:21.331] Recovered JobId=49267 StepId=extern
[2022-09-22T14:00:21.331] Recovered JobId=49267 StepId=batch
[2022-09-22T14:00:21.331] Recovered JobId=49267 Assoc=238
[2022-09-22T14:00:21.331] Recovered JobId=49298 StepId=extern
[2022-09-22T14:00:21.331] Recovered JobId=49298 StepId=batch
[2022-09-22T14:00:21.331] Recovered JobId=49298 Assoc=23
[2022-09-22T14:00:21.331] Recovered JobId=49363 Assoc=204
[2022-09-22T14:00:21.331] Recovered JobId=49364 Assoc=204
[2022-09-22T14:00:21.331] Recovered JobId=49365 StepId=extern
[2022-09-22T14:00:21.331] Recovered JobId=49365 StepId=batch
[2022-09-22T14:00:21.332] Recovered JobId=49365 Assoc=67
[2022-09-22T14:00:21.332] Recovered JobId=49398 StepId=extern
[2022-09-22T14:00:21.332] Recovered JobId=49398 StepId=batch
[2022-09-22T14:00:21.332] Recovered JobId=49398 Assoc=32
[2022-09-22T14:00:21.332] Recovered JobId=49406 StepId=extern
[2022-09-22T14:00:21.332] Recovered JobId=49406 StepId=batch
[2022-09-22T14:00:21.332] Recovered JobId=49406 Assoc=23
[2022-09-22T14:00:21.332] Recovered JobId=49414 StepId=extern
[2022-09-22T14:00:21.332] Recovered JobId=49414 StepId=batch
[2022-09-22T14:00:21.332] Recovered JobId=49414 Assoc=19
[2022-09-22T14:00:21.332] Recovered JobId=49424 StepId=extern
[2022-09-22T14:00:21.332] Recovered JobId=49424 StepId=batch
[2022-09-22T14:00:21.332] Recovered JobId=49424 Assoc=32
[2022-09-22T14:00:21.332] Recovered JobId=49425 Assoc=32
[2022-09-22T14:00:21.332] Recovered JobId=49443 StepId=extern
[2022-09-22T14:00:21.332] Recovered JobId=49443 StepId=batch
[2022-09-22T14:00:21.332] Recovered JobId=49443 Assoc=48
[2022-09-22T14:00:21.332] Recovered JobId=49445 StepId=extern
[2022-09-22T14:00:21.332] Recovered JobId=49445 StepId=batch
[2022-09-22T14:00:21.332] Recovered JobId=49445 Assoc=19
[2022-09-22T14:00:21.332] Recovered JobId=49446 StepId=extern
[2022-09-22T14:00:21.332] Recovered JobId=49446 StepId=batch
[2022-09-22T14:00:21.332] Recovered JobId=49446 Assoc=19
[2022-09-22T14:00:21.332] Recovered JobId=49447 StepId=extern
[2022-09-22T14:00:21.332] Recovered JobId=49447 StepId=batch
[2022-09-22T14:00:21.332] Recovered JobId=49447 Assoc=211
[2022-09-22T14:00:21.332] Recovered JobId=49448 Assoc=32
[2022-09-22T14:00:21.332] Recovered JobId=49475 StepId=extern
[2022-09-22T14:00:21.332] Recovered JobId=49475 StepId=batch
[2022-09-22T14:00:21.332] Recovered JobId=49475 Assoc=211
[2022-09-22T14:00:21.333] Recovered JobId=49476 StepId=extern
[2022-09-22T14:00:21.333] Recovered JobId=49476 StepId=batch
[2022-09-22T14:00:21.333] Recovered JobId=49476 Assoc=211
[2022-09-22T14:00:21.333] Recovered information about 25 jobs
[2022-09-22T14:00:21.333] select/cons_tres: part_data_create_array: select/cons_tres: preparing for 6 partitions
[2022-09-22T14:00:21.333] Recovered state of reservation opteron_hyperthread
[2022-09-22T14:00:21.334] Recovered state of 1 reservations
[2022-09-22T14:00:21.334] read_slurm_conf: backup_controller not specified
[2022-09-22T14:00:21.334] select/cons_tres: select_p_reconfigure: select/cons_tres: reconfigure
[2022-09-22T14:00:21.334] select/cons_tres: part_data_create_array: select/cons_tres: preparing for 6 partitions
[2022-09-22T14:00:21.334] Running as primary controller
[2022-09-22T14:00:21.560] No parameter for mcs plugin, default values set
[2022-09-22T14:00:21.560] mcs: MCSParameters = (null). ondemand set.
[2022-09-22T14:00:25.570] error: Node cpu07 appears to have a different slurm.conf than the slurmctld.  This could cause issues with communication and functionality.  Please review both files and make sure they are the same.  If this is expected ignore, and set DebugFlags=NO_CONF_HASH in your slurm.conf.
[2022-09-22T14:00:25.571] error: Node cpu03 appears to have a different slurm.conf than the slurmctld.  This could cause issues with communication and functionality.  Please review both files and make sure they are the same.  If this is expected ignore, and set DebugFlags=NO_CONF_HASH in your slurm.conf.
[2022-09-22T14:00:25.571] error: Node cpu13 appears to have a different slurm.conf than the slurmctld.  This could cause issues with communication and functionality.  Please review both files and make sure they are the same.  If this is expected ignore, and set DebugFlags=NO_CONF_HASH in your slurm.conf.
[2022-09-22T14:00:25.571] error: Node cpu12 appears to have a different slurm.conf than the slurmctld.  This could cause issues with communication and functionality.  Please review both files and make sure they are the same.  If this is expected ignore, and set DebugFlags=NO_CONF_HASH in your slurm.conf.
[2022-09-22T14:00:25.572] error: Node cpu01 appears to have a different slurm.conf than the slurmctld.  This could cause issues with communication and functionality.  Please review both files and make sure they are the same.  If this is expected ignore, and set DebugFlags=NO_CONF_HASH in your slurm.conf.
[2022-09-22T14:00:25.572] error: Node cpu05 appears to have a different slurm.conf than the slurmctld.  This could cause issues with communication and functionality.  Please review both files and make sure they are the same.  If this is expected ignore, and set DebugFlags=NO_CONF_HASH in your slurm.conf.
[2022-09-22T14:00:25.573] error: Node cpu09 appears to have a different slurm.conf than the slurmctld.  This could cause issues with communication and functionality.  Please review both files and make sure they are the same.  If this is expected ignore, and set DebugFlags=NO_CONF_HASH in your slurm.conf.
[2022-09-22T14:00:25.573] error: Node cpu14 appears to have a different slurm.conf than the slurmctld.  This could cause issues with communication and functionality.  Please review both files and make sure they are the same.  If this is expected ignore, and set DebugFlags=NO_CONF_HASH in your slurm.conf.
[2022-09-22T14:00:25.573] error: Node cpu15 appears to have a different slurm.conf than the slurmctld.  This could cause issues with communication and functionality.  Please review both files and make sure they are the same.  If this is expected ignore, and set DebugFlags=NO_CONF_HASH in your slurm.conf.
[2022-09-22T14:00:25.573] error: Node cpu10 appears to have a different slurm.conf than the slurmctld.  This could cause issues with communication and functionality.  Please review both files and make sure they are the same.  If this is expected ignore, and set DebugFlags=NO_CONF_HASH in your slurm.conf.
[2022-09-22T14:00:25.573] error: Node cpu11 appears to have a different slurm.conf than the slurmctld.  This could cause issues with communication and functionality.  Please review both files and make sure they are the same.  If this is expected ignore, and set DebugFlags=NO_CONF_HASH in your slurm.conf.
[2022-09-22T14:00:25.573] error: Node gpu01 appears to have a different slurm.conf than the slurmctld.  This could cause issues with communication and functionality.  Please review both files and make sure they are the same.  If this is expected ignore, and set DebugFlags=NO_CONF_HASH in your slurm.conf.
[2022-09-22T14:00:25.574] error: Node gpu03 appears to have a different slurm.conf than the slurmctld.  This could cause issues with communication and functionality.  Please review both files and make sure they are the same.  If this is expected ignore, and set DebugFlags=NO_CONF_HASH in your slurm.conf.
[2022-09-22T14:00:25.574] error: Node cpu04 appears to have a different slurm.conf than the slurmctld.  This could cause issues with communication and functionality.  Please review both files and make sure they are the same.  If this is expected ignore, and set DebugFlags=NO_CONF_HASH in your slurm.conf.
[2022-09-22T14:00:25.574] error: Node gpu02 appears to have a different slurm.conf than the slurmctld.  This could cause issues with communication and functionality.  Please review both files and make sure they are the same.  If this is expected ignore, and set DebugFlags=NO_CONF_HASH in your slurm.conf.
[2022-09-22T14:00:25.575] error: Node gpu05 appears to have a different slurm.conf than the slurmctld.  This could cause issues with communication and functionality.  Please review both files and make sure they are the same.  If this is expected ignore, and set DebugFlags=NO_CONF_HASH in your slurm.conf.
[2022-09-22T14:00:25.575] error: Node gpu04 appears to have a different slurm.conf than the slurmctld.  This could cause issues with communication and functionality.  Please review both files and make sure they are the same.  If this is expected ignore, and set DebugFlags=NO_CONF_HASH in your slurm.conf.
[2022-09-22T14:00:25.576] error: Node cpu08 appears to have a different slurm.conf than the slurmctld.  This could cause issues with communication and functionality.  Please review both files and make sure they are the same.  If this is expected ignore, and set DebugFlags=NO_CONF_HASH in your slurm.conf.
[2022-09-22T14:00:26.567] SchedulerParameters=default_queue_depth=100,max_rpc_cnt=0,max_sched_time=2,partition_job_depth=0,sched_max_job_start=0,sched_min_interval=2
[2022-09-22T14:00:33.881] Processing Reconfiguration Request
[2022-09-22T14:00:33.888] restoring original state of nodes
[2022-09-22T14:00:33.888] select/cons_tres: part_data_create_array: select/cons_tres: preparing for 6 partitions
[2022-09-22T14:00:33.889] read_slurm_conf: backup_controller not specified
[2022-09-22T14:00:33.889] select/cons_tres: select_p_reconfigure: select/cons_tres: reconfigure
[2022-09-22T14:00:33.889] select/cons_tres: part_data_create_array: select/cons_tres: preparing for 6 partitions
[2022-09-22T14:00:33.889] No parameter for mcs plugin, default values set
[2022-09-22T14:00:33.889] mcs: MCSParameters = (null). ondemand set.
[2022-09-22T14:00:33.890] _slurm_rpc_reconfigure_controller: completed usec=9088
[2022-09-22T14:00:34.578] SchedulerParameters=default_queue_depth=100,max_rpc_cnt=0,max_sched_time=2,partition_job_depth=0,sched_max_job_start=0,sched_min_interval=2
[2022-09-22T14:01:55.589] _slurm_rpc_submit_batch_job: JobId=49477 InitPrio=15333 usec=693
[2022-09-22T14:01:55.692] sched: Allocate JobId=49477 NodeList=cpu07 #CPUs=32 Partition=cpu-opteron
[2022-09-22T14:01:56.125] error: slurmd error running JobId=49477 on node(s)=cpu07: Slurmd could not execve job
[2022-09-22T14:01:56.125] drain_nodes: node cpu07 state set to DRAIN
[2022-09-22T14:01:56.822] Requeuing JobId=49477
[2022-09-22T14:03:50.459] update_node: node cpu07 state set to IDLE
[2022-09-22T14:03:50.856] Node cpu07 now responding
[2022-09-22T14:04:06.412] _slurm_rpc_requeue: Requeue of JobId=49477 returned an error: Job is pending execution
[2022-09-22T14:04:14.397] sched: _release_job_rec: release hold on JobId=49477 by uid 0
[2022-09-22T14:04:14.397] _slurm_rpc_update_job: complete JobId=49477 uid=0 usec=984
[2022-09-22T14:04:14.881] sched: Allocate JobId=49477 NodeList=cpu07 #CPUs=32 Partition=cpu-opteron
[2022-09-22T14:04:15.087] error: slurmd error running JobId=49477 on node(s)=cpu07: Slurmd could not execve job
[2022-09-22T14:04:15.087] drain_nodes: node cpu07 state set to DRAIN
[2022-09-22T14:04:15.870] Requeuing JobId=49477
[2022-09-22T14:05:29.915] _slurm_rpc_submit_batch_job: JobId=49478 InitPrio=666 usec=575
[2022-09-22T14:05:30.279] sched: Allocate JobId=49478 NodeList=cpu12 #CPUs=48 Partition=cpu-epyc
[2022-09-22T14:05:31.291] _job_complete: JobId=49478 WEXITSTATUS 1
[2022-09-22T14:05:31.291] _job_complete: JobId=49478 done
[2022-09-22T14:05:48.793] Terminate signal (SIGINT or SIGTERM) received
[2022-09-22T14:05:48.884] Saving all slurm state
[2022-09-22T14:05:50.161] slurmctld version 21.08.8-2 started on cluster um-hpc
[2022-09-22T14:05:50.166] accounting_storage/slurmdbd: clusteracct_storage_p_register_ctld: Registering slurmctld at port 6817 with slurmdbd
[2022-09-22T14:05:50.704] Recovered state of 19 nodes
[2022-09-22T14:05:50.704] Down nodes: umhpc
[2022-09-22T14:05:50.705] Recovered JobId=48950 StepId=extern
[2022-09-22T14:05:50.705] Recovered JobId=48950 StepId=batch
[2022-09-22T14:05:50.705] Recovered JobId=48950 Assoc=20
[2022-09-22T14:05:50.705] Recovered JobId=49071 Assoc=23
[2022-09-22T14:05:50.705] Recovered JobId=49096 Assoc=183
[2022-09-22T14:05:50.705] Recovered JobId=49102 Assoc=20
[2022-09-22T14:05:50.705] Recovered JobId=49103 Assoc=20
[2022-09-22T14:05:50.705] Recovered JobId=49104 Assoc=20
[2022-09-22T14:05:50.705] Recovered JobId=49137 StepId=extern
[2022-09-22T14:05:50.705] Recovered JobId=49137 StepId=batch
[2022-09-22T14:05:50.705] Recovered JobId=49137 Assoc=20
[2022-09-22T14:05:50.705] Recovered JobId=49177 StepId=extern
[2022-09-22T14:05:50.705] Recovered JobId=49177 StepId=batch
[2022-09-22T14:05:50.705] Recovered JobId=49177 Assoc=238
[2022-09-22T14:05:50.705] Recovered JobId=49267 StepId=extern
[2022-09-22T14:05:50.705] Recovered JobId=49267 StepId=batch
[2022-09-22T14:05:50.705] Recovered JobId=49267 Assoc=238
[2022-09-22T14:05:50.705] Recovered JobId=49298 StepId=extern
[2022-09-22T14:05:50.705] Recovered JobId=49298 StepId=batch
[2022-09-22T14:05:50.705] Recovered JobId=49298 Assoc=23
[2022-09-22T14:05:50.705] Recovered JobId=49363 Assoc=204
[2022-09-22T14:05:50.705] Recovered JobId=49364 Assoc=204
[2022-09-22T14:05:50.705] Recovered JobId=49365 StepId=extern
[2022-09-22T14:05:50.705] Recovered JobId=49365 StepId=batch
[2022-09-22T14:05:50.705] Recovered JobId=49365 Assoc=67
[2022-09-22T14:05:50.706] Recovered JobId=49398 StepId=extern
[2022-09-22T14:05:50.706] Recovered JobId=49398 StepId=batch
[2022-09-22T14:05:50.706] Recovered JobId=49398 Assoc=32
[2022-09-22T14:05:50.706] Recovered JobId=49406 StepId=extern
[2022-09-22T14:05:50.706] Recovered JobId=49406 StepId=batch
[2022-09-22T14:05:50.706] Recovered JobId=49406 Assoc=23
[2022-09-22T14:05:50.706] Recovered JobId=49414 StepId=extern
[2022-09-22T14:05:50.706] Recovered JobId=49414 StepId=batch
[2022-09-22T14:05:50.706] Recovered JobId=49414 Assoc=19
[2022-09-22T14:05:50.706] Recovered JobId=49424 StepId=extern
[2022-09-22T14:05:50.706] Recovered JobId=49424 StepId=batch
[2022-09-22T14:05:50.706] Recovered JobId=49424 Assoc=32
[2022-09-22T14:05:50.706] Recovered JobId=49425 Assoc=32
[2022-09-22T14:05:50.706] Recovered JobId=49443 StepId=extern
[2022-09-22T14:05:50.706] Recovered JobId=49443 StepId=batch
[2022-09-22T14:05:50.706] Recovered JobId=49443 Assoc=48
[2022-09-22T14:05:50.706] Recovered JobId=49445 StepId=extern
[2022-09-22T14:05:50.706] Recovered JobId=49445 StepId=batch
[2022-09-22T14:05:50.706] Recovered JobId=49445 Assoc=19
[2022-09-22T14:05:50.706] Recovered JobId=49446 StepId=extern
[2022-09-22T14:05:50.706] Recovered JobId=49446 StepId=batch
[2022-09-22T14:05:50.706] Recovered JobId=49446 Assoc=19
[2022-09-22T14:05:50.706] Recovered JobId=49447 StepId=extern
[2022-09-22T14:05:50.706] Recovered JobId=49447 StepId=batch
[2022-09-22T14:05:50.706] Recovered JobId=49447 Assoc=211
[2022-09-22T14:05:50.706] Recovered JobId=49448 Assoc=32
[2022-09-22T14:05:50.707] Recovered JobId=49475 StepId=extern
[2022-09-22T14:05:50.707] Recovered JobId=49475 StepId=batch
[2022-09-22T14:05:50.707] Recovered JobId=49475 Assoc=211
[2022-09-22T14:05:50.707] Recovered JobId=49476 StepId=extern
[2022-09-22T14:05:50.707] Recovered JobId=49476 StepId=batch
[2022-09-22T14:05:50.707] Recovered JobId=49476 Assoc=211
[2022-09-22T14:05:50.707] Recovered JobId=49477 Assoc=180
[2022-09-22T14:05:50.707] Recovered JobId=49478 Assoc=23
[2022-09-22T14:05:50.707] Recovered information about 27 jobs
[2022-09-22T14:05:50.707] select/cons_tres: part_data_create_array: select/cons_tres: preparing for 6 partitions
[2022-09-22T14:05:50.707] error: valid_job_resources: cpu07 sockets:8,4, cores 8,8
[2022-09-22T14:05:50.707] error: Aborting JobId=49477 due to change in socket/core configuration of allocated nodes
[2022-09-22T14:05:50.708] Recovered state of reservation opteron_hyperthread
[2022-09-22T14:05:50.708] Recovered state of 1 reservations
[2022-09-22T14:05:50.708] read_slurm_conf: backup_controller not specified
[2022-09-22T14:05:50.708] select/cons_tres: select_p_reconfigure: select/cons_tres: reconfigure
[2022-09-22T14:05:50.708] select/cons_tres: part_data_create_array: select/cons_tres: preparing for 6 partitions
[2022-09-22T14:05:50.709] Running as primary controller
[2022-09-22T14:05:51.000] No parameter for mcs plugin, default values set
[2022-09-22T14:05:51.000] mcs: MCSParameters = (null). ondemand set.
[2022-09-22T14:05:53.041] Processing Reconfiguration Request
[2022-09-22T14:05:53.048] restoring original state of nodes
[2022-09-22T14:05:53.048] select/cons_tres: part_data_create_array: select/cons_tres: preparing for 6 partitions
[2022-09-22T14:05:53.049] read_slurm_conf: backup_controller not specified
[2022-09-22T14:05:53.049] select/cons_tres: select_p_reconfigure: select/cons_tres: reconfigure
[2022-09-22T14:05:53.049] select/cons_tres: part_data_create_array: select/cons_tres: preparing for 6 partitions
[2022-09-22T14:05:53.049] No parameter for mcs plugin, default values set
[2022-09-22T14:05:53.049] mcs: MCSParameters = (null). ondemand set.
[2022-09-22T14:05:53.050] _slurm_rpc_reconfigure_controller: completed usec=8847
[2022-09-22T14:05:54.005] SchedulerParameters=default_queue_depth=100,max_rpc_cnt=0,max_sched_time=2,partition_job_depth=0,sched_max_job_start=0,sched_min_interval=2
[2022-09-22T14:05:56.651] _slurm_rpc_submit_batch_job: JobId=49479 InitPrio=666 usec=633
[2022-09-22T14:05:57.010] sched: Allocate JobId=49479 NodeList=cpu12 #CPUs=48 Partition=cpu-epyc
[2022-09-22T14:06:22.505] update_node: node cpu07 state set to IDLE
[2022-09-22T14:06:23.052] Node cpu07 now responding
[2022-09-22T14:06:58.570] _slurm_rpc_submit_batch_job: JobId=49480 InitPrio=15333 usec=412
[2022-09-22T14:06:59.095] sched: Allocate JobId=49480 NodeList=cpu07 #CPUs=32 Partition=cpu-opteron
[2022-09-22T14:06:59.337] error: slurmd error running JobId=49480 on node(s)=cpu07: Slurmd could not execve job
[2022-09-22T14:06:59.337] drain_nodes: node cpu07 state set to DRAIN
[2022-09-22T14:07:00.208] Requeuing JobId=49480
[2022-09-22T14:10:43.400] error: Nodes cpu07 not responding, setting DOWN
[2022-09-22T14:13:45.388] Node cpu07 now responding
[2022-09-22T14:13:45.388] node cpu07 returned to service
[2022-09-22T14:15:18.766] update_node: node cpu07 state set to IDLE
[2022-09-22T14:15:18.891] Node cpu07 now responding
[2022-09-22T14:15:31.288] sched: _release_job_rec: release hold on JobId=49480 by uid 548200003
[2022-09-22T14:15:31.288] _slurm_rpc_update_job: complete JobId=49480 uid=548200003 usec=942
[2022-09-22T14:15:31.820] _job_complete: JobId=49479 WEXITSTATUS 1
[2022-09-22T14:15:31.821] _job_complete: JobId=49479 done
[2022-09-22T14:15:31.899] sched: Allocate JobId=49480 NodeList=cpu07 #CPUs=32 Partition=cpu-opteron
[2022-09-22T14:16:08.550] _slurm_rpc_delete_reservation reservation=opteron_hyperthread: Requested reservation is in use
[2022-09-22T14:16:19.146] _slurm_rpc_kill_job: REQUEST_KILL_JOB JobId=49480 uid 548200003
[2022-09-22T14:16:20.537] _slurm_rpc_delete_reservation complete for opteron_hyperthread usec=58
[2022-09-22T14:42:14.816] _slurm_rpc_submit_batch_job: JobId=49481 InitPrio=666 usec=477
[2022-09-22T14:42:15.591] sched: Allocate JobId=49481 NodeList=cpu12 #CPUs=48 Partition=cpu-epyc
[2022-09-22T15:01:29.286] _job_complete: JobId=49475 WEXITSTATUS 102
[2022-09-22T15:01:29.288] _job_complete: JobId=49475 done
[2022-09-22T15:12:23.318] _slurm_rpc_submit_batch_job: JobId=49482 InitPrio=666 usec=520
[2022-09-22T15:12:23.695] sched: Allocate JobId=49482 NodeList=cpu03 #CPUs=32 Partition=cpu-opteron
[2022-09-22T15:15:51.024] _slurm_rpc_submit_batch_job: JobId=49483 InitPrio=666 usec=468
[2022-09-22T15:15:52.019] sched: Allocate JobId=49483 NodeList=cpu09 #CPUs=32 Partition=cpu-opteron
[2022-09-22T15:16:50.047] _job_complete: JobId=49483 WEXITSTATUS 0
[2022-09-22T15:16:50.047] _job_complete: JobId=49483 done
[2022-09-22T15:18:58.166] _job_complete: JobId=49482 WEXITSTATUS 0
[2022-09-22T15:18:58.166] _job_complete: JobId=49482 done
[2022-09-22T15:20:47.412] _slurm_rpc_submit_batch_job: JobId=49484 InitPrio=666 usec=485
[2022-09-22T15:20:47.471] sched: Allocate JobId=49484 NodeList=cpu15 #CPUs=48 Partition=cpu-epyc
[2022-09-22T15:36:07.678] _job_complete: JobId=49484 WEXITSTATUS 0
[2022-09-22T15:36:07.679] _job_complete: JobId=49484 done
[2022-09-22T15:43:31.805] _slurm_rpc_submit_batch_job: JobId=49485 InitPrio=2888 usec=507
[2022-09-22T15:43:32.793] sched: Allocate JobId=49485 NodeList=cpu14 #CPUs=8 Partition=cpu-epyc
[2022-09-22T15:43:34.260] _slurm_rpc_submit_batch_job: JobId=49486 InitPrio=2888 usec=400
[2022-09-22T15:43:35.781] sched: Allocate JobId=49486 NodeList=cpu14 #CPUs=8 Partition=cpu-epyc
[2022-09-22T15:43:36.297] _slurm_rpc_submit_batch_job: JobId=49487 InitPrio=2888 usec=488
[2022-09-22T15:43:38.305] _slurm_rpc_submit_batch_job: JobId=49488 InitPrio=2888 usec=577
[2022-09-22T15:43:38.785] sched: Allocate JobId=49487 NodeList=cpu14 #CPUs=8 Partition=cpu-epyc
[2022-09-22T15:43:38.786] sched: Allocate JobId=49488 NodeList=cpu15 #CPUs=8 Partition=cpu-epyc
[2022-09-22T15:43:40.105] _slurm_rpc_submit_batch_job: JobId=49489 InitPrio=2888 usec=394
[2022-09-22T15:43:41.789] sched: Allocate JobId=49489 NodeList=cpu15 #CPUs=8 Partition=cpu-epyc
[2022-09-22T15:43:41.929] _slurm_rpc_submit_batch_job: JobId=49490 InitPrio=2888 usec=401
[2022-09-22T15:43:43.769] _slurm_rpc_submit_batch_job: JobId=49491 InitPrio=2888 usec=440
[2022-09-22T15:43:44.794] sched: Allocate JobId=49490 NodeList=cpu15 #CPUs=8 Partition=cpu-epyc
[2022-09-22T15:43:44.794] sched: Allocate JobId=49491 NodeList=cpu15 #CPUs=8 Partition=cpu-epyc
[2022-09-22T15:43:45.801] _slurm_rpc_submit_batch_job: JobId=49492 InitPrio=2888 usec=451
[2022-09-22T15:43:47.798] sched: Allocate JobId=49492 NodeList=cpu15 #CPUs=8 Partition=cpu-epyc
[2022-09-22T16:04:30.806] _slurm_rpc_submit_batch_job: JobId=49493 InitPrio=12888 usec=517
[2022-09-22T16:04:30.948] sched: Allocate JobId=49493 NodeList=cpu15 #CPUs=8 Partition=cpu-epyc
[2022-09-22T16:04:32.914] _slurm_rpc_submit_batch_job: JobId=49494 InitPrio=12888 usec=453
[2022-09-22T16:04:34.986] _slurm_rpc_submit_batch_job: JobId=49495 InitPrio=12888 usec=418
[2022-09-22T16:07:47.598] _job_complete: JobId=49493 WEXITSTATUS 0
[2022-09-22T16:07:47.599] _job_complete: JobId=49493 done
[2022-09-22T16:07:47.946] sched: Allocate JobId=49494 NodeList=cpu15 #CPUs=8 Partition=cpu-epyc
[2022-09-22T16:11:05.738] _job_complete: JobId=49494 WEXITSTATUS 0
[2022-09-22T16:11:05.739] _job_complete: JobId=49494 done
[2022-09-22T16:11:06.058] sched: Allocate JobId=49495 NodeList=cpu15 #CPUs=8 Partition=cpu-epyc
[2022-09-22T16:14:30.771] _job_complete: JobId=49495 WEXITSTATUS 0
[2022-09-22T16:14:30.771] _job_complete: JobId=49495 done
[2022-09-22T16:25:35.842] _slurm_rpc_submit_batch_job: JobId=49496 InitPrio=2222 usec=404
[2022-09-22T16:25:36.090] sched: Allocate JobId=49496 NodeList=cpu07 #CPUs=35 Partition=cpu-opteron
[2022-09-22T17:08:21.893] Time limit exhausted for JobId=48950
[2022-09-22T17:08:23.987] sched: Allocate JobId=49363 NodeList=gpu05 #CPUs=32 Partition=gpu-v100s
[2022-09-22T17:29:49.507] _job_complete: JobId=49491 WEXITSTATUS 0
[2022-09-22T17:29:49.507] _job_complete: JobId=49491 done
[2022-09-22T17:34:45.705] _slurm_rpc_submit_batch_job: JobId=49497 InitPrio=1777 usec=1039
[2022-09-22T17:35:19.942] _job_complete: JobId=49487 WEXITSTATUS 0
[2022-09-22T17:35:19.942] _job_complete: JobId=49487 done
[2022-09-22T17:35:45.019] _slurm_rpc_kill_job: REQUEST_KILL_JOB JobId=49425 uid 548200029
[2022-09-22T17:35:49.997] _job_complete: JobId=49486 WEXITSTATUS 0
[2022-09-22T17:35:49.997] _job_complete: JobId=49486 done
[2022-09-22T17:35:53.291] _slurm_rpc_kill_job: REQUEST_KILL_JOB JobId=49424 uid 548200029
[2022-09-22T17:35:55.779] sched: Allocate JobId=49448 NodeList=gpu03 #CPUs=16 Partition=gpu-k10
[2022-09-22T17:35:58.986] _slurm_rpc_kill_job: REQUEST_KILL_JOB JobId=49398 uid 548200029
[2022-09-22T17:36:03.809] sched: Allocate JobId=49497 NodeList=gpu01 #CPUs=16 Partition=gpu-k10
[2022-09-22T17:36:31.044] _job_complete: JobId=49488 WEXITSTATUS 0
[2022-09-22T17:36:31.044] _job_complete: JobId=49488 done
[2022-09-22T17:36:56.887] _job_complete: JobId=49496 WEXITSTATUS 2
[2022-09-22T17:36:56.888] _job_complete: JobId=49496 done
[2022-09-22T17:37:03.205] _job_complete: JobId=49492 WEXITSTATUS 0
[2022-09-22T17:37:03.206] _job_complete: JobId=49492 done
[2022-09-22T17:38:00.828] _job_complete: JobId=49490 WEXITSTATUS 0
[2022-09-22T17:38:00.828] _job_complete: JobId=49490 done
[2022-09-22T17:39:17.904] _slurm_rpc_submit_batch_job: JobId=49498 InitPrio=2000 usec=418
[2022-09-22T17:39:18.068] sched: Allocate JobId=49498 NodeList=cpu07 #CPUs=35 Partition=cpu-opteron
[2022-09-22T17:39:18.600] _job_complete: JobId=49498 WEXITSTATUS 2
[2022-09-22T17:39:18.601] _job_complete: JobId=49498 done
[2022-09-22T17:40:12.735] _slurm_rpc_submit_batch_job: JobId=49499 InitPrio=2000 usec=748
[2022-09-22T17:40:13.141] sched: Allocate JobId=49499 NodeList=cpu07 #CPUs=35 Partition=cpu-opteron
[2022-09-22T17:40:13.658] _job_complete: JobId=49499 WEXITSTATUS 2
[2022-09-22T17:40:13.659] _job_complete: JobId=49499 done
[2022-09-22T17:40:24.467] _slurm_rpc_kill_job: REQUEST_KILL_JOB JobId=49499 uid 548300593
[2022-09-22T17:41:20.684] _slurm_rpc_kill_job: REQUEST_KILL_JOB JobId=49498 uid 548300593
[2022-09-22T17:41:25.700] _slurm_rpc_submit_batch_job: JobId=49500 InitPrio=2000 usec=388
[2022-09-22T17:41:26.307] sched: Allocate JobId=49500 NodeList=cpu07 #CPUs=35 Partition=cpu-opteron
[2022-09-22T17:41:26.820] _job_complete: JobId=49500 WEXITSTATUS 2
[2022-09-22T17:41:26.820] _job_complete: JobId=49500 done
[2022-09-22T17:43:51.879] _slurm_rpc_submit_batch_job: JobId=49501 InitPrio=2000 usec=401
[2022-09-22T17:43:54.516] sched: Allocate JobId=49501 NodeList=cpu07 #CPUs=35 Partition=cpu-opteron
[2022-09-22T17:45:23.099] _job_complete: JobId=49485 WEXITSTATUS 0
[2022-09-22T17:45:23.099] _job_complete: JobId=49485 done
[2022-09-22T17:51:58.298] _job_complete: JobId=49363 WEXITSTATUS 1
[2022-09-22T17:51:58.299] _job_complete: JobId=49363 done
[2022-09-22T17:52:08.450] sched: Allocate JobId=49364 NodeList=gpu05 #CPUs=32 Partition=gpu-v100s
[2022-09-22T17:52:08.743] _job_complete: JobId=49364 WEXITSTATUS 1
[2022-09-22T17:52:08.744] _job_complete: JobId=49364 done
[2022-09-22T17:52:09.110] sched: Allocate JobId=49071 NodeList=gpu05 #CPUs=12 Partition=gpu-v100s
[2022-09-22T17:52:09.134] sched: Allocate JobId=49096 NodeList=gpu05 #CPUs=8 Partition=gpu-v100s
[2022-09-22T17:59:39.028] _job_complete: JobId=49489 WEXITSTATUS 0
[2022-09-22T17:59:39.028] _job_complete: JobId=49489 done
[2022-09-22T18:53:21.181] _slurm_rpc_submit_batch_job: JobId=49502 InitPrio=666 usec=487
[2022-09-22T18:53:21.582] Time limit exhausted for JobId=49137
[2022-09-22T18:53:21.588] sched: Allocate JobId=49502 NodeList=cpu03 #CPUs=32 Partition=cpu-opteron
[2022-09-22T19:13:25.383] _job_complete: JobId=49501 WEXITSTATUS 102
[2022-09-22T19:13:25.389] _job_complete: JobId=49501 done
[2022-09-22T19:14:15.220] _job_complete: JobId=49502 WEXITSTATUS 0
[2022-09-22T19:14:15.220] _job_complete: JobId=49502 done
[2022-09-22T22:12:42.768] _slurm_rpc_submit_batch_job: JobId=49503 InitPrio=2000 usec=517
[2022-09-22T22:12:43.656] sched: Allocate JobId=49503 NodeList=cpu07 #CPUs=35 Partition=cpu-opteron
[2022-09-23T01:27:10.728] _job_complete: JobId=49503 WEXITSTATUS 0
[2022-09-23T01:27:10.733] _job_complete: JobId=49503 done
[2022-09-23T02:22:26.335] _job_complete: JobId=49448 WEXITSTATUS 1
[2022-09-23T02:22:26.340] _job_complete: JobId=49448 done
[2022-09-23T04:24:38.027] _job_complete: JobId=49481 WEXITSTATUS 1
[2022-09-23T04:24:38.028] _job_complete: JobId=49481 done
[2022-09-23T06:34:39.834] _job_create: exceeded association/QOS limit for user 548200045: AssocGrpCpuLimit
[2022-09-23T06:34:39.834] _slurm_rpc_submit_batch_job: Job violates accounting/QOS policy (job submit limit, user's size and/or time limits)
[2022-09-23T08:33:46.428] _job_complete: JobId=49298 WEXITSTATUS 1
[2022-09-23T08:33:46.428] _job_complete: JobId=49298 done
[2022-09-23T10:53:15.038] _job_complete: JobId=49497 WEXITSTATUS 1
[2022-09-23T10:53:15.043] _job_complete: JobId=49497 done
[2022-09-23T10:55:01.342] _slurm_rpc_submit_batch_job: JobId=49504 InitPrio=2444 usec=528
[2022-09-23T10:55:01.915] sched: Allocate JobId=49504 NodeList=cpu03 #CPUs=8 Partition=cpu-opteron
[2022-09-23T10:55:06.150] _slurm_rpc_submit_batch_job: JobId=49505 InitPrio=2444 usec=478
[2022-09-23T10:55:06.907] sched: Allocate JobId=49505 NodeList=cpu03 #CPUs=8 Partition=cpu-opteron
[2022-09-23T10:55:09.547] _slurm_rpc_submit_batch_job: JobId=49506 InitPrio=2444 usec=540
[2022-09-23T10:55:09.911] sched: Allocate JobId=49506 NodeList=cpu03 #CPUs=8 Partition=cpu-opteron
[2022-09-23T10:55:12.470] _slurm_rpc_submit_batch_job: JobId=49507 InitPrio=2444 usec=432
[2022-09-23T10:55:12.915] sched: Allocate JobId=49507 NodeList=cpu03 #CPUs=8 Partition=cpu-opteron
[2022-09-23T10:55:15.261] _slurm_rpc_submit_batch_job: JobId=49508 InitPrio=2444 usec=554
[2022-09-23T10:55:15.919] sched: Allocate JobId=49508 NodeList=cpu09 #CPUs=8 Partition=cpu-opteron
[2022-09-23T10:55:18.427] _slurm_rpc_submit_batch_job: JobId=49509 InitPrio=2444 usec=550
[2022-09-23T10:55:18.923] sched: Allocate JobId=49509 NodeList=cpu09 #CPUs=8 Partition=cpu-opteron
[2022-09-23T11:45:02.338] _slurm_rpc_submit_batch_job: JobId=49510 InitPrio=2444 usec=548
[2022-09-23T11:45:03.038] sched: Allocate JobId=49510 NodeList=cpu09 #CPUs=8 Partition=cpu-opteron
[2022-09-23T11:45:05.515] _slurm_rpc_submit_batch_job: JobId=49511 InitPrio=2444 usec=628
[2022-09-23T11:45:06.038] sched: Allocate JobId=49511 NodeList=cpu09 #CPUs=8 Partition=cpu-opteron
[2022-09-23T11:45:08.418] _slurm_rpc_submit_batch_job: JobId=49512 InitPrio=2444 usec=453
[2022-09-23T11:45:09.042] sched: Allocate JobId=49512 NodeList=cpu11 #CPUs=8 Partition=cpu-opteron
[2022-09-23T11:45:11.186] _slurm_rpc_submit_batch_job: JobId=49513 InitPrio=2444 usec=425
[2022-09-23T11:45:12.046] sched: Allocate JobId=49513 NodeList=cpu11 #CPUs=8 Partition=cpu-opteron
[2022-09-23T11:45:14.266] _slurm_rpc_submit_batch_job: JobId=49514 InitPrio=2444 usec=463
[2022-09-23T11:45:15.051] sched: Allocate JobId=49514 NodeList=cpu11 #CPUs=8 Partition=cpu-opteron
[2022-09-23T11:45:16.963] _slurm_rpc_submit_batch_job: JobId=49515 InitPrio=2444 usec=477
[2022-09-23T11:45:18.055] sched: Allocate JobId=49515 NodeList=cpu11 #CPUs=8 Partition=cpu-opteron
[2022-09-23T11:45:20.171] _slurm_rpc_submit_batch_job: JobId=49516 InitPrio=2444 usec=479
[2022-09-23T11:45:21.059] sched: Allocate JobId=49516 NodeList=cpu11 #CPUs=8 Partition=cpu-opteron
[2022-09-23T11:45:23.004] _slurm_rpc_submit_batch_job: JobId=49517 InitPrio=2444 usec=421
[2022-09-23T11:45:24.064] sched: Allocate JobId=49517 NodeList=cpu11 #CPUs=8 Partition=cpu-opteron
[2022-09-23T11:45:26.283] _slurm_rpc_submit_batch_job: JobId=49518 InitPrio=2444 usec=443
[2022-09-23T11:45:27.068] sched: Allocate JobId=49518 NodeList=cpu05 #CPUs=8 Partition=cpu-opteron
[2022-09-23T11:45:32.018] _slurm_rpc_submit_batch_job: JobId=49519 InitPrio=2444 usec=465
[2022-09-23T11:45:32.075] sched: Allocate JobId=49519 NodeList=cpu07 #CPUs=8 Partition=cpu-opteron
[2022-09-23T11:45:35.587] _slurm_rpc_submit_batch_job: JobId=49520 InitPrio=2444 usec=484
[2022-09-23T11:45:36.080] sched: Allocate JobId=49520 NodeList=cpu07 #CPUs=8 Partition=cpu-opteron
[2022-09-23T11:45:38.930] _slurm_rpc_submit_batch_job: JobId=49521 InitPrio=2444 usec=449
[2022-09-23T11:45:39.084] sched: Allocate JobId=49521 NodeList=cpu07 #CPUs=8 Partition=cpu-opteron
[2022-09-23T11:45:42.226] _slurm_rpc_submit_batch_job: JobId=49522 InitPrio=2444 usec=504
[2022-09-23T11:45:43.089] sched: Allocate JobId=49522 NodeList=cpu07 #CPUs=8 Partition=cpu-opteron
[2022-09-23T11:45:45.106] _slurm_rpc_submit_batch_job: JobId=49523 InitPrio=2444 usec=435
[2022-09-23T11:45:46.093] sched: Allocate JobId=49523 NodeList=cpu07 #CPUs=8 Partition=cpu-opteron
[2022-09-23T11:45:47.818] _slurm_rpc_submit_batch_job: JobId=49524 InitPrio=2444 usec=524
[2022-09-23T11:45:49.097] sched: Allocate JobId=49524 NodeList=cpu07 #CPUs=8 Partition=cpu-opteron
[2022-09-23T11:45:50.795] _slurm_rpc_submit_batch_job: JobId=49525 InitPrio=2444 usec=476
[2022-09-23T11:45:52.101] sched: Allocate JobId=49525 NodeList=cpu07 #CPUs=8 Partition=cpu-opteron
[2022-09-23T11:45:53.731] _slurm_rpc_submit_batch_job: JobId=49526 InitPrio=2444 usec=430
[2022-09-23T11:45:56.387] _slurm_rpc_submit_batch_job: JobId=49527 InitPrio=2444 usec=575
[2022-09-23T11:45:59.138] _slurm_rpc_submit_batch_job: JobId=49528 InitPrio=2444 usec=424
[2022-09-23T11:46:03.290] _slurm_rpc_submit_batch_job: JobId=49529 InitPrio=2444 usec=369
[2022-09-23T11:46:06.242] _slurm_rpc_submit_batch_job: JobId=49530 InitPrio=2444 usec=502
[2022-09-23T11:46:08.852] _slurm_rpc_submit_batch_job: JobId=49531 InitPrio=2444 usec=436
[2022-09-23T11:46:11.705] _slurm_rpc_submit_batch_job: JobId=49532 InitPrio=2444 usec=469
[2022-09-23T11:46:14.479] _slurm_rpc_submit_batch_job: JobId=49533 InitPrio=2444 usec=467
[2022-09-23T11:48:23.773] Node umhpc now responding
[2022-09-23T11:48:23.773] node umhpc returned to service
[2022-09-23T11:50:01.529] error: Nodes umhpc not responding, setting DOWN
[2022-09-23T11:59:27.741] _job_create: exceeded association/QOS limit for user 548200021: QOSMaxWallDurationPerJobLimit
[2022-09-23T11:59:27.741] _slurm_rpc_submit_batch_job: Job violates accounting/QOS policy (job submit limit, user's size and/or time limits)
[2022-09-23T11:59:43.758] _slurm_rpc_submit_batch_job: JobId=49534 InitPrio=444 usec=423
[2022-09-23T11:59:44.543] sched: Allocate JobId=49534 NodeList=gpu02 #CPUs=8 Partition=gpu-titan
[2022-09-23T13:56:42.880] _slurm_rpc_submit_batch_job: JobId=49535 InitPrio=15333 usec=574
[2022-09-23T13:56:49.308] _slurm_rpc_submit_batch_job: JobId=49536 InitPrio=15333 usec=384
[2022-09-23T14:11:01.791] _slurm_rpc_submit_batch_job: JobId=49537 InitPrio=666 usec=494
[2022-09-23T14:11:02.409] sched: Allocate JobId=49537 NodeList=cpu15 #CPUs=48 Partition=cpu-epyc
[2022-09-23T14:11:10.418] _job_complete: JobId=49537 WEXITSTATUS 1
[2022-09-23T14:11:10.418] _job_complete: JobId=49537 done
[2022-09-23T14:17:14.934] _slurm_rpc_submit_batch_job: JobId=49538 InitPrio=666 usec=490
[2022-09-23T14:17:15.048] sched: Allocate JobId=49538 NodeList=cpu15 #CPUs=48 Partition=cpu-epyc
[2022-09-23T14:18:32.681] _slurm_rpc_kill_job: REQUEST_KILL_JOB JobId=49538 uid 548200023
[2022-09-23T14:19:06.591] _slurm_rpc_submit_batch_job: JobId=49539 InitPrio=666 usec=550
[2022-09-23T14:19:07.197] sched: Allocate JobId=49539 NodeList=cpu15 #CPUs=48 Partition=cpu-epyc
[2022-09-23T14:19:10.942] _job_complete: JobId=49539 WEXITSTATUS 1
[2022-09-23T14:19:10.942] _job_complete: JobId=49539 done
[2022-09-23T14:19:56.992] _slurm_rpc_submit_batch_job: JobId=49540 InitPrio=666 usec=476
[2022-09-23T14:19:58.268] sched: Allocate JobId=49540 NodeList=cpu15 #CPUs=48 Partition=cpu-epyc
[2022-09-23T14:20:06.144] _job_complete: JobId=49540 WEXITSTATUS 1
[2022-09-23T14:20:06.144] _job_complete: JobId=49540 done
[2022-09-23T14:20:35.990] _job_complete: JobId=49177 WEXITSTATUS 1
[2022-09-23T14:20:35.990] _job_complete: JobId=49177 done
[2022-09-23T14:20:38.498] sched: Allocate JobId=49526 NodeList=cpu08 #CPUs=8 Partition=cpu-opteron
[2022-09-23T14:20:38.499] sched: Allocate JobId=49527 NodeList=cpu08 #CPUs=8 Partition=cpu-opteron
[2022-09-23T14:20:38.500] sched: Allocate JobId=49528 NodeList=cpu08 #CPUs=8 Partition=cpu-opteron
[2022-09-23T14:20:38.500] sched: Allocate JobId=49529 NodeList=cpu08 #CPUs=8 Partition=cpu-opteron
[2022-09-23T14:20:38.501] sched: Allocate JobId=49530 NodeList=cpu08 #CPUs=8 Partition=cpu-opteron
[2022-09-23T14:20:38.502] sched: Allocate JobId=49531 NodeList=cpu08 #CPUs=8 Partition=cpu-opteron
[2022-09-23T14:20:38.502] sched: Allocate JobId=49532 NodeList=cpu08 #CPUs=8 Partition=cpu-opteron
[2022-09-23T14:55:23.325] sched: _slurm_rpc_allocate_resources JobId=49541 NodeList=(null) usec=1084
[2022-09-23T14:55:24.000] sched: Allocate JobId=49541 NodeList=cpu14 #CPUs=16 Partition=cpu-epyc
[2022-09-23T15:07:09.561] sched: _slurm_rpc_allocate_resources JobId=49542 NodeList=(null) usec=1040
[2022-09-23T15:07:10.361] sched: Allocate JobId=49542 NodeList=cpu15 #CPUs=16 Partition=cpu-epyc
[2022-09-23T15:23:23.929] _slurm_rpc_kill_job: REQUEST_KILL_JOB JobId=49541 uid 548300543
[2022-09-23T15:23:42.422] _slurm_rpc_kill_job: REQUEST_KILL_JOB JobId=49542 uid 548300543
[2022-09-23T15:24:21.134] _get_job_parts: invalid partition specified: cppu-epyc
[2022-09-23T15:24:21.135] _slurm_rpc_allocate_resources: Invalid partition name specified 
[2022-09-23T15:24:28.307] sched: _slurm_rpc_allocate_resources JobId=49543 NodeList=(null) usec=858
[2022-09-23T15:24:29.067] sched: Allocate JobId=49543 NodeList=cpu14 #CPUs=16 Partition=cpu-epyc
[2022-09-23T16:16:04.131] _job_complete: JobId=49543 WEXITSTATUS 0
[2022-09-23T16:16:04.132] _job_complete: JobId=49543 done
[2022-09-23T16:17:40.897] sched: _slurm_rpc_allocate_resources JobId=49544 NodeList=(null) usec=1351
[2022-09-23T16:17:41.249] sched: Allocate JobId=49544 NodeList=cpu14 #CPUs=16 Partition=cpu-epyc
[2022-09-23T16:22:20.785] _slurm_rpc_kill_job: REQUEST_KILL_JOB JobId=49544 uid 548300543
[2022-09-23T16:23:04.752] sched: _slurm_rpc_allocate_resources JobId=49545 NodeList=(null) usec=796
[2022-09-23T16:23:04.869] sched: Allocate JobId=49545 NodeList=cpu07 #CPUs=4 Partition=cpu-opteron
[2022-09-23T16:23:47.723] _slurm_rpc_kill_job: REQUEST_KILL_JOB JobId=49545 uid 548300543
[2022-09-23T16:24:27.806] sched: _slurm_rpc_allocate_resources JobId=49546 NodeList=(null) usec=1287
[2022-09-23T16:24:27.982] sched: Allocate JobId=49546 NodeList=cpu07 #CPUs=8 Partition=cpu-opteron
[2022-09-23T16:25:33.894] _slurm_rpc_kill_job: REQUEST_KILL_JOB JobId=49546 uid 548300543
[2022-09-23T16:25:58.785] sched: _slurm_rpc_allocate_resources JobId=49547 NodeList=(null) usec=846
[2022-09-23T16:25:59.223] sched: Allocate JobId=49547 NodeList=cpu07 #CPUs=4 Partition=cpu-opteron
[2022-09-23T16:26:25.727] _slurm_rpc_kill_job: REQUEST_KILL_JOB JobId=49547 uid 548300543
[2022-09-23T16:27:02.762] sched: _slurm_rpc_allocate_resources JobId=49548 NodeList=(null) usec=1029
[2022-09-23T16:27:03.309] sched: Allocate JobId=49548 NodeList=cpu04 #CPUs=4 Partition=cpu-opteron
[2022-09-23T16:29:44.805] Reservation name not found (opteron_hyperthread)
[2022-09-23T16:29:44.806] _slurm_rpc_submit_batch_job: Requested reservation is invalid
[2022-09-23T16:29:55.333] _slurm_rpc_submit_batch_job: JobId=49550 InitPrio=15111 usec=504
[2022-09-23T16:30:13.355] _slurm_rpc_kill_job: REQUEST_KILL_JOB JobId=49548 uid 548300543
[2022-09-23T16:30:23.282] _slurm_rpc_kill_job: REQUEST_KILL_JOB JobId=49550 uid 548300543
[2022-09-23T16:30:44.254] _slurm_rpc_submit_batch_job: JobId=49551 InitPrio=15111 usec=542
[2022-09-23T16:30:44.609] sched: Allocate JobId=49551 NodeList=cpu07 #CPUs=8 Partition=cpu-opteron
[2022-09-23T16:31:43.517] _slurm_rpc_kill_job: REQUEST_KILL_JOB JobId=49551 uid 548300543
[2022-09-23T16:49:43.802] _slurm_rpc_submit_batch_job: JobId=49552 InitPrio=1777 usec=429
[2022-09-23T16:52:45.217] sched: _slurm_rpc_allocate_resources JobId=49553 NodeList=(null) usec=923
[2022-09-23T16:52:45.919] sched: Allocate JobId=49553 NodeList=cpu07 #CPUs=4 Partition=cpu-opteron
[2022-09-23T16:53:01.697] sched: _slurm_rpc_allocate_resources JobId=49554 NodeList=(null) usec=1028
[2022-09-23T16:53:01.944] sched: Allocate JobId=49554 NodeList=cpu08 #CPUs=4 Partition=cpu-opteron
[2022-09-23T16:53:20.640] _job_complete: JobId=49553 WEXITSTATUS 0
[2022-09-23T16:53:20.640] _job_complete: JobId=49553 done
[2022-09-23T16:54:42.142] _slurm_rpc_kill_job: REQUEST_KILL_JOB JobId=49554 uid 548300543
[2022-09-23T16:57:33.779] sched: _slurm_rpc_allocate_resources JobId=49555 NodeList=(null) usec=836
[2022-09-23T16:57:34.445] sched: Allocate JobId=49555 NodeList=cpu07 #CPUs=4 Partition=cpu-opteron
[2022-09-23T16:58:36.584] _job_complete: JobId=49555 WEXITSTATUS 0
[2022-09-23T16:58:36.584] _job_complete: JobId=49555 done
[2022-09-23T17:01:22.083] _slurm_rpc_submit_batch_job: JobId=49556 InitPrio=222 usec=374
[2022-09-23T17:01:22.862] sched: Allocate JobId=49556 NodeList=cpu15 #CPUs=48 Partition=cpu-epyc
[2022-09-23T17:11:57.653] _job_complete: JobId=49556 WEXITSTATUS 0
[2022-09-23T17:11:57.654] _job_complete: JobId=49556 done
[2022-09-23T17:22:42.114] _slurm_rpc_submit_batch_job: JobId=49557 InitPrio=49111 usec=454
[2022-09-23T17:22:42.353] sched: Allocate JobId=49557 NodeList=cpu15 #CPUs=24 Partition=cpu-epyc
[2022-09-23T17:22:44.164] _job_complete: JobId=49557 WEXITSTATUS 0
[2022-09-23T17:22:44.164] _job_complete: JobId=49557 done
[2022-09-23T17:36:43.695] _slurm_rpc_submit_batch_job: JobId=49558 InitPrio=10888 usec=617
[2022-09-23T17:38:01.701] _slurm_rpc_kill_job: REQUEST_KILL_JOB JobId=49558 uid 548300584
[2022-09-23T17:39:12.198] _slurm_rpc_submit_batch_job: JobId=49559 InitPrio=10888 usec=648
[2022-09-23T17:39:13.005] sched: Allocate JobId=49559 NodeList=gpu01 #CPUs=2 Partition=gpu-k10
[2022-09-23T17:39:25.243] _job_complete: JobId=49559 WEXITSTATUS 0
[2022-09-23T17:39:25.243] _job_complete: JobId=49559 done
[2022-09-23T17:46:13.014] _slurm_rpc_submit_batch_job: JobId=49560 InitPrio=10666 usec=584
[2022-09-23T17:46:13.789] sched: Allocate JobId=49560 NodeList=cpu14 #CPUs=4 Partition=cpu-epyc
[2022-09-23T17:46:15.263] _job_complete: JobId=49560 WEXITSTATUS 0
[2022-09-23T17:46:15.263] _job_complete: JobId=49560 done
[2022-09-23T18:06:00.885] _slurm_rpc_submit_batch_job: JobId=49561 InitPrio=10666 usec=450
[2022-09-23T18:06:00.904] sched: Allocate JobId=49561 NodeList=cpu15 #CPUs=24 Partition=cpu-epyc
[2022-09-23T18:06:02.080] _job_complete: JobId=49561 WEXITSTATUS 0
[2022-09-23T18:06:02.080] _job_complete: JobId=49561 done
[2022-09-23T18:25:25.622] _slurm_rpc_submit_batch_job: JobId=49562 InitPrio=10666 usec=576
[2022-09-23T18:25:26.107] sched: Allocate JobId=49562 NodeList=gpu01 #CPUs=2 Partition=gpu-k10
[2022-09-23T18:39:50.971] _slurm_rpc_submit_batch_job: JobId=49563 InitPrio=4222 usec=753
[2022-09-23T18:39:51.627] sched: Allocate JobId=49563 NodeList=cpu15 #CPUs=48 Partition=cpu-epyc
[2022-09-23T18:40:03.858] _job_complete: JobId=49563 WEXITSTATUS 0
[2022-09-23T18:40:03.858] _job_complete: JobId=49563 done
[2022-09-23T18:45:00.391] _slurm_rpc_submit_batch_job: JobId=49564 InitPrio=4222 usec=728
[2022-09-23T18:45:01.207] sched: Allocate JobId=49564 NodeList=cpu15 #CPUs=48 Partition=cpu-epyc
[2022-09-23T18:52:33.866] _slurm_rpc_submit_batch_job: JobId=49565 InitPrio=4222 usec=653
[2022-09-23T18:52:34.036] sched: Allocate JobId=49565 NodeList=cpu12 #CPUs=48 Partition=cpu-epyc
[2022-09-23T20:36:53.121] _slurm_rpc_submit_batch_job: JobId=49566 InitPrio=1777 usec=488
[2022-09-23T20:36:54.107] sched: Allocate JobId=49566 NodeList=cpu13 #CPUs=35 Partition=cpu-epyc
[2022-09-23T20:37:12.351] _slurm_rpc_kill_job: REQUEST_KILL_JOB JobId=49552 uid 548300593
[2022-09-23T20:54:34.151] _slurm_rpc_submit_batch_job: JobId=49567 InitPrio=222 usec=551
[2022-09-23T21:04:12.845] _slurm_rpc_submit_batch_job: JobId=49568 InitPrio=222 usec=463
[2022-09-23T21:09:38.739] _slurm_rpc_submit_batch_job: JobId=49569 InitPrio=222 usec=439
[2022-09-23T22:24:37.950] _slurm_rpc_submit_batch_job: JobId=49570 InitPrio=666 usec=551
[2022-09-23T23:51:26.284] _job_complete: JobId=49504 WEXITSTATUS 0
[2022-09-23T23:51:26.284] _job_complete: JobId=49504 done
[2022-09-23T23:51:28.222] sched: Allocate JobId=49533 NodeList=cpu03 #CPUs=8 Partition=cpu-opteron
[2022-09-23T23:52:35.651] error: slurm_receive_msgs: [[cpu15.dicc.um.edu.my]:6818] failed: Socket timed out on send/recv operation
[2022-09-23T23:52:44.666] requeue job JobId=49564 due to failure of node cpu15
[2022-09-23T23:52:44.666] Requeuing JobId=49564
[2022-09-23T23:52:44.666] error: Nodes cpu15 not responding, setting DOWN
[2022-09-23T23:52:54.678] error: slurm_receive_msgs: [[cpu15.dicc.um.edu.my]:6818] failed: Socket timed out on send/recv operation
[2022-09-23T23:58:44.251] Node cpu15 now responding
[2022-09-23T23:58:44.252] node_did_resp: node cpu15 returned to service
[2022-09-23T23:58:55.070] sched/backfill: _start_job: Started JobId=49564 in cpu-epyc on cpu15
[2022-09-23T23:59:05.083] error: slurm_receive_msgs: [[cpu15.dicc.um.edu.my]:6818] failed: Socket timed out on send/recv operation
[2022-09-23T23:59:05.349] _job_complete: JobId=49564 WEXITSTATUS 0
[2022-09-23T23:59:05.349] _job_complete: requeue JobId=49564 per user/system request
[2022-09-23T23:59:05.349] _job_complete: JobId=49564 done
[2022-09-24T00:00:53.413] error: Nodes cpu15 not responding
[2022-09-24T00:01:51.717] error: slurm_receive_msg [10.11.132.25:56376]: Socket timed out on send/recv operation
[2022-09-24T00:04:57.019] Resending TERMINATE_JOB request JobId=49564 Nodelist=cpu15
[2022-09-24T00:09:27.717] error: slurm_receive_msg [10.11.132.25:56386]: Socket timed out on send/recv operation
[2022-09-24T00:23:33.953] _job_complete: JobId=49505 WEXITSTATUS 0
[2022-09-24T00:23:33.953] _job_complete: JobId=49505 done
[2022-09-24T00:35:17.159] _job_complete: JobId=49509 WEXITSTATUS 0
[2022-09-24T00:35:17.159] _job_complete: JobId=49509 done
[2022-09-24T00:40:07.964] _job_complete: JobId=49506 WEXITSTATUS 0
[2022-09-24T00:40:07.965] _job_complete: JobId=49506 done
[2022-09-24T00:44:54.240] error: slurm_receive_msgs: [[cpu15.dicc.um.edu.my]:6818] failed: Socket timed out on send/recv operation
[2022-09-24T00:45:04.259] Node cpu15 now responding
[2022-09-24T00:45:53.318] error: Nodes cpu15 not responding
[2022-09-24T00:57:08.790] _slurm_rpc_requeue: Requeue of JobId=49564 returned an error: Job is pending execution
[2022-09-24T01:11:43.907] error: slurm_receive_msg [10.11.132.25:56452]: Socket timed out on send/recv operation
[2022-09-24T01:28:30.651] error: slurm_receive_msg [10.11.132.25:56464]: Socket timed out on send/recv operation
[2022-09-24T01:28:32.647] error: slurm_receive_msg [10.11.132.25:56468]: Socket timed out on send/recv operation
[2022-09-24T01:55:55.907] _job_complete: JobId=49508 WEXITSTATUS 0
[2022-09-24T01:55:55.908] _job_complete: JobId=49508 done
[2022-09-24T02:04:00.518] _job_complete: JobId=49518 WEXITSTATUS 0
[2022-09-24T02:04:00.519] _job_complete: JobId=49518 done
[2022-09-24T02:05:26.902] _job_complete: JobId=49507 WEXITSTATUS 0
[2022-09-24T02:05:26.902] _job_complete: JobId=49507 done
[2022-09-24T02:22:32.302] _job_complete: JobId=49517 WEXITSTATUS 0
[2022-09-24T02:22:32.302] _job_complete: JobId=49517 done
[2022-09-24T02:25:36.224] _job_complete: JobId=49510 WEXITSTATUS 0
[2022-09-24T02:25:36.224] _job_complete: JobId=49510 done
[2022-09-24T02:29:17.202] _job_complete: JobId=49522 WEXITSTATUS 0
[2022-09-24T02:29:17.202] _job_complete: JobId=49522 done
[2022-09-24T02:32:44.161] _slurm_rpc_submit_batch_job: JobId=49571 InitPrio=1111 usec=808
[2022-09-24T02:35:41.819] _job_complete: JobId=49511 WEXITSTATUS 0
[2022-09-24T02:35:41.819] _job_complete: JobId=49511 done
[2022-09-24T02:35:55.258] sched/backfill: _start_job: Started JobId=49569 in cpu-opteron on cpu09
[2022-09-24T02:37:12.490] _job_complete: JobId=49514 WEXITSTATUS 0
[2022-09-24T02:37:12.490] _job_complete: JobId=49514 done
[2022-09-24T02:37:22.374] error: slurm_receive_msg [10.11.132.25:56532]: Socket timed out on send/recv operation
[2022-09-24T02:37:22.374] error: slurm_receive_msg [10.11.132.25:56534]: Socket timed out on send/recv operation
[2022-09-24T02:37:24.379] error: slurm_receive_msg [10.11.132.25:56542]: Socket timed out on send/recv operation
[2022-09-24T02:37:24.379] error: slurm_receive_msg [10.11.132.25:56540]: Socket timed out on send/recv operation
[2022-09-24T02:37:24.380] error: slurm_receive_msg [10.11.132.25:56538]: Socket timed out on send/recv operation
[2022-09-24T02:37:26.372] error: slurm_receive_msg [10.11.132.25:56544]: Socket timed out on send/recv operation
[2022-09-24T02:43:07.369] error: slurm_receive_msg [10.11.132.25:56546]: Socket timed out on send/recv operation
[2022-09-24T02:45:07.711] _job_complete: JobId=49521 WEXITSTATUS 0
[2022-09-24T02:45:07.711] _job_complete: JobId=49521 done
[2022-09-24T02:46:20.355] _job_complete: JobId=49513 WEXITSTATUS 0
[2022-09-24T02:46:20.355] _job_complete: JobId=49513 done
[2022-09-24T02:49:40.892] error: slurm_receive_msg [10.11.132.25:56554]: Socket timed out on send/recv operation
[2022-09-24T02:50:26.416] _job_complete: JobId=49569 WEXITSTATUS 0
[2022-09-24T02:50:26.417] _job_complete: JobId=49569 done
[2022-09-24T02:51:11.838] _job_complete: JobId=49512 WEXITSTATUS 0
[2022-09-24T02:51:11.838] _job_complete: JobId=49512 done
[2022-09-24T02:54:08.372] _job_complete: JobId=49520 WEXITSTATUS 0
[2022-09-24T02:54:08.372] _job_complete: JobId=49520 done
[2022-09-24T02:55:37.499] error: slurm_receive_msg [10.11.132.25:56564]: Socket timed out on send/recv operation
[2022-09-24T02:55:39.502] error: slurm_receive_msg [10.11.132.25:56570]: Socket timed out on send/recv operation
[2022-09-24T02:56:02.521] error: slurm_receive_msg [10.11.132.25:56572]: Socket timed out on send/recv operation
[2022-09-24T02:59:18.781] _job_complete: JobId=49523 WEXITSTATUS 0
[2022-09-24T02:59:18.781] _job_complete: JobId=49523 done
[2022-09-24T03:02:00.462] _job_complete: JobId=49519 WEXITSTATUS 0
[2022-09-24T03:02:00.462] _job_complete: JobId=49519 done
[2022-09-24T03:02:25.770] error: slurm_receive_msg [10.11.132.25:56576]: Socket timed out on send/recv operation
[2022-09-24T03:08:43.080] error: slurm_receive_msg [10.11.132.25:56588]: Socket timed out on send/recv operation
[2022-09-24T03:08:45.085] error: slurm_receive_msg [10.11.132.25:56590]: Socket timed out on send/recv operation
[2022-09-24T03:20:01.144] _job_complete: JobId=49566 WEXITSTATUS 2
[2022-09-24T03:20:01.149] _job_complete: JobId=49566 done
[2022-09-24T03:20:03.141] sched: Allocate JobId=49570 NodeList=cpu13 #CPUs=48 Partition=cpu-epyc
[2022-09-24T03:20:11.588] _job_complete: JobId=49570 WEXITSTATUS 1
[2022-09-24T03:20:11.588] _job_complete: JobId=49570 done
[2022-09-24T03:20:11.895] sched: Allocate JobId=49567 NodeList=cpu13 #CPUs=48 Partition=cpu-epyc
[2022-09-24T03:20:11.896] sched: Allocate JobId=49568 NodeList=cpu14 #CPUs=24 Partition=cpu-epyc
[2022-09-24T03:21:28.877] _job_complete: JobId=49515 WEXITSTATUS 0
[2022-09-24T03:21:28.877] _job_complete: JobId=49515 done
[2022-09-24T03:27:18.891] _job_complete: JobId=49524 WEXITSTATUS 0
[2022-09-24T03:27:18.891] _job_complete: JobId=49524 done
[2022-09-24T03:39:05.692] _job_complete: JobId=49516 WEXITSTATUS 0
[2022-09-24T03:39:05.692] _job_complete: JobId=49516 done
[2022-09-24T03:39:07.353] error: slurm_receive_msg [10.11.132.25:56634]: Socket timed out on send/recv operation
[2022-09-24T03:56:11.840] _job_complete: JobId=49530 WEXITSTATUS 0
[2022-09-24T03:56:11.840] _job_complete: JobId=49530 done
[2022-09-24T04:10:52.510] _job_complete: JobId=49525 WEXITSTATUS 0
[2022-09-24T04:10:52.510] _job_complete: JobId=49525 done
[2022-09-24T04:10:53.326] sched: Allocate JobId=49571 NodeList=cpu07 #CPUs=64 Partition=cpu-opteron
[2022-09-24T04:22:17.474] _job_complete: JobId=49532 WEXITSTATUS 0
[2022-09-24T04:22:17.474] _job_complete: JobId=49532 done
[2022-09-24T04:49:17.037] _job_complete: JobId=49528 WEXITSTATUS 0
[2022-09-24T04:49:17.037] _job_complete: JobId=49528 done
[2022-09-24T04:52:15.380] error: slurm_receive_msg [10.11.132.25:56734]: Socket timed out on send/recv operation
[2022-09-24T05:01:34.879] _slurm_rpc_kill_job: REQUEST_KILL_JOB JobId=49571 uid 548300621
[2022-09-24T05:01:36.401] _slurm_rpc_kill_job: REQUEST_KILL_JOB JobId=49571 uid 548300621
[2022-09-24T05:01:44.465] _job_complete: JobId=49529 WEXITSTATUS 0
[2022-09-24T05:01:44.465] _job_complete: JobId=49529 done
[2022-09-24T05:02:54.197] error: slurm_receive_msg [10.11.132.25:56739]: Socket timed out on send/recv operation
[2022-09-24T05:02:56.199] error: slurm_receive_msg [10.11.132.25:56742]: Socket timed out on send/recv operation
[2022-09-24T05:04:25.735] _slurm_rpc_submit_batch_job: JobId=49572 InitPrio=1111 usec=512
[2022-09-24T05:04:25.802] sched: Allocate JobId=49572 NodeList=cpu07 #CPUs=64 Partition=cpu-opteron
[2022-09-24T05:04:35.392] _job_complete: JobId=49572 WEXITSTATUS 1
[2022-09-24T05:04:35.392] _job_complete: JobId=49572 done
[2022-09-24T05:10:23.553] _slurm_rpc_submit_batch_job: JobId=49573 InitPrio=1111 usec=420
[2022-09-24T05:13:52.365] error: slurm_receive_msg [10.11.132.25:56754]: Socket timed out on send/recv operation
[2022-09-24T05:14:05.368] error: slurm_receive_msg [10.11.132.25:56758]: Socket timed out on send/recv operation
[2022-09-24T05:20:50.415] _job_complete: JobId=49527 WEXITSTATUS 0
[2022-09-24T05:20:50.415] _job_complete: JobId=49527 done
[2022-09-24T05:23:47.716] error: slurm_receive_msg [10.11.132.25:56770]: Socket timed out on send/recv operation
[2022-09-24T05:41:18.534] error: slurm_receive_msg [10.11.132.25:56782]: Socket timed out on send/recv operation
[2022-09-24T05:41:20.539] error: slurm_receive_msg [10.11.132.25:56784]: Socket timed out on send/recv operation
[2022-09-24T05:45:56.135] error: slurm_receive_msg [10.11.132.25:56790]: Socket timed out on send/recv operation
[2022-09-24T05:51:49.892] error: slurm_receive_msg [10.11.132.25:56800]: Socket timed out on send/recv operation
[2022-09-24T05:51:51.895] error: slurm_receive_msg [10.11.132.25:56804]: Socket timed out on send/recv operation
[2022-09-24T06:14:11.316] _job_complete: JobId=49526 WEXITSTATUS 0
[2022-09-24T06:14:11.316] _job_complete: JobId=49526 done
[2022-09-24T06:23:28.417] _job_complete: JobId=49531 WEXITSTATUS 0
[2022-09-24T06:23:28.417] _job_complete: JobId=49531 done
[2022-09-24T06:55:04.191] error: slurm_receive_msg [10.11.132.25:56882]: Socket timed out on send/recv operation
[2022-09-24T06:55:21.188] error: slurm_receive_msg [10.11.132.25:56886]: Socket timed out on send/recv operation
[2022-09-24T08:10:47.993] error: slurm_receive_msg [10.11.132.25:56962]: Socket timed out on send/recv operation
[2022-09-24T08:11:23.024] error: slurm_receive_msg [10.11.132.25:56964]: Socket timed out on send/recv operation
[2022-09-24T09:15:44.148] _job_complete: JobId=49476 WEXITSTATUS 0
[2022-09-24T09:15:44.154] _job_complete: JobId=49476 done
[2022-09-24T09:18:22.336] _job_complete: JobId=49568 WEXITSTATUS 0
[2022-09-24T09:18:22.342] _job_complete: JobId=49568 done
[2022-09-24T09:44:36.278] error: slurm_receive_msg [10.11.132.25:57020]: Socket timed out on send/recv operation
[2022-09-24T09:44:38.281] error: slurm_receive_msg [10.11.132.25:57024]: Socket timed out on send/recv operation
[2022-09-24T09:44:38.281] error: slurm_receive_msg [10.11.132.25:57028]: Socket timed out on send/recv operation
[2022-09-24T10:05:27.416] error: slurm_receive_msg [10.11.132.25:57050]: Socket timed out on send/recv operation
[2022-09-24T10:05:43.429] error: slurm_receive_msg [10.11.132.25:57054]: Socket timed out on send/recv operation
[2022-09-24T10:16:29.664] error: slurm_receive_msg [10.11.132.25:57056]: Socket timed out on send/recv operation
[2022-09-24T10:16:35.671] error: slurm_receive_msg [10.11.132.25:57060]: Socket timed out on send/recv operation
[2022-09-24T10:25:21.285] error: slurm_receive_msg [10.11.132.25:57072]: Socket timed out on send/recv operation
[2022-09-24T10:25:38.297] error: slurm_receive_msg [10.11.132.25:57076]: Socket timed out on send/recv operation
[2022-09-24T10:43:27.916] error: slurm_receive_msg [10.11.132.25:57086]: Socket timed out on send/recv operation
[2022-09-24T10:43:29.920] error: slurm_receive_msg [10.11.132.25:57090]: Socket timed out on send/recv operation
[2022-09-24T11:21:12.049] error: slurm_receive_msg [10.11.132.25:57122]: Socket timed out on send/recv operation
[2022-09-24T11:21:14.051] error: slurm_receive_msg [10.11.132.25:57124]: Socket timed out on send/recv operation
[2022-09-24T11:28:11.826] error: slurm_receive_msg [10.11.132.25:57130]: Socket timed out on send/recv operation
[2022-09-24T11:28:26.835] error: slurm_receive_msg [10.11.132.25:57132]: Socket timed out on send/recv operation
[2022-09-24T11:37:28.876] error: slurm_receive_msg [10.11.132.25:57144]: Socket timed out on send/recv operation
[2022-09-24T12:13:05.003] _slurm_rpc_requeue: Requeue of JobId=49564 returned an error: Job is pending execution
[2022-09-24T12:13:12.643] error: slurm_receive_msgs: [[cpu12.dicc.um.edu.my]:6818] failed: Socket timed out on send/recv operation
[2022-09-24T12:13:27.595] Node cpu12 now responding
[2022-09-24T12:15:53.795] error: Nodes cpu12 not responding
[2022-09-24T12:17:27.027] cleanup_completing: JobId=49565 completion process took 233 seconds
[2022-09-24T12:17:27.027] error: Nodes cpu12 not responding, setting DOWN
[2022-09-24T12:19:27.192] cleanup_completing: JobId=49564 completion process took 44390 seconds
[2022-09-24T12:19:27.192] error: Nodes cpu15 not responding, setting DOWN
[2022-09-24T12:19:48.794] Node cpu12 now responding
[2022-09-24T12:19:48.794] node cpu12 returned to service
[2022-09-24T12:19:49.243] sched: Allocate JobId=49564 NodeList=cpu12 #CPUs=48 Partition=cpu-epyc
[2022-09-24T12:21:43.669] Node cpu15 now responding
[2022-09-24T12:21:43.669] node cpu15 returned to service
[2022-09-24T12:21:44.464] sched: Allocate JobId=49573 NodeList=cpu15 #CPUs=48 Partition=cpu-epyc
[2022-09-24T12:24:58.699] sched: _slurm_rpc_allocate_resources JobId=49574 NodeList=(null) usec=1161
[2022-09-24T12:24:58.725] sched: Allocate JobId=49574 NodeList=gpu01 #CPUs=4 Partition=gpu-k10
[2022-09-24T12:48:58.252] _job_complete: JobId=49574 WEXITSTATUS 127
[2022-09-24T12:48:58.252] _job_complete: JobId=49574 done
[2022-09-24T12:54:06.754] _slurm_rpc_submit_batch_job: JobId=49575 InitPrio=8888 usec=501
[2022-09-24T15:36:34.056] _slurm_rpc_submit_batch_job: JobId=49576 InitPrio=2000 usec=1101
[2022-09-24T15:36:34.397] sched: Allocate JobId=49576 NodeList=gpu03 #CPUs=16 Partition=gpu-k10
[2022-09-24T15:47:55.448] _job_complete: JobId=49533 WEXITSTATUS 0
[2022-09-24T15:47:55.449] _job_complete: JobId=49533 done
[2022-09-24T18:10:00.579] _job_complete: JobId=49443 WEXITSTATUS 0
[2022-09-24T18:10:00.580] _job_complete: JobId=49443 done
[2022-09-24T20:22:22.414] error: slurm_receive_msg [10.11.132.22:60982]: Socket timed out on send/recv operation
[2022-09-24T20:35:27.442] _slurm_rpc_submit_batch_job: JobId=49577 InitPrio=222 usec=482
[2022-09-24T20:35:27.846] sched: Allocate JobId=49577 NodeList=cpu14 #CPUs=48 Partition=cpu-epyc
[2022-09-24T20:41:33.248] _slurm_rpc_submit_batch_job: JobId=49578 InitPrio=222 usec=403
[2022-09-24T20:41:33.549] sched: Allocate JobId=49578 NodeList=cpu11 #CPUs=64 Partition=cpu-opteron
[2022-09-24T20:45:22.017] _slurm_rpc_submit_batch_job: JobId=49579 InitPrio=222 usec=586
[2022-09-24T20:45:22.863] sched: Allocate JobId=49579 NodeList=cpu03 #CPUs=32 Partition=cpu-opteron
[2022-09-24T20:50:59.892] _job_complete: JobId=49579 WEXITSTATUS 1
[2022-09-24T20:50:59.893] _job_complete: JobId=49579 done
[2022-09-24T21:11:21.639] _slurm_rpc_submit_batch_job: JobId=49580 InitPrio=222 usec=495
[2022-09-24T21:11:22.588] sched: Allocate JobId=49580 NodeList=cpu03 #CPUs=32 Partition=cpu-opteron
[2022-09-24T21:23:07.900] _job_complete: JobId=49580 WEXITSTATUS 0
[2022-09-24T21:23:07.900] _job_complete: JobId=49580 done
[2022-09-24T21:29:56.861] _job_complete: JobId=49414 WEXITSTATUS 0
[2022-09-24T21:29:56.861] _job_complete: JobId=49414 done
[2022-09-24T21:41:27.357] _slurm_rpc_submit_batch_job: JobId=49581 InitPrio=222 usec=519
[2022-09-24T21:41:28.341] sched: Allocate JobId=49581 NodeList=cpu01 #CPUs=64 Partition=cpu-opteron
[2022-09-24T23:09:41.446] error: slurm_receive_msgs: [[cpu12.dicc.um.edu.my]:6818] failed: Socket timed out on send/recv operation
[2022-09-24T23:09:50.290] Node cpu12 now responding
[2022-09-24T23:10:54.371] error: Nodes cpu12 not responding
[2022-09-24T23:13:30.692] cleanup_completing: JobId=49564 completion process took 205 seconds
[2022-09-24T23:13:30.693] error: Nodes cpu12 not responding, setting DOWN
[2022-09-24T23:15:11.484] Node cpu12 now responding
[2022-09-24T23:15:11.485] node cpu12 returned to service
[2022-09-24T23:16:27.896] _job_complete: JobId=49445 WEXITSTATUS 0
[2022-09-24T23:16:27.896] _job_complete: JobId=49445 done
[2022-09-25T01:35:39.386] _job_complete: JobId=49365 WEXITSTATUS 0
[2022-09-25T01:35:39.393] _job_complete: JobId=49365 done
[2022-09-25T03:11:42.622] _job_complete: JobId=49096 WEXITSTATUS 0
[2022-09-25T03:11:42.628] _job_complete: JobId=49096 done
[2022-09-25T07:34:11.569] _job_complete: JobId=49576 WEXITSTATUS 1
[2022-09-25T07:34:11.575] _job_complete: JobId=49576 done
[2022-09-25T09:31:52.242] _slurm_rpc_submit_batch_job: JobId=49582 InitPrio=222 usec=460
[2022-09-25T09:31:53.222] sched: Allocate JobId=49582 NodeList=cpu12 #CPUs=48 Partition=cpu-epyc
[2022-09-25T09:32:17.682] _job_complete: JobId=49582 WEXITSTATUS 1
[2022-09-25T09:32:17.683] _job_complete: JobId=49582 done
[2022-09-25T10:17:11.757] _slurm_rpc_submit_batch_job: JobId=49583 InitPrio=222 usec=458
[2022-09-25T10:17:12.083] sched: Allocate JobId=49583 NodeList=cpu12 #CPUs=48 Partition=cpu-epyc
[2022-09-25T10:17:35.563] _job_complete: JobId=49583 WEXITSTATUS 1
[2022-09-25T10:17:35.564] _job_complete: JobId=49583 done
[2022-09-25T10:23:19.053] _slurm_rpc_submit_batch_job: JobId=49584 InitPrio=222 usec=465
[2022-09-25T10:23:19.687] sched: Allocate JobId=49584 NodeList=cpu12 #CPUs=48 Partition=cpu-epyc
[2022-09-25T10:23:31.320] _slurm_rpc_submit_batch_job: JobId=49585 InitPrio=222 usec=435
[2022-09-25T10:25:28.111] _slurm_rpc_kill_job: REQUEST_KILL_JOB JobId=49567 uid 548200017
[2022-09-25T10:25:30.111] sched: Allocate JobId=49585 NodeList=cpu13 #CPUs=48 Partition=cpu-epyc
[2022-09-25T10:31:33.935] _slurm_rpc_submit_batch_job: JobId=49586 InitPrio=222 usec=460
[2022-09-25T10:31:34.614] sched: Allocate JobId=49586 NodeList=cpu05 #CPUs=64 Partition=cpu-opteron
[2022-09-25T10:31:50.700] _slurm_rpc_submit_batch_job: JobId=49587 InitPrio=222 usec=460
[2022-09-25T10:31:51.633] sched: Allocate JobId=49587 NodeList=cpu07 #CPUs=64 Partition=cpu-opteron
[2022-09-25T10:40:21.498] _slurm_rpc_submit_batch_job: JobId=49588 InitPrio=1333 usec=477
[2022-09-25T10:40:56.565] sched/backfill: _start_job: Started JobId=49588 in gpu-v100s on gpu05
[2022-09-25T13:29:34.977] _slurm_rpc_submit_batch_job: JobId=49589 InitPrio=1777 usec=507
[2022-09-25T13:30:05.547] _slurm_rpc_kill_job: REQUEST_KILL_JOB JobId=49589 uid 548300593
[2022-09-25T13:30:36.133] _slurm_rpc_submit_batch_job: JobId=49590 InitPrio=1777 usec=413
[2022-09-25T13:30:36.734] sched: Allocate JobId=49590 NodeList=cpu08 #CPUs=35 Partition=cpu-opteron
[2022-09-25T13:43:20.243] _slurm_rpc_submit_batch_job: JobId=49591 InitPrio=1777 usec=410
[2022-09-25T13:43:20.271] sched: Allocate JobId=49591 NodeList=cpu09 #CPUs=35 Partition=cpu-opteron
[2022-09-25T13:43:23.138] _job_complete: JobId=49591 WEXITSTATUS 1
[2022-09-25T13:43:23.139] _job_complete: JobId=49591 done
[2022-09-25T13:43:37.290] _slurm_rpc_kill_job: REQUEST_KILL_JOB JobId=49591 uid 548300593
[2022-09-25T14:48:59.429] _job_complete: JobId=49578 WEXITSTATUS 0
[2022-09-25T14:48:59.434] _job_complete: JobId=49578 done
[2022-09-25T15:03:49.104] _slurm_rpc_submit_batch_job: JobId=49592 InitPrio=2000 usec=1082
[2022-09-25T15:03:49.827] sched: Allocate JobId=49592 NodeList=gpu03 #CPUs=16 Partition=gpu-k10
[2022-09-25T15:33:58.235] _job_complete: JobId=49590 WEXITSTATUS 1
[2022-09-25T15:33:58.239] _job_complete: JobId=49590 done
[2022-09-25T15:41:26.030] _slurm_rpc_submit_batch_job: JobId=49593 InitPrio=1777 usec=431
[2022-09-25T15:41:26.697] sched: Allocate JobId=49593 NodeList=cpu11 #CPUs=35 Partition=cpu-opteron
[2022-09-25T15:50:59.398] _slurm_rpc_submit_batch_job: JobId=49594 InitPrio=1777 usec=415
[2022-09-25T15:51:00.798] sched: Allocate JobId=49594 NodeList=cpu08 #CPUs=35 Partition=cpu-opteron
[2022-09-25T15:53:34.009] Time limit exhausted for JobId=49267
[2022-09-25T17:31:52.651] _slurm_rpc_submit_batch_job: JobId=49595 InitPrio=2000 usec=466
[2022-09-25T17:31:53.173] sched: Allocate JobId=49595 NodeList=cpu03 #CPUs=8 Partition=cpu-opteron
[2022-09-25T17:34:59.997] _slurm_rpc_submit_batch_job: JobId=49596 InitPrio=2000 usec=966
[2022-09-25T17:38:14.913] _slurm_rpc_kill_job: REQUEST_KILL_JOB JobId=49596 uid 548200029
[2022-09-25T17:39:01.605] _slurm_rpc_submit_batch_job: JobId=49597 InitPrio=2000 usec=1044
[2022-09-25T17:39:23.273] _slurm_rpc_kill_job: REQUEST_KILL_JOB JobId=49597 uid 548200029
[2022-09-25T17:39:45.985] _slurm_rpc_submit_batch_job: JobId=49598 InitPrio=2000 usec=967
[2022-09-25T17:39:46.935] sched: Allocate JobId=49598 NodeList=gpu04 #CPUs=16 Partition=gpu-k40c
[2022-09-25T19:05:51.022] _job_complete: JobId=49595 WEXITSTATUS 0
[2022-09-25T19:05:51.028] _job_complete: JobId=49595 done
[2022-09-25T20:50:15.147] _slurm_rpc_submit_batch_job: JobId=49599 InitPrio=666 usec=525
[2022-09-25T20:50:15.550] sched: Allocate JobId=49599 NodeList=cpu09 #CPUs=64 Partition=cpu-opteron
[2022-09-25T20:54:32.156] _job_complete: JobId=49599 WEXITSTATUS 1
[2022-09-25T20:54:32.157] _job_complete: JobId=49599 done
[2022-09-25T21:03:41.482] _slurm_rpc_submit_batch_job: JobId=49600 InitPrio=10000 usec=825
[2022-09-25T21:03:41.968] sched: Allocate JobId=49600 NodeList=cpu04 #CPUs=1 Partition=cpu-opteron
[2022-09-25T21:12:54.128] _slurm_rpc_kill_job: REQUEST_KILL_JOB JobId=49600 uid 548200037
[2022-09-25T21:14:23.902] _slurm_rpc_submit_batch_job: JobId=49601 InitPrio=10000 usec=577
[2022-09-25T21:14:23.914] _slurm_rpc_submit_batch_job: JobId=49602 InitPrio=10000 usec=502
[2022-09-25T21:14:23.924] _slurm_rpc_submit_batch_job: JobId=49603 InitPrio=10000 usec=457
[2022-09-25T21:14:23.934] _slurm_rpc_submit_batch_job: JobId=49604 InitPrio=10000 usec=489
[2022-09-25T21:14:23.945] _slurm_rpc_submit_batch_job: JobId=49605 InitPrio=10000 usec=463
[2022-09-25T21:14:23.955] _slurm_rpc_submit_batch_job: JobId=49606 InitPrio=10000 usec=471
[2022-09-25T21:14:23.966] _slurm_rpc_submit_batch_job: JobId=49607 InitPrio=10000 usec=436
[2022-09-25T21:14:23.976] sched: Allocate JobId=49601 NodeList=cpu04 #CPUs=1 Partition=cpu-opteron
[2022-09-25T21:14:23.976] sched: Allocate JobId=49602 NodeList=cpu04 #CPUs=1 Partition=cpu-opteron
[2022-09-25T21:14:23.977] sched: Allocate JobId=49603 NodeList=cpu04 #CPUs=1 Partition=cpu-opteron
[2022-09-25T21:14:23.978] sched: Allocate JobId=49604 NodeList=cpu03 #CPUs=1 Partition=cpu-opteron
[2022-09-25T21:14:23.979] sched: Allocate JobId=49605 NodeList=cpu03 #CPUs=1 Partition=cpu-opteron
[2022-09-25T21:14:23.980] sched: Allocate JobId=49606 NodeList=cpu03 #CPUs=1 Partition=cpu-opteron
[2022-09-25T21:14:23.981] sched: Allocate JobId=49607 NodeList=cpu03 #CPUs=1 Partition=cpu-opteron
[2022-09-25T21:14:23.982] _slurm_rpc_submit_batch_job: JobId=49608 InitPrio=10000 usec=582
[2022-09-25T21:14:23.991] _slurm_rpc_submit_batch_job: JobId=49609 InitPrio=10000 usec=448
[2022-09-25T21:14:24.002] _slurm_rpc_submit_batch_job: JobId=49610 InitPrio=10000 usec=498
[2022-09-25T21:14:24.013] _slurm_rpc_submit_batch_job: JobId=49611 InitPrio=10000 usec=451
[2022-09-25T21:14:24.023] _slurm_rpc_submit_batch_job: JobId=49612 InitPrio=10000 usec=498
[2022-09-25T21:14:24.034] _slurm_rpc_submit_batch_job: JobId=49613 InitPrio=10000 usec=480
[2022-09-25T21:14:24.044] _slurm_rpc_submit_batch_job: JobId=49614 InitPrio=10000 usec=502
[2022-09-25T21:14:24.055] _slurm_rpc_submit_batch_job: JobId=49615 InitPrio=10000 usec=480
[2022-09-25T21:14:24.065] _slurm_rpc_submit_batch_job: JobId=49616 InitPrio=10000 usec=546
[2022-09-25T21:14:24.075] _slurm_rpc_submit_batch_job: JobId=49617 InitPrio=10000 usec=504
[2022-09-25T21:14:24.086] _slurm_rpc_submit_batch_job: JobId=49618 InitPrio=10000 usec=541
[2022-09-25T21:14:24.096] _slurm_rpc_submit_batch_job: JobId=49619 InitPrio=10000 usec=487
[2022-09-25T21:14:24.107] _slurm_rpc_submit_batch_job: JobId=49620 InitPrio=10000 usec=606
[2022-09-25T21:14:24.117] _slurm_rpc_submit_batch_job: JobId=49621 InitPrio=10000 usec=544
[2022-09-25T21:14:24.127] _slurm_rpc_submit_batch_job: JobId=49622 InitPrio=10000 usec=538
[2022-09-25T21:14:24.138] _slurm_rpc_submit_batch_job: JobId=49623 InitPrio=10000 usec=429
[2022-09-25T21:14:24.148] _slurm_rpc_submit_batch_job: JobId=49624 InitPrio=10000 usec=616
[2022-09-25T21:14:24.158] _slurm_rpc_submit_batch_job: JobId=49625 InitPrio=10000 usec=605
[2022-09-25T21:14:24.168] _slurm_rpc_submit_batch_job: JobId=49626 InitPrio=10000 usec=456
[2022-09-25T21:14:24.179] _slurm_rpc_submit_batch_job: JobId=49627 InitPrio=10000 usec=528
[2022-09-25T21:14:24.189] _slurm_rpc_submit_batch_job: JobId=49628 InitPrio=10000 usec=477
[2022-09-25T21:14:24.200] _slurm_rpc_submit_batch_job: JobId=49629 InitPrio=10000 usec=431
[2022-09-25T21:14:24.209] _slurm_rpc_submit_batch_job: JobId=49630 InitPrio=10000 usec=494
[2022-09-25T21:14:24.219] _slurm_rpc_submit_batch_job: JobId=49631 InitPrio=10000 usec=521
[2022-09-25T21:14:24.229] _slurm_rpc_submit_batch_job: JobId=49632 InitPrio=10000 usec=500
[2022-09-25T21:14:24.239] _slurm_rpc_submit_batch_job: JobId=49633 InitPrio=10000 usec=517
[2022-09-25T21:14:24.249] _slurm_rpc_submit_batch_job: JobId=49634 InitPrio=10000 usec=549
[2022-09-25T21:14:24.259] _slurm_rpc_submit_batch_job: JobId=49635 InitPrio=10000 usec=539
[2022-09-25T21:14:24.269] _slurm_rpc_submit_batch_job: JobId=49636 InitPrio=10000 usec=503
[2022-09-25T21:14:24.281] _slurm_rpc_submit_batch_job: JobId=49637 InitPrio=10000 usec=517
[2022-09-25T21:14:24.290] _slurm_rpc_submit_batch_job: JobId=49638 InitPrio=10000 usec=512
[2022-09-25T21:14:24.301] _slurm_rpc_submit_batch_job: JobId=49639 InitPrio=10000 usec=475
[2022-09-25T21:14:24.311] _slurm_rpc_submit_batch_job: JobId=49640 InitPrio=10000 usec=520
[2022-09-25T21:14:24.321] _slurm_rpc_submit_batch_job: JobId=49641 InitPrio=10000 usec=442
[2022-09-25T21:14:24.331] _slurm_rpc_submit_batch_job: JobId=49642 InitPrio=10000 usec=485
[2022-09-25T21:14:24.341] _slurm_rpc_submit_batch_job: JobId=49643 InitPrio=10000 usec=442
[2022-09-25T21:14:24.352] _slurm_rpc_submit_batch_job: JobId=49644 InitPrio=10000 usec=504
[2022-09-25T21:14:24.362] _slurm_rpc_submit_batch_job: JobId=49645 InitPrio=10000 usec=559
[2022-09-25T21:14:24.373] _slurm_rpc_submit_batch_job: JobId=49646 InitPrio=10000 usec=481
[2022-09-25T21:14:24.383] _slurm_rpc_submit_batch_job: JobId=49647 InitPrio=10000 usec=532
[2022-09-25T21:14:24.393] _slurm_rpc_submit_batch_job: JobId=49648 InitPrio=10000 usec=457
[2022-09-25T21:14:24.404] _slurm_rpc_submit_batch_job: JobId=49649 InitPrio=10000 usec=417
[2022-09-25T21:14:24.415] _slurm_rpc_submit_batch_job: JobId=49650 InitPrio=10000 usec=484
[2022-09-25T21:14:24.425] _slurm_rpc_submit_batch_job: JobId=49651 InitPrio=10000 usec=474
[2022-09-25T21:14:24.434] _slurm_rpc_submit_batch_job: JobId=49652 InitPrio=10000 usec=464
[2022-09-25T21:14:24.444] _slurm_rpc_submit_batch_job: JobId=49653 InitPrio=10000 usec=467
[2022-09-25T21:14:24.454] _slurm_rpc_submit_batch_job: JobId=49654 InitPrio=10000 usec=526
[2022-09-25T21:14:24.464] _slurm_rpc_submit_batch_job: JobId=49655 InitPrio=10000 usec=422
[2022-09-25T21:14:24.475] _slurm_rpc_submit_batch_job: JobId=49656 InitPrio=10000 usec=496
[2022-09-25T21:14:24.485] _slurm_rpc_submit_batch_job: JobId=49657 InitPrio=10000 usec=487
[2022-09-25T21:14:24.495] _slurm_rpc_submit_batch_job: JobId=49658 InitPrio=10000 usec=505
[2022-09-25T21:14:24.504] _slurm_rpc_submit_batch_job: JobId=49659 InitPrio=10000 usec=451
[2022-09-25T21:14:24.514] _slurm_rpc_submit_batch_job: JobId=49660 InitPrio=10000 usec=536
[2022-09-25T21:14:24.524] _slurm_rpc_submit_batch_job: JobId=49661 InitPrio=10000 usec=452
[2022-09-25T21:14:24.534] _slurm_rpc_submit_batch_job: JobId=49662 InitPrio=10000 usec=829
[2022-09-25T21:14:24.545] _slurm_rpc_submit_batch_job: JobId=49663 InitPrio=10000 usec=405
[2022-09-25T21:14:24.556] _slurm_rpc_submit_batch_job: JobId=49664 InitPrio=10000 usec=430
[2022-09-25T21:14:24.565] _slurm_rpc_submit_batch_job: JobId=49665 InitPrio=10000 usec=487
[2022-09-25T21:14:24.575] _slurm_rpc_submit_batch_job: JobId=49666 InitPrio=10000 usec=420
[2022-09-25T21:14:24.586] _slurm_rpc_submit_batch_job: JobId=49667 InitPrio=10000 usec=602
[2022-09-25T21:14:24.595] _slurm_rpc_submit_batch_job: JobId=49668 InitPrio=10000 usec=492
[2022-09-25T21:14:24.605] _slurm_rpc_submit_batch_job: JobId=49669 InitPrio=10000 usec=590
[2022-09-25T21:14:24.615] _slurm_rpc_submit_batch_job: JobId=49670 InitPrio=10000 usec=507
[2022-09-25T21:14:24.624] _slurm_rpc_submit_batch_job: JobId=49671 InitPrio=10000 usec=521
[2022-09-25T21:14:24.634] _slurm_rpc_submit_batch_job: JobId=49672 InitPrio=10000 usec=600
[2022-09-25T21:14:24.645] _slurm_rpc_submit_batch_job: JobId=49673 InitPrio=10000 usec=647
[2022-09-25T21:14:24.654] _slurm_rpc_submit_batch_job: JobId=49674 InitPrio=10000 usec=545
[2022-09-25T21:14:24.664] _slurm_rpc_submit_batch_job: JobId=49675 InitPrio=10000 usec=460
[2022-09-25T21:14:24.674] _slurm_rpc_submit_batch_job: JobId=49676 InitPrio=10000 usec=573
[2022-09-25T21:14:24.684] _slurm_rpc_submit_batch_job: JobId=49677 InitPrio=10000 usec=480
[2022-09-25T21:14:24.694] _slurm_rpc_submit_batch_job: JobId=49678 InitPrio=10000 usec=544
[2022-09-25T21:14:24.704] _slurm_rpc_submit_batch_job: JobId=49679 InitPrio=10000 usec=446
[2022-09-25T21:14:24.714] _slurm_rpc_submit_batch_job: JobId=49680 InitPrio=10000 usec=423
[2022-09-25T21:14:24.724] _slurm_rpc_submit_batch_job: JobId=49681 InitPrio=10000 usec=461
[2022-09-25T21:14:24.735] _slurm_rpc_submit_batch_job: JobId=49682 InitPrio=10000 usec=485
[2022-09-25T21:14:24.745] _slurm_rpc_submit_batch_job: JobId=49683 InitPrio=10000 usec=429
[2022-09-25T21:14:24.755] _slurm_rpc_submit_batch_job: JobId=49684 InitPrio=10000 usec=461
[2022-09-25T21:14:24.765] _slurm_rpc_submit_batch_job: JobId=49685 InitPrio=10000 usec=488
[2022-09-25T21:14:24.775] _slurm_rpc_submit_batch_job: JobId=49686 InitPrio=10000 usec=419
[2022-09-25T21:14:24.785] _slurm_rpc_submit_batch_job: JobId=49687 InitPrio=10000 usec=441
[2022-09-25T21:14:24.795] _slurm_rpc_submit_batch_job: JobId=49688 InitPrio=10000 usec=506
[2022-09-25T21:14:24.805] _slurm_rpc_submit_batch_job: JobId=49689 InitPrio=10000 usec=436
[2022-09-25T21:14:24.815] _slurm_rpc_submit_batch_job: JobId=49690 InitPrio=10000 usec=548
[2022-09-25T21:14:24.824] _slurm_rpc_submit_batch_job: JobId=49691 InitPrio=10000 usec=429
[2022-09-25T21:14:26.976] sched: Allocate JobId=49608 NodeList=cpu03 #CPUs=1 Partition=cpu-opteron
[2022-09-25T21:14:26.976] sched: Allocate JobId=49609 NodeList=cpu03 #CPUs=1 Partition=cpu-opteron
[2022-09-25T21:14:26.977] sched: Allocate JobId=49610 NodeList=cpu03 #CPUs=1 Partition=cpu-opteron
[2022-09-25T21:14:26.977] sched: Allocate JobId=49611 NodeList=cpu03 #CPUs=1 Partition=cpu-opteron
[2022-09-25T21:14:26.978] sched: Allocate JobId=49612 NodeList=cpu03 #CPUs=1 Partition=cpu-opteron
[2022-09-25T21:14:26.979] sched: Allocate JobId=49613 NodeList=cpu03 #CPUs=1 Partition=cpu-opteron
[2022-09-25T21:14:26.980] sched: Allocate JobId=49614 NodeList=cpu03 #CPUs=1 Partition=cpu-opteron
[2022-09-25T21:14:26.980] sched: Allocate JobId=49615 NodeList=cpu03 #CPUs=1 Partition=cpu-opteron
[2022-09-25T21:14:26.981] sched: Allocate JobId=49616 NodeList=cpu03 #CPUs=1 Partition=cpu-opteron
[2022-09-25T21:14:26.982] sched: Allocate JobId=49617 NodeList=cpu03 #CPUs=1 Partition=cpu-opteron
[2022-09-25T21:14:26.982] sched: Allocate JobId=49618 NodeList=cpu03 #CPUs=1 Partition=cpu-opteron
[2022-09-25T21:14:26.983] sched: Allocate JobId=49619 NodeList=cpu03 #CPUs=1 Partition=cpu-opteron
[2022-09-25T21:14:26.984] sched: Allocate JobId=49620 NodeList=cpu03 #CPUs=1 Partition=cpu-opteron
[2022-09-25T21:14:26.984] sched: Allocate JobId=49621 NodeList=cpu03 #CPUs=1 Partition=cpu-opteron
[2022-09-25T21:14:26.985] sched: Allocate JobId=49622 NodeList=cpu03 #CPUs=1 Partition=cpu-opteron
[2022-09-25T21:14:26.985] sched: Allocate JobId=49623 NodeList=cpu03 #CPUs=1 Partition=cpu-opteron
[2022-09-25T21:14:26.986] sched: Allocate JobId=49624 NodeList=cpu03 #CPUs=1 Partition=cpu-opteron
[2022-09-25T21:14:26.986] sched: Allocate JobId=49625 NodeList=cpu03 #CPUs=1 Partition=cpu-opteron
[2022-09-25T21:14:26.987] sched: Allocate JobId=49626 NodeList=cpu03 #CPUs=1 Partition=cpu-opteron
[2022-09-25T21:14:26.987] sched: Allocate JobId=49627 NodeList=cpu03 #CPUs=1 Partition=cpu-opteron
[2022-09-25T21:14:26.988] sched: Allocate JobId=49628 NodeList=cpu03 #CPUs=1 Partition=cpu-opteron
[2022-09-25T21:14:26.988] sched: Allocate JobId=49629 NodeList=cpu03 #CPUs=1 Partition=cpu-opteron
[2022-09-25T21:14:26.989] sched: Allocate JobId=49630 NodeList=cpu03 #CPUs=1 Partition=cpu-opteron
[2022-09-25T21:14:26.989] sched: Allocate JobId=49631 NodeList=cpu03 #CPUs=1 Partition=cpu-opteron
[2022-09-25T21:14:26.990] sched: Allocate JobId=49632 NodeList=cpu03 #CPUs=1 Partition=cpu-opteron
[2022-09-25T21:14:26.990] sched: Allocate JobId=49633 NodeList=cpu03 #CPUs=1 Partition=cpu-opteron
[2022-09-25T21:14:26.991] sched: Allocate JobId=49634 NodeList=cpu03 #CPUs=1 Partition=cpu-opteron
[2022-09-25T21:14:26.991] sched: Allocate JobId=49635 NodeList=cpu03 #CPUs=1 Partition=cpu-opteron
[2022-09-25T21:14:26.992] sched: Allocate JobId=49636 NodeList=cpu08 #CPUs=1 Partition=cpu-opteron
[2022-09-25T21:14:26.992] sched: Allocate JobId=49637 NodeList=cpu08 #CPUs=1 Partition=cpu-opteron
[2022-09-25T21:14:26.993] sched: Allocate JobId=49638 NodeList=cpu08 #CPUs=1 Partition=cpu-opteron
[2022-09-25T21:14:26.993] sched: Allocate JobId=49639 NodeList=cpu08 #CPUs=1 Partition=cpu-opteron
[2022-09-25T21:14:26.994] sched: Allocate JobId=49640 NodeList=cpu08 #CPUs=1 Partition=cpu-opteron
[2022-09-25T21:14:26.994] sched: Allocate JobId=49641 NodeList=cpu08 #CPUs=1 Partition=cpu-opteron
[2022-09-25T21:14:26.995] sched: Allocate JobId=49642 NodeList=cpu08 #CPUs=1 Partition=cpu-opteron
[2022-09-25T21:14:26.995] sched: Allocate JobId=49643 NodeList=cpu08 #CPUs=1 Partition=cpu-opteron
[2022-09-25T21:14:26.996] sched: Allocate JobId=49644 NodeList=cpu11 #CPUs=1 Partition=cpu-opteron
[2022-09-25T21:14:26.996] sched: Allocate JobId=49645 NodeList=cpu11 #CPUs=1 Partition=cpu-opteron
[2022-09-25T21:14:26.997] sched: Allocate JobId=49646 NodeList=cpu11 #CPUs=1 Partition=cpu-opteron
[2022-09-25T21:14:26.997] sched: Allocate JobId=49647 NodeList=cpu11 #CPUs=1 Partition=cpu-opteron
[2022-09-25T21:14:26.998] sched: Allocate JobId=49648 NodeList=cpu09 #CPUs=1 Partition=cpu-opteron
[2022-09-25T21:14:26.998] sched: Allocate JobId=49649 NodeList=cpu09 #CPUs=1 Partition=cpu-opteron
[2022-09-25T21:14:26.999] sched: Allocate JobId=49650 NodeList=cpu09 #CPUs=1 Partition=cpu-opteron
[2022-09-25T21:14:26.999] sched: Allocate JobId=49651 NodeList=cpu09 #CPUs=1 Partition=cpu-opteron
[2022-09-25T21:14:27.000] sched: Allocate JobId=49652 NodeList=cpu09 #CPUs=1 Partition=cpu-opteron
[2022-09-25T21:14:27.000] sched: Allocate JobId=49653 NodeList=cpu09 #CPUs=1 Partition=cpu-opteron
[2022-09-25T21:14:27.001] sched: Allocate JobId=49654 NodeList=cpu09 #CPUs=1 Partition=cpu-opteron
[2022-09-25T21:14:27.001] sched: Allocate JobId=49655 NodeList=cpu09 #CPUs=1 Partition=cpu-opteron
[2022-09-25T21:14:27.002] sched: Allocate JobId=49656 NodeList=cpu09 #CPUs=1 Partition=cpu-opteron
[2022-09-25T21:14:27.003] sched: Allocate JobId=49657 NodeList=cpu09 #CPUs=1 Partition=cpu-opteron
[2022-09-25T21:14:27.003] sched: Allocate JobId=49658 NodeList=cpu09 #CPUs=1 Partition=cpu-opteron
[2022-09-25T21:14:27.004] sched: Allocate JobId=49659 NodeList=cpu09 #CPUs=1 Partition=cpu-opteron
[2022-09-25T21:14:27.004] sched: Allocate JobId=49660 NodeList=cpu09 #CPUs=1 Partition=cpu-opteron
[2022-09-25T21:14:27.005] sched: Allocate JobId=49661 NodeList=cpu09 #CPUs=1 Partition=cpu-opteron
[2022-09-25T21:14:27.005] sched: Allocate JobId=49662 NodeList=cpu09 #CPUs=1 Partition=cpu-opteron
[2022-09-25T21:14:27.006] sched: Allocate JobId=49663 NodeList=cpu09 #CPUs=1 Partition=cpu-opteron
[2022-09-25T21:14:27.006] sched: Allocate JobId=49664 NodeList=cpu09 #CPUs=1 Partition=cpu-opteron
[2022-09-25T21:14:27.007] sched: Allocate JobId=49665 NodeList=cpu09 #CPUs=1 Partition=cpu-opteron
[2022-09-25T21:14:27.007] sched: Allocate JobId=49666 NodeList=cpu09 #CPUs=1 Partition=cpu-opteron
[2022-09-25T21:14:27.008] sched: Allocate JobId=49667 NodeList=cpu09 #CPUs=1 Partition=cpu-opteron
[2022-09-25T21:14:27.008] sched: Allocate JobId=49668 NodeList=cpu09 #CPUs=1 Partition=cpu-opteron
[2022-09-25T21:14:27.009] sched: Allocate JobId=49669 NodeList=cpu09 #CPUs=1 Partition=cpu-opteron
[2022-09-25T21:14:27.009] sched: Allocate JobId=49670 NodeList=cpu09 #CPUs=1 Partition=cpu-opteron
[2022-09-25T21:14:27.010] sched: Allocate JobId=49671 NodeList=cpu09 #CPUs=1 Partition=cpu-opteron
[2022-09-25T21:14:27.010] sched: Allocate JobId=49672 NodeList=cpu09 #CPUs=1 Partition=cpu-opteron
[2022-09-25T21:14:27.011] sched: Allocate JobId=49673 NodeList=cpu09 #CPUs=1 Partition=cpu-opteron
[2022-09-25T21:14:27.011] sched: Allocate JobId=49674 NodeList=cpu09 #CPUs=1 Partition=cpu-opteron
[2022-09-25T21:14:27.012] sched: Allocate JobId=49675 NodeList=cpu09 #CPUs=1 Partition=cpu-opteron
[2022-09-25T21:14:27.012] sched: Allocate JobId=49676 NodeList=cpu09 #CPUs=1 Partition=cpu-opteron
[2022-09-25T21:14:27.013] sched: Allocate JobId=49677 NodeList=cpu09 #CPUs=1 Partition=cpu-opteron
[2022-09-25T21:14:27.013] sched: Allocate JobId=49678 NodeList=cpu09 #CPUs=1 Partition=cpu-opteron
[2022-09-25T21:14:27.014] sched: Allocate JobId=49679 NodeList=cpu09 #CPUs=1 Partition=cpu-opteron
[2022-09-25T21:14:27.014] sched: Allocate JobId=49680 NodeList=cpu09 #CPUs=1 Partition=cpu-opteron
[2022-09-25T21:14:27.015] sched: Allocate JobId=49681 NodeList=cpu09 #CPUs=1 Partition=cpu-opteron
[2022-09-25T21:14:27.015] sched: Allocate JobId=49682 NodeList=cpu09 #CPUs=1 Partition=cpu-opteron
[2022-09-25T21:14:27.016] sched: Allocate JobId=49683 NodeList=cpu09 #CPUs=1 Partition=cpu-opteron
[2022-09-25T21:14:27.016] sched: Allocate JobId=49684 NodeList=cpu09 #CPUs=1 Partition=cpu-opteron
[2022-09-25T21:14:27.017] sched: Allocate JobId=49685 NodeList=cpu09 #CPUs=1 Partition=cpu-opteron
[2022-09-25T21:14:27.017] sched: Allocate JobId=49686 NodeList=cpu09 #CPUs=1 Partition=cpu-opteron
[2022-09-25T21:14:27.018] sched: Allocate JobId=49687 NodeList=cpu09 #CPUs=1 Partition=cpu-opteron
[2022-09-25T21:14:27.018] sched: Allocate JobId=49688 NodeList=cpu09 #CPUs=1 Partition=cpu-opteron
[2022-09-25T21:14:27.019] sched: Allocate JobId=49689 NodeList=cpu09 #CPUs=1 Partition=cpu-opteron
[2022-09-25T21:14:27.020] sched: Allocate JobId=49690 NodeList=cpu09 #CPUs=1 Partition=cpu-opteron
[2022-09-25T21:14:27.020] sched: Allocate JobId=49691 NodeList=cpu09 #CPUs=1 Partition=cpu-opteron
[2022-09-25T21:14:27.020]    retry_list retry_list_size:168 msg_type=REQUEST_LAUNCH_PROLOG,REQUEST_BATCH_JOB_LAUNCH,REQUEST_LAUNCH_PROLOG,REQUEST_BATCH_JOB_LAUNCH,REQUEST_LAUNCH_PROLOG
[2022-09-25T21:57:54.071] _job_complete: JobId=49626 WEXITSTATUS 1
[2022-09-25T21:57:54.072] _job_complete: JobId=49626 done
[2022-09-25T22:22:50.834] _slurm_rpc_submit_batch_job: JobId=49692 InitPrio=2000 usec=476
[2022-09-25T22:22:50.964] sched: Allocate JobId=49692 NodeList=cpu09 #CPUs=8 Partition=cpu-opteron
[2022-09-25T23:29:09.515] _job_complete: JobId=49692 WEXITSTATUS 0
[2022-09-25T23:29:09.516] _job_complete: JobId=49692 done
[2022-09-25T23:31:34.224] _slurm_rpc_submit_batch_job: JobId=49693 InitPrio=1555 usec=527
[2022-09-25T23:53:27.800] _slurm_rpc_submit_batch_job: JobId=49694 InitPrio=2000 usec=472
[2022-09-25T23:53:28.634] sched: Allocate JobId=49694 NodeList=cpu09 #CPUs=8 Partition=cpu-opteron
[2022-09-26T00:35:50.723] _job_complete: JobId=49598 WEXITSTATUS 1
[2022-09-26T00:35:50.724] _job_complete: JobId=49598 done
[2022-09-26T00:35:51.812] sched: Allocate JobId=49693 NodeList=gpu04 #CPUs=16 Partition=gpu-k40c
[2022-09-26T01:09:27.423] _pick_best_nodes: JobId=49695 never runnable in partition gpu-k40c
[2022-09-26T01:09:27.425] _slurm_rpc_submit_batch_job: Requested node configuration is not available
[2022-09-26T01:10:10.813] _slurm_rpc_submit_batch_job: JobId=49696 InitPrio=2000 usec=1014
[2022-09-26T01:19:57.073] _job_complete: JobId=49694 WEXITSTATUS 1
[2022-09-26T01:19:57.074] _job_complete: JobId=49694 done
[2022-09-26T01:21:44.716] _slurm_rpc_submit_batch_job: JobId=49697 InitPrio=2000 usec=1021
[2022-09-26T01:22:05.947] _slurm_rpc_kill_job: REQUEST_KILL_JOB JobId=49592 uid 548200029
[2022-09-26T01:22:13.427] sched: Allocate JobId=49697 NodeList=gpu03 #CPUs=16 Partition=gpu-k10
[2022-09-26T02:32:55.517] _slurm_rpc_submit_batch_job: JobId=49698 InitPrio=3777 usec=5399
[2022-09-26T02:32:56.380] sched: Allocate JobId=49698 NodeList=cpu09 #CPUs=4 Partition=cpu-opteron
[2022-09-26T02:47:38.347] _slurm_rpc_submit_batch_job: JobId=49699 InitPrio=3777 usec=468
[2022-09-26T02:47:38.964] sched: Allocate JobId=49699 NodeList=cpu09 #CPUs=4 Partition=cpu-opteron
[2022-09-26T02:59:37.996] _slurm_rpc_submit_batch_job: JobId=49700 InitPrio=3777 usec=608
[2022-09-26T02:59:38.266] sched: Allocate JobId=49700 NodeList=cpu04 #CPUs=2 Partition=cpu-opteron
[2022-09-26T03:18:07.695] _slurm_rpc_submit_batch_job: JobId=49701 InitPrio=3777 usec=561
[2022-09-26T03:18:08.640] sched: Allocate JobId=49701 NodeList=cpu09 #CPUs=8 Partition=cpu-opteron
[2022-09-26T03:27:43.214] _slurm_rpc_submit_batch_job: JobId=49702 InitPrio=3777 usec=393
[2022-09-26T04:18:28.805] _job_complete: JobId=49700 WEXITSTATUS 0
[2022-09-26T04:18:28.805] _job_complete: JobId=49700 done
[2022-09-26T07:59:54.554] _slurm_rpc_submit_batch_job: JobId=49703 InitPrio=15333 usec=583
[2022-09-26T07:59:54.965] sched: Allocate JobId=49703 NodeList=cpu10 #CPUs=8 Partition=cpu-opteron
[2022-09-26T08:00:07.428] _job_complete: JobId=49703 WEXITSTATUS 132
[2022-09-26T08:00:07.429] _job_complete: JobId=49703 done
[2022-09-26T08:02:59.857] _slurm_rpc_submit_batch_job: JobId=49704 InitPrio=15333 usec=593
[2022-09-26T08:03:00.398] sched: Allocate JobId=49704 NodeList=cpu10 #CPUs=8 Partition=cpu-opteron
[2022-09-26T08:03:10.268] _job_complete: JobId=49704 WEXITSTATUS 132
[2022-09-26T08:03:10.268] _job_complete: JobId=49704 done
[2022-09-26T08:05:04.242] sched: _slurm_rpc_allocate_resources JobId=49705 NodeList=(null) usec=586
[2022-09-26T08:05:04.570] sched: Allocate JobId=49705 NodeList=cpu10 #CPUs=8 Partition=cpu-opteron
[2022-09-26T08:06:55.968] _slurm_rpc_kill_job: REQUEST_KILL_JOB JobId=49705 uid 548300543
[2022-09-26T09:13:01.377] _job_complete: JobId=49562 WEXITSTATUS 0
[2022-09-26T09:13:01.377] _job_complete: JobId=49562 done
[2022-09-26T10:17:09.610] _slurm_rpc_kill_job: REQUEST_KILL_JOB JobId=49696 uid 548200029
[2022-09-26T10:17:39.392] _slurm_rpc_submit_batch_job: JobId=49706 InitPrio=2000 usec=1099
[2022-09-26T10:17:40.063] sched: Allocate JobId=49706 NodeList=gpu01 #CPUs=16 Partition=gpu-k10
[2022-09-26T10:28:56.147] _slurm_rpc_submit_batch_job: JobId=49707 InitPrio=2000 usec=480
[2022-09-26T10:28:56.225] sched: Allocate JobId=49707 NodeList=cpu10 #CPUs=16 Partition=cpu-opteron
[2022-09-26T10:29:42.205] _job_complete: JobId=49707 WEXITSTATUS 0
[2022-09-26T10:29:42.206] _job_complete: JobId=49707 done
[2022-09-26T10:35:58.501] _slurm_rpc_submit_batch_job: JobId=49708 InitPrio=2000 usec=478
[2022-09-26T10:35:58.869] sched/backfill: _start_job: Started JobId=49708 in cpu-opteron on cpu10
[2022-09-26T10:41:05.617] Time limit exhausted for JobId=49588
[2022-09-26T11:39:26.351] _job_complete: JobId=49665 WEXITSTATUS 1
[2022-09-26T11:39:26.351] _job_complete: JobId=49665 done
[2022-09-26T12:06:54.645] _job_complete: JobId=49643 WEXITSTATUS 0
[2022-09-26T12:06:54.645] _job_complete: JobId=49643 done
[2022-09-26T12:13:22.838] _job_complete: JobId=49642 WEXITSTATUS 0
[2022-09-26T12:13:22.838] _job_complete: JobId=49642 done
[2022-09-26T12:36:55.399] _job_complete: JobId=49601 WEXITSTATUS 0
[2022-09-26T12:36:55.400] _job_complete: JobId=49601 done
[2022-09-26T12:37:23.631] _slurm_rpc_submit_batch_job: JobId=49709 InitPrio=666 usec=497
[2022-09-26T12:37:23.876] sched: Allocate JobId=49709 NodeList=cpu10 #CPUs=32 Partition=cpu-opteron
[2022-09-26T12:37:37.144] _job_complete: JobId=49709 WEXITSTATUS 1
[2022-09-26T12:37:37.144] _job_complete: JobId=49709 done
[2022-09-26T12:48:05.647] _job_complete: JobId=49647 WEXITSTATUS 0
[2022-09-26T12:48:05.647] _job_complete: JobId=49647 done
[2022-09-26T12:56:17.291] _job_complete: JobId=49644 WEXITSTATUS 0
[2022-09-26T12:56:17.291] _job_complete: JobId=49644 done
[2022-09-26T13:04:09.617] _job_complete: JobId=49587 WEXITSTATUS 0
[2022-09-26T13:04:09.623] _job_complete: JobId=49587 done
[2022-09-26T13:06:21.723] _job_complete: JobId=49621 WEXITSTATUS 0
[2022-09-26T13:06:21.723] _job_complete: JobId=49621 done
[2022-09-26T13:08:13.429] _job_complete: JobId=49708 WEXITSTATUS 0
[2022-09-26T13:08:13.435] _job_complete: JobId=49708 done
[2022-09-26T13:09:17.509] _slurm_rpc_submit_batch_job: JobId=49710 InitPrio=666 usec=567
[2022-09-26T13:09:18.374] sched: Allocate JobId=49710 NodeList=cpu07 #CPUs=32 Partition=cpu-opteron
[2022-09-26T13:09:36.613] _job_complete: JobId=49710 WEXITSTATUS 1
[2022-09-26T13:09:36.613] _job_complete: JobId=49710 done
[2022-09-26T13:09:55.988] _job_complete: JobId=49638 WEXITSTATUS 0
[2022-09-26T13:09:55.989] _job_complete: JobId=49638 done
[2022-09-26T13:10:30.234] _slurm_rpc_submit_batch_job: JobId=49711 InitPrio=666 usec=532
[2022-09-26T13:10:30.470] sched: Allocate JobId=49711 NodeList=cpu07 #CPUs=32 Partition=cpu-opteron
[2022-09-26T13:10:52.744] _job_complete: JobId=49711 WEXITSTATUS 1
[2022-09-26T13:10:52.744] _job_complete: JobId=49711 done
[2022-09-26T13:11:43.173] _slurm_rpc_submit_batch_job: JobId=49712 InitPrio=666 usec=459
[2022-09-26T13:11:43.660] sched: Allocate JobId=49712 NodeList=cpu07 #CPUs=32 Partition=cpu-opteron
[2022-09-26T13:14:29.543] _job_complete: JobId=49712 WEXITSTATUS 0
[2022-09-26T13:14:29.543] _job_complete: JobId=49712 done
[2022-09-26T13:17:04.767] _job_complete: JobId=49634 WEXITSTATUS 0
[2022-09-26T13:17:04.767] _job_complete: JobId=49634 done
[2022-09-26T13:22:25.127] _job_complete: JobId=49602 WEXITSTATUS 0
[2022-09-26T13:22:25.128] _job_complete: JobId=49602 done
[2022-09-26T13:23:24.061] _job_complete: JobId=49622 WEXITSTATUS 0
[2022-09-26T13:23:24.062] _job_complete: JobId=49622 done
[2022-09-26T13:25:35.045] _job_complete: JobId=49636 WEXITSTATUS 0
[2022-09-26T13:25:35.045] _job_complete: JobId=49636 done
[2022-09-26T13:56:19.819] _job_complete: JobId=49637 WEXITSTATUS 0
[2022-09-26T13:56:19.819] _job_complete: JobId=49637 done
[2022-09-26T14:01:50.220] _job_complete: JobId=49613 WEXITSTATUS 0
[2022-09-26T14:01:50.220] _job_complete: JobId=49613 done
[2022-09-26T14:03:47.438] _job_complete: JobId=49683 WEXITSTATUS 0
[2022-09-26T14:03:47.438] _job_complete: JobId=49683 done
[2022-09-26T14:09:41.223] _job_complete: JobId=49632 WEXITSTATUS 0
[2022-09-26T14:09:41.223] _job_complete: JobId=49632 done
[2022-09-26T14:16:59.625] _job_complete: JobId=49682 WEXITSTATUS 0
[2022-09-26T14:16:59.625] _job_complete: JobId=49682 done
[2022-09-26T14:20:48.444] _job_complete: JobId=49605 WEXITSTATUS 0
[2022-09-26T14:20:48.444] _job_complete: JobId=49605 done
[2022-09-26T14:22:48.667] _job_complete: JobId=49630 WEXITSTATUS 0
[2022-09-26T14:22:48.667] _job_complete: JobId=49630 done
[2022-09-26T14:29:38.808] _job_complete: JobId=49680 WEXITSTATUS 0
[2022-09-26T14:29:38.808] _job_complete: JobId=49680 done
[2022-09-26T14:30:53.532] _job_complete: JobId=49641 WEXITSTATUS 0
[2022-09-26T14:30:53.532] _job_complete: JobId=49641 done
[2022-09-26T14:32:22.468] _job_complete: JobId=49633 WEXITSTATUS 0
[2022-09-26T14:32:22.468] _job_complete: JobId=49633 done
[2022-09-26T14:34:15.783] _job_complete: JobId=49640 WEXITSTATUS 0
[2022-09-26T14:34:15.783] _job_complete: JobId=49640 done
[2022-09-26T14:36:07.267] _job_complete: JobId=49577 WEXITSTATUS 0
[2022-09-26T14:36:07.322] _job_complete: JobId=49577 done
[2022-09-26T14:36:10.312] sched: Allocate JobId=49702 NodeList=cpu14 #CPUs=2 Partition=cpu-epyc
[2022-09-26T14:38:03.169] _job_complete: JobId=49625 WEXITSTATUS 0
[2022-09-26T14:38:03.169] _job_complete: JobId=49625 done
[2022-09-26T14:38:07.394] _job_complete: JobId=49611 WEXITSTATUS 0
[2022-09-26T14:38:07.394] _job_complete: JobId=49611 done
[2022-09-26T14:43:53.784] _job_complete: JobId=49620 WEXITSTATUS 0
[2022-09-26T14:43:53.784] _job_complete: JobId=49620 done
[2022-09-26T14:44:47.855] _slurm_rpc_submit_batch_job: JobId=49713 InitPrio=2000 usec=430
[2022-09-26T14:44:48.797] sched: Allocate JobId=49713 NodeList=cpu03 #CPUs=8 Partition=cpu-opteron
[2022-09-26T14:47:45.572] _job_complete: JobId=49618 WEXITSTATUS 0
[2022-09-26T14:47:45.572] _job_complete: JobId=49618 done
[2022-09-26T14:53:35.896] _job_complete: JobId=49702 WEXITSTATUS 0
[2022-09-26T14:53:35.896] _job_complete: JobId=49702 done
[2022-09-26T14:56:59.623] _job_complete: JobId=49645 WEXITSTATUS 0
[2022-09-26T14:56:59.623] _job_complete: JobId=49645 done
[2022-09-26T14:57:58.519] _job_complete: JobId=49629 WEXITSTATUS 0
[2022-09-26T14:57:58.519] _job_complete: JobId=49629 done
[2022-09-26T15:00:34.126] _job_complete: JobId=49603 WEXITSTATUS 0
[2022-09-26T15:00:34.126] _job_complete: JobId=49603 done
[2022-09-26T15:03:13.032] _job_complete: JobId=49667 WEXITSTATUS 0
[2022-09-26T15:03:13.032] _job_complete: JobId=49667 done
[2022-09-26T15:04:57.726] _slurm_rpc_submit_batch_job: JobId=49714 InitPrio=4444 usec=427
[2022-09-26T15:04:57.899] sched: Allocate JobId=49714 NodeList=cpu04 #CPUs=8 Partition=cpu-opteron
[2022-09-26T15:05:43.989] _job_complete: JobId=49714 WEXITSTATUS 0
[2022-09-26T15:05:43.989] _job_complete: JobId=49714 done
[2022-09-26T15:05:47.630] _job_complete: JobId=49628 WEXITSTATUS 0
[2022-09-26T15:05:47.630] _job_complete: JobId=49628 done
[2022-09-26T15:09:13.236] _job_complete: JobId=49604 WEXITSTATUS 0
[2022-09-26T15:09:13.236] _job_complete: JobId=49604 done
[2022-09-26T15:10:48.876] _job_complete: JobId=49674 WEXITSTATUS 0
[2022-09-26T15:10:48.876] _job_complete: JobId=49674 done
[2022-09-26T15:10:53.805] _slurm_rpc_submit_batch_job: JobId=49715 InitPrio=4444 usec=456
[2022-09-26T15:10:54.444] sched: Allocate JobId=49715 NodeList=cpu03 #CPUs=8 Partition=cpu-opteron
[2022-09-26T15:12:22.485] _job_complete: JobId=49715 WEXITSTATUS 1
[2022-09-26T15:12:22.485] _job_complete: JobId=49715 done
[2022-09-26T15:13:11.664] _job_complete: JobId=49631 WEXITSTATUS 0
[2022-09-26T15:13:11.664] _job_complete: JobId=49631 done
[2022-09-26T15:15:39.314] _slurm_rpc_submit_batch_job: JobId=49716 InitPrio=4444 usec=503
[2022-09-26T15:15:39.949] sched: Allocate JobId=49716 NodeList=cpu03 #CPUs=8 Partition=cpu-opteron
[2022-09-26T15:17:13.345] _job_complete: JobId=49652 WEXITSTATUS 0
[2022-09-26T15:17:13.345] _job_complete: JobId=49652 done
[2022-09-26T15:17:14.239] _job_complete: JobId=49716 WEXITSTATUS 0
[2022-09-26T15:17:14.239] _job_complete: JobId=49716 done
[2022-09-26T15:18:11.675] _slurm_rpc_submit_batch_job: JobId=49717 InitPrio=4444 usec=932
[2022-09-26T15:18:12.443] sched: Allocate JobId=49717 NodeList=cpu03 #CPUs=8 Partition=cpu-opteron
[2022-09-26T15:19:46.648] _job_complete: JobId=49717 WEXITSTATUS 0
[2022-09-26T15:19:46.648] _job_complete: JobId=49717 done
[2022-09-26T15:21:39.850] _job_complete: JobId=49675 WEXITSTATUS 0
[2022-09-26T15:21:39.851] _job_complete: JobId=49675 done
[2022-09-26T15:24:39.215] _job_complete: JobId=49670 WEXITSTATUS 0
[2022-09-26T15:24:39.215] _job_complete: JobId=49670 done
[2022-09-26T15:26:15.708] _job_complete: JobId=49655 WEXITSTATUS 0
[2022-09-26T15:26:15.708] _job_complete: JobId=49655 done
[2022-09-26T15:27:29.411] _slurm_rpc_submit_batch_job: JobId=49718 InitPrio=4444 usec=561
[2022-09-26T15:27:29.467] sched: Allocate JobId=49718 NodeList=cpu03 #CPUs=8 Partition=cpu-opteron
[2022-09-26T15:29:04.700] _job_complete: JobId=49718 WEXITSTATUS 0
[2022-09-26T15:29:04.700] _job_complete: JobId=49718 done
[2022-09-26T15:30:41.630] _job_complete: JobId=49624 WEXITSTATUS 0
[2022-09-26T15:30:41.630] _job_complete: JobId=49624 done
[2022-09-26T15:33:28.017] _slurm_rpc_submit_batch_job: JobId=49719 InitPrio=4444 usec=457
[2022-09-26T15:33:28.168] sched: Allocate JobId=49719 NodeList=cpu03 #CPUs=8 Partition=cpu-opteron
[2022-09-26T15:34:45.994] _job_complete: JobId=49610 WEXITSTATUS 0
[2022-09-26T15:34:45.994] _job_complete: JobId=49610 done
[2022-09-26T15:35:03.458] _job_complete: JobId=49719 WEXITSTATUS 0
[2022-09-26T15:35:03.458] _job_complete: JobId=49719 done
[2022-09-26T15:38:36.236] _slurm_rpc_submit_batch_job: JobId=49720 InitPrio=2666 usec=470
[2022-09-26T15:38:36.762] sched: Allocate JobId=49720 NodeList=cpu14 #CPUs=16 Partition=cpu-epyc
[2022-09-26T15:38:40.315] _slurm_rpc_submit_batch_job: JobId=49721 InitPrio=2666 usec=441
[2022-09-26T15:38:41.822] _slurm_rpc_submit_batch_job: JobId=49722 InitPrio=4444 usec=467
[2022-09-26T15:38:42.890] _slurm_rpc_submit_batch_job: JobId=49723 InitPrio=2666 usec=485
[2022-09-26T15:38:43.760] sched: Allocate JobId=49722 NodeList=cpu03 #CPUs=8 Partition=cpu-opteron
[2022-09-26T15:38:45.481] _slurm_rpc_submit_batch_job: JobId=49724 InitPrio=2666 usec=490
[2022-09-26T15:38:48.242] _slurm_rpc_submit_batch_job: JobId=49725 InitPrio=2666 usec=628
[2022-09-26T15:38:59.034] _slurm_rpc_submit_batch_job: JobId=49726 InitPrio=2666 usec=419
[2022-09-26T15:39:02.794] _slurm_rpc_submit_batch_job: JobId=49727 InitPrio=2666 usec=399
[2022-09-26T15:39:05.890] _slurm_rpc_submit_batch_job: JobId=49728 InitPrio=2666 usec=434
[2022-09-26T15:39:23.206] _job_complete: JobId=49627 WEXITSTATUS 0
[2022-09-26T15:39:23.206] _job_complete: JobId=49627 done
[2022-09-26T15:40:22.992] _job_complete: JobId=49722 WEXITSTATUS 0
[2022-09-26T15:40:22.992] _job_complete: JobId=49722 done
[2022-09-26T15:41:26.708] _slurm_rpc_submit_batch_job: JobId=49729 InitPrio=2666 usec=679
[2022-09-26T15:41:40.972] _slurm_rpc_submit_batch_job: JobId=49730 InitPrio=2666 usec=380
[2022-09-26T15:41:43.516] _slurm_rpc_submit_batch_job: JobId=49731 InitPrio=2666 usec=413
[2022-09-26T15:41:46.427] _slurm_rpc_submit_batch_job: JobId=49732 InitPrio=2666 usec=445
[2022-09-26T15:41:49.461] _slurm_rpc_submit_batch_job: JobId=49733 InitPrio=2666 usec=625
[2022-09-26T15:41:52.853] _slurm_rpc_submit_batch_job: JobId=49734 InitPrio=2666 usec=565
[2022-09-26T16:05:05.438] _job_complete: JobId=49663 WEXITSTATUS 0
[2022-09-26T16:05:05.439] _job_complete: JobId=49663 done
[2022-09-26T16:09:47.332] _job_complete: JobId=49660 WEXITSTATUS 0
[2022-09-26T16:09:47.332] _job_complete: JobId=49660 done
[2022-09-26T16:11:51.036] _job_complete: JobId=49646 WEXITSTATUS 0
[2022-09-26T16:11:51.036] _job_complete: JobId=49646 done
[2022-09-26T16:11:51.259] sched: _slurm_rpc_allocate_resources JobId=49735 NodeList=cpu03 usec=61623
[2022-09-26T16:13:16.200] _job_complete: JobId=49664 WEXITSTATUS 0
[2022-09-26T16:13:16.201] _job_complete: JobId=49664 done
[2022-09-26T16:18:10.938] _job_complete: JobId=49656 WEXITSTATUS 0
[2022-09-26T16:18:10.938] _job_complete: JobId=49656 done
[2022-09-26T16:19:45.399] sched: _slurm_rpc_allocate_resources JobId=49736 NodeList=(null) usec=5795
[2022-09-26T16:19:46.062] sched: Allocate JobId=49736 NodeList=cpu14 #CPUs=1 Partition=cpu-epyc
[2022-09-26T16:22:31.600] _job_complete: JobId=49736 WEXITSTATUS 0
[2022-09-26T16:22:31.600] _job_complete: JobId=49736 done
[2022-09-26T16:27:31.724] _job_complete: JobId=49581 WEXITSTATUS 2
[2022-09-26T16:27:31.729] _job_complete: JobId=49581 done
[2022-09-26T16:29:53.200] _job_complete: JobId=49677 WEXITSTATUS 0
[2022-09-26T16:29:53.200] _job_complete: JobId=49677 done
[2022-09-26T16:33:26.084] _job_complete: JobId=49609 WEXITSTATUS 0
[2022-09-26T16:33:26.084] _job_complete: JobId=49609 done
[2022-09-26T16:35:27.732] _job_complete: JobId=49649 WEXITSTATUS 0
[2022-09-26T16:35:27.732] _job_complete: JobId=49649 done
[2022-09-26T16:37:29.821] _job_complete: JobId=49713 WEXITSTATUS 0
[2022-09-26T16:37:29.826] _job_complete: JobId=49713 done
[2022-09-26T16:38:40.004] _job_complete: JobId=49639 WEXITSTATUS 0
[2022-09-26T16:38:40.004] _job_complete: JobId=49639 done
[2022-09-26T16:38:53.626] _job_complete: JobId=49658 WEXITSTATUS 0
[2022-09-26T16:38:53.627] _job_complete: JobId=49658 done
[2022-09-26T16:40:56.146] _slurm_rpc_submit_batch_job: JobId=49737 InitPrio=4444 usec=491
[2022-09-26T16:40:56.354] sched: Allocate JobId=49737 NodeList=cpu04 #CPUs=8 Partition=cpu-opteron
[2022-09-26T16:41:34.620] _job_complete: JobId=49659 WEXITSTATUS 0
[2022-09-26T16:41:34.621] _job_complete: JobId=49659 done
[2022-09-26T16:41:46.568] _slurm_rpc_submit_batch_job: JobId=49738 InitPrio=4444 usec=490
[2022-09-26T16:41:47.491] sched: Allocate JobId=49738 NodeList=cpu04 #CPUs=8 Partition=cpu-opteron
[2022-09-26T16:42:48.260] _job_complete: JobId=49662 WEXITSTATUS 0
[2022-09-26T16:42:48.260] _job_complete: JobId=49662 done
[2022-09-26T16:46:26.781] _job_complete: JobId=49686 WEXITSTATUS 0
[2022-09-26T16:46:26.782] _job_complete: JobId=49686 done
[2022-09-26T16:46:41.165] sched: _slurm_rpc_allocate_resources JobId=49739 NodeList=(null) usec=750
[2022-09-26T16:46:42.046] sched: Allocate JobId=49739 NodeList=cpu14 #CPUs=1 Partition=cpu-epyc
[2022-09-26T16:53:12.494] _job_complete: JobId=49738 WEXITSTATUS 1
[2022-09-26T16:53:12.494] _job_complete: JobId=49738 done
[2022-09-26T16:58:13.341] _job_complete: JobId=49668 WEXITSTATUS 0
[2022-09-26T16:58:13.341] _job_complete: JobId=49668 done
[2022-09-26T17:01:11.161] _job_complete: JobId=49679 WEXITSTATUS 0
[2022-09-26T17:01:11.161] _job_complete: JobId=49679 done
[2022-09-26T17:03:00.328] _slurm_rpc_kill_job: REQUEST_KILL_JOB JobId=49594 uid 548300593
[2022-09-26T17:03:07.263] _job_complete: JobId=49669 WEXITSTATUS 0
[2022-09-26T17:03:07.263] _job_complete: JobId=49669 done
[2022-09-26T17:03:08.690] _slurm_rpc_submit_batch_job: JobId=49740 InitPrio=1777 usec=506
[2022-09-26T17:03:08.791] sched: Allocate JobId=49740 NodeList=cpu01 #CPUs=35 Partition=cpu-opteron
[2022-09-26T17:04:37.536] _job_complete: JobId=49737 WEXITSTATUS 1
[2022-09-26T17:04:37.536] _job_complete: JobId=49737 done
[2022-09-26T17:05:35.420] _job_complete: JobId=49661 WEXITSTATUS 0
[2022-09-26T17:05:35.421] _job_complete: JobId=49661 done
[2022-09-26T17:07:08.665] _job_complete: JobId=49616 WEXITSTATUS 0
[2022-09-26T17:07:08.665] _job_complete: JobId=49616 done
[2022-09-26T17:09:35.005] _job_complete: JobId=49612 WEXITSTATUS 0
[2022-09-26T17:09:35.005] _job_complete: JobId=49612 done
[2022-09-26T17:12:07.751] Time limit exhausted for JobId=49735
[2022-09-26T17:17:08.993] cleanup_completing: JobId=49735 completion process took 301 seconds
[2022-09-26T17:21:23.136] _slurm_rpc_submit_batch_job: JobId=49741 InitPrio=4444 usec=427
[2022-09-26T17:21:23.732] sched: Allocate JobId=49741 NodeList=cpu04 #CPUs=8 Partition=cpu-opteron
[2022-09-26T17:21:53.809] _job_complete: JobId=49741 WEXITSTATUS 0
[2022-09-26T17:21:53.809] _job_complete: JobId=49741 done
[2022-09-26T17:23:34.322] _job_complete: JobId=49653 WEXITSTATUS 0
[2022-09-26T17:23:34.322] _job_complete: JobId=49653 done
[2022-09-26T17:23:48.896] _job_complete: JobId=49666 WEXITSTATUS 0
[2022-09-26T17:23:48.896] _job_complete: JobId=49666 done
[2022-09-26T17:27:31.078] _job_complete: JobId=49619 WEXITSTATUS 0
[2022-09-26T17:27:31.078] _job_complete: JobId=49619 done
[2022-09-26T17:30:07.775] _job_complete: JobId=49651 WEXITSTATUS 0
[2022-09-26T17:30:07.775] _job_complete: JobId=49651 done
[2022-09-26T17:30:14.907] _job_complete: JobId=49687 WEXITSTATUS 0
[2022-09-26T17:30:14.907] _job_complete: JobId=49687 done
[2022-09-26T17:30:31.273] _slurm_rpc_submit_batch_job: JobId=49742 InitPrio=4444 usec=526
[2022-09-26T17:30:31.677] sched: Allocate JobId=49742 NodeList=cpu04 #CPUs=8 Partition=cpu-opteron
[2022-09-26T17:32:01.307] _slurm_rpc_submit_batch_job: JobId=49743 InitPrio=4444 usec=477
[2022-09-26T17:32:02.891] sched: Allocate JobId=49743 NodeList=cpu04 #CPUs=8 Partition=cpu-opteron
[2022-09-26T17:32:29.668] _job_complete: JobId=49742 WEXITSTATUS 0
[2022-09-26T17:32:29.668] _job_complete: JobId=49742 done
[2022-09-26T17:33:59.744] _job_complete: JobId=49743 WEXITSTATUS 0
[2022-09-26T17:33:59.744] _job_complete: JobId=49743 done
[2022-09-26T17:39:42.824] _job_complete: JobId=49615 WEXITSTATUS 0
[2022-09-26T17:39:42.824] _job_complete: JobId=49615 done
[2022-09-26T17:39:46.962] _job_complete: JobId=49688 WEXITSTATUS 0
[2022-09-26T17:39:46.962] _job_complete: JobId=49688 done
[2022-09-26T17:39:58.117] _job_complete: JobId=49676 WEXITSTATUS 0
[2022-09-26T17:39:58.118] _job_complete: JobId=49676 done
[2022-09-26T17:47:33.186] _slurm_rpc_submit_batch_job: JobId=49744 InitPrio=4444 usec=453
[2022-09-26T17:47:33.626] sched: Allocate JobId=49744 NodeList=cpu04 #CPUs=8 Partition=cpu-opteron
[2022-09-26T17:48:06.726] _job_complete: JobId=49744 WEXITSTATUS 0
[2022-09-26T17:48:06.726] _job_complete: JobId=49744 done
[2022-09-26T17:53:45.312] _job_complete: JobId=49672 WEXITSTATUS 0
[2022-09-26T17:53:45.312] _job_complete: JobId=49672 done
[2022-09-26T17:54:05.153] _job_complete: JobId=49650 WEXITSTATUS 0
[2022-09-26T17:54:05.153] _job_complete: JobId=49650 done
[2022-09-26T17:56:41.882] _slurm_rpc_submit_batch_job: JobId=49745 InitPrio=4444 usec=435
[2022-09-26T17:56:42.576] sched: Allocate JobId=49745 NodeList=cpu04 #CPUs=8 Partition=cpu-opteron
[2022-09-26T17:57:14.876] _slurm_rpc_submit_batch_job: JobId=49746 InitPrio=4444 usec=440
[2022-09-26T17:57:15.621] sched: Allocate JobId=49746 NodeList=cpu04 #CPUs=8 Partition=cpu-opteron
[2022-09-26T18:02:00.580] _job_complete: JobId=49657 WEXITSTATUS 0
[2022-09-26T18:02:00.580] _job_complete: JobId=49657 done
[2022-09-26T18:09:39.909] _job_complete: JobId=49671 WEXITSTATUS 0
[2022-09-26T18:09:39.909] _job_complete: JobId=49671 done
[2022-09-26T18:11:08.705] _job_complete: JobId=49745 WEXITSTATUS 1
[2022-09-26T18:11:08.705] _job_complete: JobId=49745 done
[2022-09-26T18:11:48.998] _slurm_rpc_submit_batch_job: JobId=49747 InitPrio=4444 usec=493
[2022-09-26T18:11:49.303] sched: Allocate JobId=49747 NodeList=cpu04 #CPUs=8 Partition=cpu-opteron
[2022-09-26T18:12:24.931] _job_complete: JobId=49747 WEXITSTATUS 0
[2022-09-26T18:12:24.931] _job_complete: JobId=49747 done
[2022-09-26T18:12:34.601] _job_complete: JobId=49746 WEXITSTATUS 1
[2022-09-26T18:12:34.601] _job_complete: JobId=49746 done
[2022-09-26T18:13:09.364] _job_complete: JobId=49617 WEXITSTATUS 0
[2022-09-26T18:13:09.364] _job_complete: JobId=49617 done
[2022-09-26T18:13:46.660] _job_complete: JobId=49689 WEXITSTATUS 0
[2022-09-26T18:13:46.660] _job_complete: JobId=49689 done
[2022-09-26T18:14:42.958] _job_complete: JobId=49654 WEXITSTATUS 0
[2022-09-26T18:14:42.958] _job_complete: JobId=49654 done
[2022-09-26T18:15:34.192] _job_complete: JobId=49684 WEXITSTATUS 0
[2022-09-26T18:15:34.192] _job_complete: JobId=49684 done
[2022-09-26T18:18:18.179] _slurm_rpc_submit_batch_job: JobId=49748 InitPrio=4444 usec=464
[2022-09-26T18:18:18.941] sched: Allocate JobId=49748 NodeList=cpu04 #CPUs=8 Partition=cpu-opteron
[2022-09-26T18:18:41.523] _job_complete: JobId=49748 WEXITSTATUS 0
[2022-09-26T18:18:41.523] _job_complete: JobId=49748 done
[2022-09-26T18:22:01.173] _job_complete: JobId=49607 WEXITSTATUS 0
[2022-09-26T18:22:01.173] _job_complete: JobId=49607 done
[2022-09-26T18:22:54.590] _job_complete: JobId=49673 WEXITSTATUS 0
[2022-09-26T18:22:54.590] _job_complete: JobId=49673 done
[2022-09-26T18:24:51.378] _job_complete: JobId=49685 WEXITSTATUS 0
[2022-09-26T18:24:51.379] _job_complete: JobId=49685 done
[2022-09-26T18:25:26.487] _slurm_rpc_submit_batch_job: JobId=49749 InitPrio=4444 usec=438
[2022-09-26T18:25:26.800] sched: Allocate JobId=49749 NodeList=cpu04 #CPUs=8 Partition=cpu-opteron
[2022-09-26T18:39:42.762] _job_complete: JobId=49749 WEXITSTATUS 1
[2022-09-26T18:39:42.762] _job_complete: JobId=49749 done
[2022-09-26T19:02:17.751] _job_complete: JobId=49739 WEXITSTATUS 0
[2022-09-26T19:02:17.752] _job_complete: JobId=49739 done
[2022-09-26T19:07:29.124] _job_complete: JobId=49681 WEXITSTATUS 0
[2022-09-26T19:07:29.125] _job_complete: JobId=49681 done
[2022-09-26T19:11:13.083] _job_complete: JobId=49606 WEXITSTATUS 0
[2022-09-26T19:11:13.083] _job_complete: JobId=49606 done
[2022-09-26T19:16:41.511] _job_complete: JobId=49586 WEXITSTATUS 0
[2022-09-26T19:16:41.517] _job_complete: JobId=49586 done
[2022-09-26T19:29:14.842] _job_complete: JobId=49690 WEXITSTATUS 0
[2022-09-26T19:29:14.843] _job_complete: JobId=49690 done
[2022-09-26T19:48:48.603] _job_complete: JobId=49691 WEXITSTATUS 0
[2022-09-26T19:48:48.603] _job_complete: JobId=49691 done
[2022-09-26T20:00:22.278] _job_complete: JobId=49648 WEXITSTATUS 0
[2022-09-26T20:00:22.278] _job_complete: JobId=49648 done
[2022-09-26T20:41:43.703] _job_complete: JobId=49635 WEXITSTATUS 0
[2022-09-26T20:41:43.703] _job_complete: JobId=49635 done
[2022-09-26T20:56:48.352] _slurm_rpc_submit_batch_job: JobId=49750 InitPrio=4444 usec=636
[2022-09-26T20:56:48.787] sched: Allocate JobId=49750 NodeList=cpu04 #CPUs=8 Partition=cpu-opteron
[2022-09-26T20:57:23.288] _job_complete: JobId=49750 WEXITSTATUS 0
[2022-09-26T20:57:23.288] _job_complete: JobId=49750 done
[2022-09-26T21:02:37.003] _slurm_rpc_submit_batch_job: JobId=49751 InitPrio=4444 usec=493
[2022-09-26T21:02:37.755] sched: Allocate JobId=49751 NodeList=cpu04 #CPUs=8 Partition=cpu-opteron
